File: Labs/Lab 2 Tension/6061 Aluminum Sample 3.csv
Time (s),Extension (mm),Load (N),Axial Strain (mm/mm),Transverse Strain (mm/mm)
0,0,-2.33,0,0
0.1,0.003,9.38,0,0
0.2,0.013,206.5,0.00004,0.00001
0.3,0.024,300.9,0.0001,0.00002
0.4,0.033,355.31,0.00013,0.00003
0.5,0.042,376.05,0.00016,0.00003
0.6,0.05,380.51,0.00019,0.00004
0.7,0.059,395.69,0.00021,0.00004
0.8,0.067,418.81,0.00023,0.00004
0.9,0.075,436.76,0.00025,0.00004
1,0.084,456.93,0.00026,0.00004
1.1,0.092,489.01,0.00028,0.00004
1.2,0.1,525.19,0.00029,0.00004
1.3,0.109,567.03,0.0003,0.00004
1.4,0.117,607.72,0.00031,0.00004
1.5,0.125,636.09,0.00033,0.00005
1.6,0.134,659,0.00033,0.00005
1.7,0.142,690.79,0.00034,0.00005
1.8,0.15,721.72,0.00036,0.00005
1.9,0.159,756.87,0.00038,0.00005
2,0.167,802.89,0.00039,0.00006
2.1,0.175,866.96,0.00041,0.00006
2.2,0.184,912.19,0.00042,0.00006
2.3,0.192,938.21,0.00044,0.00006
2.4,0.2,953.51,0.00046,0.00007
2.5,0.208,971.57,0.00048,0.00007
2.6,0.217,985.21,0.00049,0.00007
2.7,0.225,994.43,0.00051,0.00007
2.8,0.233,1002.61,0.00053,0.00008
2.9,0.242,1024.64,0.00055,0.00008
3,0.25,1059.39,0.00057,0.00008
3.1,0.259,1101.6,0.00059,0.00008
3.2,0.267,1136.74,0.0006,0.00008
3.3,0.275,1173.86,0.00062,0.00008
3.4,0.284,1218.62,0.00064,0.00008
3.5,0.292,1250.33,0.00066,0.00004
3.6,0.3,1296.72,0.00067,0.00004
3.7,0.309,1355.89,0.00069,0.00004
3.8,0.317,1416.63,0.00071,0.00005
3.9,0.325,1439.03,0.00073,0.00005
4,0.334,1457.81,0.00075,0.00005
4.1,0.342,1482.65,0.00076,0.00005
4.2,0.35,1510.2,0.00078,0.00005
4.3,0.359,1548.24,0.0008,0.00006
4.4,0.367,1591.83,0.00082,0.00006
4.5,0.375,1647.06,0.00083,0.00006
4.6,0.383,1679.37,0.00085,0.00006
4.7,0.392,1716.27,0.00087,0.00007
4.8,0.4,1757.13,0.00088,0.00007
4.9,0.408,1788,0.0009,0.00007
5,0.417,1836.11,0.00091,0.00007
5.1,0.425,1890.5,0.00093,0.00008
5.2,0.433,1925.63,0.00095,0.00008
5.3,0.442,1942.22,0.00096,0.00007
5.4,0.45,1954.67,0.00097,0.00007
5.5,0.458,1974.33,0.00099,0.00008
5.6,0.467,2015.51,0.001,0.00008
5.7,0.475,2088.07,0.00101,0.00008
5.8,0.483,2155.17,0.00103,0.00008
5.9,0.492,2223.42,0.00104,0.00008
6,0.5,2281.25,0.00106,0.00009
6.1,0.508,2326.32,0.00107,0.00009
6.2,0.517,2362.25,0.00108,0.00009
6.3,0.525,2415.22,0.00109,0.00009
6.4,0.534,2459.37,0.00111,0.00009
6.5,0.542,2481.14,0.00112,0.00009
6.6,0.55,2499.74,0.00113,0.0001
6.7,0.558,2527.44,0.00115,0.0001
6.8,0.567,2568.14,0.00116,0.0001
6.9,0.575,2639.05,0.00117,0.0001
7,0.584,2683.97,0.00118,0.0001
7.1,0.592,2747.89,0.0012,0.0001
7.2,0.6,2817.7,0.00121,0.00011
7.3,0.608,2903.27,0.00122,0.00011
7.4,0.617,2970.97,0.00123,0.00011
7.5,0.625,3008.42,0.00124,0.00011
7.6,0.633,3037.03,0.00126,0.00011
7.7,0.642,3060.55,0.00127,0.00012
7.8,0.65,3111.76,0.00129,0.00012
7.9,0.658,3159.44,0.00129,0.00012
8,0.667,3224.54,0.00131,0.00012
8.1,0.675,3312.14,0.00132,0.00012
8.2,0.684,3369.58,0.00133,0.00013
8.3,0.692,3434.14,0.00135,0.00013
8.4,0.7,3477.71,0.00136,0.00013
8.5,0.708,3498.94,0.00137,0.00013
8.6,0.717,3550.9,0.00138,0.00013
8.7,0.725,3640.05,0.00139,0.00014
8.8,0.734,3732.23,0.00141,0.00014
8.9,0.742,3780.27,0.00142,0.00014
9,0.75,3834.22,0.00144,0.00014
9.1,0.758,3909.73,0.00144,0.00014
9.2,0.767,4003.77,0.00146,0.00015
9.3,0.775,4046.59,0.00147,0.00015
9.4,0.783,4062.57,0.00148,0.00015
9.5,0.792,4108.2,0.0015,0.00015
9.6,0.8,4192.09,0.00151,0.00016
9.7,0.809,4249.96,0.00152,0.00016
9.8,0.817,4353.81,0.00153,0.00016
9.9,0.825,4430.77,0.00155,0.00016
10,0.833,4508.03,0.00156,0.00017
10.1,0.842,4540.05,0.00157,0.00017
10.2,0.85,4559.32,0.00159,0.00017
10.3,0.859,4591.57,0.0016,0.00017
10.4,0.867,4723.43,0.00161,0.00017
10.5,0.875,4813.32,0.00162,0.00018
10.6,0.883,4875.74,0.00164,0.00018
10.7,0.892,4958.73,0.00165,0.00018
10.8,0.9,5026.43,0.00166,0.00019
10.9,0.909,5074.19,0.00168,0.00019
11,0.917,5110.78,0.00169,0.00019
11.1,0.925,5188.02,0.0017,0.00019
11.2,0.933,5248.64,0.00172,0.0002
11.3,0.942,5338.74,0.00173,0.0002
11.4,0.95,5435.11,0.00174,0.0002
11.5,0.958,5545.5,0.00176,0.00021
11.6,0.967,5589.04,0.00177,0.00021
11.7,0.975,5616.58,0.00178,0.00021
11.8,0.983,5658.37,0.0018,0.00021
11.9,0.992,5770.84,0.00181,0.00022
12,1,5853.41,0.00183,0.00022
12.1,1.008,5923.37,0.00184,0.00022
12.2,1.017,6010.1,0.00185,0.00022
12.3,1.025,6053.31,0.00187,0.00023
12.4,1.034,6115.02,0.00188,0.00023
12.5,1.042,6195.77,0.00189,0.00023
12.6,1.05,6300.19,0.00191,0.00024
12.7,1.058,6379.24,0.00192,0.00024
12.8,1.067,6462.58,0.00194,0.00024
12.9,1.075,6548.43,0.00195,0.00025
13,1.084,6578.34,0.00197,0.00025
13.1,1.092,6616.96,0.00198,0.00025
13.2,1.1,6666.19,0.00199,0.00025
13.3,1.108,6804.66,0.00201,0.00026
13.4,1.117,6893.37,0.00202,0.00026
13.5,1.125,7024.63,0.00204,0.00026
13.6,1.133,7120.79,0.00205,0.00027
13.7,1.142,7140.77,0.00206,0.00027
13.8,1.15,7181.11,0.00208,0.00028
13.9,1.158,7263.24,0.00209,0.00028
14,1.167,7327.77,0.00211,0.00028
14.1,1.175,7413.05,0.00212,0.00029
14.2,1.183,7514.54,0.00213,0.00029
14.3,1.192,7629.42,0.00215,0.00029
14.4,1.2,7672.74,0.00217,0.0003
14.5,1.209,7731.9,0.00218,0.0003
14.6,1.217,7865.68,0.00219,0.0003
14.7,1.225,7946.04,0.00221,0.00031
14.8,1.233,7997.92,0.00222,0.00031
14.9,1.242,8073.32,0.00224,0.00031
15,1.25,8122.59,0.00225,0.00032
15.1,1.258,8200.86,0.00227,0.00032
15.2,1.267,8297.61,0.00228,0.00032
15.3,1.275,8405.46,0.0023,0.00033
15.4,1.283,8533.48,0.00231,0.00033
15.5,1.292,8622.62,0.00233,0.00034
15.6,1.3,8681.53,0.00234,0.00034
15.7,1.308,8684.65,0.00235,0.00034
15.8,1.317,8745.08,0.00237,0.00035
15.9,1.325,8854.85,0.00239,0.00035
16,1.333,8975.89,0.0024,0.00035
16.1,1.342,9114.74,0.00242,0.00036
16.2,1.35,9180.6,0.00243,0.00036
16.3,1.359,9248.93,0.00245,0.00037
16.4,1.367,9349.39,0.00246,0.00037
16.5,1.375,9405.12,0.00248,0.00037
16.6,1.384,9473.68,0.00249,0.00038
16.7,1.392,9556.98,0.00251,0.00038
16.8,1.4,9667.36,0.00252,0.00038
16.9,1.409,9716.31,0.00254,0.00039
17,1.417,9801.43,0.00255,0.00039
17.1,1.425,9935.48,0.00257,0.0004
17.2,1.434,10066.56,0.00259,0.0004
17.3,1.442,10167.61,0.0026,0.0004
17.4,1.45,10189.02,0.00262,0.00041
17.5,1.458,10193.17,0.00263,0.00041
17.6,1.467,10298.96,0.00265,0.00042
17.7,1.475,10422.88,0.00266,0.00042
17.8,1.483,10546.6,0.00268,0.00042
17.9,1.492,10664.62,0.00269,0.00043
18,1.5,10760.72,0.00271,0.00043
18.1,1.508,10801.1,0.00273,0.00044
18.2,1.517,10855.72,0.00274,0.00044
18.3,1.525,10935.52,0.00276,0.00044
18.4,1.533,11040.24,0.00278,0.00045
18.5,1.542,11180.61,0.0028,0.00045
18.6,1.55,11252.07,0.00282,0.00045
18.7,1.558,11315.19,0.00288,0.00046
18.8,1.567,11447.9,0.00289,0.00046
18.9,1.575,11556.31,0.00291,0.00047
19,1.584,11617.01,0.00293,0.00047
19.1,1.592,11685.04,0.00294,0.00047
19.2,1.6,11732.9,0.00296,0.00048
19.3,1.608,11824.72,0.00297,0.00048
19.4,1.617,11952.86,0.00299,0.00049
19.5,1.625,12088.92,0.00301,0.00049
19.6,1.633,12231.09,0.00303,0.0005
19.7,1.642,12285.65,0.00304,0.0005
19.8,1.65,12310.24,0.00306,0.0005
19.9,1.659,12397.3,0.00307,0.00051
20,1.667,12474.77,0.00309,0.00051
20.1,1.675,12587.5,0.00311,0.00052
20.2,1.683,12741.67,0.00312,0.00052
20.3,1.692,12797.42,0.00313,0.00053
20.4,1.7,12867.27,0.00316,0.00053
20.5,1.708,12994.42,0.00317,0.00053
20.6,1.717,13069.68,0.00319,0.00054
20.7,1.725,13159.32,0.00321,0.00054
20.8,1.733,13263.15,0.00322,0.00055
20.9,1.742,13316.39,0.00324,0.00055
21,1.75,13424.77,0.00326,0.00056
21.1,1.758,13554.66,0.00328,0.00056
21.2,1.767,13659.93,0.00329,0.00056
21.3,1.775,13757.2,0.00331,0.00057
21.4,1.784,13819.68,0.00333,0.00057
21.5,1.792,13866.92,0.00335,0.00058
21.6,1.8,13968.09,0.00337,0.00058
21.7,1.809,14077.94,0.00338,0.00059
21.8,1.817,14213.08,0.0034,0.00059
21.9,1.825,14330.73,0.00342,0.00059
22,1.833,14365.06,0.00344,0.0006
22.1,1.842,14454.18,0.00346,0.0006
22.2,1.85,14546.52,0.00347,0.00061
22.3,1.858,14666.74,0.00349,0.00061
22.4,1.867,14756.7,0.00351,0.00062
22.5,1.875,14835.41,0.00353,0.00062
22.6,1.884,14923.62,0.00355,0.00063
22.7,1.892,15046.29,0.00356,0.00063
22.8,1.9,15137.43,0.00359,0.00064
22.9,1.908,15245.05,0.0036,0.00064
23,1.917,15365.2,0.00362,0.00065
23.1,1.925,15391.02,0.00364,0.00065
23.2,1.934,15483.84,0.00366,0.00066
23.3,1.942,15582.14,0.00368,0.00066
23.4,1.95,15734.8,0.0037,0.00067
23.5,1.958,15842.34,0.00372,0.00067
23.6,1.967,15877.54,0.00374,0.00068
23.7,1.975,15949.32,0.00376,0.00068
23.8,1.983,16101.05,0.00378,0.00069
23.9,1.992,16192.24,0.0038,0.0007
24,2,16305.97,0.00382,0.0007
24.1,2.008,16408.14,0.00384,0.00071
24.2,2.017,16445.37,0.00387,0.00071
24.3,2.025,16546.89,0.00388,0.00072
24.4,2.034,16654.91,0.00391,0.00072
24.5,2.042,16779.85,0.00392,0.00073
24.6,2.05,16895.2,0.00395,0.00074
24.7,2.058,16938.9,0.00397,0.00074
24.8,2.067,16996.54,0.00399,0.00075
24.9,2.075,17135.02,0.00401,0.00075
25,2.083,17235.54,0.00403,0.00076
25.1,2.092,17348.42,0.00406,0.00076
25.2,2.1,17412.34,0.00408,0.00077
25.3,2.108,17513.15,0.0041,0.00078
25.4,2.117,17621.26,0.00412,0.00078
25.5,2.125,17730.48,0.00415,0.00079
25.6,2.133,17834.25,0.00417,0.0008
25.7,2.142,17925.45,0.00419,0.0008
25.8,2.15,17950.82,0.00421,0.00081
25.9,2.159,18056.61,0.00423,0.00082
26,2.167,18183.32,0.00426,0.00082
26.1,2.175,18310.59,0.00429,0.00083
26.2,2.183,18437.1,0.00431,0.00084
26.3,2.192,18469.74,0.00433,0.00084
26.4,2.2,18522.94,0.00436,0.00085
26.5,2.209,18632.72,0.00439,0.00086
26.6,2.217,18731.74,0.00441,0.00086
26.7,2.225,18845.98,0.00443,0.00087
26.8,2.233,18965.73,0.00446,0.00088
26.9,2.242,19027.29,0.00449,0.00089
27,2.25,19138.73,0.00452,0.0009
27.1,2.258,19239.35,0.00454,0.0009
27.2,2.267,19304.58,0.00457,0.00091
27.3,2.275,19419.15,0.0046,0.00092
27.4,2.284,19481,0.00463,0.00093
27.5,2.292,19546.53,0.00466,0.00094
27.6,2.3,19674.87,0.00469,0.00095
27.7,2.308,19807.44,0.00471,0.00096
27.8,2.317,19902.67,0.00475,0.00096
27.9,2.325,19996.96,0.00477,0.00097
28,2.333,20002.49,0.00481,0.00098
28.1,2.342,20041.96,0.00483,0.00099
28.2,2.35,20179.08,0.00487,0.001
28.3,2.358,20312.62,0.0049,0.00101
28.4,2.367,20436.34,0.00494,0.00102
28.5,2.375,20530.61,0.00497,0.00103
28.6,2.384,20603.83,0.005,0.00104
28.7,2.392,20675.26,0.00504,0.00105
28.8,2.4,20728.73,0.00507,0.00106
28.9,2.408,20804.67,0.0051,0.00107
29,2.417,20937.04,0.00514,0.00108
29.1,2.425,21007.21,0.00518,0.00109
29.2,2.433,21065.17,0.00522,0.0011
29.3,2.442,21151.28,0.00525,0.00111
29.4,2.45,21272.89,0.00529,0.00112
29.5,2.458,21380.55,0.00533,0.00113
29.6,2.467,21460.6,0.00537,0.00115
29.7,2.475,21502.29,0.00541,0.00116
29.8,2.484,21508.92,0.00545,0.00117
29.9,2.492,21566.23,0.00549,0.00118
30,2.5,21710.98,0.00554,0.00119
30.1,2.508,21797.86,0.00558,0.00121
30.2,2.517,21896.06,0.00562,0.00122
30.3,2.525,22019.05,0.00567,0.00124
30.4,2.533,22107.56,0.00572,0.00125
30.5,2.542,22124.56,0.00576,0.00126
30.6,2.55,22131.31,0.00581,0.00128
30.7,2.559,22200.13,0.00586,0.0013
30.8,2.567,22254.75,0.0059,0.00131
30.9,2.575,22349.28,0.00596,0.00133
31,2.583,22433.81,0.00601,0.00134
31.1,2.592,22523.4,0.00606,0.00136
31.2,2.6,22573.65,0.00612,0.00138
31.3,2.608,22615.64,0.00617,0.00141
31.4,2.617,22650.04,0.00622,0.00144
31.5,2.625,22744.99,0.00628,0.00147
31.6,2.633,22818.37,0.00634,0.0015
31.7,2.642,22871.57,0.00639,0.00154
31.8,2.65,22912.3,0.00645,0.00157
31.9,2.658,22933.53,0.00651,0.00161
32,2.667,22983.45,0.00658,0.00164
32.1,2.675,23008.5,0.00664,0.00168
32.2,2.683,23040.79,0.0067,0.00172
32.3,2.692,23075.8,0.00677,0.00176
32.4,2.7,23116.96,0.00683,0.00181
32.5,2.708,23154.74,0.00689,0.00186
32.6,2.717,23216.97,0.00696,0.00191
32.7,2.725,23280.49,0.00703,0.00196
32.8,2.734,23328.8,0.0071,0.00202
32.9,2.742,23382.03,0.00717,0.00208
33,2.75,23437.78,0.00724,0.00214
33.1,2.759,23477.62,0.00731,0.00221
33.2,2.767,23523.26,0.00738,0.00228
33.3,2.775,23580.42,0.00746,0.00235
33.4,2.784,23610.69,0.00753,0.00242
33.5,2.792,23622.09,0.00761,0.00249
33.6,2.8,23624.33,0.00769,0.00255
33.7,2.808,23626.21,0.00777,0.00262
33.8,2.817,23627.03,0.00785,0.00268
33.9,2.825,23629.57,0.00794,0.00274
34,2.834,23635.95,0.00802,0.0028
34.1,2.842,23661.83,0.0081,0.00286
34.2,2.85,23698.84,0.00818,0.00291
34.3,2.858,23738.43,0.00828,0.00297
34.4,2.867,23756.17,0.00836,0.00303
34.5,2.875,23768.04,0.00845,0.00309
34.6,2.884,23793.8,0.00854,0.00316
34.7,2.892,23822.31,0.00862,0.00324
34.8,2.9,23856.94,0.00872,0.00331
34.9,2.909,23894.6,0.00881,0.00339
35,2.917,23922.76,0.0089,0.00346
35.1,2.925,23944.78,0.00899,0.00353
35.2,2.934,23966.12,0.00909,0.0036
35.3,2.942,23993.38,0.00919,0.00368
35.4,2.95,24023.13,0.00928,0.00376
35.5,2.959,24055.52,0.00938,0.00383
35.6,2.967,24077.48,0.00948,0.0039
35.7,2.975,24093.85,0.00958,0.00397
35.8,2.983,24102.12,0.00968,0.00404
35.9,2.992,24114.5,0.00978,0.00412
36,3,24125.53,0.00988,0.00419
36.1,3.009,24135.19,0.00999,0.00427
36.2,3.017,24146.57,0.01009,0.00435
36.3,3.025,24156.22,0.01019,0.00444
36.4,3.033,24172.1,0.0103,0.00452
36.5,3.042,24179.84,0.01041,0.00459
36.6,3.05,24188.16,0.01051,0.00467
36.7,3.059,24190.92,0.01062,0.00475
36.8,3.067,24198.68,0.01073,0.00484
36.9,3.075,24206.46,0.01085,0.00493
37,3.083,24214.68,0.01095,0.00503
37.1,3.092,24223.31,0.01106,0.00512
37.2,3.1,24235.11,0.01117,0.00521
37.3,3.109,24256.77,0.01129,0.00529
37.4,3.117,24275.11,0.0114,0.00538
37.5,3.125,24291.17,0.01151,0.00547
37.6,3.134,24308.43,0.01163,0.00555
37.7,3.142,24318.51,0.01175,0.00564
37.8,3.15,24324.55,0.01186,0.00573
37.9,3.158,24336.05,0.01198,0.00582
38,3.167,24340.46,0.0121,0.00592
38.1,3.175,24345.73,0.01222,0.00601
38.2,3.183,24355.01,0.01233,0.00611
38.3,3.192,24355.41,0.01245,0.00621
38.4,3.2,24365.78,0.01257,0.00631
38.5,3.208,24371.88,0.01269,0.0064
38.6,3.217,24379.28,0.01281,0.00649
38.7,3.225,24387.86,0.01293,0.00659
38.8,3.233,24394.08,0.01305,0.00671
38.9,3.242,24401.85,0.01317,0.00682
39,3.25,24407.64,0.01329,0.00691
39.1,3.258,24414.55,0.01342,0.007
39.2,3.267,24419.71,0.01354,0.00709
39.3,3.275,24427.95,0.01367,0.00718
39.4,3.284,24433.08,0.01379,0.00726
39.5,3.292,24441.45,0.01392,0.00734
39.6,3.3,24452.9,0.01404,0.00742
39.7,3.308,24471.09,0.01416,0.00751
39.8,3.317,24482.05,0.01429,0.00761
39.9,3.325,24492.64,0.01441,0.00769
40,3.334,24514,0.01454,0.00779
40.1,3.342,24526.88,0.01467,0.00788
40.2,3.35,24528.43,0.0148,0.00798
40.3,3.359,24548.99,0.01492,0.00808
40.4,3.367,24556.6,0.01505,0.00818
40.5,3.375,24557.84,0.01517,0.00827
40.6,3.383,24566.49,0.0153,0.00835
40.7,3.392,24571.6,0.01542,0.00843
40.8,3.4,24575.19,0.01555,0.00852
40.9,3.408,24580.45,0.01568,0.00861
41,3.417,24582.41,0.01581,0.0087
41.1,3.425,24589.03,0.01594,0.00879
41.2,3.433,24588.52,0.01607,0.00888
41.3,3.442,24591.54,0.0162,0.00897
41.4,3.45,24599.9,0.01633,0.00905
41.5,3.459,24597.54,0.01647,0.00914
41.6,3.467,24603.06,0.01659,0.00923
41.7,3.475,24608.38,0.01672,0.00933
41.8,3.483,24613.32,0.01685,0.00943
41.9,3.492,24618.63,0.01698,0.00952
42,3.5,24622.45,0.01711,0.00961
42.1,3.509,24626.41,0.01724,0.0097
42.2,3.517,24628.63,0.01737,0.00979
42.3,3.525,24632.31,0.0175,0.00987
42.4,3.533,24640.91,0.01763,0.00995
42.5,3.542,24648.69,0.01776,0.01004
42.6,3.55,24648.61,0.01789,0.01014
42.7,3.559,24655.07,0.01802,0.01023
42.8,3.567,24657.93,0.01815,0.01032
42.9,3.575,24667.16,0.01828,0.0104
43,3.584,24675.51,0.01841,0.01049
43.1,3.592,24676.62,0.01854,0.01058
43.2,3.6,24680.16,0.01868,0.01066
43.3,3.609,24690.05,0.01881,0.01075
43.4,3.617,24692.33,0.01894,0.01083
43.5,3.625,24697.66,0.01907,0.01092
43.6,3.634,24705.6,0.0192,0.01101
43.7,3.642,24716.94,0.01933,0.01109
43.8,3.65,24720.86,0.01946,0.01117
43.9,3.658,24728.05,0.01959,0.01126
44,3.667,24744.25,0.01972,0.01134
44.1,3.675,24758.07,0.01985,0.01143
44.2,3.684,24768.15,0.01999,0.01153
44.3,3.692,24781.37,0.02013,0.01163
44.4,3.7,24786.45,0.02026,0.01172
44.5,3.708,24796.39,0.02038,0.01182
44.6,3.717,24813.42,0.02052,0.01192
44.7,3.725,24815.73,0.02065,0.01201
44.8,3.734,24824.61,0.02078,0.0121
44.9,3.742,24831.82,0.02091,0.01219
45,3.75,24844.68,0.02104,0.01228
45.1,3.758,24844.26,0.02118,0.01237
45.2,3.767,24849.64,0.02131,0.01245
45.3,3.775,24858.03,0.02144,0.01254
45.4,3.783,24861.69,0.02157,0.01263
45.5,3.792,24869.02,0.02171,0.01272
45.6,3.8,24874.22,0.02184,0.01281
45.7,3.808,24878.81,0.02197,0.0129
45.8,3.817,24882.17,0.0221,0.01299
45.9,3.825,24888.52,0.02224,0.01308
46,3.833,24892.38,0.02236,0.01318
46.1,3.842,24898.14,0.0225,0.01327
46.2,3.85,24904.56,0.02263,0.01336
46.3,3.858,24910.4,0.02276,0.01345
46.4,3.867,24915.33,0.02289,0.01354
46.5,3.875,24922.74,0.02303,0.01363
46.6,3.883,24929.1,0.02316,0.01372
46.7,3.892,24937.3,0.02329,0.01381
46.8,3.9,24942.27,0.02343,0.0139
46.9,3.909,24946.82,0.02355,0.01399
47,3.917,24953.76,0.02368,0.01408
47.1,3.925,24958.64,0.02381,0.01417
47.2,3.933,24962.85,0.02395,0.01427
47.3,3.942,24962.61,0.02408,0.01436
47.4,3.95,24974.85,0.02421,0.01445
47.5,3.959,24976.83,0.02434,0.01454
47.6,3.967,24980.55,0.02447,0.01463
47.7,3.975,24983.2,0.02461,0.01472
47.8,3.983,24989.43,0.02474,0.01482
47.9,3.992,24996.48,0.02487,0.01491
48,4,24997.39,0.025,0.015
48.1,4.008,25002.76,0.02513,0.01509
48.2,4.017,25009.2,0.02526,0.01518
48.3,4.025,25016.75,0.02539,0.01526
48.4,4.034,25018.97,0.02552,0.01535
48.5,4.042,25026.53,0.02565,0.01544
48.6,4.05,25037.25,0.02579,0.01553
48.7,4.058,25041.02,0.02592,0.01562
48.8,4.067,25045.74,0.02605,0.01571
48.9,4.075,25056.04,0.02618,0.01579
49,4.084,25062.28,0.02632,0.01588
49.1,4.092,25070.72,0.02644,0.01597
49.2,4.1,25075.97,0.02658,0.01606
49.3,4.108,25076.78,0.0267,0.01614
49.4,4.117,25088.46,0.02683,0.01623
49.5,4.125,25098.67,0.02697,0.01631
49.6,4.134,25100.59,0.0271,0.0164
49.7,4.142,25104.89,0.02723,0.01649
49.8,4.15,25110.54,0.02736,0.01658
49.9,4.158,25112.7,0.02749,0.01666
50,4.167,25115.32,0.02763,0.01675
50.1,4.175,25115.64,0.02776,0.01683
50.2,4.183,25118.19,0.02788,0.01692
50.3,4.192,25121.83,0.02802,0.017
50.4,4.2,25121.92,0.02815,0.01708
50.5,4.208,25125.32,0.02827,0.01716
50.6,4.217,25127.37,0.02841,0.01725
50.7,4.225,25125.53,0.02854,0.01734
50.8,4.234,25132.26,0.02867,0.01743
50.9,4.242,25131.86,0.0288,0.01751
51,4.25,25130.31,0.02893,0.01759
51.1,4.259,25134.39,0.02906,0.01768
51.2,4.267,25135.91,0.02919,0.01777
51.3,4.275,25139.31,0.02932,0.01785
51.4,4.283,25142.89,0.02945,0.01794
51.5,4.292,25148.45,0.02957,0.01803
51.6,4.3,25149.38,0.02971,0.01812
51.7,4.308,25152.95,0.02984,0.01821
51.8,4.317,25154.49,0.02997,0.0183
51.9,4.325,25163.8,0.0301,0.01839
52,4.333,25165.71,0.03024,0.01847
52.1,4.342,25167.28,0.03037,0.01856
52.2,4.35,25168.08,0.03049,0.01865
52.3,4.358,25168.26,0.03063,0.01874
52.4,4.367,25168.49,0.03076,0.01883
52.5,4.375,25165.31,0.03089,0.01891
52.6,4.383,25169.03,0.03102,0.019
52.7,4.392,25169.9,0.03115,0.01909
52.8,4.4,25169.38,0.03128,0.01917
52.9,4.409,25170.78,0.03141,0.01926
53,4.417,25172.39,0.03154,0.01934
53.1,4.425,25174.57,0.03167,0.01943
53.2,4.434,25173.08,0.0318,0.01951
53.3,4.442,25176.71,0.03193,0.01959
53.4,4.45,25175.96,0.03206,0.01967
53.5,4.459,25177.24,0.03219,0.01974
53.6,4.467,25178.79,0.03232,0.01982
53.7,4.475,25179.68,0.03245,0.0199
53.8,4.483,25183.33,0.03259,0.01998
53.9,4.492,25185.33,0.03271,0.02006
54,4.5,25186.25,0.03284,0.02014
54.1,4.508,25189.32,0.03297,0.02022
54.2,4.517,25193.26,0.0331,0.02031
54.3,4.525,25197.1,0.03324,0.02039
54.4,4.533,25198.25,0.03337,0.02047
54.5,4.542,25201.03,0.0335,0.02054
54.6,4.55,25207.23,0.03362,0.02061
54.7,4.558,25215.65,0.03375,0.02068
54.8,4.567,25218.26,0.03389,0.02075
54.9,4.575,25231.62,0.03402,0.02083
55,4.584,25236.23,0.03415,0.0209
55.1,4.592,25247.27,0.03428,0.02097
55.2,4.6,25248.12,0.03441,0.02105
55.3,4.609,25258.06,0.03455,0.02112
55.4,4.617,25262.78,0.03467,0.0212
55.5,4.625,25269.09,0.0348,0.02128
55.6,4.634,25274.98,0.03493,0.02135
55.7,4.642,25287.77,0.03506,0.02143
55.8,4.65,25291.34,0.03519,0.02152
55.9,4.659,25297.18,0.03532,0.0216
56,4.667,25310.79,0.03545,0.02169
56.1,4.675,25312.31,0.03558,0.02178
56.2,4.683,25315.06,0.03571,0.02186
56.3,4.692,25323.84,0.03584,0.02194
56.4,4.7,25330.28,0.03597,0.02203
56.5,4.709,25334.59,0.0361,0.02211
56.6,4.717,25343.62,0.03623,0.0222
56.7,4.725,25343.64,0.03636,0.02228
56.8,4.733,25351.52,0.03649,0.02236
56.9,4.742,25355.71,0.03662,0.02244
57,4.75,25369.51,0.03675,0.02252
57.1,4.759,25372.38,0.03688,0.0226
57.2,4.767,25375.33,0.03701,0.02268
57.3,4.775,25378.46,0.03714,0.02276
57.4,4.783,25387.49,0.03728,0.02284
57.5,4.792,25390.94,0.03741,0.02292
57.6,4.8,25392.98,0.03754,0.023
57.7,4.809,25401.2,0.03766,0.02307
57.8,4.817,25407.39,0.0378,0.02315
57.9,4.825,25412.51,0.03793,0.02322
58,4.834,25418.74,0.03805,0.02329
58.1,4.842,25424.78,0.03819,0.02336
58.2,4.85,25426.16,0.03832,0.02344
58.3,4.858,25429.92,0.03845,0.02352
58.4,4.867,25437.13,0.03857,0.0236
58.5,4.875,25445.23,0.0387,0.02369
58.6,4.883,25451.97,0.03883,0.02377
58.7,4.892,25450.57,0.03896,0.02386
58.8,4.9,25454.16,0.03909,0.02393
58.9,4.908,25461.6,0.03922,0.02401
59,4.917,25463.36,0.03935,0.02409
59.1,4.925,25466.6,0.03948,0.02417
59.2,4.934,25471.92,0.03961,0.02425
59.3,4.942,25475.07,0.03974,0.02434
59.4,4.95,25477.02,0.03987,0.02442
59.5,4.958,25477.9,0.04,0.0245
59.6,4.967,25483.72,0.04013,0.02458
59.7,4.975,25487.2,0.04026,0.02466
59.8,4.984,25494.07,0.0404,0.02474
59.9,4.992,25495.45,0.04052,0.02482
60,5,25500.72,0.04066,0.0249
60.1,5.008,25505.06,0.04078,0.02471
60.2,5.017,25513.81,0.04091,0.02478
60.3,5.025,25516.77,0.04104,0.02481
60.4,5.034,25524.28,0.04117,0.02485
60.5,5.042,25528.92,0.04131,0.02489
60.6,5.05,25532.17,0.04144,0.02493
60.7,5.058,25541.41,0.04157,0.02498
60.8,5.067,25551.76,0.0417,0.02502
60.9,5.075,25550.16,0.04182,0.02506
61,5.083,25559.29,0.04195,0.0251
61.1,5.092,25570.3,0.04209,0.02513
61.2,5.1,25576.96,0.04222,0.02518
61.3,5.108,25582.56,0.04235,0.02521
61.4,5.117,25600.15,0.04248,0.02526
61.5,5.125,25600.53,0.04262,0.02532
61.6,5.133,25598.81,0.04274,0.02538
61.7,5.142,25612.2,0.04287,0.02544
61.8,5.15,25620.03,0.043,0.0255
61.9,5.159,25621.26,0.04313,0.02557
62,5.167,25624.34,0.04327,0.02563
62.1,5.175,25628.16,0.0434,0.0257
62.2,5.184,25637.75,0.04353,0.02577
62.3,5.192,25638.58,0.04366,0.02585
62.4,5.2,25646.9,0.04379,0.02594
62.5,5.209,25643.25,0.04392,0.02603
62.6,5.217,25653.53,0.04405,0.02611
62.7,5.225,25651.38,0.04419,0.0262
62.8,5.233,25651.19,0.04431,0.02629
62.9,5.242,25654.19,0.04445,0.0264
63,5.25,25658.77,0.04458,0.02659
63.1,5.258,25661.18,0.04471,0.02663
63.2,5.267,25660.6,0.04483,0.02666
63.3,5.275,25664.01,0.04496,0.02669
63.4,5.283,25665.42,0.04509,0.02674
63.5,5.292,25667.4,0.04523,0.02678
63.6,5.3,25668.55,0.04536,0.0269
63.7,5.308,25667.98,0.04549,0.0271
63.8,5.317,25671.75,0.04562,0.02715
63.9,5.325,25670.93,0.04575,0.02721
64,5.334,25672.99,0.04588,0.02725
64.1,5.342,25675.2,0.04601,0.0273
64.2,5.35,25675,0.04614,0.02734
64.3,5.358,25675.11,0.04627,0.02738
64.4,5.367,25677.88,0.0464,0.02743
64.5,5.375,25677.71,0.04653,0.02748
64.6,5.384,25680.39,0.04667,0.02755
64.7,5.392,25678.99,0.0468,0.02762
64.8,5.4,25680.56,0.04693,0.0277
64.9,5.408,25680.04,0.04706,0.02778
65,5.417,25682.38,0.04719,0.02786
65.1,5.425,25683.28,0.04732,0.02795
65.2,5.434,25684.12,0.04746,0.02804
65.3,5.442,25683.31,0.04759,0.02812
65.4,5.45,25683.81,0.04772,0.02821
65.5,5.458,25685.13,0.04785,0.02829
65.6,5.467,25685.93,0.04797,0.02837
65.7,5.475,25687.1,0.04811,0.02844
65.8,5.483,25688.04,0.04824,0.02852
65.9,5.492,25688.11,0.04836,0.02859
66,5.5,25690.46,0.0485,0.02867
66.1,5.508,25690.74,0.04863,0.02876
66.2,5.517,25691.67,0.04876,0.02884
66.3,5.525,25691.43,0.04889,0.02893
66.4,5.534,25692.62,0.04902,0.02901
66.5,5.542,25692.42,0.04915,0.02908
66.6,5.55,25694.37,0.04928,0.02916
66.7,5.559,25696.73,0.04942,0.02925
66.8,5.567,25698.9,0.04955,0.02935
66.9,5.575,25698.1,0.04968,0.02959
67,5.584,25699.57,0.04981,0.02964
67.1,5.592,25699.57,0.04994,0.02968
67.2,5.6,25703.39,0.05007,0.02973
67.3,5.609,25701.13,0.0502,0.02981
67.4,5.617,25704.19,0.05034,0.02988
67.5,5.625,25704.67,0.05047,0.02995
67.6,5.633,25706.69,0.0506,0.03002
67.7,5.642,25708,0.05073,0.03009
67.8,5.65,25712.69,0.05087,0.03016
67.9,5.658,25714.35,0.051,0.03022
68,5.667,25721.32,0.05113,0.03031
68.1,5.675,25716.7,0.05126,0.0304
68.2,5.683,25722.41,0.05139,0.03108
68.3,5.692,25724.57,0.05153,0.03111
68.4,5.7,25728.01,0.05166,0.03115
68.5,5.709,25724.83,0.05179,0.03119
68.6,5.717,25731.4,0.05191,0.03123
68.7,5.725,25740.75,0.05205,0.03127
68.8,5.734,25746.18,0.05218,0.03131
68.9,5.742,25746.2,0.05231,0.03136
69,5.75,25749.2,0.05245,0.0314
69.1,5.759,25750.06,0.05258,0.03146
69.2,5.767,25750.92,0.05272,0.03152
69.3,5.775,25760.73,0.05285,0.03158
69.4,5.784,25766.38,0.05298,0.03163
69.5,5.792,25768.18,0.05311,0.0317
69.6,5.8,25770.23,0.05325,0.03176
69.7,5.808,25775.87,0.05338,0.03183
69.8,5.817,25777.7,0.05351,0.0319
69.9,5.825,25783.81,0.05365,0.03196
70,5.834,25791.64,0.05378,0.03203
70.1,5.842,25792.08,0.05391,0.0321
70.2,5.85,25793.4,0.05404,0.03217
70.3,5.858,25793.74,0.05418,0.03228
70.4,5.867,25798.13,0.05431,0.03232
70.5,5.875,25800.61,0.05445,0.03238
70.6,5.884,25802.17,0.05458,0.03244
70.7,5.892,25807.31,0.05471,0.0325
70.8,5.9,25810.31,0.05485,0.03257
70.9,5.908,25814.71,0.05498,0.03264
71,5.917,25815.62,0.05511,0.03271
71.1,5.925,25819.63,0.05524,0.03278
71.2,5.934,25824.43,0.05537,0.03285
71.3,5.942,25824.98,0.05551,0.03291
71.4,5.95,25824.85,0.05564,0.03298
71.5,5.959,25826.96,0.05578,0.03305
71.6,5.967,25828.77,0.05591,0.03312
71.7,5.975,25835.11,0.05604,0.03319
71.8,5.983,25835.72,0.05618,0.03325
71.9,5.992,25832.62,0.05631,0.03332
72,6,25838.52,0.05645,0.03338
72.1,6.008,25844.73,0.05658,0.03345
72.2,6.017,25843.67,0.05671,0.03351
72.3,6.025,25845.97,0.05684,0.03358
72.4,6.033,25849.07,0.05698,0.03365
72.5,6.042,25848.13,0.05711,0.03371
72.6,6.05,25851.76,0.05725,0.03378
72.7,6.059,25852.62,0.05738,0.03385
72.8,6.067,25852.73,0.05751,0.03392
72.9,6.075,25858.7,0.05765,0.03399
73,6.083,25863.03,0.05778,0.03406
73.1,6.092,25867.29,0.05791,0.03413
73.2,6.1,25863.97,0.05805,0.0342
73.3,6.109,25872.07,0.05819,0.03427
73.4,6.117,25875.69,0.05832,0.03434
73.5,6.125,25875.58,0.05845,0.03441
73.6,6.134,25878.65,0.05859,0.03448
73.7,6.142,25886.09,0.05872,0.03455
73.8,6.15,25883.9,0.05886,0.03462
73.9,6.159,25883.98,0.05899,0.03469
74,6.167,25890.12,0.05913,0.03476
74.1,6.175,25902.76,0.05926,0.03483
74.2,6.183,25900.54,0.05939,0.0349
74.3,6.192,25908.96,0.05953,0.03497
74.4,6.2,25906.37,0.05967,0.03504
74.5,6.208,25912.31,0.0598,0.0351
74.6,6.217,25909.48,0.05993,0.03517
74.7,6.225,25914.36,0.06007,0.03524
74.8,6.234,25914.35,0.06021,0.03531
74.9,6.242,25918.63,0.06034,0.03538
75,6.25,25916.75,0.06048,0.03544
75.1,6.258,25927.37,0.06061,0.03551
75.2,6.267,25934.6,0.06075,0.03558
75.3,6.275,25934.12,0.06089,0.03565
75.4,6.284,25937.57,0.06102,0.03573
75.5,6.292,25942.17,0.06116,0.0358
75.6,6.3,25942.85,0.0613,0.03579
75.7,6.308,25944.18,0.06143,0.03582
75.8,6.317,25953.26,0.06157,0.03587
75.9,6.325,25955.96,0.06171,0.03593
76,6.334,25948.62,0.06184,0.036
76.1,6.342,25957.54,0.06197,0.03605
76.2,6.35,25960.88,0.0621,0.03484
76.3,6.358,25959.06,0.06224,0.03466
76.4,6.367,25969.85,0.06237,0.03468
76.5,6.375,25967.02,0.06251,0.03472
76.6,6.384,25972.6,0.06265,0.03474
76.7,6.392,25969.01,0.06279,0.03478
76.8,6.4,25970.53,0.06292,0.03481
76.9,6.408,25975.15,0.06306,0.03485
77,6.417,25979.37,0.06319,0.03489
77.1,6.425,25977.63,0.06333,0.03492
77.2,6.433,25980.78,0.06347,0.03496
77.3,6.442,25984.56,0.0636,0.035
77.4,6.45,25985.81,0.06374,0.03503
77.5,6.459,25987.24,0.06388,0.03507
77.6,6.467,25990.14,0.06402,0.03511
77.7,6.475,25988.08,0.06416,0.03515
77.8,6.483,25991.63,0.06429,0.0352
77.9,6.492,25993.39,0.06443,0.03524
78,6.5,25990.4,0.06457,0.0353
78.1,6.509,25994,0.06471,0.03535
78.2,6.517,25998.32,0.06485,0.03541
78.3,6.525,25994.79,0.06498,0.03546
78.4,6.534,25998.96,0.06512,0.03553
78.5,6.542,25999.85,0.06525,0.0356
78.6,6.55,26000.18,0.0654,0.03567
78.7,6.558,26001.44,0.06553,0.03574
78.8,6.567,26001.98,0.06567,0.03581
78.9,6.575,26003.67,0.06581,0.03589
79,6.583,26005.2,0.06595,0.03596
79.1,6.592,26007.35,0.06608,0.03604
79.2,6.6,26011.15,0.06622,0.03612
79.3,6.608,26010.69,0.06636,0.0362
79.4,6.617,26008.43,0.06649,0.03629
79.5,6.625,26015.36,0.06663,0.03637
79.6,6.634,26019.34,0.06678,0.03645
79.7,6.642,26017.11,0.06691,0.03653
79.8,6.65,26019.07,0.06705,0.03661
79.9,6.659,26019.24,0.06719,0.03669
80,6.667,26018.93,0.06733,0.03677
80.1,6.675,26019,0.06746,0.03685
80.2,6.684,26022.29,0.0676,0.03693
80.3,6.692,26026.13,0.06774,0.037
80.4,6.7,26023.33,0.06788,0.03707
80.5,6.708,26029.67,0.06802,0.03713
80.6,6.717,26030.45,0.06816,0.03719
80.7,6.725,26033.32,0.0683,0.03724
80.8,6.734,26036.27,0.06844,0.03728
80.9,6.742,26034.74,0.06859,0.03733
81,6.75,26032.22,0.06873,0.03738
81.1,6.758,26037.81,0.06886,0.03743
81.2,6.767,26038.46,0.069,0.03747
81.3,6.775,26037.12,0.06914,0.03751
81.4,6.784,26042.02,0.06928,0.03755
81.5,6.792,26039.92,0.06942,0.0376
81.6,6.8,26050.04,0.06956,0.03764
81.7,6.808,26043.88,0.0697,0.03768
81.8,6.817,26048.43,0.06984,0.03772
81.9,6.825,26045.02,0.06998,0.03776
82,6.834,26045.88,0.07012,0.03781
82.1,6.842,26044.77,0.07026,0.03785
82.2,6.85,26046.73,0.0704,0.03789
82.3,6.859,26050.41,0.07054,0.03793
82.4,6.867,26050.81,0.07068,0.03797
82.5,6.875,26054.71,0.07082,0.03802
82.6,6.884,26047.55,0.07096,0.03806
82.7,6.892,26059.36,0.0711,0.0381
82.8,6.9,26049.19,0.07125,0.03814
82.9,6.909,26073.01,0.07139,0.03813
83,6.917,26078.26,0.07152,0.03817
83.1,6.925,26070.79,0.07167,0.03821
83.2,6.933,26073.27,0.07181,0.03825
83.3,6.942,26063.98,0.07195,0.03829
83.4,6.95,26083.45,0.07209,0.03833
83.5,6.958,26084.1,0.07223,0.03836
83.6,6.967,26084.61,0.07237,0.0384
83.7,6.975,26086.05,0.07252,0.03844
83.8,6.983,26085.49,0.07266,0.03848
83.9,6.992,26062.18,0.0728,0.03851
84,7,26093.93,0.07294,0.03854
84.1,7.008,26097.8,0.07309,0.03858
84.2,7.017,26093.42,0.07323,0.03863
84.3,7.025,26094.27,0.07337,0.03867
84.4,7.033,26099.66,0.07351,0.03871
84.5,7.042,26098.62,0.07365,0.03874
84.6,7.05,26095.32,0.0738,0.03877
84.7,7.058,26097.59,0.07394,0.03881
84.8,7.067,26096.9,0.07408,0.03884
84.9,7.075,26100.13,0.07422,0.03887
85,7.083,26100.36,0.07436,0.0389
85.1,7.092,26104.01,0.07451,0.03893
85.2,7.1,26109.68,0.07465,0.03896
85.3,7.108,26104.51,0.0748,0.03899
85.4,7.117,26105.68,0.07493,0.03902
85.5,7.125,26109.12,0.07508,0.03905
85.6,7.134,26116.43,0.07522,0.03902
85.7,7.142,26112.89,0.07537,0.03901
85.8,7.15,26109.69,0.07551,0.03903
85.9,7.158,26111.55,0.07565,0.03906
86,7.167,26116.3,0.0758,0.0391
86.1,7.175,26119.48,0.07594,0.03912
86.2,7.183,26117.17,0.07608,0.03915
86.3,7.192,26113.22,0.07623,0.03917
86.4,7.2,26116.31,0.07637,0.03919
86.5,7.208,26118.19,0.07652,0.03919
86.6,7.217,26115.11,0.07666,0.03922
86.7,7.225,26118.68,0.0768,0.03924
86.8,7.234,26119.96,0.07695,0.0392
86.9,7.242,26121.53,0.07709,0.0392
87,7.25,26119.37,0.07723,0.03922
87.1,7.258,26121.04,0.07737,0.03926
87.2,7.267,26126.99,0.07752,0.03929
87.3,7.275,26127.73,0.07766,0.03931
87.4,7.284,26124.4,0.07781,0.0393
87.5,7.292,26121.14,0.07795,0.0392
87.6,7.3,26130.8,0.0781,0.03891
87.7,7.309,26124.95,0.07825,0.03894
87.8,7.317,26128.5,0.07839,0.03897
87.9,7.325,26131.19,0.07853,0.039
88,7.333,26125.58,0.07868,0.03903
88.1,7.342,26133.38,0.07883,0.03906
88.2,7.35,26131.49,0.07897,0.03909
88.3,7.358,26132.69,0.07912,0.0391
88.4,7.367,26135.37,0.07927,0.03914
88.5,7.375,26130.82,0.07941,0.03917
88.6,7.383,26133.19,0.07956,0.03921
88.7,7.392,26135.35,0.07971,0.03924
88.8,7.4,26136.68,0.07985,0.03896
88.9,7.409,26134.86,0.08,0.03825
89,7.417,26134.09,0.08014,0.03829
89.1,7.425,26137.74,0.08029,0.03831
89.2,7.434,26133.93,0.08043,0.03835
89.3,7.442,26139.85,0.08058,0.03838
89.4,7.45,26139.05,0.08073,0.03842
89.5,7.459,26140.96,0.08088,0.03845
89.6,7.467,26137.96,0.08102,0.03848
89.7,7.475,26139.14,0.08117,0.03852
89.8,7.484,26139.15,0.08131,0.03855
89.9,7.492,26140.21,0.08146,0.03858
90,7.5,26141.35,0.0816,0.03862
90.1,7.508,26140.65,0.08175,0.03866
90.2,7.517,26144.59,0.0819,0.0387
90.3,7.525,26141.77,0.08205,0.03874
90.4,7.533,26144.1,0.0822,0.03877
90.5,7.542,26146.81,0.08235,0.03881
90.6,7.55,26144.91,0.08249,0.03884
90.7,7.558,26145.1,0.08264,0.03887
90.8,7.567,26146.07,0.08279,0.03891
90.9,7.575,26148.58,0.08294,0.03895
91,7.584,26148.31,0.08309,0.03898
91.1,7.592,26147.56,0.08324,0.03902
91.2,7.6,26146.58,0.08338,0.03906
91.3,7.608,26149.15,0.08353,0.03909
91.4,7.617,26151.21,0.08368,0.03913
91.5,7.625,26148.51,0.08383,0.03916
91.6,7.634,26146.55,0.08397,0.03919
91.7,7.642,26149.15,0.08412,0.03923
91.8,7.65,26147.72,0.08427,0.03928
91.9,7.659,26149.12,0.08442,0.03932
92,7.667,26147.64,0.08456,0.03936
92.1,7.675,26148.77,0.08471,0.03939
92.2,7.683,26153.32,0.08486,0.03942
92.3,7.692,26152.11,0.08501,0.03946
92.4,7.7,26153.29,0.08516,0.03949
92.5,7.709,26156.68,0.0853,0.03955
92.6,7.717,26153,0.08545,0.03948
92.7,7.725,26152.34,0.0856,0.03947
92.8,7.734,26157.62,0.08575,0.03949
92.9,7.742,26150.04,0.08589,0.03952
93,7.75,26151.62,0.08604,0.03955
93.1,7.759,26150.7,0.08619,0.03959
93.2,7.767,26154.69,0.08634,0.03963
93.3,7.775,26154.41,0.08649,0.03967
93.4,7.783,26155.48,0.08663,0.03971
93.5,7.792,26152.4,0.08678,0.03976
93.6,7.8,26158.57,0.08693,0.03926
93.7,7.809,26156.48,0.08708,0.03929
93.8,7.817,26156.08,0.08723,0.03932
93.9,7.825,26153.78,0.08738,0.03934
94,7.834,26156.46,0.08752,0.03938
94.1,7.842,26144.47,0.08767,0.03942
94.2,7.85,26154.02,0.08782,0.03947
94.3,7.859,26149.23,0.08796,0.03952
94.4,7.867,26150.82,0.08811,0.03956
94.5,7.875,26150.07,0.08825,0.0396
94.6,7.883,26154.71,0.0884,0.03963
94.7,7.892,26161.95,0.08855,0.03967
94.8,7.9,26158.69,0.08869,0.03971
94.9,7.908,26154.76,0.08884,0.03974
95,7.917,26153.08,0.08899,0.03974
95.1,7.925,26157.54,0.08914,0.03968
95.2,7.934,26150.85,0.08929,0.03963
95.3,7.942,26154,0.08943,0.03965
95.4,7.95,26153.62,0.08958,0.03967
95.5,7.959,26150.93,0.08972,0.03968
95.6,7.967,26154.88,0.08987,0.03967
95.7,7.975,26157.35,0.09001,0.03967
95.8,7.984,26154.92,0.09016,0.03968
95.9,7.992,26153.62,0.09031,0.0397
96,8,26151.3,0.09046,0.03972
96.1,8.009,26153.4,0.0906,0.03974
96.2,8.017,26152.72,0.09075,0.03976
96.3,8.025,26152.35,0.09089,0.03979
96.4,8.034,26157.54,0.09104,0.0398
96.5,8.042,26152.21,0.09118,0.03983
96.6,8.05,26153.56,0.09133,0.03985
96.7,8.058,26150.83,0.09147,0.03987
96.8,8.067,26155.57,0.09161,0.03988
96.9,8.075,26152.11,0.09176,0.03986
97,8.084,26155.28,0.09191,0.03979
97.1,8.092,26148.13,0.09205,0.0398
97.2,8.1,26145.61,0.09219,0.03981
97.3,8.108,26149.89,0.09233,0.0398
97.4,8.117,26152.45,0.09247,0.03981
97.5,8.125,26147.35,0.09261,0.03984
97.6,8.133,26150.58,0.09275,0.03987
97.7,8.142,26147.5,0.0929,0.03989
97.8,8.15,26149.98,0.09304,0.0397
97.9,8.158,26147.75,0.09318,0.03962
98,8.167,26148.45,0.09332,0.03964
98.1,8.175,26145.76,0.09346,0.03966
98.2,8.183,26147.13,0.0936,0.03969
98.3,8.192,26146.32,0.09374,0.03971
98.4,8.2,26146.36,0.09387,0.03973
98.5,8.209,26147.6,0.09402,0.03976
98.6,8.217,26142.09,0.09415,0.03978
98.7,8.225,26145.47,0.09429,0.0398
98.8,8.233,26140.46,0.09442,0.03982
98.9,8.242,26141.51,0.09456,0.03985
99,8.25,26144.32,0.09469,0.03987
99.1,8.259,26141.99,0.09483,0.03991
99.2,8.267,26136.11,0.09496,0.03993
99.3,8.275,26136.61,0.0951,0.03995
99.4,8.283,26134.97,0.09523,0.03997
99.5,8.292,26137.54,0.09536,0.04
99.6,8.3,26136.69,0.09549,0.04002
99.7,8.308,26131.39,0.09562,0.04004
99.8,8.317,26130.79,0.09575,0.04007
99.9,8.325,26130.24,0.09588,0.04009
100,8.333,26132.74,0.09601,0.04011
100.1,8.342,26133.46,0.09614,0.04013
100.2,8.35,26130.01,0.09627,0.04015
100.3,8.358,26127.69,0.09639,0.04017
100.4,8.367,26130.29,0.09652,0.04019
100.5,8.375,26125.73,0.09664,0.04021
100.6,8.384,26125.99,0.09676,0.04023
100.7,8.392,26123.15,0.09689,0.04026
100.8,8.4,26125.72,0.09701,0.04028
100.9,8.409,26122.7,0.09713,0.0403
101,8.417,26120.54,0.09725,0.04032
101.1,8.425,26122.42,0.09738,0.04033
101.2,8.434,26115.59,0.0975,0.04036
101.3,8.442,26114.83,0.09762,0.04037
101.4,8.45,26108.53,0.09773,0.04039
101.5,8.458,26108.95,0.09784,0.0404
101.6,8.467,26110.41,0.09796,0.04028
101.7,8.475,26107.17,0.09807,0.04026
101.8,8.484,26104.13,0.09819,0.04026
101.9,8.492,26099.15,0.0983,0.04026
102,8.5,26092.42,0.09841,0.04027
102.1,8.508,26095.54,0.09852,0.04026
102.2,8.517,26100.31,0.09863,0.04027
102.3,8.525,26092.27,0.09874,0.04026
102.4,8.534,26092.21,0.09885,0.04027
102.5,8.542,26082.14,0.09896,0.04028
102.6,8.55,26077.06,0.09906,0.04028
102.7,8.559,26078.95,0.09917,0.04029
102.8,8.567,26071.14,0.09927,0.0403
102.9,8.575,26068.52,0.09938,0.04031
103,8.584,26065.88,0.09948,0.04032
103.1,8.592,26064.32,0.09958,0.04032
103.2,8.6,26056.2,0.09969,0.04031
103.3,8.609,26058.06,0.09978,0.04032
103.4,8.617,26045.16,0.09988,0.04031
103.5,8.625,26044.34,0.09999,0.04029
103.6,8.633,26038.74,0.10008,0.04029
103.7,8.642,26034.03,0.10018,0.0403
103.8,8.65,26034.85,0.10028,0.04031
103.9,8.659,26031.26,0.10038,0.04032
104,8.667,26024.45,0.10047,0.04033
104.1,8.675,26020.85,0.10056,0.04034
104.2,8.683,26018.25,0.10065,0.04033
104.3,8.692,26015,0.10075,0.04033
104.4,8.7,26015.1,0.10084,0.04035
104.5,8.709,26012.32,0.10093,0.04037
104.6,8.717,26013.31,0.10102,0.04038
104.7,8.725,26002.31,0.1011,0.04037
104.8,8.733,26000.13,0.1012,0.04036
104.9,8.742,25998.6,0.10128,0.04034
105,8.75,25994.59,0.10137,0.04033
105.1,8.759,25991.75,0.10146,0.04033
105.2,8.767,25988.44,0.10154,0.04032
105.3,8.775,25990.44,0.10162,0.04032
105.4,8.783,25983.19,0.10171,0.04032
105.5,8.792,25975.52,0.10179,0.04032
105.6,8.8,25971.13,0.10187,0.04033
105.7,8.808,25968.56,0.10195,0.04031
105.8,8.817,25959.45,0.10203,0.04033
105.9,8.825,25951.34,0.10211,0.04034
106,8.834,25948.88,0.10218,0.04032
106.1,8.842,25937.23,0.10226,0.04029
106.2,8.85,25922.12,0.10234,0.04028
106.3,8.858,25915.17,0.10242,0.04028
106.4,8.867,25908.96,0.10249,0.04028
106.5,8.875,25909.98,0.10257,0.04027
106.6,8.883,25899.21,0.10264,0.04026
106.7,8.892,25885.95,0.10272,0.04025
106.8,8.9,25883.7,0.10279,0.04023
106.9,8.908,25877.08,0.10286,0.04021
107,8.917,25865.13,0.10293,0.0402
107.1,8.925,25862.06,0.10301,0.04019
107.2,8.934,25852.64,0.10308,0.04018
107.3,8.942,25849.37,0.10314,0.04018
107.4,8.95,25842.78,0.10321,0.04017
107.5,8.959,25836.89,0.10328,0.04017
107.6,8.967,25836.07,0.10335,0.04013
107.7,8.975,25824.57,0.10342,0.03996
107.8,8.983,25817.64,0.10349,0.03985
107.9,8.992,25815.83,0.10355,0.03976
108,9,25806.3,0.10361,0.03976
108.1,9.009,25799.33,0.10368,0.03974
108.2,9.017,25792.64,0.10375,0.03977
108.3,9.025,25782.3,0.10381,0.03977
108.4,9.033,25768.09,0.10387,0.03976
108.5,9.042,25762.6,0.10394,0.03975
108.6,9.05,25752.8,0.104,0.03975
108.7,9.059,25743.54,0.10406,0.03974
108.8,9.067,25729.41,0.10413,0.03974
108.9,9.075,25724.15,0.10419,0.03968
109,9.084,25720.31,0.10425,0.03967
109.1,9.092,25711.79,0.10431,0.03966
109.2,9.1,25706.15,0.10437,0.03964
109.3,9.109,25702.96,0.10444,0.03962
109.4,9.117,25698.88,0.10449,0.03961
109.5,9.125,25695.75,0.10455,0.03961
109.6,9.133,25694.24,0.10461,0.0396
109.7,9.142,25691.02,0.10466,0.03959
109.8,9.15,25690.7,0.10472,0.03959
109.9,9.159,25686.63,0.10478,0.03959
110,9.167,25686.32,0.10484,0.03957
110.1,9.175,25681.87,0.10489,0.03956
110.2,9.183,25680.03,0.10495,0.03955
110.3,9.192,25680.42,0.105,0.03954
110.4,9.2,25677.28,0.10505,0.03952
110.5,9.208,25673.92,0.10511,0.03951
110.6,9.217,25673.09,0.10516,0.03951
110.7,9.225,25666.72,0.10521,0.0395
110.8,9.233,25662.86,0.10527,0.03949
110.9,9.242,25659.52,0.10532,0.03948
111,9.25,25650.33,0.10537,0.03948
111.1,9.258,25644.33,0.10542,0.03947
111.2,9.267,25634.78,0.10547,0.03945
111.3,9.275,25622.89,0.10552,0.03944
111.4,9.284,25603.56,0.10557,0.03943
111.5,9.292,25586.33,0.10562,0.03943
111.6,9.3,25573.18,0.10567,0.03943
111.7,9.308,25555.05,0.10571,0.03943
111.8,9.317,25534.97,0.10576,0.03943
111.9,9.325,25517.63,0.10581,0.03943
112,9.334,25501.85,0.10585,0.03943
112.1,9.342,25490.12,0.1059,0.03943
112.2,9.35,25477.87,0.10594,0.03943
112.3,9.358,25470.89,0.10599,0.03942
112.4,9.367,25459.83,0.10603,0.03942
112.5,9.375,25449.66,0.10608,0.03941
112.6,9.383,25438.62,0.10612,0.0394
112.7,9.392,25423.66,0.10616,0.03939
112.8,9.4,25409.47,0.1062,0.03938
112.9,9.408,25399.81,0.10625,0.03938
113,9.417,25381.88,0.10628,0.03937
113.1,9.425,25366.56,0.10632,0.03937
113.2,9.434,25349.97,0.10637,0.03936
113.3,9.442,25335.76,0.1064,0.03935
113.4,9.45,25320.89,0.10644,0.03935
113.5,9.459,25309.99,0.10648,0.03934
113.6,9.467,25286.61,0.10652,0.03933
113.7,9.475,25273.17,0.10655,0.03932
113.8,9.484,25254.14,0.10659,0.03931
113.9,9.492,25229.99,0.10663,0.03931
114,9.5,25214.38,0.10666,0.0393
114.1,9.509,25196.8,0.1067,0.0393
114.2,9.517,25187.21,0.10673,0.03929
114.3,9.525,25181.67,0.10677,0.03928
114.4,9.534,25177.62,0.10681,0.03928
114.5,9.542,25174.79,0.10683,0.03928
114.6,9.55,25171.47,0.10687,0.03927
114.7,9.558,25170.24,0.1069,0.03926
114.8,9.567,25168.52,0.10693,0.03926
114.9,9.575,25163.65,0.10696,0.03925
115,9.583,25159.15,0.10699,0.03924
115.1,9.592,25155.57,0.10702,0.03924
115.2,9.6,25148.04,0.10705,0.03923
115.3,9.609,25138.83,0.10708,0.03923
115.4,9.617,25132.77,0.10711,0.03922
115.5,9.625,25127.33,0.10714,0.03921
115.6,9.634,25123.16,0.10717,0.0392
115.7,9.642,25118.34,0.10719,0.03877
115.8,9.65,25107.33,0.10721,0.03878
115.9,9.659,25098.3,0.10724,0.03874
116,9.667,25083.58,0.10727,0.03875
116.1,9.675,25052.96,0.1073,0.03874
116.2,9.684,25042.48,0.10732,0.03872
116.3,9.692,25028.29,0.10735,0.03872
116.4,9.7,25008.75,0.10737,0.03871
116.5,9.709,24997.06,0.10739,0.03871
116.6,9.717,24986.15,0.10741,0.0387
116.7,9.725,24976.46,0.10744,0.03869
116.8,9.734,24964.9,0.10746,0.03868
116.9,9.742,24950.23,0.10748,0.03867
117,9.75,24926.71,0.1075,0.03866
117.1,9.758,24913.82,0.10752,0.03865
117.2,9.767,24901.49,0.10753,0.03865
117.3,9.775,24885.47,0.10755,0.03864
117.4,9.783,24873.42,0.10757,0.03863
117.5,9.792,24855.05,0.10759,0.03862
117.6,9.8,24846.09,0.10761,0.03862
117.7,9.808,24831.08,0.10762,0.03861
117.8,9.817,24808.26,0.10763,0.0386
117.9,9.825,24786.88,0.10765,0.03859
118,9.833,24750.49,0.10766,0.03859
118.1,9.842,24724.71,0.10767,0.03859
118.2,9.85,24706.25,0.10769,0.03858
118.3,9.858,24687.56,0.1077,0.03857
118.4,9.867,24671.97,0.10771,0.03857
118.5,9.875,24662.57,0.10771,0.03856
118.6,9.884,24649.97,0.10772,0.03856
118.7,9.892,24633.67,0.10773,0.03855
118.8,9.9,24622.67,0.10774,0.03855
118.9,9.909,24619.56,0.10775,0.03855
119,9.917,24600.85,0.10775,0.03854
119.1,9.925,24596.17,0.10776,0.03853
119.2,9.933,24588.87,0.10776,0.03853
119.3,9.942,24576.52,0.10777,0.03853
119.4,9.95,24571.6,0.10778,0.03852
119.5,9.959,24560.71,0.10779,0.03852
119.6,9.967,24539.64,0.10779,0.03851
119.7,9.975,24512.36,0.1078,0.03852
119.8,9.983,24483.6,0.10781,0.0385
119.9,9.992,24451.06,0.10781,0.0385
120,10,24440.24,0.10782,0.0385
120.1,10.009,24420.92,0.10782,0.03849
120.2,10.017,24406.1,0.10783,0.03849
120.3,10.025,24394.6,0.10783,0.03848
120.4,10.033,24389.68,0.10784,0.03847
120.5,10.042,24375.44,0.10784,0.03846
120.6,10.05,24358.23,0.10785,0.03846
120.7,10.059,24349.37,0.10785,0.03845
120.8,10.067,24342.73,0.10786,0.03844
120.9,10.075,24331.56,0.10786,0.03844
121,10.084,24307.81,0.10787,0.03843
121.1,10.092,24282.34,0.10787,0.03843
121.2,10.1,24269.98,0.10788,0.03842
121.3,10.108,24226.87,0.10788,0.03841
121.4,10.117,24219.88,0.10788,0.03841
121.5,10.125,24206.33,0.10789,0.0384
121.6,10.134,24197.45,0.10789,0.03839
121.7,10.142,24191.94,0.1079,0.03839
121.8,10.15,24181.2,0.1079,0.03838
121.9,10.158,24165.37,0.10791,0.03837
122,10.167,24155.41,0.10791,0.03837
122.1,10.175,24142.53,0.10792,0.03836
122.2,10.183,24123.12,0.10792,0.03836
122.3,10.192,24116.93,0.10793,0.03835
122.4,10.2,24101.18,0.10793,0.03835
122.5,10.208,24085.92,0.10794,0.03834
122.6,10.217,24060.31,0.10794,0.03834
122.7,10.225,24030.28,0.10794,0.03833
122.8,10.234,24003.79,0.10795,0.03833
122.9,10.242,23976.02,0.10795,0.03832
123,10.25,23956.82,0.10795,0.03832
123.1,10.259,23934.76,0.10796,0.03831
123.2,10.267,23914.66,0.10796,0.03831
123.3,10.275,23888.52,0.10796,0.0383
123.4,10.284,23860.03,0.10797,0.0383
123.5,10.292,23828.96,0.10797,0.03829
123.6,10.3,23797.33,0.10797,0.03829
123.7,10.308,23777.49,0.10797,0.03828
123.8,10.317,23760.83,0.10797,0.03828
123.9,10.325,23745.77,0.10798,0.03827
124,10.333,23729.46,0.10798,0.03827
124.1,10.342,23701.08,0.10798,0.03826
124.2,10.35,23672.01,0.10798,0.03826
124.3,10.359,23662.23,0.10798,0.03825
124.4,10.367,23633.95,0.10798,0.03825
124.5,10.375,23631.42,0.10798,0.03824
124.6,10.383,23626.34,0.10798,0.03824
124.7,10.392,23626.28,0.10798,0.03824
124.8,10.4,23625.77,0.10798,0.03823
124.9,10.409,23624.84,0.10798,0.03822
125,10.417,23622.8,0.10798,0.03822
125.1,10.425,23618.17,0.10798,0.03822
125.2,10.434,23612.1,0.10798,0.03821
125.3,10.442,23591.57,0.10798,0.03821
125.4,10.45,23570.87,0.10798,0.03821
125.5,10.459,23532.88,0.10797,0.0382
125.6,10.467,23495.56,0.10797,0.0382
125.7,10.475,23467.14,0.10797,0.03819
125.8,10.483,23443.31,0.10797,0.03819
125.9,10.492,23414.47,0.10796,0.03818
126,10.5,23381.94,0.10795,0.03818
126.1,10.509,23352.36,0.10795,0.03817
126.2,10.517,23318.79,0.10794,0.03817
126.3,10.525,23287.38,0.10793,0.03816
126.4,10.534,23261.72,0.10792,0.03816
126.5,10.542,23221.24,0.10791,0.03815
126.6,10.55,23178.38,0.1079,0.03815
126.7,10.559,23150.89,0.10789,0.03814
126.8,10.567,23129.8,0.10787,0.03814
126.9,10.575,23109.56,0.10786,0.03813
127,10.584,23085.34,0.10785,0.03813
127.1,10.592,23067.12,0.10783,0.03812
127.2,10.6,23046.11,0.10782,0.03812
127.3,10.609,23026.85,0.1078,0.03812
127.4,10.617,23012.99,0.10779,0.03812
127.5,10.625,22998.16,0.10777,0.03811
127.6,10.634,22986.19,0.10776,0.0381
127.7,10.642,22968.42,0.10774,0.0381
127.8,10.65,22946.99,0.10772,0.0381
127.9,10.658,22929.03,0.10771,0.0381
128,10.667,22918.88,0.1077,0.03809
128.1,10.675,22908.3,0.10768,0.03809
128.2,10.684,22891.57,0.10766,0.03809
128.3,10.692,22868.28,0.10765,0.03809
128.4,10.7,22841.31,0.10764,0.03809
128.5,10.709,22823.82,0.10762,0.03808
128.6,10.717,22779.59,0.10761,0.03807
128.7,10.725,22746.58,0.10759,0.03807
128.8,10.734,22713.77,0.10758,0.03807
128.9,10.742,22671.88,0.10756,0.03806
129,10.75,22646.56,0.10755,0.03806
129.1,10.759,22629.07,0.10753,0.03805
129.2,10.767,22616.04,0.10751,0.03805
129.3,10.775,22597.39,0.1075,0.03804
129.4,10.784,22578.73,0.10748,0.03803
129.5,10.792,22559.53,0.10747,0.03802
129.6,10.8,22540.2,0.10745,0.03803
129.7,10.809,22517.25,0.10744,0.03803
129.8,10.817,22487.06,0.10742,0.03803
129.9,10.825,22445.08,0.1074,0.03803
130,10.833,22396.77,0.10738,0.03805
130.1,10.842,22369.69,0.10737,0.03806
130.2,10.85,22337.05,0.10735,0.03804
130.3,10.858,22298.29,0.10734,0.03804
130.4,10.867,22253.84,0.10732,0.03803
130.5,10.875,22225.38,0.1073,0.03803
130.6,10.883,22208.75,0.10729,0.03803
130.7,10.892,22184.65,0.10727,0.03802
130.8,10.9,22145.51,0.10726,0.03801
130.9,10.908,22128.17,0.10725,0.03801
131,10.917,22125.51,0.10723,0.038
131.1,10.925,22124.23,0.10722,0.038
131.2,10.933,22122.01,0.1072,0.03799
131.3,10.942,22116.01,0.10719,0.03799
131.4,10.95,22101.13,0.10717,0.03798
131.5,10.959,22069.23,0.10716,0.03798
131.6,10.967,22007.14,0.10714,0.03797
131.7,10.975,21941.97,0.10713,0.03797
131.8,10.984,21898.59,0.10712,0.03796
131.9,10.992,21865.88,0.1071,0.03795
132,11,21806.53,0.10709,0.03795
132.1,11.009,21749.67,0.10707,0.03794
132.2,11.017,21657.22,0.10705,0.03793
132.3,11.025,21508.31,0.10702,0.03792
132.4,11.034,21367.47,0.10693,0.03788
132.424,11.036,9964.21,0.09062,0.02847