File: Labs/Lab 2 Tension/6061 Aluminum Sample 1.csv
Time (s),Extension (mm),Load (N),Axial Strain (mm/mm),Transverse Strain (mm/mm)
0,0,1.51,0,0
0.1,0.004,7.83,0,0
0.2,0.013,241.8,0.00004,0.00002
0.3,0.024,355.79,0.00008,0.00004
0.4,0.033,451.47,0.00011,0.00005
0.5,0.042,556.79,0.00012,0.00006
0.6,0.05,649.64,0.00014,0.00007
0.7,0.058,740.73,0.00015,0.00008
0.8,0.067,820.16,0.00017,0.00008
0.9,0.075,868.01,0.00018,0.00009
1,0.084,901.63,0.0002,0.0001
1.1,0.092,918.8,0.0002,0.00011
1.2,0.1,931.57,0.00022,0.00012
1.3,0.108,959.91,0.00023,0.00013
1.4,0.117,1006.48,0.00024,0.00014
1.5,0.125,1022.55,0.00024,0.00017
1.6,0.134,1046.32,0.00025,0.0002
1.7,0.142,1076.07,0.00026,0.00021
1.8,0.15,1114.74,0.00027,0.00023
1.9,0.158,1166.99,0.00028,0.00024
2,0.167,1229.71,0.0003,0.00025
2.1,0.175,1270.43,0.00031,0.00025
2.2,0.183,1326.21,0.00032,0.00026
2.3,0.192,1379.92,0.00034,0.00026
2.4,0.2,1402.49,0.00035,0.00027
2.5,0.208,1427.5,0.00036,0.00027
2.6,0.217,1472.62,0.00037,0.00028
2.7,0.225,1535.53,0.00039,0.00028
2.8,0.233,1600.39,0.0004,0.00029
2.9,0.242,1644.36,0.00041,0.00029
3,0.25,1674.73,0.00042,0.0003
3.1,0.258,1750.21,0.00043,0.0003
3.2,0.267,1815.71,0.00044,0.0003
3.3,0.275,1850.55,0.00046,0.00031
3.4,0.283,1889.86,0.00047,0.00031
3.5,0.292,1912.88,0.00048,0.00032
3.6,0.3,1943.72,0.00049,0.00032
3.7,0.308,2015.77,0.0005,0.00033
3.8,0.317,2095.59,0.00052,0.00033
3.9,0.325,2183.1,0.00053,0.00034
4,0.333,2247.22,0.00054,0.00034
4.1,0.342,2286.3,0.00055,0.00035
4.2,0.35,2325.22,0.00056,0.00035
4.3,0.358,2396.73,0.00058,0.00035
4.4,0.367,2436.57,0.00059,0.00036
4.5,0.375,2471.7,0.0006,0.00036
4.6,0.383,2492.36,0.00061,0.00036
4.7,0.392,2536.68,0.00062,0.00037
4.8,0.4,2635.77,0.00063,0.00037
4.9,0.408,2692.74,0.00065,0.00037
5,0.417,2785.26,0.00066,0.00038
5.1,0.425,2861.6,0.00067,0.00038
5.2,0.433,2902.32,0.00069,0.00038
5.3,0.442,2955.31,0.0007,0.00039
5.4,0.45,2987.54,0.00071,0.00039
5.5,0.458,3051.71,0.00072,0.00039
5.6,0.467,3086.85,0.00073,0.0004
5.7,0.475,3137.73,0.00074,0.0004
5.8,0.483,3227.39,0.00076,0.0004
5.9,0.492,3317.29,0.00077,0.00041
6,0.5,3365.47,0.00078,0.00041
6.1,0.508,3423.86,0.00079,0.00041
6.2,0.517,3469.94,0.0008,0.00041
6.3,0.525,3531.79,0.00082,0.00042
6.4,0.533,3609.11,0.00083,0.00042
6.5,0.542,3713.42,0.00084,0.00042
6.6,0.55,3744.14,0.00086,0.00042
6.7,0.558,3870.47,0.00087,0.00042
6.8,0.567,3959.69,0.00088,0.00041
6.9,0.575,3984.9,0.00089,0.00041
7,0.583,4016.99,0.0009,0.0004
7.1,0.592,4102.82,0.00092,0.0004
7.2,0.6,4159.87,0.00093,0.0004
7.3,0.608,4247.17,0.00094,0.0004
7.4,0.617,4332.24,0.00096,0.00041
7.5,0.625,4405.56,0.00097,0.00041
7.6,0.633,4469.77,0.00098,0.00041
7.7,0.642,4498.27,0.00099,0.00042
7.8,0.65,4539.02,0.00101,0.00042
7.9,0.658,4646.12,0.00102,0.00042
8,0.667,4771.19,0.00104,0.00042
8.1,0.675,4855.07,0.00105,0.00043
8.2,0.684,4956.44,0.00106,0.00043
8.3,0.692,5001.25,0.00107,0.00043
8.4,0.7,5032.48,0.00109,0.00044
8.5,0.709,5126.83,0.0011,0.00044
8.6,0.717,5180.31,0.00111,0.00044
8.7,0.725,5294.72,0.00113,0.00045
8.8,0.733,5390.09,0.00114,0.00045
8.9,0.742,5479.76,0.00116,0.00045
9,0.75,5540.82,0.00117,0.00046
9.1,0.758,5577.9,0.00118,0.00046
9.2,0.767,5633.02,0.0012,0.00046
9.3,0.775,5783.54,0.00121,0.00047
9.4,0.783,5833.04,0.00122,0.00047
9.5,0.792,5935.71,0.00124,0.00047
9.6,0.8,5991.2,0.00125,0.00048
9.7,0.808,6048.72,0.00127,0.00048
9.8,0.817,6170.52,0.00129,0.00048
9.9,0.825,6234.54,0.0013,0.00048
10,0.833,6360.12,0.00131,0.00049
10.1,0.842,6432.22,0.00133,0.00049
10.2,0.85,6501.82,0.00134,0.00049
10.3,0.858,6526.01,0.00135,0.0005
10.4,0.867,6593.88,0.00137,0.0005
10.5,0.875,6717.9,0.00138,0.0005
10.6,0.883,6819.1,0.0014,0.0005
10.7,0.892,6977.19,0.00141,0.00051
10.8,0.9,7062.93,0.00143,0.00051
10.9,0.908,7083.75,0.00144,0.00052
11,0.917,7152.41,0.00146,0.00052
11.1,0.925,7231.06,0.00147,0.00052
11.2,0.933,7306.54,0.00149,0.00053
11.3,0.942,7400.03,0.0015,0.00053
11.4,0.95,7513.53,0.00152,0.00053
11.5,0.958,7604.51,0.00153,0.00054
11.6,0.967,7640.92,0.00155,0.00054
11.7,0.975,7787.93,0.00156,0.00054
11.8,0.983,7875.92,0.00157,0.00055
11.9,0.992,7961.35,0.00159,0.00055
12,1,8017.64,0.00161,0.00055
12.1,1.008,8088.23,0.00162,0.00056
12.2,1.017,8188.2,0.00163,0.00056
12.3,1.025,8278.55,0.00165,0.00056
12.4,1.033,8430.88,0.00166,0.00057
12.5,1.042,8512.05,0.00168,0.00057
12.6,1.05,8603.34,0.00169,0.00058
12.7,1.058,8627.66,0.00171,0.00058
12.8,1.067,8681.12,0.00173,0.00058
12.9,1.075,8809.96,0.00174,0.00059
13,1.083,8919.55,0.00175,0.00059
13.1,1.092,9077.01,0.00177,0.0006
13.2,1.1,9142.43,0.00178,0.0006
13.3,1.108,9230.39,0.0018,0.00061
13.4,1.117,9322.78,0.00182,0.00061
13.5,1.125,9385.69,0.00183,0.00061
13.6,1.133,9467.69,0.00185,0.00062
13.7,1.142,9577.56,0.00186,0.00062
13.8,1.15,9651.65,0.00188,0.00063
13.9,1.158,9731.81,0.00189,0.00063
14,1.167,9897.06,0.00191,0.00064
14.1,1.175,10006.51,0.00193,0.00064
14.2,1.183,10122.71,0.00194,0.00065
14.3,1.192,10131.4,0.00196,0.00065
14.4,1.2,10189.56,0.00197,0.00066
14.5,1.209,10309.41,0.00199,0.00066
14.6,1.217,10432.39,0.00201,0.00067
14.7,1.225,10552.8,0.00202,0.00067
14.8,1.233,10683.94,0.00203,0.00068
14.9,1.242,10718.19,0.00205,0.00068
15,1.25,10776.72,0.00206,0.00069
15.1,1.258,10902.79,0.00208,0.00069
15.2,1.267,10997.19,0.0021,0.0007
15.3,1.275,11124.85,0.00212,0.0007
15.4,1.283,11211.87,0.00213,0.0007
15.5,1.292,11302.26,0.00215,0.00071
15.6,1.3,11425.42,0.00217,0.00071
15.7,1.308,11535.03,0.00218,0.00072
15.8,1.317,11574.17,0.0022,0.00072
15.9,1.325,11653.58,0.00222,0.00073
16,1.333,11749.7,0.00223,0.00073
16.1,1.342,11863.08,0.00225,0.00073
16.2,1.35,12014.21,0.00226,0.00074
16.3,1.358,12168.7,0.00229,0.00074
16.4,1.367,12211.83,0.0023,0.00075
16.5,1.375,12274.63,0.00232,0.00075
16.6,1.383,12370.07,0.00234,0.00076
16.7,1.392,12457.09,0.00236,0.00076
16.8,1.4,12576.43,0.00237,0.00077
16.9,1.408,12716.09,0.00239,0.00077
17,1.417,12760.53,0.00241,0.00078
17.1,1.425,12881.42,0.00242,0.00078
17.2,1.433,12998.58,0.00244,0.00079
17.3,1.442,13098.55,0.00246,0.00079
17.4,1.45,13202.56,0.00247,0.0008
17.5,1.458,13265.36,0.00249,0.0008
17.6,1.467,13395.56,0.00251,0.0008
17.7,1.475,13509.2,0.00253,0.00081
17.8,1.483,13620.7,0.00255,0.00082
17.9,1.492,13700.97,0.00256,0.00082
18,1.5,13796.05,0.00258,0.00082
18.1,1.508,13836.31,0.0026,0.00083
18.2,1.517,13980.78,0.00261,0.00083
18.3,1.525,14101.08,0.00263,0.00084
18.4,1.533,14245.95,0.00265,0.00084
18.5,1.542,14294.71,0.00267,0.00085
18.6,1.55,14401.42,0.00269,0.00085
18.7,1.558,14487.43,0.00271,0.00086
18.8,1.567,14629.19,0.00272,0.00087
18.9,1.575,14703.6,0.00274,0.00087
19,1.583,14825.31,0.00276,0.00088
19.1,1.592,14889.72,0.00278,0.00088
19.2,1.6,15030.54,0.00279,0.00089
19.3,1.608,15131.08,0.00281,0.00089
19.4,1.617,15265.3,0.00283,0.0009
19.5,1.625,15326.58,0.00285,0.0009
19.6,1.633,15418.6,0.00287,0.00091
19.7,1.642,15496.66,0.00289,0.00091
19.8,1.65,15636.27,0.00291,0.00092
19.9,1.658,15754.13,0.00293,0.00093
20,1.667,15821.75,0.00294,0.00093
20.1,1.675,15903.35,0.00296,0.00094
20.2,1.683,16074.63,0.00299,0.00095
20.3,1.692,16152.8,0.003,0.00095
20.4,1.7,16313.82,0.00302,0.00096
20.5,1.708,16364.27,0.00304,0.00097
20.6,1.717,16446.99,0.00306,0.00097
20.7,1.725,16558.15,0.00308,0.00098
20.8,1.733,16678.77,0.0031,0.00098
20.9,1.742,16797.56,0.00312,0.00099
21,1.75,16876.75,0.00314,0.00099
21.1,1.758,16914.15,0.00316,0.001
21.2,1.767,17063.89,0.00318,0.001
21.3,1.775,17184.52,0.0032,0.00101
21.4,1.783,17295.81,0.00322,0.00102
21.5,1.792,17376.45,0.00324,0.00103
21.6,1.8,17514.69,0.00326,0.00104
21.7,1.808,17609.67,0.00329,0.00104
21.8,1.817,17733.35,0.0033,0.00105
21.9,1.825,17831.61,0.00333,0.00106
22,1.834,17880.56,0.00335,0.00106
22.1,1.842,17965.46,0.00337,0.00107
22.2,1.85,18113.1,0.00339,0.00108
22.3,1.858,18216.03,0.00341,0.00108
22.4,1.867,18371.84,0.00344,0.00109
22.5,1.875,18398.01,0.00346,0.0011
22.6,1.883,18497.95,0.00348,0.0011
22.7,1.892,18565.63,0.00351,0.00111
22.8,1.9,18708.38,0.00353,0.00112
22.9,1.908,18814.08,0.00355,0.00112
23,1.917,18943.47,0.00357,0.00114
23.1,1.925,19024.92,0.0036,0.00114
23.2,1.933,19153.43,0.00362,0.00115
23.3,1.942,19222.12,0.00365,0.00116
23.4,1.95,19356.36,0.00367,0.00116
23.5,1.958,19427.06,0.0037,0.00117
23.6,1.967,19504.22,0.00372,0.00118
23.7,1.975,19627.32,0.00375,0.00119
23.8,1.983,19751.94,0.00378,0.00119
23.9,1.992,19837.23,0.0038,0.0012
24,2,19940.19,0.00383,0.00121
24.1,2.008,19949.2,0.00386,0.00122
24.2,2.017,20043.9,0.00388,0.00123
24.3,2.025,20190.92,0.00391,0.00124
24.4,2.033,20345.95,0.00394,0.00124
24.5,2.042,20455,0.00397,0.00125
24.6,2.05,20540.65,0.004,0.00126
24.7,2.058,20621.95,0.00403,0.00127
24.8,2.067,20672.23,0.00406,0.00128
24.9,2.075,20790.81,0.00409,0.00129
25,2.083,20880.61,0.00412,0.0013
25.1,2.092,20961.93,0.00416,0.00131
25.2,2.1,21032.64,0.00419,0.00133
25.3,2.108,21145.71,0.00422,0.00133
25.4,2.117,21247.28,0.00426,0.00135
25.5,2.125,21381.68,0.00429,0.00136
25.6,2.133,21442.12,0.00432,0.00137
25.7,2.142,21451.2,0.00436,0.00138
25.8,2.15,21523.52,0.0044,0.0014
25.9,2.158,21657.57,0.00444,0.00141
26,2.167,21770.43,0.00448,0.00142
26.1,2.175,21880.46,0.00452,0.00143
26.2,2.183,22007.08,0.00456,0.00144
26.3,2.192,22059.18,0.0046,0.00146
26.4,2.2,22071.66,0.00464,0.00147
26.5,2.208,22126.8,0.00469,0.00149
26.6,2.217,22240.06,0.00473,0.0015
26.7,2.225,22311.45,0.00478,0.00152
26.8,2.233,22422.16,0.00483,0.00153
26.9,2.242,22488.34,0.00488,0.00155
27,2.25,22547.86,0.00492,0.00156
27.1,2.258,22610.06,0.00498,0.00158
27.2,2.267,22672.85,0.00503,0.0016
27.3,2.275,22751.29,0.00509,0.00162
27.4,2.283,22829.46,0.00514,0.00163
27.5,2.292,22874.57,0.0052,0.00165
27.6,2.3,22908.29,0.00526,0.00167
27.7,2.308,22961.71,0.00532,0.00169
27.8,2.317,22993.28,0.00539,0.00171
27.9,2.325,23048.2,0.00545,0.00174
28,2.333,23105.8,0.00552,0.00176
28.1,2.342,23189.41,0.00559,0.00178
28.2,2.35,23295.89,0.00565,0.00181
28.3,2.358,23345.6,0.00573,0.00183
28.4,2.367,23412.81,0.0058,0.00186
28.5,2.375,23500.57,0.00588,0.00188
28.6,2.384,23544.59,0.00595,0.00191
28.7,2.392,23559.88,0.00602,0.00194
28.8,2.4,23568.14,0.00611,0.00196
28.9,2.408,23583.41,0.00618,0.00199
29,2.417,23619.9,0.00627,0.00202
29.1,2.425,23665.64,0.00635,0.00205
29.2,2.433,23684.94,0.00644,0.00208
29.3,2.442,23709.61,0.00653,0.00211
29.4,2.45,23753.38,0.00661,0.00214
29.5,2.458,23816.72,0.0067,0.00217
29.6,2.467,23866.51,0.00679,0.00221
29.7,2.475,23903.33,0.00688,0.00224
29.8,2.483,23930.25,0.00698,0.00228
29.9,2.492,23970.57,0.00707,0.00231
30,2.5,24018.37,0.00716,0.00235
30.1,2.508,24046.91,0.00726,0.00239
30.2,2.517,24063.48,0.00735,0.00242
30.3,2.525,24082.46,0.00745,0.00246
30.4,2.533,24100.3,0.00755,0.0025
30.5,2.542,24124.05,0.00765,0.00253
30.6,2.55,24141.35,0.00775,0.00257
30.7,2.559,24153.03,0.00785,0.00261
30.8,2.567,24169.8,0.00795,0.00265
30.9,2.575,24196.36,0.00806,0.00269
31,2.584,24232.14,0.00816,0.00272
31.1,2.592,24268.51,0.00827,0.00276
31.2,2.6,24294.2,0.00837,0.00281
31.3,2.608,24310.17,0.00849,0.00285
31.4,2.617,24321.04,0.00859,0.00289
31.5,2.625,24333.7,0.0087,0.00293
31.6,2.633,24345.53,0.00881,0.00297
31.7,2.642,24369.54,0.00892,0.00302
31.8,2.65,24399.3,0.00903,0.00306
31.9,2.658,24420.22,0.00914,0.0031
32,2.667,24446,0.00925,0.00314
32.1,2.675,24472.32,0.00936,0.00319
32.2,2.683,24501.03,0.00948,0.00323
32.3,2.692,24518.89,0.00959,0.00327
32.4,2.7,24523.32,0.00971,0.00332
32.5,2.708,24532.03,0.00983,0.00336
32.6,2.717,24538.77,0.00994,0.00341
32.7,2.725,24542.74,0.01006,0.00345
32.8,2.734,24547.6,0.01018,0.0035
32.9,2.742,24548.47,0.01029,0.00354
33,2.75,24556.87,0.0104,0.00359
33.1,2.758,24562.11,0.01053,0.00364
33.2,2.767,24582.04,0.01064,0.00368
33.3,2.775,24599.47,0.01076,0.00372
33.4,2.783,24613.5,0.01088,0.00377
33.5,2.792,24643.68,0.01101,0.00382
33.6,2.8,24670.97,0.01112,0.00386
33.7,2.808,24693.56,0.01125,0.00391
33.8,2.817,24721.02,0.01137,0.00396
33.9,2.825,24737.57,0.01149,0.00401
34,2.833,24749.83,0.01162,0.00405
34.1,2.842,24751.4,0.01174,0.0041
34.2,2.85,24764.76,0.01187,0.00415
34.3,2.858,24774.06,0.01199,0.00419
34.4,2.867,24779.15,0.01211,0.00424
34.5,2.875,24786.04,0.01224,0.00429
34.6,2.883,24797.81,0.01236,0.00434
34.7,2.892,24804.74,0.0125,0.00439
34.8,2.9,24815.92,0.01262,0.00444
34.9,2.908,24824.6,0.01275,0.00449
35,2.917,24834.56,0.01288,0.00454
35.1,2.925,24847.91,0.013,0.00458
35.2,2.933,24859.48,0.01313,0.00463
35.3,2.942,24869.25,0.01325,0.00468
35.4,2.95,24879.52,0.01338,0.00473
35.5,2.958,24890.88,0.01351,0.00478
35.6,2.967,24905.21,0.01365,0.00483
35.7,2.975,24912.9,0.01377,0.00488
35.8,2.983,24928.2,0.0139,0.00492
35.9,2.992,24938.79,0.01403,0.00497
36,3,24945.6,0.01416,0.00502
36.1,3.008,24950.99,0.01429,0.00507
36.2,3.017,24959.5,0.01442,0.00512
36.3,3.025,24964.79,0.01455,0.00517
36.4,3.033,24973.26,0.01468,0.00522
36.5,3.042,24978.56,0.01481,0.00527
36.6,3.05,24988.11,0.01494,0.00532
36.7,3.058,24991.46,0.01507,0.00537
36.8,3.067,24999.15,0.0152,0.00541
36.9,3.075,25010.92,0.01533,0.00546
37,3.083,25014.49,0.01547,0.00551
37.1,3.092,25032.36,0.0156,0.00556
37.2,3.1,25044.76,0.01573,0.00561
37.3,3.108,25052.72,0.01586,0.00566
37.4,3.117,25062.69,0.01599,0.00571
37.5,3.125,25073.5,0.01612,0.00576
37.6,3.134,25080.34,0.01625,0.00581
37.7,3.142,25084.51,0.01639,0.00585
37.8,3.15,25094.92,0.01652,0.0059
37.9,3.158,25099.99,0.01665,0.00595
38,3.167,25099.9,0.01678,0.006
38.1,3.175,25104.93,0.01691,0.00605
38.2,3.183,25106.11,0.01705,0.0061
38.3,3.192,25107.87,0.01718,0.00615
38.4,3.2,25107.51,0.01731,0.0062
38.5,3.208,25108.84,0.01744,0.00625
38.6,3.217,25110.1,0.01758,0.0063
38.7,3.225,25110.44,0.01771,0.00635
38.8,3.233,25109.73,0.01785,0.0064
38.9,3.242,25111.47,0.01798,0.00645
39,3.25,25111.38,0.01811,0.0065
39.1,3.258,25112.35,0.01824,0.00655
39.2,3.267,25113.52,0.01837,0.0066
39.3,3.275,25114.04,0.01851,0.00664
39.4,3.284,25114.98,0.01864,0.0067
39.5,3.292,25116.76,0.01877,0.00674
39.6,3.3,25116.46,0.0189,0.0068
39.7,3.308,25120.67,0.01904,0.00685
39.8,3.317,25122.53,0.01917,0.0069
39.9,3.325,25125.6,0.0193,0.00695
40,3.333,25128.19,0.01944,0.00699
40.1,3.342,25130.47,0.01957,0.00704
40.2,3.35,25134.52,0.0197,0.00709
40.3,3.358,25139.28,0.01983,0.00714
40.4,3.367,25143.67,0.01996,0.00719
40.5,3.375,25150.76,0.0201,0.00724
40.6,3.383,25155.76,0.02022,0.00729
40.7,3.392,25160.29,0.02036,0.00734
40.8,3.4,25169.61,0.02049,0.00739
40.9,3.408,25176.07,0.02062,0.00744
41,3.417,25191.42,0.02076,0.00749
41.1,3.425,25197.49,0.02089,0.00753
41.2,3.433,25206.35,0.02102,0.00759
41.3,3.442,25219.39,0.02115,0.00764
41.4,3.45,25230.3,0.02128,0.00769
41.5,3.458,25238.44,0.02141,0.00774
41.6,3.467,25252,0.02155,0.00779
41.7,3.475,25261.65,0.02168,0.00784
41.8,3.483,25275.01,0.02181,0.00788
41.9,3.492,25290.79,0.02195,0.00794
42,3.5,25293.96,0.02208,0.00799
42.1,3.508,25300.3,0.02222,0.00804
42.2,3.517,25310.58,0.02235,0.00808
42.3,3.525,25324.45,0.02248,0.00813
42.4,3.534,25327.41,0.02261,0.00819
42.5,3.542,25330.06,0.02275,0.00824
42.6,3.55,25339.69,0.02288,0.00828
42.7,3.558,25342.38,0.02301,0.00833
42.8,3.567,25354.55,0.02314,0.00838
42.9,3.575,25357.28,0.02327,0.00843
43,3.583,25357.92,0.0234,0.00849
43.1,3.592,25365.26,0.02354,0.00853
43.2,3.6,25370.5,0.02367,0.00858
43.3,3.608,25371.6,0.0238,0.00863
43.4,3.617,25375.57,0.02393,0.00868
43.5,3.625,25381.56,0.02406,0.00873
43.6,3.633,25385.46,0.02419,0.00878
43.7,3.642,25389.38,0.02432,0.00883
43.8,3.65,25391.4,0.02445,0.00888
43.9,3.658,25402.9,0.02459,0.00893
44,3.667,25408.48,0.02472,0.00898
44.1,3.675,25413.38,0.02485,0.00903
44.2,3.684,25427.33,0.02499,0.00908
44.3,3.692,25429,0.02511,0.00913
44.4,3.7,25433.27,0.02525,0.00918
44.5,3.708,25445.32,0.02537,0.00923
44.6,3.717,25455.58,0.0255,0.00928
44.7,3.725,25459.1,0.02564,0.00933
44.8,3.733,25466.23,0.02577,0.00938
44.9,3.742,25480.12,0.0259,0.00943
45,3.75,25484.39,0.02603,0.00947
45.1,3.758,25492.04,0.02616,0.00952
45.2,3.767,25508.67,0.02629,0.00957
45.3,3.775,25506.18,0.02643,0.00962
45.4,3.783,25517.94,0.02655,0.00966
45.5,3.792,25524.12,0.02668,0.00971
45.6,3.8,25528.64,0.02682,0.00976
45.7,3.808,25536.38,0.02695,0.0098
45.8,3.817,25543.96,0.02708,0.00985
45.9,3.825,25545.96,0.02721,0.00989
46,3.833,25550.06,0.02733,0.00994
46.1,3.842,25558.09,0.02746,0.00999
46.2,3.85,25568.2,0.0276,0.01004
46.3,3.858,25569.91,0.02773,0.01008
46.4,3.867,25571.69,0.02786,0.01014
46.5,3.875,25580.14,0.02799,0.01019
46.6,3.883,25582.19,0.02812,0.01023
46.7,3.892,25588.11,0.02825,0.01028
46.8,3.9,25592.1,0.02838,0.01033
46.9,3.908,25592.05,0.02851,0.01038
47,3.917,25594.94,0.02864,0.01043
47.1,3.925,25600.11,0.02877,0.01048
47.2,3.933,25605.03,0.0289,0.01053
47.3,3.942,25606.55,0.02903,0.01057
47.4,3.95,25609.38,0.02916,0.01062
47.5,3.958,25611.67,0.02929,0.01067
47.6,3.967,25612.92,0.02942,0.01072
47.7,3.975,25611.48,0.02955,0.01076
47.8,3.983,25618.32,0.02968,0.01081
47.9,3.992,25618.56,0.02981,0.01086
48,4,25621.69,0.02994,0.0109
48.1,4.008,25622.7,0.03007,0.01095
48.2,4.017,25624.45,0.0302,0.011
48.3,4.025,25625.29,0.03033,0.01105
48.4,4.034,25626.63,0.03045,0.0111
48.5,4.042,25628.95,0.03058,0.01114
48.6,4.05,25630.58,0.03071,0.01119
48.7,4.058,25633.12,0.03084,0.01124
48.8,4.067,25633.53,0.03098,0.01128
48.9,4.075,25634.53,0.03111,0.01133
49,4.083,25634.23,0.03124,0.01138
49.1,4.092,25638.04,0.03137,0.01143
49.2,4.1,25639.78,0.0315,0.01147
49.3,4.108,25643.9,0.03163,0.01152
49.4,4.117,25646.49,0.03175,0.01157
49.5,4.125,25647.44,0.03189,0.01161
49.6,4.133,25647.55,0.03202,0.01166
49.7,4.142,25655.2,0.03215,0.01171
49.8,4.15,25652.24,0.03228,0.01175
49.9,4.158,25656.87,0.03241,0.0118
50,4.167,25666.85,0.03254,0.01185
50.1,4.175,25663.92,0.03267,0.01189
50.2,4.183,25672.68,0.0328,0.01194
50.3,4.192,25680,0.03293,0.01199
50.4,4.2,25688.07,0.03306,0.01203
50.5,4.208,25694.67,0.03319,0.01208
50.6,4.217,25697.31,0.03332,0.01213
50.7,4.225,25707.22,0.03345,0.01217
50.8,4.233,25711.89,0.03357,0.01222
50.9,4.242,25712.87,0.0337,0.01227
51,4.25,25719.82,0.03383,0.01231
51.1,4.259,25723.22,0.03397,0.01236
51.2,4.267,25723.59,0.0341,0.01241
51.3,4.275,25727.33,0.03423,0.01245
51.4,4.283,25732.81,0.03436,0.0125
51.5,4.292,25742.41,0.03449,0.01255
51.6,4.3,25741.54,0.03461,0.01259
51.7,4.308,25746.87,0.03474,0.01264
51.8,4.317,25753.98,0.03487,0.01268
51.9,4.325,25756.69,0.035,0.01273
52,4.333,25756.65,0.03513,0.01277
52.1,4.342,25763.3,0.03526,0.01282
52.2,4.35,25766.06,0.03539,0.01287
52.3,4.358,25776.15,0.03552,0.01291
52.4,4.367,25779.95,0.03565,0.01296
52.5,4.375,25777.87,0.03578,0.013
52.6,4.383,25784.43,0.03591,0.01305
52.7,4.392,25793.99,0.03604,0.01308
52.8,4.4,25798.72,0.03617,0.01313
52.9,4.408,25801.19,0.0363,0.01318
53,4.417,25802.83,0.03643,0.01323
53.1,4.425,25811.24,0.03656,0.01328
53.2,4.433,25823.68,0.03668,0.01332
53.3,4.442,25821.19,0.03682,0.01337
53.4,4.45,25821.81,0.03695,0.01342
53.5,4.458,25831.48,0.03708,0.01346
53.6,4.467,25835.99,0.03721,0.01351
53.7,4.475,25854.38,0.03734,0.01356
53.8,4.483,25857.82,0.03746,0.01361
53.9,4.492,25862.51,0.03759,0.01365
54,4.5,25863.77,0.03772,0.0137
54.1,4.508,25882.11,0.03785,0.01375
54.2,4.517,25879.95,0.03798,0.01379
54.3,4.525,25892.42,0.03811,0.01384
54.4,4.533,25894.09,0.03824,0.01389
54.5,4.542,25895.58,0.03837,0.01394
54.6,4.55,25904.96,0.0385,0.01399
54.7,4.558,25916.56,0.03863,0.01403
54.8,4.567,25922.09,0.03876,0.01408
54.9,4.575,25926.43,0.03889,0.01413
55,4.583,25929.47,0.03902,0.01417
55.1,4.592,25932.82,0.03915,0.01422
55.2,4.6,25939.85,0.03928,0.01427
55.3,4.608,25945.29,0.03941,0.01432
55.4,4.617,25948.96,0.03953,0.01437
55.5,4.625,25948.06,0.03966,0.01441
55.6,4.633,25954.14,0.03979,0.01446
55.7,4.642,25959.66,0.03992,0.0145
55.8,4.65,25961.79,0.04005,0.01455
55.9,4.659,25962.46,0.04019,0.0146
56,4.667,25965.59,0.04031,0.01465
56.1,4.675,25966.77,0.04044,0.01469
56.2,4.683,25968.86,0.04057,0.01474
56.3,4.692,25968.7,0.0407,0.01479
56.4,4.7,25972.11,0.04083,0.01483
56.5,4.708,25973.1,0.04096,0.01488
56.6,4.717,25973.93,0.04108,0.01492
56.7,4.725,25976.99,0.04122,0.01497
56.8,4.733,25977.24,0.04134,0.01501
56.9,4.742,25978.54,0.04147,0.01506
57,4.75,25982.76,0.0416,0.01511
57.1,4.758,25984.61,0.04173,0.01515
57.2,4.767,25988.16,0.04186,0.0152
57.3,4.775,25992.11,0.04199,0.01525
57.4,4.783,25993.64,0.04212,0.01529
57.5,4.792,26005.28,0.04225,0.01534
57.6,4.8,26004.32,0.04239,0.01539
57.7,4.809,26010.1,0.04251,0.01543
57.8,4.817,26011.8,0.04264,0.01548
57.9,4.825,26023.11,0.04277,0.01553
58,4.834,26034.4,0.04291,0.01557
58.1,4.842,26032.14,0.04304,0.01562
58.2,4.85,26031.39,0.04316,0.01567
58.3,4.858,26044.04,0.04329,0.01571
58.4,4.867,26056.78,0.04342,0.01576
58.5,4.875,26053.12,0.04355,0.0158
58.6,4.883,26064.24,0.04368,0.01584
58.7,4.892,26071.47,0.04381,0.01589
58.8,4.9,26074.89,0.04394,0.01593
58.9,4.908,26076.29,0.04407,0.01598
59,4.917,26085.39,0.0442,0.01603
59.1,4.925,26089.22,0.04433,0.01607
59.2,4.933,26092.44,0.04446,0.01612
59.3,4.942,26102,0.04459,0.01616
59.4,4.95,26099.05,0.04472,0.01621
59.5,4.958,26105.99,0.04485,0.01625
59.6,4.967,26114.62,0.04498,0.0163
59.7,4.975,26117.82,0.04511,0.01635
59.8,4.983,26117.7,0.04525,0.01639
59.9,4.992,26122.1,0.04538,0.01644
60,5,26121.69,0.04551,0.01649
60.1,5.008,26125.59,0.04563,0.01654
60.2,5.017,26127.24,0.04577,0.01659
60.3,5.025,26129.51,0.0459,0.01664
60.4,5.033,26132.22,0.04603,0.01668
60.5,5.042,26136.05,0.04616,0.01673
60.6,5.05,26138.62,0.04629,0.01678
60.7,5.058,26140.9,0.04642,0.01682
60.8,5.067,26143.84,0.04655,0.01687
60.9,5.075,26149.98,0.04668,0.01692
61,5.083,26152.78,0.04681,0.01697
61.1,5.092,26151.57,0.04694,0.01701
61.2,5.1,26153.43,0.04707,0.01706
61.3,5.108,26157.3,0.0472,0.01711
61.4,5.117,26161.87,0.04733,0.01715
61.5,5.125,26161.68,0.04746,0.0172
61.6,5.133,26164.2,0.04759,0.01725
61.7,5.142,26163.49,0.04772,0.0173
61.8,5.15,26167.07,0.04785,0.01735
61.9,5.159,26170.27,0.04798,0.01739
62,5.167,26173.43,0.04811,0.01744
62.1,5.175,26175.76,0.04825,0.01749
62.2,5.183,26178.54,0.04837,0.01753
62.3,5.192,26181.29,0.04851,0.01758
62.4,5.2,26185.74,0.04864,0.01763
62.5,5.208,26182.39,0.04877,0.01767
62.6,5.217,26190.13,0.0489,0.01772
62.7,5.225,26191.93,0.04903,0.01777
62.8,5.233,26191.89,0.04917,0.01782
62.9,5.242,26197.69,0.04929,0.01786
63,5.25,26199.19,0.04943,0.01791
63.1,5.258,26200.84,0.04956,0.01796
63.2,5.267,26203.46,0.04969,0.018
63.3,5.275,26205.71,0.04981,0.01805
63.4,5.283,26209.18,0.04995,0.0181
63.5,5.292,26209.62,0.05008,0.01815
63.6,5.3,26212.14,0.05021,0.0182
63.7,5.308,26212.03,0.05034,0.01824
63.8,5.317,26213.89,0.05047,0.01829
63.9,5.325,26215.76,0.05061,0.01833
64,5.334,26221.07,0.05074,0.01838
64.1,5.342,26219.81,0.05087,0.01842
64.2,5.35,26221.73,0.051,0.01847
64.3,5.358,26224.92,0.05113,0.01852
64.4,5.367,26226.74,0.05127,0.01857
64.5,5.375,26234.62,0.05139,0.01862
64.6,5.383,26231.26,0.05153,0.01866
64.7,5.392,26233.99,0.05166,0.01871
64.8,5.4,26236.54,0.05179,0.01876
64.9,5.408,26239.66,0.05192,0.0188
65,5.417,26242.12,0.05206,0.01885
65.1,5.425,26244.94,0.05219,0.0189
65.2,5.433,26248.51,0.05233,0.01895
65.3,5.442,26252.89,0.05246,0.019
65.4,5.45,26252.87,0.05259,0.01904
65.5,5.458,26259.04,0.05272,0.01909
65.6,5.467,26267.28,0.05285,0.01914
65.7,5.475,26263.95,0.05298,0.01918
65.8,5.483,26271.12,0.05311,0.01923
65.9,5.492,26269.76,0.05324,0.01928
66,5.5,26275.46,0.05338,0.01933
66.1,5.508,26281.15,0.05351,0.01938
66.2,5.517,26284.18,0.05364,0.01943
66.3,5.525,26291.55,0.05378,0.01948
66.4,5.533,26294.61,0.05391,0.01952
66.5,5.542,26295.38,0.05404,0.01957
66.6,5.55,26304.86,0.05417,0.01961
66.7,5.558,26305.87,0.0543,0.01965
66.8,5.567,26310.28,0.05444,0.0197
66.9,5.575,26312.54,0.05457,0.01975
67,5.583,26318.36,0.05471,0.01979
67.1,5.592,26321.43,0.05484,0.01981
67.2,5.6,26328.06,0.05497,0.01986
67.3,5.608,26327.9,0.05511,0.01991
67.4,5.617,26327.05,0.05524,0.01995
67.5,5.625,26333.98,0.05537,0.02
67.6,5.633,26340.08,0.05551,0.02005
67.7,5.642,26339.95,0.05564,0.02009
67.8,5.65,26345.84,0.05577,0.02014
67.9,5.658,26351.13,0.0559,0.02019
68,5.667,26347.62,0.05603,0.02023
68.1,5.675,26351.25,0.05617,0.02028
68.2,5.683,26351.81,0.05631,0.02033
68.3,5.692,26353.26,0.05644,0.02038
68.4,5.7,26358.79,0.05658,0.02042
68.5,5.709,26359.11,0.05671,0.02047
68.6,5.717,26358.64,0.05684,0.02052
68.7,5.725,26368.62,0.05697,0.02057
68.8,5.734,26365.73,0.0571,0.02062
68.9,5.742,26371.91,0.05724,0.02066
69,5.75,26371.42,0.05737,0.02071
69.1,5.758,26375,0.0575,0.02076
69.2,5.767,26376.03,0.05764,0.02081
69.3,5.775,26377.81,0.05777,0.02085
69.4,5.783,26380.06,0.05791,0.0209
69.5,5.792,26383.33,0.05804,0.02095
69.6,5.8,26389.59,0.05818,0.02099
69.7,5.808,26387.53,0.05831,0.02104
69.8,5.817,26392.81,0.05844,0.02109
69.9,5.825,26395.51,0.05858,0.02114
70,5.833,26401.04,0.05871,0.02119
70.1,5.842,26398.9,0.05884,0.02123
70.2,5.85,26404.68,0.05898,0.02128
70.3,5.858,26406.01,0.05911,0.02133
70.4,5.867,26408.88,0.05925,0.02137
70.5,5.875,26409.97,0.05939,0.02142
70.6,5.884,26411.69,0.05952,0.02147
70.7,5.892,26409.59,0.05966,0.02152
70.8,5.9,26418.42,0.05979,0.02156
70.9,5.908,26417.84,0.05992,0.02161
71,5.917,26426.35,0.06005,0.02166
71.1,5.925,26436.13,0.0602,0.0217
71.2,5.933,26432.59,0.06033,0.02175
71.3,5.942,26435.73,0.06047,0.02179
71.4,5.95,26436.75,0.0606,0.02184
71.5,5.959,26447.69,0.06074,0.02189
71.6,5.967,26449.4,0.06087,0.02194
71.7,5.975,26447.9,0.06101,0.02199
71.8,5.983,26462.6,0.06114,0.02203
71.9,5.992,26459.79,0.06128,0.02208
72,6,26468.38,0.06142,0.02213
72.1,6.008,26468.74,0.06155,0.02217
72.2,6.017,26479.32,0.06169,0.02222
72.3,6.025,26484.78,0.06183,0.02226
72.4,6.033,26480.32,0.06196,0.02231
72.5,6.042,26492.42,0.0621,0.02236
72.6,6.05,26490.86,0.06223,0.02241
72.7,6.058,26494.52,0.06237,0.02245
72.8,6.067,26501.95,0.06251,0.0225
72.9,6.075,26503.51,0.06264,0.02255
73,6.083,26506.38,0.06278,0.0226
73.1,6.092,26512.65,0.06292,0.02265
73.2,6.1,26513.23,0.06305,0.02269
73.3,6.108,26518.85,0.06319,0.02274
73.4,6.117,26525.98,0.06333,0.02279
73.5,6.125,26519.61,0.06347,0.02283
73.6,6.133,26529.32,0.0636,0.02288
73.7,6.142,26531.76,0.06374,0.02293
73.8,6.15,26529.76,0.06387,0.02297
73.9,6.158,26535.52,0.06401,0.02302
74,6.167,26535.12,0.06415,0.02307
74.1,6.175,26545.53,0.06429,0.02312
74.2,6.183,26555.19,0.06443,0.02316
74.3,6.192,26555.07,0.06457,0.02322
74.4,6.2,26557.42,0.0647,0.02326
74.5,6.208,26560.39,0.06484,0.02331
74.6,6.217,26553.53,0.06498,0.02336
74.7,6.225,26558.16,0.06511,0.0234
74.8,6.234,26566.19,0.06525,0.02345
74.9,6.242,26568.31,0.06539,0.02349
75,6.25,26566.83,0.06553,0.02354
75.1,6.258,26573.56,0.06566,0.02359
75.2,6.267,26574.7,0.0658,0.02364
75.3,6.275,26579.51,0.06594,0.02369
75.4,6.283,26577.46,0.06608,0.02374
75.5,6.292,26580.35,0.06621,0.02378
75.6,6.3,26578.7,0.06635,0.02383
75.7,6.308,26583.16,0.06649,0.02388
75.8,6.317,26587.36,0.06663,0.02393
75.9,6.325,26582.97,0.06677,0.02398
76,6.334,26586.4,0.06691,0.02403
76.1,6.342,26588.33,0.06705,0.02407
76.2,6.35,26590.69,0.06719,0.02412
76.3,6.358,26589.66,0.06733,0.02417
76.4,6.367,26594.36,0.06747,0.02422
76.5,6.375,26595.34,0.0676,0.02427
76.6,6.383,26594.43,0.06775,0.02432
76.7,6.392,26595.16,0.06788,0.02436
76.8,6.4,26597.17,0.06802,0.02441
76.9,6.408,26597.34,0.06816,0.02446
77,6.417,26599.57,0.0683,0.0245
77.1,6.425,26597.38,0.06844,0.02455
77.2,6.433,26599.59,0.06858,0.0246
77.3,6.442,26600.96,0.06872,0.02464
77.4,6.45,26602.78,0.06886,0.0247
77.5,6.459,26602.16,0.069,0.02474
77.6,6.467,26601.29,0.06914,0.02479
77.7,6.475,26601.1,0.06928,0.02484
77.8,6.483,26604.02,0.06942,0.0249
77.9,6.492,26604.33,0.06957,0.02495
78,6.5,26604.03,0.06971,0.025
78.1,6.509,26605.15,0.06985,0.02504
78.2,6.517,26604.46,0.06999,0.02509
78.3,6.525,26603.26,0.07013,0.02514
78.4,6.533,26607,0.07027,0.02519
78.5,6.542,26606,0.07042,0.02524
78.6,6.55,26607.36,0.07056,0.02529
78.7,6.558,26608.03,0.07071,0.02534
78.8,6.567,26607.93,0.07085,0.02538
78.9,6.575,26606.56,0.07099,0.02543
79,6.583,26607.34,0.07113,0.02547
79.1,6.592,26608.4,0.07127,0.02552
79.2,6.6,26608.2,0.07141,0.02556
79.3,6.608,26608.78,0.07156,0.02561
79.4,6.617,26609.58,0.0717,0.02566
79.5,6.625,26610.42,0.07185,0.0257
79.6,6.633,26609.3,0.07199,0.02575
79.7,6.642,26611.25,0.07213,0.0258
79.8,6.65,26612.27,0.07227,0.02584
79.9,6.658,26611.04,0.07242,0.0259
80,6.667,26610.75,0.07257,0.02594
80.1,6.675,26611.69,0.07271,0.02599
80.2,6.683,26611.71,0.07286,0.02604
80.3,6.692,26613.32,0.073,0.02609
80.4,6.7,26613.58,0.07315,0.02614
80.5,6.708,26615.31,0.0733,0.02619
80.6,6.717,26614.09,0.07344,0.02624
80.7,6.725,26615.61,0.07359,0.0263
80.8,6.733,26614.9,0.07373,0.02635
80.9,6.742,26615.37,0.07388,0.0264
81,6.75,26616.24,0.07402,0.02645
81.1,6.758,26617.86,0.07417,0.0265
81.2,6.767,26614.05,0.07431,0.02655
81.3,6.775,26615.23,0.07446,0.0266
81.4,6.783,26617.03,0.0746,0.02665
81.5,6.792,26618.12,0.07475,0.0267
81.6,6.8,26617.86,0.0749,0.02675
81.7,6.808,26617.59,0.07504,0.0268
81.8,6.817,26618.12,0.07519,0.02685
81.9,6.825,26620.96,0.07534,0.0269
82,6.833,26618.31,0.07548,0.02695
82.1,6.842,26618.58,0.07563,0.027
82.2,6.85,26621.1,0.07577,0.02705
82.3,6.859,26621.58,0.07592,0.0271
82.4,6.867,26621.97,0.07607,0.02715
82.5,6.875,26622.17,0.07622,0.0272
82.6,6.883,26621.53,0.07637,0.02725
82.7,6.892,26623.74,0.07651,0.02731
82.8,6.9,26625.75,0.07667,0.02736
82.9,6.908,26623.03,0.07681,0.02741
83,6.917,26624.73,0.07697,0.02746
83.1,6.925,26625.04,0.07711,0.02751
83.2,6.933,26623.02,0.07726,0.02756
83.3,6.942,26626.99,0.07741,0.02761
83.4,6.95,26626.76,0.07756,0.02766
83.5,6.958,26626.66,0.07771,0.02771
83.6,6.967,26628.39,0.07786,0.02776
83.7,6.975,26626.37,0.07801,0.02782
83.8,6.983,26625.94,0.07816,0.02787
83.9,6.992,26629.12,0.07831,0.02792
84,7,26628.16,0.07846,0.02797
84.1,7.008,26627.6,0.07861,0.02802
84.2,7.017,26627.51,0.07877,0.02807
84.3,7.025,26629.22,0.07892,0.02812
84.4,7.034,26631.46,0.07907,0.02817
84.5,7.042,26629.34,0.07922,0.02822
84.6,7.05,26629.75,0.07937,0.02827
84.7,7.058,26632.23,0.07952,0.02832
84.8,7.067,26628.75,0.07968,0.02837
84.9,7.075,26632.29,0.07983,0.02842
85,7.083,26633.92,0.07999,0.02847
85.1,7.092,26631.44,0.08014,0.02852
85.2,7.1,26630.86,0.08029,0.02858
85.3,7.108,26632.65,0.08045,0.02863
85.4,7.117,26634.91,0.0806,0.02868
85.5,7.125,26634.16,0.08076,0.02873
85.6,7.133,26633.72,0.08091,0.02878
85.7,7.142,26635.13,0.08107,0.02883
85.8,7.15,26634.41,0.08123,0.02888
85.9,7.158,26633.89,0.08138,0.02893
86,7.167,26635.31,0.08154,0.02899
86.1,7.175,26634.37,0.0817,0.02904
86.2,7.183,26634.94,0.08185,0.0291
86.3,7.192,26635.92,0.08201,0.02915
86.4,7.2,26634.62,0.08216,0.0292
86.5,7.208,26637.97,0.08232,0.02925
86.6,7.217,26637.8,0.08248,0.0293
86.7,7.225,26636.04,0.08264,0.02935
86.8,7.233,26636.38,0.0828,0.0294
86.9,7.242,26638.49,0.08296,0.02945
87,7.25,26640.75,0.08311,0.02951
87.1,7.258,26638.58,0.08327,0.02956
87.2,7.267,26638.11,0.08343,0.02961
87.3,7.275,26638.67,0.08359,0.02966
87.4,7.283,26638.93,0.08375,0.02971
87.5,7.292,26639.09,0.08392,0.02976
87.6,7.3,26641.09,0.08408,0.02981
87.7,7.308,26641.29,0.08423,0.02987
87.8,7.317,26639.88,0.0844,0.02992
87.9,7.325,26638.87,0.08455,0.02997
88,7.333,26640.09,0.08472,0.03002
88.1,7.342,26639.38,0.08488,0.03007
88.2,7.35,26642.35,0.08505,0.03012
88.3,7.358,26641.53,0.08522,0.03018
88.4,7.367,26640.07,0.08538,0.03023
88.5,7.375,26641.99,0.08554,0.03028
88.6,7.383,26640.69,0.08571,0.03034
88.7,7.392,26642.07,0.08588,0.03039
88.8,7.4,26642.93,0.08604,0.03044
88.9,7.409,26642.33,0.08621,0.03049
89,7.417,26640.58,0.08637,0.03054
89.1,7.425,26641.87,0.08654,0.0306
89.2,7.434,26642.82,0.08671,0.03065
89.3,7.442,26642.04,0.08688,0.0307
89.4,7.45,26641.42,0.08704,0.03075
89.5,7.458,26641.31,0.08721,0.0308
89.6,7.467,26643.15,0.08737,0.03085
89.7,7.475,26643.66,0.08754,0.0309
89.8,7.483,26643.46,0.08771,0.03095
89.9,7.492,26641.99,0.08789,0.031
90,7.5,26643.63,0.08806,0.03105
90.1,7.508,26644.2,0.08823,0.03108
90.2,7.517,26642.33,0.08839,0.03114
90.3,7.525,26644.36,0.08857,0.03119
90.4,7.534,26644.2,0.08874,0.03125
90.5,7.542,26641.91,0.08891,0.0313
90.6,7.55,26644.35,0.08909,0.03135
90.7,7.558,26644.44,0.08926,0.03141
90.8,7.567,26643.17,0.08943,0.03146
90.9,7.575,26645.22,0.08961,0.03152
91,7.584,26642.5,0.08979,0.03157
91.1,7.592,26644.6,0.08996,0.03163
91.2,7.6,26644.12,0.09013,0.03168
91.3,7.608,26644.58,0.09031,0.03173
91.4,7.617,26645.3,0.09048,0.03179
91.5,7.625,26644.74,0.09067,0.03184
91.6,7.633,26643.21,0.09084,0.03189
91.7,7.642,26644.95,0.09102,0.03195
91.8,7.65,26645.01,0.0912,0.032
91.9,7.659,26644.04,0.09138,0.03205
92,7.667,26644.33,0.09156,0.0321
92.1,7.675,26644.05,0.09174,0.03216
92.2,7.683,26643.52,0.09192,0.03221
92.3,7.692,26644.09,0.0921,0.03226
92.4,7.7,26644.55,0.09228,0.03231
92.5,7.708,26645.96,0.09246,0.03237
92.6,7.717,26645.24,0.09264,0.03242
92.7,7.725,26643.61,0.09283,0.03247
92.8,7.733,26643.27,0.09301,0.03252
92.9,7.742,26642.37,0.0932,0.03257
93,7.75,26645.8,0.09339,0.03263
93.1,7.758,26643.89,0.09357,0.03268
93.2,7.767,26644.64,0.09376,0.03273
93.3,7.775,26643.79,0.09395,0.03278
93.4,7.783,26644.02,0.09414,0.03284
93.5,7.792,26644.54,0.09433,0.03289
93.6,7.8,26644.68,0.09452,0.03294
93.7,7.808,26643.16,0.09471,0.033
93.8,7.817,26642.27,0.09491,0.03305
93.9,7.825,26644.46,0.09511,0.0331
94,7.833,26641.09,0.09529,0.03315
94.1,7.842,26641.99,0.09549,0.0332
94.2,7.85,26643.2,0.09568,0.03325
94.3,7.858,26642.61,0.09587,0.03331
94.4,7.867,26640.83,0.09607,0.03336
94.5,7.875,26643,0.09626,0.03341
94.6,7.883,26642.88,0.09646,0.03347
94.7,7.892,26641.54,0.09666,0.03352
94.8,7.9,26640.64,0.09685,0.03357
94.9,7.908,26643.2,0.09705,0.03362
95,7.917,26641.97,0.09726,0.03367
95.1,7.925,26642.03,0.09746,0.03372
95.2,7.933,26641.34,0.09766,0.03377
95.3,7.942,26640.66,0.09786,0.03382
95.4,7.95,26641.58,0.09807,0.03387
95.5,7.958,26639.78,0.09828,0.03392
95.6,7.967,26638.61,0.09848,0.03398
95.7,7.975,26639.85,0.09868,0.03403
95.8,7.983,26640.91,0.0989,0.03408
95.9,7.992,26639.49,0.09911,0.03413
96,8,26638.9,0.09932,0.03418
96.1,8.008,26638.65,0.09952,0.03423
96.2,8.017,26640.43,0.09973,0.03427
96.3,8.025,26637.38,0.09995,0.03432
96.4,8.034,26636.81,0.10016,0.03436
96.5,8.042,26635.15,0.10037,0.03441
96.6,8.05,26638.4,0.10059,0.03445
96.7,8.058,26638.39,0.10081,0.0345
96.8,8.067,26635.92,0.10102,0.03455
96.9,8.075,26635.39,0.10124,0.03459
97,8.083,26634.42,0.10146,0.03463
97.1,8.092,26634.21,0.10168,0.03467
97.2,8.1,26635.09,0.1019,0.03472
97.3,8.108,26633.54,0.10212,0.03476
97.4,8.117,26633.99,0.10234,0.03481
97.5,8.125,26631.55,0.10256,0.03485
97.6,8.133,26631.79,0.10279,0.03489
97.7,8.142,26630.98,0.10301,0.03493
97.8,8.15,26631.25,0.10325,0.03497
97.9,8.159,26632.22,0.10347,0.03501
98,8.167,26631.47,0.1037,0.03506
98.1,8.175,26628.96,0.10393,0.0351
98.2,8.183,26626.17,0.10416,0.03514
98.3,8.192,26628.26,0.10439,0.03518
98.4,8.2,26627.11,0.10462,0.03521
98.5,8.209,26628.64,0.10486,0.03524
98.6,8.217,26625.41,0.10509,0.03528
98.7,8.225,26625.54,0.10533,0.03531
98.8,8.233,26624.7,0.10557,0.03535
98.9,8.242,26624.46,0.10582,0.03539
99,8.25,26625.12,0.10606,0.03543
99.1,8.258,26623.43,0.10631,0.03546
99.2,8.267,26620.02,0.10655,0.03549
99.3,8.275,26620.65,0.10679,0.03553
99.4,8.283,26619.05,0.10703,0.03556
99.5,8.292,26619.45,0.10728,0.0356
99.6,8.3,26618.12,0.10753,0.03563
99.7,8.308,26617.8,0.10777,0.03564
99.8,8.317,26618.46,0.10802,0.03568
99.9,8.325,26615.57,0.10827,0.03571
100,8.333,26615.77,0.10852,0.03575
100.1,8.342,26613.72,0.10878,0.03578
100.2,8.35,26614.36,0.10904,0.03581
100.3,8.358,26612.12,0.1093,0.03584
100.4,8.367,26610.76,0.10955,0.03587
100.5,8.375,26611.28,0.10981,0.0359
100.6,8.383,26611.54,0.11007,0.03593
100.7,8.392,26609.75,0.11033,0.03596
100.8,8.4,26609.35,0.11059,0.03598
100.9,8.408,26608.59,0.11085,0.036
101,8.417,26608.89,0.11111,0.03603
101.1,8.425,26607.27,0.11139,0.03605
101.2,8.433,26605.94,0.11165,0.03608
101.3,8.442,26604.82,0.11192,0.0361
101.4,8.45,26603.47,0.11219,0.03613
101.5,8.458,26603.35,0.11246,0.03615
101.6,8.467,26601.48,0.11273,0.03617
101.7,8.475,26601.82,0.113,0.03619
101.8,8.484,26601.48,0.11328,0.03621
101.9,8.492,26598.37,0.11355,0.03623
102,8.5,26597.12,0.11383,0.03624
102.1,8.508,26596.73,0.11411,0.03627
102.2,8.517,26592.36,0.11439,0.03629
102.3,8.525,26590.38,0.11467,0.03631
102.4,8.533,26588.32,0.11494,0.03632
102.5,8.542,26583.4,0.11522,0.03634
102.6,8.55,26583.93,0.11551,0.03635
102.7,8.558,26575.63,0.11579,0.03637
102.8,8.567,26573.57,0.11607,0.03639
102.9,8.575,26570.12,0.11635,0.0364
103,8.583,26562.25,0.11663,0.03641
103.1,8.592,26556.22,0.11692,0.03642
103.2,8.6,26556.71,0.11722,0.03644
103.3,8.608,26544.45,0.11751,0.03645
103.4,8.617,26533.19,0.1178,0.03647
103.5,8.625,26531.22,0.11809,0.03648
103.6,8.633,26520.49,0.11838,0.03649
103.7,8.642,26511.29,0.11867,0.0365
103.8,8.65,26501.41,0.11896,0.03651
103.9,8.658,26490.31,0.11926,0.03652
104,8.667,26488.51,0.11956,0.03653
104.1,8.675,26472.86,0.11986,0.03654
104.2,8.683,26451.45,0.12016,0.03655
104.3,8.692,26454.34,0.12045,0.03656
104.4,8.7,26449.43,0.12075,0.03657
104.5,8.708,26437.24,0.12105,0.03658
104.6,8.717,26424.28,0.12136,0.03659
104.7,8.725,26409.62,0.12166,0.03659
104.8,8.733,26409.48,0.12195,0.0366
104.9,8.742,26408.47,0.12226,0.03661
105,8.75,26392.94,0.12256,0.03661
105.1,8.758,26390.68,0.12286,0.03662
105.2,8.767,26384.47,0.12316,0.03663
105.3,8.775,26381.45,0.12347,0.03664
105.4,8.783,26371.21,0.12377,0.0366
105.5,8.792,26369.14,0.12408,0.0366
105.6,8.8,26363.33,0.12439,0.03661
105.7,8.808,26356.52,0.1247,0.03663
105.8,8.817,26347.33,0.12501,0.03664
105.9,8.825,26337.71,0.12531,0.03664
106,8.833,26333.45,0.12562,0.03665
106.1,8.842,26329.41,0.12594,0.03666
106.2,8.85,26318.39,0.12625,0.03667
106.3,8.858,26308.19,0.12656,0.03668
106.4,8.867,26299.49,0.12688,0.03668
106.5,8.875,26292.27,0.1272,0.03669
106.6,8.883,26275.99,0.12752,0.03669
106.7,8.892,26260.27,0.12783,0.0367
106.8,8.9,26256.24,0.12815,0.03671
106.9,8.908,26248.75,0.12846,0.03671
107,8.917,26242.91,0.12878,0.03672
107.1,8.925,26235.33,0.12909,0.03672
107.2,8.933,26228.48,0.12941,0.03672
107.3,8.942,26223.51,0.12972,0.03673
107.4,8.95,26219.34,0.13004,0.03673
107.5,8.958,26214.95,0.13036,0.03674
107.6,8.967,26207.88,0.13068,0.03674
107.7,8.975,26202.96,0.13101,0.03675
107.8,8.983,26197.53,0.13133,0.03675
107.9,8.992,26190.21,0.13164,0.03675
108,9,26184.96,0.13196,0.03676
108.1,9.008,26178.58,0.13228,0.03676
108.2,9.017,26169.98,0.1326,0.03677
108.3,9.025,26163.57,0.13293,0.03677
108.4,9.033,26152.98,0.13325,0.03677
108.5,9.042,26152.67,0.13357,0.03677
108.6,9.05,26150.89,0.1339,0.03678
108.7,9.058,26137.53,0.13422,0.03678
108.8,9.067,26131.27,0.13455,0.03679
108.9,9.075,26124.5,0.13487,0.03679
109,9.083,26114.38,0.13519,0.03679
109.1,9.092,26108.63,0.13552,0.03679
109.2,9.1,26095.77,0.13584,0.03679
109.3,9.109,26084.14,0.13617,0.03679
109.4,9.117,26070.75,0.1365,0.03679
109.5,9.125,26059.22,0.13683,0.0368
109.6,9.133,26035.51,0.13715,0.0368
109.7,9.142,26029.02,0.13747,0.03681
109.8,9.15,26017.63,0.13781,0.03681
109.9,9.159,25995.99,0.13814,0.03681
110,9.167,25986.74,0.13846,0.03682
110.1,9.175,25981.93,0.13878,0.03682
110.2,9.183,25976.64,0.13911,0.03683
110.3,9.192,25971.86,0.13945,0.03684
110.4,9.2,25965.3,0.13977,0.03684
110.5,9.208,25963.82,0.14009,0.03683
110.6,9.217,25955.98,0.14042,0.03683
110.7,9.225,25947.51,0.14076,0.03683
110.8,9.233,25940.89,0.14108,0.03684
110.9,9.242,25925.53,0.14141,0.03684
111,9.25,25908.31,0.14175,0.03685
111.1,9.258,25888.99,0.14208,0.03685
111.2,9.267,25873.34,0.1424,0.03683
111.3,9.275,25853.16,0.14274,0.03684
111.4,9.283,25839.43,0.14306,0.03684
111.5,9.292,25827.8,0.1434,0.03683
111.6,9.3,25805.26,0.14373,0.03684
111.7,9.308,25795.45,0.14407,0.03684
111.8,9.317,25782.12,0.1444,0.03684
111.9,9.325,25767.75,0.14473,0.03684
112,9.334,25760.61,0.14507,0.03684
112.1,9.342,25745.96,0.14539,0.03683
112.2,9.35,25737.97,0.14573,0.03681
112.3,9.358,25728.41,0.14606,0.03682
112.4,9.367,25712.44,0.14639,0.03682
112.5,9.375,25697.6,0.14672,0.03682
112.6,9.383,25687.27,0.14705,0.03682
112.7,9.392,25664.74,0.14739,0.03682
112.8,9.4,25657.68,0.14772,0.03683
112.9,9.408,25644.95,0.14805,0.03682
113,9.417,25641.17,0.14838,0.03682
113.1,9.425,25643.24,0.14872,0.03683
113.2,9.433,25632.47,0.14905,0.03683
113.3,9.442,25629.27,0.14939,0.03683
113.4,9.45,25626.69,0.14972,0.03683
113.5,9.458,25622.48,0.15005,0.03683
113.6,9.467,25617.8,0.15039,0.03684
113.7,9.475,25614.14,0.15072,0.03684
113.8,9.483,25605.85,0.15105,0.03684
113.9,9.492,25596.28,0.15139,0.03683
114,9.5,25591.48,0.15173,0.03683
114.1,9.509,25582.73,0.15207,0.03683
114.2,9.517,25569.85,0.15241,0.03683
114.3,9.525,25546.88,0.15275,0.03683
114.4,9.533,25538.22,0.15308,0.03682
114.5,9.542,25519.85,0.15342,0.03683
114.6,9.55,25496.53,0.15376,0.03685
114.7,9.558,25466.24,0.15409,0.03685
114.8,9.567,25451.57,0.15443,0.03685
114.9,9.575,25434.55,0.15477,0.03686
115,9.583,25417.02,0.15511,0.03686
115.1,9.592,25397.03,0.15544,0.03685
115.2,9.6,25386.1,0.15578,0.03685
115.3,9.608,25372.62,0.15612,0.03685
115.4,9.617,25362.88,0.15646,0.03686
115.5,9.625,25349.48,0.15679,0.03686
115.6,9.633,25331.91,0.15713,0.03684
115.7,9.642,25313.1,0.15746,0.03682
115.8,9.65,25296.07,0.1578,0.03682
115.9,9.658,25262.59,0.15814,0.03683
116,9.667,25240.61,0.15848,0.03683
116.1,9.675,25221.54,0.15882,0.03683
116.2,9.684,25181.56,0.15916,0.03684
116.3,9.692,25165.26,0.1595,0.03683
116.4,9.7,25148.6,0.15984,0.03683
116.5,9.708,25134.72,0.16018,0.03683
116.6,9.717,25127.23,0.16051,0.03683
116.7,9.725,25119.82,0.16086,0.03684
116.8,9.733,25115.23,0.1612,0.03684
116.9,9.742,25112.56,0.16153,0.03685
117,9.75,25111.57,0.16188,0.03686
117.1,9.758,25110.62,0.16222,0.03686
117.2,9.767,25109.58,0.16256,0.03686
117.3,9.775,25105.47,0.16291,0.03686
117.4,9.783,25101.87,0.16324,0.03685
117.5,9.792,25092.43,0.16358,0.03685
117.6,9.8,25076.94,0.16392,0.03685
117.7,9.808,25063.58,0.16426,0.03686
117.8,9.817,25037.7,0.16459,0.03687
117.9,9.825,25013.37,0.16493,0.03688
118,9.833,24995,0.16527,0.03688
118.1,9.842,24979.75,0.16561,0.03688
118.2,9.85,24968.88,0.16594,0.03689
118.3,9.858,24955.81,0.16628,0.03689
118.4,9.867,24941.91,0.16663,0.03689
118.5,9.875,24919.41,0.16697,0.03689
118.6,9.883,24893.81,0.16731,0.03689
118.7,9.892,24878.78,0.16765,0.03689
118.8,9.9,24860.16,0.16798,0.03689
118.9,9.908,24838.4,0.16833,0.03689
119,9.917,24818.5,0.16867,0.03689
119.1,9.925,24802.04,0.16901,0.03689
119.2,9.933,24785.33,0.16936,0.03689
119.3,9.942,24774.72,0.1697,0.03689
119.4,9.95,24763.34,0.17005,0.03689
119.5,9.958,24748.96,0.17039,0.03689
119.6,9.967,24725.8,0.17074,0.03689
119.7,9.975,24683.87,0.17107,0.03688
119.8,9.983,24653.39,0.17141,0.03688
119.9,9.992,24623.81,0.17175,0.03688
120,10,24597.71,0.17209,0.03688
120.1,10.008,24571.72,0.17245,0.03688
120.2,10.017,24555.9,0.17279,0.03687
120.3,10.025,24550.16,0.17313,0.03687
120.4,10.033,24544.73,0.17347,0.03687
120.5,10.042,24539.97,0.17382,0.03687
120.6,10.05,24532.6,0.17416,0.03687
120.7,10.058,24524.26,0.17451,0.03687
120.8,10.067,24512.95,0.17485,0.03686
120.9,10.075,24492.49,0.17519,0.03687
121,10.084,24465.64,0.17553,0.03687
121.1,10.092,24440.43,0.17588,0.03687
121.2,10.1,24415.81,0.17623,0.03686
121.3,10.108,24385.96,0.17657,0.03686
121.4,10.117,24357.57,0.17691,0.03686
121.5,10.125,24339.88,0.17726,0.03687
121.6,10.133,24324.97,0.1776,0.03687
121.7,10.142,24317.26,0.17795,0.03687
121.8,10.15,24303.39,0.1783,0.03687
121.9,10.158,24286.98,0.17864,0.03688
122,10.167,24262.38,0.17899,0.03687
122.1,10.175,24233.19,0.17934,0.03688
122.2,10.183,24195.9,0.17968,0.03687
122.3,10.192,24177.78,0.18003,0.03687
122.4,10.2,24157.31,0.18038,0.03688
122.5,10.208,24148.87,0.18072,0.03688
122.6,10.217,24140.72,0.18107,0.03688
122.7,10.225,24124.73,0.18142,0.03688
122.8,10.233,24111.19,0.18176,0.03688
122.9,10.242,24094.63,0.1821,0.03688
123,10.25,24078.43,0.18245,0.03688
123.1,10.259,24065.74,0.18279,0.03688
123.2,10.267,24056.49,0.18314,0.03688
123.3,10.275,24042.53,0.18349,0.03688
123.4,10.284,24020.9,0.18383,0.03688
123.5,10.292,23985.01,0.18418,0.03689
123.6,10.3,23958.95,0.18453,0.03689
123.7,10.309,23931.09,0.18488,0.0369
123.8,10.317,23910.32,0.18523,0.0369
123.9,10.325,23890.84,0.18558,0.0369
124,10.333,23865.84,0.18592,0.0369
124.1,10.342,23837.75,0.18627,0.03691
124.2,10.35,23803.73,0.18662,0.03691
124.3,10.358,23770.15,0.18697,0.0369
124.4,10.367,23737.47,0.18732,0.03689
124.5,10.375,23709.77,0.18767,0.03688
124.6,10.383,23690.27,0.18802,0.03687
124.7,10.392,23678.05,0.18837,0.03687
124.8,10.4,23666.9,0.18872,0.03687
124.9,10.408,23647.04,0.18907,0.03686
125,10.417,23615.69,0.18942,0.03685
125.1,10.425,23595.53,0.18976,0.03684
125.2,10.433,23579.13,0.19011,0.03685
125.3,10.442,23573.17,0.19046,0.03687
125.4,10.45,23566.61,0.19081,0.03688
125.5,10.459,23563.05,0.19116,0.03689
125.6,10.467,23559.77,0.19151,0.0369
125.7,10.475,23553.61,0.19185,0.03691
125.8,10.483,23542.62,0.19221,0.03692
125.9,10.492,23524.3,0.19256,0.03692
126,10.5,23488.18,0.19291,0.03692
126.1,10.508,23440.47,0.19326,0.03692
126.2,10.517,23396.7,0.1936,0.03692
126.3,10.525,23365.57,0.19395,0.03691
126.4,10.533,23343,0.1943,0.03691
126.5,10.542,23316.25,0.19465,0.0369
126.6,10.55,23290.28,0.19501,0.03688
126.7,10.558,23242.59,0.19536,0.0369
126.8,10.567,23193.7,0.19571,0.03691
126.9,10.575,23140,0.19606,0.03692
127,10.583,23100.18,0.19641,0.03694
127.1,10.592,23077.5,0.19676,0.03694
127.2,10.6,23054.21,0.19712,0.03694
127.3,10.608,23030.88,0.19746,0.03694
127.4,10.617,23011.28,0.19781,0.03694
127.5,10.625,22987.69,0.19817,0.03694
127.6,10.633,22969.14,0.19853,0.03694
127.7,10.642,22955.9,0.19888,0.03694
127.8,10.65,22934.05,0.19924,0.03694
127.9,10.658,22911.91,0.19958,0.03694
128,10.667,22886.54,0.19994,0.03695
128.1,10.675,22873.89,0.2003,0.03695
128.2,10.683,22865.37,0.20065,0.03695
128.3,10.692,22848.16,0.201,0.03695
128.4,10.7,22821.18,0.20135,0.03696
128.5,10.708,22787.13,0.20171,0.03696
128.6,10.717,22751.28,0.20206,0.03696
128.7,10.725,22716.54,0.20241,0.03696
128.8,10.733,22685.39,0.20278,0.03696
128.9,10.742,22662.2,0.20313,0.03697
129,10.75,22622,0.20348,0.03698
129.1,10.759,22591.26,0.20384,0.03698
129.2,10.767,22566.05,0.2042,0.03694
129.3,10.775,22545.91,0.20456,0.03693
129.4,10.783,22521.37,0.20492,0.03692
129.5,10.792,22495.79,0.20528,0.03692
129.6,10.8,22472.03,0.20564,0.03692
129.7,10.809,22437.3,0.20601,0.03692
129.8,10.817,22329.31,0.2064,0.03691
129.9,10.825,22244.53,0.2068,0.03688
130,10.833,22080.27,0.20725,0.03688
130.1,10.842,14889.46,0.21282,0.0334
130.108,10.843,9921.37,0.21367,0.03345