File: Labs/Lab 2 Tension/6061 Aluminum Sample 2.csv
Time (s),Extension (mm),Load (N),Axial Strain (mm/mm),Transverse Strain (mm/mm)
0,0,0.04,0,0
0.1,0.004,2.43,0,0
0.2,0.014,68.63,0.00004,0.00001
0.3,0.025,157.02,0.00007,0.00001
0.4,0.034,234.75,0.00009,0.00001
0.5,0.042,283.98,0.00011,0.00001
0.6,0.05,329.15,0.00013,0.00001
0.7,0.059,374.55,0.00015,0.00002
0.8,0.067,427.84,0.00016,0.00002
0.9,0.075,495.2,0.00018,0.00002
1,0.084,543.91,0.00019,0.00002
1.1,0.092,564.72,0.00021,0.00002
1.2,0.1,580.69,0.00022,0.00002
1.3,0.109,598.18,0.00024,0.00002
1.4,0.117,610.31,0.00025,0.00003
1.5,0.125,618.26,0.00026,0.00003
1.6,0.134,624.75,0.00028,0.00003
1.7,0.142,634.93,0.00029,0.00003
1.8,0.15,671.07,0.0003,0.00003
1.9,0.159,698.51,0.00031,0.00003
2,0.167,728.35,0.00033,0.00003
2.1,0.175,760.65,0.00034,0.00003
2.2,0.184,792.56,0.00035,0.00004
2.3,0.192,831.51,0.00036,0.00004
2.4,0.2,866.54,0.00037,0.00004
2.5,0.208,903.69,0.00038,0.00004
2.6,0.217,946.27,0.00039,0.00004
2.7,0.225,1011.35,0.0004,0.00004
2.8,0.233,1047.59,0.00041,0.00004
2.9,0.242,1070.53,0.00042,0.00004
3,0.25,1086.27,0.00043,0.00004
3.1,0.259,1109.68,0.00044,0.00005
3.2,0.267,1142,0.00045,0.00005
3.3,0.275,1178.87,0.00046,0.00005
3.4,0.284,1218.29,0.00047,0.00005
3.5,0.292,1274.47,0.00048,0.00005
3.6,0.3,1302.9,0.00049,0.00005
3.7,0.309,1333.76,0.0005,0.00005
3.8,0.317,1375.06,0.00051,0.00005
3.9,0.325,1411.45,0.00052,0.00005
4,0.334,1455.43,0.00053,0.00005
4.1,0.342,1507.71,0.00053,0.00006
4.2,0.35,1544.45,0.00054,0.00006
4.3,0.359,1563.51,0.00055,0.00006
4.4,0.367,1578.13,0.00056,0.00006
4.5,0.375,1595.17,0.00057,0.00006
4.6,0.383,1630.49,0.00058,0.00006
4.7,0.392,1700.28,0.00059,0.00006
4.8,0.4,1775.73,0.0006,0.00006
4.9,0.408,1835.93,0.00061,0.00006
5,0.417,1904.06,0.00062,0.00007
5.1,0.425,1950.41,0.00063,0.00007
5.2,0.433,1981.26,0.00063,0.00007
5.3,0.442,2040.54,0.00064,0.00007
5.4,0.45,2088.43,0.00065,0.00007
5.5,0.459,2108.65,0.00066,0.00007
5.6,0.467,2126.64,0.00067,0.00007
5.7,0.475,2160.66,0.00068,0.00008
5.8,0.483,2195.96,0.00069,0.00008
5.9,0.492,2277.45,0.0007,0.00008
6,0.5,2338.01,0.00071,0.00008
6.1,0.509,2400.55,0.00072,0.00008
6.2,0.517,2484.53,0.00072,0.00008
6.3,0.525,2561.03,0.00073,0.00008
6.4,0.534,2615.35,0.00075,0.00008
6.5,0.542,2651.55,0.00076,0.00009
6.6,0.55,2674.59,0.00076,0.00009
6.7,0.558,2707.95,0.00077,0.00009
6.8,0.567,2767.02,0.00078,0.00009
6.9,0.575,2818.28,0.00079,0.00009
7,0.584,2900.94,0.0008,0.00009
7.1,0.592,2975,0.00081,0.0001
7.2,0.6,3042.04,0.00082,0.0001
7.3,0.608,3095.38,0.00083,0.0001
7.4,0.617,3119.83,0.00084,0.0001
7.5,0.625,3157.3,0.00085,0.0001
7.6,0.634,3242.55,0.00086,0.00011
7.7,0.642,3341.55,0.00087,0.00011
7.8,0.65,3395.24,0.00088,0.00011
7.9,0.658,3452.74,0.00089,0.00011
8,0.667,3522.59,0.0009,0.00011
8.1,0.675,3618.15,0.00091,0.00012
8.2,0.684,3667.38,0.00092,0.00012
8.3,0.692,3685.35,0.00093,0.00012
8.4,0.7,3722.08,0.00094,0.00012
8.5,0.708,3816.14,0.00095,0.00012
8.6,0.717,3874.07,0.00096,0.00013
8.7,0.725,3974.45,0.00098,0.00013
8.8,0.734,4056.56,0.00098,0.00013
8.9,0.742,4135.01,0.00099,0.00013
9,0.75,4165,0.00101,0.00013
9.1,0.758,4187.24,0.00102,0.00014
9.2,0.767,4232.19,0.00103,0.00014
9.3,0.775,4369.51,0.00104,0.00014
9.4,0.783,4449.01,0.00105,0.00014
9.5,0.792,4515.83,0.00106,0.00014
9.6,0.8,4609.87,0.00107,0.00015
9.7,0.809,4661.59,0.00108,0.00015
9.8,0.817,4706.35,0.0011,0.00015
9.9,0.825,4756.62,0.00111,0.00015
10,0.833,4836.06,0.00112,0.00016
10.1,0.842,4898.66,0.00113,0.00016
10.2,0.85,5006.95,0.00114,0.00016
10.3,0.859,5105.84,0.00115,0.00016
10.4,0.867,5191.49,0.00117,0.00017
10.5,0.875,5227.4,0.00117,0.00017
10.6,0.883,5256.96,0.00119,0.00017
10.7,0.892,5347.3,0.0012,0.00017
10.8,0.9,5446.91,0.00121,0.00018
10.9,0.909,5524.33,0.00122,0.00018
11,0.917,5615.93,0.00123,0.00018
11.1,0.925,5668.27,0.00125,0.00018
11.2,0.933,5719.28,0.00126,0.00018
11.3,0.942,5813.3,0.00127,0.00019
11.4,0.95,5913.46,0.00128,0.00019
11.5,0.958,5991.2,0.0013,0.00019
11.6,0.967,6084.41,0.00131,0.0002
11.7,0.975,6167.69,0.00132,0.0002
11.8,0.983,6201.26,0.00133,0.0002
11.9,0.992,6243.24,0.00135,0.0002
12,1,6300.03,0.00136,0.0002
12.1,1.008,6433.06,0.00137,0.00021
12.2,1.017,6524.4,0.00138,0.00021
12.3,1.025,6655.94,0.00139,0.00021
12.4,1.034,6752.74,0.00141,0.00022
12.5,1.042,6773.24,0.00142,0.00022
12.6,1.05,6819.46,0.00143,0.00022
12.7,1.058,6905.23,0.00145,0.00022
12.8,1.067,6980.84,0.00146,0.00023
12.9,1.075,7057.11,0.00147,0.00023
13,1.084,7197.88,0.00149,0.00023
13.1,1.092,7266.17,0.0015,0.00024
13.2,1.1,7314.01,0.00151,0.00024
13.3,1.108,7419.83,0.00152,0.00024
13.4,1.117,7533.39,0.00154,0.00024
13.5,1.125,7597,0.00155,0.00025
13.6,1.133,7669.91,0.00156,0.00025
13.7,1.142,7719.1,0.00158,0.00025
13.8,1.15,7784.64,0.00159,0.00026
13.9,1.158,7881.29,0.00161,0.00026
14,1.167,7983.66,0.00162,0.00026
14.1,1.175,8122.59,0.00163,0.00027
14.2,1.183,8214.7,0.00165,0.00027
14.3,1.192,8303.89,0.00166,0.00027
14.4,1.2,8308.97,0.00167,0.00027
14.5,1.209,8336.53,0.00169,0.00028
14.6,1.217,8457.27,0.0017,0.00028
14.7,1.225,8577.81,0.00172,0.00028
14.8,1.233,8716.92,0.00173,0.00029
14.9,1.242,8797.85,0.00174,0.00029
15,1.25,8866.35,0.00176,0.00029
15.1,1.259,8966.42,0.00177,0.0003
15.2,1.267,9027.25,0.00179,0.0003
15.3,1.275,9097.56,0.0018,0.0003
15.4,1.283,9168.14,0.00182,0.00031
15.5,1.292,9297.55,0.00183,0.00031
15.6,1.3,9346.73,0.00185,0.00031
15.7,1.308,9443.01,0.00186,0.00032
15.8,1.317,9572.01,0.00187,0.00032
15.9,1.325,9708.2,0.00189,0.00032
16,1.333,9801.83,0.0019,0.00033
16.1,1.342,9813.79,0.00192,0.00033
16.2,1.35,9825.96,0.00193,0.00033
16.3,1.359,9965.16,0.00194,0.00034
16.4,1.367,10078.99,0.00196,0.00034
16.5,1.375,10196.91,0.00198,0.00034
16.6,1.384,10329.21,0.002,0.00035
16.7,1.392,10409.27,0.00201,0.00035
16.8,1.4,10431.66,0.00202,0.00035
16.9,1.409,10520.62,0.00204,0.00036
17,1.417,10592.32,0.00205,0.00036
17.1,1.425,10712.17,0.00207,0.00036
17.2,1.434,10842.63,0.00209,0.00037
17.3,1.442,10905.87,0.0021,0.00037
17.4,1.45,10992.1,0.00212,0.00037
17.5,1.459,11125.14,0.00213,0.00038
17.6,1.467,11216.44,0.00214,0.00038
17.7,1.475,11283.07,0.00216,0.00039
17.8,1.483,11324.37,0.00218,0.00039
17.9,1.492,11401.57,0.00219,0.00039
18,1.5,11525.9,0.00221,0.0004
18.1,1.508,11641.85,0.00222,0.0004
18.2,1.517,11792.08,0.00224,0.0004
18.3,1.525,11894.23,0.00225,0.00041
18.4,1.533,11929.89,0.00227,0.00041
18.5,1.542,11968.77,0.00229,0.00041
18.6,1.55,12073.33,0.0023,0.00042
18.7,1.558,12183.39,0.00232,0.00042
18.8,1.567,12334.55,0.00234,0.00043
18.9,1.575,12413.33,0.00235,0.00043
19,1.584,12480.23,0.00237,0.00043
19.1,1.592,12595.85,0.00239,0.00044
19.2,1.6,12682.43,0.0024,0.00044
19.3,1.609,12763.33,0.00241,0.00045
19.4,1.617,12878.02,0.00243,0.00045
19.5,1.625,12931.38,0.00245,0.00045
19.6,1.634,13034.91,0.00247,0.00046
19.7,1.642,13173.86,0.00248,0.00046
19.8,1.65,13284.16,0.0025,0.00047
19.9,1.659,13387.78,0.00252,0.00047
20,1.667,13447.12,0.00253,0.00047
20.1,1.675,13491.5,0.00255,0.00048
20.2,1.683,13598.25,0.00257,0.00048
20.3,1.692,13708.92,0.00258,0.00049
20.4,1.7,13851.68,0.0026,0.00049
20.5,1.709,13965.8,0.00262,0.0005
20.6,1.717,13992.38,0.00263,0.0005
20.7,1.725,14097.51,0.00265,0.0005
20.8,1.733,14188.83,0.00267,0.00051
20.9,1.742,14309.87,0.00268,0.00051
21,1.75,14415.23,0.0027,0.00052
21.1,1.759,14484.38,0.00272,0.00052
21.2,1.767,14575.62,0.00274,0.00053
21.3,1.775,14703.77,0.00275,0.00053
21.4,1.784,14790.64,0.00277,0.00054
21.5,1.792,14937.8,0.00279,0.00054
21.6,1.8,14996.67,0.00281,0.00054
21.7,1.809,15042.38,0.00283,0.00055
21.8,1.817,15147.24,0.00284,0.00055
21.9,1.825,15287.44,0.00286,0.00056
22,1.833,15405.44,0.00288,0.00056
22.1,1.842,15489.26,0.0029,0.00057
22.2,1.85,15522.71,0.00292,0.00057
22.3,1.858,15664.75,0.00294,0.00058
22.4,1.867,15764.53,0.00295,0.00058
22.5,1.875,15858.29,0.00297,0.00059
22.6,1.884,15991.48,0.00299,0.00059
22.7,1.892,16054.55,0.00301,0.0006
22.8,1.9,16111.89,0.00303,0.0006
22.9,1.908,16222.07,0.00305,0.00061
23,1.917,16358.93,0.00307,0.00061
23.1,1.925,16496.02,0.00309,0.00062
23.2,1.934,16551.63,0.00311,0.00062
23.3,1.942,16580.78,0.00313,0.00063
23.4,1.95,16724.62,0.00315,0.00063
23.5,1.958,16837.44,0.00317,0.00064
23.6,1.967,16942.58,0.00319,0.00064
23.7,1.975,17012.06,0.00322,0.00065
23.8,1.984,17109.85,0.00324,0.00066
23.9,1.992,17231.94,0.00326,0.00066
24,2,17326.4,0.00328,0.00067
24.1,2.008,17437.37,0.0033,0.00067
24.2,2.017,17543.86,0.00333,0.00068
24.3,2.025,17571.81,0.00334,0.00069
24.4,2.034,17659.69,0.00337,0.00069
24.5,2.042,17788.61,0.00339,0.0007
24.6,2.05,17918.86,0.00341,0.0007
24.7,2.059,18055.72,0.00344,0.00071
24.8,2.067,18088.25,0.00346,0.00072
24.9,2.075,18140.38,0.00349,0.00072
25,2.083,18247.54,0.00351,0.00073
25.1,2.092,18354.74,0.00353,0.00074
25.2,2.1,18476.38,0.00356,0.00074
25.3,2.108,18588.85,0.00358,0.00075
25.4,2.117,18654.09,0.00361,0.00076
25.5,2.125,18762.33,0.00363,0.00076
25.6,2.133,18863.98,0.00366,0.00077
25.7,2.142,18926.41,0.00368,0.00078
25.8,2.15,19055.12,0.00371,0.00079
25.9,2.159,19108.63,0.00374,0.00079
26,2.167,19189.7,0.00376,0.0008
26.1,2.175,19314.49,0.00379,0.00081
26.2,2.183,19462.32,0.00382,0.00082
26.3,2.192,19550.27,0.00385,0.00083
26.4,2.2,19625.71,0.00387,0.00083
26.5,2.209,19627.65,0.00391,0.00084
26.6,2.217,19697.04,0.00393,0.00085
26.7,2.225,19831.47,0.00396,0.00086
26.8,2.233,19967.38,0.00399,0.00087
26.9,2.242,20092.19,0.00403,0.00088
27,2.25,20178.1,0.00406,0.00089
27.1,2.258,20246.7,0.00409,0.0009
27.2,2.267,20320.55,0.00412,0.00091
27.3,2.275,20376.54,0.00415,0.00092
27.4,2.284,20481.44,0.00419,0.00093
27.5,2.292,20594.66,0.00422,0.00094
27.6,2.3,20646.27,0.00426,0.00095
27.7,2.309,20713.81,0.0043,0.00096
27.8,2.317,20833.82,0.00433,0.00097
27.9,2.325,20938.26,0.00437,0.00098
28,2.334,21035.41,0.00441,0.00099
28.1,2.342,21116.45,0.00444,0.001
28.2,2.35,21127.62,0.00448,0.00102
28.3,2.358,21144.88,0.00452,0.00103
28.4,2.367,21264.15,0.00456,0.00104
28.5,2.375,21379.41,0.0046,0.00105
28.6,2.384,21482.11,0.00464,0.00107
28.7,2.392,21565.74,0.00469,0.00108
28.8,2.4,21706.74,0.00474,0.0011
28.9,2.409,21745.93,0.00478,0.00111
29,2.417,21750.64,0.00483,0.00112
29.1,2.425,21787.15,0.00487,0.00114
29.2,2.433,21860.36,0.00492,0.00115
29.3,2.442,21932.84,0.00497,0.00117
29.4,2.45,22018.94,0.00502,0.00119
29.5,2.459,22117.69,0.00507,0.0012
29.6,2.467,22177.93,0.00512,0.00122
29.7,2.475,22223.62,0.00518,0.00124
29.8,2.484,22260.47,0.00523,0.00126
29.9,2.492,22321.28,0.00529,0.00128
30,2.5,22416.76,0.00535,0.0013
30.1,2.509,22468.01,0.0054,0.00132
30.2,2.517,22525.18,0.00547,0.00134
30.3,2.525,22546.24,0.00552,0.00136
30.4,2.534,22588.27,0.00558,0.00138
30.5,2.542,22626.4,0.00565,0.00141
30.6,2.55,22650.09,0.00571,0.00143
30.7,2.559,22678.46,0.00578,0.00145
30.8,2.567,22724.43,0.00585,0.00148
30.9,2.575,22762.05,0.00591,0.0015
31,2.584,22818.64,0.00598,0.00153
31.1,2.592,22889.1,0.00605,0.00157
31.2,2.6,22932.27,0.00613,0.00161
31.3,2.608,22985.69,0.00619,0.00165
31.4,2.617,23045.1,0.00627,0.00169
31.5,2.625,23091.48,0.00635,0.00173
31.6,2.633,23131.05,0.00643,0.00176
31.7,2.642,23198.82,0.00651,0.00178
31.8,2.65,23234.06,0.00658,0.00182
31.9,2.658,23243.91,0.00666,0.00185
32,2.667,23249.88,0.00675,0.00192
32.1,2.675,23250.94,0.00683,0.00199
32.2,2.683,23251.22,0.00691,0.00203
32.3,2.692,23254.36,0.007,0.00208
32.4,2.7,23261.33,0.00708,0.00216
32.5,2.708,23280.95,0.00717,0.00236
32.6,2.717,23303.83,0.00726,0.00242
32.7,2.725,23351.42,0.00735,0.00248
32.8,2.734,23376.96,0.00744,0.00254
32.9,2.742,23390.2,0.00753,0.00262
33,2.75,23412.95,0.00762,0.00288
33.1,2.759,23445.24,0.00771,0.00297
33.2,2.767,23470.19,0.00781,0.00303
33.3,2.775,23514.32,0.0079,0.00308
33.4,2.784,23542.67,0.00799,0.00312
33.5,2.792,23568.69,0.00809,0.00318
33.6,2.8,23584.48,0.00818,0.00327
33.7,2.808,23614.2,0.00829,0.00336
33.8,2.817,23646.13,0.00838,0.00344
33.9,2.825,23668.95,0.00848,0.00354
34,2.834,23698.37,0.00858,0.0036
34.1,2.842,23705.11,0.00868,0.00365
34.2,2.85,23720.5,0.00878,0.0037
34.3,2.858,23734.92,0.00888,0.00375
34.4,2.867,23750.15,0.00898,0.00379
34.5,2.875,23757.54,0.00909,0.00384
34.6,2.884,23770.43,0.00919,0.00389
34.7,2.892,23778.84,0.0093,0.00393
34.8,2.9,23792.19,0.0094,0.00398
34.9,2.909,23802.23,0.00951,0.00403
35,2.917,23810.84,0.00961,0.00408
35.1,2.925,23816.37,0.00972,0.00413
35.2,2.934,23821.69,0.00983,0.00418
35.3,2.942,23827.43,0.00993,0.00423
35.4,2.95,23834.57,0.01004,0.00429
35.5,2.959,23845.2,0.01015,0.00435
35.6,2.967,23853.03,0.01026,0.00441
35.7,2.975,23884.63,0.01037,0.00446
35.8,2.983,23892.14,0.01048,0.00452
35.9,2.992,23912.13,0.0106,0.00458
36,3,23926.85,0.01071,0.00463
36.1,3.009,23941.45,0.01082,0.00469
36.2,3.017,23949.35,0.01093,0.00476
36.3,3.025,23956.43,0.01105,0.00481
36.4,3.034,23967.26,0.01116,0.00487
36.5,3.042,23971.02,0.01128,0.00492
36.6,3.05,23974.7,0.01139,0.00497
36.7,3.059,23982.75,0.01151,0.00503
36.8,3.067,23990.47,0.01162,0.00508
36.9,3.075,23998.05,0.01174,0.0052
37,3.084,24003.15,0.01186,0.00526
37.1,3.092,24011.54,0.01197,0.00531
37.2,3.1,24019.01,0.01209,0.00537
37.3,3.109,24027.76,0.01221,0.00542
37.4,3.117,24030.39,0.01233,0.00548
37.5,3.125,24037.73,0.01244,0.00553
37.6,3.134,24042.32,0.01256,0.00559
37.7,3.142,24050.52,0.01269,0.00564
37.8,3.15,24056.08,0.01281,0.0057
37.9,3.158,24064.25,0.01292,0.00576
38,3.167,24077.48,0.01305,0.00582
38.1,3.175,24088.18,0.01316,0.00587
38.2,3.183,24107.83,0.01329,0.00593
38.3,3.192,24118.76,0.01341,0.00598
38.4,3.2,24131.58,0.01353,0.00603
38.5,3.208,24145.13,0.01365,0.00609
38.6,3.217,24157.04,0.01377,0.00614
38.7,3.225,24169.93,0.01389,0.0062
38.8,3.233,24176.76,0.01401,0.00626
38.9,3.242,24187.1,0.01414,0.00631
39,3.25,24192.07,0.01426,0.00636
39.1,3.258,24196.25,0.01438,0.00642
39.2,3.267,24199.34,0.01451,0.00648
39.3,3.275,24204.56,0.01463,0.00653
39.4,3.284,24206.89,0.01475,0.00658
39.5,3.292,24210.55,0.01488,0.00662
39.6,3.3,24212.56,0.015,0.00667
39.7,3.308,24216.46,0.01512,0.00671
39.8,3.317,24218.86,0.01524,0.00676
39.9,3.325,24224.08,0.01537,0.00681
40,3.334,24227.1,0.01549,0.00686
40.1,3.342,24230.88,0.01562,0.00691
40.2,3.35,24235.96,0.01574,0.00696
40.3,3.359,24241.58,0.01587,0.00702
40.4,3.367,24246.03,0.01599,0.00707
40.5,3.375,24247.5,0.01611,0.00712
40.6,3.384,24255.01,0.01624,0.00718
40.7,3.392,24262.17,0.01636,0.00723
40.8,3.4,24268,0.01649,0.00728
40.9,3.409,24274.54,0.01661,0.00733
41,3.417,24273.01,0.01674,0.00738
41.1,3.425,24283.86,0.01686,0.00744
41.2,3.433,24284.83,0.01699,0.00749
41.3,3.442,24290.4,0.01711,0.00755
41.4,3.45,24296.41,0.01724,0.0076
41.5,3.459,24295.46,0.01737,0.00765
41.6,3.467,24305.98,0.01749,0.0077
41.7,3.475,24311.87,0.01762,0.00776
41.8,3.484,24310.14,0.01774,0.00781
41.9,3.492,24323.99,0.01786,0.00787
42,3.5,24327.16,0.01799,0.00792
42.1,3.509,24334.23,0.01811,0.00797
42.2,3.517,24348.21,0.01824,0.00802
42.3,3.525,24352.45,0.01836,0.00806
42.4,3.534,24368.55,0.01849,0.00811
42.5,3.542,24376.73,0.01862,0.00817
42.6,3.55,24380.75,0.01874,0.00822
42.7,3.559,24400.29,0.01887,0.00828
42.8,3.567,24408.57,0.01899,0.00833
42.9,3.575,24421.95,0.01911,0.00839
43,3.584,24432.04,0.01924,0.00844
43.1,3.592,24442.37,0.01937,0.0085
43.2,3.6,24442.14,0.01949,0.00855
43.3,3.609,24453.86,0.01961,0.00861
43.4,3.617,24464.14,0.01974,0.00867
43.5,3.625,24467.88,0.01987,0.00872
43.6,3.634,24474.48,0.01999,0.00878
43.7,3.642,24480.3,0.02012,0.00883
43.8,3.65,24485.43,0.02024,0.00889
43.9,3.658,24487.09,0.02036,0.00894
44,3.667,24497.42,0.02049,0.009
44.1,3.675,24501.22,0.02061,0.00905
44.2,3.684,24508.97,0.02074,0.00911
44.3,3.692,24514.01,0.02087,0.00917
44.4,3.7,24512.56,0.02099,0.00922
44.5,3.708,24519.75,0.02112,0.00928
44.6,3.717,24529.48,0.02125,0.00933
44.7,3.725,24532.59,0.02137,0.00938
44.8,3.734,24537.66,0.0215,0.00943
44.9,3.742,24544.92,0.02162,0.00948
45,3.75,24553.59,0.02175,0.00954
45.1,3.758,24558.58,0.02188,0.00959
45.2,3.767,24562.26,0.022,0.00965
45.3,3.775,24569.26,0.02212,0.0097
45.4,3.783,24573.08,0.02224,0.00975
45.5,3.792,24578.19,0.02237,0.00981
45.6,3.8,24585.36,0.0225,0.00986
45.7,3.808,24587.79,0.02262,0.00992
45.8,3.817,24590.93,0.02275,0.00997
45.9,3.825,24595.89,0.02287,0.01003
46,3.833,24601.79,0.023,0.01008
46.1,3.842,24606.03,0.02312,0.01014
46.2,3.85,24612.01,0.02325,0.0102
46.3,3.859,24617.14,0.02337,0.01026
46.4,3.867,24618.51,0.0235,0.01031
46.5,3.875,24627.88,0.02362,0.01037
46.6,3.883,24634.3,0.02375,0.01043
46.7,3.892,24635.24,0.02387,0.01049
46.8,3.9,24645.9,0.024,0.01056
46.9,3.909,24647.81,0.02412,0.01062
47,3.917,24660.46,0.02425,0.01068
47.1,3.925,24662.91,0.02437,0.01074
47.2,3.933,24669.74,0.0245,0.0108
47.3,3.942,24672.85,0.02462,0.01085
47.4,3.95,24688.15,0.02475,0.01091
47.5,3.959,24691.04,0.02488,0.01097
47.6,3.967,24697.2,0.025,0.01102
47.7,3.975,24690.19,0.02512,0.01108
47.8,3.984,24712.95,0.02524,0.01114
47.9,3.992,24708.76,0.02537,0.0112
48,4,24711.31,0.02549,0.01126
48.1,4.009,24724.82,0.02562,0.01132
48.2,4.017,24729.49,0.02574,0.01138
48.3,4.025,24736.65,0.02587,0.01144
48.4,4.034,24737.54,0.02599,0.0115
48.5,4.042,24738.23,0.02612,0.01157
48.6,4.05,24742.3,0.02624,0.01162
48.7,4.058,24744.43,0.02637,0.01168
48.8,4.067,24745.96,0.02649,0.01175
48.9,4.075,24751.83,0.02661,0.01182
49,4.084,24748.09,0.02673,0.01189
49.1,4.092,24749.97,0.02686,0.01195
49.2,4.1,24755.98,0.02699,0.01201
49.3,4.108,24752.61,0.02711,0.01208
49.4,4.117,24756.7,0.02723,0.01214
49.5,4.125,24760.55,0.02736,0.0122
49.6,4.134,24767.45,0.02748,0.01226
49.7,4.142,24764.78,0.02761,0.01231
49.8,4.15,24768.12,0.02774,0.01236
49.9,4.158,24772.21,0.02785,0.01241
50,4.167,24770.9,0.02798,0.01247
50.1,4.175,24777.9,0.02811,0.01253
50.2,4.184,24777.21,0.02822,0.0126
50.3,4.192,24780.1,0.02835,0.01267
50.4,4.2,24782.19,0.02847,0.01275
50.5,4.209,24787.01,0.02859,0.01283
50.6,4.217,24788.57,0.02872,0.01291
50.7,4.225,24789.32,0.02885,0.013
50.8,4.234,24793.49,0.02897,0.0131
50.9,4.242,24791.07,0.0291,0.0132
51,4.25,24792.13,0.02922,0.01334
51.1,4.259,24793.72,0.02934,0.01345
51.2,4.267,24794.04,0.02946,0.01354
51.3,4.275,24796.31,0.02958,0.0136
51.4,4.284,24797.53,0.02971,0.01367
51.5,4.292,24796.29,0.02983,0.01373
51.6,4.3,24798.91,0.02995,0.0138
51.7,4.308,24801.72,0.03008,0.01386
51.8,4.317,24801.4,0.0302,0.01392
51.9,4.325,24802.04,0.03033,0.014
52,4.333,24802.54,0.03045,0.01409
52.1,4.342,24803.48,0.03057,0.01458
52.2,4.35,24806,0.0307,0.01462
52.3,4.358,24806.98,0.03082,0.01469
52.4,4.367,24808.5,0.03095,0.01474
52.5,4.375,24809.24,0.03107,0.01481
52.6,4.384,24817.39,0.03119,0.01487
52.7,4.392,24817.47,0.03131,0.01494
52.8,4.4,24819.97,0.03144,0.015
52.9,4.409,24826.31,0.03156,0.01505
53,4.417,24829.74,0.03168,0.01511
53.1,4.425,24836.5,0.03181,0.01517
53.2,4.434,24841.72,0.03193,0.01523
53.3,4.442,24849.54,0.03205,0.01528
53.4,4.45,24849.29,0.03217,0.01529
53.5,4.459,24860.2,0.0323,0.01535
53.6,4.467,24869.81,0.03242,0.01541
53.7,4.475,24876.71,0.03254,0.01548
53.8,4.483,24895.32,0.03266,0.01554
53.9,4.492,24899.18,0.03279,0.01561
54,4.5,24901.57,0.03291,0.01567
54.1,4.508,24905.48,0.03303,0.01573
54.2,4.517,24911.07,0.03315,0.01579
54.3,4.525,24922.16,0.03328,0.01585
54.4,4.533,24929.09,0.0334,0.01592
54.5,4.542,24937.44,0.03352,0.01599
54.6,4.55,24937.89,0.03364,0.01605
54.7,4.558,24940.81,0.03377,0.01612
54.8,4.567,24953.78,0.03389,0.01618
54.9,4.575,24960.14,0.03401,0.01624
55,4.584,24963.87,0.03414,0.01629
55.1,4.592,24971.66,0.03426,0.01635
55.2,4.6,24971.92,0.03438,0.01641
55.3,4.609,24978.77,0.03451,0.01647
55.4,4.617,24981.51,0.03463,0.01652
55.5,4.625,24989.71,0.03475,0.01658
55.6,4.634,24991.77,0.03487,0.01663
55.7,4.642,25001.71,0.035,0.01669
55.8,4.65,25004.25,0.03512,0.01674
55.9,4.659,25012.16,0.03524,0.01679
56,4.667,25018.49,0.03537,0.01685
56.1,4.675,25025.02,0.03548,0.0169
56.2,4.684,25026.26,0.03561,0.01695
56.3,4.692,25032.54,0.03573,0.01701
56.4,4.7,25044.55,0.03585,0.01706
56.5,4.709,25046.79,0.03597,0.01712
56.6,4.717,25052.66,0.03609,0.01718
56.7,4.725,25052.22,0.03622,0.01723
56.8,4.733,25057.46,0.03634,0.01729
56.9,4.742,25067.96,0.03646,0.01735
57,4.75,25070.62,0.03658,0.01741
57.1,4.759,25077.38,0.03671,0.01747
57.2,4.767,25079.16,0.03683,0.01752
57.3,4.775,25087.04,0.03695,0.01758
57.4,4.784,25089.09,0.03708,0.01763
57.5,4.792,25091.3,0.0372,0.01769
57.6,4.8,25093.31,0.03732,0.01775
57.7,4.809,25097.38,0.03744,0.01781
57.8,4.817,25102.33,0.03757,0.01787
57.9,4.825,25100.57,0.03769,0.01793
58,4.834,25108.07,0.03781,0.01799
58.1,4.842,25113.25,0.03794,0.01804
58.2,4.85,25114.64,0.03806,0.01809
58.3,4.858,25116.24,0.03818,0.01814
58.4,4.867,25123.43,0.0383,0.01819
58.5,4.875,25128.82,0.03842,0.01824
58.6,4.883,25135.16,0.03854,0.01829
58.7,4.892,25136.22,0.03867,0.01835
58.8,4.9,25140.95,0.03879,0.01841
58.9,4.908,25152.76,0.03891,0.01847
59,4.917,25159.22,0.03903,0.01854
59.1,4.925,25168.66,0.03916,0.01861
59.2,4.934,25175.65,0.03928,0.01868
59.3,4.942,25183.15,0.0394,0.01875
59.4,4.95,25190.14,0.03953,0.01883
59.5,4.958,25195.26,0.03964,0.01892
59.6,4.967,25204.32,0.03977,0.01904
59.7,4.975,25204.31,0.03989,0.01917
59.8,4.984,25214.5,0.04002,0.01933
59.9,4.992,25216.95,0.04014,0.01952
60,5,25221.65,0.04026,0.01951
60.1,5.008,25225.25,0.04038,0.01955
60.2,5.017,25240.63,0.04051,0.0196
60.3,5.025,25243.83,0.04063,0.01964
60.4,5.034,25246.39,0.04076,0.01969
60.5,5.042,25251.09,0.04088,0.01974
60.6,5.05,25248.67,0.041,0.0198
60.7,5.058,25257.05,0.04112,0.01986
60.8,5.067,25262.9,0.04125,0.01991
60.9,5.075,25269.22,0.04137,0.01997
61,5.083,25264.47,0.04149,0.02002
61.1,5.092,25273.01,0.04161,0.02008
61.2,5.1,25277.87,0.04173,0.02014
61.3,5.108,25281.24,0.04186,0.02019
61.4,5.117,25282.29,0.04198,0.02025
61.5,5.125,25287.07,0.0421,0.02029
61.6,5.133,25282.34,0.04223,0.02035
61.7,5.142,25287.99,0.04235,0.0204
61.8,5.15,25290.46,0.04248,0.02047
61.9,5.159,25291.55,0.0426,0.02053
62,5.167,25291.74,0.04272,0.02058
62.1,5.175,25294.97,0.04284,0.02066
62.2,5.184,25294.8,0.04297,0.02072
62.3,5.192,25296.88,0.04309,0.02076
62.4,5.2,25298.89,0.04322,0.0208
62.5,5.209,25300.37,0.04334,0.02085
62.6,5.217,25301.94,0.04346,0.02089
62.7,5.225,25300.99,0.04359,0.02094
62.8,5.233,25300.56,0.04371,0.02099
62.9,5.242,25302.71,0.04384,0.02103
63,5.25,25304.21,0.04396,0.02108
63.1,5.259,25303.12,0.04408,0.02112
63.2,5.267,25304.06,0.04421,0.02116
63.3,5.275,25306.46,0.04433,0.02121
63.4,5.283,25306.01,0.04445,0.02126
63.5,5.292,25306.88,0.04457,0.02131
63.6,5.3,25308,0.0447,0.02135
63.7,5.308,25309.11,0.04482,0.02141
63.8,5.317,25308.5,0.04494,0.02146
63.9,5.325,25310.84,0.04506,0.02152
64,5.334,25312.39,0.04519,0.02157
64.1,5.342,25312.13,0.04532,0.02162
64.2,5.35,25311.56,0.04544,0.02166
64.3,5.358,25313.71,0.04556,0.02171
64.4,5.367,25314.81,0.04569,0.02176
64.5,5.375,25315.85,0.04581,0.02181
64.6,5.384,25315.71,0.04593,0.02186
64.7,5.392,25317.24,0.04606,0.02191
64.8,5.4,25318.48,0.04618,0.02197
64.9,5.408,25317.58,0.04631,0.02202
65,5.417,25319.62,0.04643,0.02206
65.1,5.425,25321.42,0.04656,0.02211
65.2,5.434,25319.51,0.04668,0.02216
65.3,5.442,25320.69,0.0468,0.0222
65.4,5.45,25323.06,0.04692,0.02225
65.5,5.458,25325.38,0.04705,0.0223
65.6,5.467,25326.34,0.04717,0.02235
65.7,5.475,25328.54,0.04729,0.0224
65.8,5.483,25328.07,0.04742,0.02244
65.9,5.492,25331.22,0.04754,0.02249
66,5.5,25333.65,0.04766,0.02254
66.1,5.509,25336.27,0.04779,0.02259
66.2,5.517,25336.26,0.04791,0.02264
66.3,5.525,25337.14,0.04804,0.02269
66.4,5.534,25340.06,0.04816,0.02274
66.5,5.542,25338.29,0.04829,0.02279
66.6,5.55,25346.14,0.04841,0.02283
66.7,5.559,25350.31,0.04853,0.02288
66.8,5.567,25349.53,0.04866,0.02286
66.9,5.575,25356.26,0.04879,0.0229
67,5.584,25359.85,0.04891,0.02289
67.1,5.592,25356.46,0.04904,0.02289
67.2,5.6,25364.3,0.04917,0.02289
67.3,5.609,25366.12,0.04929,0.02291
67.4,5.617,25375.61,0.04941,0.02296
67.5,5.625,25376.55,0.04953,0.02299
67.6,5.633,25376.09,0.04966,0.02299
67.7,5.642,25389,0.04979,0.02304
67.8,5.65,25394.59,0.04991,0.02309
67.9,5.659,25388.49,0.05004,0.02314
68,5.667,25396.04,0.05017,0.02312
68.1,5.675,25401.28,0.05029,0.02317
68.2,5.683,25399.42,0.05042,0.02323
68.3,5.692,25407.4,0.05054,0.02329
68.4,5.7,25407.55,0.05066,0.02335
68.5,5.709,25412.44,0.05079,0.0234
68.6,5.717,25419.33,0.05091,0.02345
68.7,5.725,25419.27,0.05104,0.02348
68.8,5.734,25428.08,0.05117,0.02354
68.9,5.742,25426.19,0.05129,0.02359
69,5.75,25430.25,0.05142,0.02363
69.1,5.759,25435.17,0.05155,0.02367
69.2,5.767,25436.23,0.05167,0.02371
69.3,5.775,25439.11,0.0518,0.02376
69.4,5.784,25443.18,0.05193,0.02381
69.5,5.792,25442.72,0.05205,0.02386
69.6,5.8,25444.59,0.05218,0.02392
69.7,5.808,25448.02,0.0523,0.02397
69.8,5.817,25452.06,0.05243,0.02401
69.9,5.825,25453.01,0.05255,0.02406
70,5.834,25455.71,0.05268,0.0241
70.1,5.842,25458.32,0.05281,0.02414
70.2,5.85,25460.41,0.05294,0.02418
70.3,5.859,25460.4,0.05307,0.02422
70.4,5.867,25467.48,0.0532,0.02428
70.5,5.875,25463.54,0.05332,0.02433
70.6,5.884,25465.19,0.05345,0.02434
70.7,5.892,25469.12,0.05357,0.02338
70.8,5.9,25471.83,0.05369,0.02346
70.9,5.908,25478.11,0.05382,0.02353
71,5.917,25476.46,0.05395,0.0236
71.1,5.925,25473.68,0.05408,0.02368
71.2,5.934,25478.51,0.05421,0.02376
71.3,5.942,25485.25,0.05434,0.02384
71.4,5.95,25483.69,0.05446,0.02388
71.5,5.959,25484.41,0.05459,0.02379
71.6,5.967,25492.93,0.05471,0.0237
71.7,5.975,25496.12,0.05484,0.02372
71.8,5.983,25492.03,0.05497,0.02374
71.9,5.992,25494.89,0.05509,0.0238
72,6,25498.06,0.05522,0.02385
72.1,6.008,25511.52,0.05535,0.02391
72.2,6.017,25510.3,0.05548,0.02388
72.3,6.025,25511.16,0.0556,0.02363
72.4,6.033,25514.66,0.05573,0.02368
72.5,6.042,25512.09,0.05586,0.02373
72.6,6.05,25522.8,0.05599,0.02377
72.7,6.059,25521.91,0.05612,0.02382
72.8,6.067,25530.67,0.05624,0.02387
72.9,6.075,25531.39,0.05637,0.02391
73,6.083,25539.96,0.0565,0.02392
73.1,6.092,25540.72,0.05662,0.02229
73.2,6.1,25542.6,0.05675,0.02179
73.3,6.109,25549.66,0.05688,0.02184
73.4,6.117,25544.75,0.05701,0.02189
73.5,6.125,25552.53,0.05714,0.02195
73.6,6.134,25557.68,0.05727,0.022
73.7,6.142,25563.52,0.0574,0.02205
73.8,6.15,25560.17,0.05753,0.02211
73.9,6.159,25568.52,0.05765,0.02216
74,6.167,25570.87,0.05777,0.02221
74.1,6.175,25571.29,0.05791,0.02226
74.2,6.183,25572.08,0.05804,0.02231
74.3,6.192,25579.79,0.05817,0.02236
74.4,6.2,25576.33,0.05829,0.02241
74.5,6.208,25582.08,0.05842,0.02247
74.6,6.217,25586.69,0.05855,0.02252
74.7,6.225,25594.3,0.05868,0.02258
74.8,6.234,25590.92,0.05881,0.02263
74.9,6.242,25593.34,0.05893,0.02269
75,6.25,25595.97,0.05906,0.02274
75.1,6.258,25596.87,0.0592,0.0228
75.2,6.267,25600.14,0.05933,0.02285
75.3,6.275,25606.36,0.05946,0.02291
75.4,6.284,25606.79,0.05959,0.02297
75.5,6.292,25606.67,0.05972,0.02303
75.6,6.3,25608.25,0.05985,0.02309
75.7,6.309,25603.85,0.05997,0.02313
75.8,6.317,25615.34,0.06011,0.0231
75.9,6.325,25613.27,0.06024,0.02313
76,6.334,25610.66,0.06037,0.02317
76.1,6.342,25615.18,0.0605,0.02322
76.2,6.35,25614.16,0.06063,0.02327
76.3,6.358,25614.52,0.06075,0.02332
76.4,6.367,25619.53,0.06088,0.02337
76.5,6.375,25621.04,0.06102,0.02342
76.6,6.384,25626.56,0.06115,0.02346
76.7,6.392,25621.81,0.06128,0.0235
76.8,6.4,25624.42,0.06141,0.02356
76.9,6.409,25622.52,0.06154,0.02361
77,6.417,25624.71,0.06167,0.02365
77.1,6.425,25623.61,0.0618,0.02362
77.2,6.433,25625.63,0.06193,0.02366
77.3,6.442,25629.12,0.06206,0.02369
77.4,6.45,25629.68,0.06219,0.02373
77.5,6.459,25631.18,0.06232,0.02378
77.6,6.467,25632.15,0.06245,0.02383
77.7,6.475,25634.09,0.06259,0.02389
77.8,6.483,25634.99,0.06272,0.02394
77.9,6.492,25634.75,0.06284,0.02398
78,6.5,25635.94,0.06298,0.02322
78.1,6.509,25641.94,0.06311,0.02138
78.2,6.517,25644.1,0.06324,0.02145
78.3,6.525,25643,0.06337,0.0215
78.4,6.534,25644.37,0.0635,0.02154
78.5,6.542,25648.25,0.06363,0.02159
78.6,6.55,25647.78,0.06377,0.02164
78.7,6.559,25650.5,0.0639,0.02169
78.8,6.567,25648.05,0.06403,0.02174
78.9,6.575,25648.02,0.06416,0.02179
79,6.583,25655.53,0.06429,0.02184
79.1,6.592,25654.81,0.06442,0.02189
79.2,6.6,25658.28,0.06456,0.02195
79.3,6.608,25662.8,0.06468,0.022
79.4,6.617,25660.53,0.06481,0.02206
79.5,6.625,25663.4,0.06495,0.02212
79.6,6.634,25666.3,0.06508,0.02218
79.7,6.642,25665.03,0.06522,0.02224
79.8,6.65,25663.74,0.06535,0.02229
79.9,6.659,25670.18,0.06548,0.02235
80,6.667,25670.56,0.06561,0.0224
80.1,6.675,25673.71,0.06574,0.02246
80.2,6.684,25672.34,0.06587,0.02252
80.3,6.692,25675.92,0.06601,0.02257
80.4,6.7,25684.88,0.06614,0.02263
80.5,6.708,25684.67,0.06627,0.02268
80.6,6.717,25697.21,0.06641,0.02274
80.7,6.725,25686.4,0.06654,0.02278
80.8,6.734,25691.79,0.06667,0.02136
80.9,6.742,25690.42,0.06681,0.02135
81,6.75,25694.51,0.06694,0.02135
81.1,6.759,25697.36,0.06707,0.02139
81.2,6.767,25694.86,0.06721,0.02143
81.3,6.775,25700.67,0.06735,0.02147
81.4,6.784,25693.87,0.06748,0.02151
81.5,6.792,25707.88,0.06761,0.02155
81.6,6.8,25699.49,0.06774,0.02157
81.7,6.808,25706.74,0.06788,0.02159
81.8,6.817,25704.96,0.06802,0.02162
81.9,6.825,25700.37,0.06815,0.02167
82,6.834,25701.02,0.06829,0.02171
82.1,6.842,25702.78,0.06842,0.02176
82.2,6.85,25720.46,0.06856,0.02181
82.3,6.859,25706.56,0.06869,0.02185
82.4,6.867,25716.99,0.06882,0.0219
82.5,6.875,25722.01,0.06896,0.02195
82.6,6.884,25722.82,0.06909,0.02201
82.7,6.892,25723.28,0.06923,0.022
82.8,6.9,25723.39,0.06937,0.0208
82.9,6.909,25724.8,0.0695,0.0206
83,6.917,25728.23,0.06964,0.02064
83.1,6.925,25726.75,0.06977,0.02069
83.2,6.933,25732.89,0.06991,0.02075
83.3,6.942,25729.75,0.07005,0.02081
83.4,6.95,25726.23,0.07018,0.02086
83.5,6.959,25727.94,0.07032,0.02091
83.6,6.967,25742.53,0.07045,0.02096
83.7,6.975,25736.87,0.07059,0.02101
83.8,6.983,25733.84,0.07073,0.02106
83.9,6.992,25737.18,0.07086,0.02111
84,7,25741.06,0.071,0.02116
84.1,7.008,25739.22,0.07114,0.02121
84.2,7.017,25742.75,0.07127,0.02126
84.3,7.025,25742.19,0.07141,0.02131
84.4,7.033,25743.96,0.07155,0.02136
84.5,7.042,25744.44,0.07168,0.02141
84.6,7.05,25744.43,0.07182,0.02146
84.7,7.058,25748.1,0.07195,0.02151
84.8,7.067,25746.77,0.07209,0.02157
84.9,7.075,25749.15,0.07223,0.02162
85,7.084,25750.44,0.07237,0.02167
85.1,7.092,25751.46,0.07251,0.02172
85.2,7.1,25749.59,0.07264,0.02176
85.3,7.108,25749.99,0.07278,0.02181
85.4,7.117,25753.59,0.07292,0.02186
85.5,7.125,25753.43,0.07305,0.0219
85.6,7.134,25751.75,0.07319,0.02195
85.7,7.142,25753.5,0.07333,0.022
85.8,7.15,25748.69,0.07347,0.02205
85.9,7.158,25749.45,0.07361,0.0221
86,7.167,25755.92,0.07375,0.02214
86.1,7.175,25760.62,0.07389,0.02219
86.2,7.184,25757.02,0.07403,0.02224
86.3,7.192,25754.75,0.07417,0.02228
86.4,7.2,25757.46,0.07431,0.02232
86.5,7.209,25755.45,0.07444,0.02236
86.6,7.217,25758.38,0.07458,0.02241
86.7,7.225,25757.13,0.07472,0.02244
86.8,7.234,25761.59,0.07486,0.02248
86.9,7.242,25755.52,0.075,0.02251
87,7.25,25759.92,0.07513,0.02255
87.1,7.259,25762.85,0.07527,0.02259
87.2,7.267,25760.38,0.07542,0.02263
87.3,7.275,25768.09,0.07556,0.02266
87.4,7.284,25761.12,0.0757,0.0227
87.5,7.292,25761.13,0.07584,0.02273
87.6,7.3,25764.91,0.07598,0.02277
87.7,7.309,25768.48,0.07612,0.02281
87.8,7.317,25764.45,0.07626,0.02284
87.9,7.325,25764.54,0.0764,0.02288
88,7.333,25769.29,0.07654,0.02292
88.1,7.342,25766.36,0.07669,0.02297
88.2,7.35,25767.17,0.07683,0.02301
88.3,7.359,25766.51,0.07697,0.02305
88.4,7.367,25770.55,0.07711,0.02309
88.5,7.375,25768.87,0.07726,0.02312
88.6,7.383,25766.56,0.0774,0.02316
88.7,7.392,25770.95,0.07754,0.0232
88.8,7.4,25768.22,0.07769,0.02324
88.9,7.409,25770.7,0.07783,0.02329
89,7.417,25770.81,0.07797,0.02333
89.1,7.425,25771.09,0.07811,0.02338
89.2,7.434,25773.56,0.07825,0.02343
89.3,7.442,25773.79,0.0784,0.02347
89.4,7.45,25775.91,0.07854,0.02351
89.5,7.459,25777.36,0.07869,0.02355
89.6,7.467,25772.8,0.07883,0.02358
89.7,7.475,25770.85,0.07897,0.02359
89.8,7.484,25774.89,0.07912,0.02362
89.9,7.492,25773.31,0.07926,0.02364
90,7.5,25774.04,0.07941,0.02364
90.1,7.508,25773.39,0.07955,0.02344
90.2,7.517,25775.88,0.0797,0.02342
90.3,7.525,25775.83,0.07984,0.02345
90.4,7.534,25776.69,0.07999,0.02349
90.5,7.542,25780.89,0.08013,0.02353
90.6,7.55,25778.14,0.08028,0.02357
90.7,7.558,25777.48,0.08043,0.0236
90.8,7.567,25781.93,0.08057,0.02364
90.9,7.575,25780.6,0.08072,0.02367
91,7.584,25781.02,0.08087,0.0237
91.1,7.592,25780.12,0.08101,0.02374
91.2,7.6,25775.43,0.08116,0.02378
91.3,7.608,25782.01,0.0813,0.02382
91.4,7.617,25781.8,0.08146,0.02385
91.5,7.625,25777.29,0.08161,0.02389
91.6,7.634,25781.59,0.08175,0.02392
91.7,7.642,25782.39,0.0819,0.02393
91.8,7.65,25778.46,0.08205,0.02338
91.9,7.659,25775.52,0.0822,0.01966
92,7.667,25777.98,0.08234,0.01978
92.1,7.675,25774.63,0.08249,0.01983
92.2,7.683,25782.56,0.08264,0.01989
92.3,7.692,25777.68,0.08279,0.01995
92.4,7.7,25777.66,0.08293,0.02
92.5,7.709,25784.86,0.08309,0.02004
92.6,7.717,25780.8,0.08324,0.02009
92.7,7.725,25782.19,0.08339,0.02013
92.8,7.734,25781.4,0.08354,0.02018
92.9,7.742,25775.83,0.08369,0.02022
93,7.75,25775.57,0.08384,0.02026
93.1,7.759,25779.82,0.08399,0.02031
93.2,7.767,25777.78,0.08414,0.02035
93.3,7.775,25779.68,0.08429,0.02041
93.4,7.784,25781.45,0.08445,0.02046
93.5,7.792,25777.88,0.0846,0.02051
93.6,7.8,25782.19,0.08475,0.02056
93.7,7.809,25781.14,0.08491,0.02052
93.8,7.817,25777,0.08506,0.0199
93.9,7.825,25777.57,0.08521,0.01994
94,7.834,25777.01,0.08536,0.01997
94.1,7.842,25775.76,0.08552,0.02001
94.2,7.85,25772.33,0.08567,0.02004
94.3,7.859,25778.1,0.08583,0.02007
94.4,7.867,25772.69,0.08598,0.02011
94.5,7.875,25775.45,0.08613,0.02014
94.6,7.883,25778.54,0.08629,0.02018
94.7,7.892,25777.92,0.08645,0.02022
94.8,7.9,25777.61,0.08661,0.02025
94.9,7.909,25771.12,0.08676,0.02029
95,7.917,25773.62,0.08692,0.02033
95.1,7.925,25770.81,0.08707,0.02037
95.2,7.934,25766.91,0.08723,0.02041
95.3,7.942,25773.27,0.08739,0.02045
95.4,7.95,25767.67,0.08755,0.02049
95.5,7.959,25767.34,0.08776,0.02052
95.6,7.967,25769.16,0.08793,0.02056
95.7,7.975,25771.85,0.0881,0.0206
95.8,7.984,25765.32,0.08825,0.02063
95.9,7.992,25768.95,0.08842,0.02067
96,8,25764.42,0.08859,0.02071
96.1,8.009,25768.79,0.08875,0.02075
96.2,8.017,25761.99,0.08892,0.02078
96.3,8.025,25763.32,0.08908,0.02082
96.4,8.034,25762.55,0.08925,0.02085
96.5,8.042,25760.98,0.08941,0.02089
96.6,8.05,25755.63,0.08957,0.02092
96.7,8.058,25762.15,0.08973,0.02096
96.8,8.067,25760.17,0.0899,0.02099
96.9,8.075,25760.36,0.09006,0.02102
97,8.084,25757.97,0.09023,0.02106
97.1,8.092,25757.45,0.0904,0.02109
97.2,8.1,25749.71,0.09056,0.02112
97.3,8.108,25752.53,0.09073,0.02115
97.4,8.117,25753.17,0.09089,0.02118
97.5,8.125,25753,0.09106,0.02121
97.6,8.133,25750.79,0.09122,0.02124
97.7,8.142,25752.71,0.09139,0.02127
97.8,8.15,25741.04,0.09155,0.02131
97.9,8.158,25746.67,0.09172,0.02134
98,8.167,25745.48,0.09189,0.02136
98.1,8.175,25741.98,0.09206,0.02139
98.2,8.183,25738.44,0.09223,0.02142
98.3,8.192,25739.49,0.0924,0.02145
98.4,8.2,25737.31,0.09256,0.02147
98.5,8.209,25734.91,0.09274,0.0215
98.6,8.217,25731.8,0.09291,0.02153
98.7,8.225,25728.54,0.09307,0.02156
98.8,8.233,25730.08,0.09324,0.02158
98.9,8.242,25725.65,0.0934,0.02161
99,8.25,25723.58,0.09358,0.02163
99.1,8.259,25720.62,0.09375,0.02166
99.2,8.267,25711.78,0.09392,0.02168
99.3,8.275,25709.81,0.09408,0.0217
99.4,8.283,25692.17,0.09425,0.02173
99.5,8.292,25694.3,0.09442,0.02175
99.6,8.3,25695.12,0.09459,0.02177
99.7,8.309,25691.61,0.09476,0.02179
99.8,8.317,25684.79,0.09492,0.02181
99.9,8.325,25686.94,0.09509,0.02183
100,8.334,25690.32,0.09527,0.02185
100.1,8.342,25680.89,0.09544,0.02187
100.2,8.35,25667.38,0.09561,0.02189
100.3,8.359,25661.51,0.09578,0.02191
100.4,8.367,25662.76,0.09595,0.02192
100.5,8.375,25656.73,0.09612,0.02194
100.6,8.384,25652.48,0.09629,0.02196
100.7,8.392,25652.49,0.09646,0.02197
100.8,8.4,25650.47,0.09663,0.02199
100.9,8.409,25641.53,0.0968,0.022
101,8.417,25641.42,0.09697,0.02202
101.1,8.425,25636.91,0.09714,0.02203
101.2,8.434,25631.87,0.09732,0.02205
101.3,8.442,25627.31,0.09748,0.02206
101.4,8.45,25631.3,0.09766,0.02207
101.5,8.458,25621.17,0.09783,0.02208
101.6,8.467,25621.72,0.098,0.02209
101.7,8.475,25616.85,0.09818,0.02209
101.8,8.484,25609.54,0.09836,0.0221
101.9,8.492,25610.13,0.09852,0.0221
102,8.5,25606.8,0.09869,0.0221
102.1,8.509,25596.03,0.09887,0.0221
102.2,8.517,25595.79,0.09904,0.0221
102.3,8.525,25583.61,0.09921,0.02206
102.4,8.534,25583.89,0.09938,0.02145
102.5,8.542,25573.44,0.09955,0.02148
102.6,8.55,25563.27,0.09972,0.02148
102.7,8.559,25557.86,0.0999,0.02149
102.8,8.567,25554.91,0.10007,0.0215
102.9,8.575,25540.5,0.10024,0.0215
103,8.584,25527.73,0.10042,0.02151
103.1,8.592,25518.42,0.10058,0.02152
103.2,8.6,25513.24,0.10076,0.02153
103.3,8.609,25506.08,0.10093,0.02154
103.4,8.617,25498.2,0.1011,0.02154
103.5,8.625,25488.15,0.10127,0.02155
103.6,8.633,25478.78,0.10144,0.02156
103.7,8.642,25473.34,0.10161,0.02156
103.8,8.65,25473.91,0.10178,0.02156
103.9,8.659,25462.93,0.10195,0.02157
104,8.667,25456.99,0.10211,0.02157
104.1,8.675,25451.1,0.10228,0.02157
104.2,8.683,25445.29,0.10244,0.02158
104.3,8.692,25443.27,0.10261,0.02158
104.4,8.7,25432.34,0.10277,0.02158
104.5,8.709,25426.32,0.10293,0.02159
104.6,8.717,25417.2,0.1031,0.02159
104.7,8.725,25397.16,0.10326,0.02159
104.8,8.733,25392.92,0.10341,0.02159
104.9,8.742,25387.72,0.10357,0.02159
105,8.75,25367.76,0.10374,0.0216
105.1,8.759,25363.32,0.1039,0.0216
105.2,8.767,25352.8,0.10406,0.0216
105.3,8.775,25345.86,0.10422,0.0216
105.4,8.784,25341.33,0.10438,0.0216
105.5,8.792,25332.19,0.10454,0.0216
105.6,8.8,25329.22,0.10471,0.0216
105.7,8.809,25326.47,0.10487,0.0216
105.8,8.817,25320.36,0.10503,0.0216
105.9,8.825,25318.29,0.10519,0.0216
106,8.834,25316.66,0.10534,0.02161
106.1,8.842,25314.8,0.1055,0.02161
106.2,8.85,25312.5,0.10566,0.02161
106.3,8.858,25309.25,0.10582,0.02161
106.4,8.867,25307.09,0.10599,0.02161
106.5,8.875,25306.09,0.10615,0.02161
106.6,8.883,25302.67,0.10632,0.02161
106.7,8.892,25300.94,0.10648,0.02161
106.8,8.9,25299.4,0.10664,0.02161
106.9,8.908,25296.62,0.10682,0.02161
107,8.917,25293.29,0.107,0.02161
107.1,8.925,25291.25,0.10717,0.02161
107.2,8.934,25284.9,0.10733,0.02161
107.3,8.942,25277.15,0.10748,0.02161
107.4,8.95,25270.93,0.10763,0.02161
107.5,8.959,25262.71,0.10777,0.02161
107.6,8.967,25250.72,0.10792,0.02161
107.7,8.975,25236.71,0.10808,0.02161
107.8,8.984,25212.74,0.10822,0.02161
107.9,8.992,25191.03,0.10836,0.02161
108,9,25174.97,0.10851,0.0216
108.1,9.009,25158.24,0.10866,0.02161
108.2,9.017,25141.2,0.10881,0.0216
108.3,9.025,25126.23,0.10896,0.0216
108.4,9.034,25112.45,0.1091,0.0216
108.5,9.042,25104.83,0.10925,0.0216
108.6,9.05,25096.58,0.10941,0.0216
108.7,9.059,25089.57,0.10959,0.0216
108.8,9.067,25072.23,0.10976,0.0216
108.9,9.075,25061.44,0.10992,0.0216
109,9.084,25050.5,0.11008,0.0216
109.1,9.092,25029.76,0.11024,0.0216
109.2,9.1,25017.96,0.11038,0.0216
109.3,9.109,25000.78,0.11054,0.0216
109.4,9.117,24980.56,0.11068,0.0216
109.5,9.125,24968.92,0.11083,0.0216
109.6,9.133,24952.3,0.11096,0.0216
109.7,9.142,24940.86,0.11109,0.02159
109.8,9.15,24924.45,0.11122,0.02159
109.9,9.159,24897.46,0.11133,0.02159
110,9.167,24891.16,0.11147,0.02159
110.1,9.175,24859.21,0.1116,0.02159
110.2,9.183,24842.16,0.11174,0.02159
110.3,9.192,24826.52,0.11189,0.02159
110.4,9.2,24814.28,0.11203,0.02159
110.5,9.208,24809.85,0.11217,0.02159
110.6,9.217,24804.4,0.1123,0.02159
110.7,9.225,24802.43,0.11244,0.02158
110.8,9.233,24798.6,0.11258,0.02158
110.9,9.242,24795.45,0.11272,0.02158
111,9.25,24792.11,0.11286,0.02158
111.1,9.258,24788.46,0.113,0.02158
111.2,9.267,24783.71,0.11315,0.02158
111.3,9.275,24777.46,0.11329,0.02158
111.4,9.284,24767.89,0.11342,0.02158
111.5,9.292,24759.63,0.11356,0.02158
111.6,9.3,24758.2,0.11369,0.02158
111.7,9.308,24751.74,0.11384,0.02158
111.8,9.317,24745.98,0.11399,0.02157
111.9,9.325,24741.3,0.11414,0.02157
112,9.334,24734.08,0.11429,0.02157
112.1,9.342,24722.86,0.11445,0.02157
112.2,9.35,24697.8,0.11461,0.02157
112.3,9.358,24684.07,0.11476,0.02157
112.4,9.367,24666.64,0.11493,0.02157
112.5,9.375,24649.62,0.11509,0.02157
112.6,9.383,24633.26,0.11526,0.02156
112.7,9.392,24618.73,0.11542,0.02157
112.8,9.4,24604.14,0.11558,0.02156
112.9,9.409,24594.97,0.11575,0.02156
113,9.417,24580.32,0.11592,0.02156
113.1,9.425,24562.64,0.11608,0.02156
113.2,9.434,24546.73,0.11625,0.02156
113.3,9.442,24529.97,0.11642,0.02156
113.4,9.45,24515.66,0.11658,0.02156
113.5,9.459,24506.12,0.11675,0.02155
113.6,9.467,24488.47,0.11692,0.02155
113.7,9.475,24480.73,0.11709,0.02155
113.8,9.484,24462.28,0.11727,0.02155
113.9,9.492,24433,0.11743,0.02155
114,9.5,24410.56,0.11761,0.02155
114.1,9.509,24374.48,0.11778,0.02155
114.2,9.517,24354.13,0.11796,0.02155
114.3,9.525,24332.8,0.11813,0.02155
114.4,9.534,24314.86,0.11829,0.02155
114.5,9.542,24299.63,0.11845,0.02155
114.6,9.55,24284.52,0.11861,0.02154
114.7,9.559,24276.7,0.11877,0.02154
114.8,9.567,24266.85,0.11893,0.02154
114.9,9.575,24251.18,0.1191,0.02154
115,9.583,24238.1,0.11927,0.02154
115.1,9.592,24233.38,0.11943,0.02154
115.2,9.6,24218.8,0.1196,0.02154
115.3,9.609,24209.88,0.11977,0.02154
115.4,9.617,24206.69,0.11995,0.02153
115.5,9.625,24196.77,0.12014,0.02153
115.6,9.634,24184.08,0.12032,0.02153
115.7,9.642,24172.13,0.1205,0.02153
115.8,9.65,24143.59,0.12067,0.02153
115.9,9.659,24115.92,0.12085,0.02153
116,9.667,24089.66,0.12104,0.02153
116.1,9.675,24059.48,0.12124,0.02153
116.2,9.684,24044.09,0.12144,0.02152
116.3,9.692,24036.9,0.12163,0.02152
116.4,9.7,24022.9,0.12182,0.02152
116.5,9.709,24010.14,0.12201,0.02152
116.6,9.717,23996.77,0.12219,0.02152
116.7,9.725,23983.32,0.12238,0.02152
116.8,9.734,23972.06,0.12255,0.02152
116.9,9.742,23962.95,0.12273,0.02152
117,9.75,23951.36,0.12292,0.02151
117.1,9.758,23937.5,0.12311,0.02151
117.2,9.767,23918,0.12329,0.02151
117.3,9.775,23887.62,0.12346,0.02151
117.4,9.784,23856.92,0.12362,0.02151
117.5,9.792,23837.79,0.12378,0.02151
117.6,9.8,23828.54,0.12394,0.02151
117.7,9.808,23822.59,0.1241,0.02151
117.8,9.817,23812.53,0.12426,0.02151
117.9,9.825,23803.61,0.12442,0.0215
118,9.833,23789.27,0.12459,0.0215
118.1,9.842,23774,0.12476,0.0215
118.2,9.85,23762.19,0.12494,0.0215
118.3,9.859,23748.24,0.12511,0.0215
118.4,9.867,23728.83,0.12528,0.0215
118.5,9.875,23717.79,0.12545,0.0215
118.6,9.884,23703.22,0.12562,0.02149
118.7,9.892,23673.89,0.12579,0.02149
118.8,9.9,23649.53,0.12595,0.02149
118.9,9.909,23619.4,0.12612,0.02149
119,9.917,23582.71,0.12628,0.02149
119.1,9.925,23562.7,0.12644,0.02149
119.2,9.933,23547.61,0.12661,0.02149
119.3,9.942,23509.59,0.12678,0.02148
119.4,9.95,23487.06,0.12697,0.02148
119.5,9.959,23452.98,0.12717,0.02148
119.6,9.967,23422.89,0.12738,0.02148
119.7,9.975,23402.6,0.12758,0.02148
119.8,9.983,23387.24,0.12779,0.02148
119.9,9.992,23368.71,0.12799,0.02148
120,10,23354.79,0.12819,0.02148
120.1,10.009,23319.89,0.1284,0.02147
120.2,10.017,23281.3,0.1286,0.02147
120.3,10.025,23271.28,0.1288,0.02147
120.4,10.034,23258.5,0.129,0.02147
120.5,10.042,23253.61,0.12921,0.02147
120.6,10.05,23251.51,0.12941,0.02147
120.7,10.059,23251.16,0.12961,0.02147
120.8,10.067,23250.83,0.1298,0.02146
120.9,10.075,23249.59,0.12999,0.02146
121,10.084,23246.8,0.13018,0.02146
121.1,10.092,23242.77,0.13037,0.02146
121.2,10.1,23233.55,0.13056,0.02146
121.3,10.108,23207.52,0.13075,0.02146
121.4,10.117,23180.58,0.13094,0.02145
121.5,10.125,23146.77,0.13113,0.02145
121.6,10.134,23109.51,0.13132,0.02145
121.7,10.142,23085.26,0.13151,0.02145
121.8,10.15,23059.42,0.13171,0.02145
121.9,10.158,23021.08,0.1319,0.02145
122,10.167,22987.83,0.1321,0.02145
122.1,10.175,22949.63,0.13231,0.02144
122.2,10.184,22920.42,0.13251,0.02144
122.3,10.192,22900.04,0.13271,0.02144
122.4,10.2,22869.32,0.13292,0.02144
122.5,10.208,22827.34,0.13313,0.02144
122.6,10.217,22793.01,0.13335,0.02144
122.7,10.225,22762.41,0.13357,0.02144
122.8,10.234,22740,0.13378,0.02143
122.9,10.242,22721.62,0.134,0.02143
123,10.25,22697.41,0.13421,0.02143
123.1,10.259,22683.26,0.13443,0.02143
123.2,10.267,22663.42,0.13464,0.02143
123.3,10.275,22643.22,0.13485,0.02143
123.4,10.284,22632.65,0.13507,0.02143
123.5,10.292,22627.01,0.13528,0.02142
123.6,10.3,22607.03,0.13549,0.02142
123.7,10.308,22581.63,0.13571,0.02142
123.8,10.317,22559.96,0.13592,0.02142
123.9,10.325,22544.58,0.13613,0.02142
124,10.334,22536.18,0.13634,0.02141
124.1,10.342,22523.16,0.13655,0.02142
124.2,10.35,22498.42,0.13675,0.02141
124.3,10.359,22476.14,0.13696,0.02141
124.4,10.367,22448.49,0.13717,0.02141
124.5,10.375,22419.15,0.13738,0.02141
124.6,10.383,22386.21,0.13758,0.02141
124.7,10.392,22341.89,0.13779,0.02141
124.8,10.4,22296.71,0.138,0.0214
124.9,10.409,22267.43,0.13821,0.0214
125,10.417,22252.16,0.13841,0.0214
125.1,10.425,22240.34,0.13862,0.0214
125.2,10.434,22222.48,0.13884,0.0214
125.3,10.442,22199.85,0.13905,0.02139
125.4,10.45,22182.41,0.13927,0.02139
125.5,10.459,22160.29,0.13949,0.02139
125.6,10.467,22134.1,0.13971,0.02139
125.7,10.475,22099.86,0.13992,0.02139
125.8,10.483,22053.24,0.14012,0.02139
125.9,10.492,22013.91,0.14033,0.02138
126,10.5,21981.54,0.14054,0.02138
126.1,10.509,21947.32,0.14074,0.02138
126.2,10.517,21902.19,0.14094,0.02138
126.3,10.525,21865.33,0.14113,0.02138
126.4,10.534,21846.54,0.14133,0.02138
126.5,10.542,21823.33,0.14153,0.02137
126.6,10.55,21788.05,0.14173,0.02137
126.7,10.559,21759.29,0.14194,0.02137
126.8,10.567,21751.11,0.14214,0.02137
126.9,10.575,21750.07,0.14235,0.02137
127,10.584,21748.86,0.14255,0.02137
127.1,10.592,21743.81,0.14275,0.02136
127.2,10.6,21728.19,0.14295,0.02136
127.3,10.609,21695.61,0.14315,0.02136
127.4,10.617,21645.36,0.14335,0.02136
127.5,10.625,21571.65,0.14355,0.02135
127.6,10.634,21513.9,0.14375,0.02135
127.7,10.642,21459.78,0.14396,0.02135
127.8,10.65,21234.8,0.14424,0.02133
127.89,10.658,9496.89,0.13701,0.0157