File: Labs/Lab 2 Tension/A36 Steel Sample 1.csv
Time (s),Extension (mm),Load (N),Axial Strain (mm/mm),Transverse Strain (mm/mm)
0,0,4.2,0,0
0.2,0.014,490.7,0.00003,0.00001
0.4,0.034,1312.79,0.00011,0.00003
0.6,0.05,1632.38,0.00015,0.00003
0.8,0.067,1922.27,0.00018,0.00004
1,0.084,2146.78,0.00021,0.00004
1.2,0.1,2456.76,0.00025,0.00004
1.4,0.117,2626.69,0.00028,0.00004
1.6,0.134,2899.17,0.00031,0.00005
1.8,0.15,3097.07,0.00033,0.00006
2,0.167,3315.85,0.00035,0.00006
2.2,0.183,3504.66,0.00037,0.00007
2.4,0.2,3760.26,0.00039,0.00007
2.6,0.217,3977.6,0.00041,0.00007
2.8,0.233,4206.32,0.00043,0.00008
3,0.25,4437.06,0.00045,0.00008
3.2,0.267,4603.8,0.00048,0.00009
3.4,0.283,4861.89,0.0005,0.00009
3.6,0.3,5055.38,0.00052,0.00009
3.8,0.317,5315.36,0.00054,0.0001
4,0.334,5507.5,0.00056,0.0001
4.2,0.35,5770.86,0.00058,0.00011
4.4,0.367,6008.41,0.0006,0.00011
4.6,0.384,6171.51,0.00062,0.00012
4.8,0.4,6518.6,0.00064,0.00012
5,0.417,6648.62,0.00066,0.00012
5.2,0.434,6882.17,0.00068,0.00013
5.4,0.45,7131.12,0.00069,0.00013
5.6,0.467,7396.85,0.00071,0.00014
5.8,0.484,7560.5,0.00073,0.00014
6,0.5,7820.94,0.00075,0.00015
6.2,0.517,8113.86,0.00077,0.00015
6.4,0.534,8245.26,0.00078,0.00015
6.6,0.55,8579.01,0.0008,0.00016
6.8,0.567,8801.07,0.00082,0.00016
7,0.583,8984.58,0.00084,0.00016
7.2,0.6,9221.98,0.00086,0.00016
7.4,0.617,9558.22,0.00088,0.00016
7.6,0.633,9654.94,0.0009,0.00017
7.8,0.65,10002.05,0.00091,0.00017
8,0.667,10242.33,0.00093,0.00018
8.2,0.683,10452.96,0.00095,0.00018
8.4,0.7,10734.16,0.00097,0.00018
8.6,0.717,11026.11,0.00098,0.00019
8.8,0.733,11196.97,0.001,0.00019
9,0.75,11542.32,0.00102,0.0002
9.2,0.767,11746.93,0.00104,0.0002
9.4,0.783,12006.68,0.00106,0.0002
9.6,0.8,12295.51,0.00108,0.0002
9.8,0.817,12543.13,0.0011,0.00021
10,0.834,12777.37,0.00112,0.00021
10.2,0.85,13118.23,0.00114,0.00022
10.4,0.867,13312.53,0.00115,0.00022
10.6,0.884,13646.14,0.00117,0.00023
10.8,0.9,13855.7,0.00119,0.00023
11,0.917,14174.29,0.00121,0.00024
11.2,0.934,14421.47,0.00123,0.00024
11.4,0.95,14734.72,0.00125,0.00025
11.6,0.967,14939.1,0.00127,0.00025
11.8,0.984,15293.93,0.0013,0.00026
12,1,15531.45,0.00132,0.00026
12.2,1.017,15832.97,0.00134,0.00027
12.4,1.033,16045.41,0.00137,0.00027
12.6,1.05,16358.12,0.00138,0.00027
12.8,1.067,16637.86,0.00141,0.00028
13,1.083,16888.23,0.00144,0.00028
13.2,1.1,17193.99,0.00146,0.00029
13.4,1.117,17393.94,0.00149,0.00029
13.6,1.133,17766.72,0.00152,0.0003
13.8,1.15,17962.68,0.00154,0.0003
14,1.167,18296.2,0.00158,0.00031
14.2,1.183,18556.75,0.00161,0.00031
14.4,1.2,18849.04,0.00164,0.00032
14.6,1.217,19105.53,0.00167,0.00032
14.8,1.234,19437.95,0.0017,0.00033
15,1.25,19629.45,0.00173,0.00034
15.2,1.267,19973.27,0.00177,0.00034
15.4,1.284,20189.29,0.0018,0.00035
15.6,1.3,20473.25,0.00184,0.00035
15.8,1.317,20813.09,0.00188,0.00036
16,1.334,20956.14,0.00192,0.00036
16.2,1.35,21316.5,0.00196,0.00037
16.4,1.367,21563.55,0.002,0.00037
16.6,1.384,21803.23,0.00204,0.00038
16.8,1.4,22067.2,0.00208,0.00038
17,1.417,22350.61,0.00212,0.00039
17.2,1.434,22548.06,0.00216,0.0004
17.4,1.45,22878.45,0.0022,0.00041
17.6,1.467,23063.78,0.00224,0.00041
17.8,1.483,23271.08,0.00228,0.00042
18,1.5,23561.71,0.0023,0.00043
18.2,1.517,23740.61,0.00233,0.00044
18.4,1.534,23857.04,0.00234,0.00045
18.6,1.55,24032.84,0.00235,0.00046
18.8,1.567,24143.55,0.00236,0.00048
19,1.583,24339.92,0.00237,0.00049
19.2,1.6,24483.85,0.00241,0.00051
19.4,1.617,24566.6,0.00246,0.00054
19.6,1.634,24617.29,0.00254,0.00056
19.8,1.65,24735.69,0.00263,0.00059
20,1.667,24852.63,0.00276,0.00062
20.2,1.683,24920.29,0.00292,0.00064
20.4,1.7,24997.89,0.00311,0.00067
20.6,1.717,25065.03,0.00335,0.0007
20.8,1.734,25101.19,0.00363,0.00072
21,1.75,25110.29,0.00396,0.00075
21.2,1.767,25111.86,0.00435,0.00078
21.4,1.784,25106.48,0.00479,0.00081
21.6,1.8,25107.19,0.00525,0.00083
21.8,1.817,25111.38,0.00572,0.00086
22,1.834,25113.74,0.0062,0.00089
22.2,1.85,25113.55,0.00668,0.00091
22.4,1.867,25113.92,0.00717,0.00094
22.6,1.883,25108.29,0.00768,0.00098
22.8,1.9,25107.36,0.00819,0.00102
23,1.917,25106.96,0.0087,0.00108
23.2,1.934,25100.62,0.0092,0.00115
23.4,1.95,25040.32,0.00972,0.00127
23.6,1.967,24960.76,0.01021,0.00143
23.8,1.983,24897.16,0.01059,0.00164
24,2,24835.77,0.0109,0.0019
24.2,2.017,24742.38,0.01113,0.00222
24.4,2.034,24628.26,0.01129,0.00265
24.6,2.05,24613.83,0.01141,0.0031
24.8,2.067,24626.7,0.01154,0.00345
25,2.084,24712.81,0.01169,0.00374
25.2,2.1,24791.34,0.01187,0.00399
25.4,2.117,24871.84,0.01206,0.00421
25.6,2.134,24930.85,0.01227,0.0044
25.8,2.15,25005.54,0.01248,0.00458
26,2.167,25054.07,0.01267,0.00475
26.2,2.184,25086.82,0.01288,0.00489
26.4,2.2,25098.71,0.01307,0.00503
26.6,2.217,25085.19,0.01327,0.00514
26.8,2.233,25074.29,0.01346,0.00523
27,2.25,25007.21,0.01364,0.00529
27.2,2.267,24964.39,0.01379,0.00534
27.4,2.284,25008,0.01392,0.00538
27.6,2.3,25087.35,0.01403,0.00542
27.8,2.317,25126.26,0.01414,0.00546
28,2.334,25214.9,0.01426,0.00551
28.2,2.35,25355.34,0.01438,0.00557
28.4,2.367,25472.56,0.01451,0.00564
28.6,2.384,25577.77,0.01466,0.00573
28.8,2.4,25658.18,0.01482,0.00581
29,2.417,25705.59,0.01499,0.00589
29.2,2.433,25781.74,0.01517,0.00597
29.4,2.45,25845.13,0.01535,0.00606
29.6,2.467,25911.04,0.01554,0.00614
29.8,2.484,25968.67,0.01573,0.00622
30,2.5,26066.81,0.01593,0.0063
30.2,2.517,26109.01,0.01612,0.00638
30.4,2.534,26124.09,0.01631,0.00645
30.6,2.55,26150.29,0.0165,0.00653
30.8,2.567,26190.62,0.01669,0.00661
31,2.584,26295.09,0.01689,0.00669
31.2,2.6,26354.71,0.01708,0.00677
31.4,2.617,26453.96,0.01726,0.00685
31.6,2.633,26504.14,0.01745,0.00693
31.8,2.65,26587.5,0.01764,0.007
32,2.667,26616.27,0.01783,0.00708
32.2,2.684,26635.73,0.01801,0.00716
32.4,2.7,26667.08,0.01819,0.00724
32.6,2.717,26724.17,0.01838,0.00732
32.8,2.734,26817.04,0.01856,0.00741
33,2.75,26862.49,0.01875,0.00749
33.2,2.767,26920.13,0.01895,0.00757
33.4,2.784,26964.16,0.01913,0.00765
33.6,2.8,27050.93,0.01932,0.00774
33.8,2.817,27143.57,0.01951,0.00783
34,2.833,27183.04,0.0197,0.00791
34.2,2.85,27196.62,0.01989,0.00799
34.4,2.867,27213.66,0.02008,0.00808
34.6,2.883,27248.92,0.02026,0.00816
34.8,2.9,27325.43,0.02045,0.00825
35,2.917,27392.95,0.02064,0.00833
35.2,2.934,27475.31,0.02083,0.00842
35.4,2.95,27536.66,0.02102,0.00851
35.6,2.967,27599.57,0.02121,0.00859
35.8,2.984,27653.3,0.0214,0.00868
36,3,27681.05,0.02159,0.00877
36.2,3.017,27693.07,0.02178,0.00886
36.4,3.034,27710.46,0.02198,0.00894
36.6,3.05,27777.21,0.02217,0.00903
36.8,3.067,27872.96,0.02237,0.00912
37,3.084,27909.41,0.02256,0.00921
37.2,3.1,27966.61,0.02276,0.0093
37.4,3.117,28006.5,0.02295,0.00939
37.6,3.134,28070.91,0.02315,0.00948
37.8,3.15,28119.31,0.02334,0.00957
38,3.167,28177.06,0.02353,0.00966
38.2,3.183,28221.46,0.02373,0.00975
38.4,3.2,28257.6,0.02393,0.00984
38.6,3.217,28288.49,0.02413,0.00993
38.8,3.234,28349.04,0.02432,0.01002
39,3.25,28393.71,0.02452,0.01011
39.2,3.267,28444.9,0.02472,0.0102
39.4,3.284,28521.81,0.02492,0.01031
39.6,3.3,28559.46,0.02512,0.0104
39.8,3.317,28630.34,0.02532,0.01049
40,3.334,28676.01,0.02552,0.01059
40.2,3.35,28691.28,0.02571,0.01068
40.4,3.367,28703.07,0.02591,0.01077
40.6,3.384,28728.04,0.02611,0.01087
40.8,3.4,28772.46,0.02632,0.01095
41,3.417,28844.92,0.02652,0.01104
41.2,3.434,28910.42,0.02672,0.01114
41.4,3.45,28967.54,0.02692,0.01123
41.6,3.467,29025.71,0.02712,0.01132
41.8,3.484,29073.22,0.02732,0.01141
42,3.5,29122.29,0.02752,0.0115
42.2,3.517,29183.15,0.02772,0.0116
42.4,3.534,29198.35,0.02792,0.01169
42.6,3.55,29214.46,0.02812,0.01179
42.8,3.567,29242.61,0.02833,0.01188
43,3.584,29258.35,0.02853,0.01197
43.2,3.6,29291.84,0.02873,0.01206
43.4,3.617,29363.94,0.02893,0.01215
43.6,3.634,29407.6,0.02913,0.01225
43.8,3.65,29435.49,0.02934,0.01235
44,3.667,29487.44,0.02954,0.01244
44.2,3.684,29530.54,0.02974,0.01253
44.4,3.7,29604.08,0.02994,0.01263
44.6,3.717,29687.24,0.03015,0.01273
44.8,3.733,29728.93,0.03035,0.01282
45,3.75,29761.2,0.03056,0.01291
45.2,3.767,29785.99,0.03076,0.013
45.4,3.783,29798.72,0.03096,0.01309
45.6,3.8,29821.8,0.03117,0.01318
45.8,3.817,29882.34,0.03138,0.01328
46,3.833,29931.79,0.03158,0.01337
46.2,3.85,29965.67,0.03178,0.01346
46.4,3.867,29988.02,0.03199,0.01355
46.6,3.884,30029.71,0.0322,0.01366
46.8,3.9,30061.82,0.0324,0.01376
47,3.917,30104.4,0.03261,0.01386
47.2,3.934,30159.12,0.0328,0.01396
47.4,3.95,30196.56,0.03301,0.01405
47.6,3.967,30216.61,0.0332,0.01414
47.8,3.984,30254.18,0.03341,0.01423
48,4,30275.61,0.03361,0.01433
48.2,4.017,30296.73,0.03381,0.01443
48.4,4.034,30320.18,0.03402,0.01453
48.6,4.05,30379.66,0.03421,0.01461
48.8,4.067,30458.57,0.03441,0.01471
49,4.084,30504.57,0.03461,0.01481
49.2,4.1,30547.92,0.03482,0.0149
49.4,4.117,30585.11,0.03502,0.015
49.6,4.134,30612.85,0.03522,0.01509
49.8,4.15,30655.76,0.03542,0.01519
50,4.167,30715.36,0.03563,0.01529
50.2,4.184,30740.75,0.03582,0.01538
50.4,4.2,30743.59,0.03603,0.01548
50.6,4.217,30745.12,0.03623,0.01557
50.8,4.234,30752.96,0.03643,0.01566
51,4.25,30766.75,0.03664,0.01576
51.2,4.267,30787.08,0.03684,0.01585
51.4,4.284,30828.01,0.03705,0.01595
51.6,4.3,30880.26,0.03725,0.01605
51.8,4.317,30921,0.03746,0.01615
52,4.334,30974.02,0.03766,0.01624
52.2,4.35,31020.84,0.03787,0.01634
52.4,4.367,31072.14,0.03807,0.01643
52.6,4.383,31106.41,0.03827,0.01652
52.8,4.4,31138.88,0.03847,0.01662
53,4.417,31190.73,0.03868,0.01671
53.2,4.434,31261.44,0.03888,0.01681
53.4,4.45,31289.73,0.03909,0.01692
53.6,4.467,31313.95,0.03929,0.01701
53.8,4.484,31339.37,0.03949,0.0171
54,4.5,31357.72,0.0397,0.0172
54.2,4.517,31372.9,0.03991,0.0173
54.4,4.534,31378.71,0.04011,0.01739
54.6,4.55,31392.93,0.04032,0.01749
54.8,4.567,31425.43,0.04052,0.01759
55,4.584,31457.03,0.04072,0.01768
55.2,4.6,31473.38,0.04093,0.01778
55.4,4.617,31495.91,0.04114,0.01787
55.6,4.634,31524.62,0.04135,0.01797
55.8,4.65,31565,0.04156,0.01807
56,4.667,31590.13,0.04176,0.01816
56.2,4.684,31636.67,0.04197,0.01826
56.4,4.7,31697.29,0.04217,0.01835
56.6,4.717,31739.32,0.04238,0.01845
56.8,4.734,31766.2,0.04259,0.01854
57,4.75,31779.86,0.0428,0.01866
57.2,4.767,31795.93,0.043,0.01875
57.4,4.784,31822.51,0.04321,0.01884
57.6,4.8,31840.18,0.04343,0.01894
57.8,4.817,31857.73,0.04363,0.01904
58,4.834,31881.96,0.04384,0.01913
58.2,4.85,31912.86,0.04405,0.01923
58.4,4.867,31979.14,0.04426,0.01932
58.6,4.883,32012.37,0.04446,0.01942
58.8,4.9,32040.41,0.04467,0.01952
59,4.917,32077.73,0.04488,0.01962
59.2,4.933,32109.31,0.04509,0.01971
59.4,4.95,32144.16,0.0453,0.01981
59.6,4.967,32161.21,0.04551,0.0199
59.8,4.984,32175.01,0.04572,0.02
60,5,32194.89,0.04593,0.0201
60.2,5.017,32222.33,0.04614,0.0202
60.4,5.033,32236.12,0.04635,0.02029
60.6,5.05,32254.89,0.04656,0.02038
60.8,5.067,32257.42,0.04677,0.02048
61,5.084,32264.8,0.04698,0.02059
61.2,5.1,32272.9,0.04719,0.02068
61.4,5.117,32284.99,0.0474,0.02078
61.6,5.134,32308.29,0.04761,0.02088
61.8,5.15,32339.12,0.04782,0.02097
62,5.167,32365.33,0.04803,0.02107
62.2,5.184,32405.47,0.04824,0.02117
62.4,5.2,32442.1,0.04845,0.02127
62.6,5.217,32490.44,0.04866,0.02136
62.8,5.233,32513.52,0.04887,0.02146
63,5.25,32548.02,0.04909,0.02156
63.2,5.267,32574.61,0.0493,0.02165
63.4,5.284,32612.62,0.0495,0.02174
63.6,5.3,32635.46,0.04971,0.02184
63.8,5.317,32659.75,0.04993,0.02194
64,5.334,32696.01,0.05014,0.02204
64.2,5.35,32740.46,0.05036,0.02214
64.4,5.367,32809.3,0.05058,0.02223
64.6,5.384,32833.32,0.05079,0.02233
64.8,5.4,32855.15,0.051,0.02243
65,5.417,32866.05,0.05122,0.02253
65.2,5.433,32869.05,0.05143,0.02263
65.4,5.45,32869.43,0.05164,0.02273
65.6,5.467,32869.59,0.05186,0.02283
65.8,5.483,32869.77,0.05207,0.02293
66,5.5,32870,0.05229,0.02302
66.2,5.517,32871.46,0.05251,0.02312
66.4,5.534,32878.48,0.05272,0.02322
66.6,5.55,32893.8,0.05293,0.02332
66.8,5.567,32911.94,0.05315,0.02342
67,5.584,32951.86,0.05336,0.02352
67.2,5.6,32975.62,0.05358,0.02361
67.4,5.617,32991.89,0.0538,0.02371
67.6,5.634,33020.58,0.05401,0.0238
67.8,5.65,33058.93,0.05423,0.02389
68,5.667,33088.36,0.05445,0.02399
68.2,5.684,33120.5,0.05466,0.0241
68.4,5.7,33143.6,0.05488,0.0242
68.6,5.717,33164.04,0.05509,0.0243
68.8,5.734,33181.71,0.05531,0.02439
69,5.75,33211.8,0.05553,0.02449
69.2,5.767,33262.58,0.05575,0.02458
69.4,5.784,33283.31,0.05596,0.02468
69.6,5.8,33314.33,0.05618,0.02478
69.8,5.817,33331.02,0.0564,0.02488
70,5.833,33340.88,0.05662,0.02498
70.2,5.85,33363.37,0.05684,0.02507
70.4,5.867,33368.35,0.05705,0.02517
70.6,5.884,33380.68,0.05727,0.02527
70.8,5.9,33384.01,0.05749,0.02537
71,5.917,33396.58,0.05771,0.02547
71.2,5.933,33410.15,0.05792,0.02557
71.4,5.95,33439.27,0.05814,0.02567
71.6,5.967,33462.09,0.05837,0.02577
71.8,5.983,33499.88,0.05858,0.02586
72,6,33538.35,0.05881,0.02596
72.2,6.017,33560.03,0.05903,0.02606
72.4,6.033,33581.73,0.05925,0.02616
72.6,6.05,33589.82,0.05947,0.02627
72.8,6.067,33601.38,0.05969,0.02637
73,6.084,33612.67,0.05991,0.02647
73.2,6.1,33625.54,0.06013,0.02656
73.4,6.117,33641.21,0.06035,0.02666
73.6,6.134,33655.07,0.06057,0.02675
73.8,6.15,33659.57,0.06079,0.02685
74,6.167,33668.43,0.06102,0.02695
74.2,6.184,33676.68,0.06124,0.02705
74.4,6.2,33696.59,0.06146,0.02715
74.6,6.217,33719.43,0.06168,0.02724
74.8,6.234,33743.38,0.0619,0.02734
75,6.25,33761.36,0.06213,0.02744
75.2,6.267,33772.1,0.06235,0.02754
75.4,6.284,33783.31,0.06257,0.02764
75.6,6.3,33805.52,0.0628,0.02773
75.8,6.317,33819.08,0.06302,0.02783
76,6.333,33832.64,0.06324,0.02793
76.2,6.35,33856.4,0.06346,0.02803
76.4,6.367,33865.19,0.06368,0.02812
76.6,6.384,33880.13,0.06391,0.02822
76.8,6.4,33893.84,0.06413,0.02832
77,6.417,33900.69,0.06436,0.02842
77.2,6.434,33913.45,0.06458,0.02852
77.4,6.45,33929.52,0.0648,0.02862
77.6,6.467,33943,0.06503,0.02872
77.8,6.484,33982.47,0.06525,0.02882
78,6.5,34002.14,0.06548,0.02891
78.2,6.517,34024.53,0.0657,0.02901
78.4,6.534,34048.32,0.06592,0.02912
78.6,6.55,34067.07,0.06615,0.02922
78.8,6.567,34084.59,0.06637,0.02932
79,6.584,34108.64,0.0666,0.02942
79.2,6.6,34129.91,0.06683,0.02951
79.4,6.617,34171.89,0.06705,0.02961
79.6,6.634,34186.66,0.06728,0.02971
79.8,6.65,34214.6,0.0675,0.02981
80,6.667,34234.13,0.06774,0.02991
80.2,6.684,34249.03,0.06796,0.03001
80.4,6.7,34255.76,0.06819,0.03011
80.6,6.717,34282.18,0.06842,0.03021
80.8,6.733,34288.75,0.06864,0.03031
81,6.75,34321.5,0.06887,0.03041
81.2,6.767,34332.94,0.06909,0.03052
81.4,6.784,34351.04,0.06932,0.03061
81.6,6.8,34363.73,0.06955,0.03071
81.8,6.817,34370.02,0.06978,0.03081
82,6.834,34370.43,0.07,0.03091
82.2,6.85,34371.82,0.07023,0.03101
82.4,6.867,34372.23,0.07046,0.0311
82.6,6.884,34372.14,0.07069,0.0312
82.8,6.9,34372.53,0.07091,0.0313
83,6.917,34372.86,0.07114,0.0314
83.2,6.934,34374.12,0.07137,0.0315
83.4,6.95,34377.5,0.0716,0.0316
83.6,6.967,34378.62,0.07183,0.0317
83.8,6.984,34382.09,0.07205,0.0318
84,7,34392.45,0.07228,0.0319
84.2,7.017,34398.87,0.07252,0.032
84.4,7.034,34409.48,0.07275,0.0321
84.6,7.05,34416.95,0.07297,0.03219
84.8,7.067,34448.56,0.0732,0.03229
85,7.084,34470.7,0.07343,0.03239
85.2,7.1,34486.49,0.07366,0.03249
85.4,7.117,34509.03,0.07389,0.03259
85.6,7.133,34512.12,0.07412,0.03268
85.8,7.15,34535.89,0.07435,0.03279
86,7.167,34537.64,0.07458,0.0329
86.2,7.183,34556.14,0.07481,0.033
86.4,7.2,34583.25,0.07504,0.03309
86.6,7.217,34598.52,0.07527,0.0332
86.8,7.234,34623.46,0.0755,0.0333
87,7.25,34639.32,0.07573,0.0334
87.2,7.267,34655.57,0.07596,0.03349
87.4,7.284,34687.32,0.07619,0.03359
87.6,7.3,34692.69,0.07642,0.03369
87.8,7.317,34705.75,0.07666,0.0338
88,7.334,34720.05,0.07689,0.03389
88.2,7.35,34730.13,0.07711,0.03399
88.4,7.367,34745.61,0.07735,0.03409
88.6,7.384,34766.57,0.07758,0.03419
88.8,7.4,34787.12,0.07781,0.03428
89,7.417,34801.78,0.07804,0.03439
89.2,7.434,34826.31,0.07827,0.03449
89.4,7.45,34841.09,0.0785,0.03458
89.6,7.467,34857.9,0.07874,0.03469
89.8,7.484,34865.35,0.07897,0.03478
90,7.5,34873.77,0.07921,0.03488
90.2,7.517,34883.71,0.07943,0.03498
90.4,7.534,34889.69,0.07967,0.03509
90.6,7.55,34894.77,0.0799,0.03518
90.8,7.567,34908.87,0.08014,0.03528
91,7.584,34913.91,0.08038,0.03538
91.2,7.6,34920.8,0.08061,0.03548
91.4,7.617,34928.46,0.08084,0.03558
91.6,7.633,34937.91,0.08108,0.03568
91.8,7.65,34949.53,0.08131,0.03578
92,7.667,34951.79,0.08155,0.03588
92.2,7.683,34958.1,0.08179,0.03598
92.4,7.7,34965.52,0.08203,0.03608
92.6,7.717,34970.71,0.08226,0.03618
92.8,7.733,34981.2,0.0825,0.03628
93,7.75,34988.49,0.08274,0.03638
93.2,7.767,34991.22,0.08298,0.03648
93.4,7.784,35012.87,0.08322,0.03657
93.6,7.8,35015.77,0.08345,0.03667
93.8,7.817,35034.22,0.08369,0.03677
94,7.834,35048.75,0.08393,0.03688
94.2,7.85,35056.88,0.08417,0.03697
94.4,7.867,35068.5,0.0844,0.03708
94.6,7.884,35078.2,0.08464,0.03718
94.8,7.9,35081.02,0.08488,0.03728
95,7.917,35090.71,0.08512,0.03738
95.2,7.934,35091.14,0.08535,0.03748
95.4,7.95,35094.02,0.08559,0.03758
95.6,7.967,35096.78,0.08583,0.03768
95.8,7.984,35106.59,0.08607,0.03778
96,8,35113.78,0.08631,0.03788
96.2,8.017,35125.79,0.08654,0.03798
96.4,8.034,35129.75,0.08679,0.03808
96.6,8.05,35138.25,0.08703,0.03818
96.8,8.067,35148.43,0.08726,0.03828
97,8.083,35163.27,0.0875,0.03837
97.2,8.1,35169.48,0.08774,0.03848
97.4,8.117,35174.54,0.08798,0.03858
97.6,8.134,35183.5,0.08821,0.03868
97.8,8.15,35196.8,0.08845,0.03878
98,8.167,35204.54,0.08869,0.03888
98.2,8.184,35219.63,0.08894,0.03897
98.4,8.2,35235.04,0.08918,0.03907
98.6,8.217,35252.32,0.08942,0.03917
98.8,8.234,35257.65,0.08966,0.03928
99,8.25,35271.43,0.0899,0.03937
99.2,8.267,35282.66,0.09014,0.03947
99.4,8.283,35305.86,0.09038,0.03957
99.6,8.3,35318.17,0.09062,0.03967
99.8,8.317,35328.65,0.09086,0.03978
100,8.334,35341.84,0.0911,0.03987
100.2,8.35,35344,0.09134,0.03998
100.4,8.367,35367.63,0.09158,0.04008
100.6,8.384,35367.36,0.09183,0.04018
100.8,8.4,35368.82,0.09207,0.04027
101,8.417,35375.95,0.09232,0.04038
101.2,8.434,35384.6,0.09256,0.04047
101.4,8.45,35391.12,0.0928,0.04057
101.6,8.467,35396.53,0.09305,0.04067
101.8,8.484,35405.16,0.09329,0.04077
102,8.5,35410.66,0.09353,0.04086
102.2,8.517,35415.27,0.09378,0.04097
102.4,8.534,35419.35,0.09402,0.04107
102.6,8.55,35429.13,0.09427,0.04117
102.8,8.567,35428.11,0.09451,0.04126
103,8.584,35432.93,0.09475,0.04136
103.2,8.6,35439.06,0.095,0.04146
103.4,8.617,35440.38,0.09524,0.04156
103.6,8.634,35450.86,0.09549,0.04166
103.8,8.65,35450.19,0.09573,0.04176
104,8.667,35457.75,0.09598,0.04186
104.2,8.684,35462.3,0.09622,0.04196
104.4,8.7,35466.2,0.09646,0.04206
104.6,8.717,35479.78,0.09671,0.04216
104.8,8.734,35495.06,0.09696,0.04225
105,8.75,35494.41,0.0972,0.04235
105.2,8.767,35517.04,0.09744,0.04245
105.4,8.784,35527.07,0.09769,0.04255
105.6,8.8,35551.14,0.09793,0.04264
105.8,8.817,35564.71,0.09819,0.04275
106,8.834,35573.12,0.09843,0.04285
106.2,8.85,35589.14,0.09867,0.04295
106.4,8.867,35591,0.09892,0.04305
106.6,8.884,35609.19,0.09916,0.04315
106.8,8.9,35621.91,0.09941,0.04325
107,8.917,35631.83,0.09965,0.04335
107.2,8.934,35635.03,0.0999,0.04345
107.4,8.95,35640.02,0.10015,0.04355
107.6,8.967,35647.45,0.10039,0.04365
107.8,8.983,35650.84,0.10064,0.04375
108,9,35657.5,0.10089,0.04385
108.2,9.017,35659.51,0.10114,0.04394
108.4,9.034,35669.94,0.10139,0.04404
108.6,9.05,35675.77,0.10164,0.04414
108.8,9.067,35684.62,0.10188,0.04424
109,9.084,35695.48,0.10213,0.04435
109.2,9.1,35696.34,0.10238,0.04444
109.4,9.117,35703.65,0.10263,0.04454
109.6,9.134,35712.59,0.10287,0.04464
109.8,9.15,35721.85,0.10312,0.04474
110,9.167,35736.41,0.10337,0.04484
110.2,9.184,35743.84,0.10362,0.04494
110.4,9.2,35745.1,0.10386,0.04504
110.6,9.217,35756.67,0.10411,0.04513
110.8,9.234,35758.2,0.10436,0.04523
111,9.25,35762.98,0.10461,0.04533
111.2,9.267,35766.57,0.10486,0.04543
111.4,9.284,35777.32,0.10511,0.04553
111.6,9.3,35776.97,0.10536,0.04563
111.8,9.317,35776.35,0.10561,0.04572
112,9.334,35786.48,0.10585,0.04583
112.2,9.35,35798.45,0.1061,0.04592
112.4,9.367,35803.41,0.10636,0.04602
112.6,9.383,35805.86,0.1066,0.04612
112.8,9.4,35820.27,0.10685,0.04622
113,9.417,35818.74,0.10711,0.04632
113.2,9.434,35841.58,0.10736,0.04642
113.4,9.45,35847.74,0.10761,0.04652
113.6,9.467,35854.52,0.10786,0.04662
113.8,9.484,35858.84,0.10811,0.04672
114,9.5,35858.57,0.10837,0.04682
114.2,9.517,35866.01,0.10862,0.04692
114.4,9.534,35870.68,0.10887,0.04702
114.6,9.55,35871.6,0.10912,0.04712
114.8,9.567,35874.58,0.10938,0.04722
115,9.583,35877.62,0.10963,0.04731
115.2,9.6,35885.19,0.10988,0.04741
115.4,9.617,35880.92,0.11014,0.04751
115.6,9.634,35882.98,0.11039,0.04761
115.8,9.65,35887.46,0.11064,0.04771
116,9.667,35890.96,0.11089,0.04781
116.2,9.684,35893.57,0.11115,0.04791
116.4,9.7,35894.84,0.1114,0.04801
116.6,9.717,35902,0.11166,0.04811
116.8,9.733,35896.15,0.11191,0.04822
117,9.75,35900.98,0.11217,0.04832
117.2,9.767,35906.86,0.11242,0.04841
117.4,9.783,35909.44,0.11267,0.04851
117.6,9.8,35913.88,0.11293,0.04861
117.8,9.817,35912.8,0.11318,0.04871
118,9.833,35915.45,0.11344,0.0488
118.2,9.85,35918.57,0.1137,0.0489
118.4,9.867,35920.01,0.11395,0.049
118.6,9.883,35921.68,0.11421,0.0491
118.8,9.9,35923.79,0.11447,0.0492
119,9.917,35924.18,0.11472,0.04929
119.2,9.934,35925.95,0.11498,0.0494
119.4,9.95,35924.57,0.11523,0.0495
119.6,9.967,35925.86,0.1155,0.0496
119.8,9.984,35927.47,0.11575,0.04969
120,10,35930.16,0.11601,0.04979
120.2,10.017,35929.16,0.11627,0.04989
120.4,10.034,35930.77,0.11653,0.04999
120.6,10.05,35932.95,0.11679,0.05009
120.8,10.067,35938.98,0.11705,0.05019
121,10.084,35935.9,0.1173,0.05028
121.2,10.1,35937.64,0.11757,0.05038
121.4,10.117,35947.23,0.11783,0.05048
121.6,10.134,35945.39,0.11809,0.05058
121.8,10.15,35949,0.11835,0.05067
122,10.167,35956.54,0.11861,0.05077
122.2,10.184,35949.44,0.11887,0.05087
122.4,10.2,35969.97,0.11913,0.05097
122.6,10.217,35968.39,0.1194,0.05107
122.8,10.234,35981.64,0.11966,0.05116
123,10.25,35987.13,0.11992,0.05126
123.2,10.267,35986.05,0.12018,0.05136
123.4,10.284,35988.5,0.12045,0.05146
123.6,10.3,35996.11,0.12072,0.05155
123.8,10.317,36006.43,0.12098,0.05165
124,10.333,36024.35,0.12124,0.05175
124.2,10.35,36018.65,0.12151,0.05185
124.4,10.367,36036.82,0.12177,0.05195
124.6,10.384,36036.86,0.12203,0.05205
124.8,10.4,36042.16,0.1223,0.05214
125,10.417,36049.1,0.12256,0.05224
125.2,10.434,36067.64,0.12282,0.05234
125.4,10.45,36068.23,0.12301,0.05244
125.6,10.467,36067.08,0.12327,0.05254
125.8,10.483,36076.44,0.12353,0.05264
126,10.5,36089.09,0.1238,0.05273
126.2,10.517,36096.63,0.12407,0.05283
126.4,10.534,36097.52,0.12434,0.05293
126.6,10.55,36109.82,0.12461,0.05302
126.8,10.567,36117.29,0.12488,0.05312
127,10.584,36120.12,0.12515,0.05322
127.2,10.6,36118.47,0.12542,0.05331
127.4,10.617,36118.42,0.1257,0.05341
127.6,10.634,36126.38,0.12597,0.05351
127.8,10.65,36126.54,0.12623,0.05361
128,10.667,36141.59,0.1265,0.05371
128.2,10.683,36142.18,0.12677,0.0538
128.4,10.7,36152.55,0.12704,0.0539
128.6,10.717,36151.87,0.12732,0.05399
128.8,10.734,36156.47,0.12759,0.05409
129,10.75,36162.15,0.12787,0.05419
129.2,10.767,36165.42,0.12813,0.05429
129.4,10.784,36175.98,0.1284,0.05438
129.6,10.8,36178.9,0.12867,0.05448
129.8,10.817,36179.15,0.12892,0.05458
130,10.834,36179.3,0.12919,0.05468
130.2,10.85,36188.12,0.12945,0.05478
130.4,10.867,36194.97,0.12972,0.05487
130.6,10.884,36196.38,0.13,0.05497
130.8,10.9,36191.89,0.13027,0.05507
131,10.917,36209.72,0.13055,0.05517
131.2,10.934,36203.31,0.13081,0.05526
131.4,10.95,36211.4,0.13109,0.05536
131.6,10.967,36222.02,0.13137,0.05546
131.8,10.984,36224.07,0.13165,0.05555
132,11,36222.19,0.13193,0.05565
132.2,11.017,36223.55,0.1322,0.05575
132.4,11.034,36230.73,0.13248,0.05585
132.6,11.05,36234.71,0.13275,0.05594
132.8,11.067,36232.72,0.13303,0.05604
133,11.083,36237.36,0.1333,0.05614
133.2,11.1,36240.17,0.13357,0.05623
133.4,11.117,36244.62,0.13384,0.05633
133.6,11.134,36250.76,0.13412,0.05643
133.8,11.15,36253.1,0.1344,0.05652
134,11.167,36256.93,0.13467,0.05662
134.2,11.184,36255.5,0.13495,0.05672
134.4,11.2,36256.28,0.13523,0.05681
134.6,11.217,36262.45,0.13551,0.05691
134.8,11.233,36262.6,0.13578,0.057
135,11.25,36268.73,0.13606,0.0571
135.2,11.267,36273.75,0.13634,0.0572
135.4,11.284,36276.38,0.13662,0.05729
135.6,11.3,36277.65,0.1369,0.05739
135.8,11.317,36290.73,0.13718,0.05749
136,11.334,36293.41,0.13745,0.05758
136.2,11.35,36290.88,0.13773,0.05768
136.4,11.367,36300.95,0.13801,0.05777
136.6,11.384,36301.06,0.13829,0.05787
136.8,11.4,36308.32,0.13856,0.05797
137,11.417,36309.97,0.13884,0.05806
137.2,11.434,36313.98,0.13912,0.05816
137.4,11.45,36306.79,0.13939,0.05826
137.6,11.467,36333.03,0.13968,0.05835
137.8,11.483,36317.08,0.13995,0.05845
138,11.5,36332.3,0.14022,0.05854
138.2,11.517,36314.57,0.14051,0.05864
138.4,11.533,36332.93,0.14078,0.05873
138.6,11.55,36331.67,0.14106,0.05883
138.8,11.567,36348.84,0.14134,0.05892
139,11.584,36348.57,0.14161,0.05902
139.2,11.6,36358.21,0.1419,0.05912
139.4,11.617,36358.79,0.14218,0.05921
139.6,11.634,36364,0.14246,0.0593
139.8,11.65,36370.02,0.14274,0.0594
140,11.667,36365.62,0.14302,0.05949
140.2,11.684,36374.12,0.1433,0.05959
140.4,11.7,36376,0.14358,0.05968
140.6,11.717,36375.47,0.14386,0.05978
140.8,11.734,36378.38,0.14414,0.05987
141,11.75,36382.68,0.14442,0.05997
141.2,11.767,36390.77,0.14471,0.06007
141.4,11.784,36390.31,0.14499,0.06017
141.6,11.8,36394.47,0.14527,0.06026
141.8,11.817,36396.25,0.14556,0.06036
142,11.834,36398.4,0.14585,0.06045
142.2,11.85,36403.91,0.14613,0.06055
142.4,11.867,36410.94,0.14642,0.06064
142.6,11.884,36408.6,0.1467,0.06074
142.8,11.9,36408.2,0.14699,0.06083
143,11.917,36407.96,0.14727,0.06092
143.2,11.934,36416.39,0.14756,0.06102
143.4,11.95,36411.85,0.14784,0.06112
143.6,11.967,36414.71,0.14813,0.06122
143.8,11.984,36414.22,0.14842,0.06131
144,12,36414.76,0.14871,0.0614
144.2,12.017,36420.82,0.14899,0.06149
144.4,12.033,36421.6,0.14928,0.06159
144.6,12.05,36420.78,0.14957,0.06168
144.8,12.067,36421.94,0.14986,0.06178
145,12.084,36423.09,0.15015,0.06187
145.2,12.1,36423.32,0.15044,0.06196
145.4,12.117,36423.42,0.15072,0.06206
145.6,12.134,36425.29,0.15101,0.06215
145.8,12.15,36424.32,0.1513,0.06224
146,12.167,36422.85,0.15159,0.06234
146.2,12.184,36429.05,0.15188,0.06243
146.4,12.2,36425.1,0.15217,0.06252
146.6,12.217,36428.41,0.15245,0.06262
146.8,12.234,36428.38,0.15275,0.06271
147,12.25,36430.23,0.15303,0.0628
147.2,12.267,36430.67,0.15332,0.0629
147.4,12.284,36430.05,0.15362,0.06299
147.6,12.3,36428.38,0.15391,0.06308
147.8,12.317,36433.99,0.15419,0.06317
148,12.334,36429.72,0.15448,0.06326
148.2,12.35,36430.66,0.15477,0.06336
148.4,12.367,36432.59,0.15506,0.06345
148.6,12.384,36433.46,0.15535,0.06354
148.8,12.4,36432.53,0.15564,0.06363
149,12.417,36432.99,0.15594,0.06372
149.2,12.434,36434.26,0.15623,0.06382
149.4,12.45,36432.7,0.15652,0.06391
149.6,12.467,36434.55,0.15681,0.064
149.8,12.484,36437.34,0.15711,0.06409
150,12.5,36435.92,0.1574,0.06418
150.2,12.517,36435.38,0.15769,0.06428
150.4,12.534,36436.08,0.15799,0.06437
150.6,12.55,36435.93,0.15828,0.06446
150.8,12.567,36436.67,0.15857,0.06456
151,12.583,36435.38,0.15887,0.06465
151.2,12.6,36434.96,0.15916,0.06474
151.4,12.617,36437.87,0.15945,0.06483
151.6,12.634,36438.09,0.15975,0.06492
151.8,12.65,36437.71,0.16004,0.06502
152,12.667,36440.54,0.16034,0.06511
152.2,12.684,36442.38,0.16064,0.0652
152.4,12.7,36442.74,0.16094,0.06529
152.6,12.717,36438.92,0.16123,0.06538
152.8,12.733,36442.14,0.16153,0.06547
153,12.75,36439.62,0.16183,0.06556
153.2,12.767,36442.92,0.16212,0.06565
153.4,12.784,36441.7,0.16242,0.06574
153.6,12.8,36444.61,0.16272,0.06583
153.8,12.817,36445.52,0.16301,0.06592
154,12.834,36446.55,0.16331,0.06601
154.2,12.85,36445.74,0.16361,0.0661
154.4,12.867,36447.36,0.16391,0.06619
154.6,12.883,36445.62,0.16421,0.06629
154.8,12.9,36448.93,0.1645,0.06638
155,12.917,36448.55,0.1648,0.06647
155.2,12.933,36448.96,0.1651,0.06655
155.4,12.95,36449.85,0.16541,0.06664
155.6,12.967,36445.82,0.16571,0.06673
155.8,12.984,36447.59,0.16601,0.06682
156,13,36449.14,0.16631,0.06691
156.2,13.017,36448.59,0.16661,0.06699
156.4,13.034,36452.93,0.16691,0.06709
156.6,13.05,36446.36,0.16721,0.06717
156.8,13.067,36450.2,0.16751,0.06726
157,13.084,36453.04,0.16781,0.06735
157.2,13.1,36450.55,0.16812,0.06744
157.4,13.117,36452.98,0.16842,0.06753
157.6,13.134,36450.73,0.16873,0.06762
157.8,13.15,36447.79,0.16903,0.0677
158,13.167,36449.81,0.16934,0.06779
158.2,13.183,36447.8,0.16964,0.06788
158.4,13.2,36449.59,0.16995,0.06797
158.6,13.217,36455.06,0.17025,0.06805
158.8,13.234,36450.72,0.17056,0.06814
159,13.25,36453.04,0.17086,0.06824
159.2,13.267,36453.33,0.17117,0.06832
159.4,13.284,36453.87,0.17148,0.06841
159.6,13.3,36453.98,0.17179,0.0685
159.8,13.317,36448.96,0.17209,0.06859
160,13.334,36452.34,0.1724,0.06867
160.2,13.35,36451.18,0.17271,0.06876
160.4,13.367,36448.16,0.17302,0.06886
160.6,13.384,36457.16,0.17333,0.06894
160.8,13.4,36451.06,0.17364,0.06903
161,13.417,36452.12,0.17395,0.06911
161.2,13.434,36448.76,0.17426,0.0692
161.4,13.45,36453.96,0.17457,0.06928
161.6,13.467,36451.79,0.17489,0.06937
161.8,13.484,36449.55,0.1752,0.06946
162,13.5,36454.73,0.17551,0.06954
162.2,13.517,36453.98,0.17582,0.06963
162.4,13.534,36452.27,0.17614,0.06972
162.6,13.55,36456.82,0.17645,0.0698
162.8,13.567,36454.43,0.17676,0.06989
163,13.584,36454.53,0.17708,0.06997
163.2,13.6,36453.07,0.17739,0.07006
163.4,13.617,36455.48,0.17771,0.07014
163.6,13.634,36452.25,0.17802,0.07023
163.8,13.65,36454.4,0.17833,0.07032
164,13.667,36454.09,0.17865,0.0704
164.2,13.684,36454.68,0.17896,0.07048
164.4,13.7,36456.18,0.17928,0.07057
164.6,13.717,36452.64,0.1796,0.07065
164.8,13.733,36453.14,0.17992,0.07074
165,13.75,36457.07,0.18023,0.07082
165.2,13.767,36454,0.18056,0.07091
165.4,13.784,36460.24,0.18087,0.07099
165.6,13.8,36451.96,0.18119,0.07108
165.8,13.817,36454.68,0.18151,0.07116
166,13.834,36458.05,0.18183,0.07124
166.2,13.85,36454.84,0.18216,0.07133
166.4,13.867,36456.17,0.18248,0.07141
166.6,13.884,36452.42,0.18279,0.07149
166.8,13.9,36457.73,0.18312,0.07157
167,13.917,36454,0.18344,0.07166
167.2,13.934,36453.82,0.18376,0.07174
167.4,13.95,36452.52,0.18408,0.07182
167.6,13.967,36454.78,0.1844,0.0719
167.8,13.984,36454.81,0.18473,0.07199
168,14,36452.23,0.18506,0.07207
168.2,14.017,36454.44,0.18538,0.07216
168.4,14.034,36451.15,0.18571,0.07224
168.6,14.05,36451.66,0.18603,0.07232
168.8,14.067,36451.18,0.18636,0.0724
169,14.084,36452.97,0.18668,0.07248
169.2,14.1,36449.74,0.187,0.07257
169.4,14.117,36451.94,0.18733,0.07264
169.6,14.134,36454.79,0.18766,0.07273
169.8,14.15,36452.21,0.18799,0.07281
170,14.167,36454.67,0.18832,0.07289
170.2,14.184,36452.27,0.18865,0.07297
170.4,14.2,36455.72,0.18898,0.07305
170.6,14.217,36451.91,0.18931,0.07313
170.8,14.233,36452.77,0.18964,0.07321
171,14.25,36455.23,0.18997,0.07329
171.2,14.267,36448.58,0.1903,0.07337
171.4,14.284,36455.48,0.19064,0.07345
171.6,14.3,36452.07,0.19097,0.07353
171.8,14.317,36450.46,0.1913,0.07361
172,14.334,36451.7,0.19164,0.07368
172.2,14.35,36451.88,0.19198,0.07376
172.4,14.367,36449.02,0.19231,0.07384
172.6,14.384,36451.8,0.19265,0.07392
172.8,14.4,36448.39,0.19299,0.074
173,14.417,36449.55,0.19333,0.07408
173.2,14.433,36451.27,0.19367,0.07416
173.4,14.45,36445.7,0.19401,0.07424
173.6,14.467,36447.71,0.19435,0.07431
173.8,14.484,36450.77,0.19469,0.07439
174,14.5,36448.17,0.19503,0.07447
174.2,14.517,36448.31,0.19537,0.07454
174.4,14.534,36446.86,0.19571,0.07462
174.6,14.55,36449.7,0.19605,0.0747
174.8,14.567,36446.96,0.19639,0.07477
175,14.584,36445.31,0.19673,0.07485
175.2,14.6,36443.61,0.19708,0.07493
175.4,14.617,36448.95,0.19743,0.075
175.6,14.633,36442.82,0.19777,0.07508
175.8,14.65,36448.86,0.19812,0.07515
176,14.667,36444.3,0.19847,0.07522
176.2,14.684,36441.23,0.19882,0.0753
176.4,14.7,36441.08,0.19916,0.07537
176.6,14.717,36442.07,0.19951,0.07545
176.8,14.734,36442.78,0.19986,0.07552
177,14.75,36443.6,0.20021,0.07559
177.2,14.767,36442,0.20056,0.07566
177.4,14.784,36442.91,0.20091,0.07574
177.6,14.8,36440.54,0.20126,0.07581
177.8,14.817,36441.68,0.20161,0.07588
178,14.834,36441.35,0.20197,0.07596
178.2,14.85,36441.57,0.20232,0.07603
178.4,14.867,36440.04,0.20268,0.0761
178.6,14.884,36439.08,0.20304,0.07618
178.8,14.9,36438.57,0.2034,0.07625
179,14.917,36439.93,0.20376,0.07632
179.2,14.934,36435.65,0.20412,0.0764
179.4,14.95,36438.53,0.20447,0.07646
179.6,14.967,36438.17,0.20483,0.07653
179.8,14.983,36436.79,0.20519,0.0766
180,15,36436.75,0.20555,0.07667
180.2,15.017,36435.78,0.20591,0.07674
180.4,15.034,36434.7,0.20628,0.07681
180.6,15.05,36437.14,0.20663,0.07688
180.8,15.067,36435.37,0.207,0.07695
181,15.084,36436.82,0.20737,0.07702
181.2,15.1,36434.48,0.20774,0.07709
181.4,15.117,36433.76,0.2081,0.07716
181.6,15.134,36432.78,0.20846,0.07723
181.8,15.15,36434.57,0.20883,0.07729
182,15.167,36433.82,0.20919,0.07736
182.2,15.184,36433.05,0.20956,0.07744
182.4,15.2,36432.52,0.20992,0.0775
182.6,15.217,36432.12,0.21029,0.07757
182.8,15.234,36432.51,0.21066,0.07764
183,15.25,36432.17,0.21103,0.07771
183.2,15.267,36434.25,0.2114,0.07777
183.4,15.284,36431.63,0.21177,0.07784
183.6,15.3,36428.76,0.21215,0.0779
183.8,15.317,36429.66,0.2125,0.07797
184,15.334,36431.06,0.21288,0.07803
184.2,15.35,36428.92,0.21326,0.0781
184.4,15.367,36429.09,0.21364,0.07816
184.6,15.383,36424.34,0.21401,0.07822
184.8,15.4,36426.85,0.21438,0.07829
185,15.417,36426.59,0.21476,0.07835
185.2,15.433,36425.64,0.21513,0.07841
185.4,15.45,36425.44,0.21552,0.07847
185.6,15.467,36425.26,0.2159,0.07854
185.8,15.483,36423.77,0.21628,0.0786
186,15.5,36424.4,0.21666,0.07866
186.2,15.517,36424.28,0.21705,0.07872
186.4,15.534,36423.61,0.21743,0.07878
186.6,15.55,36420.64,0.21782,0.07885
186.8,15.567,36422.2,0.2182,0.07891
187,15.584,36422.86,0.21859,0.07897
187.2,15.6,36418.09,0.21898,0.07903
187.4,15.617,36420.46,0.21936,0.07909
187.6,15.634,36418.57,0.21975,0.07915
187.8,15.65,36415.1,0.22014,0.07921
188,15.667,36413.23,0.22053,0.07927
188.2,15.684,36413.03,0.22093,0.07933
188.4,15.7,36415.96,0.22132,0.07939
188.6,15.717,36406.66,0.22172,0.07945
188.8,15.734,36405.6,0.22211,0.07951
189,15.75,36399.11,0.2225,0.07956
189.2,15.767,36407.5,0.2229,0.07962
189.4,15.783,36397.98,0.2233,0.07968
189.6,15.8,36391.07,0.2237,0.07973
189.8,15.817,36396.05,0.2241,0.07979
190,15.834,36400.61,0.22449,0.07985
190.2,15.85,36391.04,0.22489,0.0799
190.4,15.867,36395.57,0.22529,0.07996
190.6,15.883,36383.52,0.2257,0.08001
190.8,15.9,36387.62,0.2261,0.08007
191,15.917,36383.75,0.22651,0.08012
191.2,15.933,36378.77,0.22692,0.08017
191.4,15.95,36378.52,0.22733,0.08023
191.6,15.967,36367.28,0.22773,0.08028
191.8,15.984,36359.83,0.22814,0.08034
192,16,36361.18,0.22855,0.08039
192.2,16.017,36351.93,0.22896,0.08044
192.4,16.034,36360.29,0.22937,0.08049
192.6,16.05,36356.1,0.22978,0.08054
192.8,16.067,36346.05,0.2302,0.0806
193,16.084,36342.61,0.23062,0.08065
193.2,16.1,36339.82,0.23103,0.0807
193.4,16.117,36345.1,0.23145,0.08075
193.6,16.134,36334.04,0.23188,0.0808
193.8,16.15,36328.45,0.2323,0.08086
194,16.167,36317.09,0.23272,0.0809
194.2,16.184,36320.62,0.23314,0.08095
194.4,16.2,36308.31,0.23357,0.081
194.6,16.217,36319.36,0.23399,0.08105
194.8,16.234,36306.02,0.23442,0.0811
195,16.25,36308.1,0.23485,0.08115
195.2,16.267,36292.16,0.23527,0.0812
195.4,16.283,36297.25,0.2357,0.08124
195.6,16.3,36302.63,0.23613,0.08129
195.8,16.317,36290.98,0.23656,0.08134
196,16.333,36281.15,0.237,0.08138
196.2,16.35,36285.82,0.23743,0.08143
196.4,16.367,36278.16,0.23787,0.08147
196.6,16.383,36272.95,0.2383,0.08152
196.8,16.4,36274.84,0.23874,0.08156
197,16.417,36263.48,0.23918,0.08161
197.2,16.434,36263.65,0.23962,0.08165
197.4,16.45,36261,0.24006,0.08169
197.6,16.467,36255.93,0.2405,0.08174
197.8,16.483,36258.02,0.24094,0.08178
198,16.5,36257.09,0.24138,0.08182
198.2,16.517,36249.26,0.24182,0.08186
198.4,16.534,36248.82,0.24227,0.08191
198.6,16.55,36250.82,0.24272,0.08195
198.8,16.567,36247.77,0.24317,0.08199
199,16.583,36242.88,0.24363,0.08203
199.2,16.6,36235.09,0.24408,0.08207
199.4,16.617,36238.05,0.24455,0.08211
199.6,16.634,36226.13,0.245,0.08215
199.8,16.65,36226.21,0.24546,0.08218
200,16.667,36226.72,0.24593,0.08222
200.2,16.684,36223.91,0.24639,0.08226
200.4,16.7,36218.9,0.24685,0.0823
200.6,16.717,36219.01,0.24732,0.08234
200.8,16.734,36205.19,0.24779,0.08237
201,16.75,36210.77,0.24826,0.08241
201.2,16.767,36204.93,0.24873,0.08245
201.4,16.783,36194.52,0.24922,0.08248
201.6,16.8,36202.91,0.24969,0.08252
201.8,16.817,36185.2,0.25016,0.08255
202,16.834,36188.62,0.25064,0.08259
202.2,16.85,36187.25,0.25113,0.08262
202.4,16.867,36173.82,0.25161,0.08266
202.6,16.884,36172.07,0.25209,0.08269
202.8,16.9,36165.46,0.25258,0.08272
203,16.917,36157.8,0.25306,0.08276
203.2,16.934,36159.42,0.25355,0.08279
203.4,16.95,36149.27,0.25403,0.08282
203.6,16.967,36148.31,0.25452,0.08285
203.8,16.984,36144.45,0.25501,0.08288
204,17,36139.18,0.2555,0.08291
204.2,17.017,36131.41,0.256,0.08294
204.4,17.034,36136.3,0.25649,0.08297
204.6,17.05,36119.62,0.25699,0.083
204.8,17.067,36123.2,0.25749,0.08303
205,17.083,36109.59,0.25798,0.08306
205.2,17.1,36112.93,0.25848,0.08309
205.4,17.117,36108.87,0.25899,0.08311
205.6,17.133,36101.81,0.25949,0.08314
205.8,17.15,36097.71,0.26,0.08317
206,17.167,36092.73,0.2605,0.0832
206.2,17.184,36085.89,0.26101,0.08322
206.4,17.2,36078.15,0.26152,0.08325
206.6,17.217,36075.95,0.26204,0.08328
206.8,17.233,36059.99,0.26255,0.0833
207,17.25,36055.75,0.26307,0.08333
207.2,17.267,36051.68,0.26358,0.08335
207.4,17.284,36036.61,0.2641,0.08338
207.6,17.3,36035.97,0.26462,0.0834
207.8,17.317,36032.55,0.26515,0.08342
208,17.334,36012.88,0.26567,0.08345
208.2,17.35,36004.33,0.26619,0.08347
208.4,17.367,35996.64,0.26671,0.08349
208.6,17.384,35998.2,0.26725,0.08351
208.8,17.4,35984.87,0.26777,0.08353
209,17.417,35973.11,0.26831,0.08355
209.2,17.434,35965.19,0.26885,0.08358
209.4,17.45,35962.39,0.26938,0.0836
209.6,17.467,35956.54,0.26992,0.08362
209.8,17.484,35955.58,0.27046,0.08364
210,17.5,35950.19,0.271,0.08366
210.2,17.517,35941.7,0.27154,0.08367
210.4,17.534,35936.58,0.27208,0.08369
210.6,17.55,35936.85,0.27262,0.08371
210.8,17.567,35936.34,0.27317,0.08373
211,17.584,35935.14,0.27372,0.08374
211.2,17.6,35930.61,0.27427,0.08376
211.4,17.617,35930.74,0.27482,0.08378
211.6,17.633,35931.21,0.27538,0.0838
211.8,17.65,35930.45,0.27594,0.08381
212,17.667,35926.34,0.27649,0.08383
212.2,17.684,35924.67,0.27705,0.08384
212.4,17.7,35923.9,0.2776,0.08386
212.6,17.717,35920.71,0.27816,0.08387
212.8,17.734,35922.69,0.27873,0.08389
213,17.75,35919.91,0.2793,0.0839
213.2,17.767,35916.69,0.27986,0.08391
213.4,17.784,35913.91,0.28043,0.08393
213.6,17.8,35911.31,0.28101,0.08394
213.8,17.817,35906.93,0.28158,0.08395
214,17.834,35904.43,0.28216,0.08396
214.2,17.85,35901.99,0.28273,0.08398
214.4,17.867,35899.4,0.28332,0.08399
214.6,17.884,35904.24,0.2839,0.084
214.8,17.9,35889,0.28448,0.08401
215,17.917,35893.56,0.28507,0.08402
215.2,17.934,35881.71,0.28566,0.08403
215.4,17.95,35886,0.28624,0.08404
215.6,17.967,35876.24,0.28683,0.08405
215.8,17.984,35876.19,0.28742,0.08406
216,18,35869.13,0.28802,0.08407
216.2,18.017,35870.16,0.28861,0.08408
216.4,18.033,35863.61,0.28921,0.08409
216.6,18.05,35855.02,0.28981,0.0841
216.8,18.067,35849.87,0.29041,0.08411
217,18.083,35840.32,0.29101,0.08412
217.2,18.1,35830.18,0.29163,0.08413
217.4,18.117,35814.57,0.29223,0.08413
217.6,18.134,35804.75,0.29283,0.08414
217.8,18.15,35787.3,0.29344,0.08415
218,18.167,35782.37,0.29405,0.08416
218.2,18.183,35771.63,0.29466,0.08416
218.4,18.2,35775.21,0.29527,0.08417
218.6,18.217,35757.98,0.29588,0.08418
218.8,18.234,35755.12,0.2965,0.08418
219,18.25,35742.16,0.29711,0.08419
219.2,18.267,35733.64,0.29774,0.08419
219.4,18.284,35726.85,0.29836,0.0842
219.6,18.3,35712.05,0.29898,0.0842
219.8,18.317,35696.43,0.2996,0.08421
220,18.334,35691.97,0.30022,0.08422
220.2,18.35,35675.19,0.30085,0.08422
220.4,18.367,35676.17,0.30148,0.08423
220.6,18.383,35655.93,0.30211,0.08423
220.8,18.4,35649.23,0.30273,0.08423
221,18.417,35642.91,0.30336,0.08424
221.2,18.434,35633.78,0.30399,0.08424
221.4,18.45,35627.22,0.30462,0.08425
221.6,18.467,35610.9,0.30526,0.08425
221.8,18.484,35601.99,0.3059,0.08425
222,18.5,35582.28,0.30654,0.08426
222.2,18.517,35559.84,0.30718,0.08426
222.4,18.534,35534.42,0.30782,0.08426
222.6,18.55,35514.21,0.30847,0.08427
222.8,18.567,35491.15,0.3091,0.08427
223,18.584,35470.37,0.30974,0.08427
223.2,18.6,35459.17,0.31038,0.08427
223.4,18.617,35447.49,0.31103,0.08428
223.6,18.634,35445.94,0.31168,0.08428
223.8,18.65,35436.91,0.31233,0.08428
224,18.667,35429.59,0.31297,0.08428
224.2,18.684,35419.86,0.31363,0.08429
224.4,18.7,35411.96,0.31427,0.08429
224.6,18.717,35405.53,0.31492,0.08429
224.8,18.733,35401.81,0.31558,0.08429
225,18.75,35388.37,0.31623,0.08429
225.2,18.767,35383.04,0.31688,0.0843
225.4,18.783,35364.64,0.31754,0.0843
225.6,18.8,35352.12,0.31819,0.0843
225.8,18.817,35334.04,0.31885,0.0843
226,18.834,35309.46,0.3195,0.0843
226.2,18.85,35293.05,0.32015,0.0843
226.4,18.867,35270.08,0.32081,0.0843
226.6,18.884,35240.88,0.32145,0.08431
226.8,18.9,35222.25,0.32212,0.08431
227,18.917,35210.38,0.32277,0.08431
227.2,18.933,35187.99,0.32343,0.08431
227.4,18.95,35170.63,0.3241,0.08431
227.6,18.967,35161.79,0.32476,0.08431
227.8,18.984,35141.68,0.32542,0.08431
228,19,35126.87,0.32609,0.08431
228.2,19.017,35104.92,0.32675,0.08431
228.4,19.034,35095.71,0.3274,0.08431
228.6,19.05,35089.51,0.32806,0.08431
228.8,19.067,35085.21,0.32872,0.08431
229,19.084,35078.34,0.32939,0.08432
229.2,19.1,35059.46,0.33006,0.08432
229.4,19.117,35036.91,0.33072,0.08431
229.6,19.134,35022.39,0.33138,0.08432
229.8,19.15,34994.8,0.33205,0.08432
230,19.167,34981.96,0.33272,0.08432
230.2,19.184,34964.62,0.33339,0.08432
230.4,19.2,34954.71,0.33406,0.08432
230.6,19.217,34944.4,0.33472,0.08432
230.8,19.234,34930.43,0.33539,0.08432
231,19.25,34920.23,0.33606,0.08432
231.2,19.267,34902.95,0.33672,0.08432
231.4,19.283,34890.07,0.33739,0.08432
231.6,19.3,34878.08,0.33806,0.08432
231.8,19.317,34866.13,0.33873,0.08432
232,19.333,34843.23,0.33939,0.08432
232.2,19.35,34819.41,0.34006,0.08432
232.4,19.367,34784.37,0.34074,0.08432
232.6,19.383,34739.78,0.34141,0.08432
232.8,19.4,34723.79,0.34208,0.08432
233,19.417,34688.52,0.34274,0.08432
233.2,19.434,34665.51,0.34341,0.08432
233.4,19.45,34633.15,0.34408,0.08432
233.6,19.467,34595.88,0.34474,0.08432
233.8,19.484,34562.61,0.34541,0.08432
234,19.5,34551.52,0.34608,0.08432
234.2,19.517,34512.88,0.34675,0.08432
234.4,19.534,34487.77,0.34742,0.08432
234.6,19.55,34443.22,0.3481,0.08432
234.8,19.567,34412.8,0.34877,0.08432
235,19.584,34403.41,0.34944,0.08432
235.2,19.6,34383.33,0.35012,0.08432
235.4,19.617,34374.34,0.35079,0.08432
235.6,19.634,34373.23,0.35147,0.08432
235.8,19.65,34372.33,0.35214,0.08432
236,19.667,34372.02,0.35281,0.08432
236.2,19.684,34371.68,0.35348,0.08432
236.4,19.7,34361.6,0.35416,0.08432
236.6,19.717,34350.44,0.35484,0.08432
236.8,19.734,34316.61,0.35552,0.08432
237,19.75,34280.86,0.35618,0.08431
237.2,19.767,34258.91,0.35686,0.08432
237.4,19.783,34229.46,0.35753,0.08432
237.6,19.8,34204.7,0.35822,0.08431
237.8,19.817,34148.84,0.3589,0.08431
238,19.834,34110.02,0.35957,0.08431
238.2,19.85,34069.21,0.36025,0.08431
238.4,19.867,34038.57,0.36092,0.08431
238.6,19.883,33987.95,0.3616,0.08431
238.8,19.9,33946.54,0.36227,0.08431
239,19.917,33912.06,0.36294,0.08431
239.2,19.934,33898.91,0.36361,0.08431
239.4,19.95,33880.56,0.36429,0.08431
239.6,19.967,33858.31,0.36496,0.08431
239.8,19.984,33837.06,0.36564,0.08431
240,20,33797.62,0.36632,0.08431
240.2,20.017,33775.46,0.36699,0.08431
240.4,20.034,33752.23,0.36767,0.08431
240.6,20.05,33717.48,0.36835,0.08431
240.8,20.067,33677.91,0.36903,0.08431
241,20.084,33663.06,0.3697,0.08431
241.2,20.1,33646.24,0.37036,0.08431
241.4,20.117,33631.09,0.37104,0.08431
241.6,20.134,33605.69,0.37172,0.08431
241.8,20.15,33588.5,0.3724,0.08431
242,20.167,33565.46,0.37308,0.08431
242.2,20.184,33512.56,0.37375,0.08431
242.4,20.2,33462.15,0.37443,0.08431
242.6,20.217,33418.28,0.37511,0.08431
242.8,20.234,33393.45,0.37579,0.08431
243,20.25,33376.68,0.37647,0.0843
243.2,20.267,33363.09,0.37716,0.0843
243.4,20.284,33338.08,0.37783,0.0843
243.6,20.3,33313.8,0.37851,0.0843
243.8,20.317,33260.55,0.37919,0.0843
244,20.333,33208.68,0.37987,0.0843
244.2,20.35,33167.27,0.38055,0.0843
244.4,20.367,33132.48,0.38123,0.0843
244.6,20.384,33088.9,0.38191,0.0843
244.8,20.4,33017.95,0.38259,0.0843
245,20.417,32976.66,0.38327,0.0843
245.2,20.433,32949.66,0.38396,0.0843
245.4,20.45,32903.45,0.38465,0.0843
245.6,20.467,32875.81,0.38533,0.0843
245.8,20.484,32870.55,0.38601,0.0843
246,20.5,32869.64,0.38669,0.0843
246.2,20.517,32869.55,0.38737,0.08429
246.4,20.534,32867.09,0.38805,0.0843
246.6,20.55,32851.19,0.38873,0.08429
246.8,20.567,32800.01,0.38941,0.08429
247,20.584,32713.73,0.39009,0.08429
247.2,20.6,32657.88,0.39078,0.08429
247.4,20.617,32619.79,0.39146,0.08429
247.6,20.634,32561.88,0.39214,0.08429
247.8,20.65,32522.79,0.39283,0.08429
248,20.667,32474.14,0.39351,0.08429
248.2,20.683,32403.33,0.39419,0.08429
248.4,20.7,32351.14,0.39488,0.08429
248.6,20.717,32303.82,0.39556,0.08429
248.8,20.734,32275.8,0.39624,0.08429
249,20.75,32259.58,0.39693,0.08428
249.2,20.767,32252.65,0.39761,0.08429
249.4,20.784,32233.08,0.3983,0.08428
249.6,20.8,32191.25,0.39899,0.08428
249.8,20.817,32162.5,0.39967,0.08428
250,20.834,32136.66,0.40035,0.08428
250.2,20.85,32085.53,0.40104,0.08428
250.4,20.867,32035.29,0.40173,0.08428
250.6,20.884,31979.97,0.40242,0.08428
250.8,20.9,31908.32,0.40311,0.08428
251,20.917,31858.7,0.40379,0.08428
251.2,20.934,31831.3,0.40448,0.08428
251.4,20.95,31795.97,0.40516,0.08428
251.6,20.967,31772.24,0.40586,0.08428
251.8,20.984,31738.4,0.40654,0.08428
252,21,31659.88,0.40723,0.08427
252.2,21.017,31587.44,0.40792,0.08427
252.4,21.034,31541.63,0.4086,0.08427
252.6,21.05,31484.87,0.4093,0.08427
252.8,21.067,31459.51,0.40999,0.08427
253,21.084,31417.01,0.41068,0.08427
253.2,21.1,31381.28,0.41137,0.08427
253.4,21.117,31368.26,0.41206,0.08427
253.6,21.134,31345.45,0.41275,0.08427
253.8,21.15,31302.46,0.41345,0.08427
254,21.167,31251.62,0.41413,0.08427
254.2,21.184,31170.19,0.41481,0.08426
254.4,21.2,31109.66,0.4155,0.08426
254.6,21.217,31054.34,0.41619,0.08426
254.8,21.234,30970.02,0.41688,0.08426
255,21.25,30903.35,0.41757,0.08426
255.2,21.267,30824.24,0.41826,0.08426
255.4,21.284,30779.2,0.41894,0.08426
255.6,21.3,30750.7,0.41964,0.08426
255.8,21.317,30745.41,0.42033,0.08426
256,21.334,30740.2,0.42103,0.08426
256.2,21.35,30685,0.42173,0.08426
256.4,21.367,30619.97,0.42242,0.08425
256.6,21.384,30575.86,0.42311,0.08425
256.8,21.4,30513.28,0.4238,0.08425
257,21.417,30442.31,0.42449,0.08425
257.2,21.434,30333.8,0.42518,0.08425
257.4,21.45,30294.86,0.42587,0.08425
257.6,21.467,30260.15,0.42657,0.08425
257.8,21.483,30213.7,0.42727,0.08425
258,21.5,30180.09,0.42797,0.08425
258.2,21.517,30100.33,0.42867,0.08424
258.4,21.534,30042.88,0.42936,0.08424
258.6,21.55,29989.39,0.43006,0.08424
258.8,21.567,29954.65,0.43076,0.08424
259,21.583,29882.05,0.43146,0.08424
259.2,21.6,29810.87,0.43215,0.08424
259.4,21.617,29787.03,0.43285,0.08424
259.6,21.634,29753.6,0.43355,0.08424
259.8,21.65,29691.57,0.43424,0.08424
260,21.667,29580.1,0.43494,0.08423
260.2,21.684,29504.53,0.43564,0.08423
260.4,21.7,29426.37,0.43633,0.08423
260.6,21.717,29376.82,0.43704,0.08423
260.8,21.734,29287.69,0.43774,0.08423
261,21.75,29250.74,0.43844,0.08423
261.2,21.767,29216.86,0.43914,0.08423
261.4,21.784,29193.48,0.43985,0.08422
261.6,21.8,29112.53,0.44055,0.08422
261.8,21.817,29058.05,0.44124,0.08422
262,21.834,28955.83,0.44195,0.08422
262.2,21.85,28883.52,0.44265,0.08422
262.4,21.867,28779.35,0.44335,0.08422
262.6,21.884,28719.31,0.44405,0.08422
262.8,21.9,28693.12,0.44475,0.08421
263,21.917,28677.39,0.44545,0.08421
263.2,21.934,28583.44,0.44616,0.08421
263.4,21.95,28510.04,0.44687,0.08421
263.6,21.967,28410.29,0.44758,0.08421
263.8,21.984,28344.95,0.44828,0.08421
264,22,28268.81,0.44899,0.0842
264.2,22.017,28223.27,0.44969,0.0842
264.4,22.033,28150.88,0.4504,0.0842
264.6,22.05,28073.76,0.45112,0.0842
264.8,22.067,27992.46,0.45182,0.0842
265,22.084,27921.11,0.45253,0.0842
265.2,22.1,27850.68,0.45323,0.0842
265.4,22.117,27724.09,0.45394,0.08419
265.6,22.134,27691.54,0.45465,0.08419
265.8,22.15,27665.62,0.45537,0.08419
266,22.167,27585.62,0.45608,0.08419
266.2,22.184,27500.31,0.45679,0.08419
266.4,22.2,27364.34,0.45751,0.08419
266.6,22.217,27277.52,0.45822,0.08418
266.8,22.234,27206.19,0.45894,0.08418
267,22.25,27185.43,0.45964,0.08418
267.2,22.267,27123.38,0.46035,0.08418
267.4,22.284,26976.6,0.46106,0.08418
267.6,22.3,26903.34,0.46178,0.08417
267.8,22.317,26824.49,0.46248,0.08417
268,22.334,26700.69,0.4632,0.08417
268.2,22.35,26637.34,0.46391,0.08417
268.4,22.367,26609.55,0.46463,0.08416
268.6,22.384,26503.57,0.46535,0.08416
268.8,22.4,26411.98,0.46608,0.08416
269,22.417,26286.37,0.4668,0.08416
269.2,22.434,26164.49,0.46751,0.08416
269.4,22.45,26119.51,0.46823,0.08415
269.6,22.467,26085.91,0.46894,0.08415
269.8,22.484,25961.71,0.46965,0.08415
270,22.5,25856.92,0.47037,0.08415
270.2,22.517,25768.22,0.47109,0.08415
270.4,22.534,25678.09,0.47182,0.08414
270.6,22.55,25590.15,0.47254,0.08414
270.8,22.567,25473.58,0.47327,0.08414
271,22.584,25376.81,0.474,0.08414
271.2,22.6,25255.7,0.47474,0.08413
271.4,22.617,25145.3,0.47545,0.08413
271.6,22.634,25112.37,0.47619,0.08413
271.8,22.65,24981.73,0.47692,0.08412
272,22.667,24670.48,0.47774,0.08412
272.052,22.672,13285.59,0.48523,0.08367