File: Labs/Lab 2 Tension/A36 Steel Sample 3.csv
Time (s),Extension (mm),Load (N),Axial Strain (mm/mm),Transverse Strain (mm/mm)
0,0,-0.25,0,0
0.2,0.013,394.49,0.00002,0.00001
0.4,0.034,744.6,0.00007,0.00003
0.6,0.05,800.45,0.0001,0.00003
0.8,0.067,800.54,0.00011,0.00003
1,0.084,739.75,0.0001,0.00003
1.2,0.1,746.37,0.0001,0.00003
1.4,0.117,754.28,0.00011,0.00003
1.6,0.134,800.05,0.00012,0.00003
1.8,0.15,1027.28,0.00015,0.00003
2,0.167,1293.98,0.00018,0.00004
2.2,0.184,1401.86,0.0002,0.00005
2.4,0.2,1572.19,0.00022,0.00005
2.6,0.217,1799.13,0.00025,0.00006
2.8,0.234,1967.88,0.00027,0.00006
3,0.25,2224.71,0.0003,0.00008
3.2,0.267,2405.66,0.00033,0.00009
3.4,0.284,2717.82,0.00036,0.0001
3.6,0.3,2920.38,0.00039,0.00011
3.8,0.317,3290.13,0.00042,0.00012
4,0.334,3514.35,0.00045,0.00013
4.2,0.35,3848.62,0.00048,0.00014
4.4,0.367,4181.42,0.00051,0.00014
4.6,0.383,4520.3,0.00054,0.00015
4.8,0.4,4894.65,0.00058,0.00016
5,0.417,5257.18,0.0006,0.00016
5.2,0.434,5578.32,0.00064,0.00017
5.4,0.45,5972.89,0.00067,0.00018
5.6,0.467,6344.7,0.0007,0.00018
5.8,0.484,6697.99,0.00073,0.00019
6,0.5,6987.08,0.00075,0.0002
6.2,0.517,7479.15,0.00078,0.0002
6.4,0.534,7721.09,0.00081,0.00021
6.6,0.55,8049.19,0.00084,0.00021
6.8,0.567,8424.44,0.00086,0.00022
7,0.584,8723.88,0.00088,0.00022
7.2,0.6,9047.6,0.00091,0.00023
7.4,0.617,9336.4,0.00094,0.00023
7.6,0.634,9670.23,0.00096,0.00024
7.8,0.65,9907.5,0.00098,0.00024
8,0.667,10208.59,0.001,0.00025
8.2,0.684,10554.55,0.00102,0.00025
8.4,0.7,10758.55,0.00104,0.00026
8.6,0.717,11113.98,0.00106,0.00026
8.8,0.734,11335.33,0.00108,0.00026
9,0.75,11634.12,0.0011,0.00027
9.2,0.767,11938.46,0.00112,0.00027
9.4,0.784,12126.87,0.00115,0.00028
9.6,0.8,12495.89,0.00116,0.00028
9.8,0.817,12705.05,0.00118,0.00029
10,0.834,12990.65,0.0012,0.00029
10.2,0.85,13266.64,0.00122,0.0003
10.4,0.867,13574.93,0.00124,0.0003
10.6,0.884,13843.65,0.00126,0.00031
10.8,0.9,14125.85,0.00128,0.00031
11,0.917,14372.41,0.0013,0.00032
11.2,0.934,14701.15,0.00132,0.00032
11.4,0.95,14935.05,0.00134,0.00033
11.6,0.967,15242.69,0.00136,0.00033
11.8,0.984,15519.91,0.00138,0.00034
12,1,15777.86,0.0014,0.00034
12.2,1.017,16112.07,0.00143,0.00035
12.4,1.034,16335.36,0.00145,0.00035
12.6,1.05,16709.78,0.00147,0.00036
12.8,1.067,16924.79,0.0015,0.00037
13,1.084,17257.51,0.00152,0.00037
13.2,1.1,17502.06,0.00155,0.00037
13.4,1.117,17782.73,0.00157,0.00038
13.6,1.134,18119.66,0.0016,0.00038
13.8,1.15,18321.76,0.00163,0.00039
14,1.167,18690.33,0.00166,0.0004
14.2,1.183,18901.84,0.00168,0.0004
14.4,1.2,19200.9,0.00171,0.00041
14.6,1.217,19510.96,0.00174,0.00041
14.8,1.233,19807.41,0.00177,0.00042
15,1.25,20068.61,0.0018,0.00043
15.2,1.267,20366.23,0.00184,0.00043
15.4,1.284,20608.56,0.00186,0.00044
15.6,1.3,20958.98,0.0019,0.00045
15.8,1.317,21177.82,0.00193,0.00046
16,1.334,21441.05,0.00197,0.00046
16.2,1.35,21798.19,0.00201,0.00047
16.4,1.367,21949.03,0.00204,0.00048
16.6,1.384,22341.33,0.00208,0.00049
16.8,1.4,22517.73,0.00212,0.0005
17,1.417,22869.18,0.00216,0.00051
17.2,1.434,23110.27,0.0022,0.00052
17.4,1.45,23356.51,0.00224,0.00053
17.6,1.467,23635.06,0.00228,0.00054
17.8,1.484,23975.48,0.00233,0.00055
18,1.5,24118.48,0.00237,0.00056
18.2,1.517,24431.41,0.00242,0.00058
18.4,1.534,24618.42,0.00246,0.00059
18.6,1.55,24894.49,0.0025,0.0006
18.8,1.567,25086.06,0.00254,0.0006
19,1.584,25315.84,0.00258,0.00061
19.2,1.6,25492.95,0.0026,0.00061
19.4,1.617,25533.95,0.00261,0.0006
19.6,1.634,25549.1,0.00261,0.00059
19.8,1.65,25585.02,0.00261,0.00058
20,1.667,25681.38,0.00261,0.00058
20.2,1.684,25699.5,0.00263,0.00057
20.4,1.7,25689.59,0.00266,0.00057
20.6,1.717,25729.04,0.0027,0.00057
20.8,1.734,25766.53,0.00276,0.00057
21,1.75,25806.97,0.00287,0.00057
21.2,1.767,25861.17,0.00303,0.00057
21.4,1.784,25947.08,0.00322,0.00057
21.6,1.8,26010.63,0.00345,0.00056
21.8,1.817,26034.11,0.00372,0.00056
22,1.834,26038.53,0.00404,0.00056
22.2,1.85,26035.84,0.00438,0.00057
22.4,1.867,26033.41,0.00474,0.00059
22.6,1.884,26028.97,0.00513,0.00066
22.8,1.9,26028.14,0.00557,0.00082
23,1.917,26035.37,0.00602,0.00116
23.2,1.934,26036.43,0.0065,0.00155
23.4,1.95,26037.06,0.00699,0.00201
23.6,1.967,26033.27,0.00749,0.00254
23.8,1.984,26025.18,0.00802,0.00309
24,2,26005.52,0.00854,0.00365
24.2,2.017,25915.68,0.00907,0.00412
24.4,2.034,25762.73,0.00964,0.00454
24.6,2.05,25714.63,0.01021,0.00485
24.8,2.067,25722.37,0.01076,0.00505
25,2.084,25774.58,0.01131,0.00516
25.2,2.1,25809.89,0.01182,0.00524
25.4,2.117,25825.92,0.01226,0.00531
25.6,2.134,25855.34,0.01264,0.00538
25.8,2.15,25915.21,0.01298,0.00545
26,2.167,25992.06,0.01327,0.00552
26.2,2.184,26028.75,0.01352,0.00559
26.4,2.2,26013.24,0.01373,0.00564
26.6,2.217,25983.9,0.01389,0.00568
26.8,2.234,25776.52,0.014,0.0057
27,2.25,25579.56,0.01406,0.00571
27.2,2.267,25598.86,0.01411,0.00571
27.4,2.284,25761.26,0.01417,0.00573
27.6,2.3,25846.25,0.01423,0.00575
27.8,2.317,25986.26,0.01429,0.00577
28,2.334,26039.52,0.01436,0.0058
28.2,2.35,26064,0.01444,0.00583
28.4,2.367,26158.31,0.01453,0.00587
28.6,2.384,26261.26,0.01463,0.00591
28.8,2.4,26385.93,0.01476,0.00597
29,2.417,26454.74,0.0149,0.00603
29.2,2.434,26552.56,0.01506,0.00611
29.4,2.45,26605.45,0.01522,0.00619
29.6,2.467,26649.56,0.0154,0.00627
29.8,2.484,26729.61,0.01558,0.00636
30,2.5,26794.63,0.01576,0.00644
30.2,2.517,26873.34,0.01595,0.00653
30.4,2.534,26970.66,0.01614,0.00662
30.6,2.55,27026.78,0.01632,0.00671
30.8,2.567,27046.73,0.0165,0.0068
31,2.584,27067.85,0.01669,0.00689
31.2,2.6,27103.47,0.01688,0.00697
31.4,2.617,27191.64,0.01706,0.00706
31.6,2.634,27249.27,0.01725,0.00715
31.8,2.65,27314.14,0.01743,0.00724
32,2.667,27395.75,0.01762,0.00733
32.2,2.684,27450.13,0.0178,0.00742
32.4,2.7,27513.04,0.01799,0.00751
32.6,2.717,27550.98,0.01818,0.0076
32.8,2.734,27570.37,0.01837,0.00769
33,2.75,27599.62,0.01855,0.00778
33.2,2.767,27682.92,0.01874,0.00787
33.4,2.784,27788.86,0.01893,0.00796
33.6,2.8,27823.93,0.01912,0.00806
33.8,2.817,27880.52,0.0193,0.00815
34,2.834,27975.99,0.01949,0.00824
34.2,2.85,28041.88,0.01967,0.00833
34.4,2.867,28079.04,0.01986,0.00842
34.6,2.884,28109.12,0.02005,0.00851
34.8,2.9,28138.11,0.02024,0.00859
35,2.917,28176.12,0.02043,0.00868
35.2,2.934,28244.77,0.02062,0.00877
35.4,2.95,28318.92,0.02081,0.00887
35.6,2.967,28392.76,0.021,0.00897
35.8,2.983,28455.95,0.02119,0.00906
36,3,28501.43,0.02138,0.00915
36.2,3.017,28563.09,0.02157,0.00924
36.4,3.034,28605.02,0.02175,0.00933
36.6,3.05,28625.63,0.02195,0.00942
36.8,3.067,28636.99,0.02214,0.00951
37,3.084,28676.24,0.02233,0.0096
37.2,3.1,28751.4,0.02252,0.00969
37.4,3.117,28836.64,0.02271,0.00978
37.6,3.134,28867.11,0.0229,0.00987
37.8,3.15,28917.8,0.0231,0.00996
38,3.167,28986.92,0.0233,0.01006
38.2,3.184,29050.44,0.02349,0.01015
38.4,3.2,29079.06,0.02369,0.01025
38.6,3.217,29125.48,0.02388,0.01034
38.8,3.234,29163.37,0.02408,0.01043
39,3.25,29225.85,0.02427,0.01053
39.2,3.267,29272.82,0.02447,0.01062
39.4,3.284,29328.38,0.02467,0.01072
39.6,3.3,29381.74,0.02486,0.01081
39.8,3.317,29437.58,0.02506,0.0109
40,3.334,29476.74,0.02526,0.011
40.2,3.35,29506.22,0.02545,0.01109
40.4,3.367,29561,0.02564,0.01119
40.6,3.384,29606.38,0.02584,0.01128
40.8,3.4,29638.44,0.02604,0.01138
41,3.417,29662.82,0.02625,0.01147
41.2,3.433,29691.95,0.02644,0.01157
41.4,3.45,29731.44,0.02664,0.01166
41.6,3.467,29811.79,0.02683,0.01175
41.8,3.484,29895.88,0.02703,0.01185
42,3.5,29940.44,0.02724,0.01194
42.2,3.517,29989.11,0.02744,0.01204
42.4,3.534,30059.2,0.02764,0.01214
42.6,3.55,30111.73,0.02783,0.01223
42.8,3.567,30124.35,0.02804,0.01233
43,3.584,30133.06,0.02824,0.01242
43.2,3.6,30153.74,0.02844,0.01252
43.4,3.617,30189.79,0.02864,0.01261
43.6,3.634,30233.6,0.02884,0.01271
43.8,3.65,30278.67,0.02904,0.0128
44,3.667,30305.45,0.02925,0.0129
44.2,3.684,30348.96,0.02945,0.01299
44.4,3.7,30397.07,0.02966,0.01309
44.6,3.717,30459.01,0.02985,0.01318
44.8,3.734,30496.5,0.03006,0.01327
45,3.75,30570.75,0.03026,0.01337
45.2,3.767,30636.54,0.03046,0.01346
45.4,3.784,30666.62,0.03067,0.01356
45.6,3.8,30685.42,0.03087,0.01365
45.8,3.817,30709.62,0.03107,0.01374
46,3.834,30758.78,0.03128,0.01383
46.2,3.85,30790.07,0.03148,0.01393
46.4,3.867,30821.39,0.03169,0.01403
46.6,3.884,30882.25,0.03189,0.01413
46.8,3.9,30910.92,0.0321,0.01423
47,3.917,30932.82,0.03231,0.01432
47.2,3.933,30952.77,0.03251,0.01441
47.4,3.95,31000.35,0.03272,0.01451
47.6,3.967,31056.02,0.03292,0.0146
47.8,3.984,31112.25,0.03312,0.01469
48,4,31161.15,0.03333,0.01479
48.2,4.017,31183.15,0.03354,0.01489
48.4,4.034,31193.06,0.03374,0.01499
48.6,4.05,31206.6,0.03395,0.01509
48.8,4.067,31238.97,0.03416,0.01519
49,4.084,31300.11,0.03437,0.01529
49.2,4.1,31346.6,0.03458,0.01538
49.4,4.117,31401.48,0.03478,0.01548
49.6,4.134,31448.68,0.03499,0.01558
49.8,4.15,31491.05,0.03519,0.01568
50,4.167,31530.87,0.03541,0.01577
50.2,4.184,31551.42,0.03561,0.01587
50.4,4.2,31575.02,0.03582,0.01596
50.6,4.217,31608.11,0.03603,0.01605
50.8,4.234,31650.08,0.03624,0.01616
51,4.25,31669.38,0.03645,0.01625
51.2,4.267,31675.51,0.03666,0.01634
51.4,4.284,31687.04,0.03687,0.01644
51.6,4.3,31701.39,0.03708,0.01654
51.8,4.317,31720.6,0.0373,0.01664
52,4.334,31737.5,0.03751,0.01673
52.2,4.35,31788.34,0.03772,0.01683
52.4,4.367,31843.36,0.03793,0.01693
52.6,4.384,31898.93,0.03813,0.01703
52.8,4.4,31943.11,0.03835,0.01712
53,4.417,31997.31,0.03856,0.01722
53.2,4.434,32036.4,0.03877,0.01732
53.4,4.45,32087.87,0.03899,0.01742
53.6,4.467,32136.29,0.0392,0.01751
53.8,4.484,32176.97,0.03941,0.01761
54,4.5,32207.47,0.03963,0.01771
54.2,4.517,32241.04,0.03984,0.01781
54.4,4.534,32263.75,0.04006,0.01791
54.6,4.55,32287.35,0.04027,0.018
54.8,4.567,32295.97,0.04049,0.01811
55,4.584,32311.24,0.0407,0.0182
55.2,4.6,32343,0.04091,0.01831
55.4,4.617,32364.86,0.04113,0.01841
55.6,4.634,32376.63,0.04135,0.01848
55.8,4.65,32393.61,0.04157,0.01858
56,4.667,32414.92,0.04178,0.01869
56.2,4.684,32454.04,0.04199,0.01879
56.4,4.7,32489.49,0.04221,0.0189
56.6,4.717,32535.48,0.04243,0.019
56.8,4.734,32564.78,0.04265,0.01911
57,4.75,32604.48,0.04287,0.01921
57.2,4.767,32623.09,0.04308,0.01931
57.4,4.784,32681.38,0.0433,0.01941
57.6,4.8,32701.77,0.04352,0.01952
57.8,4.817,32726.36,0.04373,0.01962
58,4.834,32738.21,0.04394,0.01972
58.2,4.85,32756.09,0.04416,0.01982
58.4,4.867,32774.39,0.04438,0.01992
58.6,4.884,32802.79,0.0446,0.02002
58.8,4.9,32838.68,0.04482,0.02012
59,4.917,32879.91,0.04503,0.02022
59.2,4.934,32922.67,0.04525,0.02032
59.4,4.95,32957.86,0.04547,0.02042
59.6,4.967,32987.3,0.04569,0.02052
59.8,4.984,33008.59,0.0459,0.02062
60,5,33037.11,0.04612,0.02072
60.2,5.017,33063.92,0.04633,0.02082
60.4,5.034,33092.3,0.04655,0.02092
60.6,5.05,33124.59,0.04677,0.02102
60.8,5.067,33153.99,0.04699,0.02112
61,5.084,33173.26,0.0472,0.02122
61.2,5.1,33181.21,0.04742,0.02132
61.4,5.117,33187.24,0.04764,0.02142
61.6,5.134,33197,0.04786,0.02152
61.8,5.15,33209.48,0.04808,0.02162
62,5.167,33221.02,0.0483,0.02172
62.2,5.184,33239.74,0.04852,0.02182
62.4,5.2,33253.27,0.04874,0.02191
62.6,5.217,33292.12,0.04896,0.02201
62.8,5.234,33325.15,0.04917,0.02211
63,5.25,33366.73,0.04939,0.02221
63.2,5.267,33401.7,0.04961,0.02231
63.4,5.284,33425.08,0.04983,0.02241
63.6,5.3,33450.18,0.05005,0.02251
63.8,5.317,33477.96,0.05027,0.02261
64,5.334,33513.65,0.05049,0.02272
64.2,5.35,33556.6,0.05072,0.02282
64.4,5.367,33601.1,0.05094,0.02292
64.6,5.384,33630.34,0.05116,0.02302
64.8,5.4,33646.12,0.05138,0.02312
65,5.417,33676.15,0.0516,0.02322
65.2,5.434,33701.12,0.05182,0.02332
65.4,5.45,33733.73,0.05204,0.02342
65.6,5.467,33759.55,0.05226,0.02352
65.8,5.484,33773.88,0.05249,0.02362
66,5.5,33785.71,0.05271,0.02372
66.2,5.517,33793.07,0.05293,0.02382
66.4,5.534,33795.12,0.05314,0.02392
66.6,5.55,33796.79,0.05337,0.02402
66.8,5.567,33797.89,0.0536,0.02412
67,5.584,33799.2,0.05382,0.02422
67.2,5.6,33804.88,0.05404,0.02433
67.4,5.617,33817.8,0.05427,0.02443
67.6,5.633,33845.64,0.05449,0.02453
67.8,5.65,33894.03,0.05472,0.02464
68,5.667,33920.68,0.05494,0.02474
68.2,5.684,33945,0.05516,0.02484
68.4,5.7,33970.79,0.05539,0.02494
68.6,5.717,33985.44,0.05561,0.02505
68.8,5.734,33996.65,0.05583,0.02516
69,5.75,34018.29,0.05607,0.02526
69.2,5.767,34049.33,0.05629,0.02537
69.4,5.784,34090.08,0.05651,0.02548
69.6,5.8,34126.75,0.05674,0.02559
69.8,5.817,34181.69,0.05696,0.02569
70,5.834,34201.62,0.05719,0.02579
70.2,5.85,34229.89,0.05741,0.0259
70.4,5.867,34243.58,0.05764,0.026
70.6,5.884,34256.14,0.05787,0.0261
70.8,5.9,34269.36,0.05809,0.0262
71,5.917,34281.25,0.05832,0.02631
71.2,5.934,34288.27,0.05854,0.02641
71.4,5.95,34303.73,0.05877,0.02651
71.6,5.967,34309.6,0.059,0.02661
71.8,5.984,34324.77,0.05923,0.02672
72,6,34339.11,0.05945,0.02682
72.2,6.017,34365.44,0.05969,0.02692
72.4,6.034,34380.24,0.05991,0.02702
72.6,6.05,34436.94,0.06014,0.02713
72.8,6.067,34454.34,0.06037,0.02723
73,6.084,34477.97,0.06059,0.02733
73.2,6.1,34492.06,0.06082,0.02743
73.4,6.117,34504.44,0.06105,0.02753
73.6,6.134,34517.07,0.06127,0.02764
73.8,6.15,34537.47,0.0615,0.02774
74,6.167,34549.88,0.06174,0.02784
74.2,6.184,34564.9,0.06197,0.02795
74.4,6.2,34582.49,0.0622,0.02805
74.6,6.217,34588.23,0.06242,0.02815
74.8,6.234,34603.3,0.06265,0.02826
75,6.25,34610.25,0.06289,0.02836
75.2,6.267,34616.76,0.06312,0.02846
75.4,6.284,34627.75,0.06334,0.02856
75.6,6.3,34639.65,0.06357,0.02867
75.8,6.317,34667.08,0.0638,0.02877
76,6.334,34690.5,0.06403,0.02887
76.2,6.35,34706.33,0.06426,0.02897
76.4,6.367,34724.62,0.06449,0.02907
76.6,6.384,34744.43,0.06472,0.02917
76.8,6.4,34765.96,0.06496,0.02927
77,6.417,34786.36,0.06519,0.02938
77.2,6.434,34794.77,0.06542,0.02948
77.4,6.45,34811.42,0.06565,0.02958
77.6,6.467,34815.02,0.06588,0.02968
77.8,6.484,34822.36,0.06611,0.02978
78,6.5,34831.42,0.06634,0.02989
78.2,6.517,34835.2,0.06657,0.02999
78.4,6.534,34848.41,0.0668,0.03009
78.6,6.55,34863.86,0.06703,0.0302
78.8,6.567,34882.46,0.06727,0.0303
79,6.584,34926.98,0.0675,0.03039
79.2,6.6,34957.88,0.06773,0.03046
79.4,6.617,34994.45,0.06797,0.03056
79.6,6.634,35028.05,0.0682,0.03067
79.8,6.65,35041.01,0.06844,0.03077
80,6.667,35068.57,0.06867,0.03088
80.2,6.684,35079.82,0.06891,0.03097
80.4,6.7,35102.34,0.06914,0.03108
80.6,6.717,35108.98,0.06937,0.03118
80.8,6.734,35126.36,0.0696,0.03128
81,6.75,35142.12,0.06984,0.03139
81.2,6.767,35160.21,0.07008,0.03149
81.4,6.784,35171.25,0.07031,0.0316
81.6,6.8,35201.53,0.07054,0.0317
81.8,6.817,35211.8,0.07078,0.03181
82,6.834,35238.14,0.07102,0.03191
82.2,6.85,35255.13,0.07125,0.03201
82.4,6.867,35267.02,0.07149,0.03212
82.6,6.884,35274.27,0.07173,0.03222
82.8,6.9,35282.61,0.07196,0.03233
83,6.917,35287.12,0.07219,0.03243
83.2,6.933,35292.08,0.07242,0.03253
83.4,6.95,35297.66,0.07266,0.03264
83.6,6.967,35302.93,0.0729,0.03274
83.8,6.984,35303.74,0.07314,0.03285
84,7,35312.32,0.07337,0.03295
84.2,7.017,35315.87,0.0736,0.03305
84.4,7.034,35322.62,0.07384,0.03316
84.6,7.05,35332.86,0.07408,0.03327
84.8,7.067,35338.57,0.07432,0.03337
85,7.084,35343.98,0.07456,0.03348
85.2,7.1,35352.89,0.0748,0.03358
85.4,7.117,35366.79,0.07503,0.03369
85.6,7.134,35378.18,0.07526,0.03379
85.8,7.15,35389.5,0.0755,0.0339
86,7.167,35406.29,0.07574,0.03401
86.2,7.184,35416.67,0.07598,0.03412
86.4,7.2,35419.83,0.07622,0.03422
86.6,7.217,35437.09,0.07646,0.03433
86.8,7.234,35441.06,0.07669,0.03444
87,7.25,35458.94,0.07693,0.03455
87.2,7.267,35471.37,0.07717,0.03466
87.4,7.284,35488.22,0.07741,0.03476
87.6,7.3,35509.14,0.07764,0.03487
87.8,7.317,35524.79,0.07788,0.03498
88,7.334,35544.33,0.07812,0.03509
88.2,7.35,35572.09,0.07837,0.03519
88.4,7.367,35579.89,0.0786,0.0353
88.6,7.384,35601.07,0.07884,0.0354
88.8,7.4,35623.95,0.07908,0.03551
89,7.417,35643.31,0.07932,0.03561
89.2,7.434,35669.7,0.07955,0.03572
89.4,7.45,35674.52,0.07979,0.03582
89.6,7.467,35682.28,0.08003,0.03593
89.8,7.484,35698.94,0.08027,0.03603
90,7.5,35712.18,0.08051,0.03614
90.2,7.517,35720.37,0.08075,0.03624
90.4,7.534,35731.75,0.08099,0.03634
90.6,7.55,35747.16,0.08123,0.03645
90.8,7.567,35762.56,0.08147,0.03655
91,7.584,35774.29,0.08171,0.03666
91.2,7.6,35784.83,0.08195,0.03676
91.4,7.617,35791.15,0.0822,0.03687
91.6,7.634,35796.5,0.08243,0.03697
91.8,7.65,35802.86,0.08267,0.03708
92,7.667,35816.16,0.08292,0.03718
92.2,7.684,35829.08,0.08317,0.03729
92.4,7.7,35832.67,0.08341,0.0374
92.6,7.717,35840.26,0.08365,0.0375
92.8,7.734,35846.61,0.08389,0.0376
93,7.75,35863.29,0.08414,0.03771
93.2,7.767,35870.83,0.08438,0.03782
93.4,7.784,35881.86,0.08463,0.03792
93.6,7.8,35884.7,0.08487,0.03802
93.8,7.817,35893.62,0.08511,0.03813
94,7.834,35901.19,0.08535,0.03824
94.2,7.85,35907.62,0.08559,0.03834
94.4,7.867,35914.83,0.08583,0.03844
94.6,7.884,35920.14,0.08608,0.03855
94.8,7.9,35929.04,0.08633,0.03865
95,7.917,35929.66,0.08657,0.03876
95.2,7.934,35948.44,0.08682,0.03887
95.4,7.95,35953,0.08706,0.03897
95.6,7.967,35971.33,0.0873,0.03907
95.8,7.984,35974.99,0.08754,0.03918
96,8,36000.91,0.08778,0.03928
96.2,8.017,36009.82,0.08803,0.03939
96.4,8.034,36024.29,0.08828,0.0395
96.6,8.05,36031.01,0.08852,0.0396
96.8,8.067,36041.11,0.08877,0.03971
97,8.084,36043.11,0.08901,0.03981
97.2,8.1,36048.83,0.08925,0.03992
97.4,8.117,36055.39,0.0895,0.04003
97.6,8.134,36062.66,0.08974,0.04013
97.8,8.15,36070.1,0.08999,0.04024
98,8.167,36072.44,0.09024,0.04035
98.2,8.184,36079.45,0.09048,0.04046
98.4,8.2,36087.07,0.09073,0.04056
98.6,8.217,36091.52,0.09098,0.04067
98.8,8.234,36102.48,0.09123,0.04078
99,8.25,36111.12,0.09147,0.04088
99.2,8.267,36128.76,0.09172,0.04099
99.4,8.284,36139.3,0.09196,0.0411
99.6,8.3,36153.39,0.09221,0.0412
99.8,8.317,36179.69,0.09247,0.04131
100,8.334,36195.63,0.09272,0.04142
100.2,8.35,36205.23,0.09296,0.04152
100.4,8.367,36235.45,0.09321,0.04163
100.6,8.384,36245.48,0.09347,0.04172
100.8,8.4,36253.61,0.09371,0.04182
101,8.417,36266.43,0.09397,0.04193
101.2,8.434,36277.35,0.09422,0.04204
101.4,8.45,36284.92,0.09446,0.04215
101.6,8.467,36294.3,0.09472,0.04226
101.8,8.484,36302.75,0.09497,0.04237
102,8.5,36304.33,0.09522,0.04248
102.2,8.517,36310.19,0.09547,0.04259
102.4,8.534,36312.59,0.09572,0.04269
102.6,8.55,36320,0.09597,0.0428
102.8,8.567,36321.12,0.09623,0.04291
103,8.584,36323.73,0.09648,0.04303
103.2,8.6,36325.61,0.09673,0.04314
103.4,8.617,36333.03,0.09698,0.04325
103.6,8.633,36338.02,0.09722,0.04337
103.8,8.65,36341,0.09748,0.04349
104,8.667,36351.57,0.09773,0.04361
104.2,8.684,36349.26,0.09798,0.04372
104.4,8.7,36363.2,0.09824,0.04384
104.6,8.717,36365.28,0.09849,0.04395
104.8,8.734,36381.66,0.09874,0.04406
105,8.75,36385.97,0.099,0.04417
105.2,8.767,36391.4,0.09925,0.04428
105.4,8.784,36410.43,0.09951,0.04439
105.6,8.8,36405.53,0.09976,0.0445
105.8,8.817,36413.16,0.10001,0.04461
106,8.834,36427.8,0.10026,0.04472
106.2,8.85,36434.8,0.10052,0.04482
106.4,8.867,36446.27,0.10077,0.04493
106.6,8.884,36453.95,0.10102,0.04504
106.8,8.9,36464.47,0.10128,0.04515
107,8.917,36484.57,0.10153,0.04526
107.2,8.934,36492.12,0.10179,0.04536
107.4,8.95,36499.48,0.10204,0.04547
107.6,8.967,36508.8,0.1023,0.04559
107.8,8.984,36512.84,0.10255,0.0457
108,9,36520.54,0.10281,0.0458
108.2,9.017,36529.75,0.10307,0.04592
108.4,9.034,36531.9,0.10332,0.04603
108.6,9.05,36542.99,0.10357,0.04614
108.8,9.067,36542.08,0.10383,0.04625
109,9.083,36546.12,0.10408,0.04635
109.2,9.1,36560.95,0.10434,0.04646
109.4,9.117,36565.45,0.1046,0.04657
109.6,9.134,36569.2,0.10485,0.04668
109.8,9.15,36575.1,0.10511,0.04679
110,9.167,36580.72,0.10536,0.04689
110.2,9.184,36586.77,0.10562,0.047
110.4,9.2,36602.32,0.10588,0.04711
110.6,9.217,36603.34,0.10614,0.04722
110.8,9.234,36609.26,0.1064,0.04733
111,9.25,36612.75,0.10666,0.04744
111.2,9.267,36626.76,0.10691,0.04756
111.4,9.284,36631.92,0.10717,0.04767
111.6,9.3,36640.02,0.10743,0.04778
111.8,9.317,36641.21,0.10769,0.04789
112,9.334,36651.12,0.10795,0.04799
112.2,9.35,36653.55,0.1082,0.04811
112.4,9.367,36663.93,0.10846,0.04822
112.6,9.384,36667.73,0.10873,0.04833
112.8,9.4,36668.82,0.10898,0.04845
113,9.417,36680.08,0.10925,0.04857
113.2,9.434,36683.14,0.1095,0.04868
113.4,9.45,36682.28,0.10976,0.04878
113.6,9.467,36693.7,0.11003,0.04889
113.8,9.484,36693.02,0.11028,0.049
114,9.5,36704.27,0.11055,0.0491
114.2,9.517,36707.08,0.11081,0.0492
114.4,9.534,36709.63,0.11106,0.0493
114.6,9.55,36721.67,0.11133,0.0494
114.8,9.567,36725.11,0.11159,0.0495
115,9.584,36732.35,0.11185,0.04961
115.2,9.6,36737.58,0.11211,0.04971
115.4,9.617,36745.19,0.11238,0.04981
115.6,9.634,36769.36,0.11263,0.04992
115.8,9.65,36781.55,0.1129,0.05003
116,9.667,36774.45,0.11316,0.05014
116.2,9.684,36793.95,0.11342,0.05024
116.4,9.7,36802.27,0.11369,0.05035
116.6,9.717,36808.68,0.11395,0.05045
116.8,9.734,36809.01,0.11421,0.05057
117,9.75,36822.07,0.11448,0.05067
117.2,9.767,36825.32,0.11474,0.05078
117.4,9.784,36832.25,0.115,0.05089
117.6,9.8,36831.46,0.11526,0.051
117.8,9.817,36842.46,0.11553,0.05111
118,9.834,36843.85,0.1158,0.05122
118.2,9.85,36842.44,0.11607,0.05133
118.4,9.867,36843.99,0.11633,0.05144
118.6,9.884,36844.99,0.1166,0.05156
118.8,9.9,36846.01,0.11687,0.05167
119,9.917,36846.84,0.11714,0.05178
119.2,9.934,36847.36,0.1174,0.05189
119.4,9.95,36848.01,0.11767,0.052
119.6,9.967,36848.5,0.11793,0.05211
119.8,9.983,36848.66,0.1182,0.05223
120,10,36849.72,0.11847,0.05233
120.2,10.017,36849.37,0.11874,0.05243
120.4,10.034,36850.13,0.11901,0.05254
120.6,10.05,36850.66,0.11927,0.05265
120.8,10.067,36851.23,0.11954,0.05276
121,10.084,36852.49,0.11981,0.05287
121.2,10.1,36853.02,0.12009,0.05298
121.4,10.117,36854.16,0.12035,0.05309
121.6,10.134,36855.7,0.12062,0.0532
121.8,10.15,36854.82,0.12089,0.05331
122,10.167,36857.44,0.12116,0.05342
122.2,10.184,36859.25,0.12143,0.05353
122.4,10.2,36859.15,0.12169,0.05364
122.6,10.217,36862.89,0.12196,0.05376
122.8,10.234,36863.29,0.12223,0.05386
123,10.25,36864.85,0.12249,0.05398
123.2,10.267,36870.4,0.12277,0.05409
123.4,10.284,36869.84,0.12304,0.0542
123.6,10.3,36870.69,0.12331,0.0543
123.8,10.317,36873.68,0.12358,0.05442
124,10.334,36877.12,0.12385,0.05453
124.2,10.35,36881.25,0.12412,0.05464
124.4,10.367,36880.52,0.12439,0.05476
124.6,10.384,36883.37,0.12466,0.05487
124.8,10.4,36887.48,0.12494,0.05498
125,10.417,36887.93,0.1252,0.05509
125.2,10.434,36896.92,0.12547,0.05521
125.4,10.45,36898.16,0.12575,0.05533
125.6,10.467,36897.63,0.12602,0.05544
125.8,10.484,36903.28,0.12629,0.05555
126,10.5,36909.37,0.12657,0.05566
126.2,10.517,36912.14,0.12684,0.05577
126.4,10.534,36923.89,0.12711,0.05588
126.6,10.55,36921.98,0.12739,0.05599
126.8,10.567,36925.74,0.12766,0.05611
127,10.584,36926.85,0.12793,0.05622
127.2,10.6,36940.95,0.12821,0.05633
127.4,10.617,36942.13,0.12848,0.05644
127.6,10.634,36953.6,0.12876,0.05655
127.8,10.65,36955.88,0.12903,0.05666
128,10.667,36962.65,0.12931,0.05677
128.2,10.684,36978.17,0.12958,0.05688
128.4,10.7,36981.14,0.12985,0.05699
128.6,10.717,36989.13,0.13013,0.05711
128.8,10.734,37001.51,0.13041,0.05721
129,10.75,36995.44,0.13069,0.05733
129.2,10.767,37009.86,0.13097,0.05744
129.4,10.784,37000.22,0.13123,0.05755
129.6,10.8,37017.91,0.13151,0.05766
129.8,10.817,37012.15,0.13179,0.05778
130,10.834,37029.49,0.13206,0.05789
130.2,10.85,37026,0.13234,0.058
130.4,10.867,37032.3,0.13261,0.05811
130.6,10.884,37042.32,0.13289,0.05823
130.8,10.9,37050.87,0.13317,0.05834
131,10.917,37050.84,0.13344,0.05846
131.2,10.934,37062.79,0.13372,0.05857
131.4,10.95,37060.61,0.134,0.05868
131.6,10.967,37066.45,0.13428,0.05879
131.8,10.984,37071.5,0.13455,0.0589
132,11,37067.86,0.13483,0.05902
132.2,11.017,37077.12,0.13511,0.05913
132.4,11.034,37085.15,0.13539,0.05924
132.6,11.05,37082.98,0.13567,0.05936
132.8,11.067,37094.53,0.13595,0.05947
133,11.084,37100.64,0.13623,0.05958
133.2,11.1,37096.12,0.1365,0.05969
133.4,11.117,37107.75,0.13679,0.05981
133.6,11.133,37105.73,0.13707,0.05992
133.8,11.15,37116.95,0.13734,0.06004
134,11.167,37116.94,0.13762,0.06015
134.2,11.184,37113.49,0.13791,0.06027
134.4,11.2,37125.47,0.13819,0.06038
134.6,11.217,37123.57,0.13846,0.06049
134.8,11.233,37125.73,0.13875,0.0606
135,11.25,37128.8,0.13903,0.06071
135.2,11.267,37126.87,0.13931,0.06083
135.4,11.284,37135.47,0.13959,0.06094
135.6,11.3,37135.79,0.13987,0.06105
135.8,11.317,37138.2,0.14015,0.06116
136,11.334,37151.63,0.14044,0.06128
136.2,11.35,37147.5,0.14072,0.06139
136.4,11.367,37148.11,0.14101,0.0615
136.6,11.384,37152.68,0.14129,0.06161
136.8,11.4,37151.54,0.14157,0.06173
137,11.417,37155.22,0.14185,0.06184
137.2,11.434,37161.52,0.14214,0.06195
137.4,11.45,37161.17,0.14242,0.06207
137.6,11.467,37159.77,0.14271,0.06217
137.8,11.484,37171.9,0.14299,0.06229
138,11.5,37163.38,0.14327,0.0624
138.2,11.517,37173.22,0.14355,0.06252
138.4,11.534,37175.39,0.14384,0.06264
138.6,11.55,37174.68,0.14412,0.06275
138.8,11.567,37182.77,0.14441,0.06287
139,11.584,37192.12,0.14469,0.06299
139.2,11.6,37185.34,0.14498,0.0631
139.4,11.617,37196.32,0.14527,0.06321
139.6,11.634,37192.39,0.14555,0.06333
139.8,11.65,37199.15,0.14624,0.06346
140,11.667,37191.22,0.1467,0.0636
140.2,11.683,37197.94,0.14699,0.06373
140.4,11.7,37208.64,0.14729,0.06384
140.6,11.717,37206.48,0.14759,0.06395
140.8,11.734,37212.2,0.14788,0.06405
141,11.75,37219.85,0.14818,0.06416
141.2,11.767,37224.59,0.14847,0.06427
141.4,11.784,37233.88,0.14877,0.06437
141.6,11.8,37236.32,0.14907,0.06449
141.8,11.817,37225.22,0.14938,0.0646
142,11.834,37236.71,0.14967,0.06472
142.2,11.85,37230.12,0.14996,0.06483
142.4,11.867,37240.18,0.15026,0.06494
142.6,11.884,37250,0.15055,0.06506
142.8,11.9,37244.45,0.15085,0.06517
143,11.917,37261.29,0.15115,0.06528
143.2,11.934,37259.33,0.15144,0.0654
143.4,11.95,37265.23,0.15174,0.06551
143.6,11.967,37274.18,0.15204,0.06563
143.8,11.984,37267.21,0.15234,0.06575
144,12,37274.37,0.15264,0.06586
144.2,12.017,37276.16,0.15293,0.06597
144.4,12.034,37277.83,0.15323,0.06608
144.6,12.05,37285.3,0.15353,0.0662
144.8,12.067,37291.14,0.15383,0.06631
145,12.084,37286.47,0.15412,0.06643
145.2,12.1,37286.71,0.15442,0.06655
145.4,12.117,37290.91,0.15472,0.06666
145.6,12.134,37298.94,0.15502,0.06677
145.8,12.15,37295.84,0.15531,0.06689
146,12.167,37300.49,0.15561,0.067
146.2,12.184,37302.91,0.1559,0.06712
146.4,12.2,37309.95,0.1562,0.06724
146.6,12.217,37305.32,0.1565,0.06736
146.8,12.234,37304.24,0.1568,0.06748
147,12.25,37308.82,0.1571,0.0676
147.2,12.267,37313.3,0.1574,0.06772
147.4,12.284,37318.3,0.1577,0.06784
147.6,12.3,37317.41,0.15799,0.06797
147.8,12.317,37314.75,0.15829,0.06809
148,12.334,37318.5,0.15859,0.06821
148.2,12.35,37321.03,0.15889,0.06832
148.4,12.367,37323.52,0.15919,0.06844
148.6,12.384,37323.09,0.1595,0.06856
148.8,12.4,37325.98,0.1598,0.06868
149,12.417,37328.55,0.16009,0.0688
149.2,12.434,37327.9,0.1604,0.06892
149.4,12.45,37325.33,0.1607,0.06904
149.6,12.467,37320.06,0.161,0.06915
149.8,12.484,37331.28,0.16131,0.06927
150,12.5,37330.2,0.16161,0.06939
150.2,12.517,37328.9,0.16191,0.0695
150.4,12.534,37333.37,0.16222,0.06962
150.6,12.55,37333.48,0.16252,0.06974
150.8,12.567,37332.93,0.16282,0.06986
151,12.584,37333.08,0.16312,0.06997
151.2,12.6,37335.43,0.16343,0.07009
151.4,12.617,37334.79,0.16374,0.07021
151.6,12.634,37335.75,0.16404,0.07032
151.8,12.65,37336.68,0.16434,0.07044
152,12.667,37334.48,0.16465,0.07055
152.2,12.684,37340.74,0.16496,0.07067
152.4,12.7,37335.49,0.16526,0.07079
152.6,12.717,37335.94,0.16557,0.07091
152.8,12.734,37333.82,0.16587,0.07103
153,12.75,37334.65,0.16618,0.07115
153.2,12.767,37338.38,0.16648,0.07128
153.4,12.784,37338.4,0.1668,0.0714
153.6,12.8,37337.59,0.1671,0.07152
153.8,12.817,37341.92,0.1674,0.07164
154,12.834,37339.83,0.16771,0.07176
154.2,12.85,37344.11,0.16802,0.07188
154.4,12.867,37342.29,0.16833,0.07201
154.6,12.884,37342.34,0.16864,0.07213
154.8,12.9,37342.92,0.16895,0.07225
155,12.917,37340.68,0.16925,0.07238
155.2,12.934,37342.02,0.16956,0.07249
155.4,12.95,37343.59,0.16987,0.07261
155.6,12.967,37345.36,0.17018,0.07274
155.8,12.984,37344.34,0.17049,0.07286
156,13,37342.07,0.1708,0.07298
156.2,13.017,37344.96,0.17111,0.0731
156.4,13.034,37345.43,0.17142,0.07323
156.6,13.05,37347.74,0.17173,0.07335
156.8,13.067,37344.04,0.17204,0.07347
157,13.084,37347.64,0.17236,0.07359
157.2,13.1,37345.93,0.17267,0.07371
157.4,13.117,37350.88,0.17298,0.07383
157.6,13.134,37348.3,0.1733,0.07396
157.8,13.15,37347.32,0.1736,0.07408
158,13.167,37348.08,0.17392,0.0742
158.2,13.184,37347.04,0.17423,0.07432
158.4,13.2,37343.85,0.17454,0.07444
158.6,13.217,37346.86,0.17485,0.07457
158.8,13.234,37350.26,0.17516,0.07469
159,13.25,37346.09,0.17548,0.07481
159.2,13.267,37350.73,0.17579,0.07493
159.4,13.284,37349.26,0.1761,0.07504
159.6,13.3,37351.61,0.17642,0.07517
159.8,13.317,37352.5,0.17674,0.07529
160,13.334,37351.68,0.17706,0.07542
160.2,13.35,37348,0.17737,0.07554
160.4,13.367,37348.33,0.17768,0.07566
160.6,13.384,37349.29,0.178,0.07578
160.8,13.4,37353.4,0.17832,0.07591
161,13.417,37349.59,0.17864,0.07603
161.2,13.434,37350.56,0.17895,0.07616
161.4,13.45,37352.58,0.17927,0.07628
161.6,13.467,37350.96,0.17959,0.0764
161.8,13.484,37354.21,0.17991,0.07653
162,13.5,37353.13,0.18023,0.07666
162.2,13.517,37351.31,0.18055,0.07678
162.4,13.534,37349.74,0.18087,0.07691
162.6,13.55,37351.21,0.1812,0.07703
162.8,13.567,37351.5,0.18152,0.07716
163,13.584,37354.79,0.18185,0.07728
163.2,13.6,37351.18,0.18217,0.0774
163.4,13.617,37350.68,0.18248,0.07751
163.6,13.634,37349.23,0.18281,0.07763
163.8,13.65,37351.13,0.18313,0.07775
164,13.667,37352.67,0.18346,0.07787
164.2,13.684,37353.68,0.18379,0.078
164.4,13.7,37351.73,0.18411,0.07813
164.6,13.717,37352.76,0.18443,0.07826
164.8,13.734,37351.7,0.18476,0.07839
165,13.75,37353.68,0.18509,0.07852
165.2,13.767,37354.58,0.18542,0.07866
165.4,13.784,37349.73,0.18574,0.07879
165.6,13.8,37354.27,0.18607,0.07891
165.8,13.817,37351.58,0.18639,0.07904
166,13.834,37354.8,0.18672,0.07917
166.2,13.85,37356.14,0.18705,0.0793
166.4,13.867,37355.01,0.18738,0.07943
166.6,13.883,37350.16,0.1877,0.07955
166.8,13.9,37354.16,0.18803,0.07967
167,13.917,37353.78,0.18836,0.0798
167.2,13.934,37351.63,0.18869,0.07993
167.4,13.95,37354.98,0.18903,0.08006
167.6,13.967,37352.12,0.18936,0.08019
167.8,13.984,37352.63,0.18969,0.08032
168,14,37352.02,0.19002,0.08045
168.2,14.017,37353.59,0.19035,0.08057
168.4,14.034,37353.51,0.19069,0.0807
168.6,14.05,37350.34,0.19102,0.08084
168.8,14.067,37352.84,0.19135,0.08097
169,14.084,37352.91,0.19169,0.0811
169.2,14.1,37351.4,0.19203,0.08123
169.4,14.117,37354.1,0.19237,0.08137
169.6,14.134,37351.57,0.1927,0.0815
169.8,14.15,37350.98,0.19304,0.08163
170,14.167,37350.91,0.19339,0.08176
170.2,14.184,37350.61,0.19372,0.0819
170.4,14.2,37350.07,0.19407,0.08203
170.6,14.217,37352.84,0.19441,0.08217
170.8,14.234,37347.41,0.19475,0.0823
171,14.25,37349.77,0.19509,0.08243
171.2,14.267,37349.61,0.19542,0.08256
171.4,14.284,37352.25,0.19577,0.08269
171.6,14.3,37350.58,0.19611,0.08282
171.8,14.317,37350.9,0.19646,0.08295
172,14.334,37348.33,0.1968,0.08308
172.2,14.35,37348.09,0.19714,0.08322
172.4,14.367,37347.7,0.19749,0.08335
172.6,14.384,37351.57,0.19784,0.08349
172.8,14.4,37346.42,0.19819,0.08362
173,14.417,37346.66,0.19853,0.08376
173.2,14.434,37350.58,0.19887,0.0839
173.4,14.45,37343.29,0.19922,0.08403
173.6,14.467,37346.33,0.19957,0.08417
173.8,14.484,37345.77,0.19991,0.0843
174,14.5,37345.9,0.20026,0.08444
174.2,14.517,37344.99,0.2006,0.08457
174.4,14.534,37342.18,0.20095,0.08471
174.6,14.55,37345.43,0.2013,0.08484
174.8,14.567,37349.54,0.20165,0.08498
175,14.584,37339.76,0.202,0.08511
175.2,14.6,37339.32,0.20235,0.08525
175.4,14.617,37345.08,0.20271,0.0854
175.6,14.634,37344.21,0.20306,0.08553
175.8,14.65,37343.95,0.20341,0.08567
176,14.667,37343.55,0.20377,0.08581
176.2,14.684,37341.81,0.20412,0.08595
176.4,14.7,37344.57,0.20447,0.08609
176.6,14.717,37343.36,0.20483,0.08623
176.8,14.734,37342.38,0.20518,0.08637
177,14.75,37344.88,0.20554,0.08651
177.2,14.767,37343.03,0.2059,0.08665
177.4,14.784,37344.83,0.20626,0.08679
177.6,14.8,37342.13,0.20661,0.08694
177.8,14.817,37338.43,0.20698,0.08708
178,14.834,37342.42,0.20733,0.08722
178.2,14.85,37340.31,0.2077,0.08736
178.4,14.867,37336.67,0.20806,0.0875
178.6,14.884,37337.51,0.20842,0.08765
178.8,14.9,37339.02,0.20879,0.08779
179,14.917,37341.29,0.20915,0.08793
179.2,14.934,37336.51,0.20952,0.08808
179.4,14.95,37334.18,0.20988,0.08822
179.6,14.967,37337.34,0.21025,0.08836
179.8,14.984,37331.76,0.21061,0.08851
180,15,37331.01,0.21097,0.08865
180.2,15.017,37334.05,0.21134,0.0888
180.4,15.034,37334.66,0.21171,0.08895
180.6,15.05,37328.46,0.21208,0.08909
180.8,15.067,37332.36,0.21244,0.08923
181,15.084,37329.14,0.21282,0.08938
181.2,15.1,37331.51,0.21319,0.08953
181.4,15.117,37329.64,0.21356,0.08967
181.6,15.134,37330.42,0.21393,0.08982
181.8,15.15,37327.96,0.2143,0.08996
182,15.167,37327.26,0.21467,0.09011
182.2,15.184,37325.66,0.21504,0.09026
182.4,15.2,37327.42,0.21541,0.09041
182.6,15.217,37323.51,0.21579,0.09056
182.8,15.234,37326.79,0.21617,0.09071
183,15.25,37322.79,0.21655,0.09086
183.2,15.267,37321.17,0.21692,0.09101
183.4,15.284,37321.21,0.2173,0.09116
183.6,15.3,37316.67,0.21768,0.09131
183.8,15.317,37318.4,0.21806,0.09146
184,15.334,37319.89,0.21844,0.09162
184.2,15.35,37312.72,0.21882,0.09177
184.4,15.367,37317.8,0.2192,0.09192
184.6,15.384,37315.97,0.21958,0.09208
184.8,15.4,37304.94,0.21996,0.09223
185,15.417,37314.31,0.22034,0.09239
185.2,15.434,37309.7,0.22073,0.09254
185.4,15.45,37299.06,0.22111,0.0927
185.6,15.467,37308.26,0.2215,0.09286
185.8,15.484,37303.33,0.22189,0.09302
186,15.5,37297.1,0.22228,0.09317
186.2,15.517,37301.77,0.22267,0.09333
186.4,15.534,37288.24,0.22305,0.09348
186.6,15.55,37303.21,0.22344,0.09364
186.8,15.567,37287.07,0.22383,0.0938
187,15.584,37280,0.22422,0.09395
187.2,15.6,37283.48,0.22461,0.09411
187.4,15.617,37280.93,0.225,0.09427
187.6,15.634,37279.64,0.2254,0.09443
187.8,15.65,37278.09,0.22579,0.09459
188,15.667,37274.67,0.22618,0.09475
188.2,15.684,37263.67,0.22658,0.09491
188.4,15.7,37267.43,0.22698,0.09507
188.6,15.717,37259.89,0.22737,0.09523
188.8,15.734,37257.44,0.22777,0.09539
189,15.75,37252.55,0.22817,0.09555
189.2,15.767,37252.9,0.22857,0.09571
189.4,15.784,37245.22,0.22896,0.09587
189.6,15.8,37247.66,0.22937,0.09604
189.8,15.817,37251.67,0.22977,0.0962
190,15.834,37238.04,0.23018,0.09637
190.2,15.85,37232.08,0.23058,0.09654
190.4,15.867,37233.93,0.23099,0.0967
190.6,15.884,37231.98,0.23139,0.09687
190.8,15.9,37225.84,0.2318,0.09704
191,15.917,37227.42,0.23222,0.09721
191.2,15.934,37219.18,0.23263,0.09738
191.4,15.95,37216.02,0.23304,0.09755
191.6,15.967,37206.82,0.23345,0.09772
191.8,15.984,37209.19,0.23386,0.0979
192,16,37202.4,0.23427,0.09806
192.2,16.017,37204.68,0.23469,0.09824
192.4,16.034,37197.63,0.2351,0.09841
192.6,16.05,37197.35,0.23552,0.09858
192.8,16.067,37194.48,0.23594,0.09876
193,16.084,37186.91,0.23636,0.09893
193.2,16.1,37186.01,0.23678,0.09911
193.4,16.117,37183.35,0.2372,0.09929
193.6,16.134,37181.71,0.23762,0.09947
193.8,16.15,37177.69,0.23805,0.09965
194,16.167,37172.73,0.23847,0.09983
194.2,16.184,37170.52,0.2389,0.10001
194.4,16.2,37169.16,0.23932,0.10018
194.6,16.217,37164.05,0.23975,0.10036
194.8,16.234,37169.77,0.24018,0.10054
195,16.25,37157.6,0.24061,0.10073
195.2,16.267,37166.01,0.24104,0.10091
195.4,16.284,37155.95,0.24147,0.1011
195.6,16.3,37151.75,0.2419,0.10128
195.8,16.317,37150.46,0.24233,0.10147
196,16.334,37151.8,0.24277,0.10166
196.2,16.35,37143.01,0.2432,0.10184
196.4,16.367,37146.34,0.24364,0.10203
196.6,16.384,37136.21,0.24408,0.10222
196.8,16.4,37142.14,0.24451,0.10241
197,16.417,37132.72,0.24496,0.1026
197.2,16.434,37137.02,0.24539,0.10278
197.4,16.45,37130.61,0.24584,0.10298
197.6,16.467,37125.85,0.24628,0.10317
197.8,16.484,37126.68,0.24673,0.10337
198,16.5,37123.06,0.24718,0.10356
198.2,16.517,37113.36,0.24763,0.10376
198.4,16.534,37117.86,0.24808,0.10396
198.6,16.55,37109.58,0.24853,0.10416
198.8,16.567,37106.25,0.24899,0.10436
199,16.584,37106.42,0.24944,0.10456
199.2,16.6,37095.46,0.2499,0.10477
199.4,16.617,37096.26,0.25035,0.10497
199.6,16.634,37091.38,0.25081,0.10518
199.8,16.65,37088.71,0.25126,0.10539
200,16.667,37085.89,0.25172,0.1056
200.2,16.684,37082.03,0.25218,0.10581
200.4,16.7,37081.19,0.25265,0.10602
200.6,16.717,37077.99,0.25311,0.10623
200.8,16.734,37065.61,0.25358,0.10645
201,16.75,37062.7,0.25405,0.10666
201.2,16.767,37057.62,0.25451,0.10688
201.4,16.784,37053.66,0.25498,0.1071
201.6,16.8,37047.94,0.25545,0.10731
201.8,16.817,37042.76,0.25592,0.10753
202,16.834,37033.93,0.25639,0.10775
202.2,16.85,37030.78,0.25686,0.10796
202.4,16.867,37029.68,0.25733,0.10819
202.6,16.883,37018.21,0.25781,0.10841
202.8,16.9,37020.35,0.25829,0.10864
203,16.917,37011.29,0.25876,0.10887
203.2,16.934,37001.82,0.25924,0.1091
203.4,16.95,37001.71,0.25972,0.10933
203.6,16.967,36989.26,0.26021,0.10957
203.8,16.984,36995.14,0.26069,0.1098
204,17,36982.77,0.26119,0.11004
204.2,17.017,36959.78,0.26168,0.11028
204.4,17.034,36969.23,0.26216,0.11052
204.6,17.05,36954.67,0.26265,0.11076
204.8,17.067,36953.97,0.26314,0.111
205,17.084,36945.21,0.26364,0.11124
205.2,17.1,36935.27,0.26414,0.11148
205.4,17.117,36924.83,0.26463,0.11172
205.6,17.134,36920.8,0.26513,0.11197
205.8,17.15,36922.16,0.26563,0.11222
206,17.167,36920.3,0.26613,0.11247
206.2,17.184,36903.04,0.26665,0.11272
206.4,17.2,36902.62,0.26714,0.11297
206.6,17.217,36903.23,0.26765,0.11322
206.8,17.233,36895.09,0.26816,0.11348
207,17.25,36893.21,0.26867,0.11373
207.2,17.267,36889.12,0.26918,0.11398
207.4,17.284,36885.66,0.26969,0.11423
207.6,17.3,36882.03,0.2702,0.11449
207.8,17.317,36878.16,0.27072,0.11475
208,17.334,36879.09,0.27124,0.11501
208.2,17.35,36876.62,0.27176,0.11528
208.4,17.367,36870.68,0.27228,0.11554
208.6,17.384,36869.67,0.27281,0.11581
208.8,17.4,36866.54,0.27334,0.11609
209,17.417,36863.24,0.27386,0.11636
209.2,17.434,36864.3,0.27439,0.11664
209.4,17.45,36860.48,0.27492,0.11692
209.6,17.467,36860.92,0.27545,0.1172
209.8,17.484,36854.66,0.27598,0.11748
210,17.5,36856.46,0.27652,0.11777
210.2,17.517,36853.31,0.27705,0.11807
210.4,17.534,36852.5,0.27759,0.11836
210.6,17.55,36852.38,0.27813,0.11865
210.8,17.567,36852.09,0.27867,0.11895
211,17.584,36850.58,0.27921,0.11925
211.2,17.6,36850.21,0.27976,0.11955
211.4,17.617,36849.08,0.2803,0.11985
211.6,17.634,36849.81,0.28086,0.12016
211.8,17.65,36847.54,0.2814,0.12046
212,17.667,36848.36,0.28195,0.12077
212.2,17.684,36845.99,0.28251,0.12108
212.4,17.7,36847,0.28306,0.1214
212.6,17.717,36844.98,0.28362,0.12173
212.8,17.734,36842.14,0.28417,0.12205
213,17.75,36843.34,0.28473,0.12238
213.2,17.767,36840.21,0.28529,0.12271
213.4,17.783,36830.29,0.28586,0.12303
213.6,17.8,36829.72,0.28643,0.12337
213.8,17.817,36817.73,0.28699,0.12371
214,17.834,36821.6,0.28756,0.12404
214.2,17.85,36804.64,0.28813,0.12438
214.4,17.867,36788.24,0.2887,0.12472
214.6,17.884,36778.65,0.28928,0.12506
214.8,17.9,36764.34,0.28986,0.1254
215,17.917,36745.77,0.29043,0.12573
215.2,17.934,36742.5,0.291,0.12608
215.4,17.95,36726.06,0.29158,0.12643
215.6,17.967,36719.8,0.29216,0.12679
215.8,17.984,36707.2,0.29275,0.12716
216,18,36700.02,0.29332,0.12752
216.2,18.017,36698.5,0.29391,0.12789
216.4,18.034,36690.29,0.2945,0.12827
216.6,18.05,36685.05,0.2951,0.12865
216.8,18.067,36681.34,0.2957,0.12903
217,18.084,36668.43,0.29629,0.1294
217.2,18.1,36660.14,0.29688,0.12978
217.4,18.117,36654.66,0.29748,0.13016
217.6,18.134,36642.72,0.29807,0.13054
217.8,18.15,36635.35,0.29867,0.13093
218,18.167,36628.04,0.29927,0.13133
218.2,18.184,36618.14,0.29986,0.13172
218.4,18.2,36606.32,0.30047,0.13213
218.6,18.217,36599.92,0.30108,0.13255
218.8,18.234,36588.33,0.30169,0.13296
219,18.25,36575.7,0.3023,0.13337
219.2,18.267,36567.21,0.30291,0.1338
219.4,18.284,36553.5,0.30351,0.13422
219.6,18.3,36552,0.30414,0.13466
219.8,18.317,36532.38,0.30475,0.13509
220,18.334,36532.79,0.30536,0.13553
220.2,18.35,36518.47,0.30598,0.13597
220.4,18.367,36506.52,0.3066,0.13641
220.6,18.384,36500.97,0.30722,0.13686
220.8,18.4,36488,0.30784,0.13731
221,18.417,36471.98,0.30847,0.13777
221.2,18.434,36451.59,0.3091,0.13823
221.4,18.45,36435.48,0.30972,0.13869
221.6,18.467,36421.62,0.31035,0.13915
221.8,18.484,36403.04,0.31099,0.13962
222,18.5,36385.98,0.31162,0.14009
222.2,18.517,36376.27,0.31226,0.14057
222.4,18.534,36358.05,0.31289,0.14104
222.6,18.55,36350.65,0.31352,0.14152
222.8,18.567,36339.02,0.31415,0.142
223,18.584,36330.26,0.31478,0.14249
223.2,18.6,36327.25,0.31542,0.14298
223.4,18.617,36317.7,0.31606,0.14347
223.6,18.634,36314.03,0.3167,0.14397
223.8,18.65,36307.99,0.31733,0.14447
224,18.667,36299.92,0.31798,0.14498
224.2,18.684,36291.12,0.31863,0.14548
224.4,18.7,36275.79,0.31927,0.14599
224.6,18.717,36256,0.31991,0.14649
224.8,18.734,36229.61,0.32056,0.14701
225,18.75,36201.95,0.32121,0.14753
225.2,18.767,36173.71,0.32186,0.14807
225.4,18.784,36131.79,0.32251,0.1486
225.6,18.8,36117.92,0.32316,0.14913
225.8,18.817,36103.43,0.3238,0.14966
226,18.834,36089.29,0.32446,0.15019
226.2,18.85,36076.35,0.3251,0.15072
226.4,18.867,36065.21,0.32575,0.15127
226.6,18.884,36050.93,0.32641,0.15182
226.8,18.9,36045.5,0.32706,0.15238
227,18.917,36032.48,0.32772,0.15293
227.2,18.934,36018.16,0.32839,0.15349
227.4,18.95,36002.53,0.32904,0.15404
227.6,18.967,35973.44,0.3297,0.15461
227.8,18.984,35948.64,0.33036,0.15518
228,19,35932.76,0.33101,0.15575
228.2,19.017,35914.48,0.33167,0.15633
228.4,19.034,35906.43,0.33233,0.15691
228.6,19.05,35897.99,0.33298,0.15749
228.8,19.067,35882.46,0.33365,0.15807
229,19.084,35872.29,0.33431,0.15866
229.2,19.1,35861.21,0.33497,0.15925
229.4,19.117,35837.25,0.33564,0.15984
229.6,19.134,35821.43,0.3363,0.16043
229.8,19.15,35796.31,0.33697,0.16103
230,19.167,35788.81,0.33763,0.16163
230.2,19.184,35779.57,0.33829,0.16222
230.4,19.2,35758.21,0.33895,0.16281
230.6,19.217,35730.88,0.33962,0.16341
230.8,19.234,35706.28,0.34028,0.16402
231,19.25,35684.27,0.34094,0.16462
231.2,19.267,35660.96,0.34161,0.16523
231.4,19.284,35635.12,0.34227,0.16584
231.6,19.3,35595.49,0.34294,0.16645
231.8,19.317,35561.54,0.34361,0.16706
232,19.334,35519.5,0.34427,0.16766
232.2,19.35,35489.73,0.34494,0.16826
232.4,19.367,35460.67,0.3456,0.16885
232.6,19.384,35444.91,0.34628,0.16946
232.8,19.4,35425.38,0.34695,0.17009
233,19.417,35404.44,0.34762,0.17071
233.2,19.434,35385.8,0.34828,0.17133
233.4,19.45,35361.62,0.34895,0.17196
233.6,19.467,35347.52,0.34962,0.17259
233.8,19.483,35329.82,0.35029,0.17321
234,19.5,35321.31,0.35097,0.17385
234.2,19.517,35306.62,0.35164,0.17448
234.4,19.534,35299.97,0.35231,0.17511
234.6,19.55,35295.74,0.35298,0.17576
234.8,19.567,35285.66,0.35366,0.17639
235,19.584,35270.79,0.35432,0.17703
235.2,19.6,35243.22,0.355,0.17767
235.4,19.617,35206.13,0.35567,0.17831
235.6,19.634,35176.44,0.35634,0.17895
235.8,19.65,35149.69,0.35702,0.17959
236,19.667,35119.42,0.35769,0.18023
236.2,19.684,35092.66,0.35836,0.18087
236.4,19.7,35070.66,0.35903,0.18152
236.6,19.717,35027.18,0.35971,0.18216
236.8,19.734,34973.55,0.36038,0.18281
237,19.75,34914.48,0.36107,0.18346
237.2,19.767,34864.95,0.36174,0.18411
237.4,19.784,34835.29,0.36241,0.18475
237.6,19.8,34825.63,0.36309,0.1854
237.8,19.817,34814.63,0.36376,0.18604
238,19.834,34793.89,0.36444,0.18668
238.2,19.85,34767.88,0.36511,0.18733
238.4,19.867,34731.3,0.36579,0.18798
238.6,19.884,34705.12,0.36645,0.18861
238.8,19.9,34666.01,0.36713,0.18926
239,19.917,34635.29,0.3678,0.18991
239.2,19.933,34614.04,0.36848,0.19055
239.4,19.95,34604.2,0.36916,0.1912
239.6,19.967,34580.71,0.36984,0.19185
239.8,19.984,34555.22,0.37051,0.19249
240,20,34533.74,0.3712,0.19315
240.2,20.017,34505.57,0.37187,0.1938
240.4,20.034,34482.42,0.37255,0.19444
240.6,20.05,34447.23,0.37322,0.19509
240.8,20.067,34389.81,0.3739,0.19573
241,20.084,34341.12,0.37458,0.19638
241.2,20.1,34316.8,0.37526,0.19703
241.4,20.117,34298.16,0.37594,0.19768
241.6,20.134,34281.79,0.37661,0.19833
241.8,20.15,34262.02,0.3773,0.19898
242,20.167,34244.3,0.37798,0.19963
242.2,20.184,34207.6,0.37866,0.20028
242.4,20.2,34155.69,0.37935,0.20093
242.6,20.217,34069.51,0.38003,0.20158
242.8,20.234,34017.11,0.38071,0.20222
243,20.25,33986.93,0.38138,0.20286
243.2,20.267,33966.29,0.38206,0.2035
243.4,20.284,33925.45,0.38274,0.20415
243.6,20.3,33871.3,0.38343,0.20478
243.8,20.317,33809.63,0.38411,0.20108
244,20.334,33799.62,0.38478,0.20125
244.2,20.35,33797.35,0.38547,0.20183
244.4,20.367,33795.59,0.38616,0.20243
244.6,20.384,33790.01,0.38683,0.20302
244.8,20.4,33769.34,0.38752,0.20361
245,20.417,33722.23,0.3882,0.2042
245.2,20.434,33686.04,0.38888,0.20478
245.4,20.45,33641.69,0.38957,0.20537
245.6,20.467,33580.93,0.39025,0.2059
245.8,20.484,33525.28,0.39093,0.20646
246,20.5,33468.18,0.39161,0.20703
246.2,20.517,33423.22,0.39229,0.20761
246.4,20.534,33386.7,0.39297,0.20818
246.6,20.55,33324.19,0.39366,0.20874
246.8,20.567,33258.66,0.39434,0.20929
247,20.584,33228.26,0.39503,0.20984
247.2,20.6,33208.09,0.39572,0.21036
247.4,20.617,33194.22,0.3964,0.2109
247.6,20.634,33180.7,0.39709,0.21144
247.8,20.65,33155.58,0.39777,0.21044
248,20.667,33112.67,0.39846,0.21101
248.2,20.684,33068.12,0.39914,0.21156
248.4,20.7,33023.62,0.39983,0.2121
248.6,20.717,32986.01,0.40052,0.21265
248.8,20.734,32929.53,0.4012,0.21319
249,20.75,32858.13,0.40189,0.21372
249.2,20.767,32803,0.40258,0.21423
249.4,20.784,32761.05,0.40326,0.21472
249.6,20.8,32740.83,0.40395,0.21522
249.8,20.817,32713.07,0.40464,0.21555
250,20.834,32669.84,0.40534,0.21608
250.2,20.85,32606.73,0.40603,0.2166
250.4,20.867,32548.27,0.40672,0.21711
250.6,20.884,32497.13,0.40741,0.21762
250.8,20.9,32435.95,0.4081,0.21811
251,20.917,32390.4,0.40879,0.21857
251.2,20.934,32369.67,0.40947,0.21899
251.4,20.95,32331.25,0.41016,0.21946
251.6,20.967,32301.29,0.41085,0.21993
251.8,20.984,32285.1,0.41154,0.21178
252,21,32245.16,0.41223,0.21249
252.2,21.017,32202.67,0.41292,0.21295
252.4,21.034,32139.29,0.41361,0.21341
252.6,21.05,32070.62,0.4143,0.21385
252.8,21.067,31995.71,0.415,0.21428
253,21.084,31928.18,0.41569,0.21472
253.2,21.1,31842.36,0.41638,0.21515
253.4,21.117,31763.08,0.41707,0.21558
253.6,21.134,31716.51,0.41776,0.216
253.8,21.15,31696.16,0.41846,0.21643
254,21.167,31673.08,0.41915,0.21685
254.2,21.184,31662.1,0.41984,0.21726
254.4,21.2,31584.54,0.42053,0.21767
254.6,21.217,31560.42,0.42123,0.21808
254.8,21.234,31521.73,0.42193,0.21847
255,21.25,31466.7,0.42262,0.21885
255.2,21.267,31389.91,0.42332,0.21923
255.4,21.284,31310.17,0.42401,0.21962
255.6,21.3,31226.94,0.42471,0.22001
255.8,21.317,31193.39,0.42541,0.21998
256,21.334,31172.84,0.4261,0.22037
256.2,21.35,31116.72,0.4268,0.22075
256.4,21.367,31039.27,0.4275,0.22112
256.6,21.384,30957.51,0.42819,0.22137
256.8,21.4,30925.28,0.42889,0.22098
257,21.417,30889.88,0.42958,0.22137
257.2,21.434,30812.62,0.43029,0.22173
257.4,21.45,30760.71,0.43098,0.22209
257.6,21.467,30700.84,0.43168,0.22245
257.8,21.484,30669.42,0.43238,0.22279
258,21.5,30615.91,0.43309,0.22313
258.2,21.517,30516.07,0.43378,0.22346
258.4,21.534,30433.83,0.4345,0.22376
258.6,21.55,30350.81,0.43519,0.2163
258.8,21.567,30298.42,0.43589,0.21665
259,21.584,30241.88,0.43658,0.21699
259.2,21.6,30178.07,0.43728,0.21732
259.4,21.617,30139.74,0.43799,0.21764
259.6,21.634,30122.92,0.43869,0.21795
259.8,21.65,30088.21,0.43939,0.21824
260,21.667,29980.64,0.4401,0.21854
260.2,21.684,29913.44,0.4408,0.21884
260.4,21.7,29812.38,0.44151,0.21914
260.6,21.717,29703.43,0.44221,0.21939
260.8,21.734,29656.91,0.44292,0.21966
261,21.75,29618.28,0.44362,0.21995
261.2,21.767,29572.23,0.44431,0.22024
261.4,21.784,29497.53,0.44502,0.2205
261.6,21.8,29443,0.44574,0.22074
261.8,21.817,29357.8,0.44643,0.22097
262,21.834,29279.34,0.44714,0.22121
262.2,21.85,29201.59,0.44784,0.22147
262.4,21.867,29137.1,0.44855,0.2217
262.6,21.884,29075.68,0.44926,0.22193
262.8,21.9,29011.21,0.44997,0.22214
263,21.917,28902.26,0.45068,0.22237
263.2,21.934,28840.38,0.4514,0.22256
263.4,21.95,28752.83,0.45211,0.22277
263.6,21.967,28644.64,0.45282,0.22297
263.8,21.984,28624.17,0.45354,0.22314
264,22,28589.57,0.45425,0.2233
264.2,22.017,28496.08,0.45496,0.22335
264.4,22.034,28419.14,0.45567,0.22353
264.6,22.05,28301.08,0.45637,0.2237
264.8,22.067,28205.04,0.4571,0.22388
265,22.084,28130.42,0.45781,0.22406
265.2,22.1,28091.16,0.45853,0.22423
265.4,22.117,28038.45,0.45925,0.22439
265.6,22.134,27901.07,0.45997,0.22454
265.8,22.15,27820.14,0.46068,0.22467
266,22.167,27718.3,0.4614,0.22479
266.2,22.184,27596.79,0.46211,0.22492
266.4,22.2,27555.24,0.46283,0.22505
266.6,22.217,27509.46,0.46355,0.22516
266.8,22.234,27416.16,0.46426,0.22527
267,22.25,27299.93,0.46499,0.22538
267.2,22.267,27199.62,0.4657,0.22549
267.4,22.284,27090.47,0.46643,0.2256
267.6,22.3,27046.2,0.46715,0.22569
267.8,22.317,27015.94,0.46787,0.22578
268,22.334,26869.64,0.4686,0.22587
268.2,22.35,26759,0.46933,0.22596
268.4,22.367,26645.2,0.47005,0.22604
268.6,22.384,26584.21,0.47078,0.22611
268.8,22.4,26475.03,0.47151,0.22618
269,22.417,26382.55,0.47224,0.22625
269.2,22.434,26245.98,0.47297,0.22627
269.4,22.45,26139.2,0.47369,0.22048
269.6,22.467,26051.23,0.47442,0.22055
269.8,22.484,26007.72,0.47516,0.22061
270,22.5,25526.77,0.47609,0.22067
270.044,22.504,14117.84,0.48516,0.21945