File: Labs/Lab 2 Tension/A36 Steel Sample 2.csv
Time (s),Extension (mm),Load (N),Axial Strain (mm/mm),Transverse Strain (mm/mm)
0,0,0.99,0,0
0.3,0.024,761.47,0.00007,0
0.6,0.05,1204.26,0.00013,0
0.9,0.075,1538,0.00019,-0.00001
1.2,0.1,1771.37,0.00024,-0.00002
1.5,0.125,2028.2,0.00029,-0.00002
1.8,0.15,2166.07,0.00032,-0.00003
2.1,0.175,2392.72,0.00036,-0.00003
2.4,0.2,2645.9,0.00038,-0.00003
2.7,0.225,2810.11,0.0004,-0.00003
3,0.25,3093.76,0.00043,-0.00003
3.3,0.275,3335.92,0.00045,-0.00003
3.6,0.3,3621.16,0.00047,-0.00003
3.9,0.325,3819.47,0.00049,-0.00003
4.2,0.35,4143.6,0.00051,-0.00003
4.5,0.375,4408.57,0.00054,-0.00003
4.8,0.4,4690.16,0.00055,-0.00002
5.1,0.425,4966.55,0.00058,-0.00001
5.4,0.45,5248.88,0.0006,0.00003
5.7,0.475,5605.39,0.00062,0.00006
6,0.5,5915.1,0.00064,0.00007
6.3,0.525,6215.3,0.00066,0.00008
6.6,0.55,6582.63,0.00068,0.00008
6.9,0.575,6879.58,0.0007,0.00008
7.2,0.6,7267.88,0.00073,0.00009
7.5,0.625,7598.09,0.00074,0.0001
7.8,0.65,7910.79,0.00077,0.0001
8.1,0.675,8308.26,0.00079,0.00012
8.4,0.7,8661.57,0.00081,0.00013
8.7,0.725,9022.17,0.00083,0.00014
9,0.75,9347.25,0.00086,0.00015
9.3,0.775,9811.44,0.00088,0.00017
9.6,0.8,10135.97,0.0009,0.00018
9.9,0.825,10472.25,0.00092,0.00019
10.2,0.85,10890.23,0.00094,0.0002
10.5,0.875,11264.3,0.00096,0.00021
10.8,0.9,11655.63,0.00099,0.00021
11.1,0.925,12018.4,0.00101,0.00022
11.4,0.95,12437.58,0.00103,0.00023
11.7,0.975,12849.77,0.00106,0.00025
12,1,13279.97,0.00108,0.00026
12.3,1.025,13602.51,0.0011,0.00028
12.6,1.05,14021.14,0.00113,0.00028
12.9,1.075,14439.01,0.00116,0.00029
13.2,1.1,14893.79,0.00118,0.0003
13.5,1.125,15266.67,0.00121,0.00032
13.8,1.15,15687.37,0.00124,0.00033
14.1,1.175,16066.01,0.00127,0.00035
14.4,1.2,16535.71,0.0013,0.00036
14.7,1.225,16933.29,0.00133,0.00037
15,1.25,17346.8,0.00137,0.00038
15.3,1.275,17742.21,0.0014,0.00039
15.6,1.3,18128.21,0.00144,0.00041
15.9,1.325,18611.42,0.00148,0.00042
16.2,1.35,19027.12,0.00152,0.00044
16.5,1.375,19458.4,0.00156,0.00045
16.8,1.4,19791.02,0.0016,0.00047
17.1,1.425,20260.64,0.00165,0.00048
17.4,1.45,20649.36,0.00169,0.0005
17.7,1.475,21113.11,0.00174,0.00052
18,1.5,21488.85,0.0018,0.00053
18.3,1.525,21831.01,0.00184,0.00055
18.6,1.55,22265.96,0.0019,0.00057
18.9,1.575,22637.21,0.00195,0.00059
19.2,1.6,23114.58,0.002,0.00062
19.5,1.625,23397.92,0.00206,0.00065
19.8,1.65,23812.54,0.00211,0.00068
20.1,1.675,24171.11,0.00215,0.00071
20.4,1.7,24499.83,0.00218,0.00074
20.7,1.725,24776.77,0.0022,0.00079
21,1.75,24995.76,0.00221,0.00085
21.3,1.775,25263.4,0.00223,0.0009
21.6,1.8,25315.55,0.00226,0.00097
21.9,1.825,25313.68,0.00233,0.00104
22.2,1.85,25293.25,0.00253,0.00108
22.5,1.875,25308.88,0.00284,0.00112
22.8,1.9,25331.94,0.00321,0.00115
23.1,1.925,25383.86,0.00366,0.00117
23.4,1.95,25467.18,0.00416,0.0012
23.7,1.975,25480.45,0.00475,0.00124
24,2,25464.95,0.00537,0.00131
24.3,2.025,25447.6,0.00601,0.00149
24.6,2.05,25451.71,0.00664,0.0021
24.9,2.075,25439.29,0.0073,0.00286
25.2,2.1,25405.08,0.008,0.00373
25.5,2.125,25414.88,0.00869,0.00467
25.8,2.15,25457.49,0.00935,0.00546
26.1,2.175,25443.01,0.01,0.00603
26.4,2.2,25318.34,0.01066,0.0064
26.7,2.225,25181.49,0.01107,0.0065
27,2.25,25070.88,0.01126,0.00649
27.3,2.275,25030.42,0.01142,0.00644
27.6,2.3,25024.15,0.0116,0.00638
27.9,2.325,25037.6,0.01184,0.00632
28.2,2.35,25102.22,0.01211,0.00623
28.5,2.375,25287.07,0.01233,0.00615
28.8,2.4,25331.68,0.0125,0.0061
29.1,2.425,25308.51,0.01257,0.00615
29.4,2.45,25263.08,0.0126,0.00619
29.7,2.475,25311.5,0.01266,0.00621
30,2.5,25472.86,0.01276,0.00624
30.3,2.525,25691.05,0.0129,0.0063
30.6,2.55,25857.49,0.01307,0.0064
30.9,2.575,25966.14,0.01328,0.00653
31.2,2.6,26075.35,0.01351,0.00667
31.5,2.625,26222.44,0.01375,0.00682
31.8,2.65,26294.18,0.01401,0.00696
32.1,2.675,26327.18,0.01427,0.00711
32.4,2.7,26417.7,0.01454,0.00726
32.7,2.725,26528.17,0.01481,0.00741
33,2.75,26654.97,0.01507,0.00755
33.3,2.775,26748.56,0.01534,0.0077
33.6,2.8,26810.17,0.0156,0.00785
33.9,2.825,26839.33,0.01587,0.00799
34.2,2.85,26933.72,0.01612,0.00813
34.5,2.875,27052.31,0.01638,0.00827
34.8,2.9,27126.4,0.01665,0.00842
35.1,2.925,27252.46,0.01691,0.00856
35.4,2.95,27358.21,0.01717,0.0087
35.7,2.975,27386.31,0.01743,0.00885
36,3,27422.09,0.01769,0.00899
36.3,3.025,27519.66,0.01795,0.00913
36.6,3.05,27650.32,0.01821,0.00927
36.9,3.075,27726.12,0.01848,0.00941
37.2,3.1,27820.84,0.01874,0.00955
37.5,3.125,27872.55,0.019,0.00969
37.8,3.15,27892.9,0.01927,0.00983
38.1,3.175,27980.37,0.01954,0.00997
38.4,3.2,28087.69,0.0198,0.01011
38.7,3.225,28154.59,0.02006,0.01025
39,3.25,28234.69,0.02033,0.01038
39.3,3.275,28323.71,0.0206,0.01051
39.6,3.3,28394.69,0.02086,0.01066
39.9,3.325,28451.31,0.02114,0.0108
40.2,3.35,28524.57,0.0214,0.01094
40.5,3.375,28603.6,0.02167,0.01107
40.8,3.4,28698.48,0.02194,0.01122
41.1,3.425,28759.91,0.02221,0.01136
41.4,3.45,28856.54,0.02248,0.0115
41.7,3.475,28885.29,0.02275,0.01164
42,3.5,28911.34,0.02301,0.01179
42.3,3.525,28972.32,0.02328,0.01193
42.6,3.55,29081.09,0.02354,0.01207
42.9,3.575,29178.79,0.02381,0.01221
43.2,3.6,29255.97,0.02408,0.01235
43.5,3.625,29345.2,0.02435,0.01249
43.8,3.65,29386.73,0.02463,0.01264
44.1,3.675,29412.05,0.0249,0.01278
44.4,3.7,29443.51,0.02517,0.01292
44.7,3.725,29514.04,0.02545,0.01306
45,3.75,29584.52,0.02573,0.0132
45.3,3.775,29649.38,0.026,0.01334
45.6,3.8,29727.46,0.02629,0.01349
45.9,3.825,29843.45,0.02657,0.01363
46.2,3.85,29915.64,0.02685,0.01377
46.5,3.875,29955.98,0.02713,0.01391
46.8,3.9,29991.63,0.02741,0.01405
47.1,3.925,30036.77,0.02769,0.0142
47.4,3.95,30125.07,0.02798,0.01434
47.7,3.975,30166.56,0.02826,0.01449
48,4,30216.44,0.02855,0.01464
48.3,4.025,30265.49,0.02883,0.01478
48.6,4.05,30355.93,0.02912,0.01493
48.9,4.075,30411.08,0.0294,0.01508
49.2,4.1,30452.95,0.0297,0.01523
49.5,4.125,30478.31,0.02998,0.01538
49.8,4.15,30531.61,0.03027,0.01553
50.1,4.175,30628.49,0.03056,0.01568
50.4,4.2,30703.51,0.03085,0.01583
50.7,4.225,30774.05,0.03115,0.01598
51,4.25,30806.24,0.03144,0.01613
51.3,4.275,30867.9,0.03173,0.01627
51.6,4.3,30925.02,0.03202,0.01642
51.9,4.325,30932.66,0.03231,0.01656
52.2,4.35,30944.26,0.0326,0.01671
52.5,4.375,30967.12,0.03289,0.01686
52.8,4.4,31013.21,0.03318,0.01701
53.1,4.425,31095.92,0.03347,0.01716
53.4,4.45,31174.55,0.03377,0.01731
53.7,4.475,31253.84,0.03406,0.01746
54,4.5,31314.39,0.03436,0.01761
54.3,4.525,31369.88,0.03465,0.01776
54.6,4.55,31446.7,0.03494,0.01791
54.9,4.575,31500.57,0.03524,0.01806
55.2,4.6,31543.04,0.03553,0.01821
55.5,4.625,31558.64,0.03582,0.01836
55.8,4.65,31583.79,0.03612,0.01851
56.1,4.675,31622.69,0.03642,0.01866
56.4,4.7,31647.24,0.03671,0.01881
56.7,4.725,31674.6,0.03701,0.01896
57,4.75,31727.96,0.03731,0.01911
57.3,4.775,31789.33,0.0376,0.01926
57.6,4.8,31859.13,0.0379,0.01942
57.9,4.825,31928.72,0.03819,0.01957
58.2,4.85,31963.37,0.03849,0.01972
58.5,4.875,31992.55,0.0388,0.01988
58.8,4.9,32018.23,0.0391,0.02003
59.1,4.925,32046.06,0.03939,0.02018
59.4,4.95,32098.32,0.03969,0.02033
59.7,4.975,32166.54,0.03999,0.02048
60,5,32220.36,0.04029,0.02063
60.3,5.025,32261.45,0.04059,0.02078
60.6,5.05,32313.07,0.04089,0.02093
60.9,5.075,32349.5,0.04119,0.02109
61.2,5.1,32385.61,0.0415,0.02124
61.5,5.125,32427.29,0.0418,0.02139
61.8,5.15,32441.56,0.0421,0.02154
62.1,5.175,32454.67,0.04241,0.02169
62.4,5.2,32465.94,0.04271,0.02183
62.7,5.225,32488.98,0.04301,0.02198
63,5.25,32517.69,0.04332,0.02213
63.3,5.275,32575.56,0.04362,0.02228
63.6,5.3,32645.43,0.04393,0.02243
63.9,5.325,32695.45,0.04424,0.02259
64.2,5.35,32738.09,0.04454,0.02274
64.5,5.375,32781.02,0.04485,0.02289
64.8,5.4,32838.32,0.04516,0.02305
65.1,5.425,32882.4,0.04547,0.02321
65.4,5.45,32940.45,0.04577,0.02336
65.7,5.475,32994.7,0.04608,0.02352
66,5.5,33040.76,0.04639,0.02367
66.3,5.525,33054.08,0.04669,0.02382
66.6,5.55,33055.97,0.047,0.02398
66.9,5.575,33057.36,0.04731,0.02414
67.2,5.6,33057.79,0.04762,0.02429
67.5,5.625,33061.77,0.04793,0.02444
67.8,5.65,33081.85,0.04824,0.0246
68.1,5.675,33130.25,0.04855,0.02475
68.4,5.7,33185.96,0.04885,0.02489
68.7,5.725,33220.68,0.04916,0.02505
69,5.75,33256.74,0.04948,0.02521
69.3,5.775,33294.3,0.04979,0.02536
69.6,5.8,33344.5,0.0501,0.02551
69.9,5.825,33382.98,0.05041,0.02566
70.2,5.85,33443.41,0.05072,0.02582
70.5,5.875,33488.7,0.05103,0.02596
70.8,5.9,33514.07,0.05134,0.02612
71.1,5.925,33533.2,0.05165,0.02628
71.4,5.95,33555.62,0.05197,0.02644
71.7,5.975,33571.59,0.05228,0.02659
72,6,33594.22,0.0526,0.02675
72.3,6.025,33622.78,0.05291,0.0269
72.6,6.05,33666.6,0.05322,0.02706
72.9,6.075,33720.38,0.05354,0.02721
73.2,6.1,33745.11,0.05385,0.02737
73.5,6.125,33766.08,0.05417,0.02752
73.8,6.15,33788.55,0.05449,0.02768
74.1,6.175,33814.78,0.0548,0.02784
74.4,6.2,33836.56,0.05512,0.028
74.7,6.225,33850.47,0.05544,0.02815
75,6.25,33864.24,0.05575,0.0283
75.3,6.275,33875.81,0.05607,0.02845
75.6,6.3,33903.04,0.05639,0.0286
75.9,6.325,33937.41,0.0567,0.02876
76.2,6.35,33970.59,0.05702,0.02891
76.5,6.375,33995.11,0.05734,0.02906
76.8,6.4,34023.1,0.05766,0.02922
77.1,6.425,34048.69,0.05798,0.02937
77.4,6.45,34067.93,0.0583,0.02952
77.7,6.475,34085.26,0.05861,0.02968
78,6.5,34094.21,0.05893,0.02982
78.3,6.525,34110.8,0.05924,0.02998
78.6,6.55,34136.79,0.05957,0.03013
78.9,6.575,34202.47,0.05988,0.03028
79.2,6.6,34246.25,0.0602,0.03043
79.5,6.625,34279.77,0.06052,0.03059
79.8,6.65,34314.86,0.06085,0.03075
80.1,6.675,34342.3,0.06116,0.0309
80.4,6.7,34380.35,0.06149,0.03105
80.7,6.725,34403.02,0.0618,0.0312
81,6.75,34425.14,0.06213,0.03136
81.3,6.775,34459.06,0.06245,0.03152
81.6,6.8,34500.59,0.06278,0.03167
81.9,6.825,34527.59,0.0631,0.03183
82.2,6.85,34548.05,0.06343,0.03198
82.5,6.875,34557.18,0.06375,0.03214
82.8,6.9,34559.98,0.06407,0.03229
83.1,6.925,34560.49,0.0644,0.03245
83.4,6.95,34561.05,0.06472,0.0326
83.7,6.975,34562.02,0.06505,0.03276
84,7,34565.33,0.06538,0.03292
84.3,7.025,34578,0.06571,0.03308
84.6,7.05,34586.59,0.06603,0.03323
84.9,7.075,34602.21,0.06636,0.03339
85.2,7.1,34631.1,0.06669,0.03355
85.5,7.125,34650.27,0.06702,0.0337
85.8,7.15,34683.06,0.06735,0.03387
86.1,7.175,34702.36,0.06768,0.03403
86.4,7.2,34717.05,0.068,0.03419
86.7,7.225,34745.3,0.06833,0.03434
87,7.25,34778.09,0.06867,0.03451
87.3,7.275,34813.78,0.069,0.03467
87.6,7.3,34837.39,0.06933,0.03484
87.9,7.325,34875.07,0.06967,0.035
88.2,7.35,34889.61,0.07,0.03516
88.5,7.375,34921.47,0.07034,0.03532
88.8,7.4,34935.81,0.07067,0.03548
89.1,7.425,34961.61,0.07101,0.03564
89.4,7.45,34984.25,0.07134,0.0358
89.7,7.475,35023.25,0.07168,0.03596
90,7.5,35040.13,0.07202,0.03611
90.3,7.525,35052.3,0.07235,0.03628
90.6,7.55,35061.5,0.07269,0.03643
90.9,7.575,35073.44,0.07302,0.03659
91.2,7.6,35086.79,0.07336,0.03675
91.5,7.625,35102.02,0.0737,0.03691
91.8,7.65,35121.3,0.07404,0.03706
92.1,7.675,35141.14,0.07438,0.03721
92.4,7.7,35147.2,0.07473,0.03738
92.7,7.725,35153.39,0.07507,0.03753
93,7.75,35162.68,0.0754,0.03769
93.3,7.775,35177.21,0.07575,0.03786
93.6,7.8,35188.32,0.07609,0.03802
93.9,7.825,35199.52,0.07644,0.03818
94.2,7.85,35219.83,0.07678,0.03835
94.5,7.875,35251.59,0.07712,0.03851
94.8,7.9,35266,0.07747,0.03868
95.1,7.925,35276.72,0.07782,0.03884
95.4,7.95,35284.89,0.07816,0.03901
95.7,7.975,35291.12,0.0785,0.03917
96,8,35302.83,0.07885,0.03932
96.3,8.025,35312.51,0.07919,0.03948
96.6,8.05,35330.59,0.07953,0.03963
96.9,8.075,35334.49,0.07988,0.03979
97.2,8.1,35352.88,0.08022,0.03994
97.5,8.125,35367.69,0.08057,0.0401
97.8,8.15,35371,0.08092,0.04025
98.1,8.175,35390.38,0.08126,0.0404
98.4,8.2,35419.75,0.08161,0.04055
98.7,8.225,35462.47,0.08196,0.04071
99,8.25,35469.75,0.0823,0.04086
99.3,8.275,35505.89,0.08265,0.04102
99.6,8.3,35525.84,0.083,0.04118
99.9,8.325,35541.21,0.08335,0.04133
100.2,8.35,35552.57,0.08369,0.04149
100.5,8.375,35562.49,0.08404,0.04164
100.8,8.4,35572.71,0.08439,0.04181
101.1,8.425,35580.88,0.08474,0.04197
101.4,8.45,35588.94,0.08509,0.04212
101.7,8.475,35594.2,0.08544,0.04228
102,8.5,35603.88,0.08579,0.04244
102.3,8.525,35607.12,0.08614,0.0426
102.6,8.55,35613.82,0.08649,0.04275
102.9,8.575,35628.2,0.08684,0.04292
103.2,8.6,35636.04,0.08719,0.04308
103.5,8.625,35641.78,0.08754,0.04324
103.8,8.65,35653.95,0.08789,0.0434
104.1,8.675,35672.14,0.08824,0.04355
104.4,8.7,35686.1,0.08859,0.04372
104.7,8.725,35721.21,0.08894,0.04387
105,8.75,35745.72,0.08929,0.04404
105.3,8.775,35765.25,0.08965,0.0442
105.6,8.8,35767.84,0.09,0.04436
105.9,8.825,35790.62,0.09035,0.04453
106.2,8.85,35810.78,0.0907,0.04469
106.5,8.875,35813.48,0.09105,0.04485
106.8,8.9,35825.67,0.0914,0.04501
107.1,8.925,35835.26,0.09175,0.04517
107.4,8.95,35842.94,0.09211,0.04533
107.7,8.975,35851.38,0.09246,0.04549
108,9,35863.81,0.09282,0.04565
108.3,9.025,35876.73,0.09317,0.04581
108.6,9.05,35884.49,0.09352,0.04596
108.9,9.075,35901.33,0.09387,0.04612
109.2,9.1,35915.68,0.09423,0.04628
109.5,9.125,35923.98,0.09458,0.04644
109.8,9.15,35932.86,0.09494,0.0466
110.1,9.175,35943.69,0.09529,0.04676
110.4,9.2,35952.72,0.09565,0.04692
110.7,9.225,35959.86,0.09601,0.04709
111,9.25,35966.93,0.09635,0.04725
111.3,9.275,35976.3,0.0967,0.04741
111.6,9.3,35995.37,0.09706,0.04757
111.9,9.325,36012.11,0.09741,0.04773
112.2,9.35,36014.51,0.09776,0.04789
112.5,9.375,36018.3,0.09811,0.04805
112.8,9.4,36039.14,0.09847,0.0482
113.1,9.425,36051.79,0.09882,0.04836
113.4,9.45,36058.94,0.09917,0.04852
113.7,9.475,36067.93,0.09952,0.04868
114,9.5,36073.75,0.09987,0.04884
114.3,9.525,36077.19,0.10022,0.049
114.6,9.55,36083.56,0.10057,0.04916
114.9,9.575,36093.82,0.10093,0.04933
115.2,9.6,36095.31,0.10129,0.04949
115.5,9.625,36099.98,0.10164,0.04966
115.8,9.65,36103.39,0.102,0.04982
116.1,9.675,36105.1,0.10236,0.04998
116.4,9.7,36107.58,0.10272,0.05014
116.7,9.725,36109.74,0.10308,0.0503
117,9.75,36110.16,0.10344,0.05047
117.3,9.775,36111.11,0.1038,0.05064
117.6,9.8,36112.8,0.10416,0.05079
117.9,9.825,36114.78,0.10452,0.05096
118.2,9.85,36116.14,0.10488,0.05113
118.5,9.875,36118.31,0.10525,0.05129
118.8,9.9,36118.64,0.1056,0.05146
119.1,9.925,36124.56,0.10597,0.05161
119.4,9.95,36125.09,0.10633,0.05178
119.7,9.975,36126.72,0.10669,0.05194
120,10,36133.3,0.10705,0.0521
120.3,10.025,36139.1,0.10742,0.05226
120.6,10.05,36150.12,0.10779,0.05243
120.9,10.075,36153.59,0.10815,0.05259
121.2,10.1,36165.82,0.10852,0.05275
121.5,10.125,36184.56,0.10888,0.05292
121.8,10.15,36194.46,0.10925,0.05309
122.1,10.175,36199.01,0.10961,0.05325
122.4,10.2,36225.34,0.10998,0.05341
122.7,10.225,36231.52,0.11035,0.05358
123,10.25,36238.59,0.11072,0.05375
123.3,10.275,36257.96,0.11109,0.05392
123.6,10.3,36270.64,0.11147,0.05408
123.9,10.325,36272.89,0.11184,0.05425
124.2,10.35,36287.05,0.11221,0.05441
124.5,10.375,36300.84,0.11258,0.05458
124.8,10.4,36302.92,0.11295,0.05474
125.1,10.425,36313.22,0.11333,0.0549
125.4,10.45,36326.63,0.11369,0.05506
125.7,10.475,36336.73,0.11407,0.05522
126,10.5,36342,0.11444,0.05538
126.3,10.525,36360.45,0.11482,0.05554
126.6,10.55,36367.29,0.11519,0.05569
126.9,10.575,36366.18,0.11556,0.05585
127.2,10.6,36378.62,0.11593,0.05601
127.5,10.625,36388.71,0.11631,0.05617
127.8,10.65,36393.97,0.11668,0.05634
128.1,10.675,36398.44,0.11706,0.0565
128.4,10.7,36403.29,0.11744,0.05667
128.7,10.725,36415.23,0.11781,0.05684
129,10.75,36411.88,0.11819,0.05701
129.3,10.775,36421.95,0.11856,0.05717
129.6,10.8,36427.63,0.11894,0.05734
129.9,10.825,36434.24,0.11931,0.0575
130.2,10.85,36433.18,0.11969,0.05766
130.5,10.875,36437.23,0.12007,0.05783
130.8,10.9,36445.63,0.12045,0.058
131.1,10.925,36453.17,0.12083,0.05816
131.4,10.95,36455.62,0.12121,0.05834
131.7,10.975,36457,0.12159,0.05851
132,11,36479.75,0.12197,0.05868
132.3,11.025,36476.48,0.12235,0.05885
132.6,11.05,36479.04,0.12272,0.05901
132.9,11.075,36490.98,0.1231,0.05918
133.2,11.1,36506.06,0.12348,0.05934
133.5,11.125,36521.69,0.12386,0.05951
133.8,11.15,36528.68,0.12425,0.05968
134.1,11.175,36533.76,0.12463,0.05984
134.4,11.2,36537.14,0.125,0.06001
134.7,11.225,36541.12,0.12538,0.06018
135,11.25,36566.59,0.12577,0.06035
135.3,11.275,36574.78,0.12615,0.06052
135.6,11.3,36575.45,0.12654,0.06068
135.9,11.325,36579.87,0.12692,0.06085
136.2,11.35,36584.43,0.1273,0.06101
136.5,11.375,36587.57,0.12769,0.06118
136.8,11.4,36590.52,0.12807,0.06135
137.1,11.425,36596.49,0.12846,0.06151
137.4,11.45,36602.61,0.12884,0.06167
137.7,11.475,36601.69,0.12922,0.06184
138,11.5,36605.56,0.12961,0.062
138.3,11.525,36607.55,0.12999,0.06217
138.6,11.55,36609.91,0.13039,0.06233
138.9,11.575,36609.77,0.13077,0.0625
139.2,11.6,36611.66,0.13116,0.06267
139.5,11.625,36612.23,0.13155,0.06284
139.8,11.65,36613.98,0.13193,0.06301
140.1,11.675,36616.62,0.13232,0.06318
140.4,11.7,36615.14,0.1327,0.06335
140.7,11.725,36618.2,0.1331,0.06352
141,11.75,36618.71,0.13348,0.06369
141.3,11.775,36620.16,0.13387,0.06386
141.6,11.8,36622.26,0.13426,0.06402
141.9,11.825,36623.91,0.13465,0.06419
142.2,11.85,36625.29,0.13504,0.06436
142.5,11.875,36626.31,0.13543,0.06454
142.8,11.9,36627.32,0.13582,0.06471
143.1,11.925,36632.45,0.13621,0.06488
143.4,11.95,36634.72,0.1366,0.06505
143.7,11.975,36632.71,0.137,0.06522
144,12,36633.96,0.13739,0.06539
144.3,12.025,36638.48,0.13779,0.06557
144.6,12.05,36640.73,0.13818,0.06574
144.9,12.075,36642.76,0.13858,0.0659
145.2,12.1,36641.67,0.13897,0.06607
145.5,12.125,36646.4,0.13937,0.06624
145.8,12.15,36646,0.13977,0.06641
146.1,12.175,36644.86,0.14016,0.06658
146.4,12.2,36647.02,0.14056,0.06675
146.7,12.225,36648.96,0.14096,0.06692
147,12.25,36650.28,0.14135,0.06783
147.3,12.275,36648.57,0.14175,0.06809
147.6,12.3,36652.27,0.14215,0.06828
147.9,12.325,36655.54,0.14254,0.06848
148.2,12.35,36658.65,0.14294,0.06868
148.5,12.375,36651.63,0.14334,0.06887
148.8,12.4,36659.86,0.14375,0.06905
149.1,12.425,36658.11,0.14414,0.06923
149.4,12.45,36662.3,0.14455,0.06941
149.7,12.475,36661.98,0.14495,0.06959
150,12.5,36661.59,0.14535,0.06977
150.3,12.525,36662.77,0.14576,0.06995
150.6,12.55,36664.05,0.14616,0.07012
150.9,12.575,36665.94,0.14656,0.0703
151.2,12.6,36665.73,0.14697,0.07048
151.5,12.625,36666.27,0.14738,0.07066
151.8,12.65,36664.33,0.14778,0.07084
152.1,12.675,36663.96,0.14819,0.07102
152.4,12.7,36670.88,0.1486,0.0712
152.7,12.725,36668.77,0.14901,0.07137
153,12.75,36671.74,0.14941,0.07155
153.3,12.775,36671.63,0.14982,0.07172
153.6,12.8,36672.68,0.15023,0.0719
153.9,12.825,36671.67,0.15064,0.07208
154.2,12.85,36674.13,0.15106,0.07226
154.5,12.875,36674.69,0.15146,0.07244
154.8,12.9,36673.3,0.15188,0.07261
155.1,12.925,36674.66,0.15229,0.07279
155.4,12.95,36675.54,0.1527,0.07297
155.7,12.975,36674.45,0.15311,0.07314
156,13,36672.12,0.15353,0.07331
156.3,13.025,36672.73,0.15395,0.07349
156.6,13.05,36682,0.15436,0.07366
156.9,13.075,36673.96,0.15478,0.07383
157.2,13.1,36673.26,0.1552,0.07401
157.5,13.125,36685.14,0.15562,0.07418
157.8,13.15,36684.32,0.15603,0.07436
158.1,13.175,36683.62,0.15645,0.07453
158.4,13.2,36681.09,0.15686,0.0747
158.7,13.225,36680.67,0.15729,0.07487
159,13.25,36681.82,0.15771,0.07504
159.3,13.275,36678.83,0.15812,0.07521
159.6,13.3,36685.07,0.15855,0.07537
159.9,13.325,36695.2,0.15897,0.07554
160.2,13.35,36681.99,0.15939,0.07572
160.5,13.375,36682.7,0.15981,0.07591
160.8,13.4,36686.11,0.16024,0.07609
161.1,13.425,36698.39,0.16066,0.07627
161.4,13.45,36692.02,0.16108,0.07643
161.7,13.475,36692.61,0.16151,0.07661
162,13.5,36689.28,0.16194,0.07678
162.3,13.525,36688.75,0.16237,0.07696
162.6,13.55,36684.4,0.16279,0.07712
162.9,13.575,36687.54,0.16322,0.07728
163.2,13.6,36689.5,0.16364,0.07747
163.5,13.625,36686.45,0.16407,0.07765
163.8,13.65,36689.52,0.1645,0.07783
164.1,13.675,36690.9,0.16493,0.078
164.4,13.7,36690.48,0.16536,0.07818
164.7,13.725,36689.8,0.16579,0.07835
165,13.75,36698.69,0.16623,0.07853
165.3,13.775,36697.96,0.16666,0.07871
165.6,13.8,36693.86,0.16709,0.07888
165.9,13.825,36696.02,0.16753,0.07906
166.2,13.85,36691.58,0.16796,0.07924
166.5,13.875,36696.81,0.1684,0.07942
166.8,13.9,36694.23,0.16884,0.0796
167.1,13.925,36692.3,0.16928,0.07978
167.4,13.95,36705.68,0.16971,0.07996
167.7,13.975,36693.85,0.17015,0.08014
168,14,36695.91,0.17059,0.08032
168.3,14.025,36693.94,0.17103,0.08049
168.6,14.05,36694.88,0.17147,0.08067
168.9,14.075,36695.61,0.17191,0.08085
169.2,14.1,36696.32,0.17235,0.08103
169.5,14.125,36697.4,0.1728,0.08122
169.8,14.15,36694.39,0.17325,0.0814
170.1,14.175,36697.49,0.17369,0.08158
170.4,14.2,36693.54,0.17413,0.08176
170.7,14.225,36689.78,0.17458,0.08195
171,14.25,36690.87,0.17503,0.08213
171.3,14.275,36692,0.17547,0.08231
171.6,14.3,36695.86,0.17593,0.0825
171.9,14.325,36693.58,0.17638,0.08268
172.2,14.35,36697.33,0.17683,0.08286
172.5,14.375,36696.97,0.17728,0.08304
172.8,14.4,36697.37,0.17774,0.08322
173.1,14.425,36689.47,0.17819,0.0834
173.4,14.45,36694.66,0.17864,0.08357
173.7,14.475,36687.45,0.1791,0.08375
174,14.5,36693.91,0.17955,0.08393
174.3,14.525,36685.88,0.17984,0.08411
174.6,14.55,36698.71,0.18015,0.08427
174.9,14.575,36689.65,0.18063,0.08445
175.2,14.6,36681.12,0.18112,0.08464
175.5,14.625,36684.29,0.18159,0.08481
175.8,14.65,36687.98,0.18208,0.08499
176.1,14.675,36682.2,0.18256,0.08517
176.4,14.7,36680.95,0.18304,0.08536
176.7,14.725,36684.49,0.18352,0.08554
177,14.75,36682.93,0.184,0.08573
177.3,14.775,36683.32,0.18448,0.08592
177.6,14.8,36682.18,0.18496,0.0861
177.9,14.825,36682.91,0.18544,0.08628
178.2,14.85,36683.66,0.18592,0.08647
178.5,14.875,36685.14,0.18641,0.08666
178.8,14.9,36681.46,0.18688,0.08685
179.1,14.925,36677.25,0.18737,0.08705
179.4,14.95,36680.21,0.18785,0.08724
179.7,14.975,36677.42,0.18834,0.08744
180,15,36679.11,0.18882,0.08763
180.3,15.025,36675.17,0.18931,0.08782
180.6,15.05,36674.3,0.18979,0.08802
180.9,15.075,36677.05,0.19027,0.08821
181.2,15.1,36676.19,0.19076,0.0884
181.5,15.125,36675.77,0.19125,0.08859
181.8,15.15,36672.49,0.19174,0.08878
182.1,15.175,36679.41,0.19223,0.08897
182.4,15.2,36676.97,0.19272,0.08916
182.7,15.225,36674,0.19321,0.08936
183,15.25,36671.32,0.19369,0.08955
183.3,15.275,36673.18,0.19419,0.08975
183.6,15.3,36669.84,0.19468,0.08994
183.9,15.325,36669.34,0.19517,0.09014
184.2,15.35,36669.94,0.19566,0.09033
184.5,15.375,36669.88,0.19615,0.09053
184.8,15.4,36671.03,0.19665,0.09072
185.1,15.425,36668.16,0.19714,0.09092
185.4,15.45,36666.93,0.19764,0.09111
185.7,15.475,36667.09,0.19814,0.09131
186,15.5,36665.18,0.19863,0.0915
186.3,15.525,36664.79,0.19913,0.0917
186.6,15.55,36666.57,0.19963,0.0919
186.9,15.575,36662.05,0.20012,0.0921
187.2,15.6,36663.64,0.20062,0.0923
187.5,15.625,36665.59,0.20113,0.09251
187.8,15.65,36662.35,0.20164,0.09271
188.1,15.675,36661.43,0.20214,0.09291
188.4,15.7,36658.48,0.20264,0.09311
188.7,15.725,36657.42,0.20315,0.09332
189,15.75,36658.92,0.20366,0.09353
189.3,15.775,36657.05,0.20416,0.09373
189.6,15.8,36656.83,0.20467,0.09393
189.9,15.825,36651.93,0.20518,0.09414
190.2,15.85,36655.89,0.20568,0.09434
190.5,15.875,36651.81,0.20619,0.09454
190.8,15.9,36649.09,0.2067,0.09475
191.1,15.925,36649.68,0.20721,0.09495
191.4,15.95,36651.85,0.20773,0.09516
191.7,15.975,36649.62,0.20824,0.09536
192,16,36647.32,0.20876,0.09557
192.3,16.025,36648.89,0.20928,0.09578
192.6,16.05,36643.53,0.20981,0.096
192.9,16.075,36643.15,0.21034,0.09621
193.2,16.1,36643.03,0.21086,0.09643
193.5,16.125,36636.49,0.21139,0.09664
193.8,16.15,36636.41,0.21192,0.09685
194.1,16.175,36636.2,0.21245,0.09706
194.4,16.2,36642.77,0.21265,0.09726
194.7,16.225,36633.73,0.21323,0.09746
195,16.25,36632.15,0.21379,0.09767
195.3,16.275,36632.43,0.21435,0.09788
195.6,16.3,36631.39,0.21492,0.0981
195.9,16.325,36629.05,0.21548,0.09832
196.2,16.35,36627.49,0.21604,0.09855
196.5,16.375,36626.43,0.2166,0.09877
196.8,16.4,36621.48,0.21715,0.09899
197.1,16.425,36622.71,0.21771,0.09921
197.4,16.45,36620.81,0.21828,0.09942
197.7,16.475,36620.18,0.21884,0.09964
198,16.5,36620.44,0.2194,0.09986
198.3,16.525,36618.26,0.21997,0.10008
198.6,16.55,36616.05,0.22054,0.10031
198.9,16.575,36615.13,0.22111,0.10053
199.2,16.6,36615.08,0.22167,0.10074
199.5,16.625,36612.47,0.22223,0.10095
199.8,16.65,36612.95,0.2228,0.10117
200.1,16.675,36610.81,0.22338,0.10139
200.4,16.7,36612.42,0.22395,0.1016
200.7,16.725,36607.6,0.22454,0.10183
201,16.75,36606.58,0.22511,0.10206
201.3,16.775,36601.99,0.22569,0.1023
201.6,16.8,36603.54,0.22628,0.10253
201.9,16.825,36598.4,0.22686,0.10275
202.2,16.85,36594.49,0.22744,0.10297
202.5,16.875,36599.59,0.22802,0.1032
202.8,16.9,36590.34,0.22862,0.10344
203.1,16.925,36584.47,0.2292,0.10369
203.4,16.95,36581.4,0.2298,0.10393
203.7,16.975,36590.07,0.23039,0.10418
204,17,36573.72,0.23098,0.10443
204.3,17.025,36567.04,0.23158,0.10468
204.6,17.05,36573.47,0.23217,0.10493
204.9,17.075,36539.76,0.23277,0.10517
205.2,17.1,36548.43,0.23338,0.10541
205.5,17.125,36544.37,0.23399,0.10566
205.8,17.15,36541.54,0.2346,0.1059
206.1,17.175,36529.84,0.2352,0.10613
206.4,17.2,36511.15,0.23581,0.10636
206.7,17.225,36515,0.23642,0.1066
207,17.25,36506.03,0.23704,0.10684
207.3,17.275,36499.49,0.23766,0.10709
207.6,17.3,36489.85,0.23828,0.10734
207.9,17.325,36484.68,0.2389,0.10759
208.2,17.35,36476.3,0.23953,0.10786
208.5,17.375,36473.34,0.24016,0.10813
208.8,17.4,36471.67,0.24079,0.1084
209.1,17.425,36456.1,0.24143,0.10866
209.4,17.45,36457.57,0.24207,0.10892
209.7,17.475,36446.8,0.2427,0.10918
210,17.5,36446.32,0.24335,0.10944
210.3,17.525,36441,0.24399,0.10968
210.6,17.55,36436.27,0.24464,0.10987
210.9,17.575,36432.28,0.24529,0.11011
211.2,17.6,36426.43,0.24594,0.11044
211.5,17.625,36420.54,0.24659,0.11079
211.8,17.65,36417.66,0.24725,0.11113
212.1,17.675,36414.06,0.24791,0.11145
212.4,17.7,36412.12,0.24858,0.11176
212.7,17.725,36402.53,0.24924,0.11206
213,17.75,36394.05,0.24991,0.11237
213.3,17.775,36390.52,0.25058,0.11266
213.6,17.8,36388.54,0.25126,0.11297
213.9,17.825,36381.89,0.25194,0.11326
214.2,17.85,36368.78,0.25263,0.11356
214.5,17.875,36361.35,0.25331,0.11385
214.8,17.9,36357.93,0.254,0.11415
215.1,17.925,36344.88,0.25469,0.11444
215.4,17.95,36347.02,0.25539,0.11473
215.7,17.975,36329.41,0.25608,0.11501
216,18,36321.99,0.25679,0.11531
216.3,18.025,36311.57,0.25749,0.11562
216.6,18.05,36308.31,0.2582,0.11592
216.9,18.075,36298.07,0.25892,0.11622
217.2,18.1,36291.89,0.25962,0.11652
217.5,18.125,36290.77,0.26034,0.11682
217.8,18.15,36267.46,0.26107,0.11713
218.1,18.175,36269.69,0.26179,0.11744
218.4,18.2,36250.6,0.26252,0.11775
218.7,18.225,36244.25,0.26324,0.11808
219,18.25,36228.35,0.26398,0.11841
219.3,18.275,36220.26,0.26472,0.11874
219.6,18.3,36210.55,0.26546,0.11907
219.9,18.325,36186.66,0.26621,0.11939
220.2,18.35,36174.34,0.26695,0.11973
220.5,18.375,36163.17,0.2677,0.12007
220.8,18.4,36154.94,0.26817,0.12039
221.1,18.425,36154.4,0.26897,0.12074
221.4,18.45,36144.08,0.26976,0.12108
221.7,18.475,36139.86,0.27057,0.12143
222,18.5,36133.79,0.27136,0.12179
222.3,18.525,36126.96,0.27216,0.12214
222.6,18.55,36122.88,0.27295,0.12246
222.9,18.575,36122.02,0.27375,0.12264
223.2,18.6,36119.99,0.27456,0.12304
223.5,18.625,36117.21,0.27536,0.12344
223.8,18.65,36116.09,0.27618,0.12384
224.1,18.675,36114.2,0.277,0.12425
224.4,18.7,36111.48,0.27782,0.12464
224.7,18.725,36110.22,0.27863,0.12504
225,18.75,36110.02,0.27945,0.12543
225.3,18.775,36108.85,0.28028,0.12583
225.6,18.8,36108.31,0.28111,0.12623
225.9,18.825,36106.68,0.28194,0.12663
226.2,18.85,36106.74,0.28277,0.12704
226.5,18.875,36100.59,0.28361,0.12745
226.8,18.9,36099.43,0.28447,0.12785
227.1,18.925,36091.01,0.28531,0.12826
227.4,18.95,36091.76,0.28615,0.12866
227.7,18.975,36079.99,0.287,0.12908
228,19,36077.24,0.28786,0.12951
228.3,19.025,36067.85,0.28872,0.12994
228.6,19.05,36056.86,0.28959,0.13033
228.9,19.075,36044.37,0.29046,0.13076
229.2,19.1,36031.87,0.29134,0.13122
229.5,19.125,36009.13,0.29222,0.13169
229.8,19.15,35998.17,0.2931,0.1322
230.1,19.175,35987.43,0.29398,0.13269
230.4,19.2,35984.01,0.29487,0.13317
230.7,19.225,35970.69,0.29576,0.13368
231,19.25,35955.37,0.29666,0.13418
231.3,19.275,35947.29,0.29756,0.13468
231.6,19.3,35943,0.29847,0.13518
231.9,19.325,35927.16,0.29937,0.13569
232.2,19.35,35910.71,0.30029,0.13621
232.5,19.375,35899.09,0.3012,0.13673
232.8,19.4,35886.91,0.30212,0.13726
233.1,19.425,35867.16,0.30303,0.13773
233.4,19.45,35854.9,0.30395,0.13832
233.7,19.475,35847.25,0.30487,0.1392
234,19.5,35831.89,0.30581,0.13981
234.3,19.525,35820.01,0.30675,0.14039
234.6,19.55,35805.54,0.30769,0.14099
234.9,19.575,35784.51,0.30862,0.14157
235.2,19.6,35766.79,0.30955,0.14215
235.5,19.625,35746.81,0.31049,0.14276
235.8,19.65,35732.74,0.31144,0.14337
236.1,19.675,35683.66,0.31239,0.144
236.4,19.7,35672.61,0.31335,0.14463
236.7,19.725,35653.41,0.31431,0.14525
237,19.75,35637.65,0.31527,0.1459
237.3,19.775,35611.2,0.31623,0.14655
237.6,19.8,35608.85,0.3172,0.14719
237.9,19.825,35598.08,0.31816,0.14783
238.2,19.85,35588.13,0.31913,0.14841
238.5,19.875,35582.27,0.3201,0.14907
238.8,19.9,35572.37,0.32107,0.1498
239.1,19.925,35560.76,0.32205,0.15044
239.4,19.95,35544.53,0.32303,0.15112
239.7,19.975,35518.88,0.324,0.15185
240,20,35485.58,0.32498,0.15248
240.3,20.025,35437.32,0.32596,0.15326
240.6,20.05,35405.54,0.32693,0.15401
240.9,20.075,35367.94,0.32792,0.15478
241.2,20.1,35351.86,0.32891,0.15556
241.5,20.125,35336.61,0.3299,0.15633
241.8,20.15,35316.82,0.33089,0.1571
242.1,20.175,35302.34,0.33187,0.15788
242.4,20.2,35287.59,0.33287,0.15867
242.7,20.225,35266.75,0.33386,0.15944
243,20.25,35243.87,0.33484,0.16025
243.3,20.275,35208.75,0.33584,0.16101
243.6,20.3,35185.43,0.33683,0.1618
243.9,20.325,35171.81,0.33782,0.16259
244.2,20.35,35157.01,0.33882,0.16339
244.5,20.375,35138.8,0.33983,0.16422
244.8,20.4,35108.4,0.34083,0.16507
245.1,20.425,35089.56,0.34182,0.16591
245.4,20.45,35065.83,0.34282,0.16676
245.7,20.475,35046.04,0.34383,0.16759
246,20.5,35012.6,0.34483,0.16846
246.3,20.525,34976.96,0.34583,0.16931
246.6,20.55,34943.54,0.34684,0.1701
246.9,20.575,34908.68,0.34784,0.17099
247.2,20.6,34868.54,0.34885,0.17184
247.5,20.625,34819.11,0.34985,0.17259
247.8,20.65,34752.84,0.35086,0.17351
248.1,20.675,34713.04,0.35186,0.1744
248.4,20.7,34689.17,0.35286,0.17516
248.7,20.725,34664.2,0.35386,0.17623
249,20.75,34622.14,0.35487,0.17718
249.3,20.775,34591.84,0.35586,0.17756
249.6,20.8,34578.21,0.35687,0.17807
249.9,20.825,34566.02,0.35789,0.17914
250.2,20.85,34561.54,0.3589,0.17977
250.5,20.875,34556.3,0.3599,0.1807
250.8,20.9,34538.88,0.3609,0.18175
251.1,20.925,34501.61,0.36191,0.18271
251.4,20.95,34440.43,0.36291,0.1836
251.7,20.975,34396.49,0.36393,0.18452
252,21,34358.91,0.36494,0.18545
252.3,21.025,34302.82,0.36596,0.1864
252.6,21.05,34244.48,0.36697,0.18731
252.9,21.075,34173.51,0.36798,0.18821
253.2,21.1,34107.14,0.369,0.18916
253.5,21.125,34086.49,0.37001,0.19012
253.8,21.15,34064.31,0.37103,0.1899
254.1,21.175,34030.14,0.37204,0.19089
254.4,21.2,33982.74,0.37305,0.19188
254.7,21.225,33941.25,0.37406,0.19278
255,21.25,33889.8,0.37508,0.19366
255.3,21.275,33862.5,0.3761,0.19435
255.6,21.3,33832.8,0.37711,0.19543
255.9,21.325,33798.07,0.37812,0.19599
256.2,21.35,33770.05,0.37914,0.19688
256.5,21.375,33729.43,0.38015,0.1963
256.8,21.4,33652.14,0.38116,0.19544
257.1,21.425,33600.46,0.38218,0.19646
257.4,21.45,33571.1,0.3832,0.19747
257.7,21.475,33537.05,0.38422,0.19844
258,21.5,33506.81,0.38525,0.19915
258.3,21.525,33459.59,0.38626,0.20023
258.6,21.55,33356.82,0.38728,0.20128
258.9,21.575,33298.08,0.3883,0.20228
259.2,21.6,33234.65,0.38932,0.2033
259.5,21.625,33171.24,0.39034,0.20241
259.8,21.65,33095.72,0.39136,0.20345
260.1,21.675,33059.13,0.39238,0.20452
260.4,21.7,33057.37,0.39341,0.20557
260.7,21.725,33056.4,0.39444,0.20661
261,21.75,33036.71,0.39545,0.20764
261.3,21.775,32963,0.39648,0.20864
261.6,21.8,32878.98,0.39751,0.20967
261.9,21.825,32801.9,0.39853,0.2107
262.2,21.85,32728.29,0.39954,0.21171
262.5,21.875,32666.65,0.40058,0.21272
262.8,21.9,32572.61,0.40161,0.21373
263.1,21.925,32498.65,0.40263,0.21475
263.4,21.95,32463.53,0.40365,0.21574
263.7,21.975,32444.48,0.40467,0.21672
264,22,32424.24,0.40569,0.2177
264.3,22.025,32357.92,0.40671,0.21868
264.6,22.05,32303.49,0.40775,0.21839
264.9,22.075,32236.55,0.40878,0.21901
265.2,22.1,32144.02,0.40981,0.22005
265.5,22.125,32065.49,0.41084,0.22081
265.8,22.15,32012.21,0.41187,0.2211
266.1,22.175,31967.25,0.41291,0.2138
266.4,22.2,31904.94,0.41393,0.21497
266.7,22.225,31816.87,0.41496,0.21615
267,22.25,31726.76,0.416,0.21708
267.3,22.275,31656.5,0.41704,0.2179
267.6,22.3,31616.09,0.41806,0.2189
267.9,22.325,31565.94,0.4191,0.21956
268.2,22.35,31538.72,0.42014,0.22084
268.5,22.375,31471.72,0.42117,0.22098
268.8,22.4,31383.92,0.4222,0.2218
269.1,22.425,31283.48,0.42323,0.22325
269.4,22.45,31177.26,0.42428,0.22451
269.7,22.475,31063.58,0.4253,0.22483
270,22.5,30973.75,0.42635,0.22601
270.3,22.525,30946.07,0.42739,0.22719
270.6,22.55,30923.85,0.42843,0.22833
270.9,22.575,30851.11,0.42946,0.22669
271.2,22.6,30784.05,0.4305,0.2279
271.5,22.625,30694.6,0.43154,0.22892
271.8,22.65,30583.82,0.43258,0.23002
272.1,22.675,30477.46,0.43362,0.23119
272.4,22.7,30436.57,0.43466,0.22816
272.7,22.725,30367.93,0.43571,0.2273
273,22.75,30246.11,0.43675,0.22789
273.3,22.775,30179.25,0.4378,0.22916
273.6,22.8,30108.3,0.43885,0.23023
273.9,22.825,30004.32,0.43989,0.2308
274.2,22.85,29951.83,0.44093,0.23177
274.5,22.875,29890.72,0.44198,0.233
274.8,22.9,29739.87,0.44303,0.23426
275.1,22.925,29625.8,0.44408,0.23547
275.4,22.95,29546.51,0.44514,0.23669
275.7,22.975,29447.86,0.44619,0.23788
276,23,29390.67,0.44725,0.239
276.3,23.025,29350.24,0.4483,0.23094
276.6,23.05,29221.08,0.44934,0.23202
276.9,23.075,29100.11,0.45039,0.23314
277.2,23.1,28952.51,0.45144,0.23099
277.5,23.125,28890.84,0.45249,0.23202
277.8,23.15,28835.19,0.45355,0.233
278.1,23.175,28725,0.4546,0.23392
278.4,23.2,28603.72,0.45565,0.23466
278.7,23.225,28498.98,0.45672,0.23558
279,23.25,28391.09,0.45778,0.23628
279.3,23.275,28308.14,0.45883,0.23469
279.6,23.3,28173.34,0.4599,0.2332
279.9,23.325,28080.63,0.46097,0.23402
280.2,23.35,27909.93,0.46203,0.23487
280.5,23.375,27870.31,0.4631,0.23622
280.8,23.4,27766.99,0.46417,0.23725
281.1,23.425,27654.66,0.46531,0.24817
281.4,23.45,27479.57,0.46639,0.24526
281.7,23.475,27390.32,0.46745,0.24743
282,23.5,27318.3,0.46851,0.24741
282.3,23.525,27130.47,0.46958,0.24744
282.6,23.55,27030.04,0.47065,0.24742
282.9,23.575,26845.6,0.47173,0.24744
283.2,23.6,26798.63,0.47281,0.24743
283.5,23.625,26669.52,0.47388,0.24744
283.8,23.65,26499.53,0.47496,0.24744
284.1,23.675,26339.6,0.47604,0.24745
284.4,23.7,26291.79,0.47712,0.24744
284.7,23.725,26127.12,0.4782,0.24745
285,23.75,25977.16,0.47928,0.24745
285.3,23.775,25854.39,0.48036,0.24745
285.6,23.8,25686.84,0.48145,0.24746
285.9,23.825,25530.71,0.48253,0.24746
286.2,23.85,25359.94,0.48364,0.24746
286.5,23.875,25292.38,0.48473,0.24746
286.8,23.9,25083.84,0.48582,0.24747
287.1,23.925,24822.98,0.48693,0.24747
287.298,23.942,13416.14,0.49565,0.24749