File: Labs/Lab 2 Tension/CFRP 0 Degree Sample 2.csv
Time (s),Extension (mm),Load (N),Axial Strain (mm/mm),Transverse Strain (mm/mm)
0,0,1.26,0,0
0.1,0.003,0.71,0,0
0.2,0.013,52.29,0.00003,0.00001
0.3,0.024,155.28,0.00006,0.00003
0.4,0.034,273.77,0.00009,0.00004
0.5,0.042,346.17,0.00011,0.00005
0.6,0.05,406.21,0.00013,0.00006
0.7,0.058,442.71,0.00015,0.00006
0.8,0.067,487.31,0.00017,0.00007
0.9,0.075,503.96,0.00018,0.00008
1,0.083,507.23,0.0002,0.00008
1.1,0.092,521.07,0.00021,0.00009
1.2,0.1,536.34,0.00022,0.00009
1.3,0.109,556.08,0.00024,0.0001
1.4,0.117,573.38,0.00025,0.0001
1.5,0.125,592.11,0.00025,0.0001
1.6,0.134,615.72,0.00026,0.00011
1.7,0.142,639.96,0.00027,0.00011
1.8,0.15,674.97,0.00028,0.00011
1.9,0.158,702.89,0.00028,0.00011
2,0.167,718.05,0.00029,0.00011
2.1,0.175,734.75,0.00029,0.00011
2.2,0.183,744.66,0.0003,0.00012
2.3,0.192,753.81,0.0003,0.00012
2.4,0.2,762.83,0.0003,0.00012
2.5,0.209,764.3,0.00031,0.00012
2.6,0.217,767.62,0.00031,0.00012
2.7,0.225,771.68,0.00031,0.00012
2.8,0.233,780.92,0.00032,0.00012
2.9,0.242,783.86,0.00032,0.00012
3,0.25,789.73,0.00032,0.00012
3.1,0.259,796.86,0.00033,0.00012
3.2,0.267,801.39,0.00033,0.00012
3.3,0.275,804.82,0.00033,0.00012
3.4,0.283,809.9,0.00033,0.00013
3.5,0.292,808.74,0.00033,0.00013
3.6,0.3,810.55,0.00033,0.00013
3.7,0.308,811.36,0.00034,0.00013
3.8,0.317,813.97,0.00033,0.00013
3.9,0.325,818.56,0.00034,0.00013
4,0.333,823.71,0.00034,0.00013
4.1,0.342,827.15,0.00034,0.00013
4.2,0.35,835.21,0.00034,0.00013
4.3,0.358,837.2,0.00034,0.00013
4.4,0.367,837.47,0.00034,0.00013
4.5,0.375,843.74,0.00035,0.00013
4.6,0.383,847.99,0.00035,0.00013
4.7,0.392,856.78,0.00035,0.00013
4.8,0.4,866.65,0.00035,0.00013
4.9,0.408,871.01,0.00036,0.00014
5,0.417,881.78,0.00036,0.00014
5.1,0.425,891.94,0.00036,0.00014
5.2,0.433,898.24,0.00037,0.00014
5.3,0.442,916.11,0.00037,0.00014
5.4,0.45,941.12,0.00037,0.00014
5.5,0.458,957.71,0.00038,0.00014
5.6,0.467,972.17,0.00038,0.00015
5.7,0.475,993.75,0.00038,0.00015
5.8,0.484,1011.98,0.00038,0.00015
5.9,0.492,1019.47,0.00039,0.00015
6,0.5,1035.74,0.00039,0.00015
6.1,0.508,1045.89,0.0004,0.00015
6.2,0.517,1055.6,0.0004,0.00015
6.3,0.525,1062.97,0.0004,0.00016
6.4,0.533,1066.53,0.00041,0.00016
6.5,0.542,1072.38,0.00041,0.00016
6.6,0.55,1076.91,0.00041,0.00016
6.7,0.558,1081.21,0.00042,0.00016
6.8,0.567,1094.75,0.00042,0.00017
6.9,0.575,1100.48,0.00043,0.00017
7,0.583,1107.22,0.00044,0.00017
7.1,0.592,1111.03,0.00044,0.00017
7.2,0.6,1114.85,0.00044,0.00017
7.3,0.608,1119.23,0.00045,0.00018
7.4,0.617,1121.2,0.00045,0.00018
7.5,0.625,1123.13,0.00046,0.00018
7.6,0.633,1125.63,0.00046,0.00018
7.7,0.642,1127.73,0.00047,0.00018
7.8,0.65,1137.69,0.00047,0.00019
7.9,0.658,1146.19,0.00048,0.00019
8,0.667,1162.89,0.00048,0.00019
8.1,0.675,1175.73,0.00049,0.00019
8.2,0.683,1192.94,0.00049,0.00019
8.3,0.692,1208.25,0.0005,0.0002
8.4,0.7,1223.32,0.0005,0.0002
8.5,0.708,1241.32,0.00051,0.0002
8.6,0.717,1252.9,0.00051,0.0002
8.7,0.725,1272.29,0.00052,0.00021
8.8,0.733,1284.19,0.00052,0.00021
8.9,0.742,1304.66,0.00053,0.00021
9,0.75,1319.58,0.00053,0.00021
9.1,0.758,1339.32,0.00054,0.00021
9.2,0.767,1352.88,0.00054,0.00022
9.3,0.775,1360.42,0.00055,0.00022
9.4,0.783,1372.75,0.00055,0.00022
9.5,0.792,1389.15,0.00056,0.00022
9.6,0.8,1414.91,0.00057,0.00022
9.7,0.808,1438.49,0.00057,0.00023
9.8,0.817,1469.68,0.00057,0.00023
9.9,0.825,1503.18,0.00058,0.00023
10,0.833,1526.51,0.00059,0.00023
10.1,0.842,1548.04,0.00059,0.00024
10.2,0.85,1558.32,0.0006,0.00024
10.3,0.858,1565.95,0.00061,0.00024
10.4,0.867,1572.02,0.00061,0.00024
10.5,0.875,1582.16,0.00062,0.00025
10.6,0.883,1593.62,0.00062,0.00025
10.7,0.892,1603.58,0.00063,0.00025
10.8,0.9,1620.14,0.00064,0.00025
10.9,0.908,1638.68,0.00064,0.00026
11,0.917,1650.71,0.00065,0.00026
11.1,0.925,1671.22,0.00066,0.00026
11.2,0.933,1683.42,0.00066,0.00026
11.3,0.942,1701.12,0.00067,0.00027
11.4,0.95,1732.78,0.00067,0.00027
11.5,0.958,1758.21,0.00068,0.00027
11.6,0.967,1775.43,0.00069,0.00027
11.7,0.975,1793.77,0.00069,0.00028
11.8,0.983,1804.2,0.0007,0.00028
11.9,0.992,1826.53,0.00071,0.00028
12,1,1845.57,0.00071,0.00029
12.1,1.008,1855.49,0.00072,0.00029
12.2,1.017,1881.85,0.00073,0.00029
12.3,1.025,1894.88,0.00073,0.00029
12.4,1.033,1907.59,0.00074,0.0003
12.5,1.042,1919.45,0.00074,0.0003
12.6,1.05,1936.31,0.00075,0.0003
12.7,1.059,1966.06,0.00076,0.0003
12.8,1.067,1989.88,0.00076,0.00031
12.9,1.075,2011.14,0.00077,0.00031
13,1.083,2033.03,0.00077,0.00031
13.1,1.092,2044.36,0.00078,0.00031
13.2,1.1,2056.62,0.00079,0.00032
13.3,1.108,2066.04,0.00079,0.00032
13.4,1.117,2067.87,0.0008,0.00032
13.5,1.125,2073.48,0.0008,0.00032
13.6,1.133,2079.25,0.00081,0.00033
13.7,1.142,2085.51,0.00082,0.00033
13.8,1.15,2094.95,0.00082,0.00033
13.9,1.158,2101.2,0.00083,0.00034
14,1.167,2121.46,0.00084,0.00034
14.1,1.175,2138.7,0.00084,0.00034
14.2,1.183,2168.07,0.00085,0.00034
14.3,1.192,2201.09,0.00086,0.00035
14.4,1.2,2237.32,0.00086,0.00035
14.5,1.208,2270.44,0.00087,0.00035
14.6,1.217,2293.77,0.00088,0.00035
14.7,1.225,2321.7,0.00088,0.00036
14.8,1.233,2355.28,0.00089,0.00036
14.9,1.242,2385.94,0.0009,0.00036
15,1.25,2412.83,0.0009,0.00037
15.1,1.258,2436.31,0.00091,0.00037
15.2,1.267,2454.66,0.00092,0.00037
15.3,1.275,2465.89,0.00092,0.00038
15.4,1.283,2486.67,0.00093,0.00038
15.5,1.292,2511.91,0.00094,0.00038
15.6,1.3,2536.73,0.00095,0.00038
15.7,1.308,2564.84,0.00095,0.00039
15.8,1.317,2579.97,0.00096,0.00039
15.9,1.325,2591.1,0.00097,0.00039
16,1.333,2608.74,0.00098,0.0004
16.1,1.342,2611.46,0.00099,0.0004
16.2,1.35,2617.09,0.001,0.0004
16.3,1.358,2624.91,0.001,0.00041
16.4,1.367,2633.06,0.00101,0.00041
16.5,1.375,2648.28,0.00102,0.00041
16.6,1.383,2668.32,0.00102,0.00041
16.7,1.392,2689.74,0.00103,0.00042
16.8,1.4,2726.04,0.00104,0.00042
16.9,1.408,2746.34,0.00104,0.00043
17,1.417,2777.86,0.00106,0.00043
17.1,1.425,2792.86,0.00106,0.00043
17.2,1.434,2811.34,0.00107,0.00043
17.3,1.442,2832.92,0.00107,0.00044
17.4,1.45,2866.26,0.00109,0.00044
17.5,1.458,2892.87,0.00109,0.00044
17.6,1.467,2916.83,0.0011,0.00045
17.7,1.475,2942.82,0.00111,0.00045
17.8,1.483,2966.65,0.00112,0.00045
17.9,1.492,2994.41,0.00112,0.00045
18,1.5,3042.61,0.00113,0.00046
18.1,1.508,3069.32,0.00114,0.00046
18.2,1.517,3098.22,0.00114,0.00046
18.3,1.525,3120.41,0.00115,0.00046
18.4,1.533,3133.94,0.00115,0.00047
18.5,1.542,3141.71,0.00116,0.00047
18.6,1.55,3152.41,0.00117,0.00047
18.7,1.558,3160.75,0.00118,0.00048
18.8,1.567,3167.91,0.00118,0.00048
18.9,1.575,3177.91,0.00119,0.00048
19,1.583,3184.48,0.0012,0.00048
19.1,1.592,3200.41,0.00121,0.00049
19.2,1.6,3214.33,0.00121,0.00049
19.3,1.608,3240.74,0.00122,0.00049
19.4,1.617,3272.57,0.00123,0.0005
19.5,1.625,3296.76,0.00124,0.0005
19.6,1.633,3316.45,0.00124,0.0005
19.7,1.642,3343.93,0.00125,0.00051
19.8,1.65,3378.99,0.00126,0.00051
19.9,1.658,3415.3,0.00127,0.00051
20,1.667,3443.81,0.00128,0.00052
20.1,1.675,3469.01,0.00129,0.00052
20.2,1.683,3490.57,0.00129,0.00052
20.3,1.692,3511.89,0.0013,0.00053
20.4,1.7,3546.93,0.0013,0.00053
20.5,1.708,3567.55,0.00131,0.00053
20.6,1.717,3592.32,0.00132,0.00054
20.7,1.725,3602.77,0.00133,0.00054
20.8,1.733,3610.81,0.00134,0.00054
20.9,1.742,3619.14,0.00134,0.00055
21,1.75,3624.8,0.00135,0.00055
21.1,1.758,3631.95,0.00135,0.00055
21.2,1.767,3647.36,0.00137,0.00055
21.3,1.775,3675.54,0.00137,0.00056
21.4,1.783,3695.46,0.00138,0.00056
21.5,1.792,3725.39,0.00139,0.00057
21.6,1.8,3773.14,0.00139,0.00057
21.7,1.808,3811.64,0.0014,0.00057
21.8,1.817,3841.7,0.00141,0.00057
21.9,1.825,3860.67,0.00142,0.00058
22,1.833,3878.55,0.00142,0.00058
22.1,1.842,3894.97,0.00143,0.00058
22.2,1.85,3923.04,0.00144,0.00059
22.3,1.858,3947.24,0.00145,0.00059
22.4,1.867,3968.16,0.00146,0.00059
22.5,1.875,3980.33,0.00146,0.0006
22.6,1.883,4007.25,0.00147,0.0006
22.7,1.892,4046.83,0.00148,0.0006
22.8,1.9,4097.2,0.00149,0.00061
22.9,1.908,4119.87,0.0015,0.00061
23,1.917,4144.56,0.00151,0.00061
23.1,1.925,4160.57,0.00151,0.00062
23.2,1.933,4178.63,0.00152,0.00062
23.3,1.942,4185.28,0.00153,0.00063
23.4,1.95,4191.9,0.00154,0.00063
23.5,1.958,4198.9,0.00155,0.00063
23.6,1.967,4208.33,0.00156,0.00064
23.7,1.975,4242.74,0.00156,0.00064
23.8,1.983,4276.22,0.00157,0.00064
23.9,1.992,4317.13,0.00158,0.00065
24,2,4337.59,0.00159,0.00065
24.1,2.008,4355.25,0.0016,0.00065
24.2,2.017,4383.45,0.00161,0.00066
24.3,2.025,4429.64,0.00162,0.00066
24.4,2.033,4469.34,0.00162,0.00066
24.5,2.042,4505.85,0.00164,0.00067
24.6,2.05,4542.24,0.00165,0.00067
24.7,2.058,4573.67,0.00165,0.00068
24.8,2.067,4611.88,0.00166,0.00068
24.9,2.075,4635.5,0.00167,0.00068
25,2.083,4645.42,0.00168,0.00069
25.1,2.092,4656.69,0.00169,0.00069
25.2,2.1,4669.9,0.0017,0.00069
25.3,2.108,4678.04,0.00171,0.0007
25.4,2.117,4687.72,0.00172,0.0007
25.5,2.125,4693.11,0.00172,0.0007
25.6,2.133,4707.37,0.00173,0.00071
25.7,2.142,4748.72,0.00174,0.00071
25.8,2.15,4819.08,0.00175,0.00072
25.9,2.158,4866.69,0.00176,0.00072
26,2.167,4900.53,0.00177,0.00072
26.1,2.175,4929.64,0.00178,0.00073
26.2,2.184,4956.72,0.00179,0.00073
26.3,2.192,4985.6,0.0018,0.00074
26.4,2.2,5009.76,0.00181,0.00074
26.5,2.208,5034.05,0.00182,0.00074
26.6,2.217,5069.37,0.00183,0.00075
26.7,2.225,5112.77,0.00184,0.00075
26.8,2.233,5130.49,0.00185,0.00075
26.9,2.242,5155.94,0.00185,0.00076
27,2.25,5176.82,0.00186,0.00076
27.1,2.258,5188.91,0.00187,0.00076
27.2,2.267,5205.85,0.00188,0.00077
27.3,2.275,5222.73,0.00189,0.00077
27.4,2.283,5239.87,0.0019,0.00077
27.5,2.292,5255.18,0.00191,0.00078
27.6,2.3,5289.83,0.00192,0.00078
27.7,2.308,5318.37,0.00193,0.00079
27.8,2.317,5348.59,0.00194,0.00079
27.9,2.325,5370.32,0.00194,0.00079
28,2.333,5393.51,0.00196,0.0008
28.1,2.342,5425.89,0.00196,0.0008
28.2,2.35,5464.51,0.00197,0.0008
28.3,2.358,5505.36,0.00198,0.00081
28.4,2.367,5548.18,0.00199,0.00081
28.5,2.375,5592.75,0.002,0.00082
28.6,2.383,5648.79,0.00201,0.00082
28.7,2.392,5677.96,0.00202,0.00082
28.8,2.4,5695.88,0.00203,0.00083
28.9,2.409,5708.67,0.00204,0.00083
29,2.417,5722.09,0.00205,0.00084
29.1,2.425,5735.17,0.00206,0.00084
29.2,2.433,5744.67,0.00207,0.00084
29.3,2.442,5751,0.00208,0.00085
29.4,2.45,5772.66,0.00209,0.00085
29.5,2.458,5811.89,0.00209,0.00086
29.6,2.467,5868.91,0.00211,0.00086
29.7,2.475,5898.15,0.00212,0.00086
29.8,2.483,5928.28,0.00212,0.00087
29.9,2.492,5967.33,0.00214,0.00087
30,2.5,6007.52,0.00214,0.00088
30.1,2.508,6033.29,0.00216,0.00088
30.2,2.517,6053.42,0.00217,0.00088
30.3,2.525,6100.06,0.00218,0.00089
30.4,2.533,6134.14,0.00218,0.00089
30.5,2.542,6158.94,0.0022,0.0009
30.6,2.55,6174.47,0.00221,0.0009
30.7,2.558,6187.35,0.00222,0.0009
30.8,2.567,6214.26,0.00223,0.00091
30.9,2.575,6244.39,0.00224,0.00091
31,2.583,6271.61,0.00225,0.00092
31.1,2.592,6316.83,0.00226,0.00092
31.2,2.6,6373.13,0.00227,0.00093
31.3,2.608,6413.96,0.00228,0.00093
31.4,2.617,6442.04,0.00229,0.00093
31.5,2.625,6471.55,0.0023,0.00094
31.6,2.633,6512.39,0.00231,0.00094
31.7,2.642,6550.95,0.00232,0.00095
31.8,2.65,6592.04,0.00233,0.00095
31.9,2.658,6619.01,0.00234,0.00096
32,2.667,6656.16,0.00235,0.00096
32.1,2.675,6684.53,0.00236,0.00096
32.2,2.683,6699.7,0.00237,0.00097
32.3,2.692,6711.78,0.00239,0.00097
32.4,2.7,6724.98,0.0024,0.00098
32.5,2.708,6740.02,0.0024,0.00098
32.6,2.717,6755.54,0.00242,0.00099
32.7,2.725,6771.55,0.00243,0.00099
32.8,2.733,6816.43,0.00244,0.001
32.9,2.742,6878.12,0.00245,0.001
33,2.75,6927.2,0.00246,0.001
33.1,2.758,6965.15,0.00247,0.00101
33.2,2.767,7010.1,0.00248,0.00101
33.3,2.775,7049.95,0.00249,0.00102
33.4,2.783,7101.98,0.0025,0.00102
33.5,2.792,7165.19,0.00252,0.00103
33.6,2.8,7224.04,0.00252,0.00103
33.7,2.808,7248.45,0.00253,0.00103
33.8,2.817,7259.54,0.00255,0.00104
33.9,2.825,7267.48,0.00256,0.00104
34,2.833,7280.52,0.00257,0.00105
34.1,2.842,7301.62,0.00258,0.00105
34.2,2.85,7316.26,0.00259,0.00106
34.3,2.858,7353.97,0.0026,0.00106
34.4,2.867,7386.58,0.00262,0.00107
34.5,2.875,7413.57,0.00262,0.00107
34.6,2.883,7443.8,0.00264,0.00108
34.7,2.892,7482.14,0.00265,0.00108
34.8,2.9,7522.13,0.00266,0.00108
34.9,2.908,7548.59,0.00267,0.00109
35,2.917,7580.5,0.00268,0.00109
35.1,2.925,7638.32,0.00269,0.0011
35.2,2.933,7711.01,0.0027,0.0011
35.3,2.942,7746.63,0.00271,0.00111
35.4,2.95,7764.16,0.00273,0.00111
35.5,2.958,7781.03,0.00274,0.00112
35.6,2.967,7802.42,0.00275,0.00112
35.7,2.975,7831.69,0.00276,0.00112
35.8,2.983,7863.78,0.00277,0.00113
35.9,2.992,7908.31,0.00278,0.00113
36,3,7973.23,0.00279,0.00114
36.1,3.008,8007.36,0.0028,0.00114
36.2,3.017,8043.1,0.00281,0.00115
36.3,3.025,8077.26,0.00283,0.00115
36.4,3.033,8096.4,0.00284,0.00116
36.5,3.042,8115.59,0.00285,0.00116
36.6,3.05,8151.61,0.00286,0.00116
36.7,3.058,8187.73,0.00287,0.00117
36.8,3.067,8206.77,0.00288,0.00117
36.9,3.075,8225.35,0.00289,0.00118
37,3.083,8248.04,0.0029,0.00118
37.1,3.092,8271.08,0.00292,0.00119
37.2,3.1,8301.96,0.00293,0.00119
37.3,3.108,8341.3,0.00294,0.00119
37.4,3.117,8389.31,0.00295,0.0012
37.5,3.125,8441.19,0.00296,0.00121
37.6,3.134,8480.99,0.00298,0.00121
37.7,3.142,8536.62,0.00299,0.00122
37.8,3.15,8601.38,0.003,0.00122
37.9,3.158,8653.4,0.00301,0.00122
38,3.167,8679.35,0.00302,0.00123
38.1,3.175,8721.83,0.00303,0.00124
38.2,3.183,8781.5,0.00305,0.00124
38.3,3.192,8801.59,0.00306,0.00124
38.4,3.2,8811.08,0.00307,0.00125
38.5,3.208,8811.52,0.00308,0.00125
38.6,3.217,8811.89,0.00309,0.00126
38.7,3.225,8814.61,0.0031,0.00126
38.8,3.233,8836.91,0.00312,0.00127
38.9,3.242,8894.17,0.00313,0.00127
39,3.25,8947.87,0.00314,0.00128
39.1,3.259,8987.88,0.00315,0.00128
39.2,3.267,9033.43,0.00316,0.00129
39.3,3.275,9091.97,0.00317,0.00129
39.4,3.283,9135.88,0.00319,0.00129
39.5,3.292,9199.72,0.0032,0.0013
39.6,3.3,9262.32,0.00321,0.0013
39.7,3.309,9288.81,0.00322,0.00131
39.8,3.317,9308.59,0.00324,0.00131
39.9,3.325,9325.84,0.00324,0.00132
40,3.333,9361.96,0.00325,0.00132
40.1,3.342,9404.36,0.00327,0.00133
40.2,3.35,9446.3,0.00328,0.00133
40.3,3.358,9488.7,0.00329,0.00133
40.4,3.367,9512.82,0.0033,0.00134
40.5,3.375,9529.8,0.00331,0.00135
40.6,3.383,9552.67,0.00333,0.00135
40.7,3.392,9587.75,0.00334,0.00135
40.8,3.4,9604.76,0.00335,0.00136
40.9,3.408,9630.38,0.00336,0.00136
41,3.417,9671.3,0.00337,0.00137
41.1,3.425,9725.67,0.00338,0.00137
41.2,3.433,9779.32,0.00339,0.00137
41.3,3.442,9808.54,0.0034,0.00138
41.4,3.45,9822.08,0.00342,0.00139
41.5,3.458,9842.5,0.00343,0.00139
41.6,3.467,9869.61,0.00344,0.00139
41.7,3.475,9910.19,0.00345,0.0014
41.8,3.483,9974.22,0.00346,0.0014
41.9,3.492,10026.2,0.00348,0.00141
42,3.5,10066.89,0.00349,0.00141
42.1,3.508,10130.8,0.0035,0.00142
42.2,3.517,10187.27,0.00351,0.00142
42.3,3.525,10227.35,0.00352,0.00143
42.4,3.533,10261.43,0.00353,0.00143
42.5,3.542,10297.37,0.00354,0.00144
42.6,3.55,10316.68,0.00356,0.00144
42.7,3.558,10316.52,0.00357,0.00145
42.8,3.567,10316.86,0.00358,0.00145
42.9,3.575,10317.48,0.00359,0.00145
43,3.583,10326.82,0.0036,0.00146
43.1,3.592,10360.3,0.00361,0.00146
43.2,3.6,10431.41,0.00362,0.00147
43.3,3.608,10502.68,0.00364,0.00147
43.4,3.617,10541.47,0.00365,0.00148
43.5,3.625,10588.96,0.00366,0.00148
43.6,3.633,10642.26,0.00368,0.00149
43.7,3.642,10688.55,0.00368,0.00149
43.8,3.65,10737.57,0.0037,0.0015
43.9,3.658,10798.43,0.00371,0.0015
44,3.667,10844.25,0.00372,0.00151
44.1,3.675,10886.87,0.00374,0.00151
44.2,3.683,10914.43,0.00374,0.00152
44.3,3.692,10927.87,0.00376,0.00152
44.4,3.7,10932,0.00377,0.00153
44.5,3.708,10949.04,0.00379,0.00153
44.6,3.717,10990.95,0.0038,0.00154
44.7,3.725,11032.2,0.00381,0.00154
44.8,3.733,11055.57,0.00382,0.00155
44.9,3.742,11096.66,0.00383,0.00155
45,3.75,11143.43,0.00385,0.00156
45.1,3.758,11193.7,0.00386,0.00156
45.2,3.767,11267.96,0.00388,0.00157
45.3,3.775,11323.02,0.00389,0.00157
45.4,3.783,11352.79,0.0039,0.00157
45.5,3.792,11382.67,0.00391,0.00158
45.6,3.8,11408.75,0.00393,0.00159
45.7,3.808,11432.79,0.00394,0.00159
45.8,3.817,11475.63,0.00395,0.0016
45.9,3.825,11532.67,0.00397,0.0016
46,3.833,11588.9,0.00398,0.0016
46.1,3.842,11648.6,0.00399,0.00161
46.2,3.85,11692.26,0.004,0.00162
46.3,3.858,11721.67,0.00402,0.00162
46.4,3.867,11738.39,0.00403,0.00162
46.5,3.875,11764.45,0.00404,0.00163
46.6,3.883,11807.58,0.00405,0.00163
46.7,3.892,11817.74,0.00407,0.00164
46.8,3.9,11834.68,0.00408,0.00164
46.9,3.908,11870.91,0.00409,0.00165
47,3.917,11906.13,0.00411,0.00165
47.1,3.925,11949.2,0.00412,0.00166
47.2,3.933,12023.33,0.00413,0.00166
47.3,3.942,12073.75,0.00414,0.00167
47.4,3.95,12112.53,0.00415,0.00167
47.5,3.958,12178.4,0.00417,0.00168
47.6,3.967,12241.39,0.00418,0.00168
47.7,3.975,12301.18,0.00419,0.00169
47.8,3.983,12361.36,0.00421,0.00169
47.9,3.992,12396.69,0.00422,0.0017
48,4,12418.27,0.00424,0.0017
48.1,4.008,12431.74,0.00425,0.00171
48.2,4.017,12436.56,0.00426,0.00172
48.3,4.025,12440.43,0.00428,0.00172
48.4,4.033,12475.5,0.00429,0.00173
48.5,4.042,12538.38,0.0043,0.00173
48.6,4.05,12578.19,0.00431,0.00174
48.7,4.058,12619.78,0.00433,0.00174
48.8,4.067,12667.81,0.00434,0.00174
48.9,4.075,12723.74,0.00436,0.00175
49,4.083,12803.9,0.00436,0.00175
49.1,4.092,12870.54,0.00438,0.00176
49.2,4.1,12895.23,0.0044,0.00177
49.3,4.108,12922.66,0.00441,0.00177
49.4,4.117,12957.87,0.00442,0.00178
49.5,4.125,12983.43,0.00443,0.00178
49.6,4.133,13010.58,0.00445,0.00179
49.7,4.142,13076.24,0.00446,0.00179
49.8,4.15,13137.49,0.00448,0.0018
49.9,4.158,13166.94,0.00449,0.0018
50,4.167,13202.11,0.0045,0.00181
50.1,4.175,13227.31,0.00452,0.00181
50.2,4.183,13277.1,0.00453,0.00182
50.3,4.192,13346.71,0.00454,0.00182
50.4,4.2,13381.57,0.00456,0.00183
50.5,4.208,13395.72,0.00457,0.00183
50.6,4.217,13424.55,0.00458,0.00184
50.7,4.225,13457.93,0.0046,0.00185
50.8,4.233,13495.11,0.00461,0.00185
50.9,4.242,13566.89,0.00462,0.00186
51,4.25,13638.71,0.00464,0.00186
51.1,4.258,13693.63,0.00465,0.00187
51.2,4.267,13753,0.00467,0.00187
51.3,4.275,13787.37,0.00468,0.00188
51.4,4.283,13823.83,0.00469,0.00188
51.5,4.292,13894.97,0.00471,0.00189
51.6,4.3,13923.87,0.00472,0.00189
51.7,4.308,13939.81,0.00473,0.0019
51.8,4.317,13960.95,0.00475,0.0019
51.9,4.325,13985.75,0.00476,0.00191
52,4.333,14010.15,0.00478,0.00191
52.1,4.342,14069.04,0.00479,0.00192
52.2,4.35,14117.37,0.00481,0.00193
52.3,4.358,14161.66,0.00482,0.00193
52.4,4.367,14226.1,0.00483,0.00194
52.5,4.375,14283.11,0.00485,0.00194
52.6,4.383,14353.57,0.00486,0.00195
52.7,4.392,14421.87,0.00487,0.00195
52.8,4.4,14459.05,0.00489,0.00196
52.9,4.408,14479.01,0.0049,0.00196
53,4.417,14488.29,0.00491,0.00197
53.1,4.425,14500.92,0.00493,0.00197
53.2,4.433,14546.63,0.00494,0.00198
53.3,4.442,14613.16,0.00495,0.00199
53.4,4.45,14650.43,0.00497,0.00199
53.5,4.458,14697.92,0.00498,0.002
53.6,4.467,14763.42,0.00499,0.002
53.7,4.475,14801.92,0.00501,0.00201
53.8,4.483,14847.45,0.00502,0.00201
53.9,4.492,14900.69,0.00504,0.00202
54,4.5,14926.13,0.00505,0.00202
54.1,4.508,14956.12,0.00506,0.00203
54.2,4.517,14999.68,0.00508,0.00203
54.3,4.525,15043.36,0.00509,0.00204
54.4,4.533,15090.01,0.00511,0.00204
54.5,4.542,15158.29,0.00512,0.00205
54.6,4.55,15203.26,0.00513,0.00205
54.7,4.558,15242.46,0.00515,0.00206
54.8,4.567,15285.08,0.00516,0.00207
54.9,4.575,15320.87,0.00517,0.00207
55,4.583,15396.9,0.00519,0.00208
55.1,4.592,15467.76,0.0052,0.00208
55.2,4.6,15492.8,0.00522,0.00209
55.3,4.608,15504.34,0.00523,0.00209
55.4,4.617,15517.27,0.00524,0.0021
55.5,4.625,15538.35,0.00526,0.0021
55.6,4.633,15595.84,0.00527,0.00211
55.7,4.642,15650.08,0.00528,0.00211
55.8,4.65,15687.51,0.0053,0.00212
55.9,4.659,15767.03,0.00531,0.00212
56,4.667,15838.91,0.00533,0.00213
56.1,4.675,15882.76,0.00534,0.00213
56.2,4.683,15940.85,0.00535,0.00214
56.3,4.692,15980.95,0.00537,0.00214
56.4,4.7,15993.17,0.00538,0.00215
56.5,4.708,16004.81,0.00539,0.00215
56.6,4.717,16039.46,0.00541,0.00216
56.7,4.725,16076.34,0.00542,0.00217
56.8,4.733,16153.86,0.00544,0.00217
56.9,4.742,16227.29,0.00545,0.00218
57,4.75,16261.91,0.00547,0.00218
57.1,4.758,16309.55,0.00548,0.00219
57.2,4.767,16345.27,0.00549,0.00219
57.3,4.775,16404.64,0.0055,0.0022
57.4,4.783,16479.04,0.00552,0.0022
57.5,4.792,16516.96,0.00553,0.00221
57.6,4.8,16548.93,0.00555,0.00221
57.7,4.808,16561.82,0.00556,0.00222
57.8,4.817,16585.15,0.00558,0.00223
57.9,4.825,16636.64,0.00559,0.00223
58,4.833,16684.09,0.0056,0.00224
58.1,4.842,16733.99,0.00562,0.00224
58.2,4.85,16803.39,0.00564,0.00225
58.3,4.858,16864.03,0.00565,0.00225
58.4,4.867,16912.01,0.00566,0.00226
58.5,4.875,16991.29,0.00568,0.00226
58.6,4.883,17027.03,0.00569,0.00227
58.7,4.892,17050.01,0.00571,0.00228
58.8,4.9,17062.68,0.00572,0.00228
58.9,4.908,17076.11,0.00574,0.00229
59,4.917,17126.54,0.00575,0.00229
59.1,4.925,17204.96,0.00576,0.0023
59.2,4.933,17253.86,0.00578,0.0023
59.3,4.942,17310.82,0.00579,0.00231
59.4,4.95,17352.71,0.00581,0.00231
59.5,4.958,17397.61,0.00582,0.00232
59.6,4.967,17467.86,0.00584,0.00233
59.7,4.975,17493.96,0.00585,0.00233
59.8,4.983,17521.81,0.00586,0.00234
59.9,4.992,17572.67,0.00588,0.00234
60,5,17620.81,0.00589,0.00235
60.1,5.008,17669.4,0.00591,0.00235
60.2,5.017,17732.99,0.00592,0.00236
60.3,5.025,17766.92,0.00594,0.00236
60.4,5.033,17824.39,0.00595,0.00237
60.5,5.042,17895.4,0.00597,0.00237
60.6,5.05,17929.77,0.00598,0.00238
60.7,5.058,17984.61,0.006,0.00239
60.8,5.067,18040.74,0.00601,0.00239
60.9,5.075,18059.49,0.00602,0.0024
61,5.083,18071.95,0.00604,0.0024
61.1,5.092,18085.77,0.00605,0.00241
61.2,5.1,18133.41,0.00607,0.00241
61.3,5.108,18210.38,0.00608,0.00242
61.4,5.117,18278.33,0.0061,0.00242
61.5,5.125,18322.82,0.00611,0.00243
61.6,5.133,18378.75,0.00613,0.00243
61.7,5.142,18462.58,0.00614,0.00244
61.8,5.15,18543.46,0.00615,0.00245
61.9,5.158,18570.01,0.00617,0.00245
62,5.167,18578.34,0.00618,0.00246
62.1,5.175,18594.56,0.0062,0.00246
62.2,5.183,18624.15,0.00622,0.00247
62.3,5.192,18668.7,0.00623,0.00247
62.4,5.2,18718.81,0.00624,0.00248
62.5,5.208,18767.4,0.00626,0.00249
62.6,5.217,18826.33,0.00627,0.00249
62.7,5.225,18877.46,0.00629,0.0025
62.8,5.233,18922.09,0.00631,0.0025
62.9,5.242,18993.72,0.00632,0.00251
63,5.25,19069.93,0.00633,0.00251
63.1,5.258,19117.87,0.00635,0.00252
63.2,5.267,19142.97,0.00636,0.00252
63.3,5.275,19171.27,0.00638,0.00253
63.4,5.283,19218.25,0.00639,0.00254
63.5,5.292,19302.25,0.00641,0.00254
63.6,5.3,19352.41,0.00642,0.00255
63.7,5.308,19384.69,0.00643,0.00255
63.8,5.317,19417.45,0.00645,0.00256
63.9,5.325,19483.09,0.00646,0.00257
64,5.333,19543.29,0.00648,0.00257
64.1,5.342,19571.24,0.00649,0.00258
64.2,5.35,19598.76,0.00651,0.00258
64.3,5.358,19637.24,0.00652,0.00259
64.4,5.367,19679.18,0.00654,0.00259
64.5,5.375,19750.18,0.00655,0.0026
64.6,5.383,19806.97,0.00657,0.0026
64.7,5.392,19877.65,0.00658,0.00261
64.8,5.4,19956.61,0.0066,0.00262
64.9,5.408,19998.9,0.00661,0.00262
65,5.417,20056.49,0.00663,0.00263
65.1,5.425,20112.67,0.00664,0.00263
65.2,5.433,20129.44,0.00666,0.00264
65.3,5.442,20130.09,0.00667,0.00264
65.4,5.45,20133.24,0.00669,0.00265
65.5,5.458,20161.63,0.0067,0.00266
65.6,5.467,20251.13,0.00672,0.00266
65.7,5.475,20308.2,0.00673,0.00267
65.8,5.483,20384.46,0.00675,0.00267
65.9,5.492,20457.57,0.00676,0.00268
66,5.5,20526.89,0.00678,0.00268
66.1,5.508,20595.66,0.00679,0.00269
66.2,5.517,20637.86,0.0068,0.00269
66.3,5.525,20688.18,0.00682,0.0027
66.4,5.533,20727.17,0.00683,0.00271
66.5,5.542,20755.24,0.00685,0.00271
66.6,5.55,20803.03,0.00686,0.00272
66.7,5.559,20840.45,0.00688,0.00272
66.8,5.567,20863.89,0.0069,0.00273
66.9,5.575,20913.73,0.00691,0.00274
67,5.583,20956.84,0.00693,0.00274
67.1,5.592,21040.18,0.00694,0.00275
67.2,5.6,21112.61,0.00695,0.00275
67.3,5.608,21136.44,0.00697,0.00276
67.4,5.617,21166.72,0.00699,0.00276
67.5,5.625,21208.89,0.007,0.00277
67.6,5.633,21259.31,0.00702,0.00277
67.7,5.642,21342.55,0.00703,0.00278
67.8,5.65,21397.05,0.00704,0.00279
67.9,5.658,21469.87,0.00706,0.00279
68,5.667,21528.22,0.00707,0.0028
68.1,5.675,21575.04,0.00709,0.0028
68.2,5.683,21622.09,0.0071,0.00281
68.3,5.692,21630.17,0.00712,0.00281
68.4,5.7,21631.98,0.00713,0.00282
68.5,5.708,21643.57,0.00715,0.00283
68.6,5.717,21694.85,0.00717,0.00283
68.7,5.725,21786.98,0.00718,0.00284
68.8,5.733,21865.04,0.0072,0.00284
68.9,5.742,21917.18,0.00721,0.00285
69,5.75,21987.16,0.00723,0.00285
69.1,5.758,22036.48,0.00724,0.00286
69.2,5.767,22129.04,0.00725,0.00287
69.3,5.775,22214.22,0.00727,0.00287
69.4,5.783,22245.17,0.00728,0.00288
69.5,5.792,22252.35,0.0073,0.00288
69.6,5.8,22254.75,0.00731,0.00289
69.7,5.808,22279.27,0.00733,0.00289
69.8,5.817,22333.83,0.00734,0.0029
69.9,5.825,22368.8,0.00736,0.00291
70,5.833,22446.21,0.00738,0.00291
70.1,5.842,22504.7,0.00739,0.00292
70.2,5.85,22582.15,0.00741,0.00292
70.3,5.858,22648.49,0.00742,0.00293
70.4,5.867,22690.74,0.00744,0.00293
70.5,5.875,22730.49,0.00745,0.00294
70.6,5.883,22758.35,0.00747,0.00294
70.7,5.892,22805.99,0.00748,0.00295
70.8,5.9,22900.39,0.0075,0.00296
70.9,5.908,22961.06,0.00751,0.00296
71,5.917,23009.95,0.00753,0.00297
71.1,5.925,23043.93,0.00754,0.00297
71.2,5.933,23065.8,0.00756,0.00298
71.3,5.942,23114.85,0.00758,0.00298
71.4,5.95,23143.38,0.00759,0.00299
71.5,5.958,23182.5,0.0076,0.00299
71.6,5.967,23229.16,0.00762,0.003
71.7,5.975,23277.84,0.00764,0.00301
71.8,5.983,23355.61,0.00765,0.00301
71.9,5.992,23427.15,0.00766,0.00302
72,6,23503.06,0.00768,0.00302
72.1,6.008,23576.81,0.0077,0.00303
72.2,6.017,23643.94,0.00771,0.00303
72.3,6.025,23726.9,0.00773,0.00304
72.4,6.033,23749.82,0.00774,0.00305
72.5,6.042,23753.78,0.00776,0.00305
72.6,6.05,23757.68,0.00777,0.00306
72.7,6.058,23803.03,0.00779,0.00306
72.8,6.067,23860.35,0.0078,0.00307
72.9,6.075,23896.64,0.00782,0.00307
73,6.084,23961.27,0.00783,0.00308
73.1,6.092,24045.16,0.00785,0.00309
73.2,6.1,24101.94,0.00786,0.00309
73.3,6.108,24173.29,0.00788,0.0031
73.4,6.117,24236.46,0.0079,0.0031
73.5,6.125,24269.53,0.00791,0.00311
73.6,6.133,24305.33,0.00793,0.00312
73.7,6.142,24340.02,0.00794,0.00312
73.8,6.15,24395.91,0.00796,0.00313
73.9,6.158,24464.43,0.00797,0.00313
74,6.167,24495.02,0.00799,0.00314
74.1,6.175,24536.02,0.008,0.00314
74.2,6.183,24586.01,0.00802,0.00315
74.3,6.192,24667.69,0.00803,0.00316
74.4,6.2,24710.78,0.00805,0.00316
74.5,6.208,24742.65,0.00806,0.00317
74.6,6.217,24785.3,0.00808,0.00317
74.7,6.225,24820.4,0.00809,0.00318
74.8,6.233,24907.52,0.00811,0.00318
74.9,6.242,24989.24,0.00812,0.00319
75,6.25,25038.22,0.00814,0.0032
75.1,6.258,25089.95,0.00816,0.0032
75.2,6.267,25141.96,0.00818,0.00321
75.3,6.275,25208.16,0.00819,0.00321
75.4,6.283,25248.88,0.00821,0.00322
75.5,6.292,25269.65,0.00823,0.00322
75.6,6.3,25294.29,0.00824,0.00323
75.7,6.308,25309.41,0.00826,0.00323
75.8,6.317,25361.79,0.00828,0.00324
75.9,6.325,25446.95,0.00829,0.00325
76,6.333,25518.63,0.00831,0.00325
76.1,6.342,25594.69,0.00833,0.00326
76.2,6.35,25646.91,0.00834,0.00326
76.3,6.358,25743.51,0.00836,0.00327
76.4,6.367,25794.01,0.00838,0.00327
76.5,6.375,25806.89,0.00839,0.00328
76.6,6.383,25824.03,0.00841,0.00329
76.7,6.392,25853.85,0.00843,0.00329
76.8,6.4,25922.35,0.00844,0.0033
76.9,6.408,25975.36,0.00846,0.0033
77,6.417,26044.43,0.00848,0.00331
77.1,6.425,26105.2,0.00849,0.00331
77.2,6.433,26151.19,0.00851,0.00332
77.3,6.442,26226,0.00853,0.00333
77.4,6.45,26269,0.00854,0.00333
77.5,6.458,26320.96,0.00856,0.00334
77.6,6.467,26374.53,0.00858,0.00334
77.7,6.475,26402.96,0.00859,0.00335
77.8,6.483,26468.99,0.00861,0.00336
77.9,6.492,26519.22,0.00863,0.00336
78,6.5,26566.74,0.00864,0.00337
78.1,6.508,26628.68,0.00866,0.00338
78.2,6.517,26694.54,0.00868,0.00338
78.3,6.525,26780.31,0.00869,0.00339
78.4,6.534,26802.71,0.00871,0.00339
78.5,6.542,26815.7,0.00873,0.0034
78.6,6.55,26840.05,0.00874,0.0034
78.7,6.558,26875.55,0.00876,0.00341
78.8,6.567,26964.14,0.00878,0.00341
78.9,6.575,27032.35,0.00879,0.00342
79,6.583,27112.29,0.00881,0.00343
79.1,6.592,27171.2,0.00883,0.00343
79.2,6.6,27232.91,0.00884,0.00344
79.3,6.608,27293.01,0.00886,0.00344
79.4,6.617,27311.58,0.00888,0.00345
79.5,6.625,27330.09,0.00889,0.00355
79.6,6.633,27362.41,0.00891,0.00341
79.7,6.642,27433.84,0.00893,0.00339
79.8,6.65,27515.6,0.00894,0.00342
79.9,6.658,27567.63,0.00896,0.00341
80,6.667,27612.57,0.00898,0.00353
80.1,6.675,27664.93,0.00899,0.0036
80.2,6.683,27766.59,0.00901,0.00377
80.3,6.692,27840.34,0.00903,0.0041
80.4,6.7,27870.13,0.00904,0.00479
80.5,6.708,27887.45,0.00906,0.00515
80.6,6.717,27905.47,0.00908,0.00507
80.7,6.725,27961.22,0.00909,0.00485
80.8,6.733,28022.62,0.00911,0.00477
80.9,6.742,28101.82,0.00913,0.00484
81,6.75,28187.55,0.00914,0.00495
81.1,6.758,28240.06,0.00916,0.00496
81.2,6.767,28313.86,0.00918,0.00501
81.3,6.775,28356.76,0.00919,0.00503
81.4,6.783,28379.79,0.00921,0.00504
81.5,6.792,28392.67,0.00923,0.00501
81.6,6.8,28440.17,0.00924,0.00511
81.7,6.808,28496.38,0.00926,0.00512
81.8,6.817,28565.13,0.00928,0.00509
81.9,6.825,28623.54,0.00929,0.00505
82,6.833,28688.46,0.00931,0.00508
82.1,6.842,28758.45,0.00933,0.00514
82.2,6.85,28814.27,0.00934,0.005
82.3,6.858,28848.77,0.00936,0.00503
82.4,6.867,28901.92,0.00938,0.00503
82.5,6.875,28953.3,0.00939,0.00506
82.6,6.883,28999.79,0.00941,0.00506
82.7,6.892,29058.36,0.00943,0.00509
82.8,6.9,29120.95,0.00944,0.00509
82.9,6.908,29198.62,0.00946,0.00511
83,6.917,29240.6,0.00948,0.0051
83.1,6.925,29293.68,0.00949,0.00484
83.2,6.933,29366.85,0.00951,0.00583
83.3,6.942,29388.53,0.00953,0.0765
83.4,6.95,29407.88,0.00954,0.00371
83.5,6.958,29444.58,0.00956,-0.01128
83.6,6.967,29521.88,0.00958,-0.01601
83.7,6.975,29606.15,0.00959,-0.03796
83.8,6.983,29679.53,0.00961,0.04907
83.9,6.992,29745.11,0.00963,-0.03057
84,7,29822.98,0.00964,-0.03765
84.1,7.008,29878.12,0.00966,-0.0215
84.2,7.017,29891.81,0.00968,0.10984
84.3,7.025,29910.95,0.00969,0.29852
84.4,7.033,29955.01,0.00971,0.31229
84.5,7.042,30017.13,0.00973,0.31233
84.6,7.05,30069.63,0.00974,0.31261
84.7,7.058,30111.43,0.00976,0.31272
84.8,7.067,30177.63,0.00978,0.31249
84.9,7.075,30248.11,0.00979,0.3121
85,7.083,30332.21,0.00981,0.31148
85.1,7.092,30421.38,0.00983,0.31131
85.2,7.1,30454.31,0.00984,0.31105
85.3,7.108,30486.76,0.00986,0.31067
85.4,7.117,30517.6,0.00988,0.31063
85.5,7.125,30591.31,0.00989,0.31073
85.6,7.133,30653.77,0.00991,0.31046
85.7,7.142,30689.67,0.00993,0.31047
85.8,7.15,30733.55,0.00994,0.31077
85.9,7.158,30798.93,0.00996,0.31299
86,7.167,30879.36,0.00998,0.31961
86.1,7.175,30913.28,0.00999,0.31922
86.2,7.183,30954.29,0.01001,0.31782
86.3,7.192,30985.81,0.01003,0.3143
86.4,7.2,31044.27,0.01004,0.31421
86.5,7.208,30944.75,0.01006,0.31522
86.6,7.217,30562.05,0.01008,0.31531
86.7,7.225,30653.68,0.01009,0.31539
86.8,7.233,30719.18,0.01011,0.31516
86.9,7.242,30792.18,0.01013,0.31519
87,7.25,30882.94,0.01014,0.31518
87.1,7.258,30934.46,0.01016,0.31518
87.2,7.267,30983.56,0.01018,0.31518
87.3,7.275,31070.52,0.01019,0.31518
87.4,7.283,31172.55,0.01021,0.31518
87.5,7.292,31251.88,0.01023,0.31518
87.6,7.3,31305,0.01024,0.31518
87.7,7.308,31396.43,0.01026,0.31518
87.8,7.317,31433.35,0.01028,0.31517
87.9,7.325,31435.41,0.01029,0.31516
88,7.333,31447.01,0.01031,0.31516
88.1,7.342,31487.63,0.01033,0.31516
88.2,7.35,31447.68,0.01034,0.31516
88.3,7.358,31498.29,0.01036,0.31515
88.4,7.367,31589.76,0.01038,0.31515
88.5,7.375,31527.86,0.01039,0.31515
88.6,7.383,31632.43,0.01041,0.31515
88.7,7.392,31740.29,0.01043,0.31515
88.8,7.4,31814.24,0.01044,0.31515
88.9,7.408,31919.83,0.01046,0.31515
89,7.417,31995.62,0.01048,0.31515
89.1,7.425,32046.82,0.01049,0.31515
89.2,7.433,32068,0.01051,0.31515
89.3,7.442,32102.95,0.01053,0.31515
89.4,7.45,32155.93,0.01054,0.31515
89.5,7.458,32199.06,0.01056,0.31515
89.6,7.467,32271.33,0.01058,0.31515
89.7,7.475,32375.13,0.01059,0.31515
89.8,7.483,32448.67,0.01061,0.31515
89.9,7.492,32485.83,0.01063,0.31515
90,7.5,32527.83,0.01064,0.31515
90.1,7.508,32571.32,0.01066,0.31515
90.2,7.517,32675.78,0.01068,0.31515
90.3,7.525,32745.02,0.01069,0.31515
90.4,7.533,32826.69,0.01071,0.31515
90.5,7.542,32861.16,0.01073,0.31515
90.6,7.55,32914.55,0.01074,0.31515
90.7,7.558,32944.86,0.01076,0.31515
90.8,7.567,32961.55,0.01078,0.31515
90.9,7.575,33007.05,0.01079,0.31515
91,7.583,33078.32,0.01081,0.31515
91.1,7.592,33180.37,0.01083,0.31515
91.2,7.6,33252.89,0.01084,0.31515
91.3,7.609,33332.61,0.01086,0.31515
91.4,7.617,33416.21,0.01088,0.31515
91.5,7.625,33535.25,0.01089,0.31515
91.6,7.633,33559.02,0.01091,0.31515
91.7,7.642,33560.17,0.01093,0.31515
91.8,7.65,33562.72,0.01094,0.31515
91.9,7.659,33614.04,0.01096,0.31515
92,7.667,33678.61,0.01098,0.31515
92.1,7.675,33770.39,0.01099,0.31515
92.2,7.683,33841.53,0.01101,0.31515
92.3,7.692,33940.58,0.01103,0.31516
92.4,7.7,34009.03,0.01104,0.31516
92.5,7.708,34048.9,0.01106,0.31516
92.6,7.717,34079.74,0.01108,0.31516
92.7,7.725,34137.78,0.01109,0.31516
92.8,7.733,34237.72,0.01111,0.31516
92.9,7.742,34287.23,0.01113,0.31516
93,7.75,34330.27,0.01114,0.31516
93.1,7.758,34363.07,0.01116,0.31516
93.2,7.767,34425.2,0.01118,0.31516
93.3,7.775,34473.82,0.01119,0.31516
93.4,7.783,34537.5,0.01121,0.31516
93.5,7.792,34583.95,0.01123,0.31516
93.6,7.8,34629.11,0.01124,0.31516
93.7,7.808,34728.95,0.01126,0.31516
93.8,7.817,34811.08,0.01128,0.31516
93.9,7.825,34903.12,0.01129,0.31516
94,7.833,34968.76,0.01131,0.31516
94.1,7.842,35047.82,0.01133,0.31516
94.2,7.85,35062.91,0.01134,0.31516
94.3,7.858,35065.73,0.01136,0.31516
94.4,7.867,35083.19,0.01138,0.31516
94.5,7.875,35147.86,0.01139,0.31516
94.6,7.883,35214.7,0.01141,0.31516
94.7,7.892,35292.29,0.01143,0.31516
94.8,7.9,35382.82,0.01144,0.31516
94.9,7.908,35450.92,0.01146,0.31516
95,7.917,35539.04,0.01148,0.31516
95.1,7.925,35585.05,0.01149,0.31517
95.2,7.933,35627.22,0.01151,0.31517
95.3,7.942,35659.44,0.01153,0.31516
95.4,7.95,35717.04,0.01154,0.31517
95.5,7.958,35773.72,0.01156,0.31517
95.6,7.967,35806.05,0.01158,0.31517
95.7,7.975,35865.02,0.01159,0.31517
95.8,7.983,35933.23,0.01161,0.31517
95.9,7.992,36023.71,0.01163,0.31517
96,8,36079.59,0.01164,0.31517
96.1,8.008,36111.8,0.01166,0.31517
96.2,8.017,36156.38,0.01168,0.31517
96.3,8.025,36249.32,0.01169,0.31517
96.4,8.033,36331.01,0.01171,0.31517
96.5,8.042,36380.19,0.01173,0.31517
96.6,8.05,36447.23,0.01174,0.31517
96.7,8.058,36506.07,0.01176,0.31517
96.8,8.067,36568.01,0.01178,0.31517
96.9,8.075,36598.36,0.01179,0.31517
97,8.083,36616.12,0.01181,0.31517
97.1,8.092,36635.97,0.01183,0.31517
97.2,8.1,36725.8,0.01184,0.31517
97.3,8.108,36811,0.01186,0.31517
97.4,8.117,36886.38,0.01188,0.31517
97.5,8.125,36953.57,0.01189,0.31517
97.6,8.133,37042.97,0.01191,0.31517
97.7,8.142,37112.29,0.01193,0.31517
97.8,8.15,37129.25,0.01194,0.31517
97.9,8.159,37155.38,0.01196,0.31517
98,8.167,37184.41,0.01198,0.31517
98.1,8.175,37248.61,0.01199,0.31517
98.2,8.183,37323.2,0.01201,0.31517
98.3,8.192,37390.13,0.01203,0.31517
98.4,8.2,37447.16,0.01204,0.31517
98.5,8.208,37532.39,0.01206,0.31517
98.6,8.217,37603.8,0.01208,0.31517
98.7,8.225,37664.44,0.01209,0.31517
98.8,8.233,37704.73,0.01211,0.31517
98.9,8.242,37742.36,0.01213,0.31517
99,8.25,37814.86,0.01214,0.31517
99.1,8.258,37859.27,0.01216,0.31517
99.2,8.267,37943,0.01218,0.31517
99.3,8.275,38004.46,0.01219,0.31517
99.4,8.283,38090.31,0.01221,0.31517
99.5,8.292,38128.52,0.01223,0.31517
99.6,8.3,38147.96,0.01224,0.31517
99.7,8.308,38178.22,0.01226,0.31517
99.8,8.317,38222.17,0.01228,0.31517
99.9,8.325,38318.59,0.01229,0.31517
100,8.333,38398.02,0.01231,0.31517
100.1,8.342,38470.9,0.01233,0.31517
100.2,8.35,38524.22,0.01234,0.31517
100.3,8.358,38607.33,0.01236,0.31517
100.4,8.367,38637.57,0.01238,0.31517
100.5,8.375,38669.82,0.01239,0.31517
100.6,8.383,38704.82,0.01241,0.31518
100.7,8.392,38768.12,0.01243,0.31518
100.8,8.4,38847.07,0.01244,0.31518
100.9,8.408,38889.09,0.01246,0.31518
101,8.417,38958.98,0.01248,0.31518
101.1,8.425,39024.24,0.01249,0.31518
101.2,8.433,39147.82,0.01251,0.31518
101.3,8.442,39190.82,0.01253,0.31518
101.4,8.45,39207.14,0.01254,0.31518
101.5,8.458,39227,0.01256,0.31518
101.6,8.467,39279.57,0.01258,0.31518
101.7,8.475,39373.02,0.01259,0.31518
101.8,8.483,39452.96,0.01261,0.31518
101.9,8.492,39520.75,0.01263,0.31518
102,8.5,39575.25,0.01264,0.31518
102.1,8.508,39655.68,0.01266,0.31518
102.2,8.517,39683.51,0.01268,0.31518
102.3,8.525,39698.74,0.01269,0.31518
102.4,8.533,39727.68,0.01271,0.31518
102.5,8.542,39841.99,0.01273,0.31518
102.6,8.55,39907.59,0.01274,0.31518
102.7,8.558,39957.8,0.01276,0.31518
102.8,8.567,40017.94,0.01278,0.31519
102.9,8.575,40070.91,0.01279,0.31519
103,8.583,40156.24,0.01281,0.31519
103.1,8.592,40229.73,0.01283,0.31519
103.2,8.6,40270.78,0.01284,0.31519
103.3,8.608,40289.63,0.01286,0.31519
103.4,8.617,40355.42,0.01288,0.31519
103.5,8.625,40425.98,0.01289,0.31519
103.6,8.633,40502.11,0.01291,0.31519
103.7,8.642,40565.75,0.01293,0.31519
103.8,8.65,40625.58,0.01294,0.31519
103.9,8.658,40691.71,0.01296,0.31519
104,8.667,40715.5,0.01298,0.31519
104.1,8.675,40745.88,0.01299,0.31519
104.2,8.683,40791.43,0.01301,0.31519
104.3,8.692,40885.46,0.01303,0.31519
104.4,8.7,40953.47,0.01304,0.31519
104.5,8.708,41034.32,0.01306,0.31519
104.6,8.717,41098.88,0.01308,0.31519
104.7,8.725,41168.92,0.01309,0.31519
104.8,8.734,41211.13,0.01311,0.31519
104.9,8.742,41247.19,0.01313,0.31519
105,8.75,41276.52,0.01314,0.31519
105.1,8.758,41315.04,0.01316,0.31519
105.2,8.767,41391.42,0.01318,0.31519
105.3,8.775,41443.04,0.01319,0.31519
105.4,8.783,41521.37,0.01321,0.31519
105.5,8.792,41600.07,0.01323,0.31519
105.6,8.8,41708.25,0.01324,0.31519
105.7,8.808,41767.86,0.01326,0.31519
105.8,8.817,41794.23,0.01328,0.31519
105.9,8.825,41819.74,0.01329,0.31519
106,8.833,41881.51,0.01331,0.31519
106.1,8.842,41954.36,0.01333,0.31519
106.2,8.85,41987.7,0.01334,0.31519
106.3,8.858,42053.75,0.01336,0.31519
106.4,8.867,42115.63,0.01338,0.3152
106.5,8.875,42191.57,0.01339,0.3152
106.6,8.883,42250.37,0.01341,0.3152
106.7,8.892,42290.68,0.01343,0.3152
106.8,8.9,42324.23,0.01344,0.3152
106.9,8.908,42409.71,0.01346,0.3152
107,8.917,42511.31,0.01348,0.3152
107.1,8.925,42568.06,0.01349,0.3152
107.2,8.933,42618.81,0.01351,0.3152
107.3,8.942,42696.95,0.01353,0.3152
107.4,8.95,42751.49,0.01354,0.3152
107.5,8.958,42761.91,0.01356,0.3152
107.6,8.967,42789.02,0.01358,0.3152
107.7,8.975,42814.27,0.01359,0.3152
107.8,8.983,42890.75,0.01361,0.3152
107.9,8.992,42987.11,0.01363,0.3152
108,9,43076.29,0.01364,0.3152
108.1,9.008,43141.23,0.01366,0.3152
108.2,9.017,43222.21,0.01368,0.3152
108.3,9.025,43307.99,0.01369,0.3152
108.4,9.033,43353.59,0.01371,0.3152
108.5,9.042,43369.73,0.01373,0.3152
108.6,9.05,43379.03,0.01374,0.3152
108.7,9.058,43436.07,0.01376,0.3152
108.8,9.067,43488.41,0.01378,0.3152
108.9,9.075,43557.31,0.01379,0.3152
109,9.084,43641.2,0.01381,0.3152
109.1,9.092,43737.54,0.01383,0.3152
109.2,9.1,43791.36,0.01384,0.3152
109.3,9.108,43830.81,0.01386,0.3152
109.4,9.117,43878.11,0.01388,0.3152
109.5,9.125,43939.52,0.01389,0.3152
109.6,9.134,44034.25,0.01391,0.3152
109.7,9.142,44093.68,0.01393,0.3152
109.8,9.15,44156.52,0.01394,0.3152
109.9,9.158,44190.25,0.01396,0.3152
110,9.167,44251.82,0.01398,0.3152
110.1,9.175,44279.94,0.01399,0.3152
110.2,9.183,44312.49,0.01401,0.3152
110.3,9.192,44357.39,0.01403,0.3152
110.4,9.2,44438,0.01404,0.3152
110.5,9.208,44515.71,0.01406,0.3152
110.6,9.217,44579.57,0.01408,0.3152
110.7,9.225,44663.3,0.01409,0.3152
110.8,9.233,44751.98,0.01411,0.3152
110.9,9.242,44847.71,0.01413,0.3152
111,9.25,44874.83,0.01414,0.3152
111.1,9.258,44875.32,0.01416,0.3152
111.2,9.267,44876,0.01418,0.3152
111.3,9.275,44907.11,0.01419,0.3152
111.4,9.283,45002.79,0.01421,0.31521
111.5,9.292,45068.62,0.01423,0.31521
111.6,9.3,45143.22,0.01424,0.31521
111.7,9.308,45197.5,0.01426,0.31521
111.8,9.317,45296.62,0.01428,0.31521
111.9,9.325,45365.37,0.01429,0.31521
112,9.333,45396.83,0.01431,0.31521
112.1,9.342,45445.45,0.01433,0.31521
112.2,9.35,45502.86,0.01434,0.31521
112.3,9.358,45578.22,0.01436,0.31521
112.4,9.367,45611.11,0.01438,0.31521
112.5,9.375,45649.75,0.01439,0.31521
112.6,9.383,45688.59,0.01441,0.31521
112.7,9.392,45780.19,0.01443,0.31521
112.8,9.4,45853.6,0.01444,0.31521
112.9,9.408,45900,0.01446,0.31521
113,9.417,45930.11,0.01448,0.31521
113.1,9.425,46011.86,0.01449,0.31521
113.2,9.433,46110.77,0.01451,0.31521
113.3,9.442,46194.61,0.01453,0.31521
113.4,9.45,46271.18,0.01454,0.31521
113.5,9.458,46338.17,0.01456,0.31521
113.6,9.467,46377.55,0.01458,0.31521
113.7,9.475,46380.57,0.01459,0.31521
113.8,9.483,46399.82,0.01461,0.31521
113.9,9.492,46433.48,0.01463,0.31521
114,9.5,46488.56,0.01464,0.31521
114.1,9.508,46586.74,0.01466,0.31521
114.2,9.517,46669.76,0.01468,0.31521
114.3,9.525,46742.43,0.01469,0.31521
114.4,9.533,46836.89,0.01471,0.31521
114.5,9.542,46906.38,0.01473,0.31521
114.6,9.55,46954.36,0.01474,0.31521
114.7,9.558,46991.69,0.01476,0.31521
114.8,9.567,47009.09,0.01478,0.31521
114.9,9.575,47069.09,0.01479,0.31521
115,9.583,47099.12,0.01481,0.31521
115.1,9.592,47163.38,0.01483,0.31521
115.2,9.6,47234.62,0.01484,0.31521
115.3,9.608,47331.05,0.01486,0.31521
115.4,9.617,47402.91,0.01488,0.31521
115.5,9.625,47435.38,0.01489,0.31521
115.6,9.633,47478.32,0.01491,0.31521
115.7,9.642,47547.04,0.01493,0.31521
115.8,9.65,47629.46,0.01494,0.31521
115.9,9.658,47685.03,0.01496,0.31521
116,9.667,47752.2,0.01498,0.31521
116.1,9.675,47795.62,0.01499,0.31521
116.2,9.683,47869.89,0.01501,0.31521
116.3,9.692,47910.02,0.01503,0.31521
116.4,9.7,47927.25,0.01504,0.31522
116.5,9.708,47945.11,0.01506,0.31522
116.6,9.717,48016.36,0.01508,0.31521
116.7,9.725,48125.4,0.01509,0.31522
116.8,9.733,48185.03,0.01511,0.31522
116.9,9.742,48262.33,0.01513,0.31522
117,9.75,48333.88,0.01514,0.31522
117.1,9.758,48419.38,0.01516,0.31522
117.2,9.767,48463.67,0.01518,0.31522
117.3,9.775,48491.47,0.01519,0.31522
117.4,9.783,48500.29,0.01521,0.31522
117.5,9.792,48530.79,0.01523,0.31522
117.6,9.8,48620.72,0.01524,0.31522
117.7,9.808,48683.53,0.01526,0.31522
117.8,9.817,48748.15,0.01528,0.31522
117.9,9.825,48807.66,0.01529,0.31522
118,9.833,48903.55,0.01531,0.31522
118.1,9.842,48971.43,0.01533,0.31522
118.2,9.85,49014.81,0.01534,0.31522
118.3,9.858,49046.14,0.01536,0.31522
118.4,9.867,49078.84,0.01538,0.31522
118.5,9.875,49149.94,0.01539,0.31522
118.6,9.883,49204.03,0.01541,0.31522
118.7,9.892,49282.06,0.01543,0.31522
118.8,9.9,49340.29,0.01544,0.31522
118.9,9.908,49405.93,0.01546,0.31522
119,9.917,49446.72,0.01548,0.31522
119.1,9.925,49474.67,0.01549,0.31522
119.2,9.933,49509.07,0.01551,0.31522
119.3,9.942,49568.2,0.01553,0.31522
119.4,9.95,49676.2,0.01554,0.31522
119.5,9.958,49751.57,0.01556,0.31522
119.6,9.967,49817.71,0.01558,0.31522
119.7,9.975,49873.8,0.01559,0.31522
119.8,9.983,49953.84,0.01561,0.31522
119.9,9.992,49993.82,0.01563,0.31522
120,10,50021.46,0.01564,0.31522
120.1,10.008,50063.01,0.01566,0.31522
120.2,10.017,50125.97,0.01568,0.31522
120.3,10.025,50186.95,0.01569,0.31522
120.4,10.033,50244.68,0.01571,0.31522
120.5,10.042,50334.66,0.01573,0.31522
120.6,10.05,50431.4,0.01574,0.31522
120.7,10.058,50499.32,0.01576,0.31522
120.8,10.067,50524.32,0.01578,0.31522
120.9,10.075,50544.96,0.01579,0.31522
121,10.083,50559.43,0.01581,0.31522
121.1,10.092,50623.72,0.01583,0.31522
121.2,10.1,50729.62,0.01584,0.31522
121.3,10.108,50792.96,0.01586,0.31522
121.4,10.117,50848.5,0.01588,0.31522
121.5,10.125,50924.93,0.01589,0.31522
121.6,10.133,50996.27,0.01591,0.31522
121.7,10.142,51013.18,0.01593,0.31522
121.8,10.15,51044.28,0.01594,0.31522
121.9,10.158,51117.96,0.01596,0.31522
122,10.167,51197.76,0.01598,0.31522
122.1,10.175,51245.71,0.01599,0.31522
122.2,10.183,51311.97,0.01601,0.31522
122.3,10.192,51361.48,0.01603,0.31522
122.4,10.2,51444,0.01604,0.31522
122.5,10.209,51540.09,0.01606,0.31522
122.6,10.217,51574.38,0.01608,0.31522
122.7,10.225,51588.18,0.01609,0.31522
122.8,10.233,51618.72,0.01611,0.31522
122.9,10.242,51723,0.01613,0.31522
123,10.25,51801.08,0.01614,0.31522
123.1,10.258,51877.63,0.01616,0.31522
123.2,10.267,51936.01,0.01618,0.31522
123.3,10.275,52007.41,0.01619,0.31522
123.4,10.283,52037.67,0.01621,0.31522
123.5,10.292,52074.38,0.01623,0.31522
123.6,10.3,52111.77,0.01624,0.31522
123.7,10.308,52189.19,0.01626,0.31522
123.8,10.317,52284.32,0.01628,0.31522
123.9,10.325,52346.54,0.01629,0.31522
124,10.333,52414.73,0.01631,0.31522
124.1,10.342,52463.23,0.01633,0.31522
124.2,10.35,52537.98,0.01634,0.31522
124.3,10.358,52580.19,0.01636,0.31522
124.4,10.367,52611.29,0.01638,0.31522
124.5,10.375,52637.54,0.01639,0.31522
124.6,10.383,52705.31,0.01641,0.31522
124.7,10.392,52770.47,0.01643,0.31522
124.8,10.4,52849.57,0.01644,0.31522
124.9,10.408,52945.59,0.01646,0.31522
125,10.417,53062.85,0.01648,0.31522
125.1,10.425,53099.86,0.01649,0.31522
125.2,10.434,53123.46,0.01651,0.31522
125.3,10.442,53160,0.01653,0.31522
125.4,10.45,53213.42,0.01654,0.31522
125.5,10.458,53271.51,0.01656,0.31522
125.6,10.467,53306.9,0.01658,0.31522
125.7,10.475,53382.59,0.01659,0.31522
125.8,10.483,53424.62,0.01661,0.31522
125.9,10.492,53492.04,0.01663,0.31522
126,10.5,53571.53,0.01664,0.31522
126.1,10.508,53606.21,0.01666,0.31522
126.2,10.517,53634.26,0.01668,0.31522
126.3,10.525,53677.75,0.01669,0.31522
126.4,10.533,53765.81,0.01671,0.31522
126.5,10.542,53845.47,0.01673,0.31523
126.6,10.55,53886.34,0.01674,0.31522
126.7,10.558,53945.5,0.01676,0.31522
126.8,10.567,54012.43,0.01678,0.31522
126.9,10.575,54068.97,0.01679,0.31523
127,10.583,54092.96,0.01681,0.31522
127.1,10.592,54119.77,0.01683,0.31523
127.2,10.6,54145.88,0.01684,0.31522
127.3,10.608,54224.75,0.01686,0.31522
127.4,10.617,54326.51,0.01688,0.31522
127.5,10.625,54405.87,0.01689,0.31522
127.6,10.633,54478.88,0.01691,0.31522
127.7,10.642,54555.92,0.01693,0.31522
127.8,10.65,54646.51,0.01694,0.31522
127.9,10.658,54683.29,0.01696,0.31522
128,10.667,54691.05,0.01698,0.31522
128.1,10.675,54697.55,0.01699,0.31522
128.2,10.683,54756.69,0.01701,0.31522
128.3,10.692,54831.71,0.01703,0.31522
128.4,10.7,54910.71,0.01704,0.31522
128.5,10.708,54978.19,0.01706,0.31522
128.6,10.717,55074.05,0.01708,0.31522
128.7,10.725,55131.71,0.01709,0.31522
128.8,10.733,55168.71,0.01711,0.31522
128.9,10.742,55218.34,0.01713,0.31522
129,10.75,55268.66,0.01714,0.31522
129.1,10.759,55349.34,0.01716,0.31522
129.2,10.767,55403.07,0.01718,0.31522
129.3,10.775,55459.29,0.01719,0.31522
129.4,10.783,55489.96,0.01721,0.31522
129.5,10.792,55547.08,0.01723,0.31522
129.6,10.8,55602.13,0.01724,0.31522
129.7,10.808,55648.65,0.01726,0.31522
129.8,10.817,55697.57,0.01728,0.31522
129.9,10.825,55753.33,0.01729,0.31522
130,10.834,55850.08,0.01731,0.31522
130.1,10.842,55923.91,0.01733,0.31522
130.2,10.85,56021.09,0.01734,0.31522
130.3,10.858,56106.61,0.01736,0.31522
130.4,10.867,56174.18,0.01738,0.31522
130.5,10.875,56181.61,0.01739,0.31522
130.554,10.882,20416.3,0.01741,0.31516