File: Labs/Lab 2 Tension/CFRP 0 Degree Sample 1.csv
Time (s),Extension (mm),Load (N),Axial Strain (mm/mm),Transverse Strain (mm/mm)
0,0,1.92,0,0
0.1,0.004,4.83,0,0
0.2,0.014,113.29,0.00003,0.00001
0.3,0.024,231.05,0.00006,0.00002
0.4,0.034,318.22,0.00008,0.00003
0.5,0.042,368.46,0.0001,0.00004
0.6,0.05,419.97,0.00012,0.00005
0.7,0.059,438,0.00014,0.00005
0.8,0.067,452.88,0.00015,0.00006
0.9,0.075,489.85,0.00017,0.00007
1,0.084,526.05,0.00018,0.00007
1.1,0.092,597.6,0.0002,0.00008
1.2,0.1,671.42,0.00021,0.00008
1.3,0.109,719.72,0.00022,0.00009
1.4,0.117,759.53,0.00023,0.00009
1.5,0.125,796.46,0.00024,0.0001
1.6,0.133,837.61,0.00025,0.0001
1.7,0.142,877.37,0.00026,0.0001
1.8,0.15,916.48,0.00026,0.0001
1.9,0.159,936.34,0.00027,0.00011
2,0.167,955.76,0.00027,0.00011
2.1,0.175,969.98,0.00027,0.00011
2.2,0.183,980.37,0.00028,0.00011
2.3,0.192,987.65,0.00028,0.00011
2.4,0.2,998.12,0.00028,0.00011
2.5,0.209,1006.3,0.00029,0.00012
2.6,0.217,1017.25,0.00029,0.00012
2.7,0.225,1023.14,0.0003,0.00012
2.8,0.234,1028.79,0.00031,0.00012
2.9,0.242,1039.28,0.00031,0.00012
3,0.25,1043.96,0.00031,0.00012
3.1,0.259,1045.49,0.00032,0.00013
3.2,0.267,1051.37,0.00032,0.00013
3.3,0.275,1055.53,0.00033,0.00013
3.4,0.284,1059.99,0.00033,0.00013
3.5,0.292,1076.13,0.00034,0.00014
3.6,0.3,1087.66,0.00034,0.00014
3.7,0.308,1104.77,0.00035,0.00014
3.8,0.317,1118.91,0.00035,0.00014
3.9,0.325,1140.05,0.00036,0.00014
4,0.334,1154.63,0.00037,0.00015
4.1,0.342,1166.73,0.00037,0.00015
4.2,0.35,1187.32,0.00037,0.00015
4.3,0.358,1202.23,0.00038,0.00015
4.4,0.367,1221.64,0.00039,0.00016
4.5,0.375,1236.09,0.00039,0.00016
4.6,0.384,1262.28,0.0004,0.00016
4.7,0.392,1279.57,0.0004,0.00016
4.8,0.4,1303.84,0.00041,0.00016
4.9,0.408,1323.11,0.00041,0.00017
5,0.417,1344.02,0.00042,0.00017
5.1,0.425,1365.6,0.00043,0.00017
5.2,0.433,1389.54,0.00043,0.00017
5.3,0.442,1421.99,0.00043,0.00018
5.4,0.45,1446.9,0.00044,0.00018
5.5,0.458,1471.29,0.00045,0.00018
5.6,0.467,1489.4,0.00045,0.00018
5.7,0.475,1501.3,0.00046,0.00018
5.8,0.484,1507.38,0.00046,0.00019
5.9,0.492,1515.96,0.00047,0.00019
6,0.5,1527.98,0.00048,0.00019
6.1,0.509,1542.36,0.00048,0.00019
6.2,0.517,1556.67,0.00049,0.0002
6.3,0.525,1573.42,0.00049,0.0002
6.4,0.534,1597.83,0.0005,0.0002
6.5,0.542,1615.1,0.00051,0.00021
6.6,0.55,1637.64,0.00051,0.00021
6.7,0.558,1663.32,0.00052,0.00021
6.8,0.567,1695.49,0.00052,0.00021
6.9,0.575,1718.29,0.00053,0.00021
7,0.583,1737.2,0.00053,0.00022
7.1,0.592,1751.09,0.00054,0.00022
7.2,0.6,1766.16,0.00054,0.00022
7.3,0.609,1780.53,0.00055,0.00022
7.4,0.617,1806.7,0.00056,0.00023
7.5,0.625,1819.15,0.00057,0.00023
7.6,0.633,1847.06,0.00057,0.00023
7.7,0.642,1875.35,0.00058,0.00023
7.8,0.65,1901.79,0.00059,0.00024
7.9,0.659,1932.08,0.00059,0.00024
8,0.667,1952.89,0.0006,0.00024
8.1,0.675,1967.06,0.0006,0.00024
8.2,0.684,1984.2,0.00061,0.00025
8.3,0.692,1993.45,0.00062,0.00025
8.4,0.7,2001.75,0.00062,0.00025
8.5,0.708,2012.2,0.00063,0.00026
8.6,0.717,2018.26,0.00064,0.00026
8.7,0.725,2023.47,0.00064,0.00026
8.8,0.733,2029.2,0.00064,0.00026
8.9,0.742,2036.96,0.00065,0.00026
9,0.75,2049.48,0.00065,0.00027
9.1,0.758,2061.09,0.00066,0.00027
9.2,0.767,2088.05,0.00067,0.00027
9.3,0.775,2115.08,0.00067,0.00027
9.4,0.784,2145.99,0.00067,0.00027
9.5,0.792,2172.18,0.00068,0.00028
9.6,0.8,2200.14,0.00068,0.00028
9.7,0.809,2228.43,0.00069,0.00028
9.8,0.817,2253.28,0.0007,0.00028
9.9,0.825,2277.51,0.0007,0.00028
10,0.834,2301.28,0.0007,0.00029
10.1,0.842,2324.74,0.00071,0.00029
10.2,0.85,2346.21,0.00071,0.00029
10.3,0.859,2361.61,0.00072,0.00029
10.4,0.867,2378.6,0.00073,0.00029
10.5,0.875,2390.6,0.00073,0.0003
10.6,0.884,2399.58,0.00074,0.0003
10.7,0.892,2410.6,0.00074,0.0003
10.8,0.9,2424.93,0.00075,0.0003
10.9,0.909,2444.45,0.00075,0.0003
11,0.917,2466.83,0.00076,0.00031
11.1,0.925,2486.33,0.00076,0.00031
11.2,0.933,2501.94,0.00076,0.00031
11.3,0.942,2518.74,0.00077,0.00031
11.4,0.95,2529.53,0.00078,0.00032
11.5,0.959,2537.21,0.00078,0.00032
11.6,0.967,2544.21,0.00079,0.00032
11.7,0.975,2554.1,0.00079,0.00032
11.8,0.983,2565.49,0.0008,0.00032
11.9,0.992,2574.58,0.0008,0.00033
12,1,2583.81,0.00081,0.00033
12.1,1.009,2590.91,0.00081,0.00033
12.2,1.017,2599.62,0.00082,0.00033
12.3,1.025,2605.77,0.00082,0.00033
12.4,1.033,2621.06,0.00083,0.00034
12.5,1.042,2642.43,0.00084,0.00034
12.6,1.05,2663.67,0.00084,0.00034
12.7,1.059,2695.08,0.00084,0.00034
12.8,1.067,2715.36,0.00085,0.00034
12.9,1.075,2737.87,0.00085,0.00035
13,1.084,2754.93,0.00086,0.00035
13.1,1.092,2772.84,0.00086,0.00035
13.2,1.1,2791.5,0.00087,0.00035
13.3,1.109,2812.26,0.00087,0.00036
13.4,1.117,2837.48,0.00088,0.00036
13.5,1.125,2861.91,0.00089,0.00036
13.6,1.134,2884.52,0.00089,0.00036
13.7,1.142,2913.28,0.0009,0.00036
13.8,1.15,2938.29,0.0009,0.00037
13.9,1.158,2976.71,0.00091,0.00037
14,1.167,2994.12,0.00091,0.00037
14.1,1.175,3017.42,0.00092,0.00037
14.2,1.183,3033.23,0.00093,0.00038
14.3,1.192,3045.7,0.00093,0.00038
14.4,1.2,3060.8,0.00094,0.00038
14.5,1.208,3068.85,0.00094,0.00038
14.6,1.217,3081.08,0.00095,0.00038
14.7,1.225,3090.45,0.00096,0.00039
14.8,1.234,3097.75,0.00096,0.00039
14.9,1.242,3105.49,0.00097,0.00039
15,1.25,3114.43,0.00097,0.00039
15.1,1.258,3124.55,0.00098,0.0004
15.2,1.267,3151.67,0.00098,0.0004
15.3,1.275,3171.58,0.00099,0.0004
15.4,1.284,3186.58,0.00099,0.0004
15.5,1.292,3199.58,0.001,0.0004
15.6,1.3,3215.11,0.00101,0.00041
15.7,1.308,3226.4,0.00101,0.00041
15.8,1.317,3250.58,0.00102,0.00041
15.9,1.325,3276.55,0.00102,0.00041
16,1.333,3303.5,0.00103,0.00042
16.1,1.342,3345.19,0.00103,0.00042
16.2,1.35,3376.3,0.00104,0.00042
16.3,1.359,3395.5,0.00105,0.00042
16.4,1.367,3418.33,0.00105,0.00043
16.5,1.375,3434.98,0.00106,0.00043
16.6,1.384,3450.81,0.00106,0.00043
16.7,1.392,3476.7,0.00107,0.00043
16.8,1.4,3494.65,0.00108,0.00044
16.9,1.409,3517.19,0.00108,0.00044
17,1.417,3532.66,0.00109,0.00044
17.1,1.425,3538.25,0.00109,0.00044
17.2,1.434,3545.9,0.0011,0.00045
17.3,1.442,3553,0.0011,0.00045
17.4,1.45,3564.92,0.00111,0.00045
17.5,1.459,3576.12,0.00112,0.00045
17.6,1.467,3601.12,0.00112,0.00046
17.7,1.475,3621.14,0.00114,0.00046
17.8,1.483,3649.97,0.00113,0.00046
17.9,1.492,3675.63,0.00114,0.00046
18,1.5,3712.44,0.00115,0.00047
18.1,1.508,3752.56,0.00115,0.00047
18.2,1.517,3781.49,0.00116,0.00047
18.3,1.525,3800.53,0.00116,0.00047
18.4,1.533,3821.63,0.00118,0.00048
18.5,1.542,3832.16,0.00118,0.00048
18.6,1.55,3849.24,0.00118,0.00048
18.7,1.558,3868.74,0.0012,0.00048
18.8,1.567,3883.75,0.00119,0.00049
18.9,1.575,3903.06,0.00121,0.00049
19,1.583,3934.11,0.0012,0.00049
19.1,1.592,3963.69,0.00122,0.00049
19.2,1.6,4007.47,0.00122,0.0005
19.3,1.608,4037.8,0.00122,0.0005
19.4,1.617,4065.21,0.00124,0.0005
19.5,1.625,4085.54,0.00123,0.0005
19.6,1.634,4096.9,0.00125,0.00051
19.7,1.642,4106.52,0.00126,0.00051
19.8,1.65,4111.03,0.00125,0.00051
19.9,1.658,4117.82,0.00127,0.00052
20,1.667,4123,0.00127,0.00052
20.1,1.675,4134.09,0.00128,0.00052
20.2,1.684,4152.6,0.00129,0.00052
20.3,1.692,4181.73,0.00129,0.00052
20.4,1.7,4217.04,0.0013,0.00053
20.5,1.708,4243.77,0.0013,0.00053
20.6,1.717,4261.15,0.00131,0.00053
20.7,1.725,4276.75,0.00131,0.00054
20.8,1.734,4298.37,0.00133,0.00054
20.9,1.742,4322.51,0.00133,0.00054
21,1.75,4358.71,0.00134,0.00055
21.1,1.758,4394.27,0.00135,0.00055
21.2,1.767,4432.76,0.00135,0.00055
21.3,1.775,4457.25,0.00136,0.00055
21.4,1.783,4481.13,0.00137,0.00056
21.5,1.792,4502.91,0.00137,0.00056
21.6,1.8,4532.28,0.00138,0.00056
21.7,1.809,4558.99,0.00139,0.00056
21.8,1.817,4574.45,0.00139,0.00057
21.9,1.825,4583.09,0.0014,0.00057
22,1.833,4592.96,0.00141,0.00057
22.1,1.842,4601.94,0.00142,0.00058
22.2,1.85,4610.7,0.00142,0.00058
22.3,1.859,4617.86,0.00143,0.00058
22.4,1.867,4625.73,0.00144,0.00058
22.5,1.875,4636.09,0.00145,0.00059
22.6,1.883,4654.9,0.00145,0.00059
22.7,1.892,4700.5,0.00146,0.00059
22.8,1.9,4756.22,0.00147,0.0006
22.9,1.909,4801.5,0.00147,0.0006
23,1.917,4833.92,0.00148,0.0006
23.1,1.925,4863.04,0.00149,0.0006
23.2,1.933,4890.24,0.00149,0.00061
23.3,1.942,4910.4,0.0015,0.00061
23.4,1.95,4927.15,0.00151,0.00061
23.5,1.959,4958.86,0.00152,0.00062
23.6,1.967,4995.83,0.00152,0.00062
23.7,1.975,5029.15,0.00153,0.00062
23.8,1.984,5056.99,0.00154,0.00063
23.9,1.992,5077.75,0.00155,0.00063
24,2,5095.89,0.00155,0.00063
24.1,2.009,5112.93,0.00156,0.00063
24.2,2.017,5123.82,0.00157,0.00064
24.3,2.025,5130.73,0.00157,0.00064
24.4,2.034,5142.01,0.00158,0.00064
24.5,2.042,5156.11,0.00159,0.00065
24.6,2.05,5175.32,0.0016,0.00065
24.7,2.058,5206.96,0.0016,0.00065
24.8,2.067,5241.86,0.00161,0.00066
24.9,2.075,5266.61,0.00162,0.00066
25,2.083,5283.15,0.00163,0.00066
25.1,2.092,5299.18,0.00163,0.00066
25.2,2.1,5322.92,0.00164,0.00067
25.3,2.108,5359.63,0.00165,0.00067
25.4,2.117,5401.01,0.00166,0.00067
25.5,2.125,5439.73,0.00167,0.00068
25.6,2.133,5468.69,0.00167,0.00068
25.7,2.142,5499.78,0.00168,0.00068
25.8,2.15,5533.47,0.00169,0.00068
25.9,2.159,5577.99,0.0017,0.00069
26,2.167,5610.57,0.0017,0.00069
26.1,2.175,5630.66,0.00171,0.00069
26.2,2.184,5643.2,0.00172,0.0007
26.3,2.192,5655.05,0.00173,0.0007
26.4,2.2,5665.44,0.00174,0.0007
26.5,2.209,5676.58,0.00174,0.0007
26.6,2.217,5685.19,0.00175,0.00071
26.7,2.225,5696.25,0.00176,0.00071
26.8,2.233,5712.34,0.00176,0.00071
26.9,2.242,5747.28,0.00177,0.00072
27,2.25,5793.42,0.00178,0.00072
27.1,2.259,5833.16,0.00179,0.00072
27.2,2.267,5867.35,0.0018,0.00073
27.3,2.275,5901.4,0.0018,0.00073
27.4,2.283,5923.66,0.00181,0.00073
27.5,2.292,5940.55,0.00182,0.00074
27.6,2.3,5967.22,0.00183,0.00074
27.7,2.309,5993.89,0.00183,0.00074
27.8,2.317,6035.34,0.00184,0.00074
27.9,2.325,6066.3,0.00185,0.00075
28,2.333,6081.8,0.00186,0.00075
28.1,2.342,6095.52,0.00187,0.00075
28.2,2.35,6108.89,0.00187,0.00076
28.3,2.359,6125.96,0.00189,0.00076
28.4,2.367,6148.19,0.00189,0.00076
28.5,2.375,6172.6,0.0019,0.00076
28.6,2.383,6200.58,0.00191,0.00077
28.7,2.392,6232.61,0.00192,0.00077
28.8,2.4,6278.07,0.00193,0.00077
28.9,2.409,6315.13,0.00193,0.00078
29,2.417,6345.24,0.00194,0.00078
29.1,2.425,6370.69,0.00195,0.00078
29.2,2.434,6395.79,0.00196,0.00079
29.3,2.442,6433.16,0.00196,0.00079
29.4,2.45,6471.81,0.00197,0.00079
29.5,2.458,6500.5,0.00198,0.0008
29.6,2.467,6533.39,0.00199,0.0008
29.7,2.475,6551.2,0.002,0.0008
29.8,2.484,6581.74,0.002,0.0008
29.9,2.492,6603.22,0.00201,0.00081
30,2.5,6616.02,0.00202,0.00081
30.1,2.509,6627.68,0.00203,0.00081
30.2,2.517,6635.51,0.00204,0.00082
30.3,2.525,6644.04,0.00205,0.00082
30.4,2.534,6662.51,0.00206,0.00082
30.5,2.542,6680.46,0.00206,0.00083
30.6,2.55,6693.29,0.00207,0.00083
30.7,2.558,6716.89,0.00208,0.00083
30.8,2.567,6765.06,0.00209,0.00084
30.9,2.575,6821.73,0.00209,0.00084
31,2.584,6859.02,0.00211,0.00084
31.1,2.592,6889.12,0.00211,0.00085
31.2,2.6,6917.37,0.00212,0.00085
31.3,2.608,6946.73,0.00213,0.00085
31.4,2.617,6990.5,0.00214,0.00086
31.5,2.625,7035.4,0.00214,0.00086
31.6,2.633,7086.46,0.00216,0.00086
31.7,2.642,7147.52,0.00216,0.00086
31.8,2.65,7172.64,0.00217,0.00087
31.9,2.658,7186.6,0.00218,0.00087
32,2.667,7194.12,0.00218,0.00087
32.1,2.675,7197.94,0.0022,0.00088
32.2,2.683,7207.25,0.0022,0.00088
32.3,2.692,7220.21,0.00221,0.00088
32.4,2.7,7234.22,0.00222,0.00089
32.5,2.709,7260.14,0.00222,0.00089
32.6,2.717,7294.22,0.00224,0.00089
32.7,2.725,7319.12,0.00224,0.0009
32.8,2.733,7337.07,0.00225,0.0009
32.9,2.742,7358.98,0.00226,0.0009
33,2.75,7387.55,0.00227,0.00091
33.1,2.759,7426,0.00228,0.00091
33.2,2.767,7452.67,0.00229,0.00091
33.3,2.775,7476.47,0.00229,0.00092
33.4,2.784,7497.87,0.0023,0.00092
33.5,2.792,7531.24,0.00231,0.00092
33.6,2.8,7579.82,0.00232,0.00092
33.7,2.809,7635.41,0.00233,0.00093
33.8,2.817,7670.78,0.00234,0.00093
33.9,2.825,7693.9,0.00234,0.00093
34,2.834,7709.13,0.00235,0.00094
34.1,2.842,7722.14,0.00236,0.00094
34.2,2.85,7734.97,0.00237,0.00094
34.3,2.858,7752.39,0.00238,0.00095
34.4,2.867,7777.98,0.00239,0.00095
34.5,2.875,7813.03,0.00239,0.00095
34.6,2.884,7876.98,0.00241,0.00096
34.7,2.892,7927.08,0.00241,0.00096
34.8,2.9,7955.46,0.00242,0.00096
34.9,2.909,7979.93,0.00243,0.00097
35,2.917,7995.04,0.00244,0.00097
35.1,2.925,8015.69,0.00244,0.00097
35.2,2.934,8036.14,0.00245,0.00098
35.3,2.942,8067.13,0.00246,0.00098
35.4,2.95,8095.73,0.00247,0.00098
35.5,2.958,8116.83,0.00248,0.00099
35.6,2.967,8130.06,0.00249,0.00099
35.7,2.975,8139.83,0.00249,0.00099
35.8,2.983,8157.5,0.0025,0.00099
35.9,2.992,8182.95,0.00251,0.001
36,3,8209.83,0.00252,0.001
36.1,3.008,8232.1,0.00252,0.001
36.2,3.017,8255.9,0.00253,0.00101
36.3,3.025,8292.23,0.00254,0.00101
36.4,3.034,8333.11,0.00255,0.00101
36.5,3.042,8367.83,0.00256,0.00102
36.6,3.05,8397.78,0.00257,0.00102
36.7,3.059,8434.59,0.00258,0.00102
36.8,3.067,8486.99,0.00259,0.00103
36.9,3.075,8538.68,0.00259,0.00103
37,3.084,8572.71,0.0026,0.00103
37.1,3.092,8601.65,0.00261,0.00104
37.2,3.1,8629.35,0.00262,0.00104
37.3,3.109,8669.16,0.00263,0.00104
37.4,3.117,8702.62,0.00264,0.00105
37.5,3.125,8725.95,0.00264,0.00105
37.6,3.134,8736.51,0.00265,0.00105
37.7,3.142,8741.31,0.00266,0.00105
37.8,3.15,8741.39,0.00267,0.00106
37.9,3.159,8742.25,0.00268,0.00106
38,3.167,8745.22,0.00268,0.00106
38.1,3.175,8757.52,0.00269,0.00107
38.2,3.183,8782.06,0.0027,0.00107
38.3,3.192,8834.18,0.00271,0.00108
38.4,3.2,8872.79,0.00272,0.00108
38.5,3.209,8904.85,0.00273,0.00108
38.6,3.217,8937.23,0.00274,0.00108
38.7,3.225,8968.87,0.00274,0.00109
38.8,3.233,9016.14,0.00275,0.00109
38.9,3.242,9056.07,0.00276,0.00109
39,3.25,9116.5,0.00277,0.0011
39.1,3.259,9171.73,0.00278,0.0011
39.2,3.267,9199.62,0.00278,0.0011
39.3,3.275,9215.78,0.00279,0.00111
39.4,3.284,9230.86,0.0028,0.00111
39.5,3.292,9248.1,0.00281,0.00111
39.6,3.3,9268.2,0.00282,0.00112
39.7,3.309,9295.91,0.00283,0.00112
39.8,3.317,9327.67,0.00284,0.00112
39.9,3.325,9363.51,0.00284,0.00113
40,3.334,9409.18,0.00285,0.00113
40.1,3.342,9432.84,0.00286,0.00113
40.2,3.35,9442.96,0.00287,0.00114
40.3,3.358,9458.68,0.00287,0.00114
40.4,3.367,9480.24,0.00288,0.00114
40.5,3.375,9505.2,0.0029,0.00114
40.6,3.384,9527.73,0.0029,0.00115
40.7,3.392,9542.68,0.00291,0.00115
40.8,3.4,9560.08,0.00292,0.00115
40.9,3.408,9588.89,0.00293,0.00116
41,3.417,9640.55,0.00294,0.00116
41.1,3.425,9686.85,0.00294,0.00116
41.2,3.434,9714.18,0.00295,0.00117
41.3,3.442,9733.13,0.00296,0.00117
41.4,3.45,9752.69,0.00297,0.00117
41.5,3.458,9769.66,0.00298,0.00118
41.6,3.467,9786.95,0.00299,0.00118
41.7,3.475,9809.14,0.003,0.00118
41.8,3.484,9840.43,0.003,0.00119
41.9,3.492,9890.3,0.00301,0.00119
42,3.5,9945.87,0.00302,0.00119
42.1,3.509,9989.22,0.00303,0.0012
42.2,3.517,10022.76,0.00304,0.0012
42.3,3.525,10063.59,0.00305,0.0012
42.4,3.534,10097.75,0.00305,0.00121
42.5,3.542,10137.51,0.00306,0.00121
42.6,3.55,10174.61,0.00307,0.00121
42.7,3.559,10215.9,0.00308,0.00122
42.8,3.567,10238.5,0.00309,0.00122
42.9,3.575,10246.34,0.00309,0.00122
43,3.583,10246.9,0.00311,0.00122
43.1,3.592,10247.18,0.00311,0.00123
43.2,3.6,10247.72,0.00312,0.00123
43.3,3.609,10250.53,0.00313,0.00123
43.4,3.617,10259.01,0.00314,0.00124
43.5,3.625,10280.49,0.00315,0.00124
43.6,3.633,10321.71,0.00315,0.00124
43.7,3.642,10383.57,0.00316,0.00125
43.8,3.65,10417.79,0.00317,0.00125
43.9,3.659,10454.77,0.00318,0.00125
44,3.667,10495.11,0.00319,0.00125
44.1,3.675,10529.35,0.0032,0.00126
44.2,3.684,10569.61,0.0032,0.00126
44.3,3.692,10602.79,0.00321,0.00126
44.4,3.7,10633.4,0.00322,0.00127
44.5,3.709,10672.25,0.00323,0.00127
44.6,3.717,10725.17,0.00324,0.00127
44.7,3.725,10768.34,0.00325,0.00128
44.8,3.733,10799.49,0.00325,0.00128
44.9,3.742,10814.6,0.00326,0.00128
45,3.75,10824.98,0.00327,0.00129
45.1,3.758,10840.19,0.00328,0.00129
45.2,3.767,10855.38,0.00329,0.00129
45.3,3.775,10862.89,0.0033,0.0013
45.4,3.784,10877.54,0.00331,0.0013
45.5,3.792,10905.3,0.00332,0.0013
45.6,3.8,10942.02,0.00332,0.00131
45.7,3.808,10970.05,0.00333,0.00131
45.8,3.817,10992.51,0.00334,0.00131
45.9,3.825,11022.83,0.00335,0.00131
46,3.834,11055.05,0.00336,0.00132
46.1,3.842,11083.65,0.00337,0.00132
46.2,3.85,11118.04,0.00337,0.00132
46.3,3.859,11171.72,0.00338,0.00133
46.4,3.867,11213.98,0.00339,0.00133
46.5,3.875,11247.89,0.0034,0.00133
46.6,3.884,11276.13,0.00341,0.00134
46.7,3.892,11297.72,0.00342,0.00134
46.8,3.9,11322.01,0.00343,0.00134
46.9,3.909,11338.21,0.00343,0.00135
47,3.917,11352.89,0.00344,0.00135
47.1,3.925,11384.67,0.00345,0.00135
47.2,3.934,11425.37,0.00346,0.00136
47.3,3.942,11464.04,0.00347,0.00136
47.4,3.95,11507.57,0.00347,0.00136
47.5,3.959,11546.61,0.00349,0.00137
47.6,3.967,11582.25,0.0035,0.00137
47.7,3.975,11617.14,0.0035,0.00137
47.8,3.984,11645.14,0.00351,0.00138
47.9,3.992,11661.29,0.00352,0.00138
48,4,11671.62,0.00353,0.00138
48.1,4.009,11688.06,0.00354,0.00138
48.2,4.017,11718.43,0.00355,0.00139
48.3,4.025,11737.67,0.00356,0.00139
48.4,4.033,11750.14,0.00357,0.00139
48.5,4.042,11761.99,0.00357,0.0014
48.6,4.05,11780.85,0.00358,0.0014
48.7,4.059,11810.39,0.00359,0.0014
48.8,4.067,11841.47,0.0036,0.00141
48.9,4.075,11870.79,0.0036,0.00141
49,4.084,11902.8,0.00361,0.00141
49.1,4.092,11948.01,0.00362,0.00142
49.2,4.1,11999.28,0.00363,0.00142
49.3,4.109,12030.62,0.00364,0.00142
49.4,4.117,12068.99,0.00365,0.00143
49.5,4.125,12116.96,0.00366,0.00143
49.6,4.134,12164.57,0.00366,0.00143
49.7,4.142,12216.26,0.00367,0.00144
49.8,4.15,12260.58,0.00368,0.00144
49.9,4.159,12299.43,0.00369,0.00144
50,4.167,12318.6,0.0037,0.00145
50.1,4.175,12327.15,0.00371,0.00145
50.2,4.184,12339,0.00372,0.00145
50.3,4.192,12352.4,0.00372,0.00146
50.4,4.2,12360.88,0.00373,0.00146
50.5,4.209,12367.64,0.00374,0.00146
50.6,4.217,12387.13,0.00375,0.00146
50.7,4.225,12420.96,0.00376,0.00147
50.8,4.234,12459.98,0.00377,0.00147
50.9,4.242,12486.51,0.00378,0.00147
51,4.25,12507.96,0.00378,0.00148
51.1,4.258,12530.15,0.00379,0.00148
51.2,4.267,12565.7,0.0038,0.00148
51.3,4.275,12605.9,0.00381,0.00149
51.4,4.284,12641.67,0.00382,0.00149
51.5,4.292,12681.33,0.00383,0.00149
51.6,4.3,12729.46,0.00384,0.0015
51.7,4.308,12784.36,0.00385,0.0015
51.8,4.317,12820.83,0.00386,0.0015
51.9,4.325,12838.17,0.00387,0.00151
52,4.333,12850.88,0.00387,0.00151
52.1,4.342,12867.23,0.00388,0.00151
52.2,4.35,12887.74,0.00389,0.00152
52.3,4.359,12916.58,0.0039,0.00152
52.4,4.367,12934.13,0.00391,0.00152
52.5,4.375,12971.81,0.00392,0.00153
52.6,4.383,13024.82,0.00392,0.00153
52.7,4.392,13065.29,0.00393,0.00153
52.8,4.4,13097.11,0.00394,0.00153
52.9,4.409,13116,0.00395,0.00154
53,4.417,13131.9,0.00396,0.00154
53.1,4.425,13153.47,0.00396,0.00154
53.2,4.433,13186.65,0.00398,0.00155
53.3,4.442,13233.05,0.00398,0.00155
53.4,4.45,13276.21,0.00399,0.00155
53.5,4.459,13307.39,0.004,0.00156
53.6,4.467,13320.78,0.00401,0.00156
53.7,4.475,13333.98,0.00402,0.00156
53.8,4.483,13348.92,0.00403,0.00157
53.9,4.492,13366.94,0.00404,0.00157
54,4.5,13390.13,0.00404,0.00157
54.1,4.509,13419.33,0.00405,0.00158
54.2,4.517,13467.47,0.00406,0.00158
54.3,4.525,13522.62,0.00407,0.00158
54.4,4.533,13560.57,0.00408,0.00159
54.5,4.542,13599.14,0.00409,0.00159
54.6,4.55,13637.9,0.0041,0.00159
54.7,4.559,13677.43,0.00411,0.0016
54.8,4.567,13709.37,0.00411,0.0016
54.9,4.575,13731.12,0.00412,0.0016
55,4.584,13753.81,0.00413,0.0016
55.1,4.592,13785.82,0.00414,0.00161
55.2,4.6,13824.68,0.00415,0.00161
55.3,4.609,13850.65,0.00416,0.00161
55.4,4.617,13872.21,0.00417,0.00162
55.5,4.625,13888.18,0.00418,0.00162
55.6,4.634,13905.89,0.00419,0.00162
55.7,4.642,13919.93,0.0042,0.00163
55.8,4.65,13928.61,0.0042,0.00163
55.9,4.658,13948.73,0.00421,0.00163
56,4.667,13992.58,0.00422,0.00164
56.1,4.675,14038.41,0.00423,0.00164
56.2,4.684,14075.25,0.00424,0.00164
56.3,4.692,14106.57,0.00425,0.00165
56.4,4.7,14143.65,0.00426,0.00165
56.5,4.709,14180.92,0.00426,0.00165
56.6,4.717,14226.77,0.00428,0.00166
56.7,4.725,14276.6,0.00428,0.00166
56.8,4.734,14331.46,0.00429,0.00166
56.9,4.742,14369.07,0.0043,0.00167
57,4.75,14389.46,0.00431,0.00167
57.1,4.759,14400.33,0.00432,0.00167
57.2,4.767,14410.16,0.00433,0.00168
57.3,4.775,14419.12,0.00434,0.00168
57.4,4.784,14431.79,0.00435,0.00168
57.5,4.792,14458.41,0.00436,0.00168
57.6,4.8,14507.77,0.00436,0.00169
57.7,4.809,14548.37,0.00438,0.00169
57.8,4.817,14573.07,0.00439,0.0017
57.9,4.825,14602.83,0.00439,0.0017
58,4.833,14639.46,0.0044,0.0017
58.1,4.842,14691.97,0.00441,0.00171
58.2,4.85,14727.22,0.00442,0.00171
58.3,4.858,14751.77,0.00443,0.00171
58.4,4.867,14782.26,0.00444,0.00171
58.5,4.875,14819.07,0.00445,0.00172
58.6,4.883,14846.02,0.00445,0.00172
58.7,4.892,14866.37,0.00447,0.00172
58.8,4.9,14895.16,0.00448,0.00173
58.9,4.908,14935.9,0.00448,0.00173
59,4.917,14960.08,0.00449,0.00173
59.1,4.925,14984.45,0.0045,0.00174
59.2,4.933,15010.61,0.00451,0.00174
59.3,4.942,15054.23,0.00452,0.00175
59.4,4.95,15104.92,0.00453,0.00175
59.5,4.959,15136.86,0.00454,0.00175
59.6,4.967,15164.83,0.00455,0.00175
59.7,4.975,15196.03,0.00456,0.00176
59.8,4.984,15221.47,0.00456,0.00176
59.9,4.992,15258.15,0.00457,0.00177
60,5,15316.15,0.00458,0.00177
60.1,5.009,15376.12,0.00459,0.00177
60.2,5.017,15406.92,0.0046,0.00177
60.3,5.025,15421.87,0.00461,0.00178
60.4,5.034,15428.52,0.00462,0.00178
60.5,5.042,15439.84,0.00463,0.00178
60.6,5.05,15455.1,0.00464,0.00179
60.7,5.058,15477.94,0.00465,0.00179
60.8,5.067,15512.28,0.00466,0.00179
60.9,5.075,15553.09,0.00467,0.0018
61,5.084,15581.65,0.00468,0.0018
61.1,5.092,15605.7,0.00469,0.0018
61.2,5.1,15650.43,0.00469,0.00181
61.3,5.108,15705.14,0.0047,0.00181
61.4,5.117,15765.06,0.00471,0.00181
61.5,5.125,15798.37,0.00472,0.00182
61.6,5.134,15836.42,0.00473,0.00182
61.7,5.142,15881.18,0.00474,0.00182
61.8,5.15,15905.47,0.00475,0.00183
61.9,5.158,15915.7,0.00476,0.00183
62,5.167,15926.17,0.00477,0.00183
62.1,5.175,15938.55,0.00478,0.00184
62.2,5.184,15957.48,0.00479,0.00184
62.3,5.192,15983.51,0.0048,0.00184
62.4,5.2,16029,0.0048,0.00185
62.5,5.209,16097.76,0.00481,0.00185
62.6,5.217,16152.56,0.00482,0.00186
62.7,5.225,16180.15,0.00483,0.00186
62.8,5.234,16209.46,0.00484,0.00186
62.9,5.242,16236.93,0.00485,0.00187
63,5.25,16264.62,0.00486,0.00187
63.1,5.259,16308.56,0.00487,0.00187
63.2,5.267,16361.98,0.00488,0.00188
63.3,5.275,16414.01,0.00489,0.00188
63.4,5.283,16444.81,0.0049,0.00188
63.5,5.292,16464.64,0.00491,0.00189
63.6,5.3,16477.34,0.00492,0.00189
63.7,5.309,16488.78,0.00493,0.00189
63.8,5.317,16500.31,0.00494,0.0019
63.9,5.325,16524.03,0.00495,0.0019
64,5.333,16563.12,0.00496,0.0019
64.1,5.342,16602.17,0.00497,0.00191
64.2,5.35,16633.95,0.00498,0.00191
64.3,5.359,16676.67,0.00499,0.00191
64.4,5.367,16738.21,0.005,0.00192
64.5,5.375,16774.93,0.005,0.00192
64.6,5.383,16807.83,0.00501,0.00192
64.7,5.392,16843.48,0.00502,0.00193
64.8,5.4,16904.45,0.00503,0.00193
64.9,5.409,16948.06,0.00504,0.00194
65,5.417,16969.01,0.00505,0.00194
65.1,5.425,16982.94,0.00506,0.00194
65.2,5.433,16996.18,0.00507,0.00194
65.3,5.442,17005.01,0.00508,0.00195
65.4,5.45,17013.65,0.00509,0.00195
65.5,5.458,17056.71,0.0051,0.00196
65.6,5.467,17109.71,0.00511,0.00196
65.7,5.475,17160.11,0.00512,0.00196
65.8,5.484,17195.8,0.00513,0.00197
65.9,5.492,17240.37,0.00514,0.00197
66,5.5,17274.49,0.00515,0.00197
66.1,5.508,17302.59,0.00516,0.00198
66.2,5.517,17343.11,0.00517,0.00198
66.3,5.525,17391.78,0.00518,0.00198
66.4,5.534,17417.5,0.00518,0.00199
66.5,5.542,17434.08,0.0052,0.00199
66.6,5.55,17467.8,0.00521,0.00199
66.7,5.559,17510.24,0.00522,0.002
66.8,5.567,17547.41,0.00523,0.002
66.9,5.575,17589.23,0.00524,0.00201
67,5.584,17629.46,0.00525,0.00201
67.1,5.592,17659.82,0.00526,0.00201
67.2,5.6,17689.53,0.00527,0.00202
67.3,5.608,17732.84,0.00528,0.00202
67.4,5.617,17785.89,0.00529,0.00202
67.5,5.625,17831.14,0.0053,0.00203
67.6,5.634,17857.95,0.00531,0.00203
67.7,5.642,17892.29,0.00532,0.00203
67.8,5.65,17939.39,0.00533,0.00204
67.9,5.659,17972.5,0.00533,0.00204
68,5.667,17986.17,0.00535,0.00205
68.1,5.675,17994.19,0.00535,0.00205
68.2,5.684,18004.15,0.00537,0.00205
68.3,5.692,18020.65,0.00538,0.00206
68.4,5.7,18057.49,0.00539,0.00206
68.5,5.709,18125.23,0.0054,0.00206
68.6,5.717,18181.04,0.00541,0.00207
68.7,5.725,18218.87,0.00542,0.00207
68.8,5.734,18260.75,0.00543,0.00207
68.9,5.742,18299.32,0.00544,0.00208
69,5.75,18353.79,0.00545,0.00208
69.1,5.759,18415.55,0.00546,0.00208
69.2,5.767,18478.43,0.00547,0.00209
69.3,5.775,18497.98,0.00548,0.00209
69.4,5.784,18504.83,0.00549,0.00209
69.5,5.792,18516.56,0.0055,0.0021
69.6,5.8,18538.02,0.00551,0.0021
69.7,5.809,18552.36,0.00552,0.00211
69.8,5.817,18578.28,0.00553,0.00211
69.9,5.825,18620.57,0.00554,0.00211
70,5.833,18657.7,0.00555,0.00212
70.1,5.842,18692.51,0.00556,0.00212
70.2,5.85,18739.93,0.00557,0.00213
70.3,5.859,18786.98,0.00558,0.00213
70.4,5.867,18819.27,0.00559,0.00213
70.5,5.875,18858.29,0.0056,0.00214
70.6,5.884,18927.04,0.00561,0.00214
70.7,5.892,18985.61,0.00562,0.00214
70.8,5.9,19016.35,0.00563,0.00215
70.9,5.909,19042.42,0.00564,0.00215
71,5.917,19072.59,0.00565,0.00215
71.1,5.925,19091.72,0.00567,0.00216
71.2,5.934,19121.9,0.00567,0.00216
71.3,5.942,19174.6,0.00569,0.00217
71.4,5.95,19244.15,0.00569,0.00217
71.5,5.958,19274.16,0.00571,0.00217
71.6,5.967,19302.25,0.00571,0.00217
71.7,5.975,19330.31,0.00573,0.00218
71.8,5.983,19355.4,0.00574,0.00218
71.9,5.992,19400.23,0.00575,0.00219
72,6,19461.27,0.00576,0.00219
72.1,6.008,19486.17,0.00577,0.00219
72.2,6.017,19508.54,0.00578,0.0022
72.3,6.025,19535.95,0.00579,0.0022
72.4,6.034,19562.96,0.0058,0.00221
72.5,6.042,19585.47,0.00581,0.00221
72.6,6.05,19630.39,0.00582,0.00221
72.7,6.059,19692.82,0.00583,0.00222
72.8,6.067,19738.65,0.00584,0.00222
72.9,6.075,19786.52,0.00585,0.00223
73,6.084,19853.82,0.00587,0.00223
73.1,6.092,19901.17,0.00587,0.00223
73.2,6.1,19936.48,0.00589,0.00224
73.3,6.109,19975.38,0.0059,0.00224
73.4,6.117,20030.99,0.00591,0.00224
73.5,6.125,20053.82,0.00592,0.00225
73.6,6.134,20058.69,0.00593,0.00225
73.7,6.142,20059.18,0.00594,0.00226
73.8,6.15,20062,0.00595,0.00226
73.9,6.159,20074.32,0.00596,0.00226
74,6.167,20124.9,0.00598,0.00227
74.1,6.175,20196.12,0.00598,0.00227
74.2,6.183,20245.26,0.00599,0.00227
74.3,6.192,20297.19,0.00601,0.00228
74.4,6.2,20362.05,0.00602,0.00228
74.5,6.208,20417.23,0.00603,0.00229
74.6,6.217,20479.26,0.00604,0.00229
74.7,6.225,20522.42,0.00605,0.00229
74.8,6.233,20553.76,0.00606,0.0023
74.9,6.242,20604.72,0.00607,0.0023
75,6.25,20643.64,0.00609,0.00231
75.1,6.258,20665.25,0.00609,0.00231
75.2,6.267,20689.25,0.00611,0.00232
75.3,6.275,20735.59,0.00612,0.00232
75.4,6.284,20759.46,0.00613,0.00232
75.5,6.292,20779.47,0.00614,0.00233
75.6,6.3,20814.08,0.00615,0.00233
75.7,6.309,20854.79,0.00616,0.00233
75.8,6.317,20900.74,0.00617,0.00234
75.9,6.325,20948.95,0.00619,0.00234
76,6.334,21018.81,0.0062,0.00235
76.1,6.342,21048.89,0.00621,0.00235
76.2,6.35,21070.71,0.00622,0.00235
76.3,6.358,21100.68,0.00623,0.00236
76.4,6.367,21131.29,0.00624,0.00236
76.5,6.375,21169.74,0.00625,0.00237
76.6,6.383,21222.37,0.00627,0.00237
76.7,6.392,21290.33,0.00627,0.00237
76.8,6.4,21331.81,0.00629,0.00238
76.9,6.408,21391.06,0.0063,0.00238
77,6.417,21449.18,0.00631,0.00238
77.1,6.425,21489.5,0.00632,0.00239
77.2,6.434,21540.19,0.00633,0.00239
77.3,6.442,21557.11,0.00634,0.0024
77.4,6.45,21559.7,0.00636,0.0024
77.5,6.458,21561.61,0.00636,0.00241
77.6,6.467,21568.88,0.00638,0.00241
77.7,6.475,21593.67,0.00639,0.00241
77.8,6.484,21666.88,0.0064,0.00242
77.9,6.492,21754.21,0.00641,0.00242
78,6.5,21800.75,0.00643,0.00243
78.1,6.508,21847.15,0.00644,0.00243
78.2,6.517,21910.14,0.00645,0.00243
78.3,6.525,21956.46,0.00646,0.00244
78.4,6.534,22013.23,0.00647,0.00244
78.5,6.542,22094.86,0.00648,0.00245
78.6,6.55,22153.83,0.00649,0.00245
78.7,6.558,22174.06,0.00651,0.00245
78.8,6.567,22181.27,0.00652,0.00246
78.9,6.575,22182.98,0.00652,0.00246
79,6.583,22191.64,0.00654,0.00247
79.1,6.592,22231.07,0.00655,0.00247
79.2,6.6,22280.5,0.00656,0.00247
79.3,6.609,22336.36,0.00657,0.00248
79.4,6.617,22377.63,0.00659,0.00248
79.5,6.625,22428.77,0.0066,0.00249
79.6,6.633,22490.33,0.00661,0.00249
79.7,6.642,22558.81,0.00662,0.00249
79.8,6.65,22598.02,0.00664,0.0025
79.9,6.659,22631.95,0.00665,0.0025
80,6.667,22666.25,0.00666,0.00251
80.1,6.675,22688.45,0.00667,0.00251
80.2,6.683,22730.02,0.00668,0.00252
80.3,6.692,22797.89,0.0067,0.00252
80.4,6.7,22856.97,0.00671,0.00252
80.5,6.709,22902.55,0.00672,0.00253
80.6,6.717,22950.25,0.00673,0.00253
80.7,6.725,22979.38,0.00674,0.00254
80.8,6.733,22995.04,0.00676,0.00254
80.9,6.742,23035.03,0.00677,0.00255
81,6.75,23068.2,0.00678,0.00255
81.1,6.758,23095.07,0.00679,0.00255
81.2,6.767,23133.52,0.0068,0.00256
81.3,6.775,23170.43,0.00682,0.00256
81.4,6.784,23215.05,0.00683,0.00257
81.5,6.792,23280.86,0.00684,0.00257
81.6,6.8,23359.45,0.00685,0.00258
81.7,6.808,23419.89,0.00686,0.00258
81.8,6.817,23483,0.00687,0.00258
81.9,6.825,23540.18,0.00689,0.00259
82,6.834,23614.32,0.0069,0.00259
82.1,6.842,23666.1,0.00691,0.0026
82.2,6.85,23678.72,0.00692,0.0026
82.3,6.859,23684.18,0.00694,0.00261
82.4,6.867,23689.11,0.00695,0.00261
82.5,6.875,23713.03,0.00696,0.00261
82.6,6.884,23778.06,0.00698,0.00262
82.7,6.892,23808.84,0.00698,0.00262
82.8,6.9,23854.03,0.007,0.00263
82.9,6.909,23925.76,0.00701,0.00263
83,6.917,23991.09,0.00702,0.00263
83.1,6.925,24036.84,0.00704,0.00264
83.2,6.934,24106.61,0.00705,0.00264
83.3,6.942,24157.58,0.00706,0.00265
83.4,6.95,24190.77,0.00707,0.00265
83.5,6.958,24226.01,0.00708,0.00266
83.6,6.967,24251.93,0.0071,0.00266
83.7,6.975,24276.13,0.00711,0.00267
83.8,6.983,24321.56,0.00712,0.00267
83.9,6.992,24397.26,0.00714,0.00267
84,7,24428.99,0.00715,0.00268
84.1,7.009,24460.18,0.00716,0.00268
84.2,7.017,24501.9,0.00717,0.00269
84.3,7.025,24583.92,0.00718,0.00269
84.4,7.034,24635.6,0.0072,0.0027
84.5,7.042,24654.96,0.00721,0.0027
84.6,7.05,24674.26,0.00723,0.0027
84.7,7.059,24718.66,0.00724,0.00271
84.8,7.067,24781.39,0.00725,0.00271
84.9,7.075,24861.2,0.00726,0.00272
85,7.083,24915.34,0.00727,0.00272
85.1,7.092,24957.61,0.00729,0.00273
85.2,7.1,25012,0.0073,0.00273
85.3,7.108,25054.74,0.00732,0.00274
85.4,7.117,25112.88,0.00733,0.00274
85.5,7.125,25166.65,0.00735,0.00274
85.6,7.133,25202.98,0.00736,0.00275
85.7,7.142,25221.2,0.00738,0.00275
85.8,7.15,25231.11,0.0074,0.00276
85.9,7.158,25243.88,0.00741,0.00276
86,7.167,25302.15,0.00743,0.00277
86.1,7.175,25382.88,0.00744,0.00277
86.2,7.184,25449.19,0.00746,0.00278
86.3,7.192,25506.68,0.00748,0.00278
86.4,7.2,25551.96,0.00749,0.00278
86.5,7.209,25633.72,0.00751,0.00279
86.6,7.217,25702.46,0.00752,0.00279
86.7,7.225,25726.68,0.00754,0.0028
86.8,7.234,25740.69,0.00755,0.0028
86.9,7.242,25752.29,0.00757,0.00281
87,7.25,25783.63,0.00759,0.00281
87.1,7.259,25855.75,0.0076,0.00281
87.2,7.267,25900.38,0.00762,0.00257
87.3,7.275,25958.64,0.00763,0.00241
87.4,7.284,26028.85,0.00765,0.00599
87.5,7.292,26072.62,0.00767,-0.02282
87.6,7.3,26110.16,0.00768,-0.11245
87.7,7.308,26168.51,0.0077,-0.114
87.8,7.317,26223.49,0.00771,-0.11259
87.9,7.325,26274.35,0.00773,-0.11744
88,7.334,26310.49,0.00775,-0.11346
88.1,7.342,26336.6,0.00776,-0.12069
88.2,7.35,26393.27,0.00778,-0.11595
88.3,7.359,26453.03,0.00779,-0.11315
88.4,7.367,26497.63,0.00781,-0.11466
88.5,7.375,26554.46,0.00782,-0.11453
88.6,7.384,26630.85,0.00784,-0.11182
88.7,7.392,26705.59,0.00786,-0.04397
88.8,7.4,26726.37,0.00787,-0.10026
88.9,7.409,26739.88,0.00789,-0.12054
89,7.417,26762.87,0.0079,-0.1243
89.1,7.425,26788.29,0.00792,-0.12025
89.2,7.434,26847.82,0.00794,0.04651
89.3,7.442,26912.82,0.00795,0.16256
89.4,7.45,26972.05,0.00797,0.22612
89.5,7.459,27047.04,0.00798,0.22329
89.6,7.467,27104.75,0.008,0.22655
89.7,7.475,27147.29,0.00802,0.22625
89.8,7.483,27209.86,0.00803,0.22906
89.9,7.492,27237.42,0.00805,0.23037
90,7.5,27252.65,0.00806,0.22877
90.1,7.509,27203.62,0.00808,0.23011
90.2,7.517,27238.45,0.00809,0.22978
90.3,7.525,27255.87,0.00811,0.23305
90.4,7.533,27288.09,0.00813,0.2298
90.5,7.542,27366.79,0.00814,0.22931
90.6,7.55,27461.94,0.00816,0.22803
90.7,7.559,27505.98,0.00817,0.22962
90.8,7.567,27551.86,0.00819,0.22793
90.9,7.575,27605.61,0.00821,0.22879
91,7.583,27708.03,0.00822,0.22593
91.1,7.592,27764.09,0.00824,0.22609
91.2,7.6,27797.77,0.00825,0.22705
91.3,7.609,27816.36,0.00827,0.22493
91.4,7.617,27836.07,0.00828,0.22656
91.5,7.625,27896.84,0.0083,0.22479
91.6,7.633,27950.07,0.00832,0.22642
91.7,7.642,28030.75,0.00833,0.22533
91.8,7.65,28109.17,0.00835,0.22665
91.9,7.659,28161.38,0.00836,0.22621
92,7.667,28205.2,0.00838,0.22655
92.1,7.675,28272.03,0.0084,0.22616
92.2,7.683,28304.87,0.00841,0.22584
92.3,7.692,28322.01,0.00843,0.22586
92.4,7.7,28333.08,0.00844,0.22591
92.5,7.708,28390.44,0.00846,0.22608
92.6,7.717,28492.81,0.00848,0.22605
92.7,7.725,28542.75,0.00849,0.22605
92.8,7.734,28581.55,0.00851,0.22605
92.9,7.742,28634.46,0.00852,0.22605
93,7.75,28719.17,0.00854,0.22604
93.1,7.758,28761.67,0.00855,0.22604
93.2,7.767,28794.7,0.00857,0.22604
93.3,7.775,28849.29,0.00859,0.22603
93.4,7.784,28903.32,0.0086,0.22603
93.5,7.792,28960.36,0.00862,0.22603
93.6,7.8,29009.27,0.00863,0.22602
93.7,7.809,29075.59,0.00865,0.22602
93.8,7.817,29142.35,0.00867,0.22602
93.9,7.825,29178.21,0.00868,0.22602
94,7.834,29231.81,0.0087,0.22601
94.1,7.842,29290.08,0.00871,0.22601
94.2,7.85,29317.15,0.00873,0.22601
94.3,7.858,29344.59,0.00875,0.22601
94.4,7.867,29381.34,0.00876,0.22601
94.5,7.875,29442.91,0.00878,0.226
94.6,7.883,29527.39,0.00879,0.226
94.7,7.892,29605.75,0.00881,0.226
94.8,7.9,29667.16,0.00882,0.226
94.9,7.909,29737.55,0.00884,0.226
95,7.917,29806.39,0.00886,0.226
95.1,7.925,29820.08,0.00887,0.22599
95.2,7.933,29834.31,0.00889,0.22599
95.3,7.942,29871.55,0.0089,0.22599
95.4,7.95,29915.18,0.00892,0.22599
95.5,7.959,29983.83,0.00894,0.22599
95.6,7.967,30016.01,0.00895,0.22599
95.7,7.975,30073.46,0.00897,0.22599
95.8,7.984,30146.16,0.00898,0.22598
95.9,7.992,30217.29,0.009,0.22598
96,8,30304.38,0.00902,0.22598
96.1,8.009,30360.45,0.00903,0.22598
96.2,8.017,30383.19,0.00905,0.22598
96.3,8.025,30428.5,0.00906,0.22598
96.4,8.034,30476.02,0.00908,0.22598
96.5,8.042,30545.35,0.00909,0.22598
96.6,8.05,30595.03,0.00911,0.22597
96.7,8.058,30627.21,0.00913,0.22597
96.8,8.067,30668.47,0.00914,0.22597
96.9,8.075,30743.79,0.00916,0.22597
97,8.083,30818.85,0.00917,0.22597
97.1,8.092,30868.64,0.00919,0.22597
97.2,8.1,30888.35,0.00921,0.22597
97.3,8.108,30909.85,0.00922,0.22597
97.4,8.117,30990.37,0.00924,0.22597
97.5,8.125,31074.96,0.00925,0.22597
97.6,8.134,31147.26,0.00927,0.22596
97.7,8.142,31211.07,0.00929,0.22596
97.8,8.15,31244.7,0.0093,0.22596
97.9,8.158,31290.86,0.00932,0.22596
98,8.167,31354.8,0.00933,0.22596
98.1,8.175,31366.43,0.00935,0.22596
98.2,8.184,31380.92,0.00936,0.22596
98.3,8.192,31406.67,0.00938,0.22596
98.4,8.2,31368.62,0.0094,0.22596
98.5,8.208,31394.54,0.00941,0.22597
98.6,8.217,31424.34,0.00943,0.22597
98.7,8.225,31515.27,0.00944,0.22597
98.8,8.233,31606.34,0.00946,0.22597
98.9,8.242,31696.78,0.00948,0.22597
99,8.25,31784.71,0.00949,0.22597
99.1,8.258,31862.37,0.00951,0.22597
99.2,8.267,31922.76,0.00952,0.22597
99.3,8.275,31968.84,0.00954,0.22596
99.4,8.283,31995.87,0.00955,0.22596
99.5,8.292,32030.9,0.00957,0.22596
99.6,8.3,32068.99,0.00959,0.22596
99.7,8.308,32101.8,0.0096,0.22596
99.8,8.317,32166.42,0.00962,0.22596
99.9,8.325,32237.17,0.00963,0.22596
100,8.334,32302.02,0.00965,0.22596
100.1,8.342,32384.89,0.00967,0.22596
100.2,8.35,32418.46,0.00968,0.22596
100.3,8.358,32453.04,0.0097,0.22596
100.4,8.367,32502.24,0.00971,0.22596
100.5,8.375,32581.18,0.00973,0.22595
100.6,8.383,32665.9,0.00975,0.22595
100.7,8.392,32719.61,0.00976,0.22595
100.8,8.4,32774.49,0.00978,0.22595
100.9,8.409,32665.19,0.00979,0.22595
101,8.417,32565.01,0.00981,0.22595
101.1,8.425,32648.71,0.00982,0.22596
101.2,8.433,32715.14,0.00984,0.22596
101.3,8.442,32784.62,0.00986,0.22596
101.4,8.45,32856.07,0.00987,0.22596
101.5,8.459,32879.95,0.00989,0.22596
101.6,8.467,32906.65,0.0099,0.22596
101.7,8.475,32949.75,0.00992,0.22596
101.8,8.484,33051.67,0.00994,0.22596
101.9,8.492,33131.57,0.00995,0.22596
102,8.5,33201.94,0.00997,0.22596
102.1,8.509,33298.86,0.00998,0.22596
102.2,8.517,33366.98,0.01,0.22596
102.3,8.525,33455.6,0.01002,0.22595
102.4,8.534,33487.22,0.01003,0.22595
102.5,8.542,33490.56,0.01005,0.22595
102.6,8.55,33495.14,0.01006,0.22595
102.7,8.559,33552.1,0.01008,0.22595
102.8,8.567,33636.2,0.01009,0.22595
102.9,8.575,33692.35,0.01011,0.22595
103,8.584,33766.79,0.01013,0.22595
103.1,8.592,33889.29,0.01014,0.22595
103.2,8.6,33939.89,0.01016,0.22595
103.3,8.608,33979.87,0.01017,0.22595
103.4,8.617,34007.78,0.01019,0.22595
103.5,8.625,34072.16,0.01021,0.22595
103.6,8.633,34170.72,0.01022,0.22595
103.7,8.642,34214.74,0.01024,0.22595
103.8,8.65,34264.53,0.01025,0.22595
103.9,8.658,34299.36,0.01027,0.22595
104,8.667,34345.82,0.01028,0.22595
104.1,8.675,34409.77,0.0103,0.22595
104.2,8.683,34474.42,0.01032,0.22594
104.3,8.692,34515.71,0.01033,0.22595
104.4,8.7,34544.75,0.01035,0.22594
104.5,8.709,34654.96,0.01036,0.22594
104.6,8.717,34754.95,0.01038,0.22594
104.7,8.725,34822.8,0.0104,0.22594
104.8,8.734,34881.31,0.01041,0.22594
104.9,8.742,34962.51,0.01043,0.22594
105,8.75,34990.74,0.01044,0.22594
105.1,8.759,34999.32,0.01046,0.22594
105.2,8.767,35025.26,0.01048,0.22594
105.3,8.775,35079.38,0.01049,0.22594
105.4,8.783,35129.74,0.01051,0.22594
105.5,8.792,35195.15,0.01052,0.22594
105.6,8.8,35295.92,0.01054,0.22594
105.7,8.808,35376.52,0.01055,0.22594
105.8,8.817,35445.3,0.01057,0.22594
105.9,8.825,35496.54,0.01059,0.22594
106,8.833,35542.23,0.0106,0.22594
106.1,8.842,35584.73,0.01062,0.22594
106.2,8.85,35625.04,0.01063,0.22594
106.3,8.859,35700.55,0.01065,0.22594
106.4,8.867,35738.38,0.01067,0.22594
106.5,8.875,35780.47,0.01068,0.22594
106.6,8.884,35852.2,0.0107,0.22594
106.7,8.892,35964.47,0.01071,0.22594
106.8,8.9,36007.09,0.01073,0.22594
106.9,8.909,36033.95,0.01075,0.22594
107,8.917,36085.89,0.01076,0.22594
107.1,8.925,36166.91,0.01078,0.22594
107.2,8.934,36240.87,0.01079,0.22594
107.3,8.942,36293.13,0.01081,0.22594
107.4,8.95,36354.8,0.01082,0.22594
107.5,8.959,36404.34,0.01084,0.22594
107.6,8.967,36483.55,0.01086,0.22594
107.7,8.975,36536.65,0.01087,0.22594
107.8,8.984,36543.86,0.01089,0.22594
107.9,8.992,36560.66,0.0109,0.22594
108,9,36604.74,0.01092,0.22594
108.1,9.008,36706.54,0.01094,0.22595
108.2,9.017,36793.6,0.01095,0.22595
108.3,9.025,36854.15,0.01097,0.22595
108.4,9.034,36932.1,0.01098,0.22595
108.5,9.042,37023.64,0.011,0.22595
108.6,9.05,37051.04,0.01102,0.22595
108.7,9.059,37083.71,0.01103,0.22595
108.8,9.067,37113.92,0.01105,0.22595
108.9,9.075,37174.39,0.01106,0.22595
109,9.084,37218.8,0.01108,0.22595
109.1,9.092,37299.39,0.01109,0.22595
109.2,9.1,37375.67,0.01111,0.22595
109.3,9.109,37421.17,0.01113,0.22595
109.4,9.117,37521.61,0.01114,0.22595
109.5,9.125,37589.57,0.01116,0.22595
109.6,9.134,37618.5,0.01117,0.22595
109.7,9.142,37647.63,0.01119,0.22595
109.8,9.15,37700.54,0.01121,0.22595
109.9,9.159,37781.59,0.01122,0.22595
110,9.167,37829.44,0.01124,0.22595
110.1,9.175,37916.81,0.01125,0.22595
110.2,9.183,38004.39,0.01127,0.22595
110.3,9.192,38054.45,0.01128,0.22595
110.4,9.2,38077.09,0.0113,0.22595
110.5,9.208,38098.94,0.01132,0.22595
110.6,9.217,38133.98,0.01133,0.22595
110.7,9.225,38205.14,0.01135,0.22595
110.8,9.233,38272.67,0.01136,0.22595
110.9,9.242,38365.42,0.01138,0.22595
111,9.25,38437.97,0.0114,0.22595
111.1,9.258,38479.09,0.01141,0.22595
111.2,9.267,38549.22,0.01143,0.22595
111.3,9.275,38593.62,0.01144,0.22595
111.4,9.283,38627.62,0.01146,0.22595
111.5,9.292,38665.41,0.01148,0.22596
111.6,9.3,38747.44,0.01149,0.22596
111.7,9.309,38809.12,0.01151,0.22596
111.8,9.317,38863.09,0.01152,0.22596
111.9,9.325,38945.83,0.01154,0.22596
112,9.333,39057.66,0.01155,0.22596
112.1,9.342,39108.44,0.01157,0.22596
112.2,9.35,39127.04,0.01159,0.22596
112.3,9.358,39150.52,0.0116,0.22596
112.4,9.367,39199.33,0.01162,0.22596
112.5,9.375,39278.06,0.01163,0.22596
112.6,9.383,39340.83,0.01165,0.22596
112.7,9.392,39420,0.01167,0.22596
112.8,9.4,39482.29,0.01168,0.22596
112.9,9.408,39542.93,0.0117,0.22596
113,9.417,39607.09,0.01171,0.22596
113.1,9.425,39624.79,0.01173,0.22596
113.2,9.434,39636.76,0.01175,0.22596
113.3,9.442,39682.52,0.01176,0.22596
113.4,9.45,39802.04,0.01178,0.22596
113.5,9.458,39866.76,0.01179,0.22596
113.6,9.467,39914.49,0.01181,0.22596
113.7,9.475,39969.74,0.01182,0.22596
113.8,9.484,40062.93,0.01184,0.22596
113.9,9.492,40136.74,0.01186,0.22596
114,9.5,40199.17,0.01187,0.22596
114.1,9.508,40215.77,0.01189,0.22596
114.2,9.517,40257.49,0.0119,0.22596
114.3,9.525,40335.34,0.01192,0.22596
114.4,9.534,40402.98,0.01194,0.22596
114.5,9.542,40479.86,0.01195,0.22596
114.6,9.55,40527.04,0.01197,0.22596
114.7,9.558,40601.62,0.01198,0.22596
114.8,9.567,40635.66,0.012,0.22596
114.9,9.575,40675.79,0.01202,0.22596
115,9.584,40724.88,0.01203,0.22596
115.1,9.592,40767.93,0.01205,0.22596
115.2,9.6,40867.07,0.01206,0.22596
115.3,9.609,40948.77,0.01208,0.22596
115.4,9.617,41011,0.01209,0.22596
115.5,9.625,41085.09,0.01211,0.22596
115.6,9.633,41132.2,0.01213,0.22596
115.7,9.642,41150.41,0.01214,0.22596
115.8,9.65,41186.15,0.01216,0.22596
115.9,9.659,41231,0.01217,0.22596
116,9.667,41311.3,0.01219,0.22596
116.1,9.675,41358.63,0.01221,0.22596
116.2,9.684,41433.98,0.01222,0.22596
116.3,9.692,41508.84,0.01224,0.22596
116.4,9.7,41617.05,0.01225,0.22596
116.5,9.709,41697.58,0.01227,0.22596
116.6,9.717,41719.76,0.01228,0.22596
116.7,9.725,41764.8,0.0123,0.22596
116.8,9.733,41794.61,0.01232,0.22596
116.9,9.742,41877.21,0.01233,0.22596
117,9.75,41924.82,0.01235,0.22596
117.1,9.758,41987.76,0.01236,0.22596
117.2,9.767,42050.23,0.01238,0.22596
117.3,9.775,42147.87,0.0124,0.22596
117.4,9.783,42192.91,0.01241,0.22596
117.5,9.792,42222.49,0.01243,0.22596
117.6,9.8,42257.83,0.01244,0.22596
117.7,9.808,42340.57,0.01246,0.22596
117.8,9.817,42431.61,0.01248,0.22596
117.9,9.825,42499.24,0.01249,0.22596
118,9.833,42549.06,0.01251,0.22596
118.1,9.842,42611.43,0.01252,0.22596
118.2,9.85,42676.88,0.01254,0.22596
118.3,9.858,42685.68,0.01255,0.22596
118.4,9.867,42709.89,0.01257,0.22596
118.5,9.875,42749.82,0.01259,0.22596
118.6,9.884,42833.27,0.0126,0.22596
118.7,9.892,42932.5,0.01262,0.22596
118.8,9.9,43023.25,0.01263,0.22596
118.9,9.908,43088.89,0.01265,0.22596
119,9.917,43208.99,0.01267,0.22596
119.1,9.925,43272.94,0.01268,0.22596
119.2,9.934,43292.01,0.0127,0.22596
119.3,9.942,43302.71,0.01271,0.22596
119.4,9.95,43343.43,0.01273,0.22596
119.5,9.958,43393.79,0.01275,0.22596
119.6,9.967,43459.42,0.01276,0.22596
119.7,9.975,43558.69,0.01278,0.22596
119.8,9.983,43606.71,0.01279,0.22596
119.9,9.992,43687.62,0.01281,0.22596
120,10,43748.53,0.01282,0.22596
120.1,10.009,43786.59,0.01284,0.22596
120.2,10.017,43829.44,0.01286,0.22596
120.3,10.025,43915.56,0.01287,0.22596
120.4,10.034,44001.02,0.01289,0.22596
120.5,10.042,44063.24,0.0129,0.22596
120.6,10.05,44105.08,0.01292,0.22596
120.7,10.059,44165.58,0.01294,0.22596
120.8,10.067,44201.25,0.01295,0.22596
120.9,10.075,44228.18,0.01297,0.22596
121,10.084,44278.34,0.01298,0.22596
121.1,10.092,44359.08,0.013,0.22596
121.2,10.1,44446.77,0.01302,0.22596
121.3,10.109,44504.96,0.01303,0.22596
121.4,10.117,44616.64,0.01305,0.22596
121.5,10.125,44701.22,0.01306,0.22595
121.6,10.133,44784.51,0.01308,0.22595
121.7,10.142,44730.91,0.01309,0.22595
121.8,10.15,44806.81,0.01311,0.22595
121.9,10.159,44809.64,0.01313,0.22595
122,10.167,44882.11,0.01314,0.22595
122.1,10.175,44983.46,0.01316,0.22595
122.2,10.184,45042.88,0.01317,0.22595
122.3,10.192,45112.71,0.01319,0.22595
122.4,10.2,45220.39,0.01321,0.22595
122.5,10.209,45295.11,0.01322,0.22595
122.6,10.217,45324.67,0.01324,0.22595
122.7,10.225,45344.1,0.01325,0.22595
122.8,10.234,45425.62,0.01327,0.22595
122.9,10.242,45501.46,0.01328,0.22595
123,10.25,45534.31,0.0133,0.22595
123.1,10.259,45588.14,0.01332,0.22595
123.2,10.267,45621.45,0.01333,0.22595
123.3,10.275,45701.78,0.01335,0.22595
123.4,10.284,45784.99,0.01336,0.22595
123.5,10.292,45839.04,0.01338,0.22596
123.6,10.3,45864.78,0.0134,0.22596
123.7,10.308,45957.02,0.01341,0.22595
123.8,10.317,46066.42,0.01343,0.22595
123.9,10.325,46144.7,0.01344,0.22596
124,10.333,46211.54,0.01346,0.22596
124.1,10.342,46286.42,0.01348,0.22596
124.2,10.35,46310.76,0.01349,0.22596
124.3,10.358,46328.34,0.01351,0.22596
124.4,10.367,46353.46,0.01352,0.22596
124.5,10.375,46407.96,0.01354,0.22596
124.6,10.383,46499.55,0.01355,0.22596
124.7,10.392,46576.88,0.01357,0.22596
124.8,10.4,46663.59,0.01359,0.22596
124.9,10.408,46739.31,0.0136,0.22596
125,10.417,46821.8,0.01362,0.22596
125.1,10.425,46865.54,0.01363,0.22596
125.2,10.433,46909.62,0.01365,0.22596
125.3,10.442,46931.05,0.01367,0.22596
125.4,10.45,46996.93,0.01368,0.22596
125.5,10.459,47048.31,0.0137,0.22596
125.6,10.467,47101.74,0.01371,0.22596
125.7,10.475,47182.5,0.01373,0.22596
125.8,10.483,47285.18,0.01375,0.22596
125.9,10.492,47334.46,0.01376,0.22596
126,10.5,47387.26,0.01378,0.22596
126.1,10.509,47440.86,0.01379,0.22596
126.2,10.517,47511.16,0.01381,0.22596
126.3,10.525,47564.3,0.01382,0.22596
126.4,10.533,47631.44,0.01384,0.22596
126.5,10.542,47707.47,0.01386,0.22596
126.6,10.55,47756.34,0.01387,0.22596
126.7,10.559,47834.17,0.01389,0.22596
126.8,10.567,47851.7,0.0139,0.22596
126.9,10.575,47871.96,0.01392,0.22596
127,10.583,47917.39,0.01394,0.22596
127.1,10.592,48030.48,0.01395,0.22596
127.2,10.6,48109.49,0.01397,0.22596
127.3,10.609,48173.17,0.01398,0.22596
127.4,10.617,48259.03,0.014,0.22596
127.5,10.625,48363.9,0.01401,0.22596
127.6,10.634,48386.62,0.01403,0.22596
127.7,10.642,48416.44,0.01405,0.22596
127.8,10.65,48442.85,0.01406,0.22597
127.9,10.659,48507.55,0.01408,0.22596
128,10.667,48575.33,0.01409,0.22596
128.1,10.675,48650.69,0.01411,0.22597
128.2,10.684,48706.96,0.01413,0.22597
128.3,10.692,48810.62,0.01414,0.22597
128.4,10.7,48915.44,0.01416,0.22597
128.5,10.708,48948.91,0.01417,0.22597
128.6,10.717,48972.45,0.01419,0.22596
128.7,10.725,49007.22,0.01421,0.22597
128.8,10.734,49102.22,0.01422,0.22597
128.9,10.742,49175.63,0.01424,0.22597
129,10.75,49251.86,0.01425,0.22597
129.1,10.759,49308.67,0.01427,0.22597
129.2,10.767,49370.78,0.01428,0.22597
129.3,10.775,49397.81,0.0143,0.22597
129.4,10.784,49432.96,0.01432,0.22597
129.5,10.792,49490.08,0.01433,0.22597
129.6,10.8,49572.93,0.01435,0.22597
129.7,10.808,49645.36,0.01436,0.22597
129.8,10.817,49741.75,0.01438,0.22597
129.9,10.825,49794.21,0.0144,0.22597
130,10.834,49865.88,0.01441,0.22597
130.1,10.842,49911.83,0.01443,0.22597
130.2,10.85,49947.4,0.01444,0.22597
130.3,10.858,49990.49,0.01446,0.22597
130.4,10.867,50054.89,0.01448,0.22597
130.5,10.875,50127.45,0.01449,0.22597
130.6,10.883,50205.98,0.01451,0.22597
130.7,10.892,50290.5,0.01452,0.22597
130.8,10.9,50401.38,0.01454,0.22597
130.9,10.908,50443.16,0.01455,0.22597
131,10.917,50461.04,0.01457,0.22597
131.1,10.925,50479.95,0.01459,0.22597
131.2,10.933,50549.24,0.0146,0.22597
131.3,10.942,50662.04,0.01462,0.22597
131.4,10.95,50720.7,0.01463,0.22597
131.5,10.958,50785.96,0.01465,0.22597
131.6,10.967,50847.4,0.01467,0.22597
131.7,10.975,50924.56,0.01468,0.22597
131.8,10.983,50951.56,0.0147,0.22597
131.9,10.992,50981.95,0.01471,0.22597
132,11,51030.66,0.01473,0.22597
132.1,11.009,51127.54,0.01475,0.22597
132.2,11.017,51190.18,0.01476,0.22597
132.3,11.025,51252.26,0.01478,0.22597
132.4,11.034,51319.25,0.01479,0.22597
132.5,11.042,51409.46,0.01481,0.22597
132.6,11.05,51481.33,0.01482,0.22597
132.7,11.058,51515.24,0.01484,0.22597
132.8,11.067,51532.63,0.01486,0.22597
132.9,11.075,51636.77,0.01487,0.22597
133,11.084,51696.25,0.01489,0.22597
133.1,11.092,51777.64,0.0149,0.22597
133.2,11.1,51843.46,0.01492,0.22597
133.3,11.109,51911.29,0.01494,0.22597
133.4,11.117,51969.33,0.01495,0.22597
133.5,11.125,52005.89,0.01497,0.22597
133.6,11.134,52043.39,0.01498,0.22597
133.7,11.142,52116.28,0.015,0.22597
133.8,11.15,52226.47,0.01502,0.22597
133.9,11.158,52290.14,0.01503,0.22597
134,11.167,52348.74,0.01505,0.22597
134.1,11.175,52419.49,0.01506,0.22597
134.2,11.184,52472.65,0.01508,0.22597
134.3,11.192,52519.45,0.01509,0.22597
134.4,11.2,52547.41,0.01511,0.22597
134.5,11.209,52589.99,0.01513,0.22597
134.6,11.217,52663.32,0.01514,0.22597
134.7,11.225,52734.91,0.01516,0.22597
134.8,11.233,52831.61,0.01517,0.22597
134.9,11.242,52923.7,0.01519,0.22597
135,11.25,53014.91,0.01521,0.22597
135.1,11.258,53045.18,0.01522,0.22597
135.2,11.267,53089.39,0.01524,0.22597
135.3,11.275,53118.24,0.01525,0.22597
135.4,11.283,53190.17,0.01527,0.22597
135.5,11.292,53240.1,0.01528,0.22597
135.6,11.3,53313.75,0.0153,0.22597
135.7,11.308,53392.93,0.01532,0.22597
135.8,11.317,53497.15,0.01533,0.22597
135.9,11.325,52120.07,0.01535,0.22609
136,11.334,52274.07,0.01536,0.226
136.1,11.342,52366.93,0.01538,0.226
136.2,11.35,52461.17,0.0154,0.226
136.3,11.359,52526.23,0.01541,0.226
136.4,11.367,52572.5,0.01543,0.226
136.5,11.375,52664.02,0.01544,0.226
136.6,11.384,52771.59,0.01546,0.226
136.7,11.392,52898.83,0.01548,0.226
136.8,11.4,53016.18,0.01549,0.226
136.9,11.409,53067.8,0.01551,0.226
137,11.417,53108.37,0.01552,0.226
137.1,11.425,53194.69,0.01554,0.226
137.2,11.433,53263.42,0.01555,0.226
137.3,11.442,53360.02,0.01557,0.226
137.4,11.45,53491.3,0.01559,0.226
137.5,11.458,53529.88,0.0156,0.226
137.6,11.467,53577.2,0.01562,0.226
137.7,11.475,53672.29,0.01563,0.226
137.8,11.483,53763.09,0.01565,0.226
137.894,11.493,21207.49,0.01567,0.2261