File: Labs/Lab 2 Tension/CFRP 0 Degree Sample 3.csv
Time (s),Extension (mm),Load (N),Axial Strain (mm/mm),Transverse Strain (mm/mm)
0,0,-0.21,-0.00002,0
0.2,0.014,60.6,0.00001,0.00001
0.4,0.034,290.33,0.00007,0.00003
0.6,0.05,394.54,0.0001,0.00005
0.8,0.067,453.24,0.00012,0.00005
1,0.084,471.64,0.00013,0.00006
1.2,0.1,475.97,0.00013,0.00006
1.4,0.117,474.79,0.00013,0.00006
1.6,0.134,475.7,0.00012,0.00006
1.8,0.15,473.73,0.00012,0.00006
2,0.167,474.45,0.00012,0.00006
2.2,0.184,476.35,0.00012,0.00006
2.4,0.2,476.39,0.00011,0.00006
2.6,0.217,477.39,0.00011,0.00007
2.8,0.233,477.67,0.00011,0.00007
3,0.25,480.39,0.00012,0.00007
3.2,0.267,488.92,0.00012,0.00007
3.4,0.284,497.93,0.00013,0.00007
3.6,0.3,515.74,0.00013,0.00008
3.8,0.317,536.12,0.00014,0.00008
4,0.334,549.09,0.00014,0.00009
4.2,0.35,570.89,0.00014,0.00009
4.4,0.367,599.82,0.00015,0.00009
4.6,0.383,650.62,0.00015,0.00009
4.8,0.4,696.44,0.00016,0.0001
5,0.417,720.57,0.00016,0.0001
5.2,0.433,742.02,0.00016,0.0001
5.4,0.45,764.09,0.00017,0.00011
5.6,0.467,792.84,0.00017,0.00011
5.8,0.484,817.72,0.00018,0.00011
6,0.5,845.41,0.00018,0.00011
6.2,0.517,860.65,0.00018,0.00011
6.4,0.534,872.1,0.00018,0.00012
6.6,0.55,878.93,0.00018,0.00012
6.8,0.567,910.66,0.00018,0.00012
7,0.584,938.25,0.00018,0.00012
7.2,0.6,969.31,0.00019,0.00012
7.4,0.617,996.06,0.00019,0.00012
7.6,0.634,1010.54,0.00019,0.00013
7.8,0.65,1017.94,0.00019,0.00013
8,0.667,1025.96,0.00018,0.00013
8.2,0.684,1032.16,0.00019,0.00013
8.4,0.7,1037.25,0.00019,0.00013
8.6,0.717,1048.28,0.00019,0.00013
8.8,0.733,1054.78,0.00019,0.00014
9,0.75,1063.19,0.0002,0.00014
9.2,0.767,1073.83,0.0002,0.00014
9.4,0.783,1077.4,0.0002,0.00014
9.6,0.8,1083.81,0.0002,0.00014
9.8,0.817,1087.32,0.0002,0.00015
10,0.834,1087.86,0.0002,0.00015
10.2,0.85,1088.44,0.00019,0.00014
10.4,0.867,1077.9,0.00018,0.00014
10.6,0.884,1076.3,0.00018,0.00014
10.8,0.9,1078.42,0.00017,0.00014
11,0.917,1084.77,0.00018,0.00014
11.2,0.934,1086.95,0.00018,0.00015
11.4,0.95,1095.08,0.00019,0.00015
11.6,0.967,1103.84,0.0002,0.00016
11.8,0.984,1122.96,0.00021,0.00016
12,1,1161.86,0.00022,0.00016
12.2,1.017,1192.04,0.00022,0.00017
12.4,1.034,1219.78,0.00023,0.00017
12.6,1.05,1248.23,0.00023,0.00017
12.8,1.067,1282.53,0.00024,0.00018
13,1.084,1319.05,0.00025,0.00018
13.2,1.1,1341.93,0.00026,0.00019
13.4,1.117,1375.25,0.00027,0.00019
13.6,1.134,1429.05,0.00027,0.00019
13.8,1.15,1487.84,0.00028,0.0002
14,1.167,1525.16,0.00029,0.0002
14.2,1.183,1542.37,0.0003,0.00021
14.4,1.2,1557.34,0.00031,0.00021
14.6,1.217,1584,0.00031,0.00021
14.8,1.234,1616.3,0.00032,0.00022
15,1.25,1643.09,0.00034,0.00022
15.2,1.267,1679.03,0.00034,0.00023
15.4,1.284,1725.58,0.00035,0.00023
15.6,1.3,1763.5,0.00036,0.00024
15.8,1.317,1791.4,0.00037,0.00024
16,1.333,1829.64,0.00037,0.00024
16.2,1.35,1864.11,0.00039,0.00025
16.4,1.367,1891.41,0.0004,0.00025
16.6,1.384,1940.35,0.00041,0.00026
16.8,1.4,1985.68,0.00042,0.00026
17,1.417,2015.4,0.00042,0.00027
17.2,1.434,2036.08,0.00043,0.00027
17.4,1.45,2045.81,0.00044,0.00027
17.6,1.467,2054.22,0.00045,0.00028
17.8,1.484,2070.89,0.00046,0.00028
18,1.5,2085.99,0.00046,0.00029
18.2,1.517,2123.78,0.00047,0.00029
18.4,1.533,2176.94,0.00048,0.00029
18.6,1.55,2231.29,0.00049,0.0003
18.8,1.567,2268.44,0.00049,0.0003
19,1.583,2316.23,0.0005,0.00031
19.2,1.6,2367.06,0.00051,0.00031
19.4,1.617,2414.55,0.00052,0.00031
19.6,1.633,2442.15,0.00053,0.00032
19.8,1.65,2473.23,0.00054,0.00032
20,1.667,2524.87,0.00055,0.00033
20.2,1.683,2557.52,0.00056,0.00033
20.4,1.7,2576.58,0.00057,0.00034
20.6,1.717,2593.21,0.00059,0.00034
20.8,1.734,2610.59,0.0006,0.00035
21,1.75,2639.97,0.00061,0.00035
21.2,1.767,2686.09,0.00062,0.00036
21.4,1.784,2751.94,0.00063,0.00036
21.6,1.8,2790.69,0.00064,0.00037
21.8,1.817,2852.04,0.00066,0.00038
22,1.834,2906.4,0.00067,0.00038
22.2,1.85,2966.3,0.00069,0.00039
22.4,1.867,3056.62,0.0007,0.00039
22.6,1.884,3094.68,0.00071,0.0004
22.8,1.9,3120.73,0.00072,0.0004
23,1.917,3142.61,0.00074,0.00041
23.2,1.934,3158.09,0.00075,0.00041
23.4,1.95,3186.7,0.00076,0.00042
23.6,1.967,3248.43,0.00078,0.00042
23.8,1.984,3301.64,0.00079,0.00043
24,2,3380.97,0.00081,0.00044
24.2,2.017,3451.6,0.00083,0.00044
24.4,2.034,3509.86,0.00084,0.00045
24.6,2.05,3570.27,0.00086,0.00046
24.8,2.067,3589.49,0.00088,0.00046
25,2.083,3616.87,0.00089,0.00047
25.2,2.1,3687.38,0.00091,0.00048
25.4,2.117,3777.84,0.00093,0.00048
25.6,2.134,3841.32,0.00094,0.00049
25.8,2.15,3896.98,0.00096,0.0005
26,2.167,3944.57,0.00098,0.0005
26.2,2.184,4016.52,0.00099,0.00051
26.4,2.2,4099.86,0.00101,0.00052
26.6,2.217,4145.61,0.00103,0.00052
26.8,2.234,4162.48,0.00105,0.00053
27,2.25,4192.76,0.00107,0.00054
27.2,2.267,4276.62,0.00108,0.00054
27.4,2.284,4326.36,0.0011,0.00055
27.6,2.3,4400.07,0.00112,0.00056
27.8,2.317,4487.84,0.00114,0.00056
28,2.334,4558.95,0.00115,0.00057
28.2,2.35,4616.82,0.00117,0.00058
28.4,2.367,4641.23,0.00119,0.00058
28.6,2.383,4657.87,0.0012,0.00059
28.8,2.4,4680.66,0.00122,0.0006
29,2.417,4794.13,0.00124,0.00061
29.2,2.433,4883.8,0.00126,0.00061
29.4,2.45,4947.51,0.00127,0.00062
29.6,2.467,5003.18,0.00129,0.00063
29.8,2.483,5076.01,0.00131,0.00063
30,2.5,5126.92,0.00133,0.00064
30.2,2.517,5167.35,0.00134,0.00065
30.4,2.533,5202.25,0.00136,0.00065
30.6,2.55,5245.97,0.00138,0.00066
30.8,2.567,5319.73,0.0014,0.00067
31,2.584,5372.38,0.00142,0.00067
31.2,2.6,5448.05,0.00143,0.00068
31.4,2.617,5536.91,0.00145,0.00069
31.6,2.634,5648.32,0.00147,0.0007
31.8,2.65,5681.82,0.00149,0.0007
32,2.667,5710.73,0.00151,0.00071
32.2,2.684,5728.71,0.00153,0.00072
32.4,2.7,5812.34,0.00155,0.00072
32.6,2.717,5888.59,0.00156,0.00073
32.8,2.734,5965.55,0.00158,0.00074
33,2.75,6020.56,0.0016,0.00075
33.2,2.767,6103.85,0.00162,0.00075
33.4,2.784,6144.58,0.00164,0.00076
33.6,2.8,6193.33,0.00166,0.00077
33.8,2.817,6249.67,0.00168,0.00078
34,2.834,6343.36,0.0017,0.00078
34.2,2.85,6423.53,0.00172,0.00079
34.4,2.867,6490.51,0.00174,0.0008
34.6,2.884,6563.44,0.00176,0.00081
34.8,2.9,6647.02,0.00178,0.00081
35,2.917,6672.58,0.0018,0.00082
35.2,2.934,6704.08,0.00182,0.00083
35.4,2.95,6729.34,0.00184,0.00084
35.6,2.967,6806.34,0.00186,0.00084
35.8,2.983,6915.22,0.00188,0.00085
36,3,7004.8,0.0019,0.00086
36.2,3.017,7086.53,0.00192,0.00086
36.4,3.034,7210.33,0.00194,0.00087
36.6,3.05,7234.18,0.00196,0.00088
36.8,3.067,7258.94,0.00198,0.00089
37,3.084,7293.03,0.002,0.00089
37.2,3.1,7353.28,0.00202,0.0009
37.4,3.117,7415.25,0.00204,0.00091
37.6,3.134,7499.4,0.00206,0.00092
37.8,3.15,7552.15,0.00208,0.00092
38,3.167,7679.6,0.0021,0.00093
38.2,3.184,7737.39,0.00212,0.00094
38.4,3.2,7778.07,0.00214,0.00095
38.6,3.217,7841.55,0.00216,0.00096
38.8,3.233,7950.07,0.00218,0.00096
39,3.25,8021.86,0.0022,0.00097
39.2,3.267,8074.8,0.00223,0.00098
39.4,3.283,8139.85,0.00225,0.00099
39.6,3.3,8187.76,0.00227,0.00099
39.8,3.317,8235.02,0.00229,0.001
40,3.334,8291,0.00231,0.00101
40.2,3.35,8403.54,0.00233,0.00102
40.4,3.367,8487.75,0.00235,0.00103
40.6,3.383,8606.59,0.00237,0.00103
40.8,3.4,8698.12,0.0024,0.00104
41,3.417,8779.75,0.00242,0.00105
41.2,3.433,8783.86,0.00244,0.00106
41.4,3.45,8787.2,0.00247,0.00107
41.6,3.467,8874.96,0.00249,0.00108
41.8,3.484,8973.11,0.00251,0.00109
42,3.5,9084.26,0.00254,0.00109
42.2,3.517,9209.58,0.00256,0.0011
42.4,3.534,9276,0.00258,0.00111
42.6,3.55,9332.45,0.00261,0.00112
42.8,3.567,9411.73,0.00263,0.00113
43,3.583,9492.16,0.00265,0.00114
43.2,3.6,9541.06,0.00267,0.00114
43.4,3.617,9591.82,0.0027,0.00115
43.6,3.634,9706.74,0.00272,0.00116
43.8,3.65,9784.89,0.00274,0.00117
44,3.667,9823.47,0.00277,0.00118
44.2,3.683,9925.16,0.00279,0.00119
44.4,3.7,10027.28,0.00281,0.0012
44.6,3.717,10168.61,0.00284,0.00121
44.8,3.733,10246.3,0.00286,0.00121
45,3.75,10288.89,0.00289,0.00122
45.2,3.767,10289.22,0.00291,0.00123
45.4,3.783,10327.96,0.00294,0.00124
45.6,3.8,10487.86,0.00297,0.00125
45.8,3.817,10580.5,0.00299,0.00126
46,3.833,10681.99,0.00301,0.00127
46.2,3.85,10809.66,0.00304,0.00128
46.4,3.867,10882.48,0.00306,0.00128
46.6,3.884,10905.23,0.00308,0.00129
46.8,3.9,10977.49,0.00311,0.0013
47,3.917,11028.65,0.00314,0.00131
47.2,3.934,11131.3,0.00316,0.00132
47.4,3.95,11274.62,0.00319,0.00133
47.6,3.967,11344.97,0.00321,0.00134
47.8,3.983,11399.06,0.00324,0.00135
48,4,11507.32,0.00327,0.00136
48.2,4.017,11625.58,0.00329,0.00137
48.4,4.034,11697.41,0.00331,0.00138
48.6,4.05,11769.25,0.00334,0.00138
48.8,4.067,11803.23,0.00336,0.00139
49,4.084,11868.25,0.00339,0.0014
49.2,4.1,11978.03,0.00342,0.00141
49.4,4.117,12083.54,0.00344,0.00142
49.6,4.133,12214.4,0.00347,0.00143
49.8,4.15,12336.13,0.00349,0.00144
50,4.167,12391.24,0.00351,0.00145
50.2,4.183,12409.28,0.00354,0.00146
50.4,4.2,12461.1,0.00356,0.00147
50.6,4.217,12564.72,0.00359,0.00148
50.8,4.234,12656.59,0.00361,0.00148
51,4.25,12801.06,0.00364,0.00149
51.2,4.267,12874.73,0.00367,0.0015
51.4,4.283,12938.18,0.00369,0.00151
51.6,4.3,13003.43,0.00371,0.00152
51.8,4.317,13117.42,0.00374,0.00153
52,4.333,13189.23,0.00377,0.00154
52.2,4.35,13283.62,0.00379,0.00155
52.4,4.367,13360.18,0.00382,0.00156
52.6,4.384,13410.6,0.00384,0.00157
52.8,4.4,13495.57,0.00387,0.00157
53,4.417,13635.96,0.00389,0.00158
53.2,4.434,13746.31,0.00392,0.00159
53.4,4.45,13834.32,0.00394,0.0016
53.6,4.467,13906.5,0.00397,0.00161
53.8,4.483,13944.09,0.00399,0.00162
54,4.5,14018.03,0.00402,0.00163
54.2,4.517,14116.49,0.00405,0.00164
54.4,4.534,14240.12,0.00408,0.00165
54.6,4.55,14382.62,0.0041,0.00166
54.8,4.567,14449.86,0.00413,0.00167
55,4.583,14473.97,0.00415,0.00168
55.2,4.6,14587.69,0.00418,0.00169
55.4,4.617,14700.41,0.00421,0.0017
55.6,4.633,14795.51,0.00424,0.0017
55.8,4.65,14893.3,0.00427,0.00171
56,4.667,14962.15,0.00429,0.00172
56.2,4.683,15068.09,0.00432,0.00173
56.4,4.7,15174.4,0.00435,0.00174
56.6,4.717,15263.38,0.00438,0.00175
56.8,4.733,15389.53,0.0044,0.00176
57,4.75,15471.91,0.00443,0.00177
57.2,4.767,15501.24,0.00446,0.00178
57.4,4.784,15608.61,0.00449,0.00179
57.6,4.8,15724.76,0.00451,0.0018
57.8,4.817,15853.18,0.00454,0.00181
58,4.834,15955.49,0.00457,0.00182
58.2,4.85,15979.88,0.0046,0.00183
58.4,4.867,16075.85,0.00463,0.00184
58.6,4.883,16209.9,0.00465,0.00185
58.8,4.9,16302.13,0.00468,0.00186
59,4.917,16412.55,0.0047,0.00187
59.2,4.934,16507.02,0.00473,0.00188
59.4,4.95,16542.81,0.00476,0.00189
59.6,4.967,16651.71,0.00479,0.0019
59.8,4.984,16750.67,0.00482,0.00191
60,5,16887.53,0.00484,0.00192
60.2,5.017,16999.41,0.00487,0.00193
60.4,5.034,17037.82,0.0049,0.00194
60.6,5.05,17117.45,0.00493,0.00195
60.8,5.067,17244.58,0.00496,0.00196
61,5.083,17338.42,0.00499,0.00197
61.2,5.1,17454.58,0.00502,0.00198
61.4,5.117,17526.85,0.00504,0.00199
61.6,5.133,17623.77,0.00507,0.002
61.8,5.15,17740.04,0.0051,0.00201
62,5.167,17857.83,0.00513,0.00202
62.2,5.183,17965.93,0.00516,0.00203
62.4,5.2,18033.82,0.00518,0.00204
62.6,5.217,18063.1,0.00521,0.00205
62.8,5.234,18215.88,0.00524,0.00206
63,5.25,18340.36,0.00527,0.00207
63.2,5.267,18482.65,0.0053,0.00208
63.4,5.283,18550.52,0.00533,0.00209
63.6,5.3,18599.85,0.00536,0.0021
63.8,5.317,18695.8,0.00538,0.00211
64,5.333,18801.58,0.00542,0.00212
64.2,5.35,18912.64,0.00544,0.00213
64.4,5.367,19049.67,0.00547,0.00214
64.6,5.384,19131.98,0.0055,0.00215
64.8,5.4,19249.25,0.00553,0.00216
65,5.417,19350.56,0.00556,0.00217
65.2,5.433,19418.4,0.00559,0.00218
65.4,5.45,19539.68,0.00561,0.00219
65.6,5.467,19606.26,0.00564,0.0022
65.8,5.483,19722.15,0.00567,0.00221
66,5.5,19870.01,0.0057,0.00222
66.2,5.517,19992.12,0.00573,0.00223
66.4,5.533,20097.69,0.00576,0.00224
66.6,5.55,20102.37,0.00579,0.00225
66.8,5.567,20191.05,0.00582,0.00226
67,5.584,20324.73,0.00585,0.00227
67.2,5.6,20472.62,0.00588,0.00228
67.4,5.617,20598.06,0.00591,0.00229
67.6,5.633,20690.28,0.00594,0.0023
67.8,5.65,20769.3,0.00597,0.00231
68,5.667,20843.89,0.006,0.00232
68.2,5.683,20933,0.00603,0.00233
68.4,5.7,21092.99,0.00606,0.00234
68.6,5.717,21153.53,0.00609,0.00235
68.8,5.734,21277.18,0.00612,0.00236
69,5.75,21413.03,0.00614,0.00237
69.2,5.767,21525.22,0.00618,0.00238
69.4,5.784,21602.03,0.00621,0.00239
69.6,5.8,21611.14,0.00624,0.0024
69.8,5.817,21758.22,0.00626,0.00242
70,5.833,21891.62,0.00629,0.00243
70.2,5.85,22023.14,0.00632,0.00244
70.4,5.867,22192.25,0.00636,0.00245
70.6,5.884,22225.4,0.00638,0.00246
70.8,5.9,22285,0.00641,0.00247
71,5.917,22381.57,0.00644,0.00248
71.2,5.933,22522.2,0.00647,0.00249
71.4,5.95,22654.79,0.0065,0.0025
71.6,5.967,22725.77,0.00653,0.00251
71.8,5.983,22871.82,0.00656,0.00252
72,6,22985.21,0.00659,0.00253
72.2,6.017,23053.85,0.00662,0.00254
72.4,6.033,23119.23,0.00665,0.00255
72.6,6.05,23215.43,0.00668,0.00256
72.8,6.067,23364.31,0.00671,0.00257
73,6.084,23522.98,0.00674,0.00258
73.2,6.1,23664.02,0.00677,0.00259
73.4,6.117,23725.34,0.0068,0.0026
73.6,6.134,23739.13,0.00683,0.00261
73.8,6.15,23867.35,0.00686,0.00262
74,6.167,24004.24,0.00689,0.00263
74.2,6.183,24172.12,0.00692,0.00264
74.4,6.2,24263.1,0.00695,0.00265
74.6,6.217,24325.07,0.00698,0.00266
74.8,6.234,24441.57,0.00701,0.00267
75,6.25,24523.17,0.00704,0.00268
75.2,6.267,24668.52,0.00708,0.00269
75.4,6.283,24738.7,0.0071,0.0027
75.6,6.3,24849.68,0.00714,0.00271
75.8,6.317,25000.62,0.00716,0.00272
76,6.333,25106.64,0.0072,0.00273
76.2,6.35,25222.29,0.00723,0.00274
76.222,6.352,25226.51,0.00723,0.00274
76.422,6.363,25260.65,0.00725,0.00275
76.622,6.361,25220.56,0.00725,0.00274
76.822,6.36,25172.44,0.00725,0.00274
77.022,6.36,25100.83,0.00725,0.00273
77.222,6.359,25063.71,0.00725,0.00273
77.422,6.359,25028.22,0.00725,0.00272
77.622,6.359,24992.16,0.00725,0.00272
77.822,6.359,24969.85,0.00725,0.00272
78.022,6.359,24934.8,0.00725,0.00272
78.222,6.359,24902.32,0.00725,0.00271
78.422,6.359,24846.15,0.00725,0.00271
78.622,6.359,24813.31,0.00725,0.00271
78.822,6.359,24790.89,0.00725,0.00271
79.022,6.359,24780.41,0.00725,0.00271
79.222,6.359,24768.51,0.00725,0.00271
79.422,6.359,24762.71,0.00725,0.00271
79.622,6.359,24738.44,0.00725,0.00271
79.822,6.359,24732.15,0.00725,0.0027
80.022,6.359,24719.18,0.00725,0.0027
80.222,6.359,24711.93,0.00725,0.0027
80.422,6.359,24703.26,0.00725,0.0027
80.622,6.359,24696.92,0.00725,0.0027
80.822,6.359,24691.79,0.00725,0.0027
81.022,6.359,24684.08,0.00725,0.0027
81.222,6.359,24677.34,0.00725,0.0027
81.422,6.359,24675.19,0.00725,0.0027
81.622,6.359,24670.12,0.00725,0.0027
81.822,6.359,24664.67,0.00725,0.00269
82.022,6.359,24655.97,0.00725,0.0027
82.222,6.359,24646.24,0.00725,0.00271
82.422,6.359,24629.98,0.00725,0.00291
82.622,6.359,24616.33,0.00725,0.00247
82.822,6.359,24602.2,0.00725,0.00237
83.022,6.359,24590.84,0.00725,0.00216
83.222,6.359,24578.24,0.00725,0.00175
83.422,6.359,24558.89,0.00725,0.00207
83.622,6.359,24552.04,0.00725,0.00239
83.822,6.359,24541.18,0.00725,0.00277
84.022,6.359,24532.86,0.00725,0.00834
84.222,6.359,24528.52,0.00725,0.00719
84.422,6.359,24523.88,0.00725,0.00764
84.622,6.359,24516.76,0.00725,0.0087
84.822,6.359,24513.55,0.00725,0.02144
85.022,6.359,24512.01,0.00725,0.01461
85.222,6.359,24505.81,0.00725,-0.03234
85.422,6.359,24502.39,0.00725,-0.09959
85.622,6.359,24501.41,0.00725,-0.09334
85.822,6.359,24495.69,0.00725,-0.09231
86.022,6.359,24492.74,0.00725,-0.08975
86.222,6.359,24489.67,0.00725,-0.09563
86.422,6.359,24483.34,0.00725,-0.09465
86.622,6.359,24478.08,0.00725,0.02479
86.822,6.359,24472.37,0.00725,0.04455
87.022,6.359,24469.91,0.00725,0.04443
87.222,6.359,24465.87,0.00725,0.04394
87.422,6.359,24462.76,0.00725,0.04357
87.622,6.359,24456.75,0.00725,0.04353
87.822,6.359,24455.34,0.00725,0.04194
88.022,6.359,24455.25,0.00725,0.04192
88.222,6.359,24448.46,0.00725,0.04192
88.422,6.359,24449.31,0.00725,0.04196
88.622,6.359,24445.88,0.00725,0.04201
88.822,6.359,24444.32,0.00725,0.04202
89.022,6.359,24442.08,0.00725,0.04204
89.222,6.359,24438.3,0.00725,0.04203
89.422,6.359,24436.77,0.00725,0.04205
89.622,6.359,24437.91,0.00725,0.04205
89.822,6.359,24432.39,0.00725,0.04205
90.022,6.359,24429.93,0.00725,0.04205
90.222,6.359,24428.27,0.00725,0.04205
90.422,6.359,24423.02,0.00725,0.04205
90.622,6.359,24421.08,0.00725,0.04197
90.822,6.359,24418.22,0.00725,0.04198
91.022,6.359,24411.35,0.00725,0.04166
91.222,6.359,24412.43,0.00725,0.04153
91.422,6.359,24410.35,0.00725,0.01628
91.622,6.359,24402.6,0.00725,-0.10422
91.822,6.359,24398.05,0.00725,-0.10293
92.022,6.359,24385.8,0.00725,-0.10446
92.222,6.359,24389.96,0.00725,-0.10298
92.422,6.359,24374.21,0.00725,-0.10509
92.622,6.359,24382.11,0.00725,-0.09839
92.822,6.359,24378.04,0.00725,-0.10925
93.022,6.359,24376.49,0.00725,-0.02192
93.222,6.359,24368.8,0.00725,0.24428
93.422,6.359,24358.56,0.00725,0.24392
93.622,6.359,24347.9,0.00725,0.24252
93.822,6.359,24351.76,0.00725,0.25237
94.022,6.359,24344.09,0.00725,0.2411
94.222,6.359,24345.78,0.00725,0.2446
94.422,6.359,24345.39,0.00725,0.24997
94.622,6.359,24332.71,0.00725,0.24182
94.822,6.359,24331.78,0.00725,0.24106
95.022,6.359,24327.64,0.00725,0.24536
95.222,6.359,24323.87,0.00725,0.20316
95.422,6.359,24325.11,0.00725,0.24506
95.622,6.359,24319.25,0.00725,0.24403
95.822,6.359,24317.18,0.00725,0.2518
96.022,6.359,24316.36,0.00725,0.24679
96.222,6.359,24316.88,0.00725,0.24318
96.422,6.359,24316.39,0.00725,0.24542
96.622,6.359,24313.05,0.00725,0.24697
96.822,6.359,24309.19,0.00725,0.24385
97.022,6.359,24309.52,0.00725,0.24855
97.222,6.359,24308.42,0.00725,0.2487
97.422,6.359,24306.37,0.00725,0.24869
97.622,6.359,24306.26,0.00725,0.24868
97.822,6.359,24303.92,0.00725,0.24867
98.022,6.359,24303.55,0.00725,0.24866
98.222,6.359,24301.58,0.00725,0.24866
98.422,6.359,24302.05,0.00725,0.24865
98.622,6.359,24299.12,0.00725,0.24865
98.822,6.359,24294.92,0.00725,0.24869
99.022,6.359,24297.08,0.00725,0.24869
99.222,6.359,24296.22,0.00725,0.24877
99.422,6.359,24296.57,0.00725,0.24878
99.622,6.359,24294.17,0.00725,0.24876
99.822,6.359,24292.93,0.00725,0.24876
100.022,6.359,24292.69,0.00725,0.24877
100.222,6.359,24290.72,0.00725,0.24876
100.422,6.359,24290.71,0.00725,0.24876
100.622,6.359,24289.83,0.00725,0.24875
100.822,6.359,24288.69,0.00725,0.24875
101.022,6.359,24288.45,0.00725,0.24874
101.222,6.359,24284.46,0.00725,0.24874
101.422,6.359,24286.95,0.00725,0.24874
101.622,6.359,24284.25,0.00725,0.24874
101.822,6.359,24284.99,0.00725,0.24873
102.022,6.359,24284.69,0.00725,0.24873
102.222,6.359,24283.27,0.00725,0.24873
102.422,6.359,24282.7,0.00725,0.24872
102.622,6.359,24281.34,0.00725,0.24872
102.822,6.359,24277.77,0.00725,0.24872
103.022,6.359,24278.4,0.00725,0.24872
103.222,6.359,24276.78,0.00725,0.24871
103.422,6.359,24276.46,0.00725,0.24871
103.622,6.359,24276.71,0.00725,0.24871
103.822,6.359,24274.83,0.00725,0.24871
104.022,6.359,24272.18,0.00725,0.2487
104.222,6.359,24270.72,0.00725,0.2487
104.422,6.359,24269.34,0.00725,0.2487
104.62,6.359,24270.95,0.00725,0.2487
104.722,6.36,24269.44,0.00725,0.2487
104.922,6.375,24390.37,0.00728,0.24869
105.122,6.395,24651.86,0.00732,0.24869
105.322,6.411,24804.46,0.00735,0.24869
105.522,6.428,25069.59,0.00738,0.24869
105.722,6.445,25234.82,0.00742,0.24868
105.922,6.461,25387.11,0.00745,0.24868
106.122,6.478,25597.85,0.00748,0.24868
106.322,6.495,25769.56,0.00752,0.24868
106.522,6.511,25800.73,0.00755,0.24868
106.722,6.528,25910.72,0.00758,0.24867
106.922,6.545,26056.92,0.00762,0.24867
107.122,6.561,26206.48,0.00765,0.24867
107.322,6.578,26330.01,0.00768,0.24867
107.522,6.594,26465.81,0.00772,0.24867
107.722,6.611,26592.55,0.00775,0.24867
107.922,6.628,26771.33,0.00778,0.24866
108.122,6.644,26821.39,0.00782,0.24866
108.322,6.661,26988.11,0.00785,0.24866
108.522,6.678,27160.46,0.00788,0.24866
108.722,6.694,27281.52,0.00792,0.24866
108.922,6.711,27372.28,0.00795,0.24865
109.122,6.728,27540.19,0.00798,0.24865
109.322,6.744,27687.63,0.00802,0.24865
109.522,6.761,27848,0.00805,0.24865
109.722,6.778,27901.38,0.00808,0.24865
109.922,6.794,28069.22,0.00812,0.24865
110.122,6.811,28255.09,0.00815,0.24864
110.322,6.828,28349.71,0.00818,0.24864
110.522,6.845,28339.94,0.00822,0.24876
110.722,6.861,28396.54,0.00825,0.2487
110.922,6.878,28576.93,0.00828,0.24869
111.122,6.895,28710.44,0.00832,0.24869
111.322,6.911,28861.78,0.00835,0.24869
111.522,6.928,28950.55,0.00838,0.24869
111.722,6.945,29099.3,0.00842,0.24868
111.922,6.961,29243.01,0.00845,0.24868
112.122,6.978,29355.12,0.00848,0.24868
112.322,6.995,29348.93,0.00852,0.24865
112.522,7.011,29405.76,0.00855,0.24863
112.722,7.028,29583.93,0.00858,0.24862
112.922,7.045,29754.68,0.00862,0.24862
113.122,7.061,29868.16,0.00865,0.24862
113.322,7.078,29919.54,0.00868,0.24862
113.522,7.094,30061.33,0.00872,0.24862
113.722,7.111,30183.99,0.00875,0.24861
113.922,7.128,30378.21,0.00878,0.24861
114.122,7.144,30461.66,0.00882,0.24861
114.322,7.161,30585.07,0.00885,0.24861
114.522,7.178,30680.36,0.00888,0.24861
114.722,7.194,30802.57,0.00892,0.24861
114.922,7.211,30908.83,0.00895,0.24861
115.122,7.228,30986.36,0.00898,0.24861
115.322,7.245,31179.61,0.00902,0.24861
115.522,7.261,31302.09,0.00905,0.2486
115.722,7.278,31270.48,0.00908,0.24835
115.922,7.295,31405.59,0.00912,0.24836
116.122,7.311,31421.07,0.00915,0.24836
116.322,7.328,31566.95,0.00918,0.24836
116.522,7.345,31745.98,0.00922,0.24836
116.722,7.361,31910.65,0.00925,0.24836
116.922,7.378,32017.49,0.00928,0.24836
117.122,7.395,32064.79,0.00932,0.24836
117.322,7.411,32158.96,0.00935,0.24836
117.522,7.428,32316.38,0.00938,0.24836
117.722,7.445,32448.31,0.00942,0.24836
117.922,7.461,32534,0.00945,0.24836
118.122,7.478,32699.36,0.00948,0.24836
118.322,7.495,32652.72,0.00952,0.24839
118.522,7.511,32810.48,0.00955,0.24838
118.722,7.528,32906.5,0.00958,0.24838
118.922,7.544,32945.68,0.00962,0.24838
119.122,7.561,33107.39,0.00965,0.24838
119.322,7.578,33264.97,0.00968,0.24838
119.522,7.594,33455.2,0.00972,0.24838
119.722,7.611,33532.41,0.00975,0.24838
119.922,7.628,33551.61,0.00978,0.24838
120.122,7.644,33687.7,0.00982,0.24837
120.322,7.661,33845.62,0.00985,0.24837
120.522,7.678,34008.58,0.00988,0.24837
120.722,7.694,34074.2,0.00992,0.24837
120.922,7.711,34246.5,0.00995,0.24837
121.122,7.728,34320.27,0.00998,0.24837
121.322,7.745,34427.96,0.01002,0.24837
121.522,7.761,34537.38,0.01005,0.24837
121.722,7.778,34667.44,0.01008,0.24837
121.922,7.795,34845.79,0.01012,0.24837
122.122,7.811,34993.04,0.01015,0.24837
122.322,7.828,35036.15,0.01018,0.24837
122.522,7.845,35085.44,0.01022,0.24836
122.722,7.861,35250.19,0.01025,0.24836
122.922,7.878,35421.01,0.01028,0.24836
123.122,7.894,35560.89,0.01032,0.24836
123.322,7.911,35630.3,0.01035,0.24836
123.522,7.928,35748.88,0.01038,0.24836
123.722,7.944,35845.32,0.01042,0.24836
123.922,7.961,36006.38,0.01045,0.24836
124.122,7.978,36097.16,0.01048,0.24836
124.322,7.995,36253.11,0.01052,0.24836
124.522,8.011,36375.72,0.01055,0.24836
124.722,8.028,36515.97,0.01058,0.24835
124.922,8.045,36580.22,0.01062,0.24835
125.122,8.061,36645.43,0.01065,0.24835
125.322,8.078,36824.77,0.01068,0.24835
125.522,8.094,36979,0.01072,0.24835
125.722,8.111,37095.89,0.01075,0.24835
125.922,8.128,37146.91,0.01078,0.24835
126.122,8.144,37288.05,0.01082,0.24835
126.322,8.161,37411.61,0.01085,0.24835
126.522,8.178,37572.97,0.01088,0.24835
126.722,8.194,37677.27,0.01092,0.24835
126.922,8.211,37792.89,0.01095,0.24835
127.122,8.228,37920.95,0.01098,0.24835
127.322,8.244,38075.55,0.01102,0.24835
127.522,8.261,38129.67,0.01105,0.24834
127.722,8.278,38219.01,0.01108,0.24834
127.922,8.294,38402.62,0.01112,0.24834
128.122,8.311,38542.85,0.01115,0.24834
128.322,8.328,38622.18,0.01118,0.24834
128.522,8.345,38718.96,0.01122,0.24834
128.722,8.361,38844.11,0.01125,0.24834
128.922,8.378,38975.94,0.01128,0.24834
129.122,8.395,39160.81,0.01132,0.24834
129.322,8.411,39199.82,0.01135,0.24834
129.522,8.428,39335.71,0.01138,0.24834
129.722,8.444,39494.59,0.01142,0.24834
129.922,8.461,39635.26,0.01145,0.24834
130.122,8.478,39675.64,0.01148,0.24834
130.322,8.494,39836.77,0.01152,0.24834
130.522,8.511,39956.48,0.01155,0.24834
130.722,8.528,40087.25,0.01158,0.24834
130.922,8.545,40228.98,0.01162,0.24834
131.122,8.561,40292.65,0.01165,0.24834
131.322,8.578,40449.45,0.01168,0.24834
131.522,8.595,40593.86,0.01172,0.24834
131.722,8.611,40685.02,0.01175,0.24834
131.922,8.628,40766.93,0.01178,0.24834
132.122,8.645,40941.32,0.01182,0.24834
132.322,8.661,41081.34,0.01185,0.24834
132.522,8.678,41196.9,0.01188,0.24834
132.722,8.695,41258.82,0.01192,0.24834
132.922,8.711,41386.55,0.01195,0.24834
133.122,8.728,41531.45,0.01198,0.24834
133.322,8.745,41722.07,0.01202,0.24834
133.522,8.761,41780.16,0.01205,0.24835
133.722,8.778,41919.4,0.01208,0.24835
133.922,8.795,42019.38,0.01212,0.24835
134.122,8.811,42156.72,0.01215,0.24836
134.322,8.828,42263.03,0.01218,0.24836
134.522,8.844,42386.66,0.01222,0.24836
134.722,8.861,42543.3,0.01225,0.24836
134.922,8.878,42687.18,0.01228,0.24837
135.122,8.894,42741.19,0.01232,0.24837
135.322,8.911,42808.9,0.01235,0.24837
135.522,8.928,43001.41,0.01238,0.24837
135.722,8.944,43147.9,0.01242,0.24837
135.922,8.961,43317.55,0.01245,0.24837
136.122,8.978,43348.51,0.01248,0.24837
136.322,8.994,43455.1,0.01252,0.24838
136.522,9.011,43617.97,0.01255,0.24838
136.722,9.028,43768.48,0.01258,0.24838
136.922,9.045,43861.88,0.01262,0.24838
137.122,9.061,44026.01,0.01265,0.24838
137.322,9.078,44139.28,0.01268,0.24838
137.522,9.095,44243.13,0.01272,0.24838
137.722,9.111,44320.91,0.01275,0.24838
137.922,9.128,44479.08,0.01278,0.24838
138.122,9.145,44638.56,0.01282,0.24838
138.322,9.161,44658.7,0.01285,0.2484
138.522,9.178,44846.3,0.01288,0.24843
138.722,9.195,44848.74,0.01292,0.24842
138.922,9.211,44978.72,0.01295,0.24843
139.122,9.228,45157.41,0.01298,0.24842
139.322,9.245,45333.53,0.01302,0.24843
139.522,9.261,45421.18,0.01305,0.24843
139.722,9.278,45422.25,0.01308,0.24843
139.922,9.294,45561.56,0.01312,0.24843
140.122,9.311,45644,0.01315,0.24843
140.322,9.328,45829.32,0.01318,0.24843
140.522,9.344,45912.07,0.01322,0.24843
140.722,9.361,46099.87,0.01325,0.24843
140.922,9.378,46262.05,0.01328,0.24843
141.122,9.394,46351.26,0.01332,0.24843
141.322,9.411,46395.07,0.01335,0.24843
141.522,9.428,46565.76,0.01338,0.24843
141.722,9.444,46731.16,0.01342,0.24843
141.922,9.461,46897.35,0.01345,0.24843
142.122,9.478,46974.92,0.01348,0.24843
142.322,9.495,47062.57,0.01352,0.24843
142.522,9.511,47198.4,0.01355,0.24843
142.722,9.528,47369.27,0.01358,0.24843
142.922,9.545,47448.52,0.01362,0.24842
143.122,9.561,47616.16,0.01365,0.24842
143.322,9.578,47741.49,0.01368,0.24842
143.522,9.594,47864.97,0.01372,0.24842
143.722,9.611,47912.61,0.01375,0.24842
143.922,9.628,48088.29,0.01378,0.24842
144.122,9.645,48246.75,0.01382,0.24842
144.322,9.661,48407.23,0.01385,0.24842
144.522,9.678,48469.7,0.01388,0.24842
144.722,9.695,48564.88,0.01392,0.24842
144.922,9.711,48711.55,0.01395,0.24842
145.122,9.728,48907.29,0.01398,0.24842
145.322,9.744,49008.32,0.01402,0.24842
145.522,9.761,49111.37,0.01405,0.24842
145.722,9.778,49259.66,0.01408,0.24842
145.922,9.794,49384.58,0.01412,0.24842
146.122,9.811,49460.06,0.01415,0.24842
146.322,9.828,49598.25,0.01418,0.24842
146.522,9.844,49772.4,0.01422,0.24842
146.722,9.861,49913.22,0.01425,0.24842
146.922,9.878,49992.87,0.01428,0.24842
147.122,9.895,50104.52,0.01432,0.24842
147.322,9.911,50233.66,0.01435,0.24842
147.522,9.928,50421.69,0.01438,0.24842
147.722,9.944,50503.82,0.01442,0.24842
147.922,9.961,50564.41,0.01445,0.24842
148.122,9.978,50763.09,0.01448,0.24842
148.322,9.994,50907.67,0.01452,0.24842
148.522,10.011,50990.96,0.01455,0.24842
148.722,10.028,51122.95,0.01458,0.24842
148.922,10.045,51248.74,0.01462,0.24842
149.122,10.061,51379.37,0.01465,0.24842
149.322,10.078,51541.55,0.01468,0.24842
149.522,10.095,51582.14,0.01472,0.24843
149.722,10.111,51772.75,0.01475,0.24843
149.922,10.128,51922.56,0.01478,0.24843
150.122,10.145,52014.01,0.01482,0.24843
150.322,10.161,52105.29,0.01485,0.24843
150.522,10.178,52287.72,0.01488,0.24843
150.722,10.194,52412.91,0.01492,0.24844
150.922,10.211,52545.46,0.01495,0.24844
151.122,10.228,52605.75,0.01498,0.24844
151.322,10.244,52746,0.01502,0.24844
151.522,10.261,52923.52,0.01505,0.24844
151.722,10.278,53076.81,0.01508,0.24845
151.922,10.295,53149.76,0.01512,0.24845
152.122,10.311,53271.43,0.01515,0.24845
152.322,10.328,53397.94,0.01518,0.24846
152.522,10.345,53565.96,0.01522,0.24846
152.722,10.361,53635.66,0.01525,0.24846
152.922,10.378,53818.2,0.01528,0.24846
153.122,10.394,53939.64,0.01532,0.24847
153.322,10.411,54042.79,0.01535,0.24847
153.522,10.428,54108.13,0.01538,0.24848
153.722,10.444,54290.8,0.01542,0.24848
153.922,10.461,54465.24,0.01545,0.24849
154.122,10.478,54633.53,0.01548,0.2485
154.322,10.494,54664.72,0.01552,0.2485
154.522,10.511,54771.73,0.01555,0.24851
154.722,10.528,54925.51,0.01558,0.24851
154.922,10.544,55098.8,0.01562,0.24852
155.122,10.561,55191.36,0.01565,0.24852
155.322,10.578,55339.6,0.01568,0.24852
155.522,10.595,55448.11,0.01572,0.24853
155.722,10.611,55548.99,0.01575,0.24853
155.922,10.628,55659.62,0.01578,0.24854
156.122,10.644,55797.2,0.01582,0.24854
156.322,10.661,56001.51,0.01585,0.24854
156.522,10.678,56151.02,0.01588,0.24854
156.722,10.694,56154.8,0.01592,0.24854
156.922,10.711,56284.33,0.01595,0.24855
157.122,10.728,56435.35,0.01598,0.24855
157.322,10.745,56605.62,0.01602,0.24855
157.522,10.761,56716.38,0.01605,0.24856
157.722,10.777,56449.64,0.01608,0.24856
157.748,10.782,21377.4,0.01609,0.24824