File: Labs/Lab 2 Tension/Specimen_RawData_1.csv
Specimen label,"Aluminum"
End date,"Monday, October 14, 2019"
Thickness,"6.43000",mm
Width,"12.05000",mm
Final length,"74.50000",mm
Axial gauge length,"25.40000",mm
Transverse gauge length,"12.05000",mm
Crosshead Rate,"5.00",mm/min

Time,Extension,Load,Axial Strain,Transverse Strain
(s),(mm),(N),(mm/mm),(mm/mm)
"0.000","0.000","-0.11","0.00000","0.00000"
"0.200","0.014","309.46","0.00004","0.00001"
"0.400","0.033","877.78","0.00015","0.00006"
"0.600","0.050","1256.65","0.00023","0.00009"
"0.800","0.067","1708.58","0.00030","0.00012"
"1.000","0.084","2012.71","0.00036","0.00015"
"1.200","0.100","2273.61","0.00040","0.00017"
"1.400","0.117","2398.72","0.00041","0.00018"
"1.600","0.134","2497.52","0.00043","0.00019"
"1.800","0.150","2527.62","0.00044","0.00020"
"2.000","0.167","2592.63","0.00045","0.00021"
"2.200","0.184","2703.52","0.00047","0.00022"
"2.400","0.200","2839.14","0.00049","0.00023"
"2.600","0.217","2992.92","0.00050","0.00024"
"2.800","0.234","3081.80","0.00052","0.00025"
"3.000","0.250","3116.10","0.00053","0.00025"
"3.200","0.267","3248.47","0.00055","0.00025"
"3.400","0.284","3374.45","0.00056","0.00026"
"3.600","0.300","3494.82","0.00058","0.00026"
"3.800","0.317","3560.63","0.00059","0.00027"
"4.000","0.334","3707.20","0.00061","0.00027"
"4.200","0.350","3834.46","0.00063","0.00028"
"4.400","0.367","3943.26","0.00065","0.00028"
"4.600","0.384","4069.63","0.00067","0.00029"
"4.800","0.400","4122.29","0.00069","0.00029"
"5.000","0.417","4269.55","0.00071","0.00030"
"5.200","0.433","4452.88","0.00072","0.00031"
"5.400","0.450","4575.95","0.00074","0.00031"
"5.600","0.467","4617.55","0.00077","0.00032"
"5.800","0.484","4805.27","0.00079","0.00033"
"6.000","0.500","4933.69","0.00081","0.00033"
"6.200","0.517","5067.03","0.00083","0.00033"
"6.400","0.534","5164.68","0.00085","0.00034"
"6.600","0.550","5306.60","0.00087","0.00035"
"6.800","0.567","5460.96","0.00090","0.00036"
"7.000","0.584","5617.58","0.00092","0.00037"
"7.200","0.600","5691.26","0.00094","0.00037"
"7.400","0.617","5892.67","0.00096","0.00038"
"7.600","0.634","6042.39","0.00099","0.00038"
"7.800","0.650","6137.87","0.00101","0.00039"
"8.000","0.667","6315.77","0.00104","0.00040"
"8.200","0.684","6460.38","0.00106","0.00040"
"8.400","0.700","6628.57","0.00109","0.00041"
"8.600","0.717","6689.07","0.00111","0.00042"
"8.800","0.734","6897.98","0.00114","0.00042"
"9.000","0.750","7120.25","0.00116","0.00043"
"9.200","0.767","7203.62","0.00119","0.00044"
"9.400","0.784","7343.72","0.00122","0.00045"
"9.600","0.800","7498.65","0.00124","0.00046"
"9.800","0.817","7683.73","0.00127","0.00047"
"10.000","0.834","7850.10","0.00130","0.00047"
"10.200","0.850","8012.81","0.00132","0.00048"
"10.400","0.867","8147.51","0.00135","0.00049"
"10.600","0.884","8260.31","0.00138","0.00050"
"10.800","0.900","8506.76","0.00141","0.00050"
"11.000","0.917","8703.91","0.00143","0.00051"
"11.200","0.933","8734.21","0.00146","0.00052"
"11.400","0.950","8934.30","0.00149","0.00053"
"11.600","0.967","9171.14","0.00152","0.00054"
"11.800","0.984","9301.71","0.00155","0.00055"
"12.000","1.000","9468.52","0.00158","0.00056"
"12.200","1.017","9649.12","0.00160","0.00057"
"12.400","1.034","9775.27","0.00163","0.00058"
"12.600","1.050","10012.89","0.00166","0.00058"
"12.800","1.067","10213.89","0.00169","0.00059"
"13.000","1.084","10240.47","0.00172","0.00061"
"13.200","1.100","10486.92","0.00175","0.00062"
"13.400","1.117","10739.23","0.00178","0.00063"
"13.600","1.134","10848.80","0.00181","0.00063"
"13.800","1.150","10983.25","0.00184","0.00064"
"14.000","1.167","11236.93","0.00187","0.00065"
"14.200","1.184","11370.90","0.00190","0.00066"
"14.400","1.200","11609.75","0.00193","0.00067"
"14.600","1.217","11728.68","0.00196","0.00069"
"14.800","1.234","11884.03","0.00199","0.00069"
"15.000","1.250","12131.22","0.00202","0.00071"
"15.200","1.267","12346.63","0.00206","0.00072"
"15.400","1.284","12414.46","0.00209","0.00073"
"15.600","1.300","12641.67","0.00212","0.00074"
"15.800","1.317","12856.89","0.00215","0.00076"
"16.000","1.333","13041.09","0.00219","0.00077"
"16.200","1.350","13198.83","0.00222","0.00077"
"16.400","1.367","13348.55","0.00226","0.00078"
"16.600","1.383","13596.67","0.00229","0.00079"
"16.800","1.400","13836.97","0.00232","0.00081"
"17.000","1.417","13899.61","0.00236","0.00082"
"17.200","1.434","14150.40","0.00239","0.00083"
"17.400","1.450","14389.30","0.00242","0.00084"
"17.600","1.467","14486.87","0.00246","0.00085"
"17.800","1.484","14705.85","0.00250","0.00088"
"18.000","1.500","14885.89","0.00254","0.00088"
"18.200","1.517","15105.25","0.00257","0.00090"
"18.400","1.534","15313.31","0.00261","0.00091"
"18.600","1.550","15427.97","0.00265","0.00092"
"18.800","1.567","15667.99","0.00268","0.00093"
"19.000","1.584","15907.62","0.00272","0.00094"
"19.200","1.600","16035.24","0.00275","0.00096"
"19.400","1.617","16247.75","0.00279","0.00097"
"19.600","1.634","16459.13","0.00283","0.00098"
"19.800","1.650","16608.93","0.00287","0.00100"
"20.000","1.667","16869.41","0.00291","0.00100"
"20.200","1.684","16975.35","0.00295","0.00102"
"20.400","1.700","17215.64","0.00299","0.00103"
"20.600","1.717","17409.71","0.00303","0.00105"
"20.800","1.733","17554.99","0.00307","0.00106"
"21.000","1.750","17778.59","0.00312","0.00108"
"21.200","1.767","17982.84","0.00316","0.00109"
"21.400","1.783","18130.72","0.00320","0.00110"
"21.600","1.800","18377.98","0.00325","0.00115"
"21.800","1.817","18525.42","0.00330","0.00116"
"22.000","1.834","18704.69","0.00334","0.00118"
"22.200","1.850","18955.39","0.00339","0.00120"
"22.400","1.867","19090.33","0.00344","0.00121"
"22.600","1.884","19299.10","0.00349","0.00122"
"22.800","1.900","19483.15","0.00354","0.00124"
"23.000","1.917","19623.77","0.00360","0.00126"
"23.200","1.934","19889.05","0.00365","0.00128"
"23.400","1.950","20042.52","0.00371","0.00129"
"23.600","1.967","20154.67","0.00376","0.00131"
"23.800","1.984","20397.00","0.00382","0.00134"
"24.000","2.000","20582.10","0.00388","0.00135"
"24.200","2.017","20735.91","0.00394","0.00138"
"24.400","2.034","20873.38","0.00401","0.00140"
"24.600","2.050","21064.24","0.00408","0.00142"
"24.800","2.067","21240.43","0.00416","0.00147"
"25.000","2.084","21436.52","0.00423","0.00150"
"25.200","2.100","21544.01","0.00431","0.00152"
"25.400","2.117","21635.08","0.00440","0.00155"
"25.600","2.133","21850.15","0.00449","0.00158"
"25.800","2.150","22065.04","0.00459","0.00162"
"26.000","2.167","22166.49","0.00469","0.00166"
"26.200","2.184","22236.67","0.00479","0.00169"
"26.400","2.200","22368.83","0.00490","0.00173"
"26.600","2.217","22540.58","0.00501","0.00178"
"26.800","2.233","22642.32","0.00514","0.00182"
"27.000","2.250","22734.67","0.00527","0.00187"
"27.200","2.267","22886.74","0.00540","0.00192"
"27.400","2.284","22954.90","0.00554","0.00197"
"27.600","2.300","23037.12","0.00569","0.00203"
"27.800","2.317","23084.53","0.00585","0.00208"
"28.000","2.334","23163.90","0.00601","0.00214"
"28.200","2.350","23269.21","0.00617","0.00221"
"28.400","2.367","23367.50","0.00635","0.00227"
"28.600","2.384","23476.57","0.00653","0.00234"
"28.800","2.400","23564.05","0.00670","0.00241"
"29.000","2.417","23652.55","0.00689","0.00248"
"29.200","2.434","23667.67","0.00708","0.00256"
"29.400","2.450","23667.89","0.00727","0.00263"
"29.600","2.467","23670.38","0.00747","0.00271"
"29.800","2.484","23713.87","0.00767","0.00279"
"30.000","2.500","23784.57","0.00787","0.00286"
"30.200","2.517","23845.59","0.00808","0.00295"
"30.400","2.534","23909.26","0.00829","0.00303"
"30.600","2.550","23961.33","0.00850","0.00311"
"30.800","2.567","24018.77","0.00872","0.00320"
"31.000","2.584","24100.59","0.00894","0.00329"
"31.200","2.600","24134.75","0.00916","0.00338"
"31.400","2.617","24158.03","0.00938","0.00346"
"31.600","2.633","24175.77","0.00960","0.00355"
"31.800","2.650","24200.09","0.00983","0.00364"
"32.000","2.667","24230.49","0.01006","0.00373"
"32.200","2.683","24247.51","0.01029","0.00382"
"32.400","2.700","24277.38","0.01053","0.00392"
"32.600","2.717","24312.86","0.01076","0.00401"
"32.800","2.734","24341.37","0.01099","0.00410"
"33.000","2.750","24362.30","0.01123","0.00420"
"33.200","2.767","24370.50","0.01147","0.00430"
"33.400","2.784","24381.34","0.01172","0.00440"
"33.600","2.800","24393.46","0.01196","0.00450"
"33.800","2.817","24414.56","0.01221","0.00459"
"34.000","2.834","24428.72","0.01245","0.00469"
"34.200","2.850","24445.48","0.01270","0.00479"
"34.400","2.867","24456.15","0.01295","0.00488"
"34.600","2.884","24466.21","0.01319","0.00498"
"34.800","2.900","24476.76","0.01344","0.00507"
"35.000","2.917","24508.79","0.01369","0.00517"
"35.200","2.934","24531.37","0.01394","0.00527"
"35.400","2.950","24552.81","0.01419","0.00537"
"35.600","2.967","24583.93","0.01445","0.00547"
"35.800","2.984","24607.97","0.01470","0.00557"
"36.000","3.000","24617.18","0.01496","0.00566"
"36.200","3.017","24628.36","0.01521","0.00576"
"36.400","3.033","24639.11","0.01547","0.00586"
"36.600","3.050","24651.40","0.01572","0.00596"
"36.800","3.067","24662.30","0.01598","0.00605"
"37.000","3.084","24667.21","0.01623","0.00615"
"37.200","3.100","24679.78","0.01649","0.00625"
"37.400","3.117","24687.94","0.01675","0.00635"
"37.600","3.134","24698.29","0.01700","0.00645"
"37.800","3.150","24708.10","0.01726","0.00655"
"38.000","3.167","24712.56","0.01752","0.00664"
"38.200","3.184","24719.63","0.01778","0.00675"
"38.400","3.200","24727.19","0.01804","0.00685"
"38.600","3.217","24739.18","0.01830","0.00695"
"38.800","3.234","24744.99","0.01856","0.00705"
"39.000","3.250","24767.57","0.01883","0.00715"
"39.200","3.267","24780.18","0.01908","0.00725"
"39.400","3.284","24807.81","0.01934","0.00734"
"39.600","3.300","24834.25","0.01960","0.00744"
"39.800","3.317","24858.72","0.01987","0.00754"
"40.000","3.334","24881.97","0.02012","0.00763"
"40.200","3.350","24890.91","0.02038","0.00774"
"40.400","3.367","24913.38","0.02064","0.00784"
"40.600","3.384","24926.32","0.02090","0.00794"
"40.800","3.400","24934.15","0.02116","0.00804"
"41.000","3.417","24952.17","0.02142","0.00813"
"41.200","3.434","24960.44","0.02168","0.00823"
"41.400","3.450","24974.19","0.02194","0.00833"
"41.600","3.467","24990.90","0.02220","0.00843"
"41.800","3.484","24997.98","0.02245","0.00853"
"42.000","3.500","25008.39","0.02271","0.00862"
"42.200","3.517","25013.82","0.02297","0.00872"
"42.400","3.533","25026.05","0.02323","0.00881"
"42.600","3.550","25031.19","0.02349","0.00891"
"42.800","3.567","25038.78","0.02374","0.00902"
"43.000","3.584","25055.92","0.02400","0.00912"
"43.200","3.600","25072.60","0.02426","0.00921"
"43.400","3.617","25087.55","0.02452","0.00931"
"43.600","3.634","25110.28","0.02478","0.00941"
"43.800","3.650","25124.00","0.02503","0.00950"
"44.000","3.667","25134.07","0.02529","0.00960"
"44.200","3.684","25143.80","0.02555","0.00970"
"44.400","3.700","25150.70","0.02581","0.00979"
"44.600","3.717","25155.48","0.02606","0.00989"
"44.800","3.734","25156.86","0.02632","0.00998"
"45.000","3.750","25158.08","0.02657","0.01008"
"45.200","3.767","25159.96","0.02684","0.01017"
"45.400","3.784","25160.49","0.02709","0.01027"
"45.600","3.800","25160.41","0.02735","0.01037"
"45.800","3.817","25161.47","0.02760","0.01047"
"46.000","3.834","25164.92","0.02786","0.01058"
"46.200","3.850","25162.97","0.02812","0.01067"
"46.400","3.867","25166.52","0.02837","0.01077"
"46.600","3.884","25167.92","0.02863","0.01087"
"46.800","3.900","25174.13","0.02889","0.01096"
"47.000","3.917","25180.64","0.02914","0.01106"
"47.200","3.933","25182.54","0.02940","0.01115"
"47.400","3.950","25190.87","0.02965","0.01125"
"47.600","3.967","25196.96","0.02991","0.01134"
"47.800","3.984","25204.30","0.03016","0.01144"
"48.000","4.000","25208.43","0.03041","0.01154"
"48.200","4.017","25216.36","0.03067","0.01163"
"48.400","4.034","25219.24","0.03093","0.01172"
"48.600","4.050","25229.99","0.03119","0.01182"
"48.800","4.067","25234.21","0.03144","0.01191"
"49.000","4.084","25253.15","0.03169","0.01200"
"49.200","4.100","25261.97","0.03195","0.01210"
"49.400","4.117","25275.35","0.03221","0.01219"
"49.600","4.134","25284.51","0.03246","0.01228"
"49.800","4.150","25293.47","0.03271","0.01237"
"50.000","4.167","25307.23","0.03297","0.01246"
"50.200","4.184","25315.26","0.03322","0.01256"
"50.400","4.200","25320.99","0.03347","0.01264"
"50.600","4.217","25332.59","0.03373","0.01274"
"50.800","4.234","25342.37","0.03398","0.01284"
"51.000","4.250","25356.03","0.03423","0.01293"
"51.200","4.267","25374.68","0.03449","0.01302"
"51.400","4.284","25375.28","0.03474","0.01311"
"51.600","4.300","25394.44","0.03500","0.01321"
"51.800","4.317","25409.71","0.03526","0.01331"
"52.000","4.334","25419.52","0.03551","0.01340"
"52.200","4.350","25440.66","0.03576","0.01349"
"52.400","4.367","25448.09","0.03601","0.01358"
"52.600","4.383","25459.47","0.03626","0.01368"
"52.800","4.400","25481.32","0.03651","0.01377"
"53.000","4.417","25491.21","0.03676","0.01387"
"53.200","4.434","25501.42","0.03700","0.01396"
"53.400","4.450","25511.14","0.03726","0.01405"
"53.600","4.467","25515.17","0.03751","0.01414"
"53.800","4.484","25529.07","0.03777","0.01424"
"54.000","4.500","25534.31","0.03803","0.01433"
"54.200","4.517","25539.75","0.03828","0.01443"
"54.400","4.534","25549.59","0.03853","0.01452"
"54.600","4.550","25559.04","0.03879","0.01461"
"54.800","4.567","25567.05","0.03904","0.01470"
"55.000","4.584","25571.32","0.03930","0.01479"
"55.200","4.600","25584.30","0.03955","0.01488"
"55.400","4.617","25603.32","0.03980","0.01498"
"55.600","4.634","25612.17","0.04006","0.01507"
"55.800","4.650","25621.38","0.04032","0.01516"
"56.000","4.667","25637.03","0.04057","0.01525"
"56.200","4.684","25652.91","0.04082","0.01534"
"56.400","4.700","25671.17","0.04108","0.01543"
"56.600","4.717","25672.21","0.04133","0.01553"
"56.800","4.734","25689.55","0.04158","0.01562"
"57.000","4.750","25694.88","0.04184","0.01571"
"57.200","4.767","25699.96","0.04210","0.01580"
"57.400","4.783","25708.65","0.04235","0.01589"
"57.600","4.800","25714.76","0.04261","0.01599"
"57.800","4.817","25713.23","0.04286","0.01608"
"58.000","4.834","25717.57","0.04312","0.01617"
"58.200","4.850","25720.91","0.04338","0.01626"
"58.400","4.867","25722.83","0.04363","0.01635"
"58.600","4.883","25723.75","0.04388","0.01644"
"58.800","4.900","25729.69","0.04414","0.01654"
"59.000","4.917","25731.72","0.04439","0.01663"
"59.200","4.934","25731.35","0.04465","0.01674"
"59.400","4.950","25732.24","0.04491","0.01683"
"59.600","4.967","25736.90","0.04517","0.01692"
"59.800","4.984","25740.89","0.04542","0.01701"
"60.000","5.000","25743.54","0.04568","0.01711"
"60.200","5.017","25748.36","0.04593","0.01720"
"60.400","5.034","25755.35","0.04619","0.01729"
"60.600","5.050","25756.97","0.04645","0.01738"
"60.800","5.067","25760.57","0.04670","0.01748"
"61.000","5.084","25765.58","0.04696","0.01757"
"61.200","5.100","25767.81","0.04722","0.01766"
"61.400","5.117","25774.40","0.04748","0.01770"
"61.600","5.133","25773.79","0.04773","0.01779"
"61.800","5.150","25778.32","0.04799","0.01789"
"62.000","5.167","25777.98","0.04825","0.01799"
"62.200","5.184","25781.67","0.04851","0.01809"
"62.400","5.200","25781.29","0.04877","0.01818"
"62.600","5.217","25786.76","0.04903","0.01828"
"62.800","5.233","25789.23","0.04928","0.01837"
"63.000","5.250","25796.60","0.04954","0.01847"
"63.200","5.267","25797.82","0.04980","0.01856"
"63.400","5.284","25803.50","0.05006","0.01865"
"63.600","5.300","25812.95","0.05031","0.01874"
"63.800","5.317","25817.29","0.05057","0.01884"
"64.000","5.334","25829.67","0.05083","0.01894"
"64.200","5.350","25837.26","0.05110","0.01903"
"64.400","5.367","25839.57","0.05135","0.01912"
"64.600","5.384","25846.41","0.05161","0.01921"
"64.800","5.400","25857.75","0.05187","0.01930"
"65.000","5.417","25857.96","0.05213","0.01940"
"65.200","5.434","25866.78","0.05239","0.01949"
"65.400","5.450","25872.83","0.05265","0.01959"
"65.600","5.467","25877.52","0.05291","0.01967"
"65.800","5.484","25882.30","0.05317","0.01975"
"66.000","5.500","25887.16","0.05343","0.01979"
"66.200","5.517","25889.99","0.05369","0.01989"
"66.400","5.534","25896.25","0.05395","0.01999"
"66.600","5.550","25901.40","0.05421","0.02009"
"66.800","5.567","25910.25","0.05447","0.02017"
"67.000","5.584","25912.44","0.05474","0.02027"
"67.200","5.600","25918.36","0.05499","0.02036"
"67.400","5.617","25929.42","0.05527","0.02046"
"67.600","5.634","25932.76","0.05553","0.02048"
"67.800","5.650","25936.31","0.05579","0.02058"
"68.000","5.667","25946.00","0.05605","0.02068"
"68.200","5.683","25951.85","0.05632","0.02077"
"68.400","5.700","25960.50","0.05657","0.02087"
"68.600","5.717","25970.22","0.05684","0.02097"
"68.800","5.733","25975.79","0.05710","0.02107"
"69.000","5.750","25982.30","0.05737","0.02116"
"69.200","5.767","25986.76","0.05763","0.02126"
"69.400","5.784","25993.57","0.05789","0.02135"
"69.600","5.800","25994.65","0.05816","0.02145"
"69.800","5.817","25999.39","0.05843","0.02155"
"70.000","5.834","26002.53","0.05870","0.02164"
"70.200","5.850","26009.38","0.05896","0.02174"
"70.400","5.867","26007.04","0.05923","0.02183"
"70.600","5.884","26013.45","0.05949","0.02193"
"70.800","5.900","26014.46","0.05976","0.02202"
"71.000","5.917","26017.57","0.06002","0.02212"
"71.200","5.934","26024.69","0.06029","0.02222"
"71.400","5.950","26025.77","0.06056","0.02232"
"71.600","5.967","26038.56","0.06082","0.02241"
"71.800","5.984","26036.46","0.06109","0.02251"
"72.000","6.000","26040.14","0.06137","0.02260"
"72.200","6.017","26042.88","0.06163","0.02270"
"72.400","6.034","26054.19","0.06190","0.02279"
"72.600","6.050","26058.95","0.06216","0.02281"
"72.800","6.067","26073.34","0.06243","0.02292"
"73.000","6.084","26061.50","0.06270","0.02302"
"73.200","6.100","26086.37","0.06297","0.02312"
"73.400","6.117","26073.14","0.06324","0.02322"
"73.600","6.134","26093.95","0.06351","0.02332"
"73.800","6.150","26099.42","0.06378","0.02342"
"74.000","6.167","26099.30","0.06406","0.02352"
"74.200","6.184","26107.38","0.06433","0.02362"
"74.400","6.200","26115.11","0.06460","0.02372"
"74.600","6.217","26126.06","0.06487","0.02382"
"74.800","6.234","26129.82","0.06515","0.02392"
"75.000","6.250","26128.54","0.06542","0.02401"
"75.200","6.267","26137.22","0.06569","0.02411"
"75.400","6.284","26146.19","0.06597","0.02420"
"75.600","6.300","26145.25","0.06624","0.02430"
"75.800","6.317","26152.70","0.06652","0.02440"
"76.000","6.334","26163.92","0.06679","0.02450"
"76.200","6.350","26161.46","0.06706","0.02460"
"76.400","6.367","26166.02","0.06734","0.02469"
"76.600","6.384","26176.39","0.06762","0.02479"
"76.800","6.400","26175.80","0.06789","0.02489"
"77.000","6.417","26184.39","0.06817","0.02499"
"77.200","6.434","26186.73","0.06845","0.02508"
"77.400","6.450","26183.87","0.06872","0.02518"
"77.600","6.467","26188.61","0.06900","0.02528"
"77.800","6.484","26190.40","0.06928","0.02538"
"78.000","6.500","26193.54","0.06956","0.02548"
"78.200","6.517","26191.88","0.06984","0.02557"
"78.400","6.534","26195.04","0.07011","0.02567"
"78.600","6.550","26194.78","0.07040","0.02577"
"78.800","6.567","26199.71","0.07068","0.02587"
"79.000","6.583","26202.54","0.07096","0.02596"
"79.200","6.600","26205.91","0.07124","0.02606"
"79.400","6.617","26202.72","0.07152","0.02617"
"79.600","6.634","26205.68","0.07180","0.02626"
"79.800","6.650","26208.96","0.07208","0.02636"
"80.000","6.667","26209.08","0.07237","0.02646"
"80.200","6.684","26214.06","0.07265","0.02656"
"80.400","6.700","26213.23","0.07294","0.02666"
"80.600","6.717","26212.65","0.07322","0.02676"
"80.800","6.734","26214.79","0.07351","0.02686"
"81.000","6.750","26215.12","0.07379","0.02695"
"81.200","6.767","26218.43","0.07408","0.02705"
"81.400","6.784","26218.26","0.07436","0.02716"
"81.600","6.800","26216.44","0.07465","0.02726"
"81.800","6.817","26217.83","0.07494","0.02736"
"82.000","6.834","26219.12","0.07523","0.02746"
"82.200","6.850","26222.28","0.07552","0.02755"
"82.400","6.867","26223.09","0.07581","0.02766"
"82.600","6.884","26221.72","0.07610","0.02776"
"82.800","6.900","26222.49","0.07639","0.02786"
"83.000","6.917","26224.59","0.07669","0.02796"
"83.200","6.933","26225.41","0.07698","0.02806"
"83.400","6.950","26225.98","0.07727","0.02816"
"83.600","6.967","26227.08","0.07756","0.02827"
"83.800","6.984","26226.43","0.07786","0.02837"
"84.000","7.000","26228.92","0.07815","0.02846"
"84.200","7.017","26230.04","0.07844","0.02856"
"84.400","7.034","26233.51","0.07874","0.02855"
"84.600","7.050","26233.51","0.07903","0.02867"
"84.800","7.067","26232.05","0.07933","0.02878"
"85.000","7.084","26235.20","0.07963","0.02889"
"85.200","7.100","26235.13","0.07993","0.02900"
"85.400","7.117","26236.94","0.08022","0.02911"
"85.600","7.134","26236.93","0.08053","0.02921"
"85.800","7.150","26236.20","0.08083","0.02931"
"86.000","7.167","26238.58","0.08113","0.02942"
"86.200","7.184","26238.92","0.08143","0.02952"
"86.400","7.200","26240.68","0.08174","0.02962"
"86.600","7.217","26243.82","0.08203","0.02972"
"86.800","7.234","26242.85","0.08234","0.02983"
"87.000","7.250","26240.50","0.08264","0.02994"
"87.200","7.267","26245.98","0.08295","0.03004"
"87.400","7.284","26242.45","0.08325","0.03015"
"87.600","7.300","26248.08","0.08356","0.03025"
"87.800","7.317","26246.27","0.08387","0.03035"
"88.000","7.334","26244.12","0.08418","0.03046"
"88.200","7.350","26241.86","0.08449","0.03056"
"88.400","7.367","26243.30","0.08480","0.03066"
"88.600","7.383","26242.01","0.08511","0.03077"
"88.800","7.400","26248.46","0.08541","0.03087"
"89.000","7.417","26249.56","0.08573","0.03098"
"89.200","7.434","26242.56","0.08604","0.03108"
"89.400","7.450","26248.55","0.08635","0.03119"
"89.600","7.467","26245.21","0.08666","0.03129"
"89.800","7.483","26248.27","0.08698","0.03139"
"90.000","7.500","26248.09","0.08729","0.03149"
"90.200","7.517","26246.23","0.08761","0.03160"
"90.400","7.534","26247.52","0.08792","0.03170"
"90.600","7.550","26247.67","0.08823","0.03180"
"90.800","7.567","26248.15","0.08855","0.03191"
"91.000","7.584","26248.08","0.08888","0.03201"
"91.200","7.600","26249.28","0.08919","0.03211"
"91.400","7.617","26244.98","0.08951","0.03221"
"91.600","7.634","26247.82","0.08983","0.03231"
"91.800","7.650","26245.02","0.09014","0.03241"
"92.000","7.667","26250.04","0.09046","0.03251"
"92.200","7.684","26245.75","0.09078","0.03261"
"92.400","7.700","26246.67","0.09110","0.03271"
"92.600","7.717","26245.21","0.09142","0.03280"
"92.800","7.734","26243.37","0.09174","0.03290"
"93.000","7.750","26245.26","0.09206","0.03300"
"93.200","7.767","26248.42","0.09238","0.03310"
"93.400","7.784","26239.75","0.09270","0.03319"
"93.600","7.800","26242.57","0.09302","0.03328"
"93.800","7.817","26244.80","0.09333","0.03338"
"94.000","7.834","26239.95","0.09365","0.03347"
"94.200","7.850","26238.84","0.09397","0.03356"
"94.400","7.867","26244.15","0.09429","0.03365"
"94.600","7.883","26241.30","0.09460","0.03374"
"94.800","7.900","26242.22","0.09492","0.03383"
"95.000","7.917","26240.84","0.09524","0.03392"
"95.200","7.933","26238.60","0.09555","0.03400"
"95.400","7.950","26233.94","0.09587","0.03408"
"95.600","7.967","26234.53","0.09619","0.03416"
"95.800","7.984","26232.82","0.09649","0.03424"
"96.000","8.000","26232.03","0.09681","0.03432"
"96.200","8.017","26231.68","0.09712","0.03439"
"96.400","8.034","26233.14","0.09743","0.03447"
"96.600","8.050","26228.27","0.09774","0.03454"
"96.800","8.067","26228.50","0.09804","0.03462"
"97.000","8.084","26227.46","0.09834","0.03468"
"97.200","8.100","26225.74","0.09864","0.03475"
"97.400","8.117","26225.02","0.09895","0.03481"
"97.600","8.134","26224.20","0.09924","0.03488"
"97.800","8.150","26216.71","0.09954","0.03493"
"98.000","8.167","26217.08","0.09984","0.03499"
"98.200","8.184","26215.23","0.10013","0.03504"
"98.400","8.200","26212.49","0.10042","0.03509"
"98.600","8.217","26208.40","0.10071","0.03514"
"98.800","8.234","26207.88","0.10099","0.03519"
"99.000","8.250","26206.87","0.10127","0.03523"
"99.200","8.267","26204.07","0.10154","0.03528"
"99.400","8.284","26200.78","0.10182","0.03531"
"99.600","8.300","26192.78","0.10209","0.03535"
"99.800","8.317","26189.48","0.10236","0.03539"
"100.000","8.334","26180.77","0.10262","0.03542"
"100.200","8.350","26180.84","0.10289","0.03546"
"100.400","8.367","26172.82","0.10315","0.03549"
"100.600","8.384","26165.40","0.10341","0.03552"
"100.800","8.400","26148.71","0.10367","0.03554"
"101.000","8.417","26138.06","0.10391","0.03557"
"101.200","8.434","26122.50","0.10417","0.03560"
"101.400","8.450","26109.71","0.10441","0.03562"
"101.600","8.467","26093.75","0.10465","0.03564"
"101.800","8.484","26076.97","0.10489","0.03562"
"102.000","8.500","26060.42","0.10514","0.03565"
"102.200","8.517","26050.13","0.10538","0.03567"
"102.400","8.534","26036.86","0.10561","0.03568"
"102.600","8.550","26031.92","0.10584","0.03571"
"102.800","8.567","26022.35","0.10607","0.03572"
"103.000","8.584","26012.80","0.10630","0.03574"
"103.200","8.600","26005.94","0.10653","0.03575"
"103.400","8.617","25988.64","0.10676","0.03577"
"103.600","8.634","25982.80","0.10699","0.03578"
"103.800","8.650","25957.12","0.10721","0.03579"
"104.000","8.667","25941.18","0.10743","0.03580"
"104.200","8.684","25920.08","0.10764","0.03581"
"104.400","8.700","25908.78","0.10786","0.03583"
"104.600","8.717","25888.57","0.10809","0.03583"
"104.800","8.733","25883.71","0.10831","0.03584"
"105.000","8.750","25871.29","0.10852","0.03585"
"105.200","8.767","25859.22","0.10872","0.03586"
"105.400","8.784","25839.98","0.10894","0.03587"
"105.600","8.800","25827.08","0.10915","0.03587"
"105.800","8.817","25801.35","0.10936","0.03588"
"106.000","8.834","25794.09","0.10957","0.03588"
"106.200","8.850","25774.29","0.10978","0.03589"
"106.400","8.867","25765.14","0.10998","0.03589"
"106.600","8.884","25761.64","0.11019","0.03590"
"106.800","8.900","25755.66","0.11039","0.03586"
"107.000","8.917","25743.88","0.11059","0.03585"
"107.200","8.934","25733.59","0.11080","0.03585"
"107.400","8.950","25727.29","0.11100","0.03586"
"107.600","8.967","25725.29","0.11120","0.03588"
"107.800","8.984","25714.76","0.11140","0.03588"
"108.000","9.000","25702.37","0.11160","0.03588"
"108.200","9.017","25682.74","0.11180","0.03589"
"108.400","9.034","25653.19","0.11200","0.03589"
"108.600","9.050","25614.18","0.11220","0.03590"
"108.800","9.067","25580.19","0.11240","0.03590"
"109.000","9.084","25552.48","0.11259","0.03590"
"109.200","9.100","25533.43","0.11279","0.03591"
"109.400","9.117","25511.45","0.11298","0.03591"
"109.600","9.134","25488.95","0.11317","0.03591"
"109.800","9.150","25456.03","0.11337","0.03591"
"110.000","9.167","25412.47","0.11356","0.03591"
"110.200","9.183","25382.69","0.11375","0.03591"
"110.400","9.200","25347.59","0.11394","0.03591"
"110.600","9.217","25318.28","0.11413","0.03591"
"110.800","9.234","25293.33","0.11433","0.03592"
"111.000","9.250","25257.99","0.11452","0.03592"
"111.200","9.267","25229.26","0.11470","0.03592"
"111.400","9.284","25214.69","0.11489","0.03592"
"111.600","9.300","25199.02","0.11508","0.03592"
"111.800","9.317","25182.68","0.11527","0.03592"
"112.000","9.334","25171.75","0.11545","0.03592"
"112.200","9.350","25164.12","0.11564","0.03592"
"112.400","9.367","25161.99","0.11582","0.03592"
"112.600","9.384","25159.31","0.11600","0.03591"
"112.800","9.400","25146.96","0.11620","0.03592"
"113.000","9.417","25117.51","0.11638","0.03591"
"113.200","9.434","25080.24","0.11656","0.03591"
"113.400","9.450","25047.88","0.11674","0.03591"
"113.600","9.467","25023.00","0.11693","0.03591"
"113.800","9.484","24994.12","0.11711","0.03591"
"114.000","9.500","24955.54","0.11729","0.03591"
"114.200","9.517","24928.36","0.11747","0.03587"
"114.400","9.534","24887.20","0.11765","0.03587"
"114.600","9.550","24839.49","0.11783","0.03587"
"114.800","9.567","24768.59","0.11800","0.03588"
"115.000","9.583","24736.55","0.11818","0.03587"
"115.200","9.600","24719.82","0.11836","0.03587"
"115.400","9.617","24699.41","0.11853","0.03587"
"115.600","9.633","24680.63","0.11871","0.03587"
"115.800","9.650","24660.86","0.11888","0.03587"
"116.000","9.667","24633.73","0.11906","0.03587"
"116.200","9.684","24613.04","0.11924","0.03587"
"116.400","9.700","24562.31","0.11941","0.03587"
"116.600","9.717","24508.60","0.11958","0.03587"
"116.800","9.734","24469.86","0.11975","0.03587"
"117.000","9.750","24450.35","0.11992","0.03587"
"117.200","9.767","24428.55","0.12009","0.03587"
"117.400","9.784","24397.56","0.12027","0.03588"
"117.600","9.800","24380.00","0.12043","0.03588"
"117.800","9.817","24361.15","0.12061","0.03588"
"118.000","9.834","24329.29","0.12077","0.03588"
"118.200","9.850","24279.74","0.12093","0.03588"
"118.400","9.867","24252.54","0.12110","0.03588"
"118.600","9.884","24218.51","0.12127","0.03588"
"118.800","9.900","24187.65","0.12143","0.03588"
"119.000","9.917","24165.23","0.12160","0.03587"
"119.200","9.934","24139.29","0.12176","0.03587"
"119.400","9.950","24104.45","0.12192","0.03587"
"119.600","9.967","24039.21","0.12208","0.03587"
"119.800","9.983","23976.92","0.12224","0.03587"
"120.000","10.000","23930.18","0.12240","0.03588"
"120.200","10.017","23868.32","0.12256","0.03587"
"120.400","10.034","23820.94","0.12271","0.03587"
"120.600","10.050","23772.85","0.12287","0.03587"
"120.800","10.067","23722.55","0.12303","0.03587"
"121.000","10.084","23674.10","0.12319","0.03586"
"121.200","10.100","23667.80","0.12334","0.03586"
"121.400","10.117","23667.81","0.12350","0.03586"
"121.600","10.134","23667.19","0.12365","0.03587"
"121.800","10.150","23663.86","0.12380","0.03587"
"122.000","10.167","23630.66","0.12396","0.03587"
"122.200","10.184","23566.32","0.12411","0.03587"
"122.400","10.200","23499.01","0.12426","0.03587"
"122.600","10.217","23435.56","0.12440","0.03586"
"122.800","10.234","23374.44","0.12455","0.03586"
"123.000","10.250","23324.42","0.12470","0.03585"
"123.200","10.267","23268.00","0.12484","0.03585"
"123.400","10.284","23189.28","0.12499","0.03585"
"123.600","10.300","23153.97","0.12513","0.03585"
"123.800","10.317","23112.21","0.12528","0.03584"
"124.000","10.334","23063.56","0.12542","0.03584"
"124.200","10.350","23042.33","0.12557","0.03584"
"124.400","10.367","23015.30","0.12572","0.03586"
"124.600","10.384","22962.85","0.12586","0.03586"
"124.800","10.400","22941.40","0.12601","0.03585"
"125.000","10.417","22902.68","0.12631","0.03597"
"125.200","10.434","22864.19","0.12647","0.03596"
"125.400","10.450","22784.79","0.12663","0.03598"
"125.600","10.467","22688.85","0.12677","0.03600"
"125.800","10.484","22661.63","0.12691","0.03602"
"126.000","10.500","22630.29","0.12705","0.03603"
"126.200","10.517","22584.34","0.12718","0.03605"
"126.400","10.534","22524.01","0.12731","0.03606"
"126.600","10.550","22449.25","0.12745","0.03607"
"126.800","10.567","22366.71","0.12758","0.03608"
"127.000","10.584","22279.45","0.12770","0.03609"
"127.200","10.600","22244.60","0.12783","0.03610"
"127.400","10.617","22189.37","0.12795","0.03610"
"127.600","10.634","22167.40","0.12807","0.03611"
"127.800","10.650","22160.49","0.12819","0.03611"
"128.000","10.667","22118.63","0.12830","0.03612"
"128.200","10.683","22004.20","0.12841","0.03612"
"128.400","10.700","21412.12","0.12846","0.03609"
"128.444","10.704","9969.49","0.14155","0.03321"