File: Labs/Lab 2 Tension/Specimen_RawData_1.csv
Time (s),Extension (mm),Load (N),Axial Strain (mm/mm),Transverse Strain (mm/mm)
0,0,-0.11,0,0
0.1,0.004,4.25,0,0
0.2,0.014,309.46,0.00004,0.00001
0.3,0.024,527.72,0.0001,0.00004
0.4,0.033,877.78,0.00015,0.00006
0.5,0.042,1043.99,0.00019,0.00007
0.6,0.05,1256.65,0.00023,0.00009
0.7,0.059,1501.57,0.00026,0.0001
0.8,0.067,1708.58,0.0003,0.00012
0.9,0.075,1891.44,0.00034,0.00013
1,0.084,2012.71,0.00036,0.00015
1.1,0.092,2193.56,0.00039,0.00016
1.2,0.1,2273.61,0.0004,0.00017
1.3,0.109,2351.82,0.00041,0.00018
1.4,0.117,2398.72,0.00041,0.00018
1.5,0.125,2458.76,0.00042,0.00019
1.6,0.134,2497.52,0.00043,0.00019
1.7,0.142,2515.77,0.00043,0.0002
1.8,0.15,2527.62,0.00044,0.0002
1.9,0.159,2539.21,0.00045,0.0002
2,0.167,2592.63,0.00045,0.00021
2.1,0.175,2670.14,0.00046,0.00021
2.2,0.184,2703.52,0.00047,0.00022
2.3,0.192,2766.65,0.00048,0.00022
2.4,0.2,2839.14,0.00049,0.00023
2.5,0.209,2908.05,0.00049,0.00023
2.6,0.217,2992.92,0.0005,0.00024
2.7,0.225,3049.96,0.00051,0.00024
2.8,0.234,3081.8,0.00052,0.00025
2.9,0.242,3096.31,0.00052,0.00025
3,0.25,3116.1,0.00053,0.00025
3.1,0.258,3187.42,0.00054,0.00025
3.2,0.267,3248.47,0.00055,0.00025
3.3,0.275,3311.14,0.00056,0.00025
3.4,0.284,3374.45,0.00056,0.00026
3.5,0.292,3434.54,0.00057,0.00026
3.6,0.3,3494.82,0.00058,0.00026
3.7,0.309,3527.05,0.00059,0.00026
3.8,0.317,3560.63,0.00059,0.00027
3.9,0.325,3606.67,0.00061,0.00027
4,0.334,3707.2,0.00061,0.00027
4.1,0.342,3773.91,0.00062,0.00027
4.2,0.35,3834.46,0.00063,0.00028
4.3,0.359,3895.45,0.00064,0.00028
4.4,0.367,3943.26,0.00065,0.00028
4.5,0.375,4025.78,0.00066,0.00029
4.6,0.384,4069.63,0.00067,0.00029
4.7,0.392,4101.21,0.00068,0.00029
4.8,0.4,4122.29,0.00069,0.00029
4.9,0.409,4211.23,0.0007,0.0003
5,0.417,4269.55,0.00071,0.0003
5.1,0.425,4364.6,0.00072,0.0003
5.2,0.433,4452.88,0.00072,0.00031
5.3,0.442,4539.49,0.00073,0.00031
5.4,0.45,4575.95,0.00074,0.00031
5.5,0.459,4597.78,0.00076,0.00032
5.6,0.467,4617.55,0.00077,0.00032
5.7,0.475,4716.31,0.00077,0.00032
5.8,0.484,4805.27,0.00079,0.00033
5.9,0.492,4871.92,0.00079,0.00033
6,0.5,4933.69,0.00081,0.00033
6.1,0.509,5013.35,0.00082,0.00033
6.2,0.517,5067.03,0.00083,0.00033
6.3,0.525,5127.93,0.00084,0.00034
6.4,0.534,5164.68,0.00085,0.00034
6.5,0.542,5235.62,0.00086,0.00034
6.6,0.55,5306.6,0.00087,0.00035
6.7,0.559,5372.09,0.00089,0.00035
6.8,0.567,5460.96,0.0009,0.00036
6.9,0.575,5587.57,0.0009,0.00036
7,0.584,5617.58,0.00092,0.00037
7.1,0.592,5651.02,0.00093,0.00037
7.2,0.6,5691.26,0.00094,0.00037
7.3,0.609,5794.4,0.00095,0.00038
7.4,0.617,5892.67,0.00096,0.00038
7.5,0.625,5962.92,0.00098,0.00038
7.6,0.634,6042.39,0.00099,0.00038
7.7,0.642,6094.57,0.001,0.00039
7.8,0.65,6137.87,0.00101,0.00039
7.9,0.659,6209.24,0.00103,0.00039
8,0.667,6315.77,0.00104,0.0004
8.1,0.675,6394.07,0.00105,0.0004
8.2,0.684,6460.38,0.00106,0.0004
8.3,0.692,6566.36,0.00107,0.00041
8.4,0.7,6628.57,0.00109,0.00041
8.5,0.709,6659.21,0.0011,0.00041
8.6,0.717,6689.07,0.00111,0.00042
8.7,0.725,6799.37,0.00112,0.00042
8.8,0.734,6897.98,0.00114,0.00042
8.9,0.742,6996.82,0.00115,0.00043
9,0.75,7120.25,0.00116,0.00043
9.1,0.758,7169.71,0.00118,0.00044
9.2,0.767,7203.62,0.00119,0.00044
9.3,0.775,7244.38,0.0012,0.00045
9.4,0.784,7343.72,0.00122,0.00045
9.5,0.792,7426.23,0.00123,0.00046
9.6,0.8,7498.65,0.00124,0.00046
9.7,0.809,7637.3,0.00125,0.00046
9.8,0.817,7683.73,0.00127,0.00047
9.9,0.825,7752.89,0.00128,0.00047
10,0.834,7850.1,0.0013,0.00047
10.1,0.842,7917.07,0.00131,0.00048
10.2,0.85,8012.81,0.00132,0.00048
10.3,0.859,8083.99,0.00134,0.00048
10.4,0.867,8147.51,0.00135,0.00049
10.5,0.875,8176.71,0.00136,0.00049
10.6,0.884,8260.31,0.00138,0.0005
10.7,0.892,8384.67,0.00139,0.0005
10.8,0.9,8506.76,0.00141,0.0005
10.9,0.909,8604.94,0.00142,0.00051
11,0.917,8703.91,0.00143,0.00051
11.1,0.925,8725.22,0.00145,0.00052
11.2,0.933,8734.21,0.00146,0.00052
11.3,0.942,8837.62,0.00147,0.00053
11.4,0.95,8934.3,0.00149,0.00053
11.5,0.959,9060.42,0.0015,0.00054
11.6,0.967,9171.14,0.00152,0.00054
11.7,0.975,9250.05,0.00153,0.00055
11.8,0.984,9301.71,0.00155,0.00055
11.9,0.992,9409.63,0.00156,0.00055
12,1,9468.52,0.00158,0.00056
12.1,1.009,9529.07,0.00159,0.00056
12.2,1.017,9649.12,0.0016,0.00057
12.3,1.025,9720.33,0.00162,0.00057
12.4,1.034,9775.27,0.00163,0.00058
12.5,1.042,9903.21,0.00165,0.00058
12.6,1.05,10012.89,0.00166,0.00058
12.7,1.059,10132.93,0.00168,0.00059
12.8,1.067,10213.89,0.00169,0.00059
12.9,1.075,10229.81,0.00171,0.0006
13,1.084,10240.47,0.00172,0.00061
13.1,1.092,10390.38,0.00174,0.00061
13.2,1.1,10486.92,0.00175,0.00062
13.3,1.108,10609.43,0.00177,0.00062
13.4,1.117,10739.23,0.00178,0.00063
13.5,1.125,10824.03,0.0018,0.00063
13.6,1.134,10848.8,0.00181,0.00063
13.7,1.142,10927.46,0.00183,0.00064
13.8,1.15,10983.25,0.00184,0.00064
13.9,1.158,11095.58,0.00186,0.00064
14,1.167,11236.93,0.00187,0.00065
14.1,1.175,11304.42,0.00189,0.00066
14.2,1.184,11370.9,0.0019,0.00066
14.3,1.192,11512.16,0.00192,0.00067
14.4,1.2,11609.75,0.00193,0.00067
14.5,1.209,11669.82,0.00194,0.00068
14.6,1.217,11728.68,0.00196,0.00069
14.7,1.225,11779.57,0.00198,0.00069
14.8,1.234,11884.03,0.00199,0.00069
14.9,1.242,12008.51,0.00201,0.0007
15,1.25,12131.22,0.00202,0.00071
15.1,1.259,12266.52,0.00204,0.00072
15.2,1.267,12346.63,0.00206,0.00072
15.3,1.275,12351.22,0.00207,0.00073
15.4,1.284,12414.46,0.00209,0.00073
15.5,1.292,12526.28,0.00211,0.00074
15.6,1.3,12641.67,0.00212,0.00074
15.7,1.308,12790.26,0.00214,0.00075
15.8,1.317,12856.89,0.00215,0.00076
15.9,1.325,12929.29,0.00217,0.00076
16,1.333,13041.09,0.00219,0.00077
16.1,1.342,13119.63,0.00221,0.00077
16.2,1.35,13198.83,0.00222,0.00077
16.3,1.359,13296,0.00224,0.00078
16.4,1.367,13348.55,0.00226,0.00078
16.5,1.375,13453.36,0.00227,0.00079
16.6,1.383,13596.67,0.00229,0.00079
16.7,1.392,13704.99,0.00231,0.0008
16.8,1.4,13836.97,0.00232,0.00081
16.9,1.409,13853.89,0.00234,0.00081
17,1.417,13899.61,0.00236,0.00082
17.1,1.425,14012.01,0.00237,0.00082
17.2,1.434,14150.4,0.00239,0.00083
17.3,1.442,14254.72,0.00241,0.00084
17.4,1.45,14389.3,0.00242,0.00084
17.5,1.459,14415.87,0.00244,0.00084
17.6,1.467,14486.87,0.00246,0.00085
17.7,1.475,14592.3,0.00248,0.00086
17.8,1.484,14705.85,0.0025,0.00088
17.9,1.492,14816.04,0.00252,0.00088
18,1.5,14885.89,0.00254,0.00088
18.1,1.508,14974.03,0.00255,0.00089
18.2,1.517,15105.25,0.00257,0.0009
18.3,1.525,15205.49,0.00259,0.00091
18.4,1.534,15313.31,0.00261,0.00091
18.5,1.542,15395.93,0.00262,0.00091
18.6,1.55,15427.97,0.00265,0.00092
18.7,1.559,15530.06,0.00266,0.00092
18.8,1.567,15667.99,0.00268,0.00093
18.9,1.575,15797.51,0.0027,0.00093
19,1.584,15907.62,0.00272,0.00094
19.1,1.592,15932.6,0.00274,0.00095
19.2,1.6,16035.24,0.00275,0.00096
19.3,1.608,16136.66,0.00277,0.00097
19.4,1.617,16247.75,0.00279,0.00097
19.5,1.625,16352.38,0.00281,0.00098
19.6,1.634,16459.13,0.00283,0.00098
19.7,1.642,16496.16,0.00285,0.00099
19.8,1.65,16608.93,0.00287,0.001
19.9,1.659,16708.86,0.00289,0.001
20,1.667,16869.41,0.00291,0.001
20.1,1.675,16935.86,0.00293,0.00101
20.2,1.684,16975.35,0.00295,0.00102
20.3,1.692,17102.62,0.00297,0.00103
20.4,1.7,17215.64,0.00299,0.00103
20.5,1.709,17300.95,0.00301,0.00104
20.6,1.717,17409.71,0.00303,0.00105
20.7,1.725,17480.09,0.00305,0.00106
20.8,1.733,17554.99,0.00307,0.00106
20.9,1.742,17685.19,0.00309,0.00107
21,1.75,17778.59,0.00312,0.00108
21.1,1.759,17924.86,0.00314,0.00108
21.2,1.767,17982.84,0.00316,0.00109
21.3,1.775,18012.95,0.00318,0.0011
21.4,1.783,18130.72,0.0032,0.0011
21.5,1.792,18275.77,0.00322,0.00113
21.6,1.8,18377.98,0.00325,0.00115
21.7,1.809,18475.63,0.00328,0.00115
21.8,1.817,18525.42,0.0033,0.00116
21.9,1.825,18595.35,0.00332,0.00117
22,1.834,18704.69,0.00334,0.00118
22.1,1.842,18800.53,0.00336,0.00119
22.2,1.85,18955.39,0.00339,0.0012
22.3,1.858,19017.51,0.00342,0.0012
22.4,1.867,19090.33,0.00344,0.00121
22.5,1.875,19192.7,0.00347,0.00122
22.6,1.884,19299.1,0.00349,0.00122
22.7,1.892,19371.87,0.00352,0.00123
22.8,1.9,19483.15,0.00354,0.00124
22.9,1.909,19526.49,0.00357,0.00125
23,1.917,19623.77,0.0036,0.00126
23.1,1.925,19759.16,0.00362,0.00127
23.2,1.934,19889.05,0.00365,0.00128
23.3,1.942,19986.82,0.00368,0.00129
23.4,1.95,20042.52,0.00371,0.00129
23.5,1.959,20060.76,0.00373,0.00131
23.6,1.967,20154.67,0.00376,0.00131
23.7,1.975,20251,0.00379,0.00132
23.8,1.984,20397,0.00382,0.00134
23.9,1.992,20501.45,0.00385,0.00134
24,2,20582.1,0.00388,0.00135
24.1,2.009,20640.31,0.00392,0.00137
24.2,2.017,20735.91,0.00394,0.00138
24.3,2.025,20792.75,0.00398,0.00139
24.4,2.034,20873.38,0.00401,0.0014
24.5,2.042,20994.85,0.00404,0.00141
24.6,2.05,21064.24,0.00408,0.00142
24.7,2.059,21119.59,0.00412,0.00144
24.8,2.067,21240.43,0.00416,0.00147
24.9,2.075,21339.23,0.00419,0.00148
25,2.084,21436.52,0.00423,0.0015
25.1,2.092,21509.29,0.00427,0.00151
25.2,2.1,21544.01,0.00431,0.00152
25.3,2.109,21561.75,0.00435,0.00154
25.4,2.117,21635.08,0.0044,0.00155
25.5,2.125,21764.62,0.00444,0.00157
25.6,2.133,21850.15,0.00449,0.00158
25.7,2.142,21942.81,0.00454,0.0016
25.8,2.15,22065.04,0.00459,0.00162
25.9,2.159,22146.56,0.00463,0.00164
26,2.167,22166.49,0.00469,0.00166
26.1,2.175,22175.52,0.00474,0.00168
26.2,2.184,22236.67,0.00479,0.00169
26.3,2.192,22269.47,0.00484,0.00171
26.4,2.2,22368.83,0.0049,0.00173
26.5,2.209,22449.78,0.00496,0.00176
26.6,2.217,22540.58,0.00501,0.00178
26.7,2.225,22596.99,0.00507,0.0018
26.8,2.233,22642.32,0.00514,0.00182
26.9,2.242,22672.3,0.0052,0.00185
27,2.25,22734.67,0.00527,0.00187
27.1,2.259,22838.23,0.00533,0.00189
27.2,2.267,22886.74,0.0054,0.00192
27.3,2.275,22929.59,0.00547,0.00195
27.4,2.284,22954.9,0.00554,0.00197
27.5,2.292,23001.43,0.00562,0.002
27.6,2.3,23037.12,0.00569,0.00203
27.7,2.309,23053.28,0.00577,0.00205
27.8,2.317,23084.53,0.00585,0.00208
27.9,2.325,23126.44,0.00593,0.00211
28,2.334,23163.9,0.00601,0.00214
28.1,2.342,23210,0.00609,0.00218
28.2,2.35,23269.21,0.00617,0.00221
28.3,2.359,23323.18,0.00626,0.00224
28.4,2.367,23367.5,0.00635,0.00227
28.5,2.375,23423.07,0.00643,0.00231
28.6,2.384,23476.57,0.00653,0.00234
28.7,2.392,23514.87,0.00662,0.00238
28.8,2.4,23564.05,0.0067,0.00241
28.9,2.409,23615.19,0.0068,0.00245
29,2.417,23652.55,0.00689,0.00248
29.1,2.425,23664.15,0.00698,0.00252
29.2,2.434,23667.67,0.00708,0.00256
29.3,2.442,23667.89,0.00717,0.00259
29.4,2.45,23667.89,0.00727,0.00263
29.5,2.458,23668.35,0.00737,0.00267
29.6,2.467,23670.38,0.00747,0.00271
29.7,2.475,23687.24,0.00757,0.00275
29.8,2.484,23713.87,0.00767,0.00279
29.9,2.492,23742.86,0.00777,0.00282
30,2.5,23784.57,0.00787,0.00286
30.1,2.509,23818.93,0.00797,0.00291
30.2,2.517,23845.59,0.00808,0.00295
30.3,2.525,23874.35,0.00818,0.00299
30.4,2.534,23909.26,0.00829,0.00303
30.5,2.542,23939.62,0.00839,0.00307
30.6,2.55,23961.33,0.0085,0.00311
30.7,2.559,23992.04,0.00861,0.00316
30.8,2.567,24018.77,0.00872,0.0032
30.9,2.575,24060.79,0.00883,0.00324
31,2.584,24100.59,0.00894,0.00329
31.1,2.592,24116.49,0.00905,0.00333
31.2,2.6,24134.75,0.00916,0.00338
31.3,2.609,24147.25,0.00927,0.00342
31.4,2.617,24158.03,0.00938,0.00346
31.5,2.625,24165.96,0.00949,0.00351
31.6,2.633,24175.77,0.0096,0.00355
31.7,2.642,24192.26,0.00972,0.0036
31.8,2.65,24200.09,0.00983,0.00364
31.9,2.659,24212.88,0.00994,0.00369
32,2.667,24230.49,0.01006,0.00373
32.1,2.675,24240.75,0.01017,0.00378
32.2,2.683,24247.51,0.01029,0.00382
32.3,2.692,24262.08,0.01041,0.00387
32.4,2.7,24277.38,0.01053,0.00392
32.5,2.709,24293.61,0.01065,0.00396
32.6,2.717,24312.86,0.01076,0.00401
32.7,2.725,24331.01,0.01088,0.00406
32.8,2.734,24341.37,0.01099,0.0041
32.9,2.742,24353.07,0.01111,0.00415
33,2.75,24362.3,0.01123,0.0042
33.1,2.759,24365.43,0.01135,0.00425
33.2,2.767,24370.5,0.01147,0.0043
33.3,2.775,24376.59,0.0116,0.00435
33.4,2.784,24381.34,0.01172,0.0044
33.5,2.792,24385.27,0.01184,0.00445
33.6,2.8,24393.46,0.01196,0.0045
33.7,2.809,24400.93,0.01209,0.00454
33.8,2.817,24414.56,0.01221,0.00459
33.9,2.825,24421.98,0.01233,0.00464
34,2.834,24428.72,0.01245,0.00469
34.1,2.842,24437.62,0.01258,0.00474
34.2,2.85,24445.48,0.0127,0.00479
34.3,2.859,24451.08,0.01283,0.00483
34.4,2.867,24456.15,0.01295,0.00488
34.5,2.875,24462.17,0.01307,0.00493
34.6,2.884,24466.21,0.01319,0.00498
34.7,2.892,24475.44,0.01332,0.00502
34.8,2.9,24476.76,0.01344,0.00507
34.9,2.909,24492.59,0.01356,0.00512
35,2.917,24508.79,0.01369,0.00517
35.1,2.925,24515.93,0.01382,0.00522
35.2,2.934,24531.37,0.01394,0.00527
35.3,2.942,24538.97,0.01407,0.00532
35.4,2.95,24552.81,0.01419,0.00537
35.5,2.959,24571.02,0.01432,0.00542
35.6,2.967,24583.93,0.01445,0.00547
35.7,2.975,24592.47,0.01457,0.00552
35.8,2.984,24607.97,0.0147,0.00557
35.9,2.992,24609.94,0.01483,0.00562
36,3,24617.18,0.01496,0.00566
36.1,3.009,24623.64,0.01509,0.00571
36.2,3.017,24628.36,0.01521,0.00576
36.3,3.025,24636.97,0.01534,0.00581
36.4,3.033,24639.11,0.01547,0.00586
36.5,3.042,24643.1,0.01559,0.00591
36.6,3.05,24651.4,0.01572,0.00596
36.7,3.059,24652.44,0.01585,0.00601
36.8,3.067,24662.3,0.01598,0.00605
36.9,3.075,24664.76,0.01611,0.0061
37,3.084,24667.21,0.01623,0.00615
37.1,3.092,24676.42,0.01636,0.0062
37.2,3.1,24679.78,0.01649,0.00625
37.3,3.109,24685.3,0.01662,0.0063
37.4,3.117,24687.94,0.01675,0.00635
37.5,3.125,24690.55,0.01688,0.0064
37.6,3.134,24698.29,0.017,0.00645
37.7,3.142,24702.72,0.01713,0.0065
37.8,3.15,24708.1,0.01726,0.00655
37.9,3.159,24711.03,0.01739,0.0066
38,3.167,24712.56,0.01752,0.00664
38.1,3.175,24716.45,0.01765,0.0067
38.2,3.184,24719.63,0.01778,0.00675
38.3,3.192,24723.7,0.01791,0.0068
38.4,3.2,24727.19,0.01804,0.00685
38.5,3.209,24730.58,0.01817,0.0069
38.6,3.217,24739.18,0.0183,0.00695
38.7,3.225,24738.97,0.01843,0.007
38.8,3.234,24744.99,0.01856,0.00705
38.9,3.242,24759.76,0.01869,0.0071
39,3.25,24767.57,0.01883,0.00715
39.1,3.259,24771.22,0.01896,0.0072
39.2,3.267,24780.18,0.01908,0.00725
39.3,3.275,24798.22,0.01921,0.00729
39.4,3.284,24807.81,0.01934,0.00734
39.5,3.292,24820.45,0.01947,0.00739
39.6,3.3,24834.25,0.0196,0.00744
39.7,3.309,24840.15,0.01973,0.00749
39.8,3.317,24858.72,0.01987,0.00754
39.9,3.325,24868.64,0.01999,0.00759
40,3.334,24881.97,0.02012,0.00763
40.1,3.342,24883.85,0.02024,0.00769
40.2,3.35,24890.91,0.02038,0.00774
40.3,3.359,24905.3,0.02051,0.00778
40.4,3.367,24913.38,0.02064,0.00784
40.5,3.375,24915.26,0.02077,0.00789
40.6,3.384,24926.32,0.0209,0.00794
40.7,3.392,24931.34,0.02103,0.00799
40.8,3.4,24934.15,0.02116,0.00804
40.9,3.409,24942.18,0.02129,0.00809
41,3.417,24952.17,0.02142,0.00813
41.1,3.425,24954.85,0.02155,0.00818
41.2,3.434,24960.44,0.02168,0.00823
41.3,3.442,24970.13,0.02181,0.00828
41.4,3.45,24974.19,0.02194,0.00833
41.5,3.459,24979.19,0.02207,0.00838
41.6,3.467,24990.9,0.0222,0.00843
41.7,3.475,24993.73,0.02233,0.00848
41.8,3.484,24997.98,0.02245,0.00853
41.9,3.492,25001.38,0.02259,0.00858
42,3.5,25008.39,0.02271,0.00862
42.1,3.509,25014.88,0.02285,0.00867
42.2,3.517,25013.82,0.02297,0.00872
42.3,3.525,25020.27,0.0231,0.00877
42.4,3.533,25026.05,0.02323,0.00881
42.5,3.542,25035.32,0.02336,0.00887
42.6,3.55,25031.19,0.02349,0.00891
42.7,3.559,25039.59,0.02361,0.00897
42.8,3.567,25038.78,0.02374,0.00902
42.9,3.575,25052.24,0.02388,0.00907
43,3.584,25055.92,0.024,0.00912
43.1,3.592,25054.99,0.02414,0.00916
43.2,3.6,25072.6,0.02426,0.00921
43.3,3.609,25076.35,0.02439,0.00926
43.4,3.617,25087.55,0.02452,0.00931
43.5,3.625,25092.3,0.02465,0.00936
43.6,3.634,25110.28,0.02478,0.00941
43.7,3.642,25118.41,0.02491,0.00945
43.8,3.65,25124,0.02503,0.0095
43.9,3.659,25127.15,0.02516,0.00955
44,3.667,25134.07,0.02529,0.0096
44.1,3.675,25134.5,0.02542,0.00965
44.2,3.684,25143.8,0.02555,0.0097
44.3,3.692,25145.6,0.02568,0.00974
44.4,3.7,25150.7,0.02581,0.00979
44.5,3.709,25153.52,0.02594,0.00984
44.6,3.717,25155.48,0.02606,0.00989
44.7,3.725,25156.92,0.02619,0.00994
44.8,3.734,25156.86,0.02632,0.00998
44.9,3.742,25159.68,0.02645,0.01003
45,3.75,25158.08,0.02657,0.01008
45.1,3.758,25159.26,0.0267,0.01013
45.2,3.767,25159.96,0.02684,0.01017
45.3,3.775,25159.92,0.02697,0.01022
45.4,3.784,25160.49,0.02709,0.01027
45.5,3.792,25161.32,0.02722,0.01032
45.6,3.8,25160.41,0.02735,0.01037
45.7,3.809,25161.86,0.02748,0.01042
45.8,3.817,25161.47,0.0276,0.01047
45.9,3.825,25161.4,0.02773,0.01053
46,3.834,25164.92,0.02786,0.01058
46.1,3.842,25163.73,0.02799,0.01063
46.2,3.85,25162.97,0.02812,0.01067
46.3,3.859,25167.22,0.02825,0.01073
46.4,3.867,25166.52,0.02837,0.01077
46.5,3.875,25167.37,0.0285,0.01082
46.6,3.884,25167.92,0.02863,0.01087
46.7,3.892,25171.48,0.02876,0.01091
46.8,3.9,25174.13,0.02889,0.01096
46.9,3.909,25178.16,0.02901,0.01101
47,3.917,25180.64,0.02914,0.01106
47.1,3.925,25182.6,0.02927,0.01111
47.2,3.933,25182.54,0.0294,0.01115
47.3,3.942,25192.03,0.02952,0.0112
47.4,3.95,25190.87,0.02965,0.01125
47.5,3.959,25192.52,0.02978,0.0113
47.6,3.967,25196.96,0.02991,0.01134
47.7,3.975,25198.39,0.03004,0.01139
47.8,3.984,25204.3,0.03016,0.01144
47.9,3.992,25205.66,0.03029,0.01149
48,4,25208.43,0.03041,0.01154
48.1,4.009,25209.47,0.03055,0.01158
48.2,4.017,25216.36,0.03067,0.01163
48.3,4.025,25216.52,0.0308,0.01168
48.4,4.034,25219.24,0.03093,0.01172
48.5,4.042,25224.93,0.03106,0.01177
48.6,4.05,25229.99,0.03119,0.01182
48.7,4.059,25235,0.03131,0.01187
48.8,4.067,25234.21,0.03144,0.01191
48.9,4.075,25242.23,0.03156,0.01196
49,4.084,25253.15,0.03169,0.012
49.1,4.092,25255.2,0.03183,0.01205
49.2,4.1,25261.97,0.03195,0.0121
49.3,4.108,25268.4,0.03208,0.01214
49.4,4.117,25275.35,0.03221,0.01219
49.5,4.125,25279.63,0.03233,0.01224
49.6,4.134,25284.51,0.03246,0.01228
49.7,4.142,25292.24,0.03258,0.01232
49.8,4.15,25293.47,0.03271,0.01237
49.9,4.158,25300.57,0.03284,0.01241
50,4.167,25307.23,0.03297,0.01246
50.1,4.175,25313.67,0.03309,0.01251
50.2,4.184,25315.26,0.03322,0.01256
50.3,4.192,25316.14,0.03334,0.0126
50.4,4.2,25320.99,0.03347,0.01264
50.5,4.209,25328.59,0.0336,0.01269
50.6,4.217,25332.59,0.03373,0.01274
50.7,4.225,25337.09,0.03386,0.01279
50.8,4.234,25342.37,0.03398,0.01284
50.9,4.242,25350.86,0.03411,0.01288
51,4.25,25356.03,0.03423,0.01293
51.1,4.259,25363.59,0.03436,0.01298
51.2,4.267,25374.68,0.03449,0.01302
51.3,4.275,25378.06,0.03462,0.01307
51.4,4.284,25375.28,0.03474,0.01311
51.5,4.292,25389.8,0.03487,0.01316
51.6,4.3,25394.44,0.035,0.01321
51.7,4.309,25405.15,0.03513,0.01326
51.8,4.317,25409.71,0.03526,0.01331
51.9,4.325,25413.82,0.03538,0.01336
52,4.334,25419.52,0.03551,0.0134
52.1,4.342,25428.88,0.03563,0.01344
52.2,4.35,25440.66,0.03576,0.01349
52.3,4.359,25444.11,0.03588,0.01353
52.4,4.367,25448.09,0.03601,0.01358
52.5,4.375,25463.38,0.03614,0.01363
52.6,4.383,25459.47,0.03626,0.01368
52.7,4.392,25468.06,0.03639,0.01372
52.8,4.4,25481.32,0.03651,0.01377
52.9,4.409,25483.48,0.03663,0.01382
53,4.417,25491.21,0.03676,0.01387
53.1,4.425,25495.26,0.03688,0.01391
53.2,4.434,25501.42,0.037,0.01396
53.3,4.442,25507.72,0.03713,0.01401
53.4,4.45,25511.14,0.03726,0.01405
53.5,4.459,25514.12,0.03739,0.01409
53.6,4.467,25515.17,0.03751,0.01414
53.7,4.475,25522.27,0.03764,0.01419
53.8,4.484,25529.07,0.03777,0.01424
53.9,4.492,25528.63,0.0379,0.01429
54,4.5,25534.31,0.03803,0.01433
54.1,4.509,25539.86,0.03815,0.01438
54.2,4.517,25539.75,0.03828,0.01443
54.3,4.525,25546.3,0.0384,0.01447
54.4,4.534,25549.59,0.03853,0.01452
54.5,4.542,25550.51,0.03866,0.01457
54.6,4.55,25559.04,0.03879,0.01461
54.7,4.559,25558.51,0.03891,0.01465
54.8,4.567,25567.05,0.03904,0.0147
54.9,4.575,25565.66,0.03917,0.01474
55,4.584,25571.32,0.0393,0.01479
55.1,4.592,25579.04,0.03942,0.01484
55.2,4.6,25584.3,0.03955,0.01488
55.3,4.608,25586.88,0.03968,0.01493
55.4,4.617,25603.32,0.0398,0.01498
55.5,4.625,25604.18,0.03993,0.01502
55.6,4.634,25612.17,0.04006,0.01507
55.7,4.642,25616.12,0.04019,0.01511
55.8,4.65,25621.38,0.04032,0.01516
55.9,4.659,25629.1,0.04044,0.0152
56,4.667,25637.03,0.04057,0.01525
56.1,4.675,25642.05,0.0407,0.01529
56.2,4.684,25652.91,0.04082,0.01534
56.3,4.692,25654.1,0.04095,0.01539
56.4,4.7,25671.17,0.04108,0.01543
56.5,4.709,25676.01,0.0412,0.01548
56.6,4.717,25672.21,0.04133,0.01553
56.7,4.725,25684.08,0.04146,0.01557
56.8,4.734,25689.55,0.04158,0.01562
56.9,4.742,25688.7,0.04171,0.01567
57,4.75,25694.88,0.04184,0.01571
57.1,4.759,25700.88,0.04197,0.01576
57.2,4.767,25699.96,0.0421,0.0158
57.3,4.775,25706.16,0.04223,0.01585
57.4,4.783,25708.65,0.04235,0.01589
57.5,4.792,25708.89,0.04248,0.01594
57.6,4.8,25714.76,0.04261,0.01599
57.7,4.809,25713.83,0.04273,0.01603
57.8,4.817,25713.23,0.04286,0.01608
57.9,4.825,25715.7,0.04299,0.01613
58,4.834,25717.57,0.04312,0.01617
58.1,4.842,25717.98,0.04324,0.01622
58.2,4.85,25720.91,0.04338,0.01626
58.3,4.859,25720.36,0.0435,0.01631
58.4,4.867,25722.83,0.04363,0.01635
58.5,4.875,25725.46,0.04375,0.0164
58.6,4.883,25723.75,0.04388,0.01644
58.7,4.892,25726.92,0.04401,0.01649
58.8,4.9,25729.69,0.04414,0.01654
58.9,4.909,25729.66,0.04426,0.01659
59,4.917,25731.72,0.04439,0.01663
59.1,4.925,25730.1,0.04452,0.01668
59.2,4.934,25731.35,0.04465,0.01674
59.3,4.942,25732.04,0.04478,0.01678
59.4,4.95,25732.24,0.04491,0.01683
59.5,4.959,25734.15,0.04504,0.01687
59.6,4.967,25736.9,0.04517,0.01692
59.7,4.975,25743.11,0.04529,0.01697
59.8,4.984,25740.89,0.04542,0.01701
59.9,4.992,25741.26,0.04555,0.01706
60,5,25743.54,0.04568,0.01711
60.1,5.009,25746.21,0.0458,0.01715
60.2,5.017,25748.36,0.04593,0.0172
60.3,5.025,25752.12,0.04607,0.01724
60.4,5.034,25755.35,0.04619,0.01729
60.5,5.042,25756.87,0.04632,0.01734
60.6,5.05,25756.97,0.04645,0.01738
60.7,5.059,25758.94,0.04658,0.01743
60.8,5.067,25760.57,0.0467,0.01748
60.9,5.075,25762.67,0.04683,0.01752
61,5.084,25765.58,0.04696,0.01757
61.1,5.092,25765.55,0.04709,0.01762
61.2,5.1,25767.81,0.04722,0.01766
61.3,5.109,25770.41,0.04735,0.0177
61.4,5.117,25774.4,0.04748,0.0177
61.5,5.125,25773.46,0.04761,0.01774
61.6,5.133,25773.79,0.04773,0.01779
61.7,5.142,25775.06,0.04787,0.01784
61.8,5.15,25778.32,0.04799,0.01789
61.9,5.159,25776.24,0.04813,0.01794
62,5.167,25777.98,0.04825,0.01799
62.1,5.175,25779.05,0.04839,0.01803
62.2,5.184,25781.67,0.04851,0.01809
62.3,5.192,25780.13,0.04864,0.01813
62.4,5.2,25781.29,0.04877,0.01818
62.5,5.209,25787.49,0.0489,0.01823
62.6,5.217,25786.76,0.04903,0.01828
62.7,5.225,25786.75,0.04916,0.01832
62.8,5.233,25789.23,0.04928,0.01837
62.9,5.242,25796.26,0.04941,0.01842
63,5.25,25796.6,0.04954,0.01847
63.1,5.259,25795.89,0.04967,0.01851
63.2,5.267,25797.82,0.0498,0.01856
63.3,5.275,25804.08,0.04993,0.0186
63.4,5.284,25803.5,0.05006,0.01865
63.5,5.292,25807.45,0.05018,0.0187
63.6,5.3,25812.95,0.05031,0.01874
63.7,5.309,25818.15,0.05044,0.01879
63.8,5.317,25817.29,0.05057,0.01884
63.9,5.325,25824.52,0.0507,0.01889
64,5.334,25829.67,0.05083,0.01894
64.1,5.342,25828.7,0.05096,0.01898
64.2,5.35,25837.26,0.0511,0.01903
64.3,5.359,25843.48,0.05123,0.01907
64.4,5.367,25839.57,0.05135,0.01912
64.5,5.375,25845.37,0.05149,0.01917
64.6,5.384,25846.41,0.05161,0.01921
64.7,5.392,25850.92,0.05174,0.01926
64.8,5.4,25857.75,0.05187,0.0193
64.9,5.409,25856.79,0.052,0.01935
65,5.417,25857.96,0.05213,0.0194
65.1,5.425,25865.55,0.05226,0.01945
65.2,5.434,25866.78,0.05239,0.01949
65.3,5.442,25865.77,0.05252,0.01954
65.4,5.45,25872.83,0.05265,0.01959
65.5,5.459,25869.67,0.05278,0.01963
65.6,5.467,25877.52,0.05291,0.01967
65.7,5.475,25879.17,0.05304,0.01972
65.8,5.484,25882.3,0.05317,0.01975
65.9,5.492,25884.72,0.0533,0.01977
66,5.5,25887.16,0.05343,0.01979
66.1,5.509,25891.12,0.05356,0.01984
66.2,5.517,25889.99,0.05369,0.01989
66.3,5.525,25894.78,0.05382,0.01994
66.4,5.534,25896.25,0.05395,0.01999
66.5,5.542,25903.12,0.05408,0.02004
66.6,5.55,25901.4,0.05421,0.02009
66.7,5.559,25904.16,0.05434,0.02013
66.8,5.567,25910.25,0.05447,0.02017
66.9,5.575,25907.95,0.05461,0.02022
67,5.584,25912.44,0.05474,0.02027
67.1,5.592,25915.75,0.05486,0.02031
67.2,5.6,25918.36,0.05499,0.02036
67.3,5.609,25928.28,0.05513,0.02041
67.4,5.617,25929.42,0.05527,0.02046
67.5,5.625,25924.92,0.05539,0.02043
67.6,5.634,25932.76,0.05553,0.02048
67.7,5.642,25933.94,0.05565,0.02054
67.8,5.65,25936.31,0.05579,0.02058
67.9,5.659,25944.1,0.05592,0.02063
68,5.667,25946,0.05605,0.02068
68.1,5.675,25952.15,0.05618,0.02073
68.2,5.683,25951.85,0.05632,0.02077
68.3,5.692,25956.12,0.05644,0.02083
68.4,5.7,25960.5,0.05657,0.02087
68.5,5.709,25965.97,0.0567,0.02092
68.6,5.717,25970.22,0.05684,0.02097
68.7,5.725,25972.64,0.05697,0.02102
68.8,5.733,25975.79,0.0571,0.02107
68.9,5.742,25981.63,0.05724,0.02111
69,5.75,25982.3,0.05737,0.02116
69.1,5.759,25984.79,0.0575,0.02121
69.2,5.767,25986.76,0.05763,0.02126
69.3,5.775,25990.9,0.05776,0.02131
69.4,5.784,25993.57,0.05789,0.02135
69.5,5.792,25996.5,0.05803,0.0214
69.6,5.8,25994.65,0.05816,0.02145
69.7,5.809,26001.43,0.05829,0.0215
69.8,5.817,25999.39,0.05843,0.02155
69.9,5.825,26000.41,0.05857,0.0216
70,5.834,26002.53,0.0587,0.02164
70.1,5.842,26004.43,0.05883,0.02169
70.2,5.85,26009.38,0.05896,0.02174
70.3,5.858,26009.95,0.05909,0.02178
70.4,5.867,26007.04,0.05923,0.02183
70.5,5.875,26013.76,0.05936,0.02188
70.6,5.884,26013.45,0.05949,0.02193
70.7,5.892,26013.59,0.05963,0.02198
70.8,5.9,26014.46,0.05976,0.02202
70.9,5.909,26014.9,0.05989,0.02207
71,5.917,26017.57,0.06002,0.02212
71.1,5.925,26021.76,0.06016,0.02217
71.2,5.934,26024.69,0.06029,0.02222
71.3,5.942,26024.1,0.06043,0.02227
71.4,5.95,26025.77,0.06056,0.02232
71.5,5.959,26031.28,0.06069,0.02237
71.6,5.967,26038.56,0.06082,0.02241
71.7,5.975,26032.21,0.06096,0.02246
71.8,5.984,26036.46,0.06109,0.02251
71.9,5.992,26035.33,0.06123,0.02256
72,6,26040.14,0.06137,0.0226
72.1,6.009,26047.54,0.0615,0.02265
72.2,6.017,26042.88,0.06163,0.0227
72.3,6.025,26046.83,0.06177,0.02275
72.4,6.034,26054.19,0.0619,0.02279
72.5,6.042,26051.46,0.06203,0.02276
72.6,6.05,26058.95,0.06216,0.02281
72.7,6.059,26060.62,0.0623,0.02287
72.8,6.067,26073.34,0.06243,0.02292
72.9,6.075,26066.66,0.06257,0.02297
73,6.084,26061.5,0.0627,0.02302
73.1,6.092,26069.1,0.06283,0.02307
73.2,6.1,26086.37,0.06297,0.02312
73.3,6.109,26080.1,0.06311,0.02317
73.4,6.117,26073.14,0.06324,0.02322
73.5,6.125,26079.22,0.06338,0.02327
73.6,6.134,26093.95,0.06351,0.02332
73.7,6.142,26093.27,0.06365,0.02337
73.8,6.15,26099.42,0.06378,0.02342
73.9,6.159,26094.72,0.06392,0.02347
74,6.167,26099.3,0.06406,0.02352
74.1,6.175,26101.89,0.06419,0.02357
74.2,6.184,26107.38,0.06433,0.02362
74.3,6.192,26113.17,0.06446,0.02367
74.4,6.2,26115.11,0.0646,0.02372
74.5,6.209,26121.59,0.06474,0.02376
74.6,6.217,26126.06,0.06487,0.02382
74.7,6.225,26124.27,0.06501,0.02386
74.8,6.234,26129.82,0.06515,0.02392
74.9,6.242,26128.12,0.06528,0.02396
75,6.25,26128.54,0.06542,0.02401
75.1,6.259,26133.1,0.06556,0.02406
75.2,6.267,26137.22,0.06569,0.02411
75.3,6.275,26141.2,0.06583,0.02415
75.4,6.284,26146.19,0.06597,0.0242
75.5,6.292,26143.14,0.0661,0.02425
75.6,6.3,26145.25,0.06624,0.0243
75.7,6.309,26155.3,0.06638,0.02435
75.8,6.317,26152.7,0.06652,0.0244
75.9,6.325,26157.94,0.06665,0.02445
76,6.334,26163.92,0.06679,0.0245
76.1,6.342,26163.24,0.06693,0.02455
76.2,6.35,26161.46,0.06706,0.0246
76.3,6.358,26167.45,0.0672,0.02465
76.4,6.367,26166.02,0.06734,0.02469
76.5,6.375,26168.87,0.06748,0.02474
76.6,6.384,26176.39,0.06762,0.02479
76.7,6.392,26177.23,0.06775,0.02484
76.8,6.4,26175.8,0.06789,0.02489
76.9,6.409,26183.58,0.06803,0.02494
77,6.417,26184.39,0.06817,0.02499
77.1,6.425,26184.49,0.06831,0.02503
77.2,6.434,26186.73,0.06845,0.02508
77.3,6.442,26187.4,0.06859,0.02513
77.4,6.45,26183.87,0.06872,0.02518
77.5,6.459,26186.55,0.06886,0.02523
77.6,6.467,26188.61,0.069,0.02528
77.7,6.475,26190.98,0.06914,0.02533
77.8,6.484,26190.4,0.06928,0.02538
77.9,6.492,26186.2,0.06942,0.02543
78,6.5,26193.54,0.06956,0.02548
78.1,6.509,26196.08,0.0697,0.02552
78.2,6.517,26191.88,0.06984,0.02557
78.3,6.525,26194.4,0.06998,0.02562
78.4,6.534,26195.04,0.07011,0.02567
78.5,6.542,26196.47,0.07026,0.02572
78.6,6.55,26194.78,0.0704,0.02577
78.7,6.559,26200.22,0.07053,0.02582
78.8,6.567,26199.71,0.07068,0.02587
78.9,6.575,26202.1,0.07082,0.02592
79,6.583,26202.54,0.07096,0.02596
79.1,6.592,26203.34,0.07109,0.02602
79.2,6.6,26205.91,0.07124,0.02606
79.3,6.609,26204.81,0.07138,0.02611
79.4,6.617,26202.72,0.07152,0.02617
79.5,6.625,26203.79,0.07166,0.02621
79.6,6.634,26205.68,0.0718,0.02626
79.7,6.642,26208.45,0.07194,0.02631
79.8,6.65,26208.96,0.07208,0.02636
79.9,6.659,26210.52,0.07223,0.02641
80,6.667,26209.08,0.07237,0.02646
80.1,6.675,26210.91,0.07251,0.02651
80.2,6.684,26214.06,0.07265,0.02656
80.3,6.692,26210.43,0.0728,0.02661
80.4,6.7,26213.23,0.07294,0.02666
80.5,6.709,26212.57,0.07308,0.02671
80.6,6.717,26212.65,0.07322,0.02676
80.7,6.725,26213.17,0.07336,0.0268
80.8,6.734,26214.79,0.07351,0.02686
80.9,6.742,26215.73,0.07365,0.0269
81,6.75,26215.12,0.07379,0.02695
81.1,6.758,26213.05,0.07393,0.027
81.2,6.767,26218.43,0.07408,0.02705
81.3,6.775,26216.59,0.07422,0.02711
81.4,6.784,26218.26,0.07436,0.02716
81.5,6.792,26218.21,0.07451,0.0272
81.6,6.8,26216.44,0.07465,0.02726
81.7,6.808,26217.91,0.07479,0.02731
81.8,6.817,26217.83,0.07494,0.02736
81.9,6.825,26219.42,0.07508,0.02741
82,6.834,26219.12,0.07523,0.02746
82.1,6.842,26220.38,0.07537,0.0275
82.2,6.85,26222.28,0.07552,0.02755
82.3,6.859,26221.84,0.07566,0.02761
82.4,6.867,26223.09,0.07581,0.02766
82.5,6.875,26223.33,0.07596,0.02771
82.6,6.884,26221.72,0.0761,0.02776
82.7,6.892,26222.46,0.07624,0.02781
82.8,6.9,26222.49,0.07639,0.02786
82.9,6.909,26223.02,0.07654,0.02791
83,6.917,26224.59,0.07669,0.02796
83.1,6.925,26224.77,0.07683,0.02801
83.2,6.933,26225.41,0.07698,0.02806
83.3,6.942,26225.05,0.07712,0.02811
83.4,6.95,26225.98,0.07727,0.02816
83.5,6.959,26226.92,0.07741,0.02821
83.6,6.967,26227.08,0.07756,0.02827
83.7,6.975,26227.11,0.07771,0.02832
83.8,6.984,26226.43,0.07786,0.02837
83.9,6.992,26228.43,0.078,0.02842
84,7,26228.92,0.07815,0.02846
84.1,7.009,26229.78,0.0783,0.02851
84.2,7.017,26230.04,0.07844,0.02856
84.3,7.025,26231.06,0.07859,0.02852
84.4,7.034,26233.51,0.07874,0.02855
84.5,7.042,26231.22,0.07888,0.02861
84.6,7.05,26233.51,0.07903,0.02867
84.7,7.059,26234.81,0.07918,0.02872
84.8,7.067,26232.05,0.07933,0.02878
84.9,7.075,26232.54,0.07948,0.02884
85,7.084,26235.2,0.07963,0.02889
85.1,7.092,26233.92,0.07978,0.02894
85.2,7.1,26235.13,0.07993,0.029
85.3,7.109,26233.55,0.08008,0.02905
85.4,7.117,26236.94,0.08022,0.02911
85.5,7.125,26235.72,0.08037,0.02916
85.6,7.134,26236.93,0.08053,0.02921
85.7,7.142,26236.66,0.08068,0.02926
85.8,7.15,26236.2,0.08083,0.02931
85.9,7.159,26237.42,0.08098,0.02936
86,7.167,26238.58,0.08113,0.02942
86.1,7.175,26233.95,0.08128,0.02947
86.2,7.184,26238.92,0.08143,0.02952
86.3,7.192,26245.29,0.08158,0.02957
86.4,7.2,26240.68,0.08174,0.02962
86.5,7.209,26241.37,0.08188,0.02968
86.6,7.217,26243.82,0.08203,0.02972
86.7,7.225,26242.46,0.08219,0.02978
86.8,7.234,26242.85,0.08234,0.02983
86.9,7.242,26241.81,0.08249,0.02988
87,7.25,26240.5,0.08264,0.02994
87.1,7.259,26241.91,0.08279,0.02999
87.2,7.267,26245.98,0.08295,0.03004
87.3,7.275,26243.52,0.0831,0.0301
87.4,7.284,26242.45,0.08325,0.03015
87.5,7.292,26247.12,0.0834,0.0302
87.6,7.3,26248.08,0.08356,0.03025
87.7,7.309,26245.12,0.08372,0.0303
87.8,7.317,26246.27,0.08387,0.03035
87.9,7.325,26243.05,0.08403,0.0304
88,7.334,26244.12,0.08418,0.03046
88.1,7.342,26243.3,0.08433,0.03051
88.2,7.35,26241.86,0.08449,0.03056
88.3,7.359,26244.71,0.08464,0.03061
88.4,7.367,26243.3,0.0848,0.03066
88.5,7.375,26242.71,0.08495,0.03072
88.6,7.383,26242.01,0.08511,0.03077
88.7,7.392,26245.25,0.08526,0.03082
88.8,7.4,26248.46,0.08541,0.03087
88.9,7.409,26246.32,0.08557,0.03093
89,7.417,26249.56,0.08573,0.03098
89.1,7.425,26249.61,0.08588,0.03103
89.2,7.434,26242.56,0.08604,0.03108
89.3,7.442,26245.42,0.0862,0.03114
89.4,7.45,26248.55,0.08635,0.03119
89.5,7.459,26247.66,0.08651,0.03124
89.6,7.467,26245.21,0.08666,0.03129
89.7,7.475,26247.39,0.08682,0.03134
89.8,7.483,26248.27,0.08698,0.03139
89.9,7.492,26247.96,0.08714,0.03144
90,7.5,26248.09,0.08729,0.03149
90.1,7.509,26247.56,0.08745,0.03155
90.2,7.517,26246.23,0.08761,0.0316
90.3,7.525,26246.92,0.08777,0.03165
90.4,7.534,26247.52,0.08792,0.0317
90.5,7.542,26248.94,0.08808,0.03175
90.6,7.55,26247.67,0.08823,0.0318
90.7,7.559,26247.99,0.0884,0.03185
90.8,7.567,26248.15,0.08855,0.03191
90.9,7.575,26250.75,0.08872,0.03196
91,7.584,26248.08,0.08888,0.03201
91.1,7.592,26247.85,0.08903,0.03206
91.2,7.6,26249.28,0.08919,0.03211
91.3,7.609,26245.5,0.08935,0.03216
91.4,7.617,26244.98,0.08951,0.03221
91.5,7.625,26241.89,0.08966,0.03226
91.6,7.634,26247.82,0.08983,0.03231
91.7,7.642,26251.34,0.08998,0.03236
91.8,7.65,26245.02,0.09014,0.03241
91.9,7.659,26245.65,0.0903,0.03246
92,7.667,26250.04,0.09046,0.03251
92.1,7.675,26246.19,0.09062,0.03256
92.2,7.684,26245.75,0.09078,0.03261
92.3,7.692,26244.75,0.09094,0.03266
92.4,7.7,26246.67,0.0911,0.03271
92.5,7.709,26245.46,0.09125,0.03275
92.6,7.717,26245.21,0.09142,0.0328
92.7,7.725,26245.94,0.09158,0.03285
92.8,7.734,26243.37,0.09174,0.0329
92.9,7.742,26244.9,0.0919,0.03295
93,7.75,26245.26,0.09206,0.033
93.1,7.759,26244.84,0.09222,0.03305
93.2,7.767,26248.42,0.09238,0.0331
93.3,7.775,26242.32,0.09254,0.03314
93.4,7.784,26239.75,0.0927,0.03319
93.5,7.792,26242.48,0.09286,0.03323
93.6,7.8,26242.57,0.09302,0.03328
93.7,7.809,26243.37,0.09318,0.03333
93.8,7.817,26244.8,0.09333,0.03338
93.9,7.825,26243.29,0.09349,0.03343
94,7.834,26239.95,0.09365,0.03347
94.1,7.842,26242.49,0.09381,0.03351
94.2,7.85,26238.84,0.09397,0.03356
94.3,7.859,26242.61,0.09413,0.03361
94.4,7.867,26244.15,0.09429,0.03365
94.5,7.875,26240.48,0.09445,0.03369
94.6,7.883,26241.3,0.0946,0.03374
94.7,7.892,26241.77,0.09476,0.03379
94.8,7.9,26242.22,0.09492,0.03383
94.9,7.909,26239.63,0.09508,0.03387
95,7.917,26240.84,0.09524,0.03392
95.1,7.925,26238.49,0.09539,0.03395
95.2,7.933,26238.6,0.09555,0.034
95.3,7.942,26240.65,0.09571,0.03404
95.4,7.95,26233.94,0.09587,0.03408
95.5,7.959,26237.69,0.09603,0.03412
95.6,7.967,26234.53,0.09619,0.03416
95.7,7.975,26233.11,0.09634,0.0342
95.8,7.984,26232.82,0.09649,0.03424
95.9,7.992,26233.18,0.09665,0.03428
96,8,26232.03,0.09681,0.03432
96.1,8.009,26233.5,0.09697,0.03436
96.2,8.017,26231.68,0.09712,0.03439
96.3,8.025,26232.64,0.09727,0.03443
96.4,8.034,26233.14,0.09743,0.03447
96.5,8.042,26228.34,0.09758,0.03451
96.6,8.05,26228.27,0.09774,0.03454
96.7,8.059,26228.23,0.09789,0.03458
96.8,8.067,26228.5,0.09804,0.03462
96.9,8.075,26228.04,0.09819,0.03465
97,8.084,26227.46,0.09834,0.03468
97.1,8.092,26224.65,0.09849,0.03472
97.2,8.1,26225.74,0.09864,0.03475
97.3,8.109,26224.38,0.0988,0.03479
97.4,8.117,26225.02,0.09895,0.03481
97.5,8.125,26223.38,0.09909,0.03485
97.6,8.134,26224.2,0.09924,0.03488
97.7,8.142,26220.19,0.09939,0.0349
97.8,8.15,26216.71,0.09954,0.03493
97.9,8.159,26218.96,0.09969,0.03496
98,8.167,26217.08,0.09984,0.03499
98.1,8.175,26216.55,0.09998,0.03501
98.2,8.184,26215.23,0.10013,0.03504
98.3,8.192,26212.64,0.10027,0.03507
98.4,8.2,26212.49,0.10042,0.03509
98.5,8.209,26212.69,0.10056,0.03512
98.6,8.217,26208.4,0.10071,0.03514
98.7,8.225,26211.16,0.10085,0.03516
98.8,8.234,26207.88,0.10099,0.03519
98.9,8.242,26205.1,0.10113,0.03521
99,8.25,26206.87,0.10127,0.03523
99.1,8.259,26206.42,0.1014,0.03525
99.2,8.267,26204.07,0.10154,0.03528
99.3,8.275,26201.94,0.10168,0.0353
99.4,8.284,26200.78,0.10182,0.03531
99.5,8.292,26196.42,0.10195,0.03533
99.6,8.3,26192.78,0.10209,0.03535
99.7,8.309,26194.78,0.10222,0.03537
99.8,8.317,26189.48,0.10236,0.03539
99.9,8.325,26184.29,0.10249,0.03541
100,8.334,26180.77,0.10262,0.03542
100.1,8.342,26181.82,0.10275,0.03544
100.2,8.35,26180.84,0.10289,0.03546
100.3,8.359,26178,0.10302,0.03548
100.4,8.367,26172.82,0.10315,0.03549
100.5,8.375,26163.2,0.10328,0.0355
100.6,8.384,26165.4,0.10341,0.03552
100.7,8.392,26160.24,0.10354,0.03553
100.8,8.4,26148.71,0.10367,0.03554
100.9,8.409,26140.79,0.10379,0.03556
101,8.417,26138.06,0.10391,0.03557
101.1,8.425,26134.48,0.10404,0.03558
101.2,8.434,26122.5,0.10417,0.0356
101.3,8.442,26119.36,0.10429,0.03561
101.4,8.45,26109.71,0.10441,0.03562
101.5,8.458,26111.62,0.10453,0.03563
101.6,8.467,26093.75,0.10465,0.03564
101.7,8.475,26086.27,0.10477,0.03564
101.8,8.484,26076.97,0.10489,0.03562
101.9,8.492,26074.59,0.10502,0.03563
102,8.5,26060.42,0.10514,0.03565
102.1,8.509,26054.57,0.10526,0.03566
102.2,8.517,26050.13,0.10538,0.03567
102.3,8.525,26046.39,0.10549,0.03568
102.4,8.534,26036.86,0.10561,0.03568
102.5,8.542,26033.11,0.10572,0.0357
102.6,8.55,26031.92,0.10584,0.03571
102.7,8.559,26023.92,0.10596,0.03571
102.8,8.567,26022.35,0.10607,0.03572
102.9,8.575,26016.31,0.10619,0.03573
103,8.584,26012.8,0.1063,0.03574
103.1,8.592,26007.1,0.10642,0.03575
103.2,8.6,26005.94,0.10653,0.03575
103.3,8.609,25999.58,0.10665,0.03576
103.4,8.617,25988.64,0.10676,0.03577
103.5,8.625,25984.41,0.10687,0.03577
103.6,8.634,25982.8,0.10699,0.03578
103.7,8.642,25965.75,0.10709,0.03578
103.8,8.65,25957.12,0.10721,0.03579
103.9,8.659,25948.01,0.10732,0.0358
104,8.667,25941.18,0.10743,0.0358
104.1,8.675,25932.37,0.10754,0.03581
104.2,8.684,25920.08,0.10764,0.03581
104.3,8.692,25913.71,0.10775,0.03582
104.4,8.7,25908.78,0.10786,0.03583
104.5,8.709,25895.59,0.10798,0.03583
104.6,8.717,25888.57,0.10809,0.03583
104.7,8.725,25885.88,0.1082,0.03584
104.8,8.733,25883.71,0.10831,0.03584
104.9,8.742,25875.61,0.10841,0.03585
105,8.75,25871.29,0.10852,0.03585
105.1,8.759,25861.2,0.10862,0.03585
105.2,8.767,25859.22,0.10872,0.03586
105.3,8.775,25847.55,0.10883,0.03586
105.4,8.784,25839.98,0.10894,0.03587
105.5,8.792,25837.22,0.10904,0.03587
105.6,8.8,25827.08,0.10915,0.03587
105.7,8.809,25814.9,0.10926,0.03587
105.8,8.817,25801.35,0.10936,0.03588
105.9,8.825,25796.73,0.10946,0.03588
106,8.834,25794.09,0.10957,0.03588
106.1,8.842,25782.83,0.10968,0.03589
106.2,8.85,25774.29,0.10978,0.03589
106.3,8.859,25771.4,0.10988,0.03589
106.4,8.867,25765.14,0.10998,0.03589
106.5,8.875,25765.65,0.11009,0.0359
106.6,8.884,25761.64,0.11019,0.0359
106.7,8.892,25757.71,0.11029,0.0359
106.8,8.9,25755.66,0.11039,0.03586
106.9,8.909,25746.67,0.11049,0.03583
107,8.917,25743.88,0.11059,0.03585
107.1,8.925,25737.64,0.1107,0.03585
107.2,8.934,25733.59,0.1108,0.03585
107.3,8.942,25731.75,0.1109,0.03586
107.4,8.95,25727.29,0.111,0.03586
107.5,8.959,25726.61,0.1111,0.03586
107.6,8.967,25725.29,0.1112,0.03588
107.7,8.975,25719.15,0.11131,0.03587
107.8,8.984,25714.76,0.1114,0.03588
107.9,8.992,25711,0.1115,0.03588
108,9,25702.37,0.1116,0.03588
108.1,9.008,25693.46,0.1117,0.03589
108.2,9.017,25682.74,0.1118,0.03589
108.3,9.025,25671.81,0.1119,0.03589
108.4,9.034,25653.19,0.112,0.03589
108.5,9.042,25629.1,0.1121,0.03589
108.6,9.05,25614.18,0.1122,0.0359
108.7,9.059,25597.56,0.1123,0.0359
108.8,9.067,25580.19,0.1124,0.0359
108.9,9.075,25564.74,0.11249,0.0359
109,9.084,25552.48,0.11259,0.0359
109.1,9.092,25542.51,0.11269,0.03591
109.2,9.1,25533.43,0.11279,0.03591
109.3,9.109,25521.36,0.11289,0.03591
109.4,9.117,25511.45,0.11298,0.03591
109.5,9.125,25498.49,0.11308,0.03591
109.6,9.134,25488.95,0.11317,0.03591
109.7,9.142,25468.16,0.11327,0.03591
109.8,9.15,25456.03,0.11337,0.03591
109.9,9.159,25443.46,0.11346,0.03591
110,9.167,25412.47,0.11356,0.03591
110.1,9.175,25392.57,0.11365,0.03591
110.2,9.183,25382.69,0.11375,0.03591
110.3,9.192,25361.91,0.11385,0.03591
110.4,9.2,25347.59,0.11394,0.03591
110.5,9.209,25330.38,0.11404,0.03592
110.6,9.217,25318.28,0.11413,0.03591
110.7,9.225,25302.45,0.11423,0.03591
110.8,9.234,25293.33,0.11433,0.03592
110.9,9.242,25279.8,0.11442,0.03591
111,9.25,25257.99,0.11452,0.03592
111.1,9.259,25244.56,0.11461,0.03592
111.2,9.267,25229.26,0.1147,0.03592
111.3,9.275,25217.85,0.1148,0.03592
111.4,9.284,25214.69,0.11489,0.03592
111.5,9.292,25206.3,0.11498,0.03592
111.6,9.3,25199.02,0.11508,0.03592
111.7,9.309,25189.56,0.11517,0.03592
111.8,9.317,25182.68,0.11527,0.03592
111.9,9.325,25177.57,0.11536,0.03592
112,9.334,25171.75,0.11545,0.03592
112.1,9.342,25166.16,0.11554,0.03592
112.2,9.35,25164.12,0.11564,0.03592
112.3,9.359,25161.5,0.11573,0.03592
112.4,9.367,25161.99,0.11582,0.03592
112.5,9.375,25161.08,0.11591,0.03592
112.6,9.384,25159.31,0.116,0.03591
112.7,9.392,25152.52,0.1161,0.03591
112.8,9.4,25146.96,0.1162,0.03592
112.9,9.409,25134,0.11629,0.03591
113,9.417,25117.51,0.11638,0.03591
113.1,9.425,25100.03,0.11647,0.03591
113.2,9.434,25080.24,0.11656,0.03591
113.3,9.442,25065.95,0.11665,0.03591
113.4,9.45,25047.88,0.11674,0.03591
113.5,9.459,25032.03,0.11683,0.03591
113.6,9.467,25023,0.11693,0.03591
113.7,9.475,25008.92,0.11702,0.03591
113.8,9.484,24994.12,0.11711,0.03591
113.9,9.492,24973.01,0.1172,0.03591
114,9.5,24955.54,0.11729,0.03591
114.1,9.509,24945.6,0.11738,0.03586
114.2,9.517,24928.36,0.11747,0.03587
114.3,9.525,24910.59,0.11756,0.03587
114.4,9.534,24887.2,0.11765,0.03587
114.5,9.542,24865.23,0.11774,0.03588
114.6,9.55,24839.49,0.11783,0.03587
114.7,9.559,24814.31,0.11792,0.03588
114.8,9.567,24768.59,0.118,0.03588
114.9,9.575,24752.08,0.11809,0.03588
115,9.583,24736.55,0.11818,0.03587
115.1,9.592,24726.75,0.11827,0.03588
115.2,9.6,24719.82,0.11836,0.03587
115.3,9.609,24713.09,0.11845,0.03587
115.4,9.617,24699.41,0.11853,0.03587
115.5,9.625,24688.22,0.11862,0.03587
115.6,9.633,24680.63,0.11871,0.03587
115.7,9.642,24667.79,0.1188,0.03587
115.8,9.65,24660.86,0.11888,0.03587
115.9,9.659,24646.41,0.11897,0.03587
116,9.667,24633.73,0.11906,0.03587
116.1,9.675,24617.04,0.11915,0.03587
116.2,9.684,24613.04,0.11924,0.03587
116.3,9.692,24584.8,0.11933,0.03587
116.4,9.7,24562.31,0.11941,0.03587
116.5,9.709,24535.24,0.1195,0.03587
116.6,9.717,24508.6,0.11958,0.03587
116.7,9.725,24487.64,0.11967,0.03587
116.8,9.734,24469.86,0.11975,0.03587
116.9,9.742,24459.47,0.11984,0.03587
117,9.75,24450.35,0.11992,0.03587
117.1,9.759,24440.81,0.12001,0.03587
117.2,9.767,24428.55,0.12009,0.03587
117.3,9.775,24412.65,0.12018,0.03587
117.4,9.784,24397.56,0.12027,0.03588
117.5,9.792,24386.96,0.12035,0.03588
117.6,9.8,24380,0.12043,0.03588
117.7,9.808,24370.58,0.12052,0.03588
117.8,9.817,24361.15,0.12061,0.03588
117.9,9.825,24347.75,0.12069,0.03588
118,9.834,24329.29,0.12077,0.03588
118.1,9.842,24311.75,0.12085,0.03588
118.2,9.85,24279.74,0.12093,0.03588
118.3,9.859,24262.27,0.12102,0.03588
118.4,9.867,24252.54,0.1211,0.03588
118.5,9.875,24233.42,0.12118,0.03588
118.6,9.884,24218.51,0.12127,0.03588
118.7,9.892,24200.03,0.12135,0.03588
118.8,9.9,24187.65,0.12143,0.03588
118.9,9.909,24174.36,0.12151,0.03587
119,9.917,24165.23,0.1216,0.03587
119.1,9.925,24156.91,0.12168,0.03587
119.2,9.934,24139.29,0.12176,0.03587
119.3,9.942,24125.65,0.12184,0.03587
119.4,9.95,24104.45,0.12192,0.03587
119.5,9.959,24073.89,0.122,0.03587
119.6,9.967,24039.21,0.12208,0.03587
119.7,9.975,23997.43,0.12216,0.03587
119.8,9.983,23976.92,0.12224,0.03587
119.9,9.992,23954.49,0.12232,0.03587
120,10,23930.18,0.1224,0.03588
120.1,10.009,23903.74,0.12248,0.03588
120.2,10.017,23868.32,0.12256,0.03587
120.3,10.025,23841.61,0.12264,0.03587
120.4,10.034,23820.94,0.12271,0.03587
120.5,10.042,23802.14,0.1228,0.03587
120.6,10.05,23772.85,0.12287,0.03587
120.7,10.059,23749.92,0.12295,0.03587
120.8,10.067,23722.55,0.12303,0.03587
120.9,10.075,23688.88,0.12311,0.03587
121,10.084,23674.1,0.12319,0.03586
121.1,10.092,23669.11,0.12327,0.03586
121.2,10.1,23667.8,0.12334,0.03586
121.3,10.109,23667.88,0.12343,0.03586
121.4,10.117,23667.81,0.1235,0.03586
121.5,10.125,23667.75,0.12358,0.03587
121.6,10.134,23667.19,0.12365,0.03587
121.7,10.142,23666.83,0.12373,0.03587
121.8,10.15,23663.86,0.1238,0.03587
121.9,10.159,23656.3,0.12388,0.03587
122,10.167,23630.66,0.12396,0.03587
122.1,10.175,23602.82,0.12403,0.03587
122.2,10.184,23566.32,0.12411,0.03587
122.3,10.192,23527.49,0.12418,0.03587
122.4,10.2,23499.01,0.12426,0.03587
122.5,10.209,23468.9,0.12433,0.03586
122.6,10.217,23435.56,0.1244,0.03586
122.7,10.225,23414.08,0.12448,0.03586
122.8,10.234,23374.44,0.12455,0.03586
122.9,10.242,23349.92,0.12462,0.03586
123,10.25,23324.42,0.1247,0.03585
123.1,10.259,23295.35,0.12477,0.03585
123.2,10.267,23268,0.12484,0.03585
123.3,10.275,23226.63,0.12492,0.03585
123.4,10.284,23189.28,0.12499,0.03585
123.5,10.292,23168.56,0.12506,0.03585
123.6,10.3,23153.97,0.12513,0.03585
123.7,10.309,23134.19,0.12521,0.03585
123.8,10.317,23112.21,0.12528,0.03584
123.9,10.325,23083.24,0.12535,0.03584
124,10.334,23063.56,0.12542,0.03584
124.1,10.342,23046.88,0.12549,0.03584
124.2,10.35,23042.33,0.12557,0.03584
124.3,10.359,23034.37,0.12564,0.03584
124.4,10.367,23015.3,0.12572,0.03586
124.5,10.375,22985.66,0.12579,0.03586
124.6,10.384,22962.85,0.12586,0.03586
124.7,10.392,22953.43,0.12593,0.03586
124.8,10.4,22941.4,0.12601,0.03585
124.9,10.409,22924.74,0.12609,0.03585
125,10.417,22902.68,0.12631,0.03597
125.1,10.425,22886.16,0.12639,0.03593
125.2,10.434,22864.19,0.12647,0.03596
125.3,10.442,22830.21,0.12655,0.03597
125.4,10.45,22784.79,0.12663,0.03598
125.5,10.459,22725.32,0.1267,0.03599
125.6,10.467,22688.85,0.12677,0.036
125.7,10.475,22673.57,0.12684,0.03601
125.8,10.484,22661.63,0.12691,0.03602
125.9,10.492,22647.2,0.12698,0.03603
126,10.5,22630.29,0.12705,0.03603
126.1,10.509,22606.16,0.12711,0.03604
126.2,10.517,22584.34,0.12718,0.03605
126.3,10.525,22559.32,0.12725,0.03605
126.4,10.534,22524.01,0.12731,0.03606
126.5,10.542,22488.28,0.12739,0.03607
126.6,10.55,22449.25,0.12745,0.03607
126.7,10.559,22407.64,0.12752,0.03608
126.8,10.567,22366.71,0.12758,0.03608
126.9,10.575,22324.61,0.12764,0.03609
127,10.584,22279.45,0.1277,0.03609
127.1,10.592,22257.76,0.12777,0.0361
127.2,10.6,22244.6,0.12783,0.0361
127.3,10.609,22227.55,0.12788,0.0361
127.4,10.617,22189.37,0.12795,0.0361
127.5,10.625,22172.53,0.12801,0.0361
127.6,10.634,22167.4,0.12807,0.03611
127.7,10.642,22166.65,0.12813,0.03611
127.8,10.65,22160.49,0.12819,0.03611
127.9,10.659,22147.29,0.12824,0.03612
128,10.667,22118.63,0.1283,0.03612
128.1,10.675,22071.12,0.12835,0.03612
128.2,10.683,22004.2,0.12841,0.03612
128.3,10.692,21932.35,0.12846,0.03611
128.4,10.7,21412.12,0.12846,0.03609
128.444,10.704,9969.49,0.14155,0.03321