File: Labs/Lab 2 Tension/Specimen_RawData_2.csv
Time (s),Extension (mm),Load (N),Axial Strain (mm/mm),Transverse Strain (mm/mm)
0,0,1.89,0,0
0.2,0.013,278.83,0.00002,0.00001
0.4,0.033,1430.63,0.00008,0.00004
0.6,0.05,2150.79,0.00013,0.00005
0.8,0.067,2375.29,0.00016,0.00006
1,0.084,2711.44,0.00018,0.00008
1.2,0.1,2877.3,0.0002,0.00008
1.4,0.117,3123.96,0.00021,0.00009
1.6,0.134,3280.46,0.00022,0.00008
1.8,0.15,3523.04,0.00024,0.00009
2,0.167,3738.07,0.00025,0.00009
2.2,0.184,3884.76,0.00026,0.00009
2.4,0.2,4124.02,0.00028,0.00009
2.6,0.217,4280.6,0.00029,0.0001
2.8,0.234,4514.85,0.0003,0.0001
3,0.25,4733.22,0.00031,0.0001
3.2,0.267,4888.66,0.00032,0.00011
3.4,0.284,5125.5,0.00034,0.00011
3.6,0.3,5327.47,0.00035,0.00011
3.8,0.317,5548.73,0.00036,0.00012
4,0.334,5764.9,0.00037,0.00012
4.2,0.35,5976.92,0.00039,0.00012
4.4,0.367,6214.87,0.0004,0.00013
4.6,0.383,6350.14,0.00041,0.00013
4.8,0.4,6644.23,0.00042,0.00013
5,0.417,6864.65,0.00044,0.00013
5.2,0.433,7050.59,0.00045,0.00014
5.4,0.45,7332.3,0.00046,0.00014
5.6,0.467,7535.86,0.00047,0.00014
5.8,0.484,7764.65,0.00049,0.00015
6,0.5,7943.54,0.0005,0.00015
6.2,0.517,8267.09,0.00051,0.00015
6.4,0.534,8405.43,0.00052,0.00015
6.6,0.55,8654.25,0.00053,0.00016
6.8,0.567,8935.71,0.00055,0.00016
7,0.584,9149.82,0.00057,0.00016
7.2,0.6,9395.52,0.00057,0.00016
7.4,0.617,9648.76,0.00059,0.00017
7.6,0.633,9910.78,0.0006,0.00017
7.8,0.65,10085.73,0.00062,0.00017
8,0.667,10412.09,0.00063,0.00018
8.2,0.684,10593.52,0.00064,0.00018
8.4,0.7,10880.96,0.00066,0.00018
8.6,0.717,11105.11,0.00067,0.00019
8.8,0.733,11380.39,0.00069,0.00019
9,0.75,11587.54,0.0007,0.00019
9.2,0.767,11952.35,0.00071,0.0002
9.4,0.784,12094.62,0.00073,0.0002
9.6,0.8,12446.17,0.00075,0.0002
9.8,0.817,12665.16,0.00076,0.00021
10,0.834,12925.58,0.00077,0.00021
10.2,0.85,13172.8,0.00079,0.00021
10.4,0.867,13503.71,0.0008,0.00022
10.6,0.883,13667.41,0.00082,0.00022
10.8,0.9,14036.24,0.00083,0.00023
11,0.917,14225.51,0.00085,0.00023
11.2,0.934,14518.97,0.00086,0.00023
11.4,0.95,14800.37,0.00088,0.00024
11.6,0.967,15081.37,0.00089,0.00024
11.8,0.984,15308.36,0.00091,0.00025
12,1,15599.89,0.00092,0.00025
12.2,1.017,15875.71,0.00094,0.00025
12.4,1.034,16159.71,0.00096,0.00026
12.6,1.05,16435.15,0.00097,0.00026
12.8,1.067,16662.76,0.00098,0.00027
13,1.084,16982.26,0.001,0.00028
13.2,1.1,17250.08,0.00102,0.00028
13.4,1.117,17588.3,0.00104,0.00029
13.6,1.134,17797.46,0.00105,0.00029
13.8,1.15,18150.37,0.00107,0.0003
14,1.167,18375.15,0.00109,0.0003
14.2,1.183,18695.9,0.00111,0.00031
14.4,1.2,18978.01,0.00113,0.00031
14.6,1.217,19208.26,0.00114,0.00032
14.8,1.233,19571.87,0.00116,0.00032
15,1.25,19750.33,0.00118,0.00033
15.2,1.267,20102.67,0.0012,0.00034
15.4,1.284,20379.17,0.00123,0.00035
15.6,1.3,20674.33,0.00125,0.00036
15.8,1.317,20959.64,0.00128,0.00037
16,1.334,21224.73,0.0013,0.00037
16.2,1.35,21486.18,0.00132,0.00038
16.4,1.367,21843.69,0.00135,0.00039
16.6,1.384,22030.88,0.00138,0.0004
16.8,1.4,22335.04,0.00141,0.00042
17,1.417,22630.92,0.00145,0.00043
17.2,1.434,22833.43,0.00148,0.00044
17.4,1.45,23182.71,0.00152,0.00046
17.6,1.467,23347.81,0.00156,0.00047
17.8,1.484,23647.61,0.0016,0.00049
18,1.5,23903.83,0.00164,0.0005
18.2,1.517,24111.17,0.0017,0.00052
18.4,1.534,24344.63,0.00175,0.00053
18.6,1.55,24599.79,0.00181,0.00055
18.8,1.567,24831.47,0.00187,0.00057
19,1.584,24904,0.00194,0.00059
19.2,1.6,25145.27,0.002,0.00061
19.4,1.617,25360.7,0.00208,0.00063
19.6,1.634,25423.35,0.00215,0.00065
19.8,1.65,25477.28,0.00223,0.00067
20,1.667,25489.16,0.0023,0.00067
20.2,1.684,25469.79,0.00237,0.00066
20.4,1.7,25464.35,0.00243,0.00065
20.6,1.717,25464.31,0.0025,0.00063
20.8,1.733,25457.28,0.00257,0.00062
21,1.75,25433.05,0.00263,0.0006
21.2,1.767,25398.86,0.00273,0.00058
21.4,1.784,25387.44,0.00286,0.00056
21.6,1.8,25404.87,0.00301,0.00055
21.8,1.817,25431.16,0.00319,0.00055
22,1.834,25461.92,0.00339,0.00055
22.2,1.85,25511.26,0.00359,0.00056
22.4,1.867,25576.99,0.00379,0.00058
22.6,1.884,25686.89,0.00401,0.00059
22.8,1.9,25714.6,0.00428,0.0006
23,1.917,25710.46,0.00463,0.00061
23.2,1.934,25693.46,0.00506,0.00062
23.4,1.95,25632.24,0.00554,0.00065
23.6,1.967,25555.8,0.00605,0.00069
23.8,1.984,25499.74,0.00654,0.00082
24,2,25465.92,0.00702,0.00105
24.2,2.017,25435.99,0.00747,0.00131
24.4,2.034,25392.6,0.00789,0.00156
24.6,2.05,25276.72,0.00825,0.00177
24.8,2.067,25287.26,0.00858,0.00193
25,2.083,25355.99,0.00892,0.00208
25.2,2.1,25367.9,0.00926,0.00225
25.4,2.117,25370.92,0.00961,0.00246
25.6,2.134,25382,0.01001,0.00275
25.8,2.15,25378.48,0.01042,0.00314
26,2.167,25393.22,0.01086,0.00356
26.2,2.184,25406.12,0.01127,0.00396
26.4,2.2,25430.09,0.01164,0.00431
26.6,2.217,25453.31,0.01196,0.0046
26.8,2.234,25482.73,0.0122,0.00483
27,2.25,25511.56,0.01239,0.005
27.2,2.267,25542.61,0.01254,0.00513
27.4,2.283,25550.94,0.01265,0.00523
27.6,2.3,25567.72,0.01273,0.00531
27.8,2.317,25608.73,0.01281,0.00538
28,2.334,25706.3,0.0129,0.00545
28.2,2.35,25823.72,0.01302,0.00553
28.4,2.367,25911.05,0.01315,0.00562
28.6,2.384,25986.43,0.0133,0.00572
28.8,2.4,26086.87,0.01347,0.00582
29,2.417,26145.77,0.01365,0.00592
29.2,2.434,26226.21,0.01384,0.00603
29.4,2.45,26278.12,0.01403,0.00613
29.6,2.467,26367.18,0.01422,0.00623
29.8,2.484,26393.57,0.0144,0.00633
30,2.5,26409.71,0.01458,0.00643
30.2,2.517,26439.92,0.01476,0.00652
30.4,2.534,26527.74,0.01495,0.00661
30.6,2.55,26615.54,0.01512,0.0067
30.8,2.567,26703.41,0.01531,0.00679
31,2.584,26766.25,0.01549,0.00689
31.2,2.6,26848.13,0.01567,0.00698
31.4,2.617,26897.82,0.01585,0.00707
31.6,2.634,26917.88,0.01603,0.00716
31.8,2.65,26947.64,0.01621,0.00725
32,2.667,26980.66,0.01638,0.00734
32.2,2.684,27081.37,0.01656,0.00743
32.4,2.7,27125.57,0.01675,0.00752
32.6,2.717,27190.47,0.01693,0.00762
32.8,2.734,27245.68,0.01711,0.00771
33,2.75,27304.89,0.01729,0.0078
33.2,2.767,27411.74,0.01746,0.00789
33.4,2.784,27468.63,0.01764,0.00798
33.6,2.8,27479.83,0.01782,0.00807
33.8,2.817,27503.02,0.01801,0.00816
34,2.834,27541.51,0.01819,0.00825
34.2,2.85,27616.58,0.01837,0.00835
34.4,2.867,27671.99,0.01855,0.00844
34.6,2.884,27766.52,0.01873,0.00853
34.8,2.9,27826.67,0.01892,0.00863
35,2.917,27900.93,0.0191,0.00872
35.2,2.934,27939.14,0.01929,0.00882
35.4,2.95,27960.37,0.01946,0.00891
35.6,2.967,27975.67,0.01965,0.00901
35.8,2.983,28003.8,0.01984,0.0091
36,3,28111.98,0.02002,0.00919
36.2,3.017,28176.87,0.02021,0.00929
36.4,3.033,28219.05,0.0204,0.00938
36.6,3.05,28279.72,0.02058,0.00948
36.8,3.067,28324.43,0.02077,0.00957
37,3.084,28382.46,0.02096,0.00967
37.2,3.1,28435.59,0.02115,0.00977
37.4,3.117,28492.82,0.02133,0.00986
37.6,3.134,28527.49,0.02152,0.00996
37.8,3.15,28545.21,0.02171,0.01006
38,3.167,28600.38,0.0219,0.01015
38.2,3.184,28663.65,0.02209,0.01025
38.4,3.2,28702.67,0.02228,0.01034
38.6,3.217,28768.84,0.02247,0.01043
38.8,3.234,28831.65,0.02266,0.01052
39,3.25,28916.21,0.02285,0.01062
39.2,3.267,28965.41,0.02304,0.01071
39.4,3.284,28978.8,0.02323,0.0108
39.6,3.3,28991.46,0.02342,0.0109
39.8,3.317,29013.78,0.02361,0.011
40,3.334,29052.88,0.0238,0.01109
40.2,3.35,29125.82,0.02399,0.01118
40.4,3.367,29189.84,0.02419,0.01127
40.6,3.384,29243.09,0.02437,0.01137
40.8,3.4,29301.08,0.02456,0.01146
41,3.417,29354.52,0.02475,0.01155
41.2,3.433,29410.8,0.02495,0.01165
41.4,3.45,29461.71,0.02514,0.01174
41.6,3.467,29478.88,0.02533,0.01184
41.8,3.484,29503.42,0.02552,0.01193
42,3.5,29529.93,0.02571,0.01203
42.2,3.517,29556.62,0.0259,0.01213
42.4,3.534,29609.28,0.0261,0.01222
42.6,3.55,29663.84,0.0263,0.01232
42.8,3.567,29703.29,0.02649,0.0124
43,3.584,29744.71,0.02667,0.0125
43.2,3.6,29795.72,0.02686,0.01259
43.4,3.617,29848.18,0.02706,0.01269
43.6,3.634,29934.52,0.02726,0.01278
43.8,3.65,29994.4,0.02745,0.01288
44,3.667,30034.97,0.02765,0.01297
44.2,3.684,30057.28,0.02784,0.01307
44.4,3.7,30077.47,0.02803,0.01316
44.6,3.717,30091.59,0.02823,0.01325
44.8,3.734,30128.9,0.02842,0.01335
45,3.75,30187.82,0.02862,0.01345
45.2,3.767,30240.52,0.02882,0.01355
45.4,3.784,30270.93,0.02902,0.01364
45.6,3.8,30327.92,0.02922,0.01374
45.8,3.817,30354.53,0.02942,0.01383
46,3.834,30393.18,0.02961,0.01393
46.2,3.85,30441.78,0.0298,0.01402
46.4,3.867,30479.94,0.03,0.01412
46.6,3.883,30501.98,0.0302,0.01422
46.8,3.9,30533.21,0.0304,0.01431
47,3.917,30565.84,0.0306,0.01442
47.2,3.933,30585.63,0.03079,0.01451
47.4,3.95,30628.16,0.03099,0.01461
47.6,3.967,30685.1,0.03119,0.01471
47.8,3.984,30753.69,0.03139,0.01481
48,4,30797.55,0.03159,0.01491
48.2,4.017,30844.11,0.03179,0.01501
48.4,4.034,30876.55,0.03199,0.01511
48.6,4.05,30910.56,0.03219,0.0152
48.8,4.067,30969.81,0.03239,0.0153
49,4.084,31006.43,0.03259,0.0154
49.2,4.1,31023.34,0.03278,0.0155
49.4,4.117,31029.3,0.03298,0.0156
49.6,4.134,31038.62,0.03319,0.01571
49.8,4.15,31051.23,0.03339,0.0158
50,4.167,31072.81,0.03359,0.01591
50.2,4.184,31109.07,0.03379,0.016
50.4,4.2,31161.32,0.03399,0.0161
50.6,4.217,31196.79,0.0342,0.01621
50.8,4.234,31241.01,0.0344,0.01631
51,4.25,31299.81,0.0346,0.01641
51.2,4.267,31353.94,0.0348,0.01651
51.4,4.284,31388.88,0.03501,0.01661
51.6,4.3,31433.68,0.03521,0.01671
51.8,4.317,31495.27,0.03541,0.01681
52,4.334,31553.82,0.03561,0.01692
52.2,4.35,31583.62,0.03581,0.01701
52.4,4.367,31596.09,0.03602,0.01711
52.6,4.384,31611.51,0.03622,0.01722
52.8,4.4,31635.73,0.03643,0.01732
53,4.417,31656.7,0.03663,0.01742
53.2,4.434,31667.27,0.03684,0.01753
53.4,4.45,31696.21,0.03704,0.01763
53.6,4.467,31726.13,0.03725,0.01772
53.8,4.484,31757.78,0.03746,0.01782
54,4.5,31779.47,0.03766,0.01793
54.2,4.517,31824.43,0.03786,0.01803
54.4,4.534,31852.43,0.03807,0.01813
54.6,4.55,31881.36,0.03828,0.01823
54.8,4.567,31923.68,0.03849,0.01833
55,4.584,31993.54,0.03869,0.01843
55.2,4.6,32029.33,0.03889,0.01853
55.4,4.617,32057.94,0.0391,0.01863
55.6,4.634,32073.21,0.03931,0.01873
55.8,4.65,32087.5,0.03952,0.01884
56,4.667,32108,0.03972,0.01894
56.2,4.684,32128.13,0.03993,0.01904
56.4,4.7,32156.15,0.04014,0.01914
56.6,4.717,32195.84,0.04035,0.01924
56.8,4.734,32244.08,0.04055,0.01934
57,4.75,32287.1,0.04075,0.01944
57.2,4.767,32317.52,0.04096,0.01955
57.4,4.784,32336.69,0.04117,0.01965
57.6,4.8,32379.35,0.04138,0.01975
57.8,4.817,32416.19,0.04158,0.01985
58,4.834,32444.76,0.04178,0.01995
58.2,4.85,32460.91,0.04199,0.02006
58.4,4.867,32483.64,0.0422,0.02016
58.6,4.883,32513.43,0.04242,0.02026
58.8,4.9,32533.02,0.04263,0.02036
59,4.917,32540.37,0.04284,0.02046
59.2,4.934,32549.02,0.04305,0.02056
59.4,4.95,32558.04,0.04326,0.02067
59.6,4.967,32577.69,0.04347,0.02077
59.8,4.984,32588.97,0.04368,0.02087
60,5,32607.19,0.04389,0.02097
60.2,5.017,32633.79,0.0441,0.02107
60.4,5.034,32681.86,0.04432,0.02117
60.6,5.05,32727.75,0.04453,0.02127
60.8,5.067,32781.87,0.04474,0.02138
61,5.084,32807.08,0.04495,0.02148
61.2,5.1,32829.98,0.04516,0.02158
61.4,5.117,32869.67,0.04538,0.02168
61.6,5.133,32905.22,0.0456,0.02179
61.8,5.15,32937.33,0.04581,0.02189
62,5.167,32960.48,0.04602,0.02198
62.2,5.184,32989.79,0.04622,0.02209
62.4,5.2,33055.32,0.04644,0.02219
62.6,5.217,33108.98,0.04665,0.02229
62.8,5.233,33129.37,0.04686,0.02239
63,5.25,33146.37,0.04708,0.02249
63.2,5.267,33151.05,0.04731,0.0226
63.4,5.284,33152,0.04752,0.0227
63.6,5.3,33153.08,0.04774,0.0228
63.8,5.317,33153.17,0.04795,0.0229
64,5.334,33153.54,0.04817,0.02301
64.2,5.35,33157.48,0.0484,0.02311
64.4,5.367,33169.23,0.04861,0.02321
64.6,5.384,33198.26,0.04883,0.02331
64.8,5.4,33227.64,0.04904,0.02342
65,5.417,33241.93,0.04926,0.02352
65.2,5.434,33272.95,0.04948,0.02363
65.4,5.45,33294.34,0.0497,0.02373
65.6,5.467,33351.29,0.04991,0.02383
65.8,5.484,33390.06,0.05013,0.02394
66,5.5,33414.76,0.05035,0.02404
66.2,5.517,33441.73,0.05057,0.02415
66.4,5.534,33451.66,0.05079,0.02425
66.6,5.55,33485.92,0.05101,0.02435
66.8,5.567,33522.56,0.05123,0.02446
67,5.584,33558.66,0.05145,0.02456
67.2,5.6,33584.14,0.05167,0.02467
67.4,5.617,33607.99,0.05188,0.02477
67.6,5.633,33622.83,0.0521,0.02487
67.8,5.65,33639.93,0.05231,0.02497
68,5.667,33651.27,0.05254,0.02508
68.2,5.684,33665.45,0.05276,0.02518
68.4,5.7,33674.35,0.05297,0.02528
68.6,5.717,33690.63,0.05319,0.02539
68.8,5.734,33705.61,0.05342,0.0255
69,5.75,33738.08,0.05364,0.0256
69.2,5.767,33753.19,0.05386,0.0257
69.4,5.784,33802.28,0.05408,0.0258
69.6,5.8,33832.09,0.0543,0.02591
69.8,5.817,33863.75,0.05452,0.02601
70,5.833,33871.13,0.05475,0.02611
70.2,5.85,33882.84,0.05497,0.02622
70.4,5.867,33897.67,0.0552,0.02632
70.6,5.884,33920.5,0.05542,0.02642
70.8,5.9,33931.69,0.05564,0.02652
71,5.917,33942.85,0.05586,0.02663
71.2,5.934,33953.64,0.05608,0.02673
71.4,5.95,33959.39,0.05631,0.02683
71.6,5.967,33981.21,0.05654,0.02694
71.8,5.984,34008.68,0.05677,0.02704
72,6,34023.27,0.05698,0.02714
72.2,6.017,34044.26,0.05721,0.02725
72.4,6.034,34057.32,0.05743,0.02735
72.6,6.05,34067.02,0.05766,0.02745
72.8,6.067,34091.81,0.05788,0.02756
73,6.084,34105.94,0.05811,0.02766
73.2,6.1,34134.05,0.05833,0.02776
73.4,6.117,34150.03,0.05855,0.02787
73.6,6.133,34159.02,0.05878,0.02797
73.8,6.15,34174.56,0.05901,0.02808
74,6.167,34183.76,0.05924,0.02819
74.2,6.183,34195.22,0.05946,0.02829
74.4,6.2,34229.75,0.05969,0.02839
74.6,6.217,34244.78,0.05992,0.0285
74.8,6.234,34282.24,0.06014,0.0286
75,6.25,34307.77,0.06036,0.0287
75.2,6.267,34327.14,0.06059,0.02881
75.4,6.284,34346.6,0.06082,0.02891
75.6,6.3,34363.52,0.06104,0.02902
75.8,6.317,34385.36,0.06127,0.02912
76,6.334,34411.16,0.0615,0.02922
76.2,6.35,34445.73,0.06172,0.02933
76.4,6.367,34492.66,0.06196,0.02943
76.6,6.384,34509.54,0.06219,0.02954
76.8,6.4,34524.68,0.06241,0.02964
77,6.417,34547.91,0.06264,0.02975
77.2,6.434,34572.82,0.06287,0.02985
77.4,6.45,34595.11,0.06309,0.02996
77.6,6.467,34613.38,0.06332,0.03006
77.8,6.484,34626.52,0.06355,0.03017
78,6.5,34640.45,0.06378,0.03028
78.2,6.517,34652.1,0.06401,0.03038
78.4,6.534,34653.78,0.06424,0.03048
78.6,6.55,34655.02,0.06447,0.03059
78.8,6.567,34654.92,0.0647,0.0307
79,6.584,34655.05,0.06494,0.03081
79.2,6.6,34655,0.06517,0.03092
79.4,6.617,34655.38,0.0654,0.03102
79.6,6.634,34656.35,0.06563,0.03113
79.8,6.65,34655.72,0.06586,0.03124
80,6.667,34657.93,0.06609,0.03134
80.2,6.684,34661.25,0.06632,0.03145
80.4,6.7,34666.77,0.06655,0.03156
80.6,6.717,34694.55,0.06679,0.03166
80.8,6.733,34713.13,0.06702,0.03177
81,6.75,34734.82,0.06725,0.03188
81.2,6.767,34763.27,0.06748,0.03199
81.4,6.784,34787.29,0.06772,0.0321
81.6,6.8,34806.38,0.06795,0.03221
81.8,6.817,34822.69,0.06818,0.03232
82,6.833,34846.39,0.06841,0.03242
82.2,6.85,34861.07,0.06865,0.03253
82.4,6.867,34873.22,0.06889,0.03264
82.6,6.884,34900.19,0.06912,0.03275
82.8,6.9,34917.3,0.06935,0.03285
83,6.917,34945.22,0.06959,0.03296
83.2,6.933,34951.27,0.06982,0.03307
83.4,6.95,34976.55,0.07006,0.03317
83.6,6.967,34988.39,0.07029,0.03328
83.8,6.983,35000.99,0.07052,0.03339
84,7,35030.62,0.07076,0.0335
84.2,7.017,35048.09,0.071,0.03361
84.4,7.034,35068.06,0.07123,0.03371
84.6,7.05,35101.05,0.07147,0.03382
84.8,7.067,35121.56,0.07171,0.03393
85,7.084,35142.47,0.07194,0.03404
85.2,7.1,35145.43,0.07217,0.03414
85.4,7.117,35154.06,0.07241,0.03425
85.6,7.134,35162.62,0.07264,0.03436
85.8,7.15,35166.44,0.07289,0.03447
86,7.167,35176.38,0.07312,0.03458
86.2,7.184,35185.74,0.07336,0.03469
86.4,7.2,35194.41,0.0736,0.03479
86.6,7.217,35210.68,0.07383,0.0349
86.8,7.234,35219.12,0.07407,0.03501
87,7.25,35227.88,0.07431,0.03512
87.2,7.267,35247.06,0.07456,0.03523
87.4,7.284,35254.77,0.07479,0.03533
87.6,7.3,35259.45,0.07503,0.03544
87.8,7.317,35268.75,0.07527,0.03555
88,7.334,35273.68,0.07551,0.03566
88.2,7.35,35284.28,0.07575,0.03576
88.4,7.367,35289.38,0.07599,0.03587
88.6,7.384,35312.05,0.07623,0.03598
88.8,7.4,35332.61,0.07647,0.03609
89,7.417,35337.33,0.0767,0.0362
89.2,7.434,35354.56,0.07695,0.0363
89.4,7.45,35363.38,0.07718,0.03641
89.6,7.467,35367.53,0.07743,0.03652
89.8,7.484,35372.17,0.07767,0.03663
90,7.5,35373.54,0.07791,0.03674
90.2,7.517,35380.52,0.07815,0.03684
90.4,7.534,35390.6,0.07839,0.03695
90.6,7.55,35397.18,0.07863,0.03706
90.8,7.567,35410.06,0.07888,0.03717
91,7.584,35418.89,0.07912,0.03727
91.2,7.6,35430.92,0.07936,0.03738
91.4,7.617,35437.72,0.0796,0.03749
91.6,7.634,35452.93,0.07985,0.0376
91.8,7.65,35454.89,0.0801,0.03771
92,7.667,35461.99,0.08035,0.03781
92.2,7.684,35473.32,0.08059,0.03792
92.4,7.7,35484.44,0.08083,0.03803
92.6,7.717,35512.61,0.08108,0.03814
92.8,7.733,35515.96,0.08132,0.03824
93,7.75,35547.29,0.08156,0.03835
93.2,7.767,35556.17,0.08181,0.03845
93.4,7.783,35586.1,0.08205,0.03856
93.6,7.8,35607.85,0.08229,0.03867
93.8,7.817,35624.25,0.08254,0.03877
94,7.833,35625.73,0.08278,0.03888
94.2,7.85,35643.02,0.08303,0.03899
94.4,7.867,35649.43,0.08328,0.0391
94.6,7.883,35661.19,0.08352,0.0392
94.8,7.9,35668.73,0.08376,0.03931
95,7.917,35674.84,0.08401,0.03942
95.2,7.934,35682.99,0.08425,0.03953
95.4,7.95,35685.96,0.08449,0.03963
95.6,7.967,35692.9,0.08474,0.03974
95.8,7.984,35702.43,0.08499,0.03985
96,8,35703.47,0.08523,0.03996
96.2,8.017,35706.7,0.08547,0.04006
96.4,8.034,35715.26,0.08572,0.04017
96.6,8.05,35720.4,0.08597,0.04028
96.8,8.067,35727.88,0.08621,0.04039
97,8.084,35734.31,0.08646,0.0405
97.2,8.1,35740.5,0.0867,0.04061
97.4,8.117,35754.82,0.08695,0.04072
97.6,8.134,35755.39,0.08719,0.04082
97.8,8.15,35763.88,0.08744,0.04093
98,8.167,35780.11,0.08768,0.04104
98.2,8.184,35789.76,0.08792,0.04115
98.4,8.2,35810.98,0.08816,0.04125
98.6,8.217,35835.94,0.08841,0.04136
98.8,8.233,35852.93,0.08865,0.04147
99,8.25,35874.3,0.0889,0.04158
99.2,8.267,35888.9,0.08915,0.04168
99.4,8.284,35901.64,0.08939,0.04179
99.6,8.3,35912.54,0.08964,0.0419
99.8,8.317,35923.14,0.08989,0.042
100,8.333,35934.12,0.09014,0.04211
100.2,8.35,35943.66,0.09039,0.04222
100.4,8.367,35949.52,0.09064,0.04233
100.6,8.384,35953.29,0.09089,0.04243
100.8,8.4,35970.01,0.09114,0.04253
101,8.417,35975.44,0.09138,0.04263
101.2,8.434,35994.08,0.09163,0.04274
101.4,8.45,36001,0.09188,0.04285
101.6,8.467,36009.13,0.09214,0.04295
101.8,8.484,36027.03,0.09239,0.04306
102,8.5,36031.83,0.09263,0.04316
102.2,8.517,36046.5,0.09289,0.04326
102.4,8.534,36047.35,0.09314,0.04337
102.6,8.55,36058.61,0.09339,0.04348
102.8,8.567,36053.51,0.09364,0.04358
103,8.584,36064.68,0.09389,0.04369
103.2,8.6,36070.99,0.09414,0.04379
103.4,8.617,36078.36,0.09439,0.0439
103.6,8.634,36082.59,0.09463,0.04401
103.8,8.65,36100.81,0.09488,0.04411
104,8.667,36104.8,0.09514,0.04422
104.2,8.684,36111.02,0.09539,0.04433
104.4,8.7,36133.83,0.09564,0.04443
104.6,8.717,36139.38,0.09589,0.04454
104.8,8.734,36140.89,0.09614,0.04465
105,8.75,36148.51,0.0964,0.04476
105.2,8.767,36149.47,0.09664,0.04487
105.4,8.784,36153.2,0.0969,0.04498
105.6,8.8,36154.2,0.09715,0.04509
105.8,8.817,36154.62,0.09739,0.0452
106,8.834,36155.96,0.09765,0.04531
106.2,8.85,36158.84,0.0979,0.04543
106.4,8.867,36159.74,0.09815,0.04554
106.6,8.884,36163.66,0.0984,0.04565
106.8,8.9,36167.07,0.09865,0.04576
107,8.917,36172.6,0.0989,0.04588
107.2,8.934,36170.12,0.09916,0.04599
107.4,8.95,36176.24,0.09942,0.04611
107.6,8.967,36176.46,0.09967,0.04622
107.8,8.984,36189.45,0.09992,0.04634
108,9,36185.23,0.10017,0.04645
108.2,9.017,36193.2,0.10043,0.04657
108.4,9.034,36191.76,0.10068,0.04668
108.6,9.05,36198.34,0.10093,0.04679
108.8,9.067,36202.53,0.10118,0.0469
109,9.084,36205.7,0.10144,0.04702
109.2,9.1,36208.17,0.10169,0.04713
109.4,9.117,36208.8,0.10195,0.04724
109.6,9.134,36212.62,0.1022,0.04735
109.8,9.15,36217.99,0.10246,0.04746
110,9.167,36217.88,0.10271,0.04758
110.2,9.184,36219.42,0.10297,0.04769
110.4,9.2,36226.73,0.10322,0.0478
110.6,9.217,36231.77,0.10348,0.04791
110.8,9.234,36238.56,0.10373,0.04802
111,9.25,36247.26,0.10398,0.04813
111.2,9.267,36253.68,0.10424,0.04824
111.4,9.284,36269.65,0.1045,0.04835
111.6,9.3,36276.85,0.10475,0.04846
111.8,9.317,36285.66,0.10501,0.04857
112,9.334,36310.23,0.10526,0.04868
112.2,9.35,36315.96,0.10552,0.04879
112.4,9.367,36333.64,0.10578,0.0489
112.6,9.384,36325.74,0.10604,0.04902
112.8,9.4,36344,0.1063,0.04913
113,9.417,36363.63,0.10656,0.04924
113.2,9.433,36362.39,0.10681,0.04935
113.4,9.45,36370.21,0.10708,0.04947
113.6,9.467,36374.38,0.10734,0.04958
113.8,9.484,36381.08,0.1076,0.04969
114,9.5,36397.68,0.10786,0.0498
114.2,9.517,36402.31,0.10814,0.04992
114.4,9.534,36405.11,0.10841,0.05003
114.6,9.55,36412.9,0.10869,0.05014
114.8,9.567,36420.57,0.10896,0.05026
115,9.583,36428.15,0.10925,0.05037
115.2,9.6,36433.79,0.10952,0.05048
115.4,9.617,36441.82,0.10979,0.0506
115.6,9.634,36446.57,0.11006,0.05071
115.8,9.65,36458.16,0.11033,0.05082
116,9.667,36457.28,0.1106,0.05093
116.2,9.684,36477.45,0.11086,0.05104
116.4,9.7,36478.88,0.11113,0.05116
116.6,9.717,36489.17,0.11139,0.05128
116.8,9.734,36495.62,0.11166,0.05139
117,9.75,36511.3,0.11193,0.0515
117.2,9.767,36508.98,0.1122,0.05161
117.4,9.784,36519.96,0.11246,0.05173
117.6,9.8,36517.51,0.11273,0.05184
117.8,9.817,36527.71,0.11299,0.05196
118,9.834,36526.86,0.11327,0.05207
118.2,9.85,36541.28,0.11354,0.05219
118.4,9.867,36543.88,0.11381,0.0523
118.6,9.884,36542.77,0.11407,0.05241
118.8,9.9,36548.7,0.11434,0.05253
119,9.917,36556.19,0.11461,0.05263
119.2,9.934,36559.76,0.11487,0.05274
119.4,9.95,36572.54,0.11514,0.05286
119.6,9.967,36575,0.11541,0.05297
119.8,9.983,36576.47,0.11567,0.05308
120,10,36594.75,0.11594,0.05319
120.2,10.017,36586.79,0.1162,0.0533
120.4,10.033,36603.89,0.11647,0.05342
120.6,10.05,36614.73,0.11674,0.05353
120.8,10.067,36621.02,0.11701,0.05365
121,10.084,36624.91,0.11727,0.05376
121.2,10.1,36627.92,0.11754,0.05387
121.4,10.117,36639.83,0.11781,0.05399
121.6,10.134,36650.5,0.11807,0.0541
121.8,10.15,36659.43,0.11834,0.05421
122,10.167,36664.53,0.11861,0.05432
122.2,10.184,36678.5,0.11887,0.05443
122.4,10.2,36679.54,0.11914,0.05454
122.6,10.217,36692.3,0.11941,0.05465
122.8,10.234,36691.62,0.11968,0.05477
123,10.25,36696.9,0.11995,0.05488
123.2,10.267,36698.64,0.12021,0.05499
123.4,10.284,36705.45,0.12049,0.05511
123.6,10.3,36711.21,0.12075,0.05522
123.8,10.317,36710.12,0.12102,0.05533
124,10.334,36713.3,0.12129,0.05545
124.2,10.35,36716.19,0.12156,0.05556
124.4,10.367,36715.14,0.12183,0.05567
124.6,10.384,36715.24,0.1221,0.05579
124.8,10.4,36721.3,0.12237,0.0559
125,10.417,36721.67,0.12264,0.05601
125.2,10.434,36723.13,0.12291,0.05612
125.4,10.45,36723.54,0.12318,0.05624
125.6,10.467,36727.41,0.12345,0.05635
125.8,10.483,36728.09,0.12373,0.05646
126,10.5,36730.86,0.124,0.05658
126.2,10.517,36728.66,0.12427,0.05669
126.4,10.534,36734.53,0.12454,0.0568
126.6,10.55,36735.02,0.12481,0.05691
126.8,10.567,36737.23,0.12508,0.05702
127,10.584,36737.67,0.12535,0.05714
127.2,10.6,36739.5,0.12562,0.05725
127.4,10.617,36736.53,0.12589,0.05737
127.6,10.634,36745.63,0.12616,0.05749
127.8,10.65,36746.62,0.12643,0.05761
128,10.667,36745.7,0.1267,0.05773
128.2,10.684,36747.92,0.12698,0.05785
128.4,10.7,36753.21,0.12724,0.05797
128.6,10.717,36755.63,0.12752,0.05808
128.8,10.734,36749.37,0.12779,0.0582
129,10.75,36751.13,0.12806,0.05831
129.2,10.767,36758.73,0.12834,0.05842
129.4,10.784,36756.7,0.12862,0.05853
129.6,10.8,36758.58,0.12889,0.05865
129.8,10.817,36760.56,0.12916,0.05876
130,10.834,36761.64,0.12944,0.05887
130.2,10.85,36764.45,0.12971,0.05899
130.4,10.867,36759.91,0.12999,0.05911
130.6,10.884,36765.44,0.13026,0.05922
130.8,10.9,36766.6,0.13054,0.05933
131,10.917,36765.42,0.13082,0.05945
131.2,10.933,36766.27,0.13109,0.05956
131.4,10.95,36767.28,0.13137,0.05967
131.6,10.967,36767.56,0.13165,0.05978
131.8,10.984,36768.16,0.13192,0.0599
132,11,36769.64,0.1322,0.06001
132.2,11.017,36771.15,0.13247,0.06012
132.4,11.034,36772.48,0.13275,0.06024
132.6,11.05,36771.29,0.13302,0.06035
132.8,11.067,36772.81,0.1333,0.06046
133,11.084,36773.12,0.13358,0.06058
133.2,11.1,36773.41,0.13386,0.06069
133.4,11.117,36775.28,0.13414,0.06081
133.6,11.134,36780.78,0.13442,0.06092
133.8,11.15,36777.48,0.1347,0.06103
134,11.167,36779.85,0.13498,0.06115
134.2,11.184,36779.52,0.13525,0.06126
134.4,11.2,36785.58,0.13554,0.06138
134.6,11.217,36784.3,0.13582,0.0615
134.8,11.233,36793.04,0.13609,0.06161
135,11.25,36790.68,0.13638,0.06173
135.2,11.267,36789.56,0.13666,0.06184
135.4,11.284,36791.87,0.13694,0.06196
135.6,11.3,36808.66,0.13722,0.06208
135.8,11.317,36806.13,0.1375,0.0622
136,11.334,36801.75,0.13778,0.06232
136.2,11.35,36809.88,0.13807,0.06244
136.4,11.367,36814.16,0.13835,0.06255
136.6,11.384,36812.84,0.13863,0.06267
136.8,11.4,36827.94,0.13891,0.06278
137,11.417,36821.25,0.1392,0.0629
137.2,11.434,36822.14,0.13948,0.06302
137.4,11.45,36830.89,0.13976,0.06313
137.6,11.467,36822.77,0.14004,0.06325
137.8,11.484,36844.09,0.14032,0.06336
138,11.5,36834.09,0.14062,0.06348
138.2,11.517,36839.18,0.1409,0.0636
138.4,11.534,36845.66,0.14118,0.06371
138.6,11.55,36849,0.14147,0.06383
138.8,11.567,36853.88,0.14175,0.06395
139,11.584,36856.84,0.14204,0.06407
139.2,11.6,36854.45,0.14232,0.06419
139.4,11.617,36854.45,0.14261,0.0643
139.6,11.634,36863.06,0.14289,0.06442
139.8,11.65,36862.04,0.14317,0.06454
140,11.667,36871.46,0.14346,0.06466
140.2,11.683,36867.25,0.14374,0.06478
140.4,11.7,36876.16,0.14403,0.0649
140.6,11.717,36873.07,0.14432,0.06501
140.8,11.733,36878.29,0.1446,0.06513
141,11.75,36884.18,0.14489,0.06525
141.2,11.767,36879.28,0.14518,0.06536
141.4,11.784,36881.47,0.14546,0.06548
141.6,11.8,36886.44,0.14575,0.06559
141.8,11.817,36883.42,0.14604,0.06571
142,11.834,36899.33,0.14633,0.06582
142.2,11.85,36889.23,0.14662,0.06594
142.4,11.867,36896.19,0.14691,0.06605
142.6,11.884,36890.32,0.1472,0.06617
142.8,11.9,36893.8,0.14748,0.06628
143,11.917,36900.57,0.14778,0.0664
143.2,11.934,36900.46,0.14806,0.06652
143.4,11.95,36903.77,0.14835,0.06664
143.6,11.967,36901.57,0.14865,0.06674
143.8,11.984,36906.64,0.14893,0.06686
144,12,36909.21,0.14922,0.06699
144.2,12.017,36910.61,0.14951,0.06712
144.4,12.034,36910.59,0.14979,0.06725
144.6,12.05,36916.95,0.15008,0.06737
144.8,12.067,36918.75,0.15038,0.06749
145,12.084,36916.93,0.15066,0.06762
145.2,12.1,36918.73,0.15096,0.06774
145.4,12.117,36928.61,0.15125,0.06786
145.6,12.134,36922.02,0.15154,0.06798
145.8,12.15,36931.73,0.15183,0.0681
146,12.167,36940,0.15213,0.06822
146.2,12.183,36938.39,0.15242,0.06834
146.4,12.2,36933.82,0.15272,0.06846
146.6,12.217,36937.25,0.15302,0.06858
146.8,12.234,36938.05,0.1533,0.06869
147,12.25,36941.31,0.1536,0.06881
147.2,12.267,36943.45,0.15389,0.06893
147.4,12.284,36945.69,0.15419,0.06904
147.6,12.3,36951.61,0.15449,0.06916
147.8,12.317,36937.57,0.15478,0.06928
148,12.334,36958.81,0.15508,0.06939
148.2,12.35,36953.25,0.15537,0.06951
148.4,12.367,36955.81,0.15567,0.06963
148.6,12.384,36958.1,0.15597,0.06975
148.8,12.4,36954.32,0.15627,0.06987
149,12.417,36968.91,0.15656,0.06998
149.2,12.434,36975.17,0.15686,0.0701
149.4,12.45,36960.57,0.15716,0.07022
149.6,12.467,36969.29,0.15746,0.07035
149.8,12.484,36963.86,0.15776,0.07047
150,12.5,36974.35,0.15805,0.07058
150.2,12.517,36971.5,0.15835,0.07071
150.4,12.534,36973.1,0.15865,0.07082
150.6,12.55,36978.19,0.15895,0.07095
150.8,12.567,36975.16,0.15925,0.07107
151,12.584,36978.96,0.15955,0.07119
151.2,12.6,36988.37,0.15985,0.07131
151.4,12.617,36982.05,0.16015,0.07144
151.6,12.633,36983.93,0.16046,0.07156
151.8,12.65,36989.64,0.16076,0.07169
152,12.667,36985.02,0.16106,0.07181
152.2,12.684,36984.73,0.16136,0.07194
152.4,12.7,36990.43,0.16166,0.07207
152.6,12.717,36991.12,0.16196,0.07219
152.8,12.733,36992.86,0.16227,0.07232
153,12.75,36982.71,0.16257,0.07244
153.2,12.767,36994.09,0.16287,0.07257
153.4,12.783,36996.02,0.16317,0.07269
153.6,12.8,36996.16,0.16348,0.07281
153.8,12.817,37002.82,0.16379,0.07294
154,12.834,36997.41,0.16409,0.07306
154.2,12.85,36996.45,0.16439,0.07318
154.4,12.867,37006.1,0.1647,0.07329
154.6,12.884,36999,0.165,0.07341
154.8,12.9,37010.45,0.16532,0.07353
155,12.917,37005.36,0.16562,0.07365
155.2,12.934,37003.35,0.16592,0.07377
155.4,12.95,37002.61,0.16623,0.07389
155.6,12.967,37006.13,0.16654,0.074
155.8,12.983,37000.92,0.16685,0.07412
156,13,37012.15,0.16716,0.07425
156.2,13.017,37005.52,0.16746,0.07437
156.4,13.034,37008.06,0.16777,0.07449
156.6,13.05,37010.8,0.16808,0.07461
156.8,13.067,37012.15,0.1684,0.07474
157,13.084,37008.67,0.16869,0.07488
157.2,13.1,37011.85,0.16901,0.075
157.4,13.117,37010.48,0.16932,0.07514
157.6,13.134,37016.01,0.16962,0.07528
157.8,13.15,37012.41,0.16993,0.07541
158,13.167,37007.1,0.17025,0.07554
158.2,13.184,37012.38,0.17055,0.07566
158.4,13.2,37007.32,0.17086,0.07579
158.6,13.217,37009.52,0.17118,0.07592
158.8,13.234,37017.82,0.17149,0.07605
159,13.25,37013.5,0.1718,0.07617
159.2,13.267,37018.07,0.17212,0.0763
159.4,13.284,37012.16,0.17243,0.07643
159.6,13.3,37011.67,0.17275,0.07655
159.8,13.317,37012.13,0.17307,0.07668
160,13.334,37017.93,0.17338,0.0768
160.2,13.35,37012.96,0.1737,0.07693
160.4,13.367,37016.45,0.17401,0.07706
160.6,13.383,37009.57,0.17433,0.07718
160.8,13.4,37018.02,0.17464,0.07731
161,13.417,37013.72,0.17496,0.07743
161.2,13.434,37017.35,0.17528,0.07756
161.4,13.45,37019.73,0.1756,0.07769
161.6,13.467,37015.61,0.17591,0.07781
161.8,13.483,37016.1,0.17623,0.07794
162,13.5,37021.15,0.17655,0.07806
162.2,13.517,37015.48,0.17687,0.07818
162.4,13.534,37016.3,0.1772,0.0783
162.6,13.55,37010.16,0.17751,0.07842
162.8,13.567,37010.96,0.17783,0.07853
163,13.584,37013.55,0.17815,0.07866
163.2,13.6,37013.57,0.17847,0.07878
163.4,13.617,37016.99,0.1788,0.07891
163.6,13.634,37023.11,0.17912,0.07903
163.8,13.65,37015.86,0.17944,0.07916
164,13.667,37019.12,0.17977,0.07928
164.2,13.684,37017.38,0.1801,0.0794
164.4,13.7,37016.54,0.18042,0.07953
164.6,13.717,37019.98,0.18075,0.07965
164.8,13.734,37018.99,0.18107,0.07978
165,13.75,37011.7,0.1814,0.0799
165.2,13.767,37019.74,0.18173,0.08003
165.4,13.784,37017.62,0.18205,0.08016
165.6,13.8,37018.24,0.18237,0.08029
165.8,13.817,37016.12,0.18271,0.08043
166,13.834,37012.01,0.18304,0.08055
166.2,13.85,37021.41,0.18336,0.08068
166.4,13.867,37017.22,0.18369,0.08081
166.6,13.883,37017.07,0.18402,0.08095
166.8,13.9,37018.88,0.18436,0.08108
167,13.917,37013.74,0.18469,0.08122
167.2,13.933,37014.1,0.18502,0.08135
167.4,13.95,37015.5,0.18535,0.08147
167.6,13.967,37016.43,0.18569,0.08161
167.8,13.984,37014.61,0.18603,0.08175
168,14,37013.88,0.18636,0.08188
168.2,14.017,37016.88,0.1867,0.08202
168.4,14.034,37013.23,0.18703,0.08216
168.6,14.05,37019.12,0.18737,0.08229
168.8,14.067,37014.14,0.18771,0.08242
169,14.084,37013.33,0.18804,0.08256
169.2,14.1,37011.2,0.18839,0.0827
169.4,14.117,37014.21,0.18872,0.08284
169.6,14.134,37013.97,0.18907,0.08297
169.8,14.15,37008.51,0.1894,0.08311
170,14.167,37006.34,0.18974,0.08323
170.2,14.184,37009.7,0.19007,0.08336
170.4,14.2,37010.11,0.19042,0.08349
170.6,14.217,37015.41,0.19075,0.08361
170.8,14.234,37015.21,0.1911,0.08375
171,14.25,37013.36,0.19144,0.08389
171.2,14.267,37008.82,0.19178,0.08402
171.4,14.284,37007.16,0.19212,0.08415
171.6,14.3,37013.9,0.19246,0.08429
171.8,14.317,37012.12,0.19281,0.08443
172,14.334,37012.9,0.19316,0.08456
172.2,14.35,37012.36,0.19351,0.0847
172.4,14.367,37006.16,0.19387,0.08484
172.6,14.384,37004.46,0.19421,0.08498
172.8,14.4,37006.71,0.19456,0.08511
173,14.417,37004.92,0.19492,0.08524
173.2,14.433,37004.8,0.19527,0.08538
173.4,14.45,37005.36,0.19563,0.08552
173.6,14.467,37005.14,0.19598,0.08567
173.8,14.484,37007.46,0.19633,0.0858
174,14.5,37007.35,0.19669,0.08594
174.2,14.517,37001.87,0.19704,0.08608
174.4,14.534,37008.76,0.19739,0.08622
174.6,14.55,36999.32,0.19775,0.08636
174.8,14.567,37008.3,0.1981,0.0865
175,14.584,37000.16,0.19846,0.08664
175.2,14.6,37000.02,0.19881,0.08678
175.4,14.617,36993.45,0.19916,0.08692
175.6,14.634,36999.43,0.19952,0.08707
175.8,14.65,36995.52,0.19987,0.0872
176,14.667,36996.09,0.20022,0.08735
176.2,14.684,36994.19,0.20057,0.08749
176.4,14.7,36998.18,0.20093,0.08762
176.6,14.717,36989.24,0.20128,0.08777
176.8,14.734,36992.39,0.20164,0.08791
177,14.75,36993.68,0.20199,0.08804
177.2,14.767,36992.66,0.20235,0.08819
177.4,14.784,36988.05,0.20271,0.08833
177.6,14.8,36985.87,0.20306,0.08847
177.8,14.817,36986.97,0.20342,0.08861
178,14.834,36988.05,0.20378,0.08876
178.2,14.85,36981.64,0.20414,0.0889
178.4,14.867,36982.64,0.20449,0.08905
178.6,14.884,36979.74,0.20485,0.08919
178.8,14.9,36977.35,0.20521,0.08934
179,14.917,36979.46,0.20557,0.08949
179.2,14.934,36981.2,0.20594,0.08963
179.4,14.95,36979.46,0.2063,0.08977
179.6,14.967,36977.29,0.20666,0.08993
179.8,14.983,36969.48,0.20703,0.09007
180,15,36969.59,0.2074,0.09022
180.2,15.017,36969.49,0.20776,0.09037
180.4,15.034,36971.24,0.20813,0.09052
180.6,15.05,36961.95,0.2085,0.09066
180.8,15.067,36970.29,0.20886,0.09082
181,15.084,36965.52,0.20923,0.09097
181.2,15.1,36958.21,0.2096,0.09112
181.4,15.117,36961.16,0.20996,0.09127
181.6,15.134,36961.21,0.21032,0.09142
181.8,15.15,36955.54,0.21069,0.09158
182,15.167,36957.33,0.21107,0.09173
182.2,15.184,36953.35,0.21144,0.09187
182.4,15.2,36951.98,0.21182,0.09203
182.6,15.217,36942.81,0.21219,0.09218
182.8,15.234,36937.66,0.21257,0.09231
183,15.25,36942.92,0.21295,0.09246
183.2,15.267,36930.21,0.21333,0.09262
183.4,15.284,36937.07,0.2137,0.09276
183.6,15.3,36927.18,0.21408,0.09292
183.8,15.317,36926.07,0.21446,0.09308
184,15.334,36926.55,0.21484,0.09323
184.2,15.35,36923.53,0.21522,0.09338
184.4,15.367,36915.8,0.21559,0.09354
184.6,15.384,36934.32,0.21598,0.0937
184.8,15.4,36918,0.21636,0.09386
185,15.417,36923.57,0.21675,0.09401
185.2,15.434,36921.14,0.21713,0.09417
185.4,15.45,36917.06,0.21752,0.09432
185.6,15.467,36914.04,0.21791,0.09448
185.8,15.484,36917.31,0.21829,0.09464
186,15.5,36907.61,0.21868,0.0948
186.2,15.517,36908.62,0.21907,0.09496
186.4,15.534,36899.93,0.21946,0.09511
186.6,15.55,36904.11,0.21985,0.09527
186.8,15.567,36902.78,0.22025,0.09543
187,15.583,36897.27,0.22064,0.09559
187.2,15.6,36904.5,0.22104,0.09575
187.4,15.617,36892.48,0.22143,0.09591
187.6,15.634,36896.45,0.22182,0.09605
187.8,15.65,36895.96,0.22222,0.09621
188,15.667,36890.94,0.22262,0.09638
188.2,15.684,36890.05,0.22302,0.09654
188.4,15.7,36886.03,0.22341,0.0967
188.6,15.717,36882.48,0.22381,0.09687
188.8,15.734,36881,0.22421,0.09704
189,15.75,36876.76,0.22461,0.0972
189.2,15.767,36880.28,0.22501,0.09736
189.4,15.784,36875.05,0.22541,0.09753
189.6,15.8,36875.71,0.2258,0.09771
189.8,15.817,36872.34,0.22618,0.09787
190,15.834,36875.39,0.22657,0.09805
190.2,15.85,36868.33,0.22697,0.09821
190.4,15.867,36872.04,0.22738,0.09837
190.6,15.884,36863.54,0.22779,0.09854
190.8,15.9,36857.03,0.2282,0.09871
191,15.917,36863.67,0.22861,0.09887
191.2,15.934,36862.42,0.22902,0.09904
191.4,15.95,36854.06,0.22944,0.09921
191.6,15.967,36853.67,0.22985,0.09939
191.8,15.984,36848.08,0.23026,0.09956
192,16,36853.13,0.23068,0.09973
192.2,16.017,36853.95,0.2311,0.0999
192.4,16.034,36847.32,0.23153,0.10007
192.6,16.05,36851.59,0.23194,0.10025
192.8,16.067,36838.04,0.23237,0.10043
193,16.083,36835,0.23279,0.1006
193.2,16.1,36837.25,0.23322,0.10078
193.4,16.117,36828.61,0.23364,0.10096
193.6,16.134,36824.39,0.23407,0.10114
193.8,16.15,36822.23,0.23449,0.10131
194,16.167,36805.91,0.23492,0.1015
194.2,16.184,36831.25,0.23534,0.10168
194.4,16.2,36816.92,0.23578,0.10186
194.6,16.217,36806.35,0.23621,0.10204
194.8,16.234,36813.5,0.23664,0.10223
195,16.25,36799.61,0.23708,0.10241
195.2,16.267,36806.29,0.23751,0.1026
195.4,16.284,36803.51,0.23794,0.10279
195.6,16.3,36793.89,0.23838,0.10298
195.8,16.317,36787.56,0.23882,0.10317
196,16.334,36788.99,0.23926,0.10335
196.2,16.35,36784.95,0.23969,0.10354
196.4,16.367,36793.8,0.24013,0.10373
196.6,16.384,36779.68,0.24058,0.10392
196.8,16.4,36780.08,0.24101,0.10411
197,16.417,36776.22,0.24139,0.1043
197.2,16.434,36774.29,0.24183,0.10449
197.4,16.45,36777.05,0.24227,0.10468
197.6,16.467,36773.08,0.24272,0.10488
197.8,16.484,36776.34,0.24317,0.10508
198,16.5,36770.07,0.24362,0.10527
198.2,16.517,36773.22,0.24408,0.10547
198.4,16.533,36772.59,0.24453,0.10567
198.6,16.55,36771.23,0.24499,0.10587
198.8,16.567,36769.61,0.24544,0.10607
199,16.584,36770.4,0.2459,0.10627
199.2,16.6,36768.59,0.24636,0.10647
199.4,16.617,36769.79,0.24682,0.10668
199.6,16.634,36768.57,0.24728,0.10688
199.8,16.65,36768.66,0.24775,0.10709
200,16.667,36764.76,0.24821,0.10729
200.2,16.684,36767.02,0.24867,0.1075
200.4,16.7,36765.1,0.24914,0.10771
200.6,16.717,36765.4,0.2496,0.10792
200.8,16.734,36763.93,0.25008,0.10813
201,16.75,36758.52,0.25055,0.10831
201.2,16.767,36758.35,0.25103,0.10852
201.4,16.784,36760.33,0.2515,0.10874
201.6,16.8,36755.54,0.25197,0.10896
201.8,16.817,36755.07,0.25245,0.10918
202,16.834,36754.26,0.25293,0.1094
202.2,16.85,36750.37,0.25341,0.10962
202.4,16.867,36754.8,0.2539,0.10984
202.6,16.883,36747.7,0.25438,0.11006
202.8,16.9,36749.7,0.25487,0.11029
203,16.917,36753.49,0.25536,0.11051
203.2,16.934,36744.91,0.25585,0.11074
203.4,16.95,36743.3,0.25634,0.11095
203.6,16.967,36741.52,0.25683,0.11117
203.8,16.984,36741.83,0.25732,0.1114
204,17,36740.12,0.25781,0.11164
204.2,17.017,36732.57,0.25831,0.11187
204.4,17.034,36735.7,0.2588,0.11211
204.6,17.05,36731.32,0.2593,0.11233
204.8,17.067,36732.64,0.2598,0.11256
205,17.084,36731.05,0.26031,0.1128
205.2,17.1,36729.64,0.26081,0.11304
205.4,17.117,36724.91,0.26132,0.11328
205.6,17.134,36727.9,0.26183,0.11352
205.8,17.15,36722.34,0.26234,0.11376
206,17.167,36720.53,0.26285,0.114
206.2,17.184,36717.76,0.26336,0.11425
206.4,17.2,36717.55,0.26387,0.1145
206.6,17.217,36718.7,0.26439,0.11475
206.8,17.233,36710.3,0.2649,0.115
207,17.25,36707.34,0.26542,0.11525
207.2,17.267,36704.83,0.26594,0.1155
207.4,17.284,36702.75,0.26647,0.11576
207.6,17.3,36700.44,0.267,0.116
207.8,17.317,36691.28,0.26752,0.11626
208,17.334,36686.56,0.26805,0.11653
208.2,17.35,36688.58,0.26858,0.11679
208.4,17.367,36678.66,0.26912,0.11705
208.6,17.384,36668.38,0.26965,0.11732
208.8,17.4,36658.6,0.27018,0.11758
209,17.417,36643.34,0.27071,0.11785
209.2,17.434,36645.56,0.27125,0.11811
209.4,17.45,36640.46,0.27178,0.11839
209.6,17.467,36625.37,0.27233,0.11867
209.8,17.484,36610.83,0.27286,0.11895
210,17.5,36611.5,0.27341,0.11923
210.2,17.517,36591.63,0.27395,0.11952
210.4,17.534,36592.2,0.27451,0.11981
210.6,17.55,36583.3,0.27506,0.1201
210.8,17.567,36577.43,0.27562,0.12039
211,17.584,36559.64,0.27618,0.12069
211.2,17.6,36559.02,0.27673,0.12098
211.4,17.617,36559.38,0.27729,0.12117
211.6,17.634,36552.86,0.27784,0.12112
211.8,17.65,36544.23,0.2784,0.12151
212,17.667,36535.18,0.27895,0.12182
212.2,17.684,36529.11,0.27952,0.12216
212.4,17.7,36525.08,0.28008,0.12244
212.6,17.717,36523.39,0.28065,0.12281
212.8,17.733,36507.79,0.28121,0.12312
213,17.75,36504.85,0.28179,0.12345
213.2,17.767,36494.7,0.28236,0.1238
213.4,17.784,36487.29,0.28293,0.1241
213.6,17.8,36472.04,0.28351,0.12444
213.8,17.817,36465.46,0.28409,0.12478
214,17.833,36447.07,0.28466,0.1251
214.2,17.85,36445.05,0.28522,0.12545
214.4,17.867,36431.92,0.28575,0.12579
214.6,17.884,36428.4,0.28632,0.12613
214.8,17.9,36414.36,0.2869,0.12649
215,17.917,36413.32,0.28749,0.12683
215.2,17.934,36401.54,0.28808,0.12718
215.4,17.95,36394.1,0.28868,0.12754
215.6,17.967,36386.28,0.28927,0.12789
215.8,17.984,36373.36,0.28988,0.12826
216,18,36360.19,0.29048,0.12862
216.2,18.017,36350.09,0.29108,0.12897
216.4,18.034,36322.71,0.29168,0.12932
216.6,18.05,36324.7,0.29228,0.12968
216.8,18.067,36308.55,0.29289,0.13007
217,18.084,36303.39,0.2935,0.13045
217.2,18.1,36270.56,0.29411,0.13084
217.4,18.117,36265.77,0.29472,0.13123
217.6,18.134,36250.49,0.29533,0.13162
217.8,18.15,36252.34,0.29594,0.13201
218,18.167,36234.46,0.29656,0.1324
218.2,18.184,36224.15,0.29718,0.1328
218.4,18.2,36216.19,0.2978,0.1332
218.6,18.217,36215.15,0.29842,0.1336
218.8,18.234,36210.16,0.29904,0.13402
219,18.25,36203.65,0.29967,0.13443
219.2,18.267,36204.5,0.30029,0.13484
219.4,18.284,36200.84,0.30092,0.13526
219.6,18.3,36192.61,0.30154,0.13569
219.8,18.317,36184.3,0.30216,0.13611
220,18.334,36180.36,0.30279,0.13653
220.2,18.35,36176.35,0.30342,0.13695
220.4,18.367,36166.71,0.30405,0.13738
220.6,18.384,36163.61,0.30467,0.13782
220.8,18.4,36160.26,0.30531,0.13827
221,18.417,36157.98,0.30595,0.13872
221.2,18.434,36157.22,0.30659,0.13918
221.4,18.45,36153.86,0.30723,0.13965
221.6,18.467,36150.45,0.30787,0.14011
221.8,18.484,36145.73,0.3085,0.14057
222,18.5,36136.03,0.30914,0.14103
222.2,18.517,36125.46,0.30979,0.1415
222.4,18.534,36106.64,0.31043,0.14197
222.6,18.55,36090,0.31108,0.14245
222.8,18.567,36077.25,0.31172,0.14293
223,18.584,36067.14,0.31236,0.14341
223.2,18.6,36057.96,0.31301,0.1439
223.4,18.617,36047.64,0.31366,0.14439
223.6,18.634,36040.02,0.31432,0.14489
223.8,18.65,36024.77,0.31497,0.14539
224,18.667,36009.71,0.31561,0.14588
224.2,18.684,35979.74,0.31627,0.14639
224.4,18.7,35972.15,0.31692,0.1469
224.6,18.717,35947.27,0.31757,0.14742
224.8,18.733,35933.18,0.31822,0.14794
225,18.75,35942.81,0.31887,0.14845
225.2,18.767,35910.49,0.31951,0.14897
225.4,18.783,35882.22,0.32017,0.1495
225.6,18.8,35855.23,0.32084,0.15001
225.8,18.817,35823.98,0.32149,0.15054
226,18.834,35803.44,0.32215,0.15109
226.2,18.85,35767.52,0.32282,0.15164
226.4,18.867,35751.04,0.32347,0.15219
226.6,18.884,35737.15,0.32414,0.15274
226.8,18.9,35724.14,0.32479,0.1533
227,18.917,35715.13,0.32546,0.15386
227.2,18.934,35708.89,0.3261,0.15442
227.4,18.95,35700.44,0.32675,0.15497
227.6,18.967,35693.9,0.32741,0.15553
227.8,18.984,35680.65,0.32808,0.15611
228,19,35671.21,0.32873,0.15668
228.2,19.017,35654.32,0.3294,0.15724
228.4,19.034,35636.46,0.33006,0.15783
228.6,19.05,35616.53,0.33072,0.15856
228.8,19.067,35591.5,0.3314,0.15918
229,19.084,35551.8,0.33206,0.15979
229.2,19.1,35520.27,0.33273,0.16039
229.4,19.117,35489.36,0.3334,0.161
229.6,19.133,35468.65,0.33406,0.1616
229.8,19.15,35453.56,0.33472,0.1622
230,19.167,35438.03,0.33539,0.16281
230.2,19.184,35424.89,0.33605,0.16342
230.4,19.2,35404.04,0.33672,0.16403
230.6,19.217,35387.52,0.33739,0.16464
230.8,19.234,35375.96,0.33805,0.16525
231,19.25,35367.31,0.33873,0.16586
231.2,19.267,35358.64,0.3394,0.16648
231.4,19.284,35347.57,0.34007,0.1671
231.6,19.3,35314.48,0.34074,0.16771
231.8,19.317,35298.16,0.34141,0.16833
232,19.334,35272.75,0.34207,0.16894
232.2,19.35,35258.86,0.34274,0.16955
232.4,19.367,35239.01,0.3434,0.17018
232.6,19.384,35226.59,0.34407,0.1708
232.8,19.4,35202.13,0.34473,0.17143
233,19.417,35188.3,0.34541,0.17206
233.2,19.434,35170.8,0.34608,0.17269
233.4,19.45,35158.87,0.34674,0.17332
233.6,19.467,35145.12,0.34741,0.17395
233.8,19.483,35126.93,0.34808,0.17459
234,19.5,35091.87,0.34875,0.17522
234.2,19.517,35040.06,0.34943,0.17587
234.4,19.533,34999.7,0.35009,0.17652
234.6,19.55,34979.1,0.35077,0.17717
234.8,19.567,34950.42,0.35142,0.17784
235,19.583,34907.15,0.35209,0.17859
235.2,19.6,34881.79,0.35277,0.17926
235.4,19.617,34851.8,0.35344,0.17994
235.6,19.634,34816.05,0.3541,0.18057
235.8,19.65,34788.5,0.35478,0.18126
236,19.667,34746.07,0.35544,0.18193
236.2,19.684,34707.14,0.35612,0.18261
236.4,19.7,34672.27,0.3568,0.18329
236.6,19.717,34659.36,0.35747,0.18397
236.8,19.734,34656.7,0.35814,0.18465
237,19.75,34655.04,0.35882,0.18533
237.2,19.767,34655.02,0.35949,0.18601
237.4,19.784,34654.97,0.36017,0.1867
237.6,19.8,34652.56,0.36084,0.18737
237.8,19.817,34643.71,0.36151,0.18805
238,19.834,34618.9,0.36218,0.18873
238.2,19.85,34583.45,0.36286,0.18941
238.4,19.867,34553.17,0.36353,0.1901
238.6,19.883,34508.43,0.36421,0.19078
238.8,19.9,34463.17,0.36488,0.19147
239,19.917,34414.52,0.36557,0.19216
239.2,19.934,34373.19,0.36624,0.19285
239.4,19.95,34341.81,0.36692,0.19354
239.6,19.967,34300.84,0.3676,0.19423
239.8,19.984,34247.14,0.36827,0.19492
240,20,34199.83,0.36893,0.1956
240.2,20.017,34176.99,0.3696,0.19628
240.4,20.033,34161.47,0.37028,0.19697
240.6,20.05,34135.08,0.37096,0.19766
240.8,20.067,34102.24,0.37163,0.19835
241,20.084,34068.65,0.37231,0.19904
241.2,20.1,34045.43,0.37299,0.19974
241.4,20.117,34023.11,0.37366,0.20043
241.6,20.134,33989.75,0.37435,0.20114
241.8,20.15,33951.67,0.37502,0.20184
242,20.167,33940.18,0.3757,0.20253
242.2,20.184,33914.02,0.37637,0.20323
242.4,20.2,33890.63,0.37705,0.20392
242.6,20.217,33873.48,0.37772,0.20464
242.8,20.234,33849.16,0.37841,0.2054
243,20.25,33783.58,0.37908,0.20606
243.2,20.267,33730,0.37975,0.20679
243.4,20.284,33698.52,0.38044,0.20751
243.6,20.3,33671.02,0.38111,0.20823
243.8,20.317,33652.85,0.38179,0.20895
244,20.334,33633.39,0.38248,0.20967
244.2,20.35,33602.2,0.38316,0.21039
244.4,20.367,33561.38,0.38384,0.21112
244.6,20.384,33500.55,0.38452,0.21186
244.8,20.4,33451.36,0.3852,0.2126
245,20.417,33425.21,0.38587,0.21415
245.2,20.433,33367.34,0.3865,0.21736
245.4,20.45,33295.85,0.38719,0.21815
245.6,20.467,33256.09,0.38788,0.21889
245.8,20.483,33221.75,0.38856,0.21964
246,20.5,33186.89,0.38925,0.22038
246.2,20.517,33157.69,0.38993,0.22113
246.4,20.534,33153.17,0.39061,0.22186
246.6,20.55,33152.69,0.3913,0.2226
246.8,20.567,33150.8,0.39199,0.22336
247,20.584,33135.47,0.39267,0.22411
247.2,20.6,33087.97,0.39335,0.22559
247.4,20.617,33017.44,0.39404,0.22637
247.6,20.634,32947.43,0.39473,0.22711
247.8,20.65,32905.59,0.39541,0.22787
248,20.667,32845.62,0.39609,0.22862
248.2,20.684,32796.19,0.39678,0.22938
248.4,20.7,32738.29,0.39745,0.23013
248.6,20.717,32667.48,0.39813,0.23084
248.8,20.734,32613.7,0.39882,0.23157
249,20.75,32583.3,0.3995,0.23232
249.2,20.767,32558.08,0.40019,0.2331
249.4,20.784,32544.04,0.40087,0.23385
249.6,20.8,32527.35,0.40156,0.23461
249.8,20.817,32486.37,0.40225,0.23537
250,20.833,32457.32,0.40293,0.23612
250.2,20.85,32429.73,0.40361,0.23687
250.4,20.867,32369.9,0.4043,0.23762
250.6,20.884,32317.49,0.40498,0.23837
250.8,20.9,32271.11,0.40567,0.23913
251,20.917,32195.74,0.40636,0.23988
251.2,20.934,32142.63,0.40704,0.24121
251.4,20.95,32105.49,0.40768,0.2465
251.6,20.967,32078.41,0.40837,0.24733
251.8,20.984,32052.74,0.40906,0.24811
252,21,32004.21,0.40975,0.2489
252.2,21.017,31915.93,0.41045,0.2497
252.4,21.034,31865.96,0.41114,0.25048
252.6,21.05,31800.74,0.41184,0.25127
252.8,21.067,31761.08,0.41253,0.25203
253,21.084,31724.29,0.41321,0.2528
253.2,21.1,31670.1,0.4139,0.25357
253.4,21.117,31651.17,0.4146,0.25434
253.6,21.134,31620.86,0.41529,0.25513
253.8,21.15,31591.4,0.41598,0.25589
254,21.167,31563.14,0.41667,0.25677
254.2,21.184,31480.55,0.41735,0.25755
254.4,21.2,31401.01,0.41805,0.2583
254.6,21.217,31347.69,0.41874,0.25908
254.8,21.234,31257.96,0.41945,0.25987
255,21.25,31185.69,0.42013,0.26067
255.2,21.267,31124.34,0.42083,0.2615
255.4,21.284,31064.89,0.42151,0.26227
255.6,21.3,31043.13,0.42221,0.26302
255.8,21.317,31028.19,0.4229,0.26378
256,21.334,31012.32,0.42359,0.26453
256.2,21.35,30942.53,0.42428,0.26529
256.4,21.367,30886.59,0.42498,0.26606
256.6,21.384,30835.68,0.42567,0.26684
256.8,21.4,30770.22,0.42636,0.26765
257,21.417,30670.86,0.42706,0.26845
257.2,21.434,30597.38,0.42776,0.2692
257.4,21.45,30557.18,0.42845,0.26995
257.6,21.467,30511.98,0.42914,0.27072
257.8,21.484,30477.2,0.42984,0.27146
258,21.5,30408.04,0.43054,0.27219
258.2,21.517,30354.07,0.43123,0.27293
258.4,21.534,30289.75,0.43193,0.27368
258.6,21.55,30231.91,0.43263,0.27443
258.8,21.567,30170.48,0.43333,0.2752
259,21.584,30089.56,0.43402,0.27599
259.2,21.6,30068.36,0.43472,0.2767
259.4,21.617,30037.65,0.43541,0.27745
259.6,21.634,29984.65,0.43611,0.27889
259.8,21.65,29852.18,0.43681,0.27994
260,21.667,29782.84,0.43751,0.28073
260.2,21.684,29705.75,0.43822,0.28152
260.4,21.7,29659.03,0.43892,0.28232
260.6,21.717,29565.84,0.43962,0.28313
260.8,21.733,29520.32,0.44032,0.2839
261,21.75,29484.55,0.44103,0.2847
261.2,21.767,29455.55,0.44172,0.28549
261.4,21.784,29370.27,0.44242,0.28628
261.6,21.8,29300.57,0.44312,0.28706
261.8,21.817,29210.17,0.44382,0.28787
262,21.834,29125.45,0.44453,0.28867
262.2,21.85,29024.59,0.44523,0.28957
262.4,21.867,28993.4,0.44593,0.29036
262.6,21.884,28972.67,0.44662,0.29803
262.8,21.9,28920.06,0.44732,0.2987
263,21.917,28816.27,0.44803,0.2998
263.2,21.934,28704.7,0.44873,0.30087
263.4,21.95,28641.9,0.44944,0.30195
263.6,21.967,28548.61,0.45014,0.30277
263.8,21.984,28523.05,0.45084,0.30396
264,22,28445.64,0.45155,0.30504
264.2,22.017,28371.35,0.45227,0.30612
264.4,22.034,28295.13,0.45298,0.30728
264.6,22.05,28212.02,0.45368,0.30829
264.8,22.067,28147.33,0.4544,0.30805
265,22.084,28000.72,0.45512,0.30919
265.2,22.1,27969.44,0.45583,0.31026
265.4,22.117,27932.1,0.45655,0.30603
265.6,22.134,27857.47,0.45726,0.30694
265.8,22.15,27764,0.45796,0.30783
266,22.167,27634.39,0.45867,0.30867
266.2,22.184,27543.47,0.45939,0.3087
266.4,22.2,27491.2,0.46011,0.30938
266.6,22.217,27460.78,0.46082,0.3098
266.8,22.234,27360.27,0.46154,0.30908
267,22.25,27237.83,0.46225,0.30743
267.2,22.267,27139.55,0.46297,0.30823
267.4,22.284,27068.21,0.46369,0.30886
267.6,22.3,26948.99,0.46441,0.30934
267.8,22.317,26909.12,0.46512,0.3092
268,22.334,26864.17,0.46584,0.30978
268.2,22.35,26754.85,0.46656,0.30921
268.4,22.367,26619.3,0.46728,0.30902
268.6,22.384,26482.83,0.468,0.30788
268.8,22.4,26407.12,0.46872,0.30852
269,22.417,26385.83,0.46943,0.30802
269.2,22.434,26270.28,0.47016,0.30611
269.4,22.45,26181.54,0.47088,0.30684
269.6,22.467,26093.88,0.47161,0.30757
269.8,22.484,25970.63,0.47233,0.30825
270,22.5,25892.36,0.47306,0.3075
270.2,22.517,25780.83,0.47378,0.30816
270.4,22.534,25664.04,0.4745,0.30875
270.6,22.55,25545.48,0.47523,0.30935
270.8,22.567,25441.75,0.47596,0.31002
271,22.584,25395.2,0.47669,0.31072
271.2,22.6,24207.5,0.47796,0.3082
271.216,22.602,14225.31,0.46583,0.29569