File: Labs/Lab 2 Tension/Specimen_RawData_2.csv
Specimen label,"Steel ME354"
End date,"Monday, October 14, 2019"
Thickness,"6.20000",mm
Width,"12.30000",mm
Final length,"78.43000",mm
Axial gauge length,"25.40000",mm
Transverse gauge length,"12.05000",mm
Crosshead Rate,"5.00",mm/min

Time,Extension,Load,Axial Strain,Transverse Strain
(s),(mm),(N),(mm/mm),(mm/mm)
"0.000","0.000","1.89","0.00000","0.00000"
"0.300","0.024","869.10","0.00005","0.00002"
"0.600","0.050","2150.79","0.00013","0.00005"
"0.900","0.075","2541.00","0.00017","0.00007"
"1.200","0.100","2877.30","0.00020","0.00008"
"1.500","0.125","3206.61","0.00022","0.00009"
"1.800","0.150","3523.04","0.00024","0.00009"
"2.100","0.175","3782.27","0.00025","0.00009"
"2.400","0.200","4124.02","0.00028","0.00009"
"2.700","0.225","4351.97","0.00029","0.00010"
"3.000","0.250","4733.22","0.00031","0.00010"
"3.300","0.275","4999.49","0.00033","0.00011"
"3.600","0.300","5327.47","0.00035","0.00011"
"3.900","0.325","5658.52","0.00037","0.00012"
"4.200","0.350","5976.92","0.00039","0.00012"
"4.500","0.375","6309.59","0.00041","0.00013"
"4.800","0.400","6644.23","0.00042","0.00013"
"5.100","0.425","6934.35","0.00044","0.00014"
"5.400","0.450","7332.30","0.00046","0.00014"
"5.700","0.475","7665.90","0.00048","0.00014"
"6.000","0.500","7943.54","0.00050","0.00015"
"6.300","0.525","8384.98","0.00052","0.00015"
"6.600","0.550","8654.25","0.00053","0.00016"
"6.900","0.575","9045.43","0.00056","0.00016"
"7.200","0.600","9395.52","0.00057","0.00016"
"7.500","0.625","9810.47","0.00060","0.00017"
"7.800","0.650","10085.73","0.00062","0.00017"
"8.100","0.675","10522.22","0.00064","0.00018"
"8.400","0.700","10880.96","0.00066","0.00018"
"8.700","0.725","11284.32","0.00068","0.00019"
"9.000","0.750","11587.54","0.00070","0.00019"
"9.300","0.775","12028.79","0.00072","0.00020"
"9.600","0.800","12446.17","0.00075","0.00020"
"9.900","0.825","12795.94","0.00077","0.00021"
"10.200","0.850","13172.80","0.00079","0.00021"
"10.500","0.875","13553.09","0.00081","0.00022"
"10.800","0.900","14036.24","0.00083","0.00023"
"11.100","0.925","14378.49","0.00085","0.00023"
"11.400","0.950","14800.37","0.00088","0.00024"
"11.700","0.975","15141.06","0.00090","0.00024"
"12.000","1.000","15599.89","0.00092","0.00025"
"12.300","1.025","16038.20","0.00095","0.00026"
"12.600","1.050","16435.15","0.00097","0.00026"
"12.900","1.075","16850.02","0.00099","0.00027"
"13.200","1.100","17250.08","0.00102","0.00028"
"13.500","1.125","17671.54","0.00104","0.00029"
"13.800","1.150","18150.37","0.00107","0.00030"
"14.100","1.175","18516.34","0.00110","0.00030"
"14.400","1.200","18978.01","0.00113","0.00031"
"14.700","1.225","19379.87","0.00116","0.00032"
"15.000","1.250","19750.33","0.00118","0.00033"
"15.300","1.275","20263.34","0.00122","0.00034"
"15.600","1.300","20674.33","0.00125","0.00036"
"15.900","1.325","21127.43","0.00129","0.00037"
"16.200","1.350","21486.18","0.00132","0.00038"
"16.500","1.375","21884.41","0.00137","0.00040"
"16.800","1.400","22335.04","0.00141","0.00042"
"17.100","1.425","22720.65","0.00146","0.00044"
"17.400","1.450","23182.71","0.00152","0.00046"
"17.700","1.475","23478.56","0.00158","0.00048"
"18.000","1.500","23903.83","0.00164","0.00050"
"18.300","1.525","24242.49","0.00172","0.00053"
"18.600","1.550","24599.79","0.00181","0.00055"
"18.900","1.575","24855.55","0.00190","0.00058"
"19.200","1.600","25145.27","0.00200","0.00061"
"19.500","1.625","25401.76","0.00212","0.00064"
"19.800","1.650","25477.28","0.00223","0.00067"
"20.100","1.675","25480.18","0.00233","0.00067"
"20.400","1.700","25464.35","0.00243","0.00065"
"20.700","1.725","25457.83","0.00254","0.00062"
"21.000","1.750","25433.05","0.00263","0.00060"
"21.300","1.775","25388.50","0.00279","0.00057"
"21.600","1.800","25404.87","0.00301","0.00055"
"21.900","1.825","25445.98","0.00329","0.00055"
"22.200","1.850","25511.26","0.00359","0.00056"
"22.500","1.875","25628.34","0.00390","0.00058"
"22.800","1.900","25714.60","0.00428","0.00060"
"23.100","1.925","25706.09","0.00484","0.00062"
"23.400","1.950","25632.24","0.00554","0.00065"
"23.700","1.975","25536.71","0.00629","0.00074"
"24.000","2.000","25465.92","0.00702","0.00105"
"24.300","2.025","25417.00","0.00769","0.00144"
"24.600","2.050","25276.72","0.00825","0.00177"
"24.900","2.075","25318.13","0.00875","0.00201"
"25.200","2.100","25367.90","0.00926","0.00225"
"25.500","2.125","25382.28","0.00981","0.00259"
"25.800","2.150","25378.48","0.01042","0.00314"
"26.100","2.175","25399.81","0.01107","0.00376"
"26.400","2.200","25430.09","0.01164","0.00431"
"26.700","2.225","25464.18","0.01209","0.00473"
"27.000","2.250","25511.56","0.01239","0.00500"
"27.300","2.275","25546.10","0.01260","0.00519"
"27.600","2.300","25567.72","0.01273","0.00531"
"27.900","2.325","25672.67","0.01285","0.00541"
"28.200","2.350","25823.72","0.01302","0.00553"
"28.500","2.375","25954.52","0.01322","0.00566"
"28.800","2.400","26086.87","0.01347","0.00582"
"29.100","2.425","26190.47","0.01375","0.00598"
"29.400","2.450","26278.12","0.01403","0.00613"
"29.700","2.475","26385.10","0.01431","0.00628"
"30.000","2.500","26409.71","0.01458","0.00643"
"30.300","2.525","26475.79","0.01485","0.00656"
"30.600","2.550","26615.54","0.01512","0.00670"
"30.900","2.575","26749.51","0.01540","0.00684"
"31.200","2.600","26848.13","0.01567","0.00698"
"31.500","2.625","26906.83","0.01594","0.00711"
"31.800","2.650","26947.64","0.01621","0.00725"
"32.100","2.675","27021.15","0.01647","0.00739"
"32.400","2.700","27125.57","0.01675","0.00752"
"32.700","2.725","27220.33","0.01702","0.00766"
"33.000","2.750","27304.89","0.01729","0.00780"
"33.300","2.775","27449.88","0.01755","0.00793"
"33.600","2.800","27479.83","0.01782","0.00807"
"33.900","2.825","27527.14","0.01810","0.00821"
"34.200","2.850","27616.58","0.01837","0.00835"
"34.500","2.875","27732.18","0.01864","0.00849"
"34.800","2.900","27826.67","0.01892","0.00863"
"35.100","2.925","27919.57","0.01919","0.00877"
"35.400","2.950","27960.37","0.01946","0.00891"
"35.700","2.975","27986.87","0.01975","0.00906"
"36.000","3.000","28111.98","0.02002","0.00919"
"36.300","3.025","28191.25","0.02030","0.00933"
"36.600","3.050","28279.72","0.02058","0.00948"
"36.900","3.075","28346.74","0.02086","0.00962"
"37.200","3.100","28435.59","0.02115","0.00977"
"37.500","3.125","28515.42","0.02143","0.00991"
"37.800","3.150","28545.21","0.02171","0.01006"
"38.100","3.175","28642.81","0.02200","0.01020"
"38.400","3.200","28702.67","0.02228","0.01034"
"38.700","3.225","28803.64","0.02256","0.01047"
"39.000","3.250","28916.21","0.02285","0.01062"
"39.300","3.275","28972.71","0.02313","0.01076"
"39.600","3.300","28991.46","0.02342","0.01090"
"39.900","3.325","29026.54","0.02370","0.01104"
"40.200","3.350","29125.82","0.02399","0.01118"
"40.500","3.375","29209.63","0.02428","0.01132"
"40.800","3.400","29301.08","0.02456","0.01146"
"41.100","3.425","29381.83","0.02485","0.01160"
"41.400","3.450","29461.71","0.02514","0.01174"
"41.700","3.475","29487.73","0.02543","0.01188"
"42.000","3.500","29529.93","0.02571","0.01203"
"42.300","3.525","29576.26","0.02600","0.01217"
"42.600","3.550","29663.84","0.02630","0.01232"
"42.900","3.575","29717.60","0.02658","0.01245"
"43.200","3.600","29795.72","0.02686","0.01259"
"43.500","3.625","29886.64","0.02716","0.01274"
"43.800","3.650","29994.40","0.02745","0.01288"
"44.100","3.675","30048.84","0.02774","0.01302"
"44.400","3.700","30077.47","0.02803","0.01316"
"44.700","3.725","30106.54","0.02833","0.01331"
"45.000","3.750","30187.82","0.02862","0.01345"
"45.300","3.775","30253.15","0.02892","0.01360"
"45.600","3.800","30327.92","0.02922","0.01374"
"45.900","3.825","30375.40","0.02951","0.01388"
"46.200","3.850","30441.78","0.02980","0.01402"
"46.500","3.875","30485.43","0.03010","0.01417"
"46.800","3.900","30533.21","0.03040","0.01431"
"47.100","3.925","30574.65","0.03070","0.01446"
"47.400","3.950","30628.16","0.03099","0.01461"
"47.700","3.975","30732.21","0.03129","0.01476"
"48.000","4.000","30797.55","0.03159","0.01491"
"48.300","4.025","30867.82","0.03189","0.01506"
"48.600","4.050","30910.56","0.03219","0.01520"
"48.900","4.075","30991.30","0.03249","0.01535"
"49.200","4.100","31023.34","0.03278","0.01550"
"49.500","4.125","31032.17","0.03309","0.01565"
"49.800","4.150","31051.23","0.03339","0.01580"
"50.100","4.175","31087.98","0.03369","0.01596"
"50.400","4.200","31161.32","0.03399","0.01610"
"50.700","4.225","31220.22","0.03430","0.01626"
"51.000","4.250","31299.81","0.03460","0.01641"
"51.300","4.275","31376.55","0.03490","0.01656"
"51.600","4.300","31433.68","0.03521","0.01671"
"51.900","4.325","31527.33","0.03551","0.01686"
"52.200","4.350","31583.62","0.03581","0.01701"
"52.500","4.375","31601.66","0.03612","0.01717"
"52.800","4.400","31635.73","0.03643","0.01732"
"53.100","4.425","31658.73","0.03673","0.01748"
"53.400","4.450","31696.21","0.03704","0.01763"
"53.700","4.475","31741.94","0.03735","0.01777"
"54.000","4.500","31779.47","0.03766","0.01793"
"54.300","4.525","31844.11","0.03797","0.01808"
"54.600","4.550","31881.36","0.03828","0.01823"
"54.900","4.575","31956.02","0.03859","0.01838"
"55.200","4.600","32029.33","0.03889","0.01853"
"55.500","4.625","32066.11","0.03921","0.01868"
"55.800","4.650","32087.50","0.03952","0.01884"
"56.100","4.675","32117.67","0.03983","0.01899"
"56.400","4.700","32156.15","0.04014","0.01914"
"56.700","4.725","32222.61","0.04045","0.01929"
"57.000","4.750","32287.10","0.04075","0.01944"
"57.300","4.775","32326.96","0.04106","0.01960"
"57.600","4.800","32379.35","0.04138","0.01975"
"57.900","4.825","32430.88","0.04169","0.01990"
"58.200","4.850","32460.91","0.04199","0.02006"
"58.500","4.875","32493.84","0.04231","0.02021"
"58.800","4.900","32533.02","0.04263","0.02036"
"59.100","4.925","32547.28","0.04294","0.02052"
"59.400","4.950","32558.04","0.04326","0.02067"
"59.700","4.975","32583.83","0.04357","0.02082"
"60.000","5.000","32607.19","0.04389","0.02097"
"60.300","5.025","32657.61","0.04421","0.02112"
"60.600","5.050","32727.75","0.04453","0.02127"
"60.900","5.075","32792.26","0.04485","0.02143"
"61.200","5.100","32829.98","0.04516","0.02158"
"61.500","5.125","32889.75","0.04549","0.02174"
"61.800","5.150","32937.33","0.04581","0.02189"
"62.100","5.175","32979.94","0.04612","0.02204"
"62.400","5.200","33055.32","0.04644","0.02219"
"62.700","5.225","33118.54","0.04676","0.02234"
"63.000","5.250","33146.37","0.04708","0.02249"
"63.300","5.275","33151.96","0.04741","0.02265"
"63.600","5.300","33153.08","0.04774","0.02280"
"63.900","5.325","33153.15","0.04806","0.02296"
"64.200","5.350","33157.48","0.04840","0.02311"
"64.500","5.375","33182.14","0.04872","0.02326"
"64.800","5.400","33227.64","0.04904","0.02342"
"65.100","5.425","33256.18","0.04937","0.02357"
"65.400","5.450","33294.34","0.04970","0.02373"
"65.700","5.475","33366.21","0.05002","0.02389"
"66.000","5.500","33414.76","0.05035","0.02404"
"66.300","5.525","33446.22","0.05068","0.02420"
"66.600","5.550","33485.92","0.05101","0.02435"
"66.900","5.575","33527.62","0.05134","0.02451"
"67.200","5.600","33584.14","0.05167","0.02467"
"67.500","5.625","33612.91","0.05199","0.02482"
"67.800","5.650","33639.93","0.05231","0.02497"
"68.100","5.675","33656.16","0.05265","0.02513"
"68.400","5.700","33674.35","0.05297","0.02528"
"68.700","5.725","33698.45","0.05331","0.02544"
"69.000","5.750","33738.08","0.05364","0.02560"
"69.300","5.775","33786.85","0.05397","0.02575"
"69.600","5.800","33832.09","0.05430","0.02591"
"69.900","5.825","33870.02","0.05464","0.02606"
"70.200","5.850","33882.84","0.05497","0.02622"
"70.500","5.875","33908.72","0.05531","0.02637"
"70.800","5.900","33931.69","0.05564","0.02652"
"71.100","5.925","33947.84","0.05597","0.02668"
"71.400","5.950","33959.39","0.05631","0.02683"
"71.700","5.975","33990.93","0.05665","0.02699"
"72.000","6.000","34023.27","0.05698","0.02714"
"72.300","6.025","34047.83","0.05732","0.02730"
"72.600","6.050","34067.02","0.05766","0.02745"
"72.900","6.075","34093.34","0.05799","0.02761"
"73.200","6.100","34134.05","0.05833","0.02776"
"73.500","6.125","34154.35","0.05867","0.02792"
"73.800","6.150","34174.56","0.05901","0.02808"
"74.100","6.175","34183.27","0.05935","0.02824"
"74.400","6.200","34229.75","0.05969","0.02839"
"74.700","6.225","34269.70","0.06003","0.02855"
"75.000","6.250","34307.77","0.06036","0.02870"
"75.300","6.275","34344.05","0.06071","0.02886"
"75.600","6.300","34363.52","0.06104","0.02902"
"75.900","6.325","34399.84","0.06138","0.02917"
"76.200","6.350","34445.73","0.06172","0.02933"
"76.500","6.375","34500.39","0.06207","0.02949"
"76.800","6.400","34524.68","0.06241","0.02964"
"77.100","6.425","34556.49","0.06275","0.02980"
"77.400","6.450","34595.11","0.06309","0.02996"
"77.700","6.475","34618.00","0.06344","0.03012"
"78.000","6.500","34640.45","0.06378","0.03028"
"78.300","6.525","34653.54","0.06412","0.03043"
"78.600","6.550","34655.02","0.06447","0.03059"
"78.900","6.575","34655.07","0.06482","0.03075"
"79.200","6.600","34655.00","0.06517","0.03092"
"79.500","6.625","34655.51","0.06551","0.03108"
"79.800","6.650","34655.72","0.06586","0.03124"
"80.100","6.675","34662.38","0.06620","0.03140"
"80.400","6.700","34666.77","0.06655","0.03156"
"80.700","6.725","34707.13","0.06690","0.03172"
"81.000","6.750","34734.82","0.06725","0.03188"
"81.300","6.775","34774.97","0.06760","0.03204"
"81.600","6.800","34806.38","0.06795","0.03221"
"81.900","6.825","34833.62","0.06830","0.03237"
"82.200","6.850","34861.07","0.06865","0.03253"
"82.500","6.875","34894.60","0.06901","0.03269"
"82.800","6.900","34917.30","0.06935","0.03285"
"83.100","6.925","34945.41","0.06971","0.03302"
"83.400","6.950","34976.55","0.07006","0.03317"
"83.700","6.975","34993.57","0.07041","0.03334"
"84.000","7.000","35030.62","0.07076","0.03350"
"84.300","7.025","35054.30","0.07112","0.03366"
"84.600","7.050","35101.05","0.07147","0.03382"
"84.900","7.075","35132.76","0.07183","0.03398"
"85.200","7.100","35145.43","0.07217","0.03414"
"85.500","7.125","35160.43","0.07253","0.03430"
"85.800","7.150","35166.44","0.07289","0.03447"
"86.100","7.175","35180.18","0.07324","0.03463"
"86.400","7.200","35194.41","0.07360","0.03479"
"86.700","7.225","35216.61","0.07396","0.03496"
"87.000","7.250","35227.88","0.07431","0.03512"
"87.300","7.275","35243.57","0.07467","0.03528"
"87.600","7.300","35259.45","0.07503","0.03544"
"87.900","7.325","35272.02","0.07539","0.03560"
"88.200","7.350","35284.28","0.07575","0.03576"
"88.500","7.375","35300.88","0.07611","0.03593"
"88.800","7.400","35332.61","0.07647","0.03609"
"89.100","7.425","35351.02","0.07683","0.03625"
"89.400","7.450","35363.38","0.07718","0.03641"
"89.700","7.475","35370.03","0.07755","0.03657"
"90.000","7.500","35373.54","0.07791","0.03674"
"90.300","7.525","35386.64","0.07827","0.03690"
"90.600","7.550","35397.18","0.07863","0.03706"
"90.900","7.575","35416.74","0.07900","0.03722"
"91.200","7.600","35430.92","0.07936","0.03738"
"91.500","7.625","35441.84","0.07972","0.03755"
"91.800","7.650","35454.89","0.08010","0.03771"
"92.100","7.675","35468.70","0.08047","0.03787"
"92.400","7.700","35484.44","0.08083","0.03803"
"92.700","7.725","35521.60","0.08120","0.03819"
"93.000","7.750","35547.29","0.08156","0.03835"
"93.300","7.775","35572.63","0.08193","0.03851"
"93.600","7.800","35607.85","0.08229","0.03867"
"93.900","7.825","35631.04","0.08266","0.03883"
"94.200","7.850","35643.02","0.08303","0.03899"
"94.500","7.875","35656.89","0.08340","0.03915"
"94.800","7.900","35668.73","0.08376","0.03931"
"95.100","7.925","35679.61","0.08413","0.03947"
"95.400","7.950","35685.96","0.08449","0.03963"
"95.700","7.975","35698.14","0.08486","0.03980"
"96.000","8.000","35703.47","0.08523","0.03996"
"96.300","8.025","35712.80","0.08560","0.04012"
"96.600","8.050","35720.40","0.08597","0.04028"
"96.900","8.075","35734.93","0.08634","0.04044"
"97.200","8.100","35740.50","0.08670","0.04061"
"97.500","8.125","35746.72","0.08707","0.04077"
"97.800","8.150","35763.88","0.08744","0.04093"
"98.100","8.175","35792.59","0.08780","0.04109"
"98.400","8.200","35810.98","0.08816","0.04125"
"98.700","8.225","35831.06","0.08853","0.04142"
"99.000","8.250","35874.30","0.08890","0.04158"
"99.300","8.275","35891.55","0.08928","0.04173"
"99.600","8.300","35912.54","0.08964","0.04190"
"99.900","8.325","35926.89","0.09002","0.04205"
"100.200","8.350","35943.66","0.09039","0.04222"
"100.500","8.375","35953.10","0.09076","0.04238"
"100.800","8.400","35970.01","0.09114","0.04253"
"101.100","8.425","35994.63","0.09151","0.04269"
"101.400","8.450","36001.00","0.09188","0.04285"
"101.700","8.475","36016.81","0.09226","0.04300"
"102.000","8.500","36031.83","0.09263","0.04316"
"102.300","8.525","36045.31","0.09301","0.04331"
"102.600","8.550","36058.61","0.09339","0.04348"
"102.900","8.575","36058.19","0.09376","0.04364"
"103.200","8.600","36070.99","0.09414","0.04379"
"103.500","8.625","36087.25","0.09451","0.04395"
"103.800","8.650","36100.81","0.09488","0.04411"
"104.100","8.675","36114.55","0.09526","0.04427"
"104.400","8.700","36133.83","0.09564","0.04443"
"104.700","8.725","36135.25","0.09601","0.04459"
"105.000","8.750","36148.51","0.09640","0.04476"
"105.300","8.775","36153.29","0.09677","0.04492"
"105.600","8.800","36154.20","0.09715","0.04509"
"105.900","8.825","36154.30","0.09752","0.04526"
"106.200","8.850","36158.84","0.09790","0.04543"
"106.500","8.875","36162.69","0.09828","0.04559"
"106.800","8.900","36167.07","0.09865","0.04576"
"107.100","8.925","36171.20","0.09904","0.04594"
"107.400","8.950","36176.24","0.09942","0.04611"
"107.700","8.975","36183.83","0.09979","0.04628"
"108.000","9.000","36185.23","0.10017","0.04645"
"108.300","9.025","36195.27","0.10055","0.04662"
"108.600","9.050","36198.34","0.10093","0.04679"
"108.900","9.075","36202.93","0.10132","0.04696"
"109.200","9.100","36208.17","0.10169","0.04713"
"109.500","9.125","36209.46","0.10207","0.04730"
"109.800","9.150","36217.99","0.10246","0.04746"
"110.100","9.175","36216.79","0.10284","0.04763"
"110.400","9.200","36226.73","0.10322","0.04780"
"110.700","9.225","36233.19","0.10360","0.04796"
"111.000","9.250","36247.26","0.10398","0.04813"
"111.300","9.275","36261.90","0.10437","0.04829"
"111.600","9.300","36276.85","0.10475","0.04846"
"111.900","9.325","36293.33","0.10513","0.04863"
"112.200","9.350","36315.96","0.10552","0.04879"
"112.500","9.375","36332.15","0.10591","0.04896"
"112.800","9.400","36344.00","0.10630","0.04913"
"113.100","9.425","36356.92","0.10669","0.04930"
"113.400","9.450","36370.21","0.10708","0.04947"
"113.700","9.475","36387.54","0.10747","0.04964"
"114.000","9.500","36397.68","0.10786","0.04980"
"114.300","9.525","36402.07","0.10827","0.04998"
"114.600","9.550","36412.90","0.10869","0.05014"
"114.900","9.575","36422.14","0.10911","0.05031"
"115.200","9.600","36433.79","0.10952","0.05048"
"115.500","9.625","36442.79","0.10993","0.05065"
"115.800","9.650","36458.16","0.11033","0.05082"
"116.100","9.675","36476.39","0.11072","0.05099"
"116.400","9.700","36478.88","0.11113","0.05116"
"116.700","9.725","36492.53","0.11153","0.05133"
"117.000","9.750","36511.30","0.11193","0.05150"
"117.300","9.775","36520.84","0.11233","0.05167"
"117.600","9.800","36517.51","0.11273","0.05184"
"117.900","9.825","36529.30","0.11314","0.05202"
"118.200","9.850","36541.28","0.11354","0.05219"
"118.500","9.875","36545.37","0.11394","0.05236"
"118.800","9.900","36548.70","0.11434","0.05253"
"119.100","9.925","36554.39","0.11474","0.05269"
"119.400","9.950","36572.54","0.11514","0.05286"
"119.700","9.975","36575.59","0.11554","0.05302"
"120.000","10.000","36594.75","0.11594","0.05319"
"120.300","10.025","36609.47","0.11633","0.05336"
"120.600","10.050","36614.73","0.11674","0.05353"
"120.900","10.075","36614.64","0.11714","0.05370"
"121.200","10.100","36627.92","0.11754","0.05387"
"121.500","10.125","36638.85","0.11794","0.05404"
"121.800","10.150","36659.43","0.11834","0.05421"
"122.100","10.175","36670.45","0.11874","0.05438"
"122.400","10.200","36679.54","0.11914","0.05454"
"122.700","10.225","36691.22","0.11955","0.05471"
"123.000","10.250","36696.90","0.11995","0.05488"
"123.300","10.275","36704.19","0.12035","0.05505"
"123.600","10.300","36711.21","0.12075","0.05522"
"123.900","10.325","36710.36","0.12115","0.05539"
"124.200","10.350","36716.19","0.12156","0.05556"
"124.500","10.375","36719.62","0.12197","0.05573"
"124.800","10.400","36721.30","0.12237","0.05590"
"125.100","10.425","36722.93","0.12278","0.05607"
"125.400","10.450","36723.54","0.12318","0.05624"
"125.700","10.475","36729.53","0.12359","0.05640"
"126.000","10.500","36730.86","0.12400","0.05658"
"126.300","10.525","36730.29","0.12441","0.05674"
"126.600","10.550","36735.02","0.12481","0.05691"
"126.900","10.575","36737.29","0.12521","0.05708"
"127.200","10.600","36739.50","0.12562","0.05725"
"127.500","10.625","36741.87","0.12602","0.05743"
"127.800","10.650","36746.62","0.12643","0.05761"
"128.100","10.675","36749.46","0.12685","0.05779"
"128.400","10.700","36753.21","0.12724","0.05797"
"128.700","10.725","36750.84","0.12766","0.05814"
"129.000","10.750","36751.13","0.12806","0.05831"
"129.300","10.775","36753.57","0.12848","0.05848"
"129.600","10.800","36758.58","0.12889","0.05865"
"129.900","10.825","36759.02","0.12930","0.05882"
"130.200","10.850","36764.45","0.12971","0.05899"
"130.500","10.875","36762.82","0.13013","0.05917"
"130.800","10.900","36766.60","0.13054","0.05933"
"131.100","10.925","36764.55","0.13096","0.05950"
"131.400","10.950","36767.28","0.13137","0.05967"
"131.700","10.975","36767.30","0.13178","0.05984"
"132.000","11.000","36769.64","0.13220","0.06001"
"132.300","11.025","36770.22","0.13261","0.06018"
"132.600","11.050","36771.29","0.13302","0.06035"
"132.900","11.075","36772.86","0.13344","0.06052"
"133.200","11.100","36773.41","0.13386","0.06069"
"133.500","11.125","36775.92","0.13428","0.06086"
"133.800","11.150","36777.48","0.13470","0.06103"
"134.100","11.175","36777.73","0.13512","0.06121"
"134.400","11.200","36785.58","0.13554","0.06138"
"134.700","11.225","36786.51","0.13596","0.06156"
"135.000","11.250","36790.68","0.13638","0.06173"
"135.300","11.275","36796.99","0.13680","0.06191"
"135.600","11.300","36808.66","0.13722","0.06208"
"135.900","11.325","36800.00","0.13765","0.06226"
"136.200","11.350","36809.88","0.13807","0.06244"
"136.500","11.375","36818.17","0.13849","0.06261"
"136.800","11.400","36827.94","0.13891","0.06278"
"137.100","11.425","36821.77","0.13933","0.06296"
"137.400","11.450","36830.89","0.13976","0.06313"
"137.700","11.475","36838.73","0.14018","0.06330"
"138.000","11.500","36834.09","0.14062","0.06348"
"138.300","11.525","36844.43","0.14104","0.06366"
"138.600","11.550","36849.00","0.14147","0.06383"
"138.900","11.575","36856.43","0.14190","0.06401"
"139.200","11.600","36854.45","0.14232","0.06419"
"139.500","11.625","36861.66","0.14275","0.06436"
"139.800","11.650","36862.04","0.14317","0.06454"
"140.100","11.675","36867.05","0.14360","0.06472"
"140.400","11.700","36876.16","0.14403","0.06490"
"140.700","11.725","36879.23","0.14446","0.06507"
"141.000","11.750","36884.18","0.14489","0.06525"
"141.300","11.775","36878.34","0.14532","0.06542"
"141.600","11.800","36886.44","0.14575","0.06559"
"141.900","11.825","36887.79","0.14619","0.06577"
"142.200","11.850","36889.23","0.14662","0.06594"
"142.500","11.875","36892.56","0.14705","0.06611"
"142.800","11.900","36893.80","0.14748","0.06628"
"143.100","11.925","36895.52","0.14792","0.06646"
"143.400","11.950","36903.77","0.14835","0.06664"
"143.700","11.975","36907.43","0.14879","0.06680"
"144.000","12.000","36909.21","0.14922","0.06699"
"144.300","12.025","36909.50","0.14965","0.06718"
"144.600","12.050","36916.95","0.15008","0.06737"
"144.900","12.075","36915.56","0.15052","0.06756"
"145.200","12.100","36918.73","0.15096","0.06774"
"145.500","12.125","36922.08","0.15139","0.06792"
"145.800","12.150","36931.73","0.15183","0.06810"
"146.100","12.175","36939.88","0.15228","0.06828"
"146.400","12.200","36933.82","0.15272","0.06846"
"146.700","12.225","36929.50","0.15317","0.06864"
"147.000","12.250","36941.31","0.15360","0.06881"
"147.300","12.275","36942.64","0.15404","0.06899"
"147.600","12.300","36951.61","0.15449","0.06916"
"147.900","12.325","36945.45","0.15493","0.06934"
"148.200","12.350","36953.25","0.15537","0.06951"
"148.500","12.375","36956.60","0.15582","0.06969"
"148.800","12.400","36954.32","0.15627","0.06987"
"149.100","12.425","36966.46","0.15671","0.07004"
"149.400","12.450","36960.57","0.15716","0.07022"
"149.700","12.475","36968.20","0.15761","0.07040"
"150.000","12.500","36974.35","0.15805","0.07058"
"150.300","12.525","36977.29","0.15850","0.07076"
"150.600","12.550","36978.19","0.15895","0.07095"
"150.900","12.575","36979.57","0.15940","0.07113"
"151.200","12.600","36988.37","0.15985","0.07131"
"151.500","12.625","36980.20","0.16030","0.07150"
"151.800","12.650","36989.64","0.16076","0.07169"
"152.100","12.675","36984.52","0.16121","0.07188"
"152.400","12.700","36990.43","0.16166","0.07207"
"152.700","12.725","36993.16","0.16211","0.07225"
"153.000","12.750","36982.71","0.16257","0.07244"
"153.300","12.775","36997.48","0.16302","0.07263"
"153.600","12.800","36996.16","0.16348","0.07281"
"153.900","12.825","36999.02","0.16394","0.07300"
"154.200","12.850","36996.45","0.16439","0.07318"
"154.500","12.875","37000.32","0.16485","0.07335"
"154.800","12.900","37010.45","0.16532","0.07353"
"155.100","12.925","37003.11","0.16577","0.07371"
"155.400","12.950","37002.61","0.16623","0.07389"
"155.700","12.975","37005.94","0.16670","0.07406"
"156.000","13.000","37012.15","0.16716","0.07425"
"156.300","13.025","37007.46","0.16761","0.07443"
"156.600","13.050","37010.80","0.16808","0.07461"
"156.900","13.075","37005.90","0.16855","0.07481"
"157.200","13.100","37011.85","0.16901","0.07500"
"157.500","13.125","37008.44","0.16947","0.07521"
"157.800","13.150","37012.41","0.16993","0.07541"
"158.100","13.175","37009.73","0.17040","0.07560"
"158.400","13.200","37007.32","0.17086","0.07579"
"158.700","13.225","37012.53","0.17134","0.07598"
"159.000","13.250","37013.50","0.17180","0.07617"
"159.300","13.275","37014.46","0.17228","0.07636"
"159.600","13.300","37011.67","0.17275","0.07655"
"159.900","13.325","37012.27","0.17322","0.07674"
"160.200","13.350","37012.96","0.17370","0.07693"
"160.500","13.375","37017.67","0.17417","0.07712"
"160.800","13.400","37018.02","0.17464","0.07731"
"161.100","13.425","37016.89","0.17512","0.07750"
"161.400","13.450","37019.73","0.17560","0.07769"
"161.700","13.475","37019.84","0.17607","0.07787"
"162.000","13.500","37021.15","0.17655","0.07806"
"162.300","13.525","37014.41","0.17704","0.07824"
"162.600","13.550","37010.16","0.17751","0.07842"
"162.900","13.575","37013.66","0.17798","0.07859"
"163.200","13.600","37013.57","0.17847","0.07878"
"163.500","13.625","37027.58","0.17896","0.07897"
"163.800","13.650","37015.86","0.17944","0.07916"
"164.100","13.675","37020.75","0.17993","0.07934"
"164.400","13.700","37016.54","0.18042","0.07953"
"164.700","13.725","37015.94","0.18091","0.07972"
"165.000","13.750","37011.70","0.18140","0.07990"
"165.300","13.775","37016.37","0.18189","0.08009"
"165.600","13.800","37018.24","0.18237","0.08029"
"165.900","13.825","37013.89","0.18287","0.08049"
"166.200","13.850","37021.41","0.18336","0.08068"
"166.500","13.875","37022.42","0.18386","0.08088"
"166.800","13.900","37018.88","0.18436","0.08108"
"167.100","13.925","37014.29","0.18485","0.08129"
"167.400","13.950","37015.50","0.18535","0.08147"
"167.700","13.975","37014.93","0.18586","0.08168"
"168.000","14.000","37013.88","0.18636","0.08188"
"168.300","14.025","37016.40","0.18686","0.08209"
"168.600","14.050","37019.12","0.18737","0.08229"
"168.900","14.075","37014.59","0.18788","0.08249"
"169.200","14.100","37011.20","0.18839","0.08270"
"169.500","14.125","37014.45","0.18889","0.08290"
"169.800","14.150","37008.51","0.18940","0.08311"
"170.100","14.175","37008.45","0.18991","0.08329"
"170.400","14.200","37010.11","0.19042","0.08349"
"170.700","14.225","37010.23","0.19093","0.08368"
"171.000","14.250","37013.36","0.19144","0.08389"
"171.300","14.275","37004.24","0.19195","0.08408"
"171.600","14.300","37013.90","0.19246","0.08429"
"171.900","14.325","37012.75","0.19298","0.08449"
"172.200","14.350","37012.36","0.19351","0.08470"
"172.500","14.375","37003.77","0.19404","0.08491"
"172.800","14.400","37006.71","0.19456","0.08511"
"173.100","14.425","37005.95","0.19510","0.08531"
"173.400","14.450","37005.36","0.19563","0.08552"
"173.700","14.475","37003.99","0.19616","0.08573"
"174.000","14.500","37007.35","0.19669","0.08594"
"174.300","14.525","37002.95","0.19722","0.08615"
"174.600","14.550","36999.32","0.19775","0.08636"
"174.900","14.575","37002.79","0.19828","0.08657"
"175.200","14.600","37000.02","0.19881","0.08678"
"175.500","14.625","36994.21","0.19934","0.08699"
"175.800","14.650","36995.52","0.19987","0.08720"
"176.100","14.675","37000.25","0.20040","0.08742"
"176.400","14.700","36998.18","0.20093","0.08762"
"176.700","14.725","36993.59","0.20146","0.08783"
"177.000","14.750","36993.68","0.20199","0.08804"
"177.300","14.775","36986.44","0.20253","0.08826"
"177.600","14.800","36985.87","0.20306","0.08847"
"177.900","14.825","36987.42","0.20360","0.08869"
"178.200","14.850","36981.64","0.20414","0.08890"
"178.500","14.875","36974.20","0.20467","0.08912"
"178.800","14.900","36977.35","0.20521","0.08934"
"179.100","14.925","36981.48","0.20575","0.08956"
"179.400","14.950","36979.46","0.20630","0.08977"
"179.700","14.975","36980.46","0.20685","0.09000"
"180.000","15.000","36969.59","0.20740","0.09022"
"180.300","15.025","36970.21","0.20794","0.09045"
"180.600","15.050","36961.95","0.20850","0.09066"
"180.900","15.075","36962.21","0.20904","0.09089"
"181.200","15.100","36958.21","0.20960","0.09112"
"181.500","15.125","36962.08","0.21015","0.09135"
"181.800","15.150","36955.54","0.21069","0.09158"
"182.100","15.175","36947.80","0.21126","0.09180"
"182.400","15.200","36951.98","0.21182","0.09203"
"182.700","15.225","36941.02","0.21238","0.09223"
"183.000","15.250","36942.92","0.21295","0.09246"
"183.300","15.275","36929.20","0.21351","0.09270"
"183.600","15.300","36927.18","0.21408","0.09292"
"183.900","15.325","36934.12","0.21465","0.09315"
"184.200","15.350","36923.53","0.21522","0.09338"
"184.500","15.375","36920.08","0.21579","0.09362"
"184.800","15.400","36918.00","0.21636","0.09386"
"185.100","15.425","36922.89","0.21694","0.09409"
"185.400","15.450","36917.06","0.21752","0.09432"
"185.700","15.475","36915.33","0.21810","0.09456"
"186.000","15.500","36907.61","0.21868","0.09480"
"186.300","15.525","36909.11","0.21926","0.09504"
"186.600","15.550","36904.11","0.21985","0.09527"
"186.900","15.575","36902.20","0.22044","0.09551"
"187.200","15.600","36904.50","0.22104","0.09575"
"187.500","15.625","36894.79","0.22163","0.09599"
"187.800","15.650","36895.96","0.22222","0.09621"
"188.100","15.675","36889.69","0.22282","0.09646"
"188.400","15.700","36886.03","0.22341","0.09670"
"188.700","15.725","36884.06","0.22401","0.09695"
"189.000","15.750","36876.76","0.22461","0.09720"
"189.300","15.775","36879.34","0.22521","0.09744"
"189.600","15.800","36875.71","0.22580","0.09771"
"189.900","15.825","36880.48","0.22638","0.09796"
"190.200","15.850","36868.33","0.22697","0.09821"
"190.500","15.875","36869.05","0.22759","0.09846"
"190.800","15.900","36857.03","0.22820","0.09871"
"191.100","15.925","36857.96","0.22882","0.09896"
"191.400","15.950","36854.06","0.22944","0.09921"
"191.700","15.975","36850.28","0.23006","0.09947"
"192.000","16.000","36853.13","0.23068","0.09973"
"192.300","16.025","36850.59","0.23131","0.09998"
"192.600","16.050","36851.59","0.23194","0.10025"
"192.900","16.075","36832.41","0.23258","0.10052"
"193.200","16.100","36837.25","0.23322","0.10078"
"193.500","16.125","36832.38","0.23386","0.10106"
"193.800","16.150","36822.23","0.23449","0.10131"
"194.100","16.175","36821.17","0.23513","0.10159"
"194.400","16.200","36816.92","0.23578","0.10186"
"194.700","16.225","36814.66","0.23643","0.10213"
"195.000","16.250","36799.61","0.23708","0.10241"
"195.300","16.275","36807.78","0.23772","0.10269"
"195.600","16.300","36793.89","0.23838","0.10298"
"195.900","16.325","36790.41","0.23904","0.10326"
"196.200","16.350","36784.95","0.23969","0.10354"
"196.500","16.375","36785.45","0.24035","0.10383"
"196.800","16.400","36780.08","0.24101","0.10411"
"197.100","16.425","36776.14","0.24161","0.10440"
"197.400","16.450","36777.05","0.24227","0.10468"
"197.700","16.475","36776.96","0.24295","0.10498"
"198.000","16.500","36770.07","0.24362","0.10527"
"198.300","16.525","36770.93","0.24431","0.10557"
"198.600","16.550","36771.23","0.24499","0.10587"
"198.900","16.575","36768.75","0.24567","0.10617"
"199.200","16.600","36768.59","0.24636","0.10647"
"199.500","16.625","36770.30","0.24705","0.10677"
"199.800","16.650","36768.66","0.24775","0.10709"
"200.100","16.675","36766.13","0.24844","0.10740"
"200.400","16.700","36765.10","0.24914","0.10771"
"200.700","16.725","36765.47","0.24984","0.10803"
"201.000","16.750","36758.52","0.25055","0.10831"
"201.300","16.775","36758.26","0.25126","0.10863"
"201.600","16.800","36755.54","0.25197","0.10896"
"201.900","16.825","36756.53","0.25269","0.10930"
"202.200","16.850","36750.37","0.25341","0.10962"
"202.500","16.875","36749.29","0.25414","0.10995"
"202.800","16.900","36749.70","0.25487","0.11029"
"203.100","16.925","36752.16","0.25560","0.11063"
"203.400","16.950","36743.30","0.25634","0.11095"
"203.700","16.975","36736.65","0.25708","0.11128"
"204.000","17.000","36740.12","0.25781","0.11164"
"204.300","17.025","36737.29","0.25856","0.11199"
"204.600","17.050","36731.32","0.25930","0.11233"
"204.900","17.075","36732.00","0.26005","0.11268"
"205.200","17.100","36729.64","0.26081","0.11304"
"205.500","17.125","36729.10","0.26157","0.11340"
"205.800","17.150","36722.34","0.26234","0.11376"
"206.100","17.175","36720.37","0.26310","0.11412"
"206.400","17.200","36717.55","0.26387","0.11450"
"206.700","17.225","36713.77","0.26464","0.11487"
"207.000","17.250","36707.34","0.26542","0.11525"
"207.300","17.275","36708.39","0.26620","0.11563"
"207.600","17.300","36700.44","0.26700","0.11600"
"207.900","17.325","36689.80","0.26778","0.11640"
"208.200","17.350","36688.58","0.26858","0.11679"
"208.500","17.375","36674.27","0.26938","0.11719"
"208.800","17.400","36658.60","0.27018","0.11758"
"209.100","17.425","36642.70","0.27098","0.11797"
"209.400","17.450","36640.46","0.27178","0.11839"
"209.700","17.475","36621.81","0.27259","0.11881"
"210.000","17.500","36611.50","0.27341","0.11923"
"210.300","17.525","36602.29","0.27423","0.11966"
"210.600","17.550","36583.30","0.27506","0.12010"
"210.900","17.575","36570.77","0.27590","0.12054"
"211.200","17.600","36559.02","0.27673","0.12098"
"211.500","17.625","36551.78","0.27756","0.12109"
"211.800","17.650","36544.23","0.27840","0.12151"
"212.100","17.675","36536.45","0.27924","0.12193"
"212.400","17.700","36525.08","0.28008","0.12244"
"212.700","17.725","36512.84","0.28093","0.12295"
"213.000","17.750","36504.85","0.28179","0.12345"
"213.300","17.775","36491.20","0.28265","0.12395"
"213.600","17.800","36472.04","0.28351","0.12444"
"213.900","17.825","36458.75","0.28438","0.12495"
"214.200","17.850","36445.05","0.28522","0.12545"
"214.500","17.875","36427.73","0.28603","0.12597"
"214.800","17.900","36414.36","0.28690","0.12649"
"215.100","17.925","36404.34","0.28778","0.12701"
"215.400","17.950","36394.10","0.28868","0.12754"
"215.700","17.975","36385.53","0.28957","0.12808"
"216.000","18.000","36360.19","0.29048","0.12862"
"216.300","18.025","36343.21","0.29138","0.12913"
"216.600","18.050","36324.70","0.29228","0.12968"
"216.900","18.075","36309.02","0.29319","0.13026"
"217.200","18.100","36270.56","0.29411","0.13084"
"217.500","18.125","36262.29","0.29502","0.13142"
"217.800","18.150","36252.34","0.29594","0.13201"
"218.100","18.175","36230.83","0.29687","0.13260"
"218.400","18.200","36216.19","0.29780","0.13320"
"218.700","18.225","36211.83","0.29873","0.13381"
"219.000","18.250","36203.65","0.29967","0.13443"
"219.300","18.275","36195.46","0.30060","0.13505"
"219.600","18.300","36192.61","0.30154","0.13569"
"219.900","18.325","36183.73","0.30248","0.13632"
"220.200","18.350","36176.35","0.30342","0.13695"
"220.500","18.375","36168.21","0.30436","0.13760"
"220.800","18.400","36160.26","0.30531","0.13827"
"221.100","18.425","36157.12","0.30627","0.13896"
"221.400","18.450","36153.86","0.30723","0.13965"
"221.700","18.475","36147.52","0.30818","0.14034"
"222.000","18.500","36136.03","0.30914","0.14103"
"222.300","18.525","36116.27","0.31011","0.14174"
"222.600","18.550","36090.00","0.31108","0.14245"
"222.900","18.575","36074.52","0.31204","0.14317"
"223.200","18.600","36057.96","0.31301","0.14390"
"223.500","18.625","36046.49","0.31399","0.14464"
"223.800","18.650","36024.77","0.31497","0.14539"
"224.100","18.675","35997.54","0.31594","0.14614"
"224.400","18.700","35972.15","0.31692","0.14690"
"224.700","18.725","35942.23","0.31790","0.14768"
"225.000","18.750","35942.81","0.31887","0.14845"
"225.300","18.775","35892.84","0.31984","0.14923"
"225.600","18.800","35855.23","0.32084","0.15001"
"225.900","18.825","35810.47","0.32182","0.15082"
"226.200","18.850","35767.52","0.32282","0.15164"
"226.500","18.875","35751.80","0.32380","0.15247"
"226.800","18.900","35724.14","0.32479","0.15330"
"227.100","18.925","35712.61","0.32577","0.15414"
"227.400","18.950","35700.44","0.32675","0.15497"
"227.700","18.975","35687.10","0.32774","0.15582"
"228.000","19.000","35671.21","0.32873","0.15668"
"228.300","19.025","35646.31","0.32973","0.15754"
"228.600","19.050","35616.53","0.33072","0.15856"
"228.900","19.075","35576.75","0.33173","0.15948"
"229.200","19.100","35520.27","0.33273","0.16039"
"229.500","19.125","35478.65","0.33373","0.16130"
"229.800","19.150","35453.56","0.33472","0.16220"
"230.100","19.175","35429.21","0.33572","0.16311"
"230.400","19.200","35404.04","0.33672","0.16403"
"230.700","19.225","35382.60","0.33772","0.16495"
"231.000","19.250","35367.31","0.33873","0.16586"
"231.300","19.275","35351.98","0.33973","0.16678"
"231.600","19.300","35314.48","0.34074","0.16771"
"231.900","19.325","35281.94","0.34174","0.16863"
"232.200","19.350","35258.86","0.34274","0.16955"
"232.500","19.375","35229.07","0.34374","0.17049"
"232.800","19.400","35202.13","0.34473","0.17143"
"233.100","19.425","35179.22","0.34574","0.17237"
"233.400","19.450","35158.87","0.34674","0.17332"
"233.700","19.475","35136.71","0.34775","0.17427"
"234.000","19.500","35091.87","0.34875","0.17522"
"234.300","19.525","35028.91","0.34976","0.17619"
"234.600","19.550","34979.10","0.35077","0.17717"
"234.900","19.575","34927.96","0.35176","0.17823"
"235.200","19.600","34881.79","0.35277","0.17926"
"235.500","19.625","34832.75","0.35377","0.18025"
"235.800","19.650","34788.50","0.35478","0.18126"
"236.100","19.675","34722.53","0.35578","0.18228"
"236.400","19.700","34672.27","0.35680","0.18329"
"236.700","19.725","34656.66","0.35781","0.18431"
"237.000","19.750","34655.04","0.35882","0.18533"
"237.300","19.775","34655.00","0.35983","0.18635"
"237.600","19.800","34652.56","0.36084","0.18737"
"237.900","19.825","34627.75","0.36185","0.18839"
"238.200","19.850","34583.45","0.36286","0.18941"
"238.500","19.875","34533.36","0.36388","0.19045"
"238.800","19.900","34463.17","0.36488","0.19147"
"239.100","19.925","34385.98","0.36591","0.19250"
"239.400","19.950","34341.81","0.36692","0.19354"
"239.700","19.975","34272.08","0.36793","0.19457"
"240.000","20.000","34199.83","0.36893","0.19560"
"240.300","20.025","34168.84","0.36995","0.19662"
"240.600","20.050","34135.08","0.37096","0.19766"
"240.900","20.075","34087.68","0.37198","0.19870"
"241.200","20.100","34045.43","0.37299","0.19974"
"241.500","20.125","34003.02","0.37400","0.20078"
"241.800","20.150","33951.67","0.37502","0.20184"
"242.100","20.175","33931.64","0.37604","0.20288"
"242.400","20.200","33890.63","0.37705","0.20392"
"242.700","20.225","33861.04","0.37807","0.20503"
"243.000","20.250","33783.58","0.37908","0.20606"
"243.300","20.275","33713.72","0.38010","0.20715"
"243.600","20.300","33671.02","0.38111","0.20823"
"243.900","20.325","33643.41","0.38214","0.20931"
"244.200","20.350","33602.20","0.38316","0.21039"
"244.500","20.375","33530.26","0.38418","0.21149"
"244.800","20.400","33451.36","0.38520","0.21260"
"245.100","20.425","33390.75","0.38620","0.21624"
"245.400","20.450","33295.85","0.38719","0.21815"
"245.700","20.475","33242.39","0.38822","0.21926"
"246.000","20.500","33186.89","0.38925","0.22038"
"246.300","20.525","33153.33","0.39028","0.22149"
"246.600","20.550","33152.69","0.39130","0.22260"
"246.900","20.575","33147.21","0.39233","0.22372"
"247.200","20.600","33087.97","0.39335","0.22559"
"247.500","20.625","32980.89","0.39439","0.22675"
"247.800","20.650","32905.59","0.39541","0.22787"
"248.100","20.675","32826.50","0.39644","0.22901"
"248.400","20.700","32738.29","0.39745","0.23013"
"248.700","20.725","32632.53","0.39847","0.23118"
"249.000","20.750","32583.30","0.39950","0.23232"
"249.300","20.775","32549.08","0.40053","0.23347"
"249.600","20.800","32527.35","0.40156","0.23461"
"249.900","20.825","32467.28","0.40259","0.23575"
"250.200","20.850","32429.73","0.40361","0.23687"
"250.500","20.875","32338.76","0.40464","0.23800"
"250.800","20.900","32271.11","0.40567","0.23913"
"251.100","20.925","32163.80","0.40670","0.24021"
"251.400","20.950","32105.49","0.40768","0.24650"
"251.700","20.975","32066.62","0.40872","0.24772"
"252.000","21.000","32004.21","0.40975","0.24890"
"252.300","21.025","31892.20","0.41079","0.25009"
"252.600","21.050","31800.74","0.41184","0.25127"
"252.900","21.075","31743.75","0.41287","0.25242"
"253.200","21.100","31670.10","0.41390","0.25357"
"253.500","21.125","31637.49","0.41494","0.25474"
"253.800","21.150","31591.40","0.41598","0.25589"
"254.100","21.175","31523.51","0.41701","0.25715"
"254.400","21.200","31401.01","0.41805","0.25830"
"254.700","21.225","31308.84","0.41910","0.25947"
"255.000","21.250","31185.69","0.42013","0.26067"
"255.300","21.275","31082.45","0.42118","0.26188"
"255.600","21.300","31043.13","0.42221","0.26302"
"255.900","21.325","31024.06","0.42325","0.26415"
"256.200","21.350","30942.53","0.42428","0.26529"
"256.500","21.375","30870.02","0.42533","0.26645"
"256.800","21.400","30770.22","0.42636","0.26765"
"257.100","21.425","30621.51","0.42740","0.26882"
"257.400","21.450","30557.18","0.42845","0.26995"
"257.700","21.475","30487.75","0.42949","0.27109"
"258.000","21.500","30408.04","0.43054","0.27219"
"258.300","21.525","30324.01","0.43158","0.27330"
"258.600","21.550","30231.91","0.43263","0.27443"
"258.900","21.575","30115.16","0.43368","0.27558"
"259.200","21.600","30068.36","0.43472","0.27670"
"259.500","21.625","30012.96","0.43576","0.27779"
"259.800","21.650","29852.18","0.43681","0.27994"
"260.100","21.675","29740.68","0.43787","0.28113"
"260.400","21.700","29659.03","0.43892","0.28232"
"260.700","21.725","29541.61","0.43997","0.28351"
"261.000","21.750","29484.55","0.44103","0.28470"
"261.300","21.775","29409.03","0.44207","0.28588"
"261.600","21.800","29300.57","0.44312","0.28706"
"261.900","21.825","29175.04","0.44417","0.28827"
"262.200","21.850","29024.59","0.44523","0.28957"
"262.500","21.875","28979.78","0.44628","0.29064"
"262.800","21.900","28920.06","0.44732","0.29870"
"263.100","21.925","28759.62","0.44839","0.30035"
"263.400","21.950","28641.90","0.44944","0.30195"
"263.700","21.975","28534.06","0.45049","0.30336"
"264.000","22.000","28445.64","0.45155","0.30504"
"264.300","22.025","28322.94","0.45262","0.30676"
"264.600","22.050","28212.02","0.45368","0.30829"
"264.900","22.075","28075.52","0.45476","0.30862"
"265.200","22.100","27969.44","0.45583","0.31026"
"265.500","22.125","27908.35","0.45690","0.30648"
"265.800","22.150","27764.00","0.45796","0.30783"
"266.100","22.175","27597.94","0.45904","0.30877"
"266.400","22.200","27491.20","0.46011","0.30938"
"266.700","22.225","27430.63","0.46118","0.30941"
"267.000","22.250","27237.83","0.46225","0.30743"
"267.300","22.275","27112.63","0.46333","0.30857"
"267.600","22.300","26948.99","0.46441","0.30934"
"267.900","22.325","26899.63","0.46548","0.30948"
"268.200","22.350","26754.85","0.46656","0.30921"
"268.500","22.375","26566.21","0.46764","0.30750"
"268.800","22.400","26407.12","0.46872","0.30852"
"269.100","22.425","26346.91","0.46980","0.30645"
"269.400","22.450","26181.54","0.47088","0.30684"
"269.700","22.475","26023.47","0.47197","0.30793"
"270.000","22.500","25892.36","0.47306","0.30750"
"270.300","22.525","25712.07","0.47414","0.30847"
"270.600","22.550","25545.48","0.47523","0.30935"
"270.900","22.575","25412.25","0.47633","0.31040"
"271.200","22.600","24207.50","0.47796","0.30820"
"271.216","22.602","14225.31","0.46583","0.29569"